File: Example Date/DSC TA/YN019 -160-150.txt
Filename	YN019 -160-150
Instrument name	DSC2A-01799 (192.168.1.250)
Operator
rundate	10/12/2024
Sample name	YN019 -160-150
proceduresegments	Ramp 10.00 °C/min to 150.0000 °C; Isothermal 3.0 min; Ramp 100.00 °C/min to -160.0000 °C; Isothermal 20.0 min; Ramp 10.00 °C/min to 150.0000 °C; Isothermal 3.0 min; Ramp 100.00 °C/min to -160.0000 °C; Isothermal 20.0 min; Ramp 10.00 °C/min to 150.0000 °C; Isothermal 3.0 min; Ramp 10.00 °C/min to 40.0000 °C
[File Parameters]
Run Date	10/12/2024 11:28:56
Trios version	5.7.0.56
Original File Name
Current File Name	C:\Users\TA Instruments DSC\Desktop\Data\Yutong Niu\YN019 -160-150.tri
User at run start	DESKTOP-CFGN8IT\TA Instruments DSC
[Procedure]
Procedure Name	polyether
Sample Name	YN019 -160-150
Sample Mass	15.5 mg
Reference Sample Mass	0 mg
Pan Mass	60.77 mg
Pan Number	23
Reference Pan Mass	60.81 mg
Reference Pan Number	45
Pan Type	Tzero Aluminum Pin Hole Hermetic
Comments
Project Name
Operator
Test	Custom
Unload Max Temperature	25
Unload Min Temperature	25
FillCooler	Do not fill
Load Max Temperature	25
Load Min Temperature	25
Discard pan in waste bin at end of test	Yes
Stop on Gas Flow Error	No
[Signal List]
Signal #1	Time (min)
Signal #2	Temperature (°C)
Signal #3	Heat Flow (mW)
Signal #4	Delta T (µV)
Signal #5	Delta Tzero (µV)
Signal #6	Tzero Temperature (°C)
Signal #7	Cell Purge (mL/min)
Signal #8	Heater Temp (°C)
Signal #9	Power Delivered (W)
Signal #10	Reference Junction Temperature (°C)
Signal #11	Flange Temperature (°C)
Signal #12	Heat Flow Phase (rad)
Signal #13	Total Heat Capacity (J/°C)
Signal #14	Heat Capacity (J/°C)
Signal #15	LN Pump Tank level (%)
[Configuration]
Company Name	Warwick University
Instrument Name	DSC2A-01799
Instrument Type	DSC2500
Serial Number	DSC2A-01799
IP	192.168.1.250
Location of Instrument	Polymer RTP
DisplayType	TianmaV2andV3
Sample Interval 	0.1 s/pt
Selected Heat Flow	T4P
Exotherm Direction	Up
Cell Serial	DRC2-03788
Lid Type	High Temperature
Cooler	LN Pump
Leave Cooler on at End of Sequence	Off
Gas 2	Air
Gas Selected	Channel 1: Nitrogen
Flow Rate	50 mL/min
Secondary Purge	On
Licensed Heat Flow	Heat Flow T4P
Modulation Licensed	Yes
[Versions]
Common IDD Version	1
Cortex Version	VER 2.11.0.729
Driver	5.0.0.6
GDM Version	1.0.3.3
TouchscreenVersion	1.0.3.1841
FEP Version	1.2.1.21
FEP Bootloader	2.0.0.5
AutoSampler Version	2.1.2.1
Auto Sampler Bootloader	2.0.0.5
FCM Version	1.1.0.3
FCM Bootloader	2.0.0.5
LN Pump Version	10.17.0.0
LN Pump Bootloader	2.0.0.5
[Experiment Logs]
Experiment Log Entry # 1	Air Cool is off.
Experiment Log Entry # 3	Ramp Segment 10 C/min to 150 Started
Experiment Log Entry # 5	Isothermal Segment 3 min started
Experiment Log Entry # 7	Ramp Segment 100 C/min to -160 Started
Experiment Log Entry # 9	Isothermal Segment 20 min started
Experiment Log Entry # 11	Ramp Segment 10 C/min to 150 Started
Experiment Log Entry # 14	LN2P is filling
Experiment Log Entry # 16	LN2P stopped filling
Experiment Log Entry # 17	Isothermal Segment 3 min started
Experiment Log Entry # 19	Ramp Segment 100 C/min to -160 Started
Experiment Log Entry # 21	Isothermal Segment 20 min started
Experiment Log Entry # 23	Ramp Segment 10 C/min to 150 Started
Experiment Log Entry # 25	Isothermal Segment 3 min started
Experiment Log Entry # 27	Ramp Segment 10 C/min to 40 Started
Experiment Log Entry # 30	LN2P is filling
[Method Log]
Method Log Entry # 1	(Ramp 708913) Ramp 10 °C/minute to 150 °C
Method Log Entry # 2	Isothermal 3 minutes
Method Log Entry # 3	(Ramp 708915) Ramp 100 °C/minute to -160 °C
Method Log Entry # 4	Isothermal 20 minutes
Method Log Entry # 5	(Ramp 708917) Ramp 10 °C/minute to 150 °C
Method Log Entry # 6	Isothermal 3 minutes
Method Log Entry # 7	(Ramp 708919) Ramp 100 °C/minute to -160 °C
Method Log Entry # 8	Isothermal 20 minutes
Method Log Entry # 9	(Ramp 708921) Ramp 10 °C/minute to 150 °C
Method Log Entry # 10	Isothermal 3 minutes
Method Log Entry # 11	(Ramp 708923) Ramp 10 °C/minute to 40 °C
Cell Serial	DRC2-03788
[T1 Calibration]
Date Applied	04/03/2021 14:58:04
Description
Gas Type	Nitrogen
Pan Type	None
Slope	-0.001800291
Offset	-0.1301359
Initial Temperature	-100.6228
GUID	a1d5a6be-decd-4ae4-b22f-d560f3a78a92
[TZero Calibration]
Date Applied	21/08/2024 09:53:38
Description	From -180.022 °C to 395.167 °C at 20.000°C/min
Gas Type	Nitrogen
Pan Type	None
Source Files 1	C:\ProgramData\TA Instruments\TRIOS\Data\TAService\PMV 20Aug2024\Tzero Cal.tri
Source Files 2	C:\ProgramData\TA Instruments\TRIOS\Data\TAService\PMV 20Aug2024\Tzero Cal sapphire.tri
Delta T Offset	1.787969
Delta T Slope	-0.003527276
Delta T0 Offset	0.06831977
Delta T0 Slope	0.02007191
[Temperature Calibration]
Date Applied	21/08/2024 11:06:35
Description	From 106.660 °C to 186.660 °C at 10.000°C/min
Gas Type	Nitrogen
Pan Type	Tzero Aluminum
Source Files 1	C:\ProgramData\TA Instruments\TRIOS\Data\TAService\PMV 20Aug2024\TA Indium cal.tri
Measured 1	157.9141
Known 1	156.66
[Cell Constant Calibration]
Date Applied	21/08/2024 11:06:35
Description	From 106.660 °C to 186.660 °C at 10.000°C/min
Gas Type	Nitrogen
Pan Type	Tzero Aluminum
Source Files 1	C:\ProgramData\TA Instruments\TRIOS\Data\TAService\PMV 20Aug2024\TA Indium cal.tri
T4P KCell	1.038055
Onset Slope	-66.72884 mW/°C
[Direct Cp Calibration]
Date Applied	19/11/2024 16:37:27
Description	From -89.996 °C to 396.697 °C at 20.000°C/min
Gas Type	Nitrogen
Pan Type	Tzero Aluminum
Source Files 1	C:\ProgramData\TA Instruments\TRIOS\Data\Sapphire Direct Heat Capacity(8).tri
GUID	544f8371-fe9b-4f4f-81ca-7980c172113e
Temperature	-89.99625 °C
Cp	1.464367
Temperature	-89.02287 °C
Cp	1.460558
Temperature	-88.04948 °C
Cp	1.456263
Temperature	-87.0761 °C
Cp	1.451626
Temperature	-86.10271 °C
Cp	1.446737
Temperature	-85.12933 °C
Cp	1.441723
Temperature	-84.15594 °C
Cp	1.436654
Temperature	-83.18256 °C
Cp	1.431684
Temperature	-82.20917 °C
Cp	1.426935
Temperature	-81.23578 °C
Cp	1.422396
Temperature	-80.2624 °C
Cp	1.418192
Temperature	-79.28901 °C
Cp	1.414363
Temperature	-78.31562 °C
Cp	1.410925
Temperature	-77.34224 °C
Cp	1.407865
Temperature	-76.36885 °C
Cp	1.405143
Temperature	-75.39546 °C
Cp	1.402789
Temperature	-74.42208 °C
Cp	1.400703
Temperature	-73.44869 °C
Cp	1.398837
Temperature	-72.4753 °C
Cp	1.397142
Temperature	-71.50192 °C
Cp	1.395565
Temperature	-70.52853 °C
Cp	1.394053
Temperature	-69.55515 °C
Cp	1.392558
Temperature	-68.58176 °C
Cp	1.391036
Temperature	-67.60838 °C
Cp	1.389483
Temperature	-66.63499 °C
Cp	1.387847
Temperature	-65.66161 °C
Cp	1.38616
Temperature	-64.68822 °C
Cp	1.384397
Temperature	-63.71483 °C
Cp	1.382535
Temperature	-62.74145 °C
Cp	1.380598
Temperature	-61.76806 °C
Cp	1.37865
Temperature	-60.79467 °C
Cp	1.376673
Temperature	-59.82129 °C
Cp	1.374677
Temperature	-58.8479 °C
Cp	1.372642
Temperature	-57.87452 °C
Cp	1.370686
Temperature	-56.90113 °C
Cp	1.368741
Temperature	-55.92775 °C
Cp	1.366786
Temperature	-54.95436 °C
Cp	1.364863
Temperature	-53.98097 °C
Cp	1.362959
Temperature	-53.00759 °C
Cp	1.361116
Temperature	-52.0342 °C
Cp	1.359247
Temperature	-51.06082 °C
Cp	1.357393
Temperature	-50.08743 °C
Cp	1.355593
Temperature	-49.11404 °C
Cp	1.353796
Temperature	-48.14066 °C
Cp	1.352008
Temperature	-47.16727 °C
Cp	1.350215
Temperature	-46.19389 °C
Cp	1.348396
Temperature	-45.2205 °C
Cp	1.346593
Temperature	-44.24712 °C
Cp	1.344755
Temperature	-43.27373 °C
Cp	1.342891
Temperature	-42.30034 °C
Cp	1.341008
Temperature	-41.32696 °C
Cp	1.339126
Temperature	-40.35357 °C
Cp	1.337236
Temperature	-39.38018 °C
Cp	1.335367
Temperature	-38.4068 °C
Cp	1.333522
Temperature	-37.43341 °C
Cp	1.331708
Temperature	-36.46003 °C
Cp	1.32991
Temperature	-35.48664 °C
Cp	1.328145
Temperature	-34.51326 °C
Cp	1.326414
Temperature	-33.53987 °C
Cp	1.32471
Temperature	-32.56648 °C
Cp	1.323012
Temperature	-31.5931 °C
Cp	1.321323
Temperature	-30.61971 °C
Cp	1.319657
Temperature	-29.64633 °C
Cp	1.317968
Temperature	-28.67294 °C
Cp	1.316286
Temperature	-27.69955 °C
Cp	1.314585
Temperature	-26.72617 °C
Cp	1.312857
Temperature	-25.75278 °C
Cp	1.31111
Temperature	-24.7794 °C
Cp	1.309333
Temperature	-23.80601 °C
Cp	1.307544
Temperature	-22.83262 °C
Cp	1.30575
Temperature	-21.85924 °C
Cp	1.303941
Temperature	-20.88585 °C
Cp	1.302132
Temperature	-19.91247 °C
Cp	1.300313
Temperature	-18.93908 °C
Cp	1.298512
Temperature	-17.96569 °C
Cp	1.296728
Temperature	-16.99231 °C
Cp	1.294939
Temperature	-16.01892 °C
Cp	1.293198
Temperature	-15.04554 °C
Cp	1.291453
Temperature	-14.07215 °C
Cp	1.289723
Temperature	-13.09876 °C
Cp	1.288007
Temperature	-12.12538 °C
Cp	1.286283
Temperature	-11.15199 °C
Cp	1.284578
Temperature	-10.17861 °C
Cp	1.282885
Temperature	-9.205221 °C
Cp	1.281173
Temperature	-8.231835 °C
Cp	1.279472
Temperature	-7.258449 °C
Cp	1.277766
Temperature	-6.285063 °C
Cp	1.276053
Temperature	-5.311677 °C
Cp	1.274341
Temperature	-4.338291 °C
Cp	1.272592
Temperature	-3.364905 °C
Cp	1.270844
Temperature	-2.391519 °C
Cp	1.269062
Temperature	-1.418133 °C
Cp	1.267264
Temperature	-0.4447474 °C
Cp	1.265435
Temperature	0.5286385 °C
Cp	1.263575
Temperature	1.502024 °C
Cp	1.261727
Temperature	2.47541 °C
Cp	1.259854
Temperature	3.448796 °C
Cp	1.257978
Temperature	4.422182 °C
Cp	1.256109
Temperature	5.395568 °C
Cp	1.254244
Temperature	6.368954 °C
Cp	1.252392
Temperature	7.34234 °C
Cp	1.250552
Temperature	8.315726 °C
Cp	1.248704
Temperature	9.289112 °C
Cp	1.246884
Temperature	10.2625 °C
Cp	1.245078
Temperature	11.23588 °C
Cp	1.243287
Temperature	12.20927 °C
Cp	1.241522
Temperature	13.18266 °C
Cp	1.239778
Temperature	14.15604 °C
Cp	1.238068
Temperature	15.12943 °C
Cp	1.236393
Temperature	16.10281 °C
Cp	1.234762
Temperature	17.0762 °C
Cp	1.233176
Temperature	18.04959 °C
Cp	1.231629
Temperature	19.02297 °C
Cp	1.230129
Temperature	19.99636 °C
Cp	1.228694
Temperature	20.96974 °C
Cp	1.22731
Temperature	21.94313 °C
Cp	1.225968
Temperature	22.91652 °C
Cp	1.224676
Temperature	23.8899 °C
Cp	1.223431
Temperature	24.86329 °C
Cp	1.222217
Temperature	25.83667 °C
Cp	1.221065
Temperature	26.81006 °C
Cp	1.219919
Temperature	27.78345 °C
Cp	1.218811
Temperature	28.75683 °C
Cp	1.21773
Temperature	29.73022 °C
Cp	1.216663
Temperature	30.7036 °C
Cp	1.2156
Temperature	31.67699 °C
Cp	1.214515
Temperature	32.65038 °C
Cp	1.213439
Temperature	33.62376 °C
Cp	1.21234
Temperature	34.59715 °C
Cp	1.211209
Temperature	35.57053 °C
Cp	1.210051
Temperature	36.54392 °C
Cp	1.208868
Temperature	37.5173 °C
Cp	1.207666
Temperature	38.49069 °C
Cp	1.206439
Temperature	39.46408 °C
Cp	1.205199
Temperature	40.43746 °C
Cp	1.203959
Temperature	41.41085 °C
Cp	1.202712
Temperature	42.38424 °C
Cp	1.20147
Temperature	43.35762 °C
Cp	1.200231
Temperature	44.33101 °C
Cp	1.199
Temperature	45.30439 °C
Cp	1.197777
Temperature	46.27778 °C
Cp	1.19657
Temperature	47.25116 °C
Cp	1.195367
Temperature	48.22455 °C
Cp	1.194179
Temperature	49.19794 °C
Cp	1.19301
Temperature	50.17132 °C
Cp	1.191849
Temperature	51.14471 °C
Cp	1.190694
Temperature	52.11809 °C
Cp	1.189555
Temperature	53.09148 °C
Cp	1.18843
Temperature	54.06487 °C
Cp	1.187311
Temperature	55.03825 °C
Cp	1.186195
Temperature	56.01164 °C
Cp	1.185095
Temperature	56.98502 °C
Cp	1.183997
Temperature	57.95841 °C
Cp	1.182894
Temperature	58.93179 °C
Cp	1.181793
Temperature	59.90518 °C
Cp	1.180693
Temperature	60.87857 °C
Cp	1.179595
Temperature	61.85195 °C
Cp	1.178501
Temperature	62.82534 °C
Cp	1.177406
Temperature	63.79873 °C
Cp	1.176313
Temperature	64.77211 °C
Cp	1.175239
Temperature	65.7455 °C
Cp	1.17417
Temperature	66.71888 °C
Cp	1.173105
Temperature	67.69227 °C
Cp	1.172037
Temperature	68.66566 °C
Cp	1.170989
Temperature	69.63904 °C
Cp	1.169948
Temperature	70.61243 °C
Cp	1.168905
Temperature	71.58582 °C
Cp	1.167872
Temperature	72.5592 °C
Cp	1.166849
Temperature	73.53259 °C
Cp	1.165851
Temperature	74.50597 °C
Cp	1.164848
Temperature	75.47935 °C
Cp	1.163876
Temperature	76.45274 °C
Cp	1.162926
Temperature	77.42612 °C
Cp	1.162008
Temperature	78.39951 °C
Cp	1.161113
Temperature	79.3729 °C
Cp	1.160219
Temperature	80.34628 °C
Cp	1.159377
Temperature	81.31967 °C
Cp	1.158546
Temperature	82.29306 °C
Cp	1.157726
Temperature	83.26644 °C
Cp	1.15692
Temperature	84.23983 °C
Cp	1.156126
Temperature	85.21322 °C
Cp	1.155375
Temperature	86.1866 °C
Cp	1.154604
Temperature	87.15999 °C
Cp	1.153869
Temperature	88.13337 °C
Cp	1.153158
Temperature	89.10676 °C
Cp	1.152474
Temperature	90.08015 °C
Cp	1.15181
Temperature	91.05353 °C
Cp	1.151134
Temperature	92.02692 °C
Cp	1.150513
Temperature	93.00031 °C
Cp	1.149892
Temperature	93.97369 °C
Cp	1.149266
Temperature	94.94707 °C
Cp	1.148642
Temperature	95.92046 °C
Cp	1.148019
Temperature	96.89384 °C
Cp	1.147402
Temperature	97.86723 °C
Cp	1.146799
Temperature	98.84062 °C
Cp	1.146191
Temperature	99.814 °C
Cp	1.145602
Temperature	100.7874 °C
Cp	1.14503
Temperature	101.7608 °C
Cp	1.144469
Temperature	102.7342 °C
Cp	1.143921
Temperature	103.7076 °C
Cp	1.143383
Temperature	104.6809 °C
Cp	1.142861
Temperature	105.6543 °C
Cp	1.142345
Temperature	106.6277 °C
Cp	1.141835
Temperature	107.6011 °C
Cp	1.141335
Temperature	108.5745 °C
Cp	1.140846
Temperature	109.5479 °C
Cp	1.140365
Temperature	110.5212 °C
Cp	1.139891
Temperature	111.4946 °C
Cp	1.139429
Temperature	112.468 °C
Cp	1.138976
Temperature	113.4414 °C
Cp	1.13853
Temperature	114.4148 °C
Cp	1.138092
Temperature	115.3882 °C
Cp	1.137654
Temperature	116.3616 °C
Cp	1.137223
Temperature	117.335 °C
Cp	1.136785
Temperature	118.3083 °C
Cp	1.136338
Temperature	119.2817 °C
Cp	1.13588
Temperature	120.2551 °C
Cp	1.13541
Temperature	121.2285 °C
Cp	1.134927
Temperature	122.2019 °C
Cp	1.134417
Temperature	123.1753 °C
Cp	1.133892
Temperature	124.1487 °C
Cp	1.133347
Temperature	125.122 °C
Cp	1.132786
Temperature	126.0954 °C
Cp	1.132206
Temperature	127.0688 °C
Cp	1.131606
Temperature	128.0422 °C
Cp	1.130999
Temperature	129.0156 °C
Cp	1.130384
Temperature	129.989 °C
Cp	1.129765
Temperature	130.9624 °C
Cp	1.129147
Temperature	131.9357 °C
Cp	1.12854
Temperature	132.9091 °C
Cp	1.127949
Temperature	133.8825 °C
Cp	1.127383
Temperature	134.8559 °C
Cp	1.126841
Temperature	135.8293 °C
Cp	1.126334
Temperature	136.8027 °C
Cp	1.125871
Temperature	137.7761 °C
Cp	1.125443
Temperature	138.7494 °C
Cp	1.125058
Temperature	139.7228 °C
Cp	1.124701
Temperature	140.6962 °C
Cp	1.124397
Temperature	141.6696 °C
Cp	1.124114
Temperature	142.643 °C
Cp	1.123854
Temperature	143.6164 °C
Cp	1.123612
Temperature	144.5898 °C
Cp	1.123385
Temperature	145.5631 °C
Cp	1.123182
Temperature	146.5365 °C
Cp	1.12296
Temperature	147.5099 °C
Cp	1.12275
Temperature	148.4833 °C
Cp	1.122543
Temperature	149.4567 °C
Cp	1.122327
Temperature	150.4301 °C
Cp	1.122099
Temperature	151.4035 °C
Cp	1.121837
Temperature	152.3768 °C
Cp	1.121582
Temperature	153.3502 °C
Cp	1.121289
Temperature	154.3236 °C
Cp	1.120967
Temperature	155.297 °C
Cp	1.120616
Temperature	156.2704 °C
Cp	1.120238
Temperature	157.2438 °C
Cp	1.119862
Temperature	158.2172 °C
Cp	1.119444
Temperature	159.1906 °C
Cp	1.119028
Temperature	160.1639 °C
Cp	1.118613
Temperature	161.1373 °C
Cp	1.118202
Temperature	162.1107 °C
Cp	1.117795
Temperature	163.0841 °C
Cp	1.117374
Temperature	164.0575 °C
Cp	1.116987
Temperature	165.0309 °C
Cp	1.116595
Temperature	166.0042 °C
Cp	1.116198
Temperature	166.9776 °C
Cp	1.1158
Temperature	167.951 °C
Cp	1.115402
Temperature	168.9244 °C
Cp	1.115006
Temperature	169.8978 °C
Cp	1.11462
Temperature	170.8712 °C
Cp	1.114223
Temperature	171.8446 °C
Cp	1.113836
Temperature	172.8179 °C
Cp	1.113458
Temperature	173.7913 °C
Cp	1.113085
Temperature	174.7647 °C
Cp	1.112712
Temperature	175.7381 °C
Cp	1.112323
Temperature	176.7115 °C
Cp	1.111957
Temperature	177.6849 °C
Cp	1.111578
Temperature	178.6583 °C
Cp	1.111185
Temperature	179.6317 °C
Cp	1.110789
Temperature	180.605 °C
Cp	1.110391
Temperature	181.5784 °C
Cp	1.110016
Temperature	182.5518 °C
Cp	1.109611
Temperature	183.5252 °C
Cp	1.109232
Temperature	184.4986 °C
Cp	1.108873
Temperature	185.472 °C
Cp	1.108531
Temperature	186.4454 °C
Cp	1.108199
Temperature	187.4187 °C
Cp	1.107851
Temperature	188.3921 °C
Cp	1.107551
Temperature	189.3655 °C
Cp	1.107238
Temperature	190.3389 °C
Cp	1.106917
Temperature	191.3123 °C
Cp	1.106589
Temperature	192.2857 °C
Cp	1.106259
Temperature	193.259 °C
Cp	1.105958
Temperature	194.2324 °C
Cp	1.105619
Temperature	195.2058 °C
Cp	1.105301
Temperature	196.1792 °C
Cp	1.105002
Temperature	197.1526 °C
Cp	1.104718
Temperature	198.126 °C
Cp	1.104445
Temperature	199.0994 °C
Cp	1.104161
Temperature	200.0728 °C
Cp	1.103914
Temperature	201.0461 °C
Cp	1.103657
Temperature	202.0195 °C
Cp	1.103395
Temperature	202.9929 °C
Cp	1.103125
Temperature	203.9663 °C
Cp	1.102847
Temperature	204.9397 °C
Cp	1.102563
Temperature	205.9131 °C
Cp	1.102283
Temperature	206.8865 °C
Cp	1.101985
Temperature	207.8598 °C
Cp	1.10169
Temperature	208.8332 °C
Cp	1.101394
Temperature	209.8066 °C
Cp	1.101099
Temperature	210.78 °C
Cp	1.1008
Temperature	211.7534 °C
Cp	1.10049
Temperature	212.7268 °C
Cp	1.100193
Temperature	213.7002 °C
Cp	1.099886
Temperature	214.6735 °C
Cp	1.099577
Temperature	215.6469 °C
Cp	1.099268
Temperature	216.6203 °C
Cp	1.098965
Temperature	217.5937 °C
Cp	1.098685
Temperature	218.5671 °C
Cp	1.098396
Temperature	219.5405 °C
Cp	1.098134
Temperature	220.5139 °C
Cp	1.097895
Temperature	221.4872 °C
Cp	1.09768
Temperature	222.4606 °C
Cp	1.097485
Temperature	223.434 °C
Cp	1.097292
Temperature	224.4074 °C
Cp	1.09714
Temperature	225.3808 °C
Cp	1.096991
Temperature	226.3542 °C
Cp	1.096844
Temperature	227.3276 °C
Cp	1.096699
Temperature	228.3009 °C
Cp	1.096559
Temperature	229.2743 °C
Cp	1.096442
Temperature	230.2477 °C
Cp	1.096296
Temperature	231.2211 °C
Cp	1.096164
Temperature	232.1945 °C
Cp	1.09604
Temperature	233.1679 °C
Cp	1.095924
Temperature	234.1413 °C
Cp	1.095807
Temperature	235.1147 °C
Cp	1.095665
Temperature	236.088 °C
Cp	1.095557
Temperature	237.0614 °C
Cp	1.095433
Temperature	238.0348 °C
Cp	1.095296
Temperature	239.0082 °C
Cp	1.095147
Temperature	239.9816 °C
Cp	1.094995
Temperature	240.955 °C
Cp	1.094843
Temperature	241.9283 °C
Cp	1.094705
Temperature	242.9017 °C
Cp	1.094562
Temperature	243.8751 °C
Cp	1.094442
Temperature	244.8485 °C
Cp	1.094344
Temperature	245.8219 °C
Cp	1.094266
Temperature	246.7953 °C
Cp	1.094209
Temperature	247.7687 °C
Cp	1.094161
Temperature	248.7421 °C
Cp	1.094144
Temperature	249.7154 °C
Cp	1.094133
Temperature	250.6888 °C
Cp	1.094127
Temperature	251.6622 °C
Cp	1.094126
Temperature	252.6356 °C
Cp	1.094127
Temperature	253.609 °C
Cp	1.094138
Temperature	254.5824 °C
Cp	1.09413
Temperature	255.5558 °C
Cp	1.094123
Temperature	256.5291 °C
Cp	1.094111
Temperature	257.5025 °C
Cp	1.094087
Temperature	258.4759 °C
Cp	1.094046
Temperature	259.4493 °C
Cp	1.093978
Temperature	260.4227 °C
Cp	1.093895
Temperature	261.3961 °C
Cp	1.093783
Temperature	262.3694 °C
Cp	1.093645
Temperature	263.3428 °C
Cp	1.093483
Temperature	264.3162 °C
Cp	1.093302
Temperature	265.2896 °C
Cp	1.093109
Temperature	266.263 °C
Cp	1.092906
Temperature	267.2364 °C
Cp	1.092704
Temperature	268.2098 °C
Cp	1.092511
Temperature	269.1832 °C
Cp	1.092331
Temperature	270.1566 °C
Cp	1.092174
Temperature	271.1299 °C
Cp	1.092046
Temperature	272.1033 °C
Cp	1.091947
Temperature	273.0767 °C
Cp	1.091882
Temperature	274.0501 °C
Cp	1.091853
Temperature	275.0235 °C
Cp	1.091859
Temperature	275.9969 °C
Cp	1.091895
Temperature	276.9702 °C
Cp	1.091957
Temperature	277.9436 °C
Cp	1.092036
Temperature	278.917 °C
Cp	1.092132
Temperature	279.8904 °C
Cp	1.09223
Temperature	280.8638 °C
Cp	1.092323
Temperature	281.8372 °C
Cp	1.092405
Temperature	282.8105 °C
Cp	1.092468
Temperature	283.7839 °C
Cp	1.092513
Temperature	284.7573 °C
Cp	1.092525
Temperature	285.7307 °C
Cp	1.092512
Temperature	286.7041 °C
Cp	1.092472
Temperature	287.6775 °C
Cp	1.092405
Temperature	288.6509 °C
Cp	1.092313
Temperature	289.6243 °C
Cp	1.092197
Temperature	290.5977 °C
Cp	1.09207
Temperature	291.571 °C
Cp	1.091931
Temperature	292.5444 °C
Cp	1.091785
Temperature	293.5178 °C
Cp	1.091641
Temperature	294.4912 °C
Cp	1.091506
Temperature	295.4646 °C
Cp	1.091387
Temperature	296.438 °C
Cp	1.091282
Temperature	297.4113 °C
Cp	1.091201
Temperature	298.3847 °C
Cp	1.091145
Temperature	299.3581 °C
Cp	1.091112
Temperature	300.3315 °C
Cp	1.091102
Temperature	301.3049 °C
Cp	1.091107
Temperature	302.2783 °C
Cp	1.091137
Temperature	303.2517 °C
Cp	1.091177
Temperature	304.2251 °C
Cp	1.091226
Temperature	305.1984 °C
Cp	1.09128
Temperature	306.1718 °C
Cp	1.091336
Temperature	307.1452 °C
Cp	1.091403
Temperature	308.1186 °C
Cp	1.091453
Temperature	309.092 °C
Cp	1.091506
Temperature	310.0654 °C
Cp	1.091561
Temperature	311.0388 °C
Cp	1.091617
Temperature	312.0121 °C
Cp	1.09167
Temperature	312.9855 °C
Cp	1.091716
Temperature	313.9589 °C
Cp	1.091762
Temperature	314.9323 °C
Cp	1.091805
Temperature	315.9057 °C
Cp	1.091838
Temperature	316.8791 °C
Cp	1.09186
Temperature	317.8524 °C
Cp	1.091871
Temperature	318.8258 °C
Cp	1.091872
Temperature	319.7992 °C
Cp	1.091867
Temperature	320.7726 °C
Cp	1.091838
Temperature	321.746 °C
Cp	1.0918
Temperature	322.7194 °C
Cp	1.091752
Temperature	323.6928 °C
Cp	1.091689
Temperature	324.6662 °C
Cp	1.091611
Temperature	325.6396 °C
Cp	1.091508
Temperature	326.6129 °C
Cp	1.091406
Temperature	327.5863 °C
Cp	1.091285
Temperature	328.5597 °C
Cp	1.09115
Temperature	329.5331 °C
Cp	1.091009
Temperature	330.5065 °C
Cp	1.09087
Temperature	331.4799 °C
Cp	1.090747
Temperature	332.4532 °C
Cp	1.090628
Temperature	333.4266 °C
Cp	1.090536
Temperature	334.4 °C
Cp	1.090472
Temperature	335.3734 °C
Cp	1.090437
Temperature	336.3468 °C
Cp	1.090431
Temperature	337.3202 °C
Cp	1.090455
Temperature	338.2935 °C
Cp	1.090503
Temperature	339.2669 °C
Cp	1.090573
Temperature	340.2403 °C
Cp	1.090658
Temperature	341.2137 °C
Cp	1.090753
Temperature	342.1871 °C
Cp	1.090853
Temperature	343.1605 °C
Cp	1.090952
Temperature	344.1339 °C
Cp	1.09105
Temperature	345.1073 °C
Cp	1.091141
Temperature	346.0807 °C
Cp	1.091225
Temperature	347.054 °C
Cp	1.091303
Temperature	348.0274 °C
Cp	1.091379
Temperature	349.0008 °C
Cp	1.091453
Temperature	349.9742 °C
Cp	1.091537
Temperature	350.9476 °C
Cp	1.091633
Temperature	351.921 °C
Cp	1.091743
Temperature	352.8943 °C
Cp	1.091874
Temperature	353.8677 °C
Cp	1.092028
Temperature	354.8411 °C
Cp	1.092206
Temperature	355.8145 °C
Cp	1.092411
Temperature	356.7879 °C
Cp	1.092628
Temperature	357.7613 °C
Cp	1.092862
Temperature	358.7346 °C
Cp	1.093102
Temperature	359.708 °C
Cp	1.093338
Temperature	360.6814 °C
Cp	1.093559
Temperature	361.6548 °C
Cp	1.093752
Temperature	362.6282 °C
Cp	1.093915
Temperature	363.6016 °C
Cp	1.094036
Temperature	364.575 °C
Cp	1.094117
Temperature	365.5484 °C
Cp	1.094159
Temperature	366.5218 °C
Cp	1.094172
Temperature	367.4951 °C
Cp	1.094165
Temperature	368.4685 °C
Cp	1.094163
Temperature	369.4419 °C
Cp	1.094182
Temperature	370.4153 °C
Cp	1.094244
Temperature	371.3887 °C
Cp	1.094375
Temperature	372.3621 °C
Cp	1.094598
Temperature	373.3354 °C
Cp	1.094937
Temperature	374.3088 °C
Cp	1.095389
Temperature	375.2822 °C
Cp	1.095973
Temperature	376.2556 °C
Cp	1.096685
Temperature	377.229 °C
Cp	1.097506
Temperature	378.2024 °C
Cp	1.098406
Temperature	379.1758 °C
Cp	1.099338
Temperature	380.1492 °C
Cp	1.10027
Temperature	381.1225 °C
Cp	1.10112
Temperature	382.0959 °C
Cp	1.101818
Temperature	383.0693 °C
Cp	1.10229
Temperature	384.0427 °C
Cp	1.102459
Temperature	385.0161 °C
Cp	1.102253
Temperature	385.9895 °C
Cp	1.101596
Temperature	386.9629 °C
Cp	1.100438
Temperature	387.9362 °C
Cp	1.098736
Temperature	388.9096 °C
Cp	1.096461
Temperature	389.883 °C
Cp	1.093614
Temperature	390.8564 °C
Cp	1.090208
Temperature	391.8298 °C
Cp	1.086278
Temperature	392.8032 °C
Cp	1.081887
Temperature	393.7766 °C
Cp	1.077096
Temperature	394.7499 °C
Cp	1.072007
Temperature	395.7233 °C
Cp	1.066707
[Rev Cp Calibration]
Date Applied	24/10/2024 12:37:31
Description	From -89.998 °C to 390.542 °C at 2.000°C/min
Gas Type	Nitrogen
Pan Type	Tzero Aluminum
Source Files 1	C:\ProgramData\TA Instruments\TRIOS\Data\Reverse Heat Capacity Calibration(6).tri
GUID	ba867d72-cfbb-486e-971e-e86aa544cc02
Temperature	-89.99799 °C
Cp	1.070076
Temperature	-89.03691 °C
Cp	1.072008
Temperature	-88.07584 °C
Cp	1.073556
Temperature	-87.11475 °C
Cp	1.074743
Temperature	-86.15367 °C
Cp	1.075597
Temperature	-85.1926 °C
Cp	1.076163
Temperature	-84.23151 °C
Cp	1.076477
Temperature	-83.27043 °C
Cp	1.076579
Temperature	-82.30936 °C
Cp	1.076527
Temperature	-81.34827 °C
Cp	1.076322
Temperature	-80.38719 °C
Cp	1.076039
Temperature	-79.42612 °C
Cp	1.07571
Temperature	-78.46503 °C
Cp	1.075361
Temperature	-77.50395 °C
Cp	1.075011
Temperature	-76.54288 °C
Cp	1.074656
Temperature	-75.58179 °C
Cp	1.074359
Temperature	-74.62071 °C
Cp	1.074086
Temperature	-73.65964 °C
Cp	1.073842
Temperature	-72.69855 °C
Cp	1.073627
Temperature	-71.73747 °C
Cp	1.073442
Temperature	-70.7764 °C
Cp	1.07329
Temperature	-69.81532 °C
Cp	1.073148
Temperature	-68.85423 °C
Cp	1.073021
Temperature	-67.89315 °C
Cp	1.072902
Temperature	-66.93208 °C
Cp	1.072782
Temperature	-65.97099 °C
Cp	1.072656
Temperature	-65.00991 °C
Cp	1.072518
Temperature	-64.04884 °C
Cp	1.072374
Temperature	-63.08775 °C
Cp	1.072201
Temperature	-62.12667 °C
Cp	1.072019
Temperature	-61.1656 °C
Cp	1.071827
Temperature	-60.20451 °C
Cp	1.071624
Temperature	-59.24343 °C
Cp	1.071411
Temperature	-58.28236 °C
Cp	1.071167
Temperature	-57.32127 °C
Cp	1.070956
Temperature	-56.3602 °C
Cp	1.070724
Temperature	-55.39911 °C
Cp	1.070483
Temperature	-54.43803 °C
Cp	1.070242
Temperature	-53.47696 °C
Cp	1.070009
Temperature	-52.51587 °C
Cp	1.069825
Temperature	-51.55479 °C
Cp	1.069601
Temperature	-50.59372 °C
Cp	1.069418
Temperature	-49.63263 °C
Cp	1.069267
Temperature	-48.67155 °C
Cp	1.069138
Temperature	-47.71048 °C
Cp	1.069021
Temperature	-46.74939 °C
Cp	1.068875
Temperature	-45.78831 °C
Cp	1.068771
Temperature	-44.82724 °C
Cp	1.068634
Temperature	-43.86615 °C
Cp	1.068462
Temperature	-42.90508 °C
Cp	1.068255
Temperature	-41.944 °C
Cp	1.068012
Temperature	-40.98291 °C
Cp	1.067742
Temperature	-40.02184 °C
Cp	1.067427
Temperature	-39.06076 °C
Cp	1.067088
Temperature	-38.09967 °C
Cp	1.066727
Temperature	-37.1386 °C
Cp	1.066349
Temperature	-36.17752 °C
Cp	1.065958
Temperature	-35.21643 °C
Cp	1.065559
Temperature	-34.25536 °C
Cp	1.065162
Temperature	-33.29427 °C
Cp	1.06476
Temperature	-32.33319 °C
Cp	1.064368
Temperature	-31.37212 °C
Cp	1.06399
Temperature	-30.41104 °C
Cp	1.063628
Temperature	-29.44995 °C
Cp	1.063283
Temperature	-28.48887 °C
Cp	1.06295
Temperature	-27.5278 °C
Cp	1.062645
Temperature	-26.56672 °C
Cp	1.062355
Temperature	-25.60563 °C
Cp	1.06208
Temperature	-24.64456 °C
Cp	1.061819
Temperature	-23.68348 °C
Cp	1.061573
Temperature	-22.72239 °C
Cp	1.061345
Temperature	-21.76132 °C
Cp	1.061123
Temperature	-20.80024 °C
Cp	1.060915
Temperature	-19.83916 °C
Cp	1.060719
Temperature	-18.87807 °C
Cp	1.060531
Temperature	-17.917 °C
Cp	1.06035
Temperature	-16.95592 °C
Cp	1.060161
Temperature	-15.99484 °C
Cp	1.059992
Temperature	-15.03376 °C
Cp	1.059817
Temperature	-14.07268 °C
Cp	1.059634
Temperature	-13.1116 °C
Cp	1.059445
Temperature	-12.15052 °C
Cp	1.059248
Temperature	-11.18944 °C
Cp	1.059043
Temperature	-10.22836 °C
Cp	1.058842
Temperature	-9.267276 °C
Cp	1.058615
Temperature	-8.306196 °C
Cp	1.058388
Temperature	-7.345116 °C
Cp	1.058155
Temperature	-6.384036 °C
Cp	1.057911
Temperature	-5.422956 °C
Cp	1.057652
Temperature	-4.461876 °C
Cp	1.057356
Temperature	-3.500796 °C
Cp	1.057063
Temperature	-2.539716 °C
Cp	1.056732
Temperature	-1.578636 °C
Cp	1.056364
Temperature	-0.6175562 °C
Cp	1.05596
Temperature	0.3435238 °C
Cp	1.055523
Temperature	1.304604 °C
Cp	1.055066
Temperature	2.265684 °C
Cp	1.054561
Temperature	3.226764 °C
Cp	1.054035
Temperature	4.187844 °C
Cp	1.053488
Temperature	5.148924 °C
Cp	1.052922
Temperature	6.110003 °C
Cp	1.052337
Temperature	7.071084 °C
Cp	1.051736
Temperature	8.032164 °C
Cp	1.051118
Temperature	8.993243 °C
Cp	1.050488
Temperature	9.954324 °C
Cp	1.049848
Temperature	10.9154 °C
Cp	1.049202
Temperature	11.87648 °C
Cp	1.048552
Temperature	12.83756 °C
Cp	1.047902
Temperature	13.79864 °C
Cp	1.047255
Temperature	14.75972 °C
Cp	1.046615
Temperature	15.7208 °C
Cp	1.045983
Temperature	16.68188 °C
Cp	1.045362
Temperature	17.64296 °C
Cp	1.044756
Temperature	18.60404 °C
Cp	1.044164
Temperature	19.56512 °C
Cp	1.04358
Temperature	20.5262 °C
Cp	1.043027
Temperature	21.48728 °C
Cp	1.042485
Temperature	22.44836 °C
Cp	1.041958
Temperature	23.40944 °C
Cp	1.041446
Temperature	24.37052 °C
Cp	1.040952
Temperature	25.3316 °C
Cp	1.040493
Temperature	26.29268 °C
Cp	1.040022
Temperature	27.25376 °C
Cp	1.039578
Temperature	28.21484 °C
Cp	1.039158
Temperature	29.17592 °C
Cp	1.038758
Temperature	30.137 °C
Cp	1.038373
Temperature	31.09808 °C
Cp	1.037981
Temperature	32.05916 °C
Cp	1.03763
Temperature	33.02024 °C
Cp	1.037276
Temperature	33.98132 °C
Cp	1.03692
Temperature	34.9424 °C
Cp	1.036565
Temperature	35.90348 °C
Cp	1.036213
Temperature	36.86456 °C
Cp	1.035866
Temperature	37.82564 °C
Cp	1.035529
Temperature	38.78672 °C
Cp	1.035195
Temperature	39.7478 °C
Cp	1.034875
Temperature	40.70888 °C
Cp	1.034568
Temperature	41.66996 °C
Cp	1.034276
Temperature	42.63104 °C
Cp	1.033996
Temperature	43.59212 °C
Cp	1.033726
Temperature	44.5532 °C
Cp	1.033469
Temperature	45.51428 °C
Cp	1.033221
Temperature	46.47536 °C
Cp	1.03298
Temperature	47.43644 °C
Cp	1.032744
Temperature	48.39752 °C
Cp	1.032514
Temperature	49.3586 °C
Cp	1.032289
Temperature	50.31968 °C
Cp	1.032065
Temperature	51.28076 °C
Cp	1.031844
Temperature	52.24184 °C
Cp	1.031627
Temperature	53.20292 °C
Cp	1.031413
Temperature	54.164 °C
Cp	1.031203
Temperature	55.12508 °C
Cp	1.030989
Temperature	56.08616 °C
Cp	1.030791
Temperature	57.04724 °C
Cp	1.030595
Temperature	58.00832 °C
Cp	1.030403
Temperature	58.9694 °C
Cp	1.030217
Temperature	59.93048 °C
Cp	1.03004
Temperature	60.89156 °C
Cp	1.029871
Temperature	61.85264 °C
Cp	1.029718
Temperature	62.81372 °C
Cp	1.029567
Temperature	63.7748 °C
Cp	1.02943
Temperature	64.73589 °C
Cp	1.029304
Temperature	65.69696 °C
Cp	1.029185
Temperature	66.65804 °C
Cp	1.02907
Temperature	67.61913 °C
Cp	1.028946
Temperature	68.5802 °C
Cp	1.028831
Temperature	69.54128 °C
Cp	1.028703
Temperature	70.50237 °C
Cp	1.028561
Temperature	71.46344 °C
Cp	1.028404
Temperature	72.42452 °C
Cp	1.028234
Temperature	73.3856 °C
Cp	1.028063
Temperature	74.34668 °C
Cp	1.027861
Temperature	75.30776 °C
Cp	1.027657
Temperature	76.26884 °C
Cp	1.027451
Temperature	77.22992 °C
Cp	1.027243
Temperature	78.191 °C
Cp	1.027036
Temperature	79.15208 °C
Cp	1.026812
Temperature	80.11316 °C
Cp	1.026623
Temperature	81.07424 °C
Cp	1.026431
Temperature	82.03532 °C
Cp	1.026241
Temperature	82.9964 °C
Cp	1.02606
Temperature	83.95748 °C
Cp	1.025891
Temperature	84.91856 °C
Cp	1.025739
Temperature	85.87964 °C
Cp	1.025614
Temperature	86.84072 °C
Cp	1.025493
Temperature	87.8018 °C
Cp	1.0254
Temperature	88.76288 °C
Cp	1.025329
Temperature	89.72396 °C
Cp	1.025274
Temperature	90.68504 °C
Cp	1.025229
Temperature	91.64612 °C
Cp	1.025174
Temperature	92.6072 °C
Cp	1.025138
Temperature	93.56828 °C
Cp	1.025083
Temperature	94.52936 °C
Cp	1.025008
Temperature	95.49044 °C
Cp	1.024912
Temperature	96.45152 °C
Cp	1.024796
Temperature	97.4126 °C
Cp	1.024671
Temperature	98.37368 °C
Cp	1.024506
Temperature	99.33476 °C
Cp	1.02433
Temperature	100.2958 °C
Cp	1.024144
Temperature	101.2569 °C
Cp	1.023948
Temperature	102.218 °C
Cp	1.023743
Temperature	103.1791 °C
Cp	1.023522
Temperature	104.1402 °C
Cp	1.023309
Temperature	105.1012 °C
Cp	1.023089
Temperature	106.0623 °C
Cp	1.022866
Temperature	107.0234 °C
Cp	1.022644
Temperature	107.9845 °C
Cp	1.022427
Temperature	108.9456 °C
Cp	1.022218
Temperature	109.9066 °C
Cp	1.022022
Temperature	110.8677 °C
Cp	1.021836
Temperature	111.8288 °C
Cp	1.021666
Temperature	112.7899 °C
Cp	1.021512
Temperature	113.751 °C
Cp	1.021374
Temperature	114.712 °C
Cp	1.02125
Temperature	115.6731 °C
Cp	1.021137
Temperature	116.6342 °C
Cp	1.021041
Temperature	117.5953 °C
Cp	1.020953
Temperature	118.5564 °C
Cp	1.020872
Temperature	119.5174 °C
Cp	1.020796
Temperature	120.4785 °C
Cp	1.020725
Temperature	121.4396 °C
Cp	1.020659
Temperature	122.4007 °C
Cp	1.020587
Temperature	123.3618 °C
Cp	1.020515
Temperature	124.3228 °C
Cp	1.02044
Temperature	125.2839 °C
Cp	1.020359
Temperature	126.245 °C
Cp	1.02027
Temperature	127.2061 °C
Cp	1.020167
Temperature	128.1672 °C
Cp	1.020057
Temperature	129.1282 °C
Cp	1.019933
Temperature	130.0893 °C
Cp	1.019793
Temperature	131.0504 °C
Cp	1.019638
Temperature	132.0115 °C
Cp	1.019471
Temperature	132.9726 °C
Cp	1.019292
Temperature	133.9336 °C
Cp	1.019107
Temperature	134.8947 °C
Cp	1.018912
Temperature	135.8558 °C
Cp	1.018717
Temperature	136.8169 °C
Cp	1.018527
Temperature	137.778 °C
Cp	1.018344
Temperature	138.739 °C
Cp	1.018171
Temperature	139.7001 °C
Cp	1.018004
Temperature	140.6612 °C
Cp	1.01787
Temperature	141.6223 °C
Cp	1.01775
Temperature	142.5834 °C
Cp	1.017652
Temperature	143.5444 °C
Cp	1.017578
Temperature	144.5055 °C
Cp	1.017534
Temperature	145.4666 °C
Cp	1.017536
Temperature	146.4277 °C
Cp	1.017545
Temperature	147.3888 °C
Cp	1.017595
Temperature	148.3498 °C
Cp	1.017679
Temperature	149.3109 °C
Cp	1.01779
Temperature	150.272 °C
Cp	1.01792
Temperature	151.2331 °C
Cp	1.018043
Temperature	152.1942 °C
Cp	1.018199
Temperature	153.1552 °C
Cp	1.018339
Temperature	154.1163 °C
Cp	1.018458
Temperature	155.0774 °C
Cp	1.018552
Temperature	156.0385 °C
Cp	1.018618
Temperature	156.9996 °C
Cp	1.018662
Temperature	157.9606 °C
Cp	1.018664
Temperature	158.9217 °C
Cp	1.018632
Temperature	159.8828 °C
Cp	1.018575
Temperature	160.8439 °C
Cp	1.018492
Temperature	161.805 °C
Cp	1.018383
Temperature	162.766 °C
Cp	1.01825
Temperature	163.7271 °C
Cp	1.018087
Temperature	164.6882 °C
Cp	1.017917
Temperature	165.6493 °C
Cp	1.017726
Temperature	166.6104 °C
Cp	1.017522
Temperature	167.5714 °C
Cp	1.01731
Temperature	168.5325 °C
Cp	1.017098
Temperature	169.4936 °C
Cp	1.016902
Temperature	170.4547 °C
Cp	1.016695
Temperature	171.4158 °C
Cp	1.016508
Temperature	172.3768 °C
Cp	1.016342
Temperature	173.3379 °C
Cp	1.016195
Temperature	174.299 °C
Cp	1.016065
Temperature	175.2601 °C
Cp	1.015927
Temperature	176.2212 °C
Cp	1.015838
Temperature	177.1822 °C
Cp	1.015746
Temperature	178.1433 °C
Cp	1.015651
Temperature	179.1044 °C
Cp	1.015555
Temperature	180.0655 °C
Cp	1.015459
Temperature	181.0266 °C
Cp	1.015401
Temperature	181.9876 °C
Cp	1.015288
Temperature	182.9487 °C
Cp	1.015195
Temperature	183.9098 °C
Cp	1.015117
Temperature	184.8709 °C
Cp	1.01505
Temperature	185.832 °C
Cp	1.014988
Temperature	186.793 °C
Cp	1.014927
Temperature	187.7541 °C
Cp	1.014849
Temperature	188.7152 °C
Cp	1.014789
Temperature	189.6763 °C
Cp	1.01471
Temperature	190.6374 °C
Cp	1.014614
Temperature	191.5984 °C
Cp	1.014503
Temperature	192.5595 °C
Cp	1.014381
Temperature	193.5206 °C
Cp	1.014268
Temperature	194.4817 °C
Cp	1.014122
Temperature	195.4428 °C
Cp	1.013984
Temperature	196.4038 °C
Cp	1.013853
Temperature	197.3649 °C
Cp	1.013726
Temperature	198.326 °C
Cp	1.013603
Temperature	199.2871 °C
Cp	1.013467
Temperature	200.2482 °C
Cp	1.013359
Temperature	201.2092 °C
Cp	1.013243
Temperature	202.1703 °C
Cp	1.013123
Temperature	203.1314 °C
Cp	1.013002
Temperature	204.0925 °C
Cp	1.012884
Temperature	205.0536 °C
Cp	1.012788
Temperature	206.0146 °C
Cp	1.012674
Temperature	206.9757 °C
Cp	1.012579
Temperature	207.9368 °C
Cp	1.012501
Temperature	208.8979 °C
Cp	1.012439
Temperature	209.859 °C
Cp	1.012389
Temperature	210.82 °C
Cp	1.012351
Temperature	211.7811 °C
Cp	1.012312
Temperature	212.7422 °C
Cp	1.01229
Temperature	213.7033 °C
Cp	1.012262
Temperature	214.6644 °C
Cp	1.012227
Temperature	215.6254 °C
Cp	1.012183
Temperature	216.5865 °C
Cp	1.012129
Temperature	217.5476 °C
Cp	1.012077
Temperature	218.5087 °C
Cp	1.01199
Temperature	219.4698 °C
Cp	1.011897
Temperature	220.4308 °C
Cp	1.011793
Temperature	221.3919 °C
Cp	1.011674
Temperature	222.353 °C
Cp	1.011537
Temperature	223.3141 °C
Cp	1.011362
Temperature	224.2752 °C
Cp	1.011194
Temperature	225.2362 °C
Cp	1.010993
Temperature	226.1973 °C
Cp	1.010766
Temperature	227.1584 °C
Cp	1.010517
Temperature	228.1195 °C
Cp	1.010251
Temperature	229.0806 °C
Cp	1.009998
Temperature	230.0416 °C
Cp	1.009703
Temperature	231.0027 °C
Cp	1.009422
Temperature	231.9638 °C
Cp	1.009156
Temperature	232.9249 °C
Cp	1.008906
Temperature	233.886 °C
Cp	1.008675
Temperature	234.847 °C
Cp	1.008462
Temperature	235.8081 °C
Cp	1.008258
Temperature	236.7692 °C
Cp	1.00809
Temperature	237.7303 °C
Cp	1.007934
Temperature	238.6914 °C
Cp	1.007793
Temperature	239.6524 °C
Cp	1.007668
Temperature	240.6135 °C
Cp	1.007562
Temperature	241.5746 °C
Cp	1.007487
Temperature	242.5357 °C
Cp	1.00741
Temperature	243.4967 °C
Cp	1.00736
Temperature	244.4578 °C
Cp	1.007332
Temperature	245.4189 °C
Cp	1.007321
Temperature	246.38 °C
Cp	1.007321
Temperature	247.3411 °C
Cp	1.007312
Temperature	248.3022 °C
Cp	1.007331
Temperature	249.2632 °C
Cp	1.007338
Temperature	250.2243 °C
Cp	1.007335
Temperature	251.1854 °C
Cp	1.00732
Temperature	252.1465 °C
Cp	1.007295
Temperature	253.1076 °C
Cp	1.007277
Temperature	254.0686 °C
Cp	1.007227
Temperature	255.0297 °C
Cp	1.007179
Temperature	255.9908 °C
Cp	1.007133
Temperature	256.9519 °C
Cp	1.00709
Temperature	257.913 °C
Cp	1.007049
Temperature	258.874 °C
Cp	1.007012
Temperature	259.8351 °C
Cp	1.006978
Temperature	260.7962 °C
Cp	1.006956
Temperature	261.7573 °C
Cp	1.00694
Temperature	262.7184 °C
Cp	1.006934
Temperature	263.6794 °C
Cp	1.006939
Temperature	264.6405 °C
Cp	1.00696
Temperature	265.6016 °C
Cp	1.006999
Temperature	266.5627 °C
Cp	1.007054
Temperature	267.5237 °C
Cp	1.007131
Temperature	268.4848 °C
Cp	1.00723
Temperature	269.4459 °C
Cp	1.00735
Temperature	270.407 °C
Cp	1.007493
Temperature	271.3681 °C
Cp	1.007656
Temperature	272.3292 °C
Cp	1.007839
Temperature	273.2902 °C
Cp	1.008039
Temperature	274.2513 °C
Cp	1.008257
Temperature	275.2124 °C
Cp	1.008488
Temperature	276.1735 °C
Cp	1.008731
Temperature	277.1346 °C
Cp	1.008977
Temperature	278.0956 °C
Cp	1.009237
Temperature	279.0567 °C
Cp	1.009498
Temperature	280.0178 °C
Cp	1.009757
Temperature	280.9789 °C
Cp	1.010014
Temperature	281.9399 °C
Cp	1.010267
Temperature	282.901 °C
Cp	1.010515
Temperature	283.8621 °C
Cp	1.01076
Temperature	284.8232 °C
Cp	1.010993
Temperature	285.7843 °C
Cp	1.011222
Temperature	286.7454 °C
Cp	1.011447
Temperature	287.7064 °C
Cp	1.011665
Temperature	288.6675 °C
Cp	1.011876
Temperature	289.6286 °C
Cp	1.012079
Temperature	290.5897 °C
Cp	1.01228
Temperature	291.5508 °C
Cp	1.012474
Temperature	292.5118 °C
Cp	1.012662
Temperature	293.4729 °C
Cp	1.012846
Temperature	294.434 °C
Cp	1.013028
Temperature	295.3951 °C
Cp	1.013211
Temperature	296.3561 °C
Cp	1.013391
Temperature	297.3172 °C
Cp	1.013574
Temperature	298.2783 °C
Cp	1.013759
Temperature	299.2394 °C
Cp	1.013947
Temperature	300.2005 °C
Cp	1.014136
Temperature	301.1616 °C
Cp	1.01432
Temperature	302.1226 °C
Cp	1.014511
Temperature	303.0837 °C
Cp	1.014695
Temperature	304.0448 °C
Cp	1.014872
Temperature	305.0059 °C
Cp	1.01504
Temperature	305.9669 °C
Cp	1.015198
Temperature	306.928 °C
Cp	1.015343
Temperature	307.8891 °C
Cp	1.015479
Temperature	308.8502 °C
Cp	1.015595
Temperature	309.8113 °C
Cp	1.015699
Temperature	310.7724 °C
Cp	1.015789
Temperature	311.7334 °C
Cp	1.015865
Temperature	312.6945 °C
Cp	1.015925
Temperature	313.6556 °C
Cp	1.015964
Temperature	314.6167 °C
Cp	1.015999
Temperature	315.5778 °C
Cp	1.016018
Temperature	316.5388 °C
Cp	1.016025
Temperature	317.4999 °C
Cp	1.016024
Temperature	318.461 °C
Cp	1.01602
Temperature	319.4221 °C
Cp	1.016029
Temperature	320.3831 °C
Cp	1.016025
Temperature	321.3442 °C
Cp	1.016037
Temperature	322.3053 °C
Cp	1.016066
Temperature	323.2664 °C
Cp	1.01611
Temperature	324.2275 °C
Cp	1.016169
Temperature	325.1886 °C
Cp	1.016225
Temperature	326.1496 °C
Cp	1.016318
Temperature	327.1107 °C
Cp	1.016411
Temperature	328.0718 °C
Cp	1.016504
Temperature	329.0329 °C
Cp	1.016596
Temperature	329.994 °C
Cp	1.016687
Temperature	330.955 °C
Cp	1.016775
Temperature	331.9161 °C
Cp	1.016864
Temperature	332.8772 °C
Cp	1.016942
Temperature	333.8383 °C
Cp	1.017019
Temperature	334.7993 °C
Cp	1.017093
Temperature	335.7604 °C
Cp	1.017163
Temperature	336.7215 °C
Cp	1.01723
Temperature	337.6826 °C
Cp	1.017295
Temperature	338.6437 °C
Cp	1.017358
Temperature	339.6048 °C
Cp	1.017423
Temperature	340.5658 °C
Cp	1.017491
Temperature	341.5269 °C
Cp	1.017567
Temperature	342.488 °C
[...]
133.7800	111.1150	0.3639
133.7883	111.0320	0.3639
133.7967	110.9496	0.3638
133.8050	110.8664	0.3638
133.8133	110.7829	0.3637
133.8217	110.7008	0.3635
133.8300	110.6164	0.3635
133.8383	110.5325	0.3635
133.8467	110.4505	0.3635
133.8550	110.3677	0.3635
133.8633	110.2839	0.3635
133.8717	110.2015	0.3634
133.8800	110.1186	0.3634
133.8883	110.0354	0.3634
133.8967	109.9523	0.3634
133.9050	109.8701	0.3633
133.9133	109.7860	0.3633
133.9217	109.7022	0.3633
133.9300	109.6189	0.3633
133.9383	109.5366	0.3632
133.9467	109.4531	0.3632
133.9550	109.3694	0.3631
133.9633	109.2860	0.3631
133.9717	109.2031	0.3631
133.9800	109.1200	0.3630
133.9883	109.0374	0.3630
133.9967	108.9536	0.3630
134.0050	108.8705	0.3630
134.0133	108.7871	0.3630
134.0217	108.7041	0.3628
134.0300	108.6213	0.3627
134.0383	108.5385	0.3628
134.0467	108.4546	0.3628
134.0550	108.3715	0.3628
134.0633	108.2884	0.3627
134.0717	108.2053	0.3627
134.0800	108.1220	0.3627
134.0883	108.0406	0.3627
134.0967	107.9560	0.3627
134.1050	107.8731	0.3627
134.1133	107.7892	0.3626
134.1217	107.7075	0.3625
134.1300	107.6240	0.3625
134.1383	107.5404	0.3625
134.1467	107.4585	0.3625
134.1550	107.3751	0.3624
134.1633	107.2914	0.3625
134.1717	107.2081	0.3624
134.1800	107.1245	0.3624
134.1883	107.0418	0.3622
134.1967	106.9584	0.3622
134.2050	106.8763	0.3622
134.2133	106.7927	0.3622
134.2217	106.7092	0.3622
134.2300	106.6258	0.3622
134.2383	106.5423	0.3621
134.2467	106.4588	0.3621
134.2550	106.3756	0.3621
134.2633	106.2935	0.3621
134.2717	106.2102	0.3621
134.2800	106.1267	0.3620
134.2883	106.0429	0.3620
134.2967	105.9604	0.3620
134.3050	105.8780	0.3620
134.3133	105.7942	0.3619
134.3217	105.7103	0.3619
134.3300	105.6287	0.3619
134.3383	105.5459	0.3619
134.3467	105.4617	0.3618
134.3550	105.3789	0.3618
134.3633	105.2952	0.3618
134.3717	105.2123	0.3618
134.3800	105.1303	0.3617
134.3883	105.0453	0.3617
134.3967	104.9623	0.3617
134.4050	104.8800	0.3617
134.4133	104.7964	0.3616
134.4217	104.7133	0.3616
134.4300	104.6303	0.3615
134.4383	104.5469	0.3615
134.4467	104.4645	0.3615
134.4550	104.3812	0.3615
134.4633	104.2977	0.3614
134.4717	104.2152	0.3614
134.4800	104.1324	0.3613
134.4883	104.0479	0.3613
134.4967	103.9653	0.3613
134.5050	103.8824	0.3612
134.5133	103.7992	0.3611
134.5217	103.7168	0.3611
134.5300	103.6331	0.3611
134.5383	103.5495	0.3610
134.5467	103.4671	0.3610
134.5550	103.3831	0.3610
134.5633	103.3005	0.3610
134.5717	103.2174	0.3609
134.5800	103.1342	0.3609
134.5883	103.0513	0.3609
134.5967	102.9675	0.3609
134.6050	102.8854	0.3609
134.6133	102.8010	0.3608
134.6217	102.7178	0.3607
134.6300	102.6354	0.3607
134.6383	102.5520	0.3607
134.6467	102.4681	0.3607
134.6550	102.3857	0.3606
134.6633	102.3025	0.3606
134.6717	102.2185	0.3606
134.6800	102.1349	0.3606
134.6883	102.0524	0.3606
134.6967	101.9705	0.3605
134.7050	101.8871	0.3605
134.7133	101.8033	0.3605
134.7217	101.7202	0.3604
134.7300	101.6372	0.3604
134.7383	101.5535	0.3604
134.7467	101.4713	0.3603
134.7550	101.3884	0.3602
134.7633	101.3042	0.3602
134.7717	101.2217	0.3602
134.7800	101.1382	0.3602
134.7883	101.0552	0.3601
134.7967	100.9723	0.3601
134.8050	100.8880	0.3600
134.8133	100.8056	0.3600
134.8217	100.7231	0.3600
134.8300	100.6400	0.3600
134.8383	100.5565	0.3599
134.8467	100.4727	0.3599
134.8550	100.3897	0.3599
134.8633	100.3065	0.3599
134.8717	100.2242	0.3598
134.8800	100.1411	0.3598
134.8883	100.0577	0.3598
134.8967	99.9742	0.3597
134.9050	99.8901	0.3597
134.9133	99.8077	0.3596
134.9217	99.7248	0.3596
134.9300	99.6410	0.3596
134.9383	99.5576	0.3596
134.9467	99.4749	0.3596
134.9550	99.3916	0.3595
134.9633	99.3087	0.3595
134.9717	99.2260	0.3595
134.9800	99.1431	0.3594
134.9883	99.0597	0.3593
134.9967	98.9760	0.3593
135.0050	98.8931	0.3593
135.0133	98.8099	0.3592
135.0217	98.7271	0.3592
135.0300	98.6440	0.3591
135.0383	98.5604	0.3591
135.0467	98.4772	0.3591
135.0550	98.3933	0.3591
135.0633	98.3111	0.3590
135.0717	98.2286	0.3590
135.0800	98.1455	0.3589
135.0883	98.0606	0.3589
135.0967	97.9780	0.3588
135.1050	97.8954	0.3588
135.1133	97.8112	0.3588
135.1217	97.7296	0.3587
135.1300	97.6453	0.3587
135.1383	97.5609	0.3587
135.1467	97.4787	0.3586
135.1550	97.3968	0.3586
135.1633	97.3122	0.3586
135.1717	97.2289	0.3586
135.1800	97.1467	0.3585
135.1883	97.0628	0.3585
135.1967	96.9806	0.3584
135.2050	96.8959	0.3584
135.2133	96.8134	0.3584
135.2217	96.7308	0.3583
135.2300	96.6471	0.3583
135.2383	96.5637	0.3582
135.2467	96.4819	0.3582
135.2550	96.3981	0.3581
135.2633	96.3152	0.3581
135.2717	96.2332	0.3581
135.2800	96.1487	0.3580
135.2883	96.0651	0.3580
135.2967	95.9817	0.3579
135.3050	95.8997	0.3579
135.3133	95.8159	0.3579
135.3217	95.7344	0.3578
135.3300	95.6494	0.3578
135.3383	95.5669	0.3576
135.3467	95.4832	0.3575
135.3550	95.4006	0.3575
135.3633	95.3178	0.3575
135.3717	95.2353	0.3575
135.3800	95.1506	0.3574
135.3883	95.0675	0.3574
135.3967	94.9856	0.3574
135.4050	94.9026	0.3573
135.4133	94.8182	0.3573
135.4217	94.7353	0.3573
135.4300	94.6519	0.3572
135.4383	94.5694	0.3572
135.4467	94.4856	0.3571
135.4550	94.4026	0.3571
135.4633	94.3205	0.3570
135.4717	94.2373	0.3570
135.4800	94.1544	0.3570
135.4883	94.0706	0.3569
135.4967	93.9874	0.3569
135.5050	93.9038	0.3569
135.5133	93.8216	0.3569
135.5217	93.7369	0.3568
135.5300	93.6544	0.3568
135.5383	93.5710	0.3568
135.5467	93.4889	0.3567
135.5550	93.4051	0.3567
135.5633	93.3215	0.3567
135.5717	93.2381	0.3566
135.5800	93.1551	0.3566
135.5883	93.0728	0.3566
135.5967	92.9895	0.3565
135.6050	92.9057	0.3565
135.6133	92.8233	0.3565
135.6217	92.7396	0.3564
135.6300	92.6568	0.3564
135.6383	92.5751	0.3564
135.6467	92.4910	0.3564
135.6550	92.4065	0.3564
135.6633	92.3246	0.3563
135.6717	92.2412	0.3563
135.6800	92.1585	0.3563
135.6883	92.0747	0.3562
135.6967	91.9913	0.3562
135.7050	91.9087	0.3561
135.7133	91.8258	0.3561
135.7217	91.7432	0.3561
135.7300	91.6601	0.3560
135.7383	91.5771	0.3560
135.7467	91.4928	0.3559
135.7550	91.4095	0.3559
135.7633	91.3260	0.3558
135.7717	91.2442	0.3558
135.7800	91.1601	0.3558
135.7883	91.0766	0.3558
135.7967	90.9949	0.3557
135.8050	90.9107	0.3557
135.8133	90.8280	0.3557
135.8217	90.7451	0.3557
135.8300	90.6623	0.3556
135.8383	90.5786	0.3556
135.8467	90.4956	0.3555
135.8550	90.4132	0.3555
135.8633	90.3290	0.3555
135.8717	90.2455	0.3554
135.8800	90.1629	0.3554
135.8883	90.0795	0.3554
135.8967	89.9962	0.3554
135.9050	89.9123	0.3553
135.9133	89.8294	0.3553
135.9217	89.7465	0.3552
135.9300	89.6630	0.3552
135.9383	89.5797	0.3552
135.9467	89.4972	0.3552
135.9550	89.4139	0.3551
135.9633	89.3307	0.3551
135.9717	89.2483	0.3551
135.9800	89.1637	0.3550
135.9883	89.0812	0.3550
135.9967	88.9977	0.3550
136.0050	88.9155	0.3550
136.0133	88.8318	0.3549
136.0217	88.7491	0.3549
136.0300	88.6659	0.3549
136.0383	88.5829	0.3548
136.0467	88.4994	0.3548
136.0550	88.4164	0.3548
136.0633	88.3332	0.3547
136.0717	88.2500	0.3547
136.0800	88.1676	0.3546
136.0883	88.0846	0.3546
136.0967	88.0002	0.3546
136.1050	87.9165	0.3545
136.1133	87.8337	0.3545
136.1217	87.7517	0.3545
136.1300	87.6674	0.3544
136.1383	87.5839	0.3544
136.1467	87.5018	0.3544
136.1550	87.4185	0.3544
136.1633	87.3354	0.3559
136.1717	87.2532	0.3612
136.1800	87.1701	0.3603
136.1883	87.0871	0.3594
136.1967	87.0048	0.3589
136.2050	86.9208	0.3583
136.2133	86.8384	0.3582
136.2217	86.7558	0.3580
136.2300	86.6711	0.3573
136.2383	86.5890	0.3566
136.2467	86.5071	0.3563
136.2550	86.4234	0.3562
136.2633	86.3393	0.3561
136.2717	86.2572	0.3560
136.2800	86.1738	0.3559
136.2883	86.0906	0.3558
136.2967	86.0072	0.3557
136.3050	85.9234	0.3556
136.3133	85.8409	0.3556
136.3217	85.7573	0.3555
136.3300	85.6737	0.3555
136.3383	85.5906	0.3553
136.3467	85.5075	0.3553
136.3550	85.4235	0.3552
136.3633	85.3419	0.3552
136.3717	85.2574	0.3551
136.3800	85.1744	0.3549
136.3883	85.0909	0.3549
136.3967	85.0081	0.3548
136.4050	84.9249	0.3548
136.4133	84.8426	0.3547
136.4217	84.7586	0.3547
136.4300	84.6743	0.3546
136.4383	84.5926	0.3545
136.4467	84.5091	0.3544
136.4550	84.4263	0.3544
136.4633	84.3432	0.3543
136.4717	84.2592	0.3543
136.4800	84.1763	0.3542
136.4883	84.0938	0.3542
136.4967	84.0095	0.3541
136.5050	83.9275	0.3541
136.5133	83.8448	0.3541
136.5217	83.7610	0.3540
136.5300	83.6782	0.3539
136.5383	83.5957	0.3539
136.5467	83.5110	0.3539
136.5550	83.4277	0.3538
136.5633	83.3447	0.3538
136.5717	83.2621	0.3537
136.5800	83.1788	0.3537
136.5883	83.0967	0.3536
136.5967	83.0119	0.3536
136.6050	82.9296	0.3536
136.6133	82.8464	0.3535
136.6217	82.7643	0.3534
136.6300	82.6798	0.3534
136.6383	82.5961	0.3532
136.6467	82.5135	0.3532
136.6550	82.4317	0.3531
136.6633	82.3477	0.3531
136.6717	82.2640	0.3530
136.6800	82.1819	0.3530
136.6883	82.0978	0.3529
136.6967	82.0147	0.3529
136.7050	81.9308	0.3529
136.7133	81.8483	0.3528
136.7217	81.7649	0.3528
136.7300	81.6818	0.3527
136.7383	81.5985	0.3527
136.7467	81.5156	0.3526
136.7550	81.4318	0.3526
136.7633	81.3490	0.3526
136.7717	81.2683	0.3525
136.7800	81.1834	0.3525
136.7883	81.0986	0.3523
136.7967	81.0162	0.3523
136.8050	80.9325	0.3523
136.8133	80.8507	0.3522
136.8217	80.7672	0.3522
136.8300	80.6843	0.3522
136.8383	80.6021	0.3521
136.8467	80.5170	0.3521
136.8550	80.4348	0.3520
136.8633	80.3505	0.3520
136.8717	80.2676	0.3520
136.8800	80.1845	0.3519
136.8883	80.1011	0.3519
136.8967	80.0187	0.3519
136.9050	79.9354	0.3518
136.9133	79.8518	0.3518
136.9217	79.7691	0.3517
136.9300	79.6852	0.3517
136.9383	79.6036	0.3516
136.9467	79.5208	0.3516
136.9550	79.4377	0.3516
136.9633	79.3537	0.3515
136.9717	79.2706	0.3515
136.9800	79.1872	0.3514
136.9883	79.1052	0.3514
136.9967	79.0211	0.3513
137.0050	78.9376	0.3512
137.0133	78.8551	0.3512
137.0217	78.7715	0.3511
137.0300	78.6875	0.3511
137.0383	78.6060	0.3511
137.0467	78.5230	0.3511
137.0550	78.4386	0.3510
137.0633	78.3558	0.3510
137.0717	78.2732	0.3509
137.0800	78.1886	0.3509
137.0883	78.1063	0.3507
137.0967	78.0227	0.3507
137.1050	77.9401	0.3507
137.1133	77.8571	0.3507
137.1217	77.7736	0.3506
137.1300	77.6903	0.3506
137.1383	77.6070	0.3506
137.1467	77.5232	0.3505
137.1550	77.4404	0.3503
137.1633	77.3565	0.3503
137.1717	77.2744	0.3503
137.1800	77.1925	0.3502
137.1883	77.1070	0.3502
137.1967	77.0247	0.3501
137.2050	76.9414	0.3501
137.2133	76.8582	0.3501
137.2217	76.7748	0.3501
137.2300	76.6931	0.3500
137.2383	76.6095	0.3499
137.2467	76.5261	0.3499
137.2550	76.4425	0.3498
137.2633	76.3599	0.3498
137.2717	76.2759	0.3498
137.2800	76.1941	0.3497
137.2883	76.1099	0.3497
137.2967	76.0270	0.3497
137.3050	75.9444	0.3497
137.3133	75.8605	0.3496
137.3217	75.7773	0.3496
137.3300	75.6949	0.3495
137.3383	75.6112	0.3495
137.3467	75.5281	0.3495
137.3550	75.4446	0.3492
137.3633	75.3619	0.3492
137.3717	75.2793	0.3492
137.3800	75.1958	0.3492
137.3883	75.1132	0.3492
137.3967	75.0294	0.3492
137.4050	74.9465	0.3491
137.4133	74.8632	0.3491
137.4217	74.7810	0.3490
137.4300	74.6979	0.3490
137.4383	74.6153	0.3490
137.4467	74.5307	0.3490
137.4550	74.4472	0.3489
137.4633	74.3658	0.3488
137.4717	74.2824	0.3487
137.4800	74.1997	0.3487
137.4883	74.1161	0.3487
137.4967	74.0335	0.3486
137.5050	73.9499	0.3485
137.5133	73.8686	0.3485
137.5217	73.7844	0.3485
137.5300	73.7019	0.3484
137.5383	73.6177	0.3483
137.5467	73.5348	0.3482
137.5550	73.4515	0.3482
137.5633	73.3696	0.3482
137.5717	73.2863	0.3481
137.5800	73.2030	0.3481
137.5883	73.1197	0.3481
137.5967	73.0370	0.3480
137.6050	72.9539	0.3480
137.6133	72.8714	0.3480
137.6217	72.7875	0.3479
137.6300	72.7048	0.3479
137.6383	72.6211	0.3478
137.6467	72.5377	0.3478
137.6550	72.4556	0.3478
137.6633	72.3723	0.3477
137.6717	72.2888	0.3477
137.6800	72.2057	0.3477
137.6883	72.1237	0.3476
137.6967	72.0389	0.3476
137.7050	71.9563	0.3475
137.7133	71.8728	0.3475
137.7217	71.7900	0.3475
137.7300	71.7055	0.3475
137.7383	71.6230	0.3474
137.7467	71.5402	0.3474
137.7550	71.4563	0.3473
137.7633	71.3732	0.3473
137.7717	71.2907	0.3473
137.7800	71.2069	0.3472
137.7883	71.1240	0.3472
137.7967	71.0410	0.3472
137.8050	70.9576	0.3472
137.8133	70.8745	0.3471
137.8217	70.7921	0.3471
137.8300	70.7082	0.3471
137.8383	70.6256	0.3471
137.8467	70.5414	0.3470
137.8550	70.4584	0.3470
137.8633	70.3765	0.3469
137.8717	70.2922	0.3469
137.8800	70.2091	0.3469
137.8883	70.1258	0.3469
137.8967	70.0429	0.3468
137.9050	69.9592	0.3468
137.9133	69.8765	0.3468
137.9217	69.7933	0.3468
137.9300	69.7094	0.3467
137.9383	69.6273	0.3467
137.9467	69.5440	0.3466
137.9550	69.4598	0.3466
137.9633	69.3757	0.3467
137.9717	69.2940	0.3466
137.9800	69.2097	0.3466
137.9883	69.1271	0.3465
137.9967	69.0433	0.3465
138.0050	68.9604	0.3465
138.0133	68.8780	0.3465
138.0217	68.7940	0.3464
138.0300	68.7109	0.3464
138.0383	68.6281	0.3464
138.0467	68.5450	0.3463
138.0550	68.4620	0.3463
138.0633	68.3796	0.3463
138.0717	68.2954	0.3463
138.0800	68.2126	0.3463
138.0883	68.1290	0.3462
138.0967	68.0459	0.3462
138.1050	67.9629	0.3462
138.1133	67.8797	0.3462
138.1217	67.7972	0.3463
138.1300	67.7136	0.3463
138.1383	67.6319	0.3463
138.1467	67.5469	0.3469
138.1550	67.4636	0.3478
138.1633	67.3814	0.3497
138.1717	67.2993	0.3517
138.1800	67.2176	0.3533
138.1883	67.1345	0.3576
138.1967	67.0523	0.3608
138.2050	66.9715	0.3671
138.2133	66.8894	0.3742
138.2217	66.8104	0.3842
138.2300	66.7314	0.3979
138.2383	66.6529	0.4164
138.2467	66.5777	0.4404
138.2550	66.5045	0.4731
138.2633	66.4343	0.5145
138.2717	66.3686	0.5678
138.2800	66.3073	0.6333
138.2883	66.2541	0.7124
138.2967	66.2045	0.8041
138.3050	66.1647	0.9061
138.3133	66.1304	1.0163
138.3217	66.1073	1.1302
138.3300	66.0895	1.2449
138.3383	66.0755	1.3559
138.3467	66.0679	1.4596
138.3550	66.0640	1.5570
138.3633	66.0599	1.6456
138.3717	66.0573	1.7235
138.3800	66.0559	1.7949
138.3883	66.0518	1.8589
138.3967	66.0452	1.9169
138.4050	66.0378	1.9686
138.4133	66.0300	2.0175
138.4217	66.0162	2.0621
138.4300	66.0032	2.1043
138.4383	65.9843	2.1436
138.4467	65.9643	2.1816
138.4550	65.9410	2.2187
138.4633	65.9156	2.2529
138.4717	65.8900	2.2866
138.4800	65.8589	2.3198
138.4883	65.8287	2.3516
138.4967	65.7950	2.3827
138.5050	65.7600	2.4139
138.5133	65.7241	2.4437
138.5217	65.6854	2.4723
138.5300	65.6453	2.4998
138.5383	65.6047	2.5275
138.5467	65.5620	2.5551
138.5550	65.5196	2.5813
138.5633	65.4754	2.6061
138.5717	65.4280	2.6321
138.5800	65.3806	2.6549
138.5883	65.3339	2.6771
138.5967	65.2828	2.6980
138.6050	65.2335	2.7200
138.6133	65.1815	2.7413
138.6217	65.1299	2.7598
138.6300	65.0769	2.7779
138.6383	65.0211	2.7950
138.6467	64.9652	2.8112
138.6550	64.9088	2.8260
138.6633	64.8508	2.8392
138.6717	64.7924	2.8522
138.6800	64.7305	2.8647
138.6883	64.6699	2.8756
138.6967	64.6072	2.8867
138.7050	64.5450	2.8942
138.7133	64.4803	2.9032
138.7217	64.4144	2.9101
138.7300	64.3487	2.9153
138.7383	64.2801	2.9192
138.7467	64.2119	2.9232
138.7550	64.1421	2.9263
138.7633	64.0701	2.9276
138.7717	63.9986	2.9276
138.7800	63.9257	2.9275
138.7883	63.8514	2.9264
138.7967	63.7758	2.9235
138.8050	63.6997	2.9204
138.8133	63.6220	2.9148
138.8217	63.5441	2.9088
138.8300	63.4636	2.9018
138.8383	63.3824	2.8925
138.8467	63.3006	2.8833
138.8550	63.2177	2.8712
138.8633	63.1326	2.8597
138.8717	63.0469	2.8467
138.8800	62.9592	2.8306
138.8883	62.8721	2.8137
138.8967	62.7820	2.7950
138.9050	62.6896	2.7738
138.9133	62.5976	2.7523
138.9217	62.5029	2.7276
138.9300	62.4078	2.7018
138.9383	62.3098	2.6763
138.9467	62.2107	2.6483
138.9550	62.1105	2.6191
138.9633	62.0083	2.5893
138.9717	61.9050	2.5595
138.9800	61.8014	2.5288
138.9883	61.6959	2.4987
138.9967	61.5889	2.4674
139.0050	61.4811	2.4356
139.0133	61.3735	2.4025
139.0217	61.2643	2.3721
139.0300	61.1534	2.3412
139.0383	61.0430	2.3107
139.0467	60.9303	2.2790
139.0550	60.8193	2.2474
139.0633	60.7081	2.2182
139.0717	60.5960	2.1881
139.0800	60.4835	2.1607
139.0883	60.3706	2.1347
139.0967	60.2583	2.1066
139.1050	60.1458	2.0745
139.1133	60.0333	2.0425
139.1217	59.9174	2.0108
139.1300	59.8042	1.9796
139.1383	59.6905	1.9492
139.1467	59.5751	1.9183
139.1550	59.4603	1.8874
139.1633	59.3462	1.8564
139.1717	59.2309	1.8257
139.1800	59.1164	1.7943
139.1883	59.0008	1.7635
139.1967	58.8865	1.7339
139.2050	58.7709	1.7027
139.2133	58.6548	1.6728
139.2217	58.5403	1.6410
139.2300	58.4236	1.6124
139.2383	58.3070	1.5825
139.2467	58.1928	1.5531
139.2550	58.0781	1.5248
139.2633	57.9627	1.4968
139.2717	57.8469	1.4694
139.2800	57.7321	1.4431
139.2883	57.6193	1.4166
139.2967	57.5045	1.3909
139.3050	57.3903	1.3667
139.3133	57.2778	1.3414
139.3217	57.1650	1.3186
139.3300	57.0521	1.2963
139.3383	56.9412	1.2733
139.3467	56.8295	1.2509
139.3550	56.7179	1.2294
139.3633	56.6080	1.2083
139.3717	56.4984	1.1878
139.3800	56.3892	1.1693
139.3883	56.2798	1.1507
139.3967	56.1717	1.1320
139.4050	56.0638	1.1131
139.4133	55.9564	1.0954
139.4217	55.8502	1.0788
139.4300	55.7447	1.0631
139.4383	55.6385	1.0473
139.4467	55.5338	1.0320
139.4550	55.4299	1.0178
139.4633	55.3252	1.0031
139.4717	55.2227	0.9881
139.4800	55.1195	0.9748
139.4883	55.0169	0.9626
139.4967	54.9152	0.9494
139.5050	54.8136	0.9370
139.5133	54.7128	0.9240
139.5217	54.6120	0.9135
139.5300	54.5133	0.9024
139.5383	54.4137	0.8913
139.5467	54.3150	0.8806
139.5550	54.2173	0.8700
139.5633	54.1192	0.8595
139.5717	54.0210	0.8501
139.5800	53.9235	0.8411
139.5883	53.8271	0.8310
139.5967	53.7304	0.8211
139.6050	53.6341	0.8132
139.6133	53.5390	0.8039
139.6217	53.4445	0.7967
139.6300	53.3468	0.7878
139.6383	53.2528	0.7793
139.6467	53.1593	0.7719
139.6550	53.0649	0.7643
139.6633	52.9698	0.7572
139.6717	52.8752	0.7495
139.6800	52.7829	0.7425
139.6883	52.6904	0.7356
139.6967	52.5967	0.7293
139.7050	52.5046	0.7221
139.7133	52.4123	0.7164
139.7217	52.3206	0.7100
139.7300	52.2287	0.7038
139.7383	52.1367	0.6978
139.7467	52.0459	0.6917
139.7550	51.9552	0.6862
139.7633	51.8639	0.6806
139.7717	51.7726	0.6756
139.7800	51.6827	0.6705
139.7883	51.5922	0.6649
139.7967	51.5003	0.6595
139.8050	51.4118	0.6550
139.8133	51.3224	0.6500
139.8217	51.2335	0.6463
139.8300	51.1427	0.6414
139.8383	51.0539	0.6358
139.8467	50.9642	0.6324
139.8550	50.8750	0.6277
139.8633	50.7860	0.6239
139.8717	50.6976	0.6199
139.8800	50.6091	0.6166
139.8883	50.5202	0.6118
139.8967	50.4311	0.6085
139.9050	50.3427	0.6053
139.9133	50.2552	0.6011
139.9217	50.1654	0.5980
139.9300	50.0768	0.5941
139.9383	49.9896	0.5908
139.9467	49.9016	0.5873
139.9550	49.8152	0.5838
139.9633	49.7291	0.5815
139.9717	49.6408	0.5783
139.9800	49.5535	0.5758
139.9883	49.4663	0.5725
139.9967	49.3793	0.5686
140.0050	49.2910	0.5663
140.0133	49.2047	0.5641
140.0217	49.1178	0.5610
140.0300	49.0312	0.5582
140.0383	48.9446	0.5558
140.0467	48.8571	0.5541
140.0550	48.7708	0.5503
140.0633	48.6845	0.5470
140.0717	48.5988	0.5462
140.0800	48.5114	0.5435
140.0883	48.4253	0.5405
140.0967	48.3402	0.5387
140.1050	48.2523	0.5369
140.1133	48.1666	0.5342
140.1217	48.0812	0.5313
140.1300	47.9940	0.5293
140.1383	47.9092	0.5272
140.1467	47.8229	0.5257
140.1550	47.7360	0.5236
140.1633	47.6505	0.5213
140.1717	47.5656	0.5191
140.1800	47.4791	0.5167
140.1883	47.3940	0.5151
140.1967	47.3083	0.5138
140.2050	47.2231	0.5114
140.2133	47.1371	0.5098
140.2217	47.0527	0.5078
140.2300	46.9662	0.5061
140.2383	46.8803	0.5040
140.2467	46.7955	0.5023
140.2550	46.7106	0.5016
140.2633	46.6240	0.4989
140.2717	46.5397	0.4967
140.2800	46.4548	0.4962
140.2883	46.3687	0.4942
140.2967	46.2842	0.4923
140.3050	46.1980	0.4906
140.3133	46.1140	0.4891
140.3217	46.0290	0.4879
140.3300	45.9434	0.4861
140.3383	45.8585	0.4849
140.3467	45.7731	0.4837
140.3550	45.6888	0.4821
140.3633	45.6043	0.4799
140.3717	45.5185	0.4791
140.3800	45.4336	0.4779
140.3883	45.3487	0.4768
140.3967	45.2636	0.4749
140.4050	45.1792	0.4731
140.4133	45.0949	0.4724
140.4217	45.0099	0.4718
140.4300	44.9260	0.4700
140.4383	44.8409	0.4692
140.4467	44.7562	0.4684
140.4550	44.6721	0.4683
140.4633	44.5863	0.4671
140.4717	44.5024	0.4642
140.4800	44.4188	0.4628
140.4883	44.3333	0.4628
140.4967	44.2495	0.4613
140.5050	44.1633	0.4607
140.5133	44.0788	0.4590
140.5217	43.9951	0.4580
140.5300	43.9098	0.4579
140.5383	43.8252	0.4562
140.5467	43.7423	0.4553
140.5550	43.6567	0.4552
140.5633	43.5726	0.4539
140.5717	43.4878	0.4533
140.5800	43.4036	0.4524
140.5883	43.3218	0.4519
140.5967	43.2359	0.4511
140.6050	43.1509	0.4507
140.6133	43.0666	0.4497
140.6217	42.9845	0.4481
140.6300	42.9000
140.6383	42.8165
140.6467	42.7314
140.6550	42.6467
140.6633	42.5637
140.6717	42.4789
140.6800
140.6867