File: Example Date/DSC TA/YN019.txt
Filename	YN019
Instrument name	DSC2A-01799 (192.168.1.250)
Operator
rundate	28/11/2024
Sample name	YN019
proceduresegments	Ramp 10.00 °C/min to 150.0000 °C; Isothermal 3.0 min; Ramp 10.00 °C/min to -100.0000 °C; Isothermal 3.0 min; Ramp 10.00 °C/min to 150.0000 °C; Isothermal 3.0 min; Ramp 10.00 °C/min to -100.0000 °C; Isothermal 3.0 min; Ramp 10.00 °C/min to 150.0000 °C; Isothermal 3.0 min; Ramp 10.00 °C/min to -100.0000 °C; Isothermal 3.0 min; Ramp 10.00 °C/min to 150.0000 °C; Isothermal 3.0 min; Ramp 10.00 °C/min to 40.0000 °C
[File Parameters]
Run Date	28/11/2024 03:24:50
Trios version	5.7.0.56
Original File Name
Current File Name	C:\Users\TA Instruments DSC\Desktop\Data\Yutong Niu\2024-1126\YN019.tri
User at run start	DESKTOP-CFGN8IT\TA Instruments DSC
[Procedure]
Procedure Name	polyether
Sample Name	YN019
Sample Mass	5.33 mg
Reference Sample Mass	0 mg
Pan Mass	61.5 mg
Pan Number	8
Reference Pan Mass	60.81 mg
Reference Pan Number	45
Pan Type	Tzero Aluminum Pin Hole Hermetic
Comments
Project Name
Operator
Test	Custom
Unload Max Temperature	25
Unload Min Temperature	25
FillCooler	Do not fill
Load Max Temperature	25
Load Min Temperature	25
Discard pan in waste bin at end of test	Yes
Stop on Gas Flow Error	No
[Signal List]
Signal #1	Time (min)
Signal #2	Temperature (°C)
Signal #3	Heat Flow (mW)
Signal #4	Delta T (µV)
Signal #5	Delta Tzero (µV)
Signal #6	Tzero Temperature (°C)
Signal #7	Cell Purge (mL/min)
Signal #8	Heater Temp (°C)
Signal #9	Power Delivered (W)
Signal #10	Reference Junction Temperature (°C)
Signal #11	Flange Temperature (°C)
Signal #12	Heat Flow Phase (rad)
Signal #13	Total Heat Capacity (J/°C)
Signal #14	Heat Capacity (J/°C)
Signal #15	LN Pump Tank level (%)
[Configuration]
Company Name	Warwick University
Instrument Name	DSC2A-01799
Instrument Type	DSC2500
Serial Number	DSC2A-01799
IP	192.168.1.250
Location of Instrument	Polymer RTP
DisplayType	TianmaV2andV3
Sample Interval 	0.1 s/pt
Selected Heat Flow	T4P
Exotherm Direction	Up
Cell Serial	DRC2-03788
Lid Type	High Temperature
Cooler	LN Pump
Leave Cooler on at End of Sequence	Off
Gas 2	Air
Gas Selected	Channel 1: Nitrogen
Flow Rate	50 mL/min
Secondary Purge	On
Licensed Heat Flow	Heat Flow T4P
Modulation Licensed	Yes
[Versions]
Common IDD Version	1
Cortex Version	VER 2.11.0.729
Driver	5.0.0.6
GDM Version	1.0.3.3
TouchscreenVersion	1.0.3.1841
FEP Version	1.2.1.21
FEP Bootloader	2.0.0.5
AutoSampler Version	2.1.2.1
Auto Sampler Bootloader	2.0.0.5
FCM Version	1.1.0.3
FCM Bootloader	2.0.0.5
LN Pump Version	10.17.0.0
LN Pump Bootloader	2.0.0.5
[Experiment Logs]
Experiment Log Entry # 1	Ramp Segment 10 C/min to 150 Started
Experiment Log Entry # 3	Air Cool is off.
Experiment Log Entry # 5	Isothermal Segment 3 min started
Experiment Log Entry # 7	Ramp Segment 10 C/min to -100 Started
Experiment Log Entry # 10	LN2P is filling
Experiment Log Entry # 11	Current LN2P tank level (76.42%) not increasing during fill. Bulk tank may be empty.
Experiment Log Entry # 13	LN2P stopped filling
Experiment Log Entry # 14	Isothermal Segment 3 min started
Experiment Log Entry # 16	Ramp Segment 10 C/min to 150 Started
Experiment Log Entry # 18	Isothermal Segment 3 min started
Experiment Log Entry # 20	Ramp Segment 10 C/min to -100 Started
Experiment Log Entry # 22	Isothermal Segment 3 min started
Experiment Log Entry # 24	Ramp Segment 10 C/min to 150 Started
Experiment Log Entry # 26	Isothermal Segment 3 min started
Experiment Log Entry # 28	Ramp Segment 10 C/min to -100 Started
Experiment Log Entry # 30	Isothermal Segment 3 min started
Experiment Log Entry # 32	Ramp Segment 10 C/min to 150 Started
Experiment Log Entry # 34	Isothermal Segment 3 min started
Experiment Log Entry # 36	Ramp Segment 10 C/min to 40 Started
[Method Log]
Method Log Entry # 1	(Ramp 1870836) Ramp 10 °C/minute to 150 °C
Method Log Entry # 2	Isothermal 3 minutes
Method Log Entry # 3	(Ramp 1870838) Ramp 10 °C/minute to -100 °C
Method Log Entry # 4	Isothermal 3 minutes
Method Log Entry # 5	(Ramp 1870840) Ramp 10 °C/minute to 150 °C
Method Log Entry # 6	Isothermal 3 minutes
Method Log Entry # 7	(Ramp 1870842) Ramp 10 °C/minute to -100 °C
Method Log Entry # 8	Isothermal 3 minutes
Method Log Entry # 9	(Ramp 1870844) Ramp 10 °C/minute to 150 °C
Method Log Entry # 10	Isothermal 3 minutes
Method Log Entry # 11	(Ramp 1870846) Ramp 10 °C/minute to -100 °C
Method Log Entry # 12	Isothermal 3 minutes
Method Log Entry # 13	(Ramp 1870848) Ramp 10 °C/minute to 150 °C
Method Log Entry # 14	Isothermal 3 minutes
Method Log Entry # 15	(Ramp 1870850) Ramp 10 °C/minute to 40 °C
Cell Serial	DRC2-03788
[T1 Calibration]
Date Applied	04/03/2021 14:58:04
Description
Gas Type	Nitrogen
Pan Type	None
Slope	-0.001800291
Offset	-0.1301359
Initial Temperature	-100.6228
GUID	a1d5a6be-decd-4ae4-b22f-d560f3a78a92
[TZero Calibration]
Date Applied	21/08/2024 09:53:38
Description	From -180.022 °C to 395.167 °C at 20.000°C/min
Gas Type	Nitrogen
Pan Type	None
Source Files 1	C:\ProgramData\TA Instruments\TRIOS\Data\TAService\PMV 20Aug2024\Tzero Cal.tri
Source Files 2	C:\ProgramData\TA Instruments\TRIOS\Data\TAService\PMV 20Aug2024\Tzero Cal sapphire.tri
Delta T Offset	1.787969
Delta T Slope	-0.003527276
Delta T0 Offset	0.06831977
Delta T0 Slope	0.02007191
[Temperature Calibration]
Date Applied	21/08/2024 11:06:35
Description	From 106.660 °C to 186.660 °C at 10.000°C/min
Gas Type	Nitrogen
Pan Type	Tzero Aluminum
Source Files 1	C:\ProgramData\TA Instruments\TRIOS\Data\TAService\PMV 20Aug2024\TA Indium cal.tri
Measured 1	157.9141
Known 1	156.66
[Cell Constant Calibration]
Date Applied	21/08/2024 11:06:35
Description	From 106.660 °C to 186.660 °C at 10.000°C/min
Gas Type	Nitrogen
Pan Type	Tzero Aluminum
Source Files 1	C:\ProgramData\TA Instruments\TRIOS\Data\TAService\PMV 20Aug2024\TA Indium cal.tri
T4P KCell	1.038055
Onset Slope	-66.72884 mW/°C
[Direct Cp Calibration]
Date Applied	19/11/2024 16:37:27
Description	From -89.996 °C to 396.697 °C at 20.000°C/min
Gas Type	Nitrogen
Pan Type	Tzero Aluminum
Source Files 1	C:\ProgramData\TA Instruments\TRIOS\Data\Sapphire Direct Heat Capacity(8).tri
GUID	544f8371-fe9b-4f4f-81ca-7980c172113e
Temperature	-89.99625 °C
Cp	1.464367
Temperature	-89.02287 °C
Cp	1.460558
Temperature	-88.04948 °C
Cp	1.456263
Temperature	-87.0761 °C
Cp	1.451626
Temperature	-86.10271 °C
Cp	1.446737
Temperature	-85.12933 °C
Cp	1.441723
Temperature	-84.15594 °C
Cp	1.436654
Temperature	-83.18256 °C
Cp	1.431684
Temperature	-82.20917 °C
Cp	1.426935
Temperature	-81.23578 °C
Cp	1.422396
Temperature	-80.2624 °C
Cp	1.418192
Temperature	-79.28901 °C
Cp	1.414363
Temperature	-78.31562 °C
Cp	1.410925
Temperature	-77.34224 °C
Cp	1.407865
Temperature	-76.36885 °C
Cp	1.405143
Temperature	-75.39546 °C
Cp	1.402789
Temperature	-74.42208 °C
Cp	1.400703
Temperature	-73.44869 °C
Cp	1.398837
Temperature	-72.4753 °C
Cp	1.397142
Temperature	-71.50192 °C
Cp	1.395565
Temperature	-70.52853 °C
Cp	1.394053
Temperature	-69.55515 °C
Cp	1.392558
Temperature	-68.58176 °C
Cp	1.391036
Temperature	-67.60838 °C
Cp	1.389483
Temperature	-66.63499 °C
Cp	1.387847
Temperature	-65.66161 °C
Cp	1.38616
Temperature	-64.68822 °C
Cp	1.384397
Temperature	-63.71483 °C
Cp	1.382535
Temperature	-62.74145 °C
Cp	1.380598
Temperature	-61.76806 °C
Cp	1.37865
Temperature	-60.79467 °C
Cp	1.376673
Temperature	-59.82129 °C
Cp	1.374677
Temperature	-58.8479 °C
Cp	1.372642
Temperature	-57.87452 °C
Cp	1.370686
Temperature	-56.90113 °C
Cp	1.368741
Temperature	-55.92775 °C
Cp	1.366786
Temperature	-54.95436 °C
Cp	1.364863
Temperature	-53.98097 °C
Cp	1.362959
Temperature	-53.00759 °C
Cp	1.361116
Temperature	-52.0342 °C
Cp	1.359247
Temperature	-51.06082 °C
Cp	1.357393
Temperature	-50.08743 °C
Cp	1.355593
Temperature	-49.11404 °C
Cp	1.353796
Temperature	-48.14066 °C
Cp	1.352008
Temperature	-47.16727 °C
Cp	1.350215
Temperature	-46.19389 °C
Cp	1.348396
Temperature	-45.2205 °C
Cp	1.346593
Temperature	-44.24712 °C
Cp	1.344755
Temperature	-43.27373 °C
Cp	1.342891
Temperature	-42.30034 °C
Cp	1.341008
Temperature	-41.32696 °C
Cp	1.339126
Temperature	-40.35357 °C
Cp	1.337236
Temperature	-39.38018 °C
Cp	1.335367
Temperature	-38.4068 °C
Cp	1.333522
Temperature	-37.43341 °C
Cp	1.331708
Temperature	-36.46003 °C
Cp	1.32991
Temperature	-35.48664 °C
Cp	1.328145
Temperature	-34.51326 °C
Cp	1.326414
Temperature	-33.53987 °C
Cp	1.32471
Temperature	-32.56648 °C
Cp	1.323012
Temperature	-31.5931 °C
Cp	1.321323
Temperature	-30.61971 °C
Cp	1.319657
Temperature	-29.64633 °C
Cp	1.317968
Temperature	-28.67294 °C
Cp	1.316286
Temperature	-27.69955 °C
Cp	1.314585
Temperature	-26.72617 °C
Cp	1.312857
Temperature	-25.75278 °C
Cp	1.31111
Temperature	-24.7794 °C
Cp	1.309333
Temperature	-23.80601 °C
Cp	1.307544
Temperature	-22.83262 °C
Cp	1.30575
Temperature	-21.85924 °C
Cp	1.303941
Temperature	-20.88585 °C
Cp	1.302132
Temperature	-19.91247 °C
Cp	1.300313
Temperature	-18.93908 °C
Cp	1.298512
Temperature	-17.96569 °C
Cp	1.296728
Temperature	-16.99231 °C
Cp	1.294939
Temperature	-16.01892 °C
Cp	1.293198
Temperature	-15.04554 °C
Cp	1.291453
Temperature	-14.07215 °C
Cp	1.289723
Temperature	-13.09876 °C
Cp	1.288007
Temperature	-12.12538 °C
Cp	1.286283
Temperature	-11.15199 °C
Cp	1.284578
Temperature	-10.17861 °C
Cp	1.282885
Temperature	-9.205221 °C
Cp	1.281173
Temperature	-8.231835 °C
Cp	1.279472
Temperature	-7.258449 °C
Cp	1.277766
Temperature	-6.285063 °C
Cp	1.276053
Temperature	-5.311677 °C
Cp	1.274341
Temperature	-4.338291 °C
Cp	1.272592
Temperature	-3.364905 °C
Cp	1.270844
Temperature	-2.391519 °C
Cp	1.269062
Temperature	-1.418133 °C
Cp	1.267264
Temperature	-0.4447474 °C
Cp	1.265435
Temperature	0.5286385 °C
Cp	1.263575
Temperature	1.502024 °C
Cp	1.261727
Temperature	2.47541 °C
Cp	1.259854
Temperature	3.448796 °C
Cp	1.257978
Temperature	4.422182 °C
Cp	1.256109
Temperature	5.395568 °C
Cp	1.254244
Temperature	6.368954 °C
Cp	1.252392
Temperature	7.34234 °C
Cp	1.250552
Temperature	8.315726 °C
Cp	1.248704
Temperature	9.289112 °C
Cp	1.246884
Temperature	10.2625 °C
Cp	1.245078
Temperature	11.23588 °C
Cp	1.243287
Temperature	12.20927 °C
Cp	1.241522
Temperature	13.18266 °C
Cp	1.239778
Temperature	14.15604 °C
Cp	1.238068
Temperature	15.12943 °C
Cp	1.236393
Temperature	16.10281 °C
Cp	1.234762
Temperature	17.0762 °C
Cp	1.233176
Temperature	18.04959 °C
Cp	1.231629
Temperature	19.02297 °C
Cp	1.230129
Temperature	19.99636 °C
Cp	1.228694
Temperature	20.96974 °C
Cp	1.22731
Temperature	21.94313 °C
Cp	1.225968
Temperature	22.91652 °C
Cp	1.224676
Temperature	23.8899 °C
Cp	1.223431
Temperature	24.86329 °C
Cp	1.222217
Temperature	25.83667 °C
Cp	1.221065
Temperature	26.81006 °C
Cp	1.219919
Temperature	27.78345 °C
Cp	1.218811
Temperature	28.75683 °C
Cp	1.21773
Temperature	29.73022 °C
Cp	1.216663
Temperature	30.7036 °C
Cp	1.2156
Temperature	31.67699 °C
Cp	1.214515
Temperature	32.65038 °C
Cp	1.213439
Temperature	33.62376 °C
Cp	1.21234
Temperature	34.59715 °C
Cp	1.211209
Temperature	35.57053 °C
Cp	1.210051
Temperature	36.54392 °C
Cp	1.208868
Temperature	37.5173 °C
Cp	1.207666
Temperature	38.49069 °C
Cp	1.206439
Temperature	39.46408 °C
Cp	1.205199
Temperature	40.43746 °C
Cp	1.203959
Temperature	41.41085 °C
Cp	1.202712
Temperature	42.38424 °C
Cp	1.20147
Temperature	43.35762 °C
Cp	1.200231
Temperature	44.33101 °C
Cp	1.199
Temperature	45.30439 °C
Cp	1.197777
Temperature	46.27778 °C
Cp	1.19657
Temperature	47.25116 °C
Cp	1.195367
Temperature	48.22455 °C
Cp	1.194179
Temperature	49.19794 °C
Cp	1.19301
Temperature	50.17132 °C
Cp	1.191849
Temperature	51.14471 °C
Cp	1.190694
Temperature	52.11809 °C
Cp	1.189555
Temperature	53.09148 °C
Cp	1.18843
Temperature	54.06487 °C
Cp	1.187311
Temperature	55.03825 °C
Cp	1.186195
Temperature	56.01164 °C
Cp	1.185095
Temperature	56.98502 °C
Cp	1.183997
Temperature	57.95841 °C
Cp	1.182894
Temperature	58.93179 °C
Cp	1.181793
Temperature	59.90518 °C
Cp	1.180693
Temperature	60.87857 °C
Cp	1.179595
Temperature	61.85195 °C
Cp	1.178501
Temperature	62.82534 °C
Cp	1.177406
Temperature	63.79873 °C
Cp	1.176313
Temperature	64.77211 °C
Cp	1.175239
Temperature	65.7455 °C
Cp	1.17417
Temperature	66.71888 °C
Cp	1.173105
Temperature	67.69227 °C
Cp	1.172037
Temperature	68.66566 °C
Cp	1.170989
Temperature	69.63904 °C
Cp	1.169948
Temperature	70.61243 °C
Cp	1.168905
Temperature	71.58582 °C
Cp	1.167872
Temperature	72.5592 °C
Cp	1.166849
Temperature	73.53259 °C
Cp	1.165851
Temperature	74.50597 °C
Cp	1.164848
Temperature	75.47935 °C
Cp	1.163876
Temperature	76.45274 °C
Cp	1.162926
Temperature	77.42612 °C
Cp	1.162008
Temperature	78.39951 °C
Cp	1.161113
Temperature	79.3729 °C
Cp	1.160219
Temperature	80.34628 °C
Cp	1.159377
Temperature	81.31967 °C
Cp	1.158546
Temperature	82.29306 °C
Cp	1.157726
Temperature	83.26644 °C
Cp	1.15692
Temperature	84.23983 °C
Cp	1.156126
Temperature	85.21322 °C
Cp	1.155375
Temperature	86.1866 °C
Cp	1.154604
Temperature	87.15999 °C
Cp	1.153869
Temperature	88.13337 °C
Cp	1.153158
Temperature	89.10676 °C
Cp	1.152474
Temperature	90.08015 °C
Cp	1.15181
Temperature	91.05353 °C
Cp	1.151134
Temperature	92.02692 °C
Cp	1.150513
Temperature	93.00031 °C
Cp	1.149892
Temperature	93.97369 °C
Cp	1.149266
Temperature	94.94707 °C
Cp	1.148642
Temperature	95.92046 °C
Cp	1.148019
Temperature	96.89384 °C
Cp	1.147402
Temperature	97.86723 °C
Cp	1.146799
Temperature	98.84062 °C
Cp	1.146191
Temperature	99.814 °C
Cp	1.145602
Temperature	100.7874 °C
Cp	1.14503
Temperature	101.7608 °C
Cp	1.144469
Temperature	102.7342 °C
Cp	1.143921
Temperature	103.7076 °C
Cp	1.143383
Temperature	104.6809 °C
Cp	1.142861
Temperature	105.6543 °C
Cp	1.142345
Temperature	106.6277 °C
Cp	1.141835
Temperature	107.6011 °C
Cp	1.141335
Temperature	108.5745 °C
Cp	1.140846
Temperature	109.5479 °C
Cp	1.140365
Temperature	110.5212 °C
Cp	1.139891
Temperature	111.4946 °C
Cp	1.139429
Temperature	112.468 °C
Cp	1.138976
Temperature	113.4414 °C
Cp	1.13853
Temperature	114.4148 °C
Cp	1.138092
Temperature	115.3882 °C
Cp	1.137654
Temperature	116.3616 °C
Cp	1.137223
Temperature	117.335 °C
Cp	1.136785
Temperature	118.3083 °C
Cp	1.136338
Temperature	119.2817 °C
Cp	1.13588
Temperature	120.2551 °C
Cp	1.13541
Temperature	121.2285 °C
Cp	1.134927
Temperature	122.2019 °C
Cp	1.134417
Temperature	123.1753 °C
Cp	1.133892
Temperature	124.1487 °C
Cp	1.133347
Temperature	125.122 °C
Cp	1.132786
Temperature	126.0954 °C
Cp	1.132206
Temperature	127.0688 °C
Cp	1.131606
Temperature	128.0422 °C
Cp	1.130999
Temperature	129.0156 °C
Cp	1.130384
Temperature	129.989 °C
Cp	1.129765
Temperature	130.9624 °C
Cp	1.129147
Temperature	131.9357 °C
Cp	1.12854
Temperature	132.9091 °C
Cp	1.127949
Temperature	133.8825 °C
Cp	1.127383
Temperature	134.8559 °C
Cp	1.126841
Temperature	135.8293 °C
Cp	1.126334
Temperature	136.8027 °C
Cp	1.125871
Temperature	137.7761 °C
Cp	1.125443
Temperature	138.7494 °C
Cp	1.125058
Temperature	139.7228 °C
Cp	1.124701
Temperature	140.6962 °C
Cp	1.124397
Temperature	141.6696 °C
Cp	1.124114
Temperature	142.643 °C
Cp	1.123854
Temperature	143.6164 °C
Cp	1.123612
Temperature	144.5898 °C
Cp	1.123385
Temperature	145.5631 °C
Cp	1.123182
Temperature	146.5365 °C
Cp	1.12296
Temperature	147.5099 °C
Cp	1.12275
Temperature	148.4833 °C
Cp	1.122543
Temperature	149.4567 °C
Cp	1.122327
Temperature	150.4301 °C
Cp	1.122099
Temperature	151.4035 °C
Cp	1.121837
Temperature	152.3768 °C
Cp	1.121582
Temperature	153.3502 °C
Cp	1.121289
Temperature	154.3236 °C
Cp	1.120967
Temperature	155.297 °C
Cp	1.120616
Temperature	156.2704 °C
Cp	1.120238
Temperature	157.2438 °C
Cp	1.119862
Temperature	158.2172 °C
Cp	1.119444
Temperature	159.1906 °C
Cp	1.119028
Temperature	160.1639 °C
Cp	1.118613
Temperature	161.1373 °C
Cp	1.118202
Temperature	162.1107 °C
Cp	1.117795
Temperature	163.0841 °C
Cp	1.117374
Temperature	164.0575 °C
Cp	1.116987
Temperature	165.0309 °C
Cp	1.116595
Temperature	166.0042 °C
Cp	1.116198
Temperature	166.9776 °C
Cp	1.1158
Temperature	167.951 °C
Cp	1.115402
Temperature	168.9244 °C
Cp	1.115006
Temperature	169.8978 °C
Cp	1.11462
Temperature	170.8712 °C
Cp	1.114223
Temperature	171.8446 °C
Cp	1.113836
Temperature	172.8179 °C
Cp	1.113458
Temperature	173.7913 °C
Cp	1.113085
Temperature	174.7647 °C
Cp	1.112712
Temperature	175.7381 °C
Cp	1.112323
Temperature	176.7115 °C
Cp	1.111957
Temperature	177.6849 °C
Cp	1.111578
Temperature	178.6583 °C
Cp	1.111185
Temperature	179.6317 °C
Cp	1.110789
Temperature	180.605 °C
Cp	1.110391
Temperature	181.5784 °C
Cp	1.110016
Temperature	182.5518 °C
Cp	1.109611
Temperature	183.5252 °C
Cp	1.109232
Temperature	184.4986 °C
Cp	1.108873
Temperature	185.472 °C
Cp	1.108531
Temperature	186.4454 °C
Cp	1.108199
Temperature	187.4187 °C
Cp	1.107851
Temperature	188.3921 °C
Cp	1.107551
Temperature	189.3655 °C
Cp	1.107238
Temperature	190.3389 °C
Cp	1.106917
Temperature	191.3123 °C
Cp	1.106589
Temperature	192.2857 °C
Cp	1.106259
Temperature	193.259 °C
Cp	1.105958
Temperature	194.2324 °C
Cp	1.105619
Temperature	195.2058 °C
Cp	1.105301
Temperature	196.1792 °C
Cp	1.105002
Temperature	197.1526 °C
Cp	1.104718
Temperature	198.126 °C
Cp	1.104445
Temperature	199.0994 °C
Cp	1.104161
Temperature	200.0728 °C
Cp	1.103914
Temperature	201.0461 °C
Cp	1.103657
Temperature	202.0195 °C
Cp	1.103395
Temperature	202.9929 °C
Cp	1.103125
Temperature	203.9663 °C
Cp	1.102847
Temperature	204.9397 °C
Cp	1.102563
Temperature	205.9131 °C
Cp	1.102283
Temperature	206.8865 °C
Cp	1.101985
Temperature	207.8598 °C
Cp	1.10169
Temperature	208.8332 °C
Cp	1.101394
Temperature	209.8066 °C
Cp	1.101099
Temperature	210.78 °C
Cp	1.1008
Temperature	211.7534 °C
Cp	1.10049
Temperature	212.7268 °C
Cp	1.100193
Temperature	213.7002 °C
Cp	1.099886
Temperature	214.6735 °C
Cp	1.099577
Temperature	215.6469 °C
Cp	1.099268
Temperature	216.6203 °C
Cp	1.098965
Temperature	217.5937 °C
Cp	1.098685
Temperature	218.5671 °C
Cp	1.098396
Temperature	219.5405 °C
Cp	1.098134
Temperature	220.5139 °C
Cp	1.097895
Temperature	221.4872 °C
Cp	1.09768
Temperature	222.4606 °C
Cp	1.097485
Temperature	223.434 °C
Cp	1.097292
Temperature	224.4074 °C
Cp	1.09714
Temperature	225.3808 °C
Cp	1.096991
Temperature	226.3542 °C
Cp	1.096844
Temperature	227.3276 °C
Cp	1.096699
Temperature	228.3009 °C
Cp	1.096559
Temperature	229.2743 °C
Cp	1.096442
Temperature	230.2477 °C
Cp	1.096296
Temperature	231.2211 °C
Cp	1.096164
Temperature	232.1945 °C
Cp	1.09604
Temperature	233.1679 °C
Cp	1.095924
Temperature	234.1413 °C
Cp	1.095807
Temperature	235.1147 °C
Cp	1.095665
Temperature	236.088 °C
Cp	1.095557
Temperature	237.0614 °C
Cp	1.095433
Temperature	238.0348 °C
Cp	1.095296
Temperature	239.0082 °C
Cp	1.095147
Temperature	239.9816 °C
Cp	1.094995
Temperature	240.955 °C
Cp	1.094843
Temperature	241.9283 °C
Cp	1.094705
Temperature	242.9017 °C
Cp	1.094562
Temperature	243.8751 °C
Cp	1.094442
Temperature	244.8485 °C
Cp	1.094344
Temperature	245.8219 °C
Cp	1.094266
Temperature	246.7953 °C
Cp	1.094209
Temperature	247.7687 °C
Cp	1.094161
Temperature	248.7421 °C
Cp	1.094144
Temperature	249.7154 °C
Cp	1.094133
Temperature	250.6888 °C
Cp	1.094127
Temperature	251.6622 °C
Cp	1.094126
Temperature	252.6356 °C
Cp	1.094127
Temperature	253.609 °C
Cp	1.094138
Temperature	254.5824 °C
Cp	1.09413
Temperature	255.5558 °C
Cp	1.094123
Temperature	256.5291 °C
Cp	1.094111
Temperature	257.5025 °C
Cp	1.094087
Temperature	258.4759 °C
Cp	1.094046
Temperature	259.4493 °C
Cp	1.093978
Temperature	260.4227 °C
Cp	1.093895
Temperature	261.3961 °C
Cp	1.093783
Temperature	262.3694 °C
Cp	1.093645
Temperature	263.3428 °C
Cp	1.093483
Temperature	264.3162 °C
Cp	1.093302
Temperature	265.2896 °C
Cp	1.093109
Temperature	266.263 °C
Cp	1.092906
Temperature	267.2364 °C
Cp	1.092704
Temperature	268.2098 °C
Cp	1.092511
Temperature	269.1832 °C
Cp	1.092331
Temperature	270.1566 °C
Cp	1.092174
Temperature	271.1299 °C
Cp	1.092046
Temperature	272.1033 °C
Cp	1.091947
Temperature	273.0767 °C
Cp	1.091882
Temperature	274.0501 °C
Cp	1.091853
Temperature	275.0235 °C
Cp	1.091859
Temperature	275.9969 °C
Cp	1.091895
Temperature	276.9702 °C
Cp	1.091957
Temperature	277.9436 °C
Cp	1.092036
Temperature	278.917 °C
Cp	1.092132
Temperature	279.8904 °C
Cp	1.09223
Temperature	280.8638 °C
Cp	1.092323
Temperature	281.8372 °C
Cp	1.092405
Temperature	282.8105 °C
Cp	1.092468
Temperature	283.7839 °C
Cp	1.092513
Temperature	284.7573 °C
Cp	1.092525
Temperature	285.7307 °C
Cp	1.092512
Temperature	286.7041 °C
Cp	1.092472
Temperature	287.6775 °C
Cp	1.092405
Temperature	288.6509 °C
Cp	1.092313
Temperature	289.6243 °C
Cp	1.092197
Temperature	290.5977 °C
Cp	1.09207
Temperature	291.571 °C
Cp	1.091931
Temperature	292.5444 °C
Cp	1.091785
Temperature	293.5178 °C
Cp	1.091641
Temperature	294.4912 °C
Cp	1.091506
Temperature	295.4646 °C
Cp	1.091387
Temperature	296.438 °C
Cp	1.091282
Temperature	297.4113 °C
Cp	1.091201
Temperature	298.3847 °C
Cp	1.091145
Temperature	299.3581 °C
Cp	1.091112
Temperature	300.3315 °C
Cp	1.091102
Temperature	301.3049 °C
Cp	1.091107
Temperature	302.2783 °C
Cp	1.091137
Temperature	303.2517 °C
Cp	1.091177
Temperature	304.2251 °C
Cp	1.091226
Temperature	305.1984 °C
Cp	1.09128
Temperature	306.1718 °C
Cp	1.091336
Temperature	307.1452 °C
Cp	1.091403
Temperature	308.1186 °C
Cp	1.091453
Temperature	309.092 °C
Cp	1.091506
Temperature	310.0654 °C
Cp	1.091561
Temperature	311.0388 °C
Cp	1.091617
Temperature	312.0121 °C
Cp	1.09167
Temperature	312.9855 °C
Cp	1.091716
Temperature	313.9589 °C
Cp	1.091762
Temperature	314.9323 °C
Cp	1.091805
Temperature	315.9057 °C
Cp	1.091838
Temperature	316.8791 °C
Cp	1.09186
Temperature	317.8524 °C
Cp	1.091871
Temperature	318.8258 °C
Cp	1.091872
Temperature	319.7992 °C
Cp	1.091867
Temperature	320.7726 °C
Cp	1.091838
Temperature	321.746 °C
Cp	1.0918
Temperature	322.7194 °C
Cp	1.091752
Temperature	323.6928 °C
Cp	1.091689
Temperature	324.6662 °C
Cp	1.091611
Temperature	325.6396 °C
Cp	1.091508
Temperature	326.6129 °C
Cp	1.091406
Temperature	327.5863 °C
Cp	1.091285
Temperature	328.5597 °C
Cp	1.09115
Temperature	329.5331 °C
Cp	1.091009
Temperature	330.5065 °C
Cp	1.09087
Temperature	331.4799 °C
Cp	1.090747
Temperature	332.4532 °C
Cp	1.090628
Temperature	333.4266 °C
Cp	1.090536
Temperature	334.4 °C
Cp	1.090472
Temperature	335.3734 °C
Cp	1.090437
Temperature	336.3468 °C
Cp	1.090431
Temperature	337.3202 °C
Cp	1.090455
Temperature	338.2935 °C
Cp	1.090503
Temperature	339.2669 °C
Cp	1.090573
Temperature	340.2403 °C
Cp	1.090658
Temperature	341.2137 °C
Cp	1.090753
Temperature	342.1871 °C
Cp	1.090853
Temperature	343.1605 °C
Cp	1.090952
Temperature	344.1339 °C
Cp	1.09105
Temperature	345.1073 °C
Cp	1.091141
Temperature	346.0807 °C
Cp	1.091225
Temperature	347.054 °C
Cp	1.091303
Temperature	348.0274 °C
Cp	1.091379
Temperature	349.0008 °C
Cp	1.091453
Temperature	349.9742 °C
Cp	1.091537
Temperature	350.9476 °C
Cp	1.091633
Temperature	351.921 °C
Cp	1.091743
Temperature	352.8943 °C
Cp	1.091874
Temperature	353.8677 °C
Cp	1.092028
Temperature	354.8411 °C
Cp	1.092206
Temperature	355.8145 °C
Cp	1.092411
Temperature	356.7879 °C
Cp	1.092628
Temperature	357.7613 °C
Cp	1.092862
Temperature	358.7346 °C
Cp	1.093102
Temperature	359.708 °C
Cp	1.093338
Temperature	360.6814 °C
Cp	1.093559
Temperature	361.6548 °C
Cp	1.093752
Temperature	362.6282 °C
Cp	1.093915
Temperature	363.6016 °C
Cp	1.094036
Temperature	364.575 °C
Cp	1.094117
Temperature	365.5484 °C
Cp	1.094159
Temperature	366.5218 °C
Cp	1.094172
Temperature	367.4951 °C
Cp	1.094165
Temperature	368.4685 °C
Cp	1.094163
Temperature	369.4419 °C
Cp	1.094182
Temperature	370.4153 °C
Cp	1.094244
Temperature	371.3887 °C
Cp	1.094375
Temperature	372.3621 °C
Cp	1.094598
Temperature	373.3354 °C
Cp	1.094937
Temperature	374.3088 °C
Cp	1.095389
Temperature	375.2822 °C
Cp	1.095973
Temperature	376.2556 °C
Cp	1.096685
Temperature	377.229 °C
Cp	1.097506
Temperature	378.2024 °C
Cp	1.098406
Temperature	379.1758 °C
Cp	1.099338
Temperature	380.1492 °C
Cp	1.10027
Temperature	381.1225 °C
Cp	1.10112
Temperature	382.0959 °C
Cp	1.101818
Temperature	383.0693 °C
Cp	1.10229
Temperature	384.0427 °C
Cp	1.102459
Temperature	385.0161 °C
Cp	1.102253
Temperature	385.9895 °C
Cp	1.101596
Temperature	386.9629 °C
Cp	1.100438
Temperature	387.9362 °C
Cp	1.098736
Temperature	388.9096 °C
Cp	1.096461
Temperature	389.883 °C
Cp	1.093614
Temperature	390.8564 °C
Cp	1.090208
Temperature	391.8298 °C
Cp	1.086278
Temperature	392.8032 °C
Cp	1.081887
Temperature	393.7766 °C
Cp	1.077096
Temperature	394.7499 °C
Cp	1.072007
Temperature	395.7233 °C
Cp	1.066707
[Rev Cp Calibration]
Date Applied	24/10/2024 12:37:31
Description	From -89.998 °C to 390.542 °C at 2.000°C/min
Gas Type	Nitrogen
Pan Type	Tzero Aluminum
Source Files 1	C:\ProgramData\TA Instruments\TRIOS\Data\Reverse Heat Capacity Calibration(6).tri
GUID	ba867d72-cfbb-486e-971e-e86aa544cc02
Temperature	-89.99799 °C
Cp	1.070076
Temperature	-89.03691 °C
Cp	1.072008
Temperature	-88.07584 °C
Cp	1.073556
Temperature	-87.11475 °C
Cp	1.074743
Temperature	-86.15367 °C
Cp	1.075597
Temperature	-85.1926 °C
Cp	1.076163
Temperature	-84.23151 °C
Cp	1.076477
Temperature	-83.27043 °C
Cp	1.076579
Temperature	-82.30936 °C
Cp	1.076527
Temperature	-81.34827 °C
Cp	1.076322
Temperature	-80.38719 °C
Cp	1.076039
Temperature	-79.42612 °C
Cp	1.07571
Temperature	-78.46503 °C
Cp	1.075361
Temperature	-77.50395 °C
Cp	1.075011
Temperature	-76.54288 °C
Cp	1.074656
Temperature	-75.58179 °C
Cp	1.074359
Temperature	-74.62071 °C
Cp	1.074086
Temperature	-73.65964 °C
Cp	1.073842
Temperature	-72.69855 °C
Cp	1.073627
Temperature	-71.73747 °C
Cp	1.073442
Temperature	-70.7764 °C
Cp	1.07329
Temperature	-69.81532 °C
Cp	1.073148
Temperature	-68.85423 °C
Cp	1.073021
Temperature	-67.89315 °C
Cp	1.072902
Temperature	-66.93208 °C
Cp	1.072782
Temperature	-65.97099 °C
Cp	1.072656
Temperature	-65.00991 °C
Cp	1.072518
Temperature	-64.04884 °C
Cp	1.072374
Temperature	-63.08775 °C
Cp	1.072201
Temperature	-62.12667 °C
Cp	1.072019
Temperature	-61.1656 °C
Cp	1.071827
Temperature	-60.20451 °C
Cp	1.071624
Temperature	-59.24343 °C
Cp	1.071411
Temperature	-58.28236 °C
Cp	1.071167
Temperature	-57.32127 °C
Cp	1.070956
Temperature	-56.3602 °C
Cp	1.070724
Temperature	-55.39911 °C
Cp	1.070483
Temperature	-54.43803 °C
Cp	1.070242
Temperature	-53.47696 °C
Cp	1.070009
Temperature	-52.51587 °C
Cp	1.069825
Temperature	-51.55479 °C
Cp	1.069601
Temperature	-50.59372 °C
Cp	1.069418
Temperature	-49.63263 °C
Cp	1.069267
Temperature	-48.67155 °C
Cp	1.069138
Temperature	-47.71048 °C
Cp	1.069021
Temperature	-46.74939 °C
Cp	1.068875
Temperature	-45.78831 °C
Cp	1.068771
Temperature	-44.82724 °C
Cp	1.068634
Temperature	-43.86615 °C
Cp	1.068462
Temperature	-42.90508 °C
Cp	1.068255
Temperature	-41.944 °C
Cp	1.068012
Temperature	-40.98291 °C
Cp	1.067742
Temperature	-40.02184 °C
Cp	1.067427
Temperature	-39.06076 °C
Cp	1.067088
Temperature	-38.09967 °C
Cp	1.066727
Temperature	-37.1386 °C
Cp	1.066349
Temperature	-36.17752 °C
Cp	1.065958
Temperature	-35.21643 °C
Cp	1.065559
Temperature	-34.25536 °C
Cp	1.065162
Temperature	-33.29427 °C
Cp	1.06476
Temperature	-32.33319 °C
Cp	1.064368
Temperature	-31.37212 °C
Cp	1.06399
Temperature	-30.41104 °C
Cp	1.063628
Temperature	-29.44995 °C
Cp	1.063283
Temperature	-28.48887 °C
Cp	1.06295
Temperature	-27.5278 °C
Cp	1.062645
Temperature	-26.56672 °C
Cp	1.062355
Temperature	-25.60563 °C
Cp	1.06208
Temperature	-24.64456 °C
Cp	1.061819
Temperature	-23.68348 °C
Cp	1.061573
Temperature	-22.72239 °C
Cp	1.061345
Temperature	-21.76132 °C
Cp	1.061123
Temperature	-20.80024 °C
Cp	1.060915
Temperature	-19.83916 °C
Cp	1.060719
Temperature	-18.87807 °C
Cp	1.060531
Temperature	-17.917 °C
Cp	1.06035
Temperature	-16.95592 °C
Cp	1.060161
Temperature	-15.99484 °C
Cp	1.059992
Temperature	-15.03376 °C
Cp	1.059817
Temperature	-14.07268 °C
Cp	1.059634
Temperature	-13.1116 °C
Cp	1.059445
Temperature	-12.15052 °C
Cp	1.059248
Temperature	-11.18944 °C
Cp	1.059043
Temperature	-10.22836 °C
Cp	1.058842
Temperature	-9.267276 °C
Cp	1.058615
Temperature	-8.306196 °C
Cp	1.058388
Temperature	-7.345116 °C
Cp	1.058155
Temperature	-6.384036 °C
Cp	1.057911
Temperature	-5.422956 °C
Cp	1.057652
Temperature	-4.461876 °C
Cp	1.057356
Temperature	-3.500796 °C
Cp	1.057063
Temperature	-2.539716 °C
Cp	1.056732
Temperature	-1.578636 °C
Cp	1.056364
Temperature	-0.6175562 °C
Cp	1.05596
Temperature	0.3435238 °C
Cp	1.055523
Temperature	1.304604 °C
Cp	1.055066
Temperature	2.265684 °C
Cp	1.054561
Temperature	3.226764 °C
Cp	1.054035
Temperature	4.187844 °C
Cp	1.053488
Temperature	5.148924 °C
Cp	1.052922
Temperature	6.110003 °C
Cp	1.052337
Temperature	7.071084 °C
Cp	1.051736
Temperature	8.032164 °C
Cp	1.051118
Temperature	8.993243 °C
Cp	1.050488
Temperature	9.954324 °C
Cp	1.049848
Temperature	10.9154 °C
Cp	1.049202
Temperature	11.87648 °C
Cp	1.048552
Temperature	12.83756 °C
Cp	1.047902
Temperature	13.79864 °C
Cp	1.047255
Temperature	14.75972 °C
Cp	1.046615
Temperature	15.7208 °C
Cp	1.045983
Temperature	16.68188 °C
Cp	1.045362
Temperature	17.64296 °C
Cp	1.044756
Temperature	18.60404 °C
Cp	1.044164
Temperature	19.56512 °C
Cp	1.04358
Temperature	20.5262 °C
Cp	1.043027
Temperature	21.48728 °C
Cp	1.042485
Temperature	22.44836 °C
Cp	1.041958
Temperature	23.40944 °C
Cp	1.041446
Temperature	24.37052 °C
Cp	1.040952
Temperature	25.3316 °C
Cp	1.040493
Temperature	26.29268 °C
Cp	1.040022
Temperature	27.25376 °C
Cp	1.039578
Temperature	28.21484 °C
Cp	1.039158
Temperature	29.17592 °C
Cp	1.038758
Temperature	30.137 °C
Cp	1.038373
Temperature	31.09808 °C
Cp	1.037981
Temperature	32.05916 °C
Cp	1.03763
Temperature	33.02024 °C
Cp	1.037276
Temperature	33.98132 °C
Cp	1.03692
Temperature	34.9424 °C
Cp	1.036565
Temperature	35.90348 °C
Cp	1.036213
Temperature	36.86456 °C
Cp	1.035866
Temperature	37.82564 °C
Cp	1.035529
Temperature	38.78672 °C
Cp	1.035195
Temperature	39.7478 °C
Cp	1.034875
Temperature	40.70888 °C
Cp	1.034568
Temperature	41.66996 °C
Cp	1.034276
Temperature	42.63104 °C
Cp	1.033996
Temperature	43.59212 °C
Cp	1.033726
Temperature	44.5532 °C
Cp	1.033469
Temperature	45.51428 °C
Cp	1.033221
Temperature	46.47536 °C
Cp	1.03298
Temperature	47.43644 °C
Cp	1.032744
Temperature	48.39752 °C
Cp	1.032514
Temperature	49.3586 °C
Cp	1.032289
Temperature	50.31968 °C
Cp	1.032065
Temperature	51.28076 °C
Cp	1.031844
Temperature	52.24184 °C
Cp	1.031627
Temperature	53.20292 °C
Cp	1.031413
Temperature	54.164 °C
Cp	1.031203
Temperature	55.12508 °C
Cp	1.030989
Temperature	56.08616 °C
Cp	1.030791
Temperature	57.04724 °C
Cp	1.030595
Temperature	58.00832 °C
Cp	1.030403
Temperature	58.9694 °C
Cp	1.030217
Temperature	59.93048 °C
Cp	1.03004
Temperature	60.89156 °C
Cp	1.029871
Temperature	61.85264 °C
Cp	1.029718
Temperature	62.81372 °C
Cp	1.029567
Temperature	63.7748 °C
Cp	1.02943
Temperature	64.73589 °C
Cp	1.029304
Temperature	65.69696 °C
Cp	1.029185
Temperature	66.65804 °C
Cp	1.02907
Temperature	67.61913 °C
Cp	1.028946
Temperature	68.5802 °C
Cp	1.028831
Temperature	69.54128 °C
Cp	1.028703
Temperature	70.50237 °C
Cp	1.028561
Temperature	71.46344 °C
Cp	1.028404
Temperature	72.42452 °C
Cp	1.028234
Temperature	73.3856 °C
Cp	1.028063
Temperature	74.34668 °C
Cp	1.027861
Temperature	75.30776 °C
Cp	1.027657
Temperature	76.26884 °C
Cp	1.027451
Temperature	77.22992 °C
Cp	1.027243
Temperature	78.191 °C
Cp	1.027036
Temperature	79.15208 °C
Cp	1.026812
Temperature	80.11316 °C
Cp	1.026623
Temperature	81.07424 °C
Cp	1.026431
Temperature	82.03532 °C
Cp	1.026241
Temperature	82.9964 °C
Cp	1.02606
Temperature	83.95748 °C
Cp	1.025891
Temperature	84.91856 °C
Cp	1.025739
Temperature	85.87964 °C
Cp	1.025614
Temperature	86.84072 °C
Cp	1.025493
Temperature	87.8018 °C
Cp	1.0254
Temperature	88.76288 °C
Cp	1.025329
Temperature	89.72396 °C
Cp	1.025274
Temperature	90.68504 °C
Cp	1.025229
Temperature	91.64612 °C
Cp	1.025174
Temperature	92.6072 °C
Cp	1.025138
Temperature	93.56828 °C
Cp	1.025083
Temperature	94.52936 °C
Cp	1.025008
Temperature	95.49044 °C
Cp	1.024912
Temperature	96.45152 °C
Cp	1.024796
Temperature	97.4126 °C
Cp	1.024671
Temperature	98.37368 °C
Cp	1.024506
Temperature	99.33476 °C
Cp	1.02433
Temperature	100.2958 °C
Cp	1.024144
Temperature	101.2569 °C
Cp	1.023948
Temperature	102.218 °C
Cp	1.023743
Temperature	103.1791 °C
Cp	1.023522
Temperature	104.1402 °C
Cp	1.023309
Temperature	105.1012 °C
Cp	1.023089
Temperature	106.0623 °C
Cp	1.022866
Temperature	107.0234 °C
Cp	1.022644
Temperature	107.9845 °C
Cp	1.022427
Temperature	108.9456 °C
Cp	1.022218
Temperature	109.9066 °C
Cp	1.022022
Temperature	110.8677 °C
Cp	1.021836
Temperature	111.8288 °C
Cp	1.021666
Temperature	112.7899 °C
Cp	1.021512
Temperature	113.751 °C
Cp	1.021374
Temperature	114.712 °C
Cp	1.02125
Temperature	115.6731 °C
Cp	1.021137
Temperature	116.6342 °C
Cp	1.021041
Temperature	117.5953 °C
Cp	1.020953
Temperature	118.5564 °C
Cp	1.020872
Temperature	119.5174 °C
Cp	1.020796
Temperature	120.4785 °C
Cp	1.020725
Temperature	121.4396 °C
Cp	1.020659
Temperature	122.4007 °C
Cp	1.020587
Temperature	123.3618 °C
Cp	1.020515
Temperature	124.3228 °C
Cp	1.02044
Temperature	125.2839 °C
Cp	1.020359
Temperature	126.245 °C
Cp	1.02027
Temperature	127.2061 °C
Cp	1.020167
Temperature	128.1672 °C
Cp	1.020057
Temperature	129.1282 °C
Cp	1.019933
Temperature	130.0893 °C
Cp	1.019793
Temperature	131.0504 °C
Cp	1.019638
Temperature	132.0115 °C
Cp	1.019471
Temperature	132.9726 °C
Cp	1.019292
Temperature	133.9336 °C
Cp	1.019107
Temperature	134.8947 °C
Cp	1.018912
Temperature	135.8558 °C
Cp	1.018717
Temperature	136.8169 °C
Cp	1.018527
Temperature	137.778 °C
Cp	1.018344
Temperature	138.739 °C
Cp	1.018171
Temperature	139.7001 °C
Cp	1.018004
Temperature	140.6612 °C
Cp	1.01787
Temperature	141.6223 °C
Cp	1.01775
Temperature	142.5834 °C
Cp	1.017652
Temperature	143.5444 °C
Cp	1.017578
Temperature	144.5055 °C
Cp	1.017534
Temperature	145.4666 °C
Cp	1.017536
Temperature	146.4277 °C
Cp	1.017545
Temperature	147.3888 °C
Cp	1.017595
Temperature	148.3498 °C
Cp	1.017679
Temperature	149.3109 °C
Cp	1.01779
Temperature	150.272 °C
Cp	1.01792
Temperature	151.2331 °C
Cp	1.018043
Temperature	152.1942 °C
Cp	1.018199
Temperature	153.1552 °C
Cp	1.018339
Temperature	154.1163 °C
Cp	1.018458
Temperature	155.0774 °C
Cp	1.018552
Temperature	156.0385 °C
Cp	1.018618
Temperature	156.9996 °C
Cp	1.018662
Temperature	157.9606 °C
Cp	1.018664
Temperature	158.9217 °C
Cp	1.018632
Temperature	159.8828 °C
Cp	1.018575
Temperature	160.8439 °C
Cp	1.018492
Temperature	161.805 °C
Cp	1.018383
Temperature	162.766 °C
Cp	1.01825
Temperature	163.7271 °C
Cp	1.018087
Temperature	164.6882 °C
Cp	1.017917
Temperature	165.6493 °C
Cp	1.017726
Temperature	166.6104 °C
Cp	1.017522
Temperature	167.5714 °C
Cp	1.01731
Temperature	168.5325 °C
Cp	1.017098
Temperature	169.4936 °C
Cp	1.016902
Temperature	170.4547 °C
Cp	1.016695
Temperature	171.4158 °C
Cp	1.016508
Temperature	172.3768 °C
Cp	1.016342
Temperature	173.3379 °C
Cp	1.016195
Temperature	174.299 °C
Cp	1.016065
Temperature	175.2601 °C
Cp	1.015927
Temperature	176.2212 °C
Cp	1.015838
Temperature	177.1822 °C
Cp	1.015746
Temperature	178.1433 °C
Cp	1.015651
Temperature	179.1044 °C
Cp	1.015555
Temperature	180.0655 °C
Cp	1.015459
Temperature	181.0266 °C
Cp	1.015401
Temperature	181.9876 °C
Cp	1.015288
Temperature	182.9487 °C
Cp	1.015195
Temperature	183.9098 °C
Cp	1.015117
Temperature	184.8709 °C
Cp	1.01505
Temperature	185.832 °C
Cp	1.014988
Temperature	186.793 °C
Cp	1.014927
Temperature	187.7541 °C
Cp	1.014849
Temperature	188.7152 °C
Cp	1.014789
Temperature	189.6763 °C
Cp	1.01471
Temperature	190.6374 °C
Cp	1.014614
Temperature	191.5984 °C
Cp	1.014503
Temperature	192.5595 °C
Cp	1.014381
Temperature	193.5206 °C
Cp	1.014268
Temperature	194.4817 °C
Cp	1.014122
Temperature	195.4428 °C
Cp	1.013984
Temperature	196.4038 °C
Cp	1.013853
Temperature	197.3649 °C
Cp	1.013726
Temperature	198.326 °C
Cp	1.013603
Temperature	199.2871 °C
Cp	1.013467
Temperature	200.2482 °C
Cp	1.013359
Temperature	201.2092 °C
Cp	1.013243
Temperature	202.1703 °C
Cp	1.013123
Temperature	203.1314 °C
Cp	1.013002
Temperature	204.0925 °C
Cp	1.012884
Temperature	205.0536 °C
Cp	1.012788
Temperature	206.0146 °C
Cp	1.012674
Temperature	206.9757 °C
Cp	1.012579
Temperature	207.9368 °C
Cp	1.012501
Temperature	208.8979 °C
Cp	1.012439
Temperature	209.859 °C
Cp	1.012389
Temperature	210.82 °C
Cp	1.012351
Temperature	211.7811 °C
Cp	1.012312
Temperature	212.7422 °C
Cp	1.01229
Temperature	213.7033 °C
Cp	1.012262
Temperature	214.6644 °C
Cp	1.012227
Temperature	215.6254 °C
Cp	1.012183
Temperature	216.5865 °C
Cp	1.012129
Temperature	217.5476 °C
Cp	1.012077
Temperature	218.5087 °C
Cp	1.01199
Temperature	219.4698 °C
Cp	1.011897
Temperature	220.4308 °C
Cp	1.011793
Temperature	221.3919 °C
Cp	1.011674
Temperature	222.353 °C
Cp	1.011537
Temperature	223.3141 °C
Cp	1.011362
Temperature	224.2752 °C
Cp	1.011194
Temperature	225.2362 °C
Cp	1.010993
Temperature	226.1973 °C
Cp	1.010766
Temperature	227.1584 °C
Cp	1.010517
Temperature	228.1195 °C
Cp	1.010251
Temperature	229.0806 °C
Cp	1.009998
Temperature	230.0416 °C
Cp	1.009703
Temperature	231.0027 °C
Cp	1.009422
Temperature	231.9638 °C
Cp	1.009156
Temperature	232.9249 °C
Cp	1.008906
Temperature	233.886 °C
Cp	1.008675
Temperature	234.847 °C
Cp	1.008462
Temperature	235.8081 °C
Cp	1.008258
Temperature	236.7692 °C
Cp	1.00809
Temperature	237.7303 °C
Cp	1.007934
Temperature	238.6914 °C
Cp	1.007793
Temperature	239.6524 °C
Cp	1.007668
Temperature	240.6135 °C
Cp	1.007562
Temperature	241.5746 °C
Cp	1.007487
Temperature	242.5357 °C
Cp	1.00741
Temperature	243.4967 °C
Cp	1.00736
Temperature	244.4578 °C
Cp	1.007332
Temperature	245.4189 °C
Cp	1.007321
Temperature	246.38 °C
Cp	1.007321
Temperature	247.3411 °C
Cp	1.007312
Temperature	248.3022 °C
Cp	1.007331
Temperature	249.2632 °C
Cp	1.007338
Temperature	250.2243 °C
Cp	1.007335
Temperature	251.1854 °C
Cp	1.00732
Temperature	252.1465 °C
Cp	1.007295
Temperature	253.1076 °C
Cp	1.007277
Temperature	254.0686 °C
Cp	1.007227
Temperature	255.0297 °C
Cp	1.007179
Temperature	255.9908 °C
Cp	1.007133
Temperature	256.9519 °C
Cp	1.00709
Temperature	257.913 °C
Cp	1.007049
Temperature	258.874 °C
Cp	1.007012
Temperature	259.8351 °C
Cp	1.006978
Temperature	260.7962 °C
Cp	1.006956
Temperature	261.7573 °C
Cp	1.00694
Temperature	262.7184 °C
Cp	1.006934
Temperature	263.6794 °C
Cp	1.006939
Temperature	264.6405 °C
Cp	1.00696
Temperature	265.6016 °C
Cp	1.006999
Temperature	266.5627 °C
Cp	1.007054
Temperature	267.5237 °C
Cp	1.007131
Temperature	268.4848 °C
Cp	1.00723
Temperature	269.4459 °C
Cp	1.00735
Temperature	270.407 °C
Cp	1.007493
Temperature	271.3681 °C
Cp	1.007656
Temperature	272.3292 °C
Cp	1.007839
Temperature	273.2902 °C
Cp	1.008039
Temperature	274.2513 °C
Cp	1.008257
Temperature	275.2124 °C
Cp	1.008488
Temperature	276.1735 °C
Cp	1.008731
Temperature	277.1346 °C
Cp	1.008977
Temperature	278.0956 °C
Cp	1.009237
Temperature	279.0567 °C
Cp	1.009498
Temperature	280.0178 °C
Cp	1.009757
Temperature	280.9789 °C
Cp	1.010014
Temperature	281.9399 °C
Cp	1.010267
Temperature	282.901 °C
Cp	1.010515
Temperature	283.8621 °C
Cp	1.01076
Temperature	284.8232 °C
Cp	1.010993
Temperature	285.7843 °C
Cp	1.011222
Temperature	286.7454 °C
Cp	1.011447
Temperature	287.7064 °C
Cp	1.011665
Temperature	288.6675 °C
Cp	1.011876
Temperature	289.6286 °C
Cp	1.012079
Temperature	290.5897 °C
Cp	1.01228
Temperature	291.5508 °C
Cp	1.012474
Temperature	292.5118 °C
Cp	1.012662
Temperature	293.4729 °C
Cp	1.012846
Temperature	294.434 °C
Cp	1.013028
Temperature	295.3951 °C
Cp	1.013211
Temperature	296.3561 °C
Cp	1.013391
Temperature	297.3172 °C
Cp	1.013574
Temperature	298.2783 °C
Cp	1.013759
Temperature	299.2394 °C
Cp	1.013947
Temperature	300.2005 °C
Cp	1.014136
Temperature	301.1616 °C
Cp	1.01432
Temperature	302.1226 °C
Cp	1.014511
Temperature	303.0837 °C
Cp	1.014695
Temperature	304.0448 °C
Cp	1.014872
Temperature	305.0059 °C
Cp	1.01504
Temperature	305.9669 °C
Cp	1.015198
Temperature	306.928 °C
Cp	1.015343
Temperature	307.8891 °C
Cp	1.015479
Temperature	308.8502 °C
Cp	1.015595
Temperature	309.8113 °C
Cp	1.015699
Temperature	310.7724 °C
Cp	1.015789
Temperature	311.7334 °C
Cp	1.015865
Temperature	312.6945 °C
Cp	1.015925
Temperature	313.6556 °C
Cp	1.015964
Temperature	314.6167 °C
Cp	1.015999
Temperature	315.5778 °C
Cp	1.016018
Temperature	316.5388 °C
Cp	1.016025
Temperature	317.4999 °C
Cp	1.016024
Temperature	318.461 °C
Cp	1.01602
Temperature	319.4221 °C
Cp	1.016029
Temperature	320.3831 °C
Cp	1.016025
Temperature	321.3442 °C
Cp	1.016037
Temperature	322.3053 °C
Cp	1.016066
Temperature	323.2664 °C
Cp	1.01611
Temperature	324.2275 °C
Cp	1.016169
Temperature	325.1886 °C
Cp	1.016225
Temperature	326.1496 °C
[...]
189.5967	90.8536	0.3659	-161.9773
189.6050	90.7700	0.3659	-161.9825
189.6133	90.6864	0.3659	-161.9901
189.6217	90.6033	0.3658	-161.9969
189.6300	90.5203	0.3657	-162.0040
189.6383	90.4380	0.3656	-162.0108
189.6467	90.3549	0.3656	-162.0178
189.6550	90.2721	0.3656	-162.0249
189.6633	90.1890	0.3655	-162.0307
189.6717	90.1050	0.3655	-162.0379
189.6800	90.0221	0.3654	-162.0462
189.6883	89.9386	0.3654	-162.0513
189.6967	89.8561	0.3653	-162.0599
189.7050	89.7724	0.3653	-162.0654
189.7133	89.6897	0.3653	-162.0718
189.7217	89.6073	0.3652	-162.0764
189.7300	89.5236	0.3652	-162.0841
189.7383	89.4407	0.3651	-162.0927
189.7467	89.3584	0.3650	-162.0976
189.7550	89.2736	0.3650	-162.1040
189.7633	89.1899	0.3650	-162.1125
189.7717	89.1080	0.3647	-162.1163
189.7800	89.0246	0.3647	-162.1216
189.7883	88.9404	0.3647	-162.1313
189.7967	88.8576	0.3646	-162.1375
189.8050	88.7754	0.3647	-162.1452
189.8133	88.6910	0.3646	-162.1517
189.8217	88.6083	0.3646	-162.1594
189.8300	88.5240	0.3645	-162.1662
189.8383	88.4421	0.3645	-162.1716
189.8467	88.3585	0.3645	-162.1790
189.8550	88.2750	0.3644	-162.1863
189.8633	88.1924	0.3644	-162.1904
189.8717	88.1100	0.3644	-162.1974
189.8800	88.0262	0.3643	-162.2037
189.8883	87.9424	0.3643	-162.2107
189.8967	87.8592	0.3643	-162.2180
189.9050	87.7766	0.3642	-162.2247
189.9133	87.6934	0.3641	-162.2302
189.9217	87.6100	0.3641	-162.2375
189.9300	87.5270	0.3641	-162.2456
189.9383	87.4427	0.3641	-162.2511
189.9467	87.3607	0.3641	-162.2572
189.9550	87.2767	0.3640	-162.2661
189.9633	87.1941	0.3639	-162.2716
189.9717	87.1105	0.3639	-162.2782
189.9800	87.0281	0.3638	-162.2835
189.9883	86.9457	0.3638	-162.2903
189.9967	86.8621	0.3637	-162.2991
190.0050	86.7783	0.3637	-162.3038
190.0133	86.6942	0.3637	-162.3098
190.0217	86.6114	0.3637	-162.3178
190.0300	86.5285	0.3636	-162.3246
190.0383	86.4452	0.3635	-162.3303
190.0467	86.3623	0.3634	-162.3358
190.0550	86.2796	0.3634	-162.3430
190.0633	86.1953	0.3633	-162.3512
190.0717	86.1128	0.3632	-162.3562
190.0800	86.0301	0.3633	-162.3631
190.0883	85.9467	0.3634	-162.3690
190.0967	85.8627	0.3632	-162.3774
190.1050	85.7804	0.3630	-162.3828
190.1133	85.6967	0.3630	-162.3921
190.1217	85.6141	0.3629	-162.3945
190.1300	85.5311	0.3629	-162.4017
190.1383	85.4481	0.3628	-162.4086
190.1467	85.3653	0.3627	-162.4139
190.1550	85.2816	0.3627	-162.4218
190.1633	85.1986	0.3627	-162.4276
190.1717	85.1156	0.3626	-162.4345
190.1800	85.0322	0.3625	-162.4424
190.1883	84.9497	0.3625	-162.4464
190.1967	84.8669	0.3624	-162.4556
190.2050	84.7816	0.3624	-162.4614
190.2133	84.6996	0.3624	-162.4684
190.2217	84.6167	0.3623	-162.4748
190.2300	84.5326	0.3623	-162.4821
190.2383	84.4504	0.3622	-162.4881
190.2467	84.3667	0.3622	-162.4964
190.2550	84.2835	0.3621	-162.5030
190.2633	84.1994	0.3622	-162.5079
190.2717	84.1164	0.3622	-162.5147
190.2800	84.0332	0.3622	-162.5215
190.2883	83.9504	0.3622	-162.5265
190.2967	83.8677	0.3621	-162.5361
190.3050	83.7850	0.3621	-162.5415
190.3133	83.7018	0.3620	-162.5483
190.3217	83.6175	0.3619	-162.5559
190.3300	83.5346	0.3618	-162.5613
190.3383	83.4522	0.3618	-162.5696
190.3467	83.3684	0.3619	-162.5755
190.3550	83.2847	0.3618	-162.5831
190.3633	83.2025	0.3617	-162.5899
190.3717	83.1187	0.3617	-162.5954
190.3800	83.0351	0.3617	-162.6022
190.3883	82.9526	0.3615	-162.6080
190.3967	82.8706	0.3615	-162.6121
190.4050	82.7871	0.3614	-162.6196
190.4133	82.7035	0.3614	-162.6265
190.4217	82.6200	0.3614	-162.6334
190.4300	82.5368	0.3613	-162.6404
190.4383	82.4539	0.3613	-162.6449
190.4467	82.3707	0.3613	-162.6537
190.4550	82.2873	0.3612	-162.6590
190.4633	82.2049	0.3611	-162.6660
190.4717	82.1206	0.3611	-162.6744
190.4800	82.0371	0.3610	-162.6803
190.4883	81.9544	0.3610	-162.6875
190.4967	81.8711	0.3609	-162.6923
190.5050	81.7882	0.3608	-162.6997
190.5133	81.7044	0.3608	-162.7054
190.5217	81.6212	0.3608	-162.7134
190.5300	81.5377	0.3607	-162.7212
190.5383	81.4555	0.3607	-162.7241
190.5467	81.3725	0.3606	-162.7319
190.5550	81.2885	0.3606	-162.7365
190.5633	81.2061	0.3606	-162.7439
190.5717	81.1222	0.3605	-162.7518
190.5800	81.0403	0.3604	-162.7583
190.5883	80.9568	0.3604	-162.7645
190.5967	80.8725	0.3604	-162.7696
190.6050	80.7890	0.3603	-162.7757
190.6133	80.7069	0.3602	-162.7843
190.6217	80.6231	0.3601	-162.7931
190.6300	80.5407	0.3600	-162.7965
190.6383	80.4578	0.3600	-162.8028
190.6467	80.3743	0.3600	-162.8116
190.6550	80.2908	0.3599	-162.8163
190.6633	80.2084	0.3599	-162.8242
190.6717	80.1249	0.3598	-162.8314
190.6800	80.0420	0.3597	-162.8372
190.6883	79.9588	0.3597	-162.8450
190.6967	79.8756	0.3596	-162.8504
190.7050	79.7922	0.3595	-162.8569
190.7133	79.7090	0.3594	-162.8622
190.7217	79.6260	0.3594	-162.8717
190.7300	79.5436	0.3594	-162.8768
190.7383	79.4609	0.3593	-162.8829
190.7467	79.3769	0.3592	-162.8908
190.7550	79.2936	0.3592	-162.8972
190.7633	79.2095	0.3591	-162.9052
190.7717	79.1273	0.3591	-162.9104
190.7800	79.0436	0.3590	-162.9153
190.7883	78.9612	0.3589	-162.9213
190.7967	78.8776	0.3589	-162.9300
190.8050	78.7938	0.3588	-162.9357
190.8133	78.7112	0.3588	-162.9417
190.8217	78.6286	0.3587	-162.9509
190.8300	78.5447	0.3586	-162.9561
190.8383	78.4618	0.3586	-162.9641
190.8467	78.3792	0.3585	-162.9680
190.8550	78.2961	0.3585	-162.9747
190.8633	78.2125	0.3584	-162.9824
190.8717	78.1306	0.3582	-162.9915
190.8800	78.0463	0.3581	-162.9963
190.8883	77.9638	0.3582	-163.0036
190.8967	77.8796	0.3581	-163.0086
190.9050	77.7968	0.3579	-163.0154
190.9133	77.7138	0.3579	-163.0232
190.9217	77.6310	0.3578	-163.0297
190.9300	77.5465	0.3578	-163.0341
190.9383	77.4643	0.3577	-163.0408
190.9467	77.3801	0.3576	-163.0483
190.9550	77.2980	0.3576	-163.0562
190.9633	77.2144	0.3576	-163.0623
190.9717	77.1312	0.3576	-163.0667
190.9800	77.0477	0.3574	-163.0743
190.9883	76.9646	0.3573	-163.0799
190.9967	76.8819	0.3574	-163.0894
191.0050	76.7967	0.3574	-163.0931
191.0133	76.7151	0.3573	-163.1016
191.0217	76.6320	0.3573	-163.1071
191.0300	76.5488	0.3572	-163.1156
191.0383	76.4643	0.3572	-163.1214
191.0467	76.3827	0.3571	-163.1277
191.0550	76.2990	0.3570	-163.1343
191.0633	76.2156	0.3570	-163.1428
191.0717	76.1336	0.3566	-163.1490
191.0800	76.0494	0.3565	-163.1556
191.0883	75.9670	0.3565	-163.1628
191.0967	75.8840	0.3564	-163.1693
191.1050	75.8008	0.3564	-163.1763
191.1133	75.7182	0.3563	-163.1840
191.1217	75.6345	0.3562	-163.1907
191.1300	75.5504	0.3562	-163.1971
191.1383	75.4681	0.3561	-163.2031
191.1467	75.3845	0.3561	-163.2116
191.1550	75.3021	0.3560	-163.2174
191.1633	75.2181	0.3560	-163.2227
191.1717	75.1351	0.3559	-163.2294
191.1800	75.0518	0.3560	-163.2364
191.1883	74.9701	0.3559	-163.2442
191.1967	74.8846	0.3559	-163.2514
191.2050	74.8025	0.3559	-163.2553
191.2133	74.7195	0.3558	-163.2624
191.2217	74.6358	0.3557	-163.2694
191.2300	74.5530	0.3556	-163.2785
191.2383	74.4694	0.3555	-163.2841
191.2467	74.3869	0.3556	-163.2881
191.2550	74.3038	0.3555	-163.2960
191.2633	74.2192	0.3554	-163.3038
191.2717	74.1368	0.3554	-163.3097
191.2800	74.0534	0.3554	-163.3159
191.2883	73.9708	0.3553	-163.3209
191.2967	73.8877	0.3553	-163.3282
191.3050	73.8045	0.3553	-163.3357
191.3133	73.7223	0.3551	-163.3416
191.3217	73.6389	0.3551	-163.3493
191.3300	73.5555	0.3551	-163.3537
191.3383	73.4724	0.3551	-163.3603
191.3467	73.3882	0.3550	-163.3677
191.3550	73.3052	0.3549	-163.3738
191.3633	73.2224	0.3547	-163.3810
191.3717	73.1400	0.3546	-163.3890
191.3800	73.0562	0.3546	-163.3950
191.3883	72.9733	0.3546	-163.3999
191.3967	72.8896	0.3545	-163.4086
191.4050	72.8070	0.3545	-163.4143
191.4133	72.7240	0.3544	-163.4218
191.4217	72.6398	0.3544	-163.4290
191.4300	72.5573	0.3543	-163.4352
191.4383	72.4743	0.3541	-163.4423
191.4467	72.3905	0.3541	-163.4483
191.4550	72.3067	0.3541	-163.4563
191.4633	72.2250	0.3540	-163.4634
191.4717	72.1405	0.3540	-163.4698
191.4800	72.0598	0.3538	-163.4778
191.4883	71.9748	0.3537	-163.4837
191.4967	71.8923	0.3537	-163.4904
191.5050	71.8086	0.3537	-163.4963
191.5133	71.7253	0.3536	-163.5025
191.5217	71.6423	0.3536	-163.5118
191.5300	71.5582	0.3536	-163.5190
191.5383	71.4757	0.3535	-163.5225
191.5467	71.3923	0.3535	-163.5300
191.5550	71.3102	0.3534	-163.5372
191.5633	71.2267	0.3533	-163.5441
191.5717	71.1426	0.3532	-163.5503
191.5800	71.0595	0.3532	-163.5562
191.5883	70.9762	0.3532	-163.5627
191.5967	70.8938	0.3531	-163.5703
191.6050	70.8101	0.3531	-163.5763
191.6133	70.7265	0.3530	-163.5850
191.6217	70.6445	0.3529	-163.5890
191.6300	70.5603	0.3527	-163.5980
191.6383	70.4775	0.3528	-163.6035
191.6467	70.3946	0.3527	-163.6097
191.6550	70.3117	0.3526	-163.6168
191.6633	70.2290	0.3526	-163.6231
191.6717	70.1457	0.3524	-163.6294
191.6800	70.0625	0.3524	-163.6372
191.6883	69.9792	0.3523	-163.6436
191.6967	69.8967	0.3523	-163.6489
191.7050	69.8128	0.3522	-163.6569
191.7133	69.7304	0.3521	-163.6645
191.7217	69.6471	0.3521	-163.6700
191.7300	69.5626	0.3521	-163.6782
191.7383	69.4803	0.3520	-163.6829
191.7467	69.3966	0.3520	-163.6908
191.7550	69.3139	0.3519	-163.6981
191.7633	69.2306	0.3518	-163.7062
191.7717	69.1469	0.3519	-163.7122
191.7800	69.0636	0.3518	-163.7192
191.7883	68.9814	0.3518	-163.7277
191.7967	68.8974	0.3518	-163.7340
191.8050	68.8144	0.3517	-163.7426
191.8133	68.7316	0.3517	-163.7459
191.8217	68.6489	0.3517	-163.7542
191.8300	68.5646	0.3516	-163.7611
191.8383	68.4821	0.3516	-163.7680
191.8467	68.3984	0.3516	-163.7719
191.8550	68.3157	0.3516	-163.7804
191.8633	68.2327	0.3516	-163.7881
191.8717	68.1497	0.3515	-163.7926
191.8800	68.0669	0.3518	-163.8007
191.8883	67.9826	0.3519	-163.8077
191.8967	67.9005	0.3519	-163.8147
191.9050	67.8168	0.3520	-163.8181
191.9133	67.7338	0.3524	-163.8262
191.9217	67.6518	0.3535	-163.8342
191.9300	67.5687	0.3569	-163.8403
191.9383	67.4852	0.3612	-163.8460
191.9467	67.4017	0.3675	-163.8555
191.9550	67.3188	0.3769	-163.8607
191.9633	67.2376	0.3867	-163.8666
191.9717	67.1565	0.3989	-163.8742
191.9800	67.0750	0.4166	-163.8829
191.9883	66.9944	0.4435	-163.8888
191.9967	66.9133	0.4783	-163.8942
192.0050	66.8350	0.5224	-163.9014
192.0133	66.7593	0.5858	-163.9065
192.0217	66.6842	0.6692	-163.9138
192.0300	66.6117	0.7771	-163.9207
192.0383	66.5453	0.9123	-163.9306
192.0467	66.4811	1.0849	-163.9366
192.0550	66.4228	1.2935	-163.9421
192.0633	66.3716	1.5364	-163.9474
192.0717	66.3273	1.8105	-163.9553
192.0800	66.2898	2.1051	-163.9591
192.0883	66.2591	2.4127	-163.9685
192.0967	66.2356	2.7162	-163.9732
192.1050	66.2169	3.0126	-163.9825
192.1133	66.2027	3.2891	-163.9895
192.1217	66.1896	3.5391	-163.9944
192.1300	66.1783	3.7645	-164.0023
192.1383	66.1686	3.9638	-164.0092
192.1467	66.1561	4.1362	-164.0162
192.1550	66.1453	4.2889	-164.0215
192.1633	66.1304	4.4205	-164.0300
192.1717	66.1127	4.5357	-164.0338
192.1800	66.0924	4.6327	-164.0408
192.1883	66.0687	4.7204	-164.0486
192.1967	66.0426	4.7969	-164.0534
192.2050	66.0136	4.8609	-164.0605
192.2133	65.9794	4.9161	-164.0672
192.2217	65.9435	4.9626	-164.0729
192.2300	65.9047	5.0030	-164.0812
192.2383	65.8627	5.0338	-164.0876
192.2467	65.8164	5.0577	-164.0957
192.2550	65.7677	5.0757	-164.1015
192.2633	65.7150	5.0886	-164.1092
192.2717	65.6604	5.0921	-164.1164
192.2800	65.6024	5.0879	-164.1256
192.2883	65.5408	5.0724	-164.1297
192.2967	65.4782	5.0525	-164.1353
192.3050	65.4121	5.0268	-164.1431
192.3133	65.3421	4.9928	-164.1507
192.3217	65.2698	4.9480	-164.1557
192.3300	65.1939	4.8949	-164.1631
192.3383	65.1155	4.8354	-164.1710
192.3467	65.0345	4.7658	-164.1751
192.3550	64.9502	4.6884	-164.1827
192.3633	64.8627	4.6035	-164.1891
192.3717	64.7727	4.5098	-164.1958
192.3800	64.6795	4.4058	-164.2018
192.3883	64.5839	4.2926	-164.2096
192.3967	64.4851	4.1751	-164.2171
192.4050	64.3811	4.0500	-164.2221
192.4133	64.2761	3.9180	-164.2292
192.4217	64.1685	3.7842	-164.2370
192.4300	64.0587	3.6502	-164.2431
192.4383	63.9455	3.5233	-164.2492
192.4467	63.8314	3.3964	-164.2568
192.4550	63.7171	3.2818	-164.2635
192.4633	63.6004	3.1695	-164.2675
192.4717	63.4834	3.0644	-164.2774
192.4800	63.3656	2.9691	-164.2831
192.4883	63.2482	2.8732	-164.2892
192.4967	63.1314	2.7861	-164.2967
192.5050	63.0131	2.7046	-164.3028
192.5133	62.8981	2.6242	-164.3083
192.5217	62.7824	2.5512	-164.3158
192.5300	62.6655	2.4769	-164.3223
192.5383	62.5526	2.4088	-164.3278
192.5467	62.4384	2.3454	-164.3339
192.5550	62.3258	2.2820	-164.3402
192.5633	62.2122	2.2241	-164.3465
192.5717	62.1001	2.1645	-164.3565
192.5800	61.9899	2.1077	-164.3617
192.5883	61.8795	2.0597	-164.3707
192.5967	61.7710	2.0079	-164.3739
192.6050	61.6625	1.9600	-164.3838
192.6133	61.5540	1.9138	-164.3898
192.6217	61.4476	1.8679	-164.3961
192.6300	61.3418	1.8259	-164.4041
192.6383	61.2360	1.7819	-164.4093
192.6467	61.1318	1.7419	-164.4177
192.6550	61.0283	1.7015	-164.4236
192.6633	60.9236	1.6648	-164.4311
192.6717	60.8211	1.6241	-164.4384
192.6800	60.7203	1.5914	-164.4453
192.6883	60.6176	1.5545	-164.4527
192.6967	60.5166	1.5186	-164.4588
192.7050	60.4163	1.4836	-164.4652
192.7133	60.3169	1.4528	-164.4724
192.7217	60.2179	1.4195	-164.4773
192.7300	60.1183	1.3885	-164.4845
192.7383	60.0205	1.3592	-164.4933
192.7467	59.9210	1.3310	-164.4975
192.7550	59.8231	1.3016	-164.5040
192.7633	59.7273	1.2742	-164.5120
192.7717	59.6300	1.2488	-164.5174
192.7800	59.5329	1.2246	-164.5254
192.7883	59.4375	1.1992	-164.5307
192.7967	59.3418	1.1731	-164.5362
192.8050	59.2468	1.1516	-164.5415
192.8133	59.1512	1.1281	-164.5463
192.8217	59.0577	1.1065	-164.5546
192.8300	58.9634	1.0877	-164.5622
192.8383	58.8688	1.0697	-164.5687
192.8467	58.7757	1.0482	-164.5780
192.8550	58.6832	1.0290	-164.5829
192.8633	58.5897	1.0121	-164.5916
192.8717	58.4975	0.9960	-164.5968
192.8800	58.4055	0.9780	-164.6035
192.8883	58.3125	0.9611	-164.6109
192.8967	58.2212	0.9470	-164.6184
192.9050	58.1298	0.9316	-164.6251
192.9133	58.0383	0.9185	-164.6316
192.9217	57.9481	0.9034	-164.6365
192.9300	57.8585	0.8898	-164.6440
192.9383	57.7677	0.8775	-164.6518
192.9467	57.6777	0.8658	-164.6579
192.9550	57.5876	0.8563	-164.6672
192.9633	57.4982	0.8439	-164.6751
192.9717	57.4095	0.8310	-164.6803
192.9800	57.3198	0.8204	-164.6868
192.9883	57.2308	0.8106	-164.6927
192.9967	57.1431	0.7993	-164.7001
193.0050	57.0536	0.7910	-164.7056
193.0133	56.9650	0.7827	-164.7123
193.0217	56.8775	0.7714	-164.7193
193.0300	56.7880	0.7645	-164.7252
193.0383	56.7020	0.7559	-164.7337
193.0467	56.6134	0.7487	-164.7393
193.0550	56.5262	0.7404	-164.7470
193.0633	56.4394	0.7340	-164.7537
193.0717	56.3521	0.7248	-164.7586
193.0800	56.2656	0.7181	-164.7651
193.0883	56.1787	0.7149	-164.7746
193.0967	56.0917	0.7086	-164.7792
193.1050	56.0046	0.7002	-164.7870
193.1133	55.9185	0.6956	-164.7931
193.1217	55.8316	0.6885	-164.8005
193.1300	55.7465	0.6848	-164.8067
193.1383	55.6599	0.6782	-164.8140
193.1467	55.5734	0.6734	-164.8186
193.1550	55.4883	0.6696	-164.8255
193.1633	55.4021	0.6641	-164.8333
193.1717	55.3162	0.6604	-164.8390
193.1800	55.2306	0.6552	-164.8453
193.1883	55.1451	0.6508	-164.8534
193.1967	55.0608	0.6462	-164.8584
193.2050	54.9747	0.6443	-164.8662
193.2133	54.8895	0.6384	-164.8730
193.2217	54.8051	0.6367	-164.8801
193.2300	54.7193	0.6304	-164.8871
193.2383	54.6338	0.6271	-164.8926
193.2467	54.5493	0.6258	-164.8991
193.2550	54.4638	0.6205	-164.9030
193.2633	54.3788	0.6185	-164.9116
193.2717	54.2949	0.6163	-164.9190
193.2800	54.2095	0.6105	-164.9250
193.2883	54.1251	0.6097	-164.9334
193.2967	54.0402	0.6061	-164.9381
193.3050	53.9550	0.6042	-164.9492
193.3133	53.8709	0.5999	-164.9551
193.3217	53.7860	0.5982	-164.9614
193.3300	53.7016	0.5941	-164.9679
193.3383	53.6174	0.5935	-164.9721
193.3467	53.5326	0.5911	-164.9810
193.3550	53.4482	0.5881	-164.9897
193.3633	53.3640	0.5838	-164.9945
193.3717	53.2805	0.5815	-165.0003
193.3800	53.1955	0.5822	-165.0083
193.3883	53.1116	0.5804	-165.0144
193.3967	53.0271	0.5757	-165.0214
193.4050	52.9418	0.5753	-165.0274
193.4133	52.8575	0.5740	-165.0333
193.4217	52.7747	0.5696	-165.0406
193.4300	52.6905	0.5681	-165.0495
193.4383	52.6063	0.5671	-165.0536
193.4467	52.5214	0.5642	-165.0618
193.4550	52.4386	0.5614	-165.0656
193.4633	52.3541	0.5607	-165.0746
193.4717	52.2700	0.5586	-165.0810
193.4800	52.1853	0.5564	-165.0896
193.4883	52.1009	0.5547	-165.0954
193.4967	52.0174	0.5528	-165.1020
193.5050	51.9341	0.5508	-165.1092
193.5133	51.8500	0.5488	-165.1137
193.5217	51.7660	0.5471	-165.1187
193.5300	51.6825	0.5451	-165.1269
193.5383	51.5981	0.5448	-165.1323
193.5467	51.5142	0.5442	-165.1403
193.5550	51.4308	0.5416	-165.1484
193.5633	51.3463	0.5382	-165.1534
193.5717	51.2627	0.5379	-165.1617
193.5800	51.1781	0.5369	-165.1682
193.5883	51.0946	0.5350	-165.1731
193.5967	51.0108	0.5329	-165.1795
193.6050	50.9281	0.5323	-165.1884
193.6133	50.8439	0.5314	-165.1944
193.6217	50.7605	0.5298	-165.2013
193.6300	50.6768	0.5275	-165.2059
193.6383	50.5931	0.5261	-165.2146
193.6467	50.5091	0.5247	-165.2204
193.6550	50.4254	0.5239	-165.2285
193.6633	50.3412	0.5223	-165.2329
193.6717	50.2577	0.5216	-165.2418
193.6800	50.1723	0.5205	-165.2491
193.6883	50.0894	0.5182	-165.2543
193.6967	50.0060	0.5167	-165.2614
193.7050	49.9229	0.5157	-165.2679
193.7133	49.8387	0.5146	-165.2743
193.7217	49.7552	0.5138	-165.2821
193.7300	49.6713	0.5126	-165.2879
193.7383	49.5869	0.5123	-165.2948
193.7467	49.5038	0.5099	-165.3038
193.7550	49.4183	0.5084	-165.3101
193.7633	49.3370	0.5060	-165.3173
193.7717	49.2541	0.5053	-165.3234
193.7800	49.1705	0.5047	-165.3292
193.7883	49.0857	0.5042	-165.3369
193.7967	49.0009	0.5018	-165.3434
193.8050	48.9187	0.5003	-165.3505
193.8133	48.8350	0.4998	-165.3592
193.8217	48.7514	0.4991	-165.3652
193.8300	48.6692	0.4982	-165.3728
193.8383	48.5841	0.4972	-165.3782
193.8467	48.5008	0.4958	-165.3849
193.8550	48.4172	0.4948	-165.3903
193.8633	48.3330	0.4935	-165.3991
193.8717	48.2497	0.4927	-165.4073
193.8800	48.1659	0.4909	-165.4126
193.8883	48.0825	0.4888	-165.4201
193.8967	47.9977	0.4873	-165.4276
193.9050	47.9158	0.4864	-165.4346
193.9133	47.8312	0.4864	-165.4401
193.9217	47.7473	0.4851	-165.4474
193.9300	47.6638	0.4841	-165.4508
193.9383	47.5798	0.4826	-165.4621
193.9467	47.4963	0.4821	-165.4670
193.9550	47.4141	0.4811	-165.4753
193.9633	47.3296	0.4794	-165.4812
193.9717	47.2462	0.4786	-165.4853
193.9800	47.1623	0.4770	-165.4931
193.9883	47.0777	0.4759	-165.4998
193.9967	46.9960	0.4749	-165.5067
194.0050	46.9121	0.4747	-165.5175
194.0133	46.8274	0.4725	-165.5226
194.0217	46.7441	0.4706	-165.5309
194.0300	46.6620	0.4705	-165.5370
194.0383	46.5777	0.4692	-165.5426
194.0467	46.4943	0.4663	-165.5512
194.0550	46.4101	0.4661	-165.5556
194.0633	46.3277	0.4650	-165.5623
194.0717	46.2435	0.4644	-165.5697
194.0800	46.1602	0.4643	-165.5753
194.0883	46.0774	0.4636	-165.5833
194.0967	45.9935	0.4626	-165.5891
194.1050	45.9095	0.4614	-165.5948
194.1133	45.8277	0.4590	-165.6019
194.1217	45.7423	0.4589	-165.6082
194.1300	45.6596	0.4585	-165.6175
194.1383	45.5753	0.4577	-165.6242
194.1467	45.4910	0.4574	-165.6313
194.1550	45.4081	0.4566	-165.6366
194.1633	45.3251	0.4553	-165.6441
194.1717	45.2413	0.4541	-165.6533
194.1800	45.1577	0.4525	-165.6569
194.1883	45.0734	0.4523	-165.6644
194.1967	44.9914	0.4513	-165.6709
194.2050	44.9073	0.4501	-165.6791
194.2133	44.8238	0.4497	-165.6860
194.2217	44.7401	0.4487	-165.6913
194.2300	44.6562	0.4485	-165.6991
194.2383	44.5728	0.4477	-165.7077
194.2467	44.4884	0.4471	-165.7150
194.2550	44.4059	0.4456	-165.7188
194.2633	44.3233	0.4452	-165.7268
194.2717	44.2399	0.4448	-165.7324
194.2800	44.1553	0.4432	-165.7409
194.2883	44.0717	0.4426	-165.7463
194.2967	43.9881	0.4423	-165.7521
194.3050	43.9057	0.4411	-165.7587
194.3133	43.8216	0.4404	-165.7658
194.3217	43.7383	0.4401	-165.7741
194.3300	43.6542	0.4400	-165.7802
194.3383	43.5703	0.4397	-165.7863
194.3467	43.4884	0.4391	-165.7911
194.3550	43.4047	0.4380	-165.8001
194.3633	43.3208	0.4367	-165.8056
194.3717	43.2367	0.4364	-165.8113
194.3800	43.1543	0.4359	-165.8192
194.3883	43.0708	0.4355	-165.8245
194.3967	42.9881	0.4353	-165.8311
194.4050	42.9041	0.4353	-165.8369
194.4133	42.8197	0.4350	-165.8448
194.4217	42.7364	0.4332	-165.8494
194.4300	42.6539	0.4328	-165.8573
194.4383	42.5697	0.4326	-165.8657
194.4467	42.4866		-165.8716
194.4550	42.4034		-165.8783
194.4633	42.3211		-165.8868
194.4717	42.2367		-165.8934
194.4800	42.1547		-165.9000
194.4883	42.0704		-165.9060
194.4967			-165.9124