File: Example Date/DSC TA/YN039-A.txt
Filename	YN039-A
Instrument name	DSC2A-01799 (192.168.1.250)
Operator
rundate	04/12/2024
Sample name	YN039-A
proceduresegments	Ramp 10.00 °C/min to 150.0000 °C; Isothermal 3.0 min; Ramp 10.00 °C/min to -100.0000 °C; Isothermal 3.0 min; Ramp 10.00 °C/min to 150.0000 °C; Isothermal 3.0 min; Ramp 10.00 °C/min to -100.0000 °C; Isothermal 3.0 min; Ramp 10.00 °C/min to 150.0000 °C; Isothermal 3.0 min; Ramp 10.00 °C/min to -100.0000 °C; Isothermal 3.0 min; Ramp 10.00 °C/min to 150.0000 °C; Isothermal 3.0 min; Ramp 10.00 °C/min to 40.0000 °C
[File Parameters]
Run Date	04/12/2024 10:10:18
Trios version	5.7.0.56
Original File Name
Current File Name	C:\Users\TA Instruments DSC\Desktop\Data\Yutong Niu\YN039-A.tri
User at run start	DESKTOP-CFGN8IT\TA Instruments DSC
[Procedure]
Procedure Name	polyester
Sample Name	YN039-A
Sample Mass	16.67 mg
Reference Sample Mass	0 mg
Pan Mass	61.29 mg
Pan Number	23
Reference Pan Mass	60.81 mg
Reference Pan Number	45
Pan Type	Tzero Aluminum Pin Hole Hermetic
Comments
Project Name
Operator
Test	Custom
Unload Max Temperature	25
Unload Min Temperature	25
FillCooler	Do not fill
Load Max Temperature	25
Load Min Temperature	25
Discard pan in waste bin at end of test	Yes
Stop on Gas Flow Error	No
[Signal List]
Signal #1	Time (min)
Signal #2	Temperature (°C)
Signal #3	Heat Flow (mW)
Signal #4	Delta T (µV)
Signal #5	Delta Tzero (µV)
Signal #6	Tzero Temperature (°C)
Signal #7	Cell Purge (mL/min)
Signal #8	Heater Temp (°C)
Signal #9	Power Delivered (W)
Signal #10	Reference Junction Temperature (°C)
Signal #11	Flange Temperature (°C)
Signal #12	Heat Flow Phase (rad)
Signal #13	Total Heat Capacity (J/°C)
Signal #14	Heat Capacity (J/°C)
Signal #15	LN Pump Tank level (%)
[Configuration]
Company Name	Warwick University
Instrument Name	DSC2A-01799
Instrument Type	DSC2500
Serial Number	DSC2A-01799
IP	192.168.1.250
Location of Instrument	Polymer RTP
DisplayType	TianmaV2andV3
Sample Interval 	0.1 s/pt
Selected Heat Flow	T4P
Exotherm Direction	Up
Cell Serial	DRC2-03788
Lid Type	High Temperature
Cooler	LN Pump
Leave Cooler on at End of Sequence	Off
Gas 2	Air
Gas Selected	Channel 1: Nitrogen
Flow Rate	50 mL/min
Secondary Purge	On
Licensed Heat Flow	Heat Flow T4P
Modulation Licensed	Yes
[Versions]
Common IDD Version	1
Cortex Version	VER 2.11.0.729
Driver	5.0.0.6
GDM Version	1.0.3.3
TouchscreenVersion	1.0.3.1841
FEP Version	1.2.1.21
FEP Bootloader	2.0.0.5
AutoSampler Version	2.1.2.1
Auto Sampler Bootloader	2.0.0.5
FCM Version	1.1.0.3
FCM Bootloader	2.0.0.5
LN Pump Version	10.17.0.0
LN Pump Bootloader	2.0.0.5
[Experiment Logs]
Experiment Log Entry # 1	Ramp Segment 10 C/min to 150 Started
Experiment Log Entry # 3	Air Cool is off.
Experiment Log Entry # 5	Isothermal Segment 3 min started
Experiment Log Entry # 7	Ramp Segment 10 C/min to -100 Started
Experiment Log Entry # 9	Isothermal Segment 3 min started
Experiment Log Entry # 11	Ramp Segment 10 C/min to 150 Started
Experiment Log Entry # 13	Isothermal Segment 3 min started
Experiment Log Entry # 15	Ramp Segment 10 C/min to -100 Started
Experiment Log Entry # 17	Isothermal Segment 3 min started
Experiment Log Entry # 19	Ramp Segment 10 C/min to 150 Started
Experiment Log Entry # 22	LN2P is filling
Experiment Log Entry # 24	LN2P stopped filling
Experiment Log Entry # 25	Isothermal Segment 3 min started
Experiment Log Entry # 27	Ramp Segment 10 C/min to -100 Started
[Method Log]
Method Log Entry # 1	(Ramp 2400979) Ramp 10 °C/minute to 150 °C
Method Log Entry # 2	Isothermal 3 minutes
Method Log Entry # 3	(Ramp 2400981) Ramp 10 °C/minute to -100 °C
Method Log Entry # 4	Isothermal 3 minutes
Method Log Entry # 5	(Ramp 2400983) Ramp 10 °C/minute to 150 °C
Method Log Entry # 6	Isothermal 3 minutes
Method Log Entry # 7	(Ramp 2400985) Ramp 10 °C/minute to -100 °C
Method Log Entry # 8	Isothermal 3 minutes
Method Log Entry # 9	(Ramp 2400987) Ramp 10 °C/minute to 150 °C
Method Log Entry # 10	Isothermal 3 minutes
Method Log Entry # 11	(Ramp 2400989) Ramp 10 °C/minute to -100 °C
Cell Serial	DRC2-03788
[T1 Calibration]
Date Applied	04/03/2021 14:58:04
Description
Gas Type	Nitrogen
Pan Type	None
Slope	-0.001800291
Offset	-0.1301359
Initial Temperature	-100.6228
GUID	a1d5a6be-decd-4ae4-b22f-d560f3a78a92
[TZero Calibration]
Date Applied	21/08/2024 09:53:38
Description	From -180.022 °C to 395.167 °C at 20.000°C/min
Gas Type	Nitrogen
Pan Type	None
Source Files 1	C:\ProgramData\TA Instruments\TRIOS\Data\TAService\PMV 20Aug2024\Tzero Cal.tri
Source Files 2	C:\ProgramData\TA Instruments\TRIOS\Data\TAService\PMV 20Aug2024\Tzero Cal sapphire.tri
Delta T Offset	1.787969
Delta T Slope	-0.003527276
Delta T0 Offset	0.06831977
Delta T0 Slope	0.02007191
[Temperature Calibration]
Date Applied	21/08/2024 11:06:35
Description	From 106.660 °C to 186.660 °C at 10.000°C/min
Gas Type	Nitrogen
Pan Type	Tzero Aluminum
Source Files 1	C:\ProgramData\TA Instruments\TRIOS\Data\TAService\PMV 20Aug2024\TA Indium cal.tri
Measured 1	157.9141
Known 1	156.66
[Cell Constant Calibration]
Date Applied	21/08/2024 11:06:35
Description	From 106.660 °C to 186.660 °C at 10.000°C/min
Gas Type	Nitrogen
Pan Type	Tzero Aluminum
Source Files 1	C:\ProgramData\TA Instruments\TRIOS\Data\TAService\PMV 20Aug2024\TA Indium cal.tri
T4P KCell	1.038055
Onset Slope	-66.72884 mW/°C
[Direct Cp Calibration]
Date Applied	19/11/2024 16:37:27
Description	From -89.996 °C to 396.697 °C at 20.000°C/min
Gas Type	Nitrogen
Pan Type	Tzero Aluminum
Source Files 1	C:\ProgramData\TA Instruments\TRIOS\Data\Sapphire Direct Heat Capacity(8).tri
GUID	544f8371-fe9b-4f4f-81ca-7980c172113e
Temperature	-89.99625 °C
Cp	1.464367
Temperature	-89.02287 °C
Cp	1.460558
Temperature	-88.04948 °C
Cp	1.456263
Temperature	-87.0761 °C
Cp	1.451626
Temperature	-86.10271 °C
Cp	1.446737
Temperature	-85.12933 °C
Cp	1.441723
Temperature	-84.15594 °C
Cp	1.436654
Temperature	-83.18256 °C
Cp	1.431684
Temperature	-82.20917 °C
Cp	1.426935
Temperature	-81.23578 °C
Cp	1.422396
Temperature	-80.2624 °C
Cp	1.418192
Temperature	-79.28901 °C
Cp	1.414363
Temperature	-78.31562 °C
Cp	1.410925
Temperature	-77.34224 °C
Cp	1.407865
Temperature	-76.36885 °C
Cp	1.405143
Temperature	-75.39546 °C
Cp	1.402789
Temperature	-74.42208 °C
Cp	1.400703
Temperature	-73.44869 °C
Cp	1.398837
Temperature	-72.4753 °C
Cp	1.397142
Temperature	-71.50192 °C
Cp	1.395565
Temperature	-70.52853 °C
Cp	1.394053
Temperature	-69.55515 °C
Cp	1.392558
Temperature	-68.58176 °C
Cp	1.391036
Temperature	-67.60838 °C
Cp	1.389483
Temperature	-66.63499 °C
Cp	1.387847
Temperature	-65.66161 °C
Cp	1.38616
Temperature	-64.68822 °C
Cp	1.384397
Temperature	-63.71483 °C
Cp	1.382535
Temperature	-62.74145 °C
Cp	1.380598
Temperature	-61.76806 °C
Cp	1.37865
Temperature	-60.79467 °C
Cp	1.376673
Temperature	-59.82129 °C
Cp	1.374677
Temperature	-58.8479 °C
Cp	1.372642
Temperature	-57.87452 °C
Cp	1.370686
Temperature	-56.90113 °C
Cp	1.368741
Temperature	-55.92775 °C
Cp	1.366786
Temperature	-54.95436 °C
Cp	1.364863
Temperature	-53.98097 °C
Cp	1.362959
Temperature	-53.00759 °C
Cp	1.361116
Temperature	-52.0342 °C
Cp	1.359247
Temperature	-51.06082 °C
Cp	1.357393
Temperature	-50.08743 °C
Cp	1.355593
Temperature	-49.11404 °C
Cp	1.353796
Temperature	-48.14066 °C
Cp	1.352008
Temperature	-47.16727 °C
Cp	1.350215
Temperature	-46.19389 °C
Cp	1.348396
Temperature	-45.2205 °C
Cp	1.346593
Temperature	-44.24712 °C
Cp	1.344755
Temperature	-43.27373 °C
Cp	1.342891
Temperature	-42.30034 °C
Cp	1.341008
Temperature	-41.32696 °C
Cp	1.339126
Temperature	-40.35357 °C
Cp	1.337236
Temperature	-39.38018 °C
Cp	1.335367
Temperature	-38.4068 °C
Cp	1.333522
Temperature	-37.43341 °C
Cp	1.331708
Temperature	-36.46003 °C
Cp	1.32991
Temperature	-35.48664 °C
Cp	1.328145
Temperature	-34.51326 °C
Cp	1.326414
Temperature	-33.53987 °C
Cp	1.32471
Temperature	-32.56648 °C
Cp	1.323012
Temperature	-31.5931 °C
Cp	1.321323
Temperature	-30.61971 °C
Cp	1.319657
Temperature	-29.64633 °C
Cp	1.317968
Temperature	-28.67294 °C
Cp	1.316286
Temperature	-27.69955 °C
Cp	1.314585
Temperature	-26.72617 °C
Cp	1.312857
Temperature	-25.75278 °C
Cp	1.31111
Temperature	-24.7794 °C
Cp	1.309333
Temperature	-23.80601 °C
Cp	1.307544
Temperature	-22.83262 °C
Cp	1.30575
Temperature	-21.85924 °C
Cp	1.303941
Temperature	-20.88585 °C
Cp	1.302132
Temperature	-19.91247 °C
Cp	1.300313
Temperature	-18.93908 °C
Cp	1.298512
Temperature	-17.96569 °C
Cp	1.296728
Temperature	-16.99231 °C
Cp	1.294939
Temperature	-16.01892 °C
Cp	1.293198
Temperature	-15.04554 °C
Cp	1.291453
Temperature	-14.07215 °C
Cp	1.289723
Temperature	-13.09876 °C
Cp	1.288007
Temperature	-12.12538 °C
Cp	1.286283
Temperature	-11.15199 °C
Cp	1.284578
Temperature	-10.17861 °C
Cp	1.282885
Temperature	-9.205221 °C
Cp	1.281173
Temperature	-8.231835 °C
Cp	1.279472
Temperature	-7.258449 °C
Cp	1.277766
Temperature	-6.285063 °C
Cp	1.276053
Temperature	-5.311677 °C
Cp	1.274341
Temperature	-4.338291 °C
Cp	1.272592
Temperature	-3.364905 °C
Cp	1.270844
Temperature	-2.391519 °C
Cp	1.269062
Temperature	-1.418133 °C
Cp	1.267264
Temperature	-0.4447474 °C
Cp	1.265435
Temperature	0.5286385 °C
Cp	1.263575
Temperature	1.502024 °C
Cp	1.261727
Temperature	2.47541 °C
Cp	1.259854
Temperature	3.448796 °C
Cp	1.257978
Temperature	4.422182 °C
Cp	1.256109
Temperature	5.395568 °C
Cp	1.254244
Temperature	6.368954 °C
Cp	1.252392
Temperature	7.34234 °C
Cp	1.250552
Temperature	8.315726 °C
Cp	1.248704
Temperature	9.289112 °C
Cp	1.246884
Temperature	10.2625 °C
Cp	1.245078
Temperature	11.23588 °C
Cp	1.243287
Temperature	12.20927 °C
Cp	1.241522
Temperature	13.18266 °C
Cp	1.239778
Temperature	14.15604 °C
Cp	1.238068
Temperature	15.12943 °C
Cp	1.236393
Temperature	16.10281 °C
Cp	1.234762
Temperature	17.0762 °C
Cp	1.233176
Temperature	18.04959 °C
Cp	1.231629
Temperature	19.02297 °C
Cp	1.230129
Temperature	19.99636 °C
Cp	1.228694
Temperature	20.96974 °C
Cp	1.22731
Temperature	21.94313 °C
Cp	1.225968
Temperature	22.91652 °C
Cp	1.224676
Temperature	23.8899 °C
Cp	1.223431
Temperature	24.86329 °C
Cp	1.222217
Temperature	25.83667 °C
Cp	1.221065
Temperature	26.81006 °C
Cp	1.219919
Temperature	27.78345 °C
Cp	1.218811
Temperature	28.75683 °C
Cp	1.21773
Temperature	29.73022 °C
Cp	1.216663
Temperature	30.7036 °C
Cp	1.2156
Temperature	31.67699 °C
Cp	1.214515
Temperature	32.65038 °C
Cp	1.213439
Temperature	33.62376 °C
Cp	1.21234
Temperature	34.59715 °C
Cp	1.211209
Temperature	35.57053 °C
Cp	1.210051
Temperature	36.54392 °C
Cp	1.208868
Temperature	37.5173 °C
Cp	1.207666
Temperature	38.49069 °C
Cp	1.206439
Temperature	39.46408 °C
Cp	1.205199
Temperature	40.43746 °C
Cp	1.203959
Temperature	41.41085 °C
Cp	1.202712
Temperature	42.38424 °C
Cp	1.20147
Temperature	43.35762 °C
Cp	1.200231
Temperature	44.33101 °C
Cp	1.199
Temperature	45.30439 °C
Cp	1.197777
Temperature	46.27778 °C
Cp	1.19657
Temperature	47.25116 °C
Cp	1.195367
Temperature	48.22455 °C
Cp	1.194179
Temperature	49.19794 °C
Cp	1.19301
Temperature	50.17132 °C
Cp	1.191849
Temperature	51.14471 °C
Cp	1.190694
Temperature	52.11809 °C
Cp	1.189555
Temperature	53.09148 °C
Cp	1.18843
Temperature	54.06487 °C
Cp	1.187311
Temperature	55.03825 °C
Cp	1.186195
Temperature	56.01164 °C
Cp	1.185095
Temperature	56.98502 °C
Cp	1.183997
Temperature	57.95841 °C
Cp	1.182894
Temperature	58.93179 °C
Cp	1.181793
Temperature	59.90518 °C
Cp	1.180693
Temperature	60.87857 °C
Cp	1.179595
Temperature	61.85195 °C
Cp	1.178501
Temperature	62.82534 °C
Cp	1.177406
Temperature	63.79873 °C
Cp	1.176313
Temperature	64.77211 °C
Cp	1.175239
Temperature	65.7455 °C
Cp	1.17417
Temperature	66.71888 °C
Cp	1.173105
Temperature	67.69227 °C
Cp	1.172037
Temperature	68.66566 °C
Cp	1.170989
Temperature	69.63904 °C
Cp	1.169948
Temperature	70.61243 °C
Cp	1.168905
Temperature	71.58582 °C
Cp	1.167872
Temperature	72.5592 °C
Cp	1.166849
Temperature	73.53259 °C
Cp	1.165851
Temperature	74.50597 °C
Cp	1.164848
Temperature	75.47935 °C
Cp	1.163876
Temperature	76.45274 °C
Cp	1.162926
Temperature	77.42612 °C
Cp	1.162008
Temperature	78.39951 °C
Cp	1.161113
Temperature	79.3729 °C
Cp	1.160219
Temperature	80.34628 °C
Cp	1.159377
Temperature	81.31967 °C
Cp	1.158546
Temperature	82.29306 °C
Cp	1.157726
Temperature	83.26644 °C
Cp	1.15692
Temperature	84.23983 °C
Cp	1.156126
Temperature	85.21322 °C
Cp	1.155375
Temperature	86.1866 °C
Cp	1.154604
Temperature	87.15999 °C
Cp	1.153869
Temperature	88.13337 °C
Cp	1.153158
Temperature	89.10676 °C
Cp	1.152474
Temperature	90.08015 °C
Cp	1.15181
Temperature	91.05353 °C
Cp	1.151134
Temperature	92.02692 °C
Cp	1.150513
Temperature	93.00031 °C
Cp	1.149892
Temperature	93.97369 °C
Cp	1.149266
Temperature	94.94707 °C
Cp	1.148642
Temperature	95.92046 °C
Cp	1.148019
Temperature	96.89384 °C
Cp	1.147402
Temperature	97.86723 °C
Cp	1.146799
Temperature	98.84062 °C
Cp	1.146191
Temperature	99.814 °C
Cp	1.145602
Temperature	100.7874 °C
Cp	1.14503
Temperature	101.7608 °C
Cp	1.144469
Temperature	102.7342 °C
Cp	1.143921
Temperature	103.7076 °C
Cp	1.143383
Temperature	104.6809 °C
Cp	1.142861
Temperature	105.6543 °C
Cp	1.142345
Temperature	106.6277 °C
Cp	1.141835
Temperature	107.6011 °C
Cp	1.141335
Temperature	108.5745 °C
Cp	1.140846
Temperature	109.5479 °C
Cp	1.140365
Temperature	110.5212 °C
Cp	1.139891
Temperature	111.4946 °C
Cp	1.139429
Temperature	112.468 °C
Cp	1.138976
Temperature	113.4414 °C
Cp	1.13853
Temperature	114.4148 °C
Cp	1.138092
Temperature	115.3882 °C
Cp	1.137654
Temperature	116.3616 °C
Cp	1.137223
Temperature	117.335 °C
Cp	1.136785
Temperature	118.3083 °C
Cp	1.136338
Temperature	119.2817 °C
Cp	1.13588
Temperature	120.2551 °C
Cp	1.13541
Temperature	121.2285 °C
Cp	1.134927
Temperature	122.2019 °C
Cp	1.134417
Temperature	123.1753 °C
Cp	1.133892
Temperature	124.1487 °C
Cp	1.133347
Temperature	125.122 °C
Cp	1.132786
Temperature	126.0954 °C
Cp	1.132206
Temperature	127.0688 °C
Cp	1.131606
Temperature	128.0422 °C
Cp	1.130999
Temperature	129.0156 °C
Cp	1.130384
Temperature	129.989 °C
Cp	1.129765
Temperature	130.9624 °C
Cp	1.129147
Temperature	131.9357 °C
Cp	1.12854
Temperature	132.9091 °C
Cp	1.127949
Temperature	133.8825 °C
Cp	1.127383
Temperature	134.8559 °C
Cp	1.126841
Temperature	135.8293 °C
Cp	1.126334
Temperature	136.8027 °C
Cp	1.125871
Temperature	137.7761 °C
Cp	1.125443
Temperature	138.7494 °C
Cp	1.125058
Temperature	139.7228 °C
Cp	1.124701
Temperature	140.6962 °C
Cp	1.124397
Temperature	141.6696 °C
Cp	1.124114
Temperature	142.643 °C
Cp	1.123854
Temperature	143.6164 °C
Cp	1.123612
Temperature	144.5898 °C
Cp	1.123385
Temperature	145.5631 °C
Cp	1.123182
Temperature	146.5365 °C
Cp	1.12296
Temperature	147.5099 °C
Cp	1.12275
Temperature	148.4833 °C
Cp	1.122543
Temperature	149.4567 °C
Cp	1.122327
Temperature	150.4301 °C
Cp	1.122099
Temperature	151.4035 °C
Cp	1.121837
Temperature	152.3768 °C
Cp	1.121582
Temperature	153.3502 °C
Cp	1.121289
Temperature	154.3236 °C
Cp	1.120967
Temperature	155.297 °C
Cp	1.120616
Temperature	156.2704 °C
Cp	1.120238
Temperature	157.2438 °C
Cp	1.119862
Temperature	158.2172 °C
Cp	1.119444
Temperature	159.1906 °C
Cp	1.119028
Temperature	160.1639 °C
Cp	1.118613
Temperature	161.1373 °C
Cp	1.118202
Temperature	162.1107 °C
Cp	1.117795
Temperature	163.0841 °C
Cp	1.117374
Temperature	164.0575 °C
Cp	1.116987
Temperature	165.0309 °C
Cp	1.116595
Temperature	166.0042 °C
Cp	1.116198
Temperature	166.9776 °C
Cp	1.1158
Temperature	167.951 °C
Cp	1.115402
Temperature	168.9244 °C
Cp	1.115006
Temperature	169.8978 °C
Cp	1.11462
Temperature	170.8712 °C
Cp	1.114223
Temperature	171.8446 °C
Cp	1.113836
Temperature	172.8179 °C
Cp	1.113458
Temperature	173.7913 °C
Cp	1.113085
Temperature	174.7647 °C
Cp	1.112712
Temperature	175.7381 °C
Cp	1.112323
Temperature	176.7115 °C
Cp	1.111957
Temperature	177.6849 °C
Cp	1.111578
Temperature	178.6583 °C
Cp	1.111185
Temperature	179.6317 °C
Cp	1.110789
Temperature	180.605 °C
Cp	1.110391
Temperature	181.5784 °C
Cp	1.110016
Temperature	182.5518 °C
Cp	1.109611
Temperature	183.5252 °C
Cp	1.109232
Temperature	184.4986 °C
Cp	1.108873
Temperature	185.472 °C
Cp	1.108531
Temperature	186.4454 °C
Cp	1.108199
Temperature	187.4187 °C
Cp	1.107851
Temperature	188.3921 °C
Cp	1.107551
Temperature	189.3655 °C
Cp	1.107238
Temperature	190.3389 °C
Cp	1.106917
Temperature	191.3123 °C
Cp	1.106589
Temperature	192.2857 °C
Cp	1.106259
Temperature	193.259 °C
Cp	1.105958
Temperature	194.2324 °C
Cp	1.105619
Temperature	195.2058 °C
Cp	1.105301
Temperature	196.1792 °C
Cp	1.105002
Temperature	197.1526 °C
Cp	1.104718
Temperature	198.126 °C
Cp	1.104445
Temperature	199.0994 °C
Cp	1.104161
Temperature	200.0728 °C
Cp	1.103914
Temperature	201.0461 °C
Cp	1.103657
Temperature	202.0195 °C
Cp	1.103395
Temperature	202.9929 °C
Cp	1.103125
Temperature	203.9663 °C
Cp	1.102847
Temperature	204.9397 °C
Cp	1.102563
Temperature	205.9131 °C
Cp	1.102283
Temperature	206.8865 °C
Cp	1.101985
Temperature	207.8598 °C
Cp	1.10169
Temperature	208.8332 °C
Cp	1.101394
Temperature	209.8066 °C
Cp	1.101099
Temperature	210.78 °C
Cp	1.1008
Temperature	211.7534 °C
Cp	1.10049
Temperature	212.7268 °C
Cp	1.100193
Temperature	213.7002 °C
Cp	1.099886
Temperature	214.6735 °C
Cp	1.099577
Temperature	215.6469 °C
Cp	1.099268
Temperature	216.6203 °C
Cp	1.098965
Temperature	217.5937 °C
Cp	1.098685
Temperature	218.5671 °C
Cp	1.098396
Temperature	219.5405 °C
Cp	1.098134
Temperature	220.5139 °C
Cp	1.097895
Temperature	221.4872 °C
Cp	1.09768
Temperature	222.4606 °C
Cp	1.097485
Temperature	223.434 °C
Cp	1.097292
Temperature	224.4074 °C
Cp	1.09714
Temperature	225.3808 °C
Cp	1.096991
Temperature	226.3542 °C
Cp	1.096844
Temperature	227.3276 °C
Cp	1.096699
Temperature	228.3009 °C
Cp	1.096559
Temperature	229.2743 °C
Cp	1.096442
Temperature	230.2477 °C
Cp	1.096296
Temperature	231.2211 °C
Cp	1.096164
Temperature	232.1945 °C
Cp	1.09604
Temperature	233.1679 °C
Cp	1.095924
Temperature	234.1413 °C
Cp	1.095807
Temperature	235.1147 °C
Cp	1.095665
Temperature	236.088 °C
Cp	1.095557
Temperature	237.0614 °C
Cp	1.095433
Temperature	238.0348 °C
Cp	1.095296
Temperature	239.0082 °C
Cp	1.095147
Temperature	239.9816 °C
Cp	1.094995
Temperature	240.955 °C
Cp	1.094843
Temperature	241.9283 °C
Cp	1.094705
Temperature	242.9017 °C
Cp	1.094562
Temperature	243.8751 °C
Cp	1.094442
Temperature	244.8485 °C
Cp	1.094344
Temperature	245.8219 °C
Cp	1.094266
Temperature	246.7953 °C
Cp	1.094209
Temperature	247.7687 °C
Cp	1.094161
Temperature	248.7421 °C
Cp	1.094144
Temperature	249.7154 °C
Cp	1.094133
Temperature	250.6888 °C
Cp	1.094127
Temperature	251.6622 °C
Cp	1.094126
Temperature	252.6356 °C
Cp	1.094127
Temperature	253.609 °C
Cp	1.094138
Temperature	254.5824 °C
Cp	1.09413
Temperature	255.5558 °C
Cp	1.094123
Temperature	256.5291 °C
Cp	1.094111
Temperature	257.5025 °C
Cp	1.094087
Temperature	258.4759 °C
Cp	1.094046
Temperature	259.4493 °C
Cp	1.093978
Temperature	260.4227 °C
Cp	1.093895
Temperature	261.3961 °C
Cp	1.093783
Temperature	262.3694 °C
Cp	1.093645
Temperature	263.3428 °C
Cp	1.093483
Temperature	264.3162 °C
Cp	1.093302
Temperature	265.2896 °C
Cp	1.093109
Temperature	266.263 °C
Cp	1.092906
Temperature	267.2364 °C
Cp	1.092704
Temperature	268.2098 °C
Cp	1.092511
Temperature	269.1832 °C
Cp	1.092331
Temperature	270.1566 °C
Cp	1.092174
Temperature	271.1299 °C
Cp	1.092046
Temperature	272.1033 °C
Cp	1.091947
Temperature	273.0767 °C
Cp	1.091882
Temperature	274.0501 °C
Cp	1.091853
Temperature	275.0235 °C
Cp	1.091859
Temperature	275.9969 °C
Cp	1.091895
Temperature	276.9702 °C
Cp	1.091957
Temperature	277.9436 °C
Cp	1.092036
Temperature	278.917 °C
Cp	1.092132
Temperature	279.8904 °C
Cp	1.09223
Temperature	280.8638 °C
Cp	1.092323
Temperature	281.8372 °C
Cp	1.092405
Temperature	282.8105 °C
Cp	1.092468
Temperature	283.7839 °C
Cp	1.092513
Temperature	284.7573 °C
Cp	1.092525
Temperature	285.7307 °C
Cp	1.092512
Temperature	286.7041 °C
Cp	1.092472
Temperature	287.6775 °C
Cp	1.092405
Temperature	288.6509 °C
Cp	1.092313
Temperature	289.6243 °C
Cp	1.092197
Temperature	290.5977 °C
Cp	1.09207
Temperature	291.571 °C
Cp	1.091931
Temperature	292.5444 °C
Cp	1.091785
Temperature	293.5178 °C
Cp	1.091641
Temperature	294.4912 °C
Cp	1.091506
Temperature	295.4646 °C
Cp	1.091387
Temperature	296.438 °C
Cp	1.091282
Temperature	297.4113 °C
Cp	1.091201
Temperature	298.3847 °C
Cp	1.091145
Temperature	299.3581 °C
Cp	1.091112
Temperature	300.3315 °C
Cp	1.091102
Temperature	301.3049 °C
Cp	1.091107
Temperature	302.2783 °C
Cp	1.091137
Temperature	303.2517 °C
Cp	1.091177
Temperature	304.2251 °C
Cp	1.091226
Temperature	305.1984 °C
Cp	1.09128
Temperature	306.1718 °C
Cp	1.091336
Temperature	307.1452 °C
Cp	1.091403
Temperature	308.1186 °C
Cp	1.091453
Temperature	309.092 °C
Cp	1.091506
Temperature	310.0654 °C
Cp	1.091561
Temperature	311.0388 °C
Cp	1.091617
Temperature	312.0121 °C
Cp	1.09167
Temperature	312.9855 °C
Cp	1.091716
Temperature	313.9589 °C
Cp	1.091762
Temperature	314.9323 °C
Cp	1.091805
Temperature	315.9057 °C
Cp	1.091838
Temperature	316.8791 °C
Cp	1.09186
Temperature	317.8524 °C
Cp	1.091871
Temperature	318.8258 °C
Cp	1.091872
Temperature	319.7992 °C
Cp	1.091867
Temperature	320.7726 °C
Cp	1.091838
Temperature	321.746 °C
Cp	1.0918
Temperature	322.7194 °C
Cp	1.091752
Temperature	323.6928 °C
Cp	1.091689
Temperature	324.6662 °C
Cp	1.091611
Temperature	325.6396 °C
Cp	1.091508
Temperature	326.6129 °C
Cp	1.091406
Temperature	327.5863 °C
Cp	1.091285
Temperature	328.5597 °C
Cp	1.09115
Temperature	329.5331 °C
Cp	1.091009
Temperature	330.5065 °C
Cp	1.09087
Temperature	331.4799 °C
Cp	1.090747
Temperature	332.4532 °C
Cp	1.090628
Temperature	333.4266 °C
Cp	1.090536
Temperature	334.4 °C
Cp	1.090472
Temperature	335.3734 °C
Cp	1.090437
Temperature	336.3468 °C
Cp	1.090431
Temperature	337.3202 °C
Cp	1.090455
Temperature	338.2935 °C
Cp	1.090503
Temperature	339.2669 °C
Cp	1.090573
Temperature	340.2403 °C
Cp	1.090658
Temperature	341.2137 °C
Cp	1.090753
Temperature	342.1871 °C
Cp	1.090853
Temperature	343.1605 °C
Cp	1.090952
Temperature	344.1339 °C
Cp	1.09105
Temperature	345.1073 °C
Cp	1.091141
Temperature	346.0807 °C
Cp	1.091225
Temperature	347.054 °C
Cp	1.091303
Temperature	348.0274 °C
Cp	1.091379
Temperature	349.0008 °C
Cp	1.091453
Temperature	349.9742 °C
Cp	1.091537
Temperature	350.9476 °C
Cp	1.091633
Temperature	351.921 °C
Cp	1.091743
Temperature	352.8943 °C
Cp	1.091874
Temperature	353.8677 °C
Cp	1.092028
Temperature	354.8411 °C
Cp	1.092206
Temperature	355.8145 °C
Cp	1.092411
Temperature	356.7879 °C
Cp	1.092628
Temperature	357.7613 °C
Cp	1.092862
Temperature	358.7346 °C
Cp	1.093102
Temperature	359.708 °C
Cp	1.093338
Temperature	360.6814 °C
Cp	1.093559
Temperature	361.6548 °C
Cp	1.093752
Temperature	362.6282 °C
Cp	1.093915
Temperature	363.6016 °C
Cp	1.094036
Temperature	364.575 °C
Cp	1.094117
Temperature	365.5484 °C
Cp	1.094159
Temperature	366.5218 °C
Cp	1.094172
Temperature	367.4951 °C
Cp	1.094165
Temperature	368.4685 °C
Cp	1.094163
Temperature	369.4419 °C
Cp	1.094182
Temperature	370.4153 °C
Cp	1.094244
Temperature	371.3887 °C
Cp	1.094375
Temperature	372.3621 °C
Cp	1.094598
Temperature	373.3354 °C
Cp	1.094937
Temperature	374.3088 °C
Cp	1.095389
Temperature	375.2822 °C
Cp	1.095973
Temperature	376.2556 °C
Cp	1.096685
Temperature	377.229 °C
Cp	1.097506
Temperature	378.2024 °C
Cp	1.098406
Temperature	379.1758 °C
Cp	1.099338
Temperature	380.1492 °C
Cp	1.10027
Temperature	381.1225 °C
Cp	1.10112
Temperature	382.0959 °C
Cp	1.101818
Temperature	383.0693 °C
Cp	1.10229
Temperature	384.0427 °C
Cp	1.102459
Temperature	385.0161 °C
Cp	1.102253
Temperature	385.9895 °C
Cp	1.101596
Temperature	386.9629 °C
Cp	1.100438
Temperature	387.9362 °C
Cp	1.098736
Temperature	388.9096 °C
Cp	1.096461
Temperature	389.883 °C
Cp	1.093614
Temperature	390.8564 °C
Cp	1.090208
Temperature	391.8298 °C
Cp	1.086278
Temperature	392.8032 °C
Cp	1.081887
Temperature	393.7766 °C
Cp	1.077096
Temperature	394.7499 °C
Cp	1.072007
Temperature	395.7233 °C
Cp	1.066707
[Rev Cp Calibration]
Date Applied	24/10/2024 12:37:31
Description	From -89.998 °C to 390.542 °C at 2.000°C/min
Gas Type	Nitrogen
Pan Type	Tzero Aluminum
Source Files 1	C:\ProgramData\TA Instruments\TRIOS\Data\Reverse Heat Capacity Calibration(6).tri
GUID	ba867d72-cfbb-486e-971e-e86aa544cc02
Temperature	-89.99799 °C
Cp	1.070076
Temperature	-89.03691 °C
Cp	1.072008
Temperature	-88.07584 °C
Cp	1.073556
Temperature	-87.11475 °C
Cp	1.074743
Temperature	-86.15367 °C
Cp	1.075597
Temperature	-85.1926 °C
Cp	1.076163
Temperature	-84.23151 °C
Cp	1.076477
Temperature	-83.27043 °C
Cp	1.076579
Temperature	-82.30936 °C
Cp	1.076527
Temperature	-81.34827 °C
Cp	1.076322
Temperature	-80.38719 °C
Cp	1.076039
Temperature	-79.42612 °C
Cp	1.07571
Temperature	-78.46503 °C
Cp	1.075361
Temperature	-77.50395 °C
Cp	1.075011
Temperature	-76.54288 °C
Cp	1.074656
Temperature	-75.58179 °C
Cp	1.074359
Temperature	-74.62071 °C
Cp	1.074086
Temperature	-73.65964 °C
Cp	1.073842
Temperature	-72.69855 °C
Cp	1.073627
Temperature	-71.73747 °C
Cp	1.073442
Temperature	-70.7764 °C
Cp	1.07329
Temperature	-69.81532 °C
Cp	1.073148
Temperature	-68.85423 °C
Cp	1.073021
Temperature	-67.89315 °C
Cp	1.072902
Temperature	-66.93208 °C
Cp	1.072782
Temperature	-65.97099 °C
Cp	1.072656
Temperature	-65.00991 °C
Cp	1.072518
Temperature	-64.04884 °C
Cp	1.072374
Temperature	-63.08775 °C
Cp	1.072201
Temperature	-62.12667 °C
Cp	1.072019
Temperature	-61.1656 °C
Cp	1.071827
Temperature	-60.20451 °C
Cp	1.071624
Temperature	-59.24343 °C
Cp	1.071411
Temperature	-58.28236 °C
Cp	1.071167
Temperature	-57.32127 °C
Cp	1.070956
Temperature	-56.3602 °C
Cp	1.070724
Temperature	-55.39911 °C
Cp	1.070483
Temperature	-54.43803 °C
Cp	1.070242
Temperature	-53.47696 °C
Cp	1.070009
Temperature	-52.51587 °C
Cp	1.069825
Temperature	-51.55479 °C
Cp	1.069601
Temperature	-50.59372 °C
Cp	1.069418
Temperature	-49.63263 °C
Cp	1.069267
Temperature	-48.67155 °C
Cp	1.069138
Temperature	-47.71048 °C
Cp	1.069021
Temperature	-46.74939 °C
Cp	1.068875
Temperature	-45.78831 °C
Cp	1.068771
Temperature	-44.82724 °C
Cp	1.068634
Temperature	-43.86615 °C
Cp	1.068462
Temperature	-42.90508 °C
Cp	1.068255
Temperature	-41.944 °C
Cp	1.068012
Temperature	-40.98291 °C
Cp	1.067742
Temperature	-40.02184 °C
Cp	1.067427
Temperature	-39.06076 °C
Cp	1.067088
Temperature	-38.09967 °C
Cp	1.066727
Temperature	-37.1386 °C
Cp	1.066349
Temperature	-36.17752 °C
Cp	1.065958
Temperature	-35.21643 °C
Cp	1.065559
Temperature	-34.25536 °C
Cp	1.065162
Temperature	-33.29427 °C
Cp	1.06476
Temperature	-32.33319 °C
Cp	1.064368
Temperature	-31.37212 °C
Cp	1.06399
Temperature	-30.41104 °C
Cp	1.063628
Temperature	-29.44995 °C
Cp	1.063283
Temperature	-28.48887 °C
Cp	1.06295
Temperature	-27.5278 °C
Cp	1.062645
Temperature	-26.56672 °C
Cp	1.062355
Temperature	-25.60563 °C
Cp	1.06208
Temperature	-24.64456 °C
Cp	1.061819
Temperature	-23.68348 °C
Cp	1.061573
Temperature	-22.72239 °C
Cp	1.061345
Temperature	-21.76132 °C
Cp	1.061123
Temperature	-20.80024 °C
Cp	1.060915
Temperature	-19.83916 °C
Cp	1.060719
Temperature	-18.87807 °C
Cp	1.060531
Temperature	-17.917 °C
Cp	1.06035
Temperature	-16.95592 °C
Cp	1.060161
Temperature	-15.99484 °C
Cp	1.059992
Temperature	-15.03376 °C
Cp	1.059817
Temperature	-14.07268 °C
Cp	1.059634
Temperature	-13.1116 °C
Cp	1.059445
Temperature	-12.15052 °C
Cp	1.059248
Temperature	-11.18944 °C
Cp	1.059043
Temperature	-10.22836 °C
Cp	1.058842
Temperature	-9.267276 °C
Cp	1.058615
Temperature	-8.306196 °C
Cp	1.058388
Temperature	-7.345116 °C
Cp	1.058155
Temperature	-6.384036 °C
Cp	1.057911
Temperature	-5.422956 °C
Cp	1.057652
Temperature	-4.461876 °C
Cp	1.057356
Temperature	-3.500796 °C
Cp	1.057063
Temperature	-2.539716 °C
Cp	1.056732
Temperature	-1.578636 °C
Cp	1.056364
Temperature	-0.6175562 °C
Cp	1.05596
Temperature	0.3435238 °C
Cp	1.055523
Temperature	1.304604 °C
Cp	1.055066
Temperature	2.265684 °C
Cp	1.054561
Temperature	3.226764 °C
Cp	1.054035
Temperature	4.187844 °C
Cp	1.053488
Temperature	5.148924 °C
Cp	1.052922
Temperature	6.110003 °C
Cp	1.052337
Temperature	7.071084 °C
Cp	1.051736
Temperature	8.032164 °C
Cp	1.051118
Temperature	8.993243 °C
Cp	1.050488
Temperature	9.954324 °C
Cp	1.049848
Temperature	10.9154 °C
Cp	1.049202
Temperature	11.87648 °C
Cp	1.048552
Temperature	12.83756 °C
Cp	1.047902
Temperature	13.79864 °C
Cp	1.047255
Temperature	14.75972 °C
Cp	1.046615
Temperature	15.7208 °C
Cp	1.045983
Temperature	16.68188 °C
Cp	1.045362
Temperature	17.64296 °C
Cp	1.044756
Temperature	18.60404 °C
Cp	1.044164
Temperature	19.56512 °C
Cp	1.04358
Temperature	20.5262 °C
Cp	1.043027
Temperature	21.48728 °C
Cp	1.042485
Temperature	22.44836 °C
Cp	1.041958
Temperature	23.40944 °C
Cp	1.041446
Temperature	24.37052 °C
Cp	1.040952
Temperature	25.3316 °C
Cp	1.040493
Temperature	26.29268 °C
Cp	1.040022
Temperature	27.25376 °C
Cp	1.039578
Temperature	28.21484 °C
Cp	1.039158
Temperature	29.17592 °C
Cp	1.038758
Temperature	30.137 °C
Cp	1.038373
Temperature	31.09808 °C
Cp	1.037981
Temperature	32.05916 °C
Cp	1.03763
Temperature	33.02024 °C
Cp	1.037276
Temperature	33.98132 °C
Cp	1.03692
Temperature	34.9424 °C
Cp	1.036565
Temperature	35.90348 °C
Cp	1.036213
Temperature	36.86456 °C
Cp	1.035866
Temperature	37.82564 °C
Cp	1.035529
Temperature	38.78672 °C
Cp	1.035195
Temperature	39.7478 °C
Cp	1.034875
Temperature	40.70888 °C
Cp	1.034568
Temperature	41.66996 °C
Cp	1.034276
Temperature	42.63104 °C
Cp	1.033996
Temperature	43.59212 °C
Cp	1.033726
Temperature	44.5532 °C
Cp	1.033469
Temperature	45.51428 °C
Cp	1.033221
Temperature	46.47536 °C
Cp	1.03298
Temperature	47.43644 °C
Cp	1.032744
Temperature	48.39752 °C
Cp	1.032514
Temperature	49.3586 °C
Cp	1.032289
Temperature	50.31968 °C
Cp	1.032065
Temperature	51.28076 °C
Cp	1.031844
Temperature	52.24184 °C
Cp	1.031627
Temperature	53.20292 °C
Cp	1.031413
Temperature	54.164 °C
Cp	1.031203
Temperature	55.12508 °C
Cp	1.030989
Temperature	56.08616 °C
Cp	1.030791
Temperature	57.04724 °C
Cp	1.030595
Temperature	58.00832 °C
Cp	1.030403
Temperature	58.9694 °C
Cp	1.030217
Temperature	59.93048 °C
Cp	1.03004
Temperature	60.89156 °C
Cp	1.029871
Temperature	61.85264 °C
Cp	1.029718
Temperature	62.81372 °C
Cp	1.029567
Temperature	63.7748 °C
Cp	1.02943
Temperature	64.73589 °C
Cp	1.029304
Temperature	65.69696 °C
Cp	1.029185
Temperature	66.65804 °C
Cp	1.02907
Temperature	67.61913 °C
Cp	1.028946
Temperature	68.5802 °C
Cp	1.028831
Temperature	69.54128 °C
Cp	1.028703
Temperature	70.50237 °C
Cp	1.028561
Temperature	71.46344 °C
Cp	1.028404
Temperature	72.42452 °C
Cp	1.028234
Temperature	73.3856 °C
Cp	1.028063
Temperature	74.34668 °C
Cp	1.027861
Temperature	75.30776 °C
Cp	1.027657
Temperature	76.26884 °C
Cp	1.027451
Temperature	77.22992 °C
Cp	1.027243
Temperature	78.191 °C
Cp	1.027036
Temperature	79.15208 °C
Cp	1.026812
Temperature	80.11316 °C
Cp	1.026623
Temperature	81.07424 °C
Cp	1.026431
Temperature	82.03532 °C
Cp	1.026241
Temperature	82.9964 °C
Cp	1.02606
Temperature	83.95748 °C
Cp	1.025891
Temperature	84.91856 °C
Cp	1.025739
Temperature	85.87964 °C
Cp	1.025614
Temperature	86.84072 °C
Cp	1.025493
Temperature	87.8018 °C
Cp	1.0254
Temperature	88.76288 °C
Cp	1.025329
Temperature	89.72396 °C
Cp	1.025274
Temperature	90.68504 °C
Cp	1.025229
Temperature	91.64612 °C
Cp	1.025174
Temperature	92.6072 °C
Cp	1.025138
Temperature	93.56828 °C
Cp	1.025083
Temperature	94.52936 °C
Cp	1.025008
Temperature	95.49044 °C
Cp	1.024912
Temperature	96.45152 °C
Cp	1.024796
Temperature	97.4126 °C
Cp	1.024671
Temperature	98.37368 °C
Cp	1.024506
Temperature	99.33476 °C
Cp	1.02433
Temperature	100.2958 °C
Cp	1.024144
Temperature	101.2569 °C
Cp	1.023948
Temperature	102.218 °C
Cp	1.023743
Temperature	103.1791 °C
Cp	1.023522
Temperature	104.1402 °C
Cp	1.023309
Temperature	105.1012 °C
Cp	1.023089
Temperature	106.0623 °C
Cp	1.022866
Temperature	107.0234 °C
Cp	1.022644
Temperature	107.9845 °C
Cp	1.022427
Temperature	108.9456 °C
Cp	1.022218
Temperature	109.9066 °C
Cp	1.022022
Temperature	110.8677 °C
Cp	1.021836
Temperature	111.8288 °C
Cp	1.021666
Temperature	112.7899 °C
Cp	1.021512
Temperature	113.751 °C
Cp	1.021374
Temperature	114.712 °C
Cp	1.02125
Temperature	115.6731 °C
Cp	1.021137
Temperature	116.6342 °C
Cp	1.021041
Temperature	117.5953 °C
Cp	1.020953
Temperature	118.5564 °C
Cp	1.020872
Temperature	119.5174 °C
Cp	1.020796
Temperature	120.4785 °C
Cp	1.020725
Temperature	121.4396 °C
Cp	1.020659
Temperature	122.4007 °C
Cp	1.020587
Temperature	123.3618 °C
Cp	1.020515
Temperature	124.3228 °C
Cp	1.02044
Temperature	125.2839 °C
Cp	1.020359
Temperature	126.245 °C
Cp	1.02027
Temperature	127.2061 °C
Cp	1.020167
Temperature	128.1672 °C
Cp	1.020057
Temperature	129.1282 °C
Cp	1.019933
Temperature	130.0893 °C
Cp	1.019793
Temperature	131.0504 °C
Cp	1.019638
Temperature	132.0115 °C
Cp	1.019471
Temperature	132.9726 °C
Cp	1.019292
Temperature	133.9336 °C
Cp	1.019107
Temperature	134.8947 °C
Cp	1.018912
Temperature	135.8558 °C
Cp	1.018717
Temperature	136.8169 °C
Cp	1.018527
Temperature	137.778 °C
Cp	1.018344
Temperature	138.739 °C
Cp	1.018171
Temperature	139.7001 °C
Cp	1.018004
Temperature	140.6612 °C
Cp	1.01787
Temperature	141.6223 °C
Cp	1.01775
Temperature	142.5834 °C
Cp	1.017652
Temperature	143.5444 °C
Cp	1.017578
Temperature	144.5055 °C
Cp	1.017534
Temperature	145.4666 °C
Cp	1.017536
Temperature	146.4277 °C
Cp	1.017545
Temperature	147.3888 °C
Cp	1.017595
Temperature	148.3498 °C
Cp	1.017679
Temperature	149.3109 °C
Cp	1.01779
Temperature	150.272 °C
Cp	1.01792
Temperature	151.2331 °C
Cp	1.018043
Temperature	152.1942 °C
Cp	1.018199
Temperature	153.1552 °C
Cp	1.018339
Temperature	154.1163 °C
Cp	1.018458
Temperature	155.0774 °C
Cp	1.018552
Temperature	156.0385 °C
Cp	1.018618
Temperature	156.9996 °C
Cp	1.018662
Temperature	157.9606 °C
Cp	1.018664
Temperature	158.9217 °C
Cp	1.018632
Temperature	159.8828 °C
Cp	1.018575
Temperature	160.8439 °C
Cp	1.018492
Temperature	161.805 °C
Cp	1.018383
Temperature	162.766 °C
Cp	1.01825
Temperature	163.7271 °C
Cp	1.018087
Temperature	164.6882 °C
Cp	1.017917
Temperature	165.6493 °C
Cp	1.017726
Temperature	166.6104 °C
Cp	1.017522
Temperature	167.5714 °C
Cp	1.01731
Temperature	168.5325 °C
Cp	1.017098
Temperature	169.4936 °C
Cp	1.016902
Temperature	170.4547 °C
Cp	1.016695
Temperature	171.4158 °C
Cp	1.016508
Temperature	172.3768 °C
Cp	1.016342
Temperature	173.3379 °C
Cp	1.016195
Temperature	174.299 °C
Cp	1.016065
Temperature	175.2601 °C
Cp	1.015927
Temperature	176.2212 °C
Cp	1.015838
Temperature	177.1822 °C
Cp	1.015746
Temperature	178.1433 °C
Cp	1.015651
Temperature	179.1044 °C
Cp	1.015555
Temperature	180.0655 °C
Cp	1.015459
Temperature	181.0266 °C
Cp	1.015401
Temperature	181.9876 °C
Cp	1.015288
Temperature	182.9487 °C
Cp	1.015195
Temperature	183.9098 °C
Cp	1.015117
Temperature	184.8709 °C
Cp	1.01505
Temperature	185.832 °C
Cp	1.014988
Temperature	186.793 °C
Cp	1.014927
Temperature	187.7541 °C
Cp	1.014849
Temperature	188.7152 °C
Cp	1.014789
Temperature	189.6763 °C
Cp	1.01471
Temperature	190.6374 °C
Cp	1.014614
Temperature	191.5984 °C
Cp	1.014503
Temperature	192.5595 °C
Cp	1.014381
Temperature	193.5206 °C
Cp	1.014268
Temperature	194.4817 °C
Cp	1.014122
Temperature	195.4428 °C
Cp	1.013984
Temperature	196.4038 °C
Cp	1.013853
Temperature	197.3649 °C
Cp	1.013726
Temperature	198.326 °C
Cp	1.013603
Temperature	199.2871 °C
Cp	1.013467
Temperature	200.2482 °C
Cp	1.013359
Temperature	201.2092 °C
Cp	1.013243
Temperature	202.1703 °C
Cp	1.013123
Temperature	203.1314 °C
Cp	1.013002
Temperature	204.0925 °C
Cp	1.012884
Temperature	205.0536 °C
Cp	1.012788
Temperature	206.0146 °C
Cp	1.012674
Temperature	206.9757 °C
Cp	1.012579
Temperature	207.9368 °C
Cp	1.012501
Temperature	208.8979 °C
Cp	1.012439
Temperature	209.859 °C
Cp	1.012389
Temperature	210.82 °C
Cp	1.012351
Temperature	211.7811 °C
Cp	1.012312
Temperature	212.7422 °C
Cp	1.01229
Temperature	213.7033 °C
Cp	1.012262
Temperature	214.6644 °C
Cp	1.012227
Temperature	215.6254 °C
Cp	1.012183
Temperature	216.5865 °C
Cp	1.012129
Temperature	217.5476 °C
Cp	1.012077
Temperature	218.5087 °C
Cp	1.01199
Temperature	219.4698 °C
Cp	1.011897
Temperature	220.4308 °C
Cp	1.011793
Temperature	221.3919 °C
Cp	1.011674
Temperature	222.353 °C
Cp	1.011537
Temperature	223.3141 °C
Cp	1.011362
Temperature	224.2752 °C
Cp	1.011194
Temperature	225.2362 °C
Cp	1.010993
Temperature	226.1973 °C
Cp	1.010766
Temperature	227.1584 °C
Cp	1.010517
Temperature	228.1195 °C
Cp	1.010251
Temperature	229.0806 °C
Cp	1.009998
Temperature	230.0416 °C
Cp	1.009703
Temperature	231.0027 °C
Cp	1.009422
Temperature	231.9638 °C
Cp	1.009156
Temperature	232.9249 °C
Cp	1.008906
Temperature	233.886 °C
Cp	1.008675
Temperature	234.847 °C
Cp	1.008462
Temperature	235.8081 °C
Cp	1.008258
Temperature	236.7692 °C
Cp	1.00809
Temperature	237.7303 °C
Cp	1.007934
Temperature	238.6914 °C
Cp	1.007793
Temperature	239.6524 °C
Cp	1.007668
Temperature	240.6135 °C
Cp	1.007562
Temperature	241.5746 °C
Cp	1.007487
Temperature	242.5357 °C
Cp	1.00741
Temperature	243.4967 °C
Cp	1.00736
Temperature	244.4578 °C
Cp	1.007332
Temperature	245.4189 °C
Cp	1.007321
Temperature	246.38 °C
Cp	1.007321
Temperature	247.3411 °C
Cp	1.007312
Temperature	248.3022 °C
Cp	1.007331
Temperature	249.2632 °C
Cp	1.007338
Temperature	250.2243 °C
Cp	1.007335
Temperature	251.1854 °C
Cp	1.00732
Temperature	252.1465 °C
Cp	1.007295
Temperature	253.1076 °C
Cp	1.007277
Temperature	254.0686 °C
Cp	1.007227
Temperature	255.0297 °C
Cp	1.007179
Temperature	255.9908 °C
Cp	1.007133
Temperature	256.9519 °C
Cp	1.00709
Temperature	257.913 °C
Cp	1.007049
Temperature	258.874 °C
Cp	1.007012
Temperature	259.8351 °C
Cp	1.006978
Temperature	260.7962 °C
Cp	1.006956
Temperature	261.7573 °C
Cp	1.00694
Temperature	262.7184 °C
Cp	1.006934
Temperature	263.6794 °C
Cp	1.006939
Temperature	264.6405 °C
Cp	1.00696
Temperature	265.6016 °C
Cp	1.006999
Temperature	266.5627 °C
Cp	1.007054
Temperature	267.5237 °C
Cp	1.007131
Temperature	268.4848 °C
Cp	1.00723
Temperature	269.4459 °C
Cp	1.00735
Temperature	270.407 °C
Cp	1.007493
Temperature	271.3681 °C
Cp	1.007656
Temperature	272.3292 °C
Cp	1.007839
Temperature	273.2902 °C
Cp	1.008039
Temperature	274.2513 °C
Cp	1.008257
Temperature	275.2124 °C
Cp	1.008488
Temperature	276.1735 °C
Cp	1.008731
Temperature	277.1346 °C
Cp	1.008977
Temperature	278.0956 °C
Cp	1.009237
Temperature	279.0567 °C
Cp	1.009498
Temperature	280.0178 °C
Cp	1.009757
Temperature	280.9789 °C
Cp	1.010014
Temperature	281.9399 °C
Cp	1.010267
Temperature	282.901 °C
Cp	1.010515
Temperature	283.8621 °C
Cp	1.01076
Temperature	284.8232 °C
Cp	1.010993
Temperature	285.7843 °C
Cp	1.011222
Temperature	286.7454 °C
Cp	1.011447
Temperature	287.7064 °C
Cp	1.011665
Temperature	288.6675 °C
Cp	1.011876
Temperature	289.6286 °C
Cp	1.012079
Temperature	290.5897 °C
Cp	1.01228
Temperature	291.5508 °C
Cp	1.012474
Temperature	292.5118 °C
Cp	1.012662
Temperature	293.4729 °C
Cp	1.012846
Temperature	294.434 °C
Cp	1.013028
Temperature	295.3951 °C
Cp	1.013211
Temperature	296.3561 °C
Cp	1.013391
Temperature	297.3172 °C
Cp	1.013574
Temperature	298.2783 °C
Cp	1.013759
Temperature	299.2394 °C
Cp	1.013947
Temperature	300.2005 °C
Cp	1.014136
Temperature	301.1616 °C
Cp	1.01432
Temperature	302.1226 °C
Cp	1.014511
Temperature	303.0837 °C
Cp	1.014695
Temperature	304.0448 °C
Cp	1.014872
Temperature	305.0059 °C
Cp	1.01504
Temperature	305.9669 °C
Cp	1.015198
Temperature	306.928 °C
Cp	1.015343
Temperature	307.8891 °C
Cp	1.015479
Temperature	308.8502 °C
Cp	1.015595
Temperature	309.8113 °C
Cp	1.015699
Temperature	310.7724 °C
Cp	1.015789
Temperature	311.7334 °C
Cp	1.015865
Temperature	312.6945 °C
Cp	1.015925
Temperature	313.6556 °C
Cp	1.015964
Temperature	314.6167 °C
Cp	1.015999
Temperature	315.5778 °C
Cp	1.016018
Temperature	316.5388 °C
Cp	1.016025
Temperature	317.4999 °C
Cp	1.016024
Temperature	318.461 °C
Cp	1.01602
Temperature	319.4221 °C
Cp	1.016029
Temperature	320.3831 °C
Cp	1.016025
Temperature	321.3442 °C
Cp	1.016037
Temperature	322.3053 °C
Cp	1.016066
Temperature	323.2664 °C
Cp	1.01611
Temperature	324.2275 °C
Cp	1.016169
Temperature	325.1886 °C
Cp	1.016225
Temperature	326.1496 °C
Cp	1.016318
Temperature	327.1107 °C
Cp	1.016411
Temperature	328.0718 °C
Cp	1.016504
Temperature	329.0329 °C
Cp	1.016596
Temperature	329.994 °C
Cp	1.016687
Temperature	330.955 °C
Cp	1.016775
Temperature	331.9161 °C
Cp	1.016864
Temperature	332.8772 °C
Cp	1.016942
Temperature	333.8383 °C
Cp	1.017019
Temperature	334.7993 °C
Cp	1.017093
Temperature	335.7604 °C
Cp	1.017163
Temperature	336.7215 °C
Cp	1.01723
Temperature	337.6826 °C
Cp	1.017295
Temperature	338.6437 °C
Cp	1.017358
Temperature	339.6048 °C
Cp	1.017423
Temperature	340.5658 °C
Cp	1.017491
Temperature	341.5269 °C
[...]
136.4417	64.0498	1.4205
136.4550	63.8806	1.3911
136.4683	63.7102	1.3620
136.4817	63.5425	1.3339
136.4950	63.3737	1.3061
136.5083	63.2051	1.2800
136.5217	63.0390	1.2526
136.5350	62.8707	1.2274
136.5483	62.7060	1.2024
136.5617	62.5408	1.1773
136.5750	62.3750	1.1534
136.5883	62.2132	1.1294
136.6017	62.0491	1.1072
136.6150	61.8870	1.0844
136.6283	61.7255	1.0629
136.6417	61.5649	1.0413
136.6550	61.4039	1.0214
136.6683	61.2436	1.0016
136.6817	61.0842	0.9817
136.6950	60.9254	0.9631
136.7083	60.7672	0.9444
136.7217	60.6103	0.9273
136.7350	60.4536	0.9095
136.7483	60.2984	0.8935
136.7617	60.1422	0.8771
136.7750	59.9878	0.8614
136.7883	59.8354	0.8466
136.8017	59.6809	0.8314
136.8150	59.5279	0.8181
136.8283	59.3753	0.8041
136.8417	59.2247	0.7906
136.8550	59.0729	0.7777
136.8683	58.9233	0.7662
136.8817	58.7729	0.7539
136.8950	58.6242	0.7421
136.9083	58.4743	0.7314
136.9217	58.3259	0.7210
136.9350	58.1780	0.7102
136.9483	58.0317	0.7011
136.9617	57.8840	0.6906
136.9750	57.7384	0.6819
136.9883	57.5932	0.6719
137.0017	57.4465	0.6646
137.0150	57.3019	0.6560
137.0283	57.1566	0.6487
137.0417	57.0123	0.6395
137.0550	56.8686	0.6330
137.0683	56.7254	0.6258
137.0817	56.5827	0.6188
137.0950	56.4395	0.6121
137.1083	56.2970	0.6054
137.1217	56.1562	0.5997
137.1350	56.0130	0.5924
137.1483	55.8728	0.5878
137.1617	55.7315	0.5820
137.1750	55.5905	0.5757
137.1883	55.4493	0.5709
137.2017	55.3101	0.5661
137.2150	55.1688	0.5610
137.2283	55.0281	0.5556
137.2417	54.8889	0.5514
137.2550	54.7500	0.5461
137.2683	54.6110	0.5428
137.2817	54.4726	0.5384
137.2950	54.3324	0.5340
137.3083	54.1939	0.5300
137.3217	54.0546	0.5261
137.3350	53.9175	0.5220
137.3483	53.7798	0.5186
137.3617	53.6419	0.5158
137.3750	53.5029	0.5111
137.3883	53.3661	0.5086
137.4017	53.2283	0.5042
137.4150	53.0909	0.5024
137.4283	52.9538	0.4989
137.4417	52.8159	0.4958
137.4550	52.6789	0.4934
137.4683	52.5421	0.4902
137.4817	52.4062	0.4874
137.4950	52.2690	0.4853
137.5083	52.1329	0.4822
137.5217	51.9960	0.4798
137.5350	51.8594	0.4777
137.5483	51.7237	0.4756
137.5617	51.5877	0.4735
137.5750	51.4504	0.4713
137.5883	51.3150	0.4692
137.6017	51.1799	0.4677
137.6150	51.0438	0.4656
137.6283	50.9090	0.4635
137.6417	50.7732	0.4623
137.6550	50.6372	0.4602
137.6683	50.5025	0.4587
137.6817	50.3688	0.4573
137.6950	50.2325	0.4556
137.7083	50.0961	0.4548
137.7217	49.9609	0.4527
137.7350	49.8261	0.4520
137.7483	49.6921	0.4503
137.7617	49.5572	0.4492
137.7750	49.4218	0.4474
137.7883	49.2882	0.4471
137.8017	49.1532	0.4456
137.8150	49.0192	0.4442
137.8283	48.8852	0.4433
137.8417	48.7500	0.4428
137.8550	48.6150	0.4425
137.8683	48.4804	0.4414
137.8817	48.3469	0.4402
137.8950	48.2135	0.4394
137.9083	48.0779	0.4369
137.9217	47.9441	0.4362
137.9350	47.8098	0.4355
137.9483	47.6750	0.4336
137.9617	47.5407	0.4329
137.9750	47.4061	0.4316
137.9883	47.2728	0.4306
138.0017	47.1388	0.4297
138.0150	47.0043	0.4281
138.0283	46.8692	0.4272
138.0417	46.7354	0.4262
138.0550	46.5999	0.4247
138.0683	46.4666	0.4241
138.0817	46.3319	0.4222
138.0950	46.1969	0.4210
138.1083	46.0624	0.4202
138.1217	45.9289	0.4188
138.1350	45.7939	0.4171
138.1483	45.6599	0.4164
138.1617	45.5257	0.4144
138.1750	45.3911	0.4135
138.1883	45.2558	0.4121
138.2017	45.1226	0.4106
138.2150	44.9870	0.4099
138.2283	44.8533	0.4073
138.2417	44.7181	0.4071
138.2550	44.5836	0.4055
138.2683	44.4499	0.4037
138.2817	44.3152	0.4027
138.2950	44.1808	0.4004
138.3083	44.0466	0.4003
138.3217	43.9114	0.3984
138.3350	43.7779	0.3973
138.3483	43.6426	0.3951
138.3617	43.5075	0.3944
138.3750	43.3736	0.3924
138.3883	43.2393	0.3922
138.4017	43.1050	0.3897
138.4150	42.9696	0.3892
138.4283	42.8344	0.3868
138.4417	42.6994	0.3862
138.4550	42.5658	0.3843
138.4683	42.4304	0.3834
138.4817	42.2952	0.3820
138.4950	42.1610	0.3805
138.5083	42.0263	0.3796
138.5217	41.8918	0.3781
138.5350	41.7577	0.3768
138.5483	41.6227	0.3755
138.5617	41.4881	0.3733
138.5750	41.3543	0.3727
138.5883	41.2202	0.3713
138.6017	41.0857	0.3701
138.6150	40.9511	0.3693
138.6283	40.8157	0.3677
138.6417	40.6813	0.3662
138.6550	40.5470	0.3653
138.6683	40.4120	0.3640
138.6817	40.2789	0.3628
138.6950	40.1435	0.3616
138.7083	40.0087	0.3610
138.7217	39.8748	0.3590
138.7350	39.7412	0.3582
138.7483	39.6049	0.3576
138.7617	39.4712	0.3562
138.7750	39.3371	0.3552
138.7883	39.2025	0.3541
138.8017	39.0689	0.3524
138.8150	38.9343	0.3520
138.8283	38.8004	0.3512
138.8417	38.6654	0.3500
138.8550	38.5301	0.3493
138.8683	38.3977	0.3481
138.8817	38.2632	0.3468
138.8950	38.1294	0.3462
138.9083	37.9941	0.3451
138.9217	37.8606	0.3441
138.9350	37.7280	0.3431
138.9483	37.5923	0.3427
138.9617	37.4587	0.3421
138.9750	37.3241	0.3407
138.9883	37.1901	0.3400
139.0017	37.0563	0.3392
139.0150	36.9217	0.3387
139.0283	36.7878	0.3374
139.0417	36.6540	0.3368
139.0550	36.5197	0.3363
139.0683	36.3858	0.3359
139.0817	36.2514	0.3345
139.0950	36.1163	0.3343
139.1083	35.9844	0.3333
139.1217	35.8509	0.3327
139.1350	35.7153	0.3320
139.1483	35.5825	0.3312
139.1617	35.4487	0.3306
139.1750	35.3154	0.3297
139.1883	35.1817	0.3294
139.2017	35.0462	0.3290
139.2150	34.9132	0.3279
139.2283	34.7794	0.3274
139.2417	34.6450	0.3268
139.2550	34.5117	0.3264
139.2683	34.3779	0.3256
139.2817	34.2455	0.3245
139.2950	34.1109	0.3243
139.3083	33.9764	0.3238
139.3217	33.8431	0.3235
139.3350	33.7091	0.3226
139.3483	33.5754	0.3223
139.3617	33.4419	0.3214
139.3750	33.3075	0.3209
139.3883	33.1742	0.3207
139.4017	33.0404	0.3201
139.4150	32.9067	0.3196
139.4283	32.7731	0.3188
139.4417	32.6398	0.3183
139.4550	32.5060	0.3178
139.4683	32.3723	0.3174
139.4817	32.2381	0.3169
139.4950	32.1055	0.3167
139.5083	31.9718	0.3157
139.5217	31.8376	0.3152
139.5350	31.7045	0.3150
139.5483	31.5703	0.3147
139.5617	31.4375	0.3138
139.5750	31.3038	0.3136
139.5883	31.1700	0.3129
139.6017	31.0369	0.3127
139.6150	30.9024	0.3121
139.6283	30.7698	0.3117
139.6417	30.6361	0.3115
139.6550	30.5028	0.3107
139.6683	30.3688	0.3099
139.6817	30.2344	0.3097
139.6950	30.1024	0.3090
139.7083	29.9681	0.3089
139.7217	29.8350	0.3086
139.7350	29.7006	0.3080
139.7483	29.5674	0.3078
139.7617	29.4332	0.3068
139.7750	29.3002	0.3065
139.7883	29.1676	0.3060
139.8017	29.0331	0.3059
139.8150	28.8998	0.3050
139.8283	28.7662	0.3048
139.8417	28.6315	0.3043
139.8550	28.4983	0.3041
139.8683	28.3651	0.3034
139.8817	28.2320	0.3032
139.8950	28.0984	0.3028
139.9083	27.9651	0.3022
139.9217	27.8313	0.3017
139.9350	27.6964	0.3014
139.9483	27.5638	0.3011
139.9617	27.4293	0.3005
139.9750	27.2971	0.3000
139.9883	27.1628	0.2998
140.0017	27.0304	0.2994
140.0150	26.8966	0.2989
140.0283	26.7635	0.2984
140.0417	26.6305	0.2981
140.0550	26.4956	0.2977
140.0683	26.3620	0.2973
140.0817	26.2285	0.2968
140.0950	26.0950	0.2964
140.1083	25.9617	0.2962
140.1217	25.8291	0.2957
140.1350	25.6946	0.2953
140.1483	25.5611	0.2945
140.1617	25.4288	0.2941
140.1750	25.2937	0.2937
140.1883	25.1607	0.2933
140.2017	25.0277	0.2929
140.2150	24.8944	0.2923
140.2283	24.7599	0.2921
140.2417	24.6267	0.2916
140.2550	24.4936	0.2913
140.2683	24.3599	0.2908
140.2817	24.2263	0.2905
140.2950	24.0929	0.2899
140.3083	23.9589	0.2896
140.3217	23.8256	0.2893
140.3350	23.6925	0.2888
140.3483	23.5584	0.2886
140.3617	23.4246	0.2879
140.3750	23.2920	0.2871
140.3883	23.1580	0.2868
140.4017	23.0252	0.2866
140.4150	22.8914	0.2864
140.4283	22.7579	0.2860
140.4417	22.6247	0.2858
140.4550	22.4922	0.2853
140.4683	22.3572	0.2850
140.4817	22.2239	0.2849
140.4950	22.0893	0.2842
140.5083	21.9572	0.2835
140.5217	21.8229	0.2833
140.5350	21.6903	0.2830
140.5483	21.5564	0.2825
140.5617	21.4233	0.2823
140.5750	21.2887	0.2820
140.5883	21.1565	0.2814
140.6017	21.0227	0.2806
140.6150	20.8891	0.2805
140.6283	20.7547	0.2802
140.6417	20.6222	0.2798
140.6550	20.4882	0.2797
140.6683	20.3542	0.2790
140.6817	20.2214	0.2788
140.6950	20.0868	0.2785
140.7083	19.9541	0.2777
140.7217	19.8196	0.2775
140.7350	19.6874	0.2769
140.7483	19.5537	0.2768
140.7617	19.4214	0.2762
140.7750	19.2869	0.2757
140.7883	19.1535	0.2756
140.8017	19.0198	0.2750
140.8150	18.8867	0.2750
140.8283	18.7531	0.2745
140.8417	18.6201	0.2739
140.8550	18.4856	0.2737
140.8683	18.3538	0.2733
140.8817	18.2186	0.2728
140.8950	18.0863	0.2727
140.9083	17.9524	0.2726
140.9217	17.8185	0.2723
140.9350	17.6843	0.2718
140.9483	17.5507	0.2712
140.9617	17.4184	0.2711
140.9750	17.2845	0.2708
140.9883	17.1515	0.2704
141.0017	17.0183	0.2702
141.0150	16.8840	0.2698
141.0283	16.7509	0.2696
141.0417	16.6174	0.2689
141.0550	16.4841	0.2688
141.0683	16.3508	0.2682
141.0817	16.2182	0.2680
141.0950	16.0832	0.2675
141.1083	15.9499	0.2671
141.1217	15.8168	0.2670
141.1350	15.6833	0.2663
141.1483	15.5510	0.2661
141.1617	15.4167	0.2657
141.1750	15.2828	0.2656
141.1883	15.1494	0.2653
141.2017	15.0159	0.2651
141.2150	14.8834	0.2647
141.2283	14.7493	0.2641
141.2417	14.6165	0.2638
141.2550	14.4834	0.2636
141.2683	14.3498	0.2631
141.2817	14.2155	0.2630
141.2950	14.0824	0.2629
141.3083	13.9498	0.2624
141.3217	13.8155	0.2620
141.3350	13.6819	0.2615
141.3483	13.5485	0.2613
141.3617	13.4165	0.2611
141.3750	13.2827	0.2607
141.3883	13.1481	0.2605
141.4017	13.0156	0.2602
141.4150	12.8822	0.2601
141.4283	12.7486	0.2598
141.4417	12.6144	0.2594
141.4550	12.4816	0.2593
141.4683	12.3480	0.2587
141.4817	12.2151	0.2585
141.4950	12.0807	0.2581
141.5083	11.9474	0.2580
141.5217	11.8131	0.2577
141.5350	11.6798	0.2574
141.5483	11.5472	0.2569
141.5617	11.4136	0.2566
141.5750	11.2798	0.2563
141.5883	11.1467	0.2561
141.6017	11.0131	0.2558
141.6150	10.8807	0.2552
141.6283	10.7467	0.2549
141.6417	10.6128	0.2548
141.6550	10.4795	0.2545
141.6683	10.3463	0.2542
141.6817	10.2130	0.2540
141.6950	10.0790	0.2536
141.7083	9.9464	0.2531
141.7217	9.8134	0.2529
141.7350	9.6785	0.2527
141.7483	9.5465	0.2518
141.7617	9.4122	0.2517
141.7750	9.2804	0.2513
141.7883	9.1456	0.2511
141.8017	9.0129	0.2508
141.8150	8.8790	0.2506
141.8283	8.7447	0.2504
141.8417	8.6125	0.2502
141.8550	8.4785	0.2498
141.8683	8.3467	0.2495
141.8817	8.2129	0.2493
141.8950	8.0787	0.2490
141.9083	7.9452	0.2487
141.9217	7.8133	0.2479
141.9350	7.6799	0.2478
141.9483	7.5459	0.2477
141.9617	7.4131	0.2471
141.9750	7.2796	0.2470
141.9883	7.1459	0.2468
142.0017	7.0126	0.2467
142.0150	6.8793	0.2464
142.0283	6.7460	0.2456
142.0417	6.6124	0.2454
142.0550	6.4779	0.2453
142.0683	6.3456	0.2452
142.0817	6.2113	0.2450
142.0950	6.0785	0.2444
142.1083	5.9455	0.2443
142.1217	5.8132	0.2441
142.1350	5.6793	0.2439
142.1483	5.5460	0.2438
142.1617	5.4130	0.2435
142.1750	5.2788	0.2433
142.1883	5.1459	0.2422
142.2017	5.0117	0.2421
142.2150	4.8790	0.2414
142.2283	4.7450	0.2414
142.2417	4.6120	0.2407
142.2550	4.4786	0.2405
142.2683	4.3453	0.2404
142.2817	4.2121	0.2400
142.2950	4.0775	0.2400
142.3083	3.9447	0.2395
142.3217	3.8122	0.2393
142.3350	3.6777	0.2392
142.3483	3.5450	0.2390
142.3617	3.4115	0.2389
142.3750	3.2786	0.2385
142.3883	3.1459	0.2379
142.4017	3.0122	0.2378
142.4150	2.8796	0.2375
142.4283	2.7436	0.2373
142.4417	2.6138	0.2368
142.4550	2.4793	0.2366
142.4683	2.3459	0.2365
142.4817	2.2128	0.2364
142.4950	2.0784	0.2360
142.5083	1.9450	0.2359
142.5217	1.8117	0.2357
142.5350	1.6786	0.2353
142.5483	1.5454	0.2347
142.5617	1.4126	0.2344
142.5750	1.2806	0.2341
142.5883	1.1456	0.2341
142.6017	1.0135	0.2334
142.6150	0.8800	0.2332
142.6283	0.7474	0.2331
142.6417	0.6122	0.2328
142.6550	0.4806	0.2323
142.6683	0.3461	0.2322
142.6817	0.2124	0.2319
142.6950	0.0792	0.2317
142.7083	-0.0541	0.2313
142.7217	-0.1883	0.2313
142.7350	-0.3213	0.2306
142.7483	-0.4543	0.2303
142.7617	-0.5882	0.2301
142.7750	-0.7206	0.2300
142.7883	-0.8537	0.2299
142.8017	-0.9867	0.2294
142.8150	-1.1210	0.2292
142.8283	-1.2535	0.2291
142.8417	-1.3870	0.2291
142.8550	-1.5201	0.2285
142.8683	-1.6540	0.2283
142.8817	-1.7857	0.2278
142.8950	-1.9201	0.2277
142.9083	-2.0547	0.2271
142.9217	-2.1861	0.2271
142.9350	-2.3208	0.2267
142.9483	-2.4546	0.2266
142.9617	-2.5873	0.2263
142.9750	-2.7201	0.2262
142.9883	-2.8537	0.2261
143.0017	-2.9863	0.2257
143.0150	-3.1200	0.2255
143.0283	-3.2526	0.2249
143.0417	-3.3858	0.2246
143.0550	-3.5193	0.2245
143.0683	-3.6523	0.2243
143.0817	-3.7869	0.2240
143.0950	-3.9191	0.2237
143.1083	-4.0526	0.2236
143.1217	-4.1868	0.2233
143.1350	-4.3189	0.2232
143.1483	-4.4524	0.2231
143.1617	-4.5849	0.2229
143.1750	-4.7188	0.2223
143.1883	-4.8513	0.2221
143.2017	-4.9853	0.2220
143.2150	-5.1179	0.2217
143.2283	-5.2522	0.2216
143.2417	-5.3844	0.2214
143.2550	-5.5197	0.2209
143.2683	-5.6505	0.2203
143.2817	-5.7852	0.2201
143.2950	-5.9191	0.2199
143.3083	-6.0514	0.2198
143.3217	-6.1855	0.2193
143.3350	-6.3172	0.2190
143.3483	-6.4516	0.2187
143.3617	-6.5842	0.2185
143.3750	-6.7182	0.2182
143.3883	-6.8508	0.2178
143.4017	-6.9838	0.2175
143.4150	-7.1187	0.2173
143.4283	-7.2508	0.2171
143.4417	-7.3830	0.2170
143.4550	-7.5163	0.2167
143.4683	-7.6504	0.2167
143.4817	-7.7850	0.2166
143.4950	-7.9161	0.2157
143.5083	-8.0499	0.2155
143.5217	-8.1837	0.2154
143.5350	-8.3171	0.2147
143.5483	-8.4500	0.2145
143.5617	-8.5839	0.2144
143.5750	-8.7174	0.2143
143.5883	-8.8495	0.2139
143.6017	-8.9830	0.2138
143.6150	-9.1161	0.2132
143.6283	-9.2496	0.2131
143.6417	-9.3833	0.2127
143.6550	-9.5180	0.2126
143.6683	-9.6512	0.2122
143.6817	-9.7839	0.2120
143.6950	-9.9175	0.2118
143.7083	-10.0492	0.2116
143.7217	-10.1840	0.2111
143.7350	-10.3177	0.2110
143.7483	-10.4494	0.2109
143.7617	-10.5825	0.2102
143.7750	-10.7162	0.2102
143.7883	-10.8507	0.2100
143.8017	-10.9844	0.2100
143.8150	-11.1161	0.2096
143.8283	-11.2498	0.2090
143.8417	-11.3834	0.2086
143.8550	-11.5156	0.2081
143.8683	-11.6500	0.2079
143.8817	-11.7819	0.2079
143.8950	-11.9153	0.2078
143.9083	-12.0497	0.2075
143.9217	-12.1825	0.2074
143.9350	-12.3160	0.2069
143.9483	-12.4492	0.2068
143.9617	-12.5825	0.2067
143.9750	-12.7151	0.2065
143.9883	-12.8485	0.2064
144.0017	-12.9818	0.2062
144.0150	-13.1157	0.2060
144.0283	-13.2492	0.2058
144.0417	-13.3822	0.2056
144.0550	-13.5155	0.2055
144.0683	-13.6485	0.2054
144.0817	-13.7830	0.2053
144.0950	-13.9147	0.2046
144.1083	-14.0480	0.2044
144.1217	-14.1813	0.2040
144.1350	-14.3144	0.2039
144.1483	-14.4487	0.2037
144.1617	-14.5811	0.2035
144.1750	-14.7158	0.2034
144.1883	-14.8490	0.2029
144.2017	-14.9814	0.2027
144.2150	-15.1159	0.2026
144.2283	-15.2478	0.2019
144.2417	-15.3816	0.2016
144.2550	-15.5151	0.2015
144.2683	-15.6484	0.2013
144.2817	-15.7817	0.2010
144.2950	-15.9156	0.2007
144.3083	-16.0475	0.2005
144.3217	-16.1821	0.2004
144.3350	-16.3128	0.2002
144.3483	-16.4484	0.2000
144.3617	-16.5805	0.1997
144.3750	-16.7150	0.1990
144.3883	-16.8477	0.1989
144.4017	-16.9810	0.1982
144.4150	-17.1149	0.1981
144.4283	-17.2476	0.1980
144.4417	-17.3807	0.1979
144.4550	-17.5145	0.1973
144.4683	-17.6473	0.1972
144.4817	-17.7802	0.1971
144.4950	-17.9123	0.1969
144.5083	-18.0491	0.1968
144.5217	-18.1810	0.1967
144.5350	-18.3142	0.1965
144.5483	-18.4476	0.1964
144.5617	-18.5805	0.1960
144.5750	-18.7137	0.1958
144.5883	-18.8484	0.1956
144.6017	-18.9807	0.1955
144.6150	-19.1131	0.1954
144.6283	-19.2467	0.1947
144.6417	-19.3795	0.1946
144.6550	-19.5131	0.1945
144.6683	-19.6464	0.1944
144.6817	-19.7807	0.1938
144.6950	-19.9141	0.1937
144.7083	-20.0457	0.1934
144.7217	-20.1801	0.1932
144.7350	-20.3132	0.1930
144.7483	-20.4466	0.1929
144.7617	-20.5801	0.1928
144.7750	-20.7136	0.1920
144.7883	-20.8455	0.1918
144.8017	-20.9790	0.1917
144.8150	-21.1126	0.1915
144.8283	-21.2459	0.1914
144.8417	-21.3796	0.1904
144.8550	-21.5123	0.1902
144.8683	-21.6455	0.1900
144.8817	-21.7791	0.1899
144.8950	-21.9128	0.1898
144.9083	-22.0459	0.1898
144.9217	-22.1789	0.1897
144.9350	-22.3122	0.1894
144.9483	-22.4461	0.1893
144.9617	-22.5798	0.1893
144.9750	-22.7124	0.1890
144.9883	-22.8459	0.1887
145.0017	-22.9806	0.1887
145.0150	-23.1110	0.1885
145.0283	-23.2461	0.1884
145.0417	-23.3791	0.1877
145.0550	-23.5117	0.1876
145.0683	-23.6451	0.1873
145.0817	-23.7778	0.1872
145.0950	-23.9109	0.1871
145.1083	-24.0447	0.1868
145.1217	-24.1775	0.1867
145.1350	-24.3125	0.1863
145.1483	-24.4429	0.1860
145.1617	-24.5778	0.1859
145.1750	-24.7111	0.1858
145.1883	-24.8441	0.1853
145.2017	-24.9765	0.1852
145.2150	-25.1104	0.1847
145.2283	-25.2442	0.1846
145.2417	-25.3777	0.1844
145.2550	-25.5109	0.1841
145.2683	-25.6442	0.1841
145.2817	-25.7776	0.1839
145.2950	-25.9108	0.1835
145.3083	-26.0424	0.1834
145.3217	-26.1772	0.1832
145.3350	-26.3115	0.1830
145.3483	-26.4431	0.1828
145.3617	-26.5758	0.1827
145.3750	-26.7101	0.1826
145.3883	-26.8424	0.1824
145.4017	-26.9766	0.1821
145.4150	-27.1084	0.1818
145.4283	-27.2431	0.1817
145.4417	-27.3762	0.1815
145.4550	-27.5094	0.1811
145.4683	-27.6424	0.1811
145.4817	-27.7764	0.1809
145.4950	-27.9091	0.1806
145.5083	-28.0424	0.1801
145.5217	-28.1747	0.1800
145.5350	-28.3085	0.1799
145.5483	-28.4420	0.1794
145.5617	-28.5758	0.1790
145.5750	-28.7098	0.1790
145.5883	-28.8418	0.1788
145.6017	-28.9760	0.1787
145.6150	-29.1080	0.1782
145.6283	-29.2413	0.1778
145.6417	-29.3750	0.1775
145.6550	-29.5072	0.1774
145.6683	-29.6413	0.1773
145.6817	-29.7748	0.1771
145.6950	-29.9072	0.1769
145.7083	-30.0413	0.1767
145.7217	-30.1743	0.1766
145.7350	-30.3080	0.1766
145.7483	-30.4411	0.1765
145.7617	-30.5741	0.1759
145.7750	-30.7074	0.1758
145.7883	-30.8407	0.1757
145.8017	-30.9742	0.1756
145.8150	-31.1093	0.1756
145.8283	-31.2415	0.1752
145.8417	-31.3738	0.1749
145.8550	-31.5085	0.1746
145.8683	-31.6412	0.1745
145.8817	-31.7750	0.1744
145.8950	-31.9072	0.1742
145.9083	-32.0427	0.1741
145.9217	-32.1728	0.1737
145.9350	-32.3086	0.1736
145.9483	-32.4403	0.1733
145.9617	-32.5742	0.1732
145.9750	-32.7067	0.1729
145.9883	-32.8401	0.1728
146.0017	-32.9740	0.1727
146.0150	-33.1074	0.1723
146.0283	-33.2411	0.1720
146.0417	-33.3729	0.1719
146.0550	-33.5073	0.1718
146.0683	-33.6394	0.1712
146.0817	-33.7732	0.1711
146.0950	-33.9072	0.1710
146.1083	-34.0401	0.1709
146.1217	-34.1743	0.1708
146.1350	-34.3067	0.1707
146.1483	-34.4400	0.1705
146.1617	-34.5738	0.1704
146.1750	-34.7072	0.1703
146.1883	-34.8392	0.1699
146.2017	-34.9713	0.1697
146.2150	-35.1057	0.1696
146.2283	-35.2399	0.1696
146.2417	-35.3717	0.1695
146.2550	-35.5057	0.1694
146.2683	-35.6385	0.1691
146.2817	-35.7721	0.1691
146.2950	-35.9042	0.1685
146.3083	-36.0379	0.1684
146.3217	-36.1715	0.1682
146.3350	-36.3042	0.1681
146.3483	-36.4381	0.1681
146.3617	-36.5716	0.1676
146.3750	-36.7037	0.1672
146.3883	-36.8377	0.1671
146.4017	-36.9716	0.1669
146.4150	-37.1040	0.1667
146.4283	-37.2374	0.1664
146.4417	-37.3707	0.1664
146.4550	-37.5023	0.1658
146.4683	-37.6371	0.1656
146.4817	-37.7699	0.1655
146.4950	-37.9041	0.1652
146.5083	-38.0362	0.1650
146.5217	-38.1712	0.1650
146.5350	-38.3014	0.1646
146.5483	-38.4358	0.1646
146.5617	-38.5685	0.1645
146.5750	-38.7028	0.1645
146.5883	-38.8353	0.1643
146.6017	-38.9699	0.1642
146.6150	-39.1029	0.1640
146.6283	-39.2356	0.1639
146.6417	-39.3690	0.1638
146.6550	-39.5025	0.1633
146.6683	-39.6352	0.1632
146.6817	-39.7689	0.1627
146.6950	-39.9028	0.1626
146.7083	-40.0339	0.1626
146.7217	-40.1684	0.1624
146.7350	-40.3013	0.1622
146.7483	-40.4341	0.1621
146.7617	-40.5687	0.1619
146.7750	-40.7012	0.1618
146.7883	-40.8356	0.1616
146.8017	-40.9671	0.1614
146.8150	-41.1013	0.1612
146.8283	-41.2335	0.1610
146.8417	-41.3680	0.1609
146.8550	-41.5006	0.1609
146.8683	-41.6356	0.1608
146.8817	-41.7668	0.1606
146.8950	-41.9003	0.1604
146.9083	-42.0322	0.1599
146.9217	-42.1676	0.1598
146.9350	-42.3011	0.1595
146.9483	-42.4349	0.1594
146.9617	-42.5677	0.1593
146.9750	-42.6996	0.1590
146.9883	-42.8332	0.1587
147.0017	-42.9660	0.1586
147.0150	-43.0988	0.1586
147.0283	-43.2333	0.1582
147.0417	-43.3654	0.1580
147.0550	-43.5003	0.1578
147.0683	-43.6318	0.1576
147.0817	-43.7649	0.1575
147.0950	-43.8986	0.1574
147.1083	-44.0319	0.1572
147.1217	-44.1654	0.1571
147.1350	-44.2986	0.1567
147.1483	-44.4326	0.1566
147.1617	-44.5653	0.1564
147.1750	-44.6971	0.1560
147.1883	-44.8309	0.1558
147.2017	-44.9650	0.1557
147.2150	-45.0995	0.1556
147.2283	-45.2319	0.1553
147.2417	-45.3652	0.1552
147.2550	-45.4979	0.1550
147.2683	-45.6324	0.1549
147.2817	-45.7646	0.1548
147.2950	-45.8978	0.1546
147.3083	-46.0301	0.1544
147.3217	-46.1629	0.1540
147.3350	-46.2981	0.1539
147.3483	-46.4302	0.1537
147.3617	-46.5635	0.1536
147.3750	-46.6958	0.1535
147.3883	-46.8317	0.1532
147.4017	-46.9632	0.1531
147.4133	-47.0798	0.1530