File: Example Date/DSC TA/YN041 -150-150.txt
Filename	YN041 -150-150
Instrument name	DSC2A-01799 (192.168.1.250)
Operator
rundate	09/12/2024
Sample name	YN041 -150-150
proceduresegments	Ramp 10.00 °C/min to 150.0000 °C; Isothermal 3.0 min; Ramp 10.00 °C/min to -150.0000 °C; Isothermal 3.0 min; Ramp 10.00 °C/min to 150.0000 °C; Isothermal 3.0 min; Ramp 10.00 °C/min to -150.0000 °C; Isothermal 3.0 min; Ramp 10.00 °C/min to 150.0000 °C; Isothermal 3.0 min; Ramp 10.00 °C/min to 40.0000 °C
[File Parameters]
Run Date	09/12/2024 19:46:31
Trios version	5.7.0.56
Original File Name	C:\Users\TA Instruments DSC\Desktop\Data\Yutong Niu\YN041 -150-150.tri
Current File Name	C:\Users\TA Instruments DSC\Desktop\Data\Yutong Niu\YN041 -150-150.tri
User at run start	DESKTOP-CFGN8IT\TA Instruments DSC
[Procedure]
Procedure Name	polyether
Sample Name	YN041 -150-150
Sample Mass	11.73 mg
Reference Sample Mass	0 mg
Pan Mass	60.77 mg
Pan Number	35
Reference Pan Mass	60.81 mg
Reference Pan Number	45
Pan Type	Tzero Aluminum Pin Hole Hermetic
Comments
Project Name
Operator
Test	Custom
Unload Max Temperature	25
Unload Min Temperature	25
FillCooler	Do not fill
Load Max Temperature	25
Load Min Temperature	25
Discard pan in waste bin at end of test	Yes
Stop on Gas Flow Error	No
[Signal List]
Signal #1	Time (min)
Signal #2	Temperature (°C)
Signal #3	Heat Flow (mW)
Signal #4	Delta T (µV)
Signal #5	Delta Tzero (µV)
Signal #6	Tzero Temperature (°C)
Signal #7	Cell Purge (mL/min)
Signal #8	Heater Temp (°C)
Signal #9	Power Delivered (W)
Signal #10	Reference Junction Temperature (°C)
Signal #11	Flange Temperature (°C)
Signal #12	Heat Flow Phase (rad)
Signal #13	Total Heat Capacity (J/°C)
Signal #14	Heat Capacity (J/°C)
Signal #15	LN Pump Tank level (%)
[Configuration]
Company Name	Warwick University
Instrument Name	DSC2A-01799
Instrument Type	DSC2500
Serial Number	DSC2A-01799
IP	192.168.1.250
Location of Instrument	Polymer RTP
DisplayType	TianmaV2andV3
Sample Interval 	0.1 s/pt
Selected Heat Flow	T4P
Exotherm Direction	Up
Cell Serial	DRC2-03788
Lid Type	High Temperature
Cooler	LN Pump
Leave Cooler on at End of Sequence	Off
Gas 2	Air
Gas Selected	Channel 1: Nitrogen
Flow Rate	50 mL/min
Secondary Purge	On
Licensed Heat Flow	Heat Flow T4P
Modulation Licensed	Yes
[Versions]
Common IDD Version	1
Cortex Version	VER 2.11.0.729
Driver	5.0.0.6
GDM Version	1.0.3.3
TouchscreenVersion	1.0.3.1841
FEP Version	1.2.1.21
FEP Bootloader	2.0.0.5
AutoSampler Version	2.1.2.1
Auto Sampler Bootloader	2.0.0.5
FCM Version	1.1.0.3
FCM Bootloader	2.0.0.5
LN Pump Version	10.17.0.0
LN Pump Bootloader	2.0.0.5
[Experiment Logs]
Experiment Log Entry # 1	Air Cool is off.
Experiment Log Entry # 3	Ramp Segment 10 C/min to 150 Started
Experiment Log Entry # 5	Isothermal Segment 3 min started
Experiment Log Entry # 7	Ramp Segment 10 C/min to -150 Started
Experiment Log Entry # 9	Isothermal Segment 3 min started
Experiment Log Entry # 11	Ramp Segment 10 C/min to 150 Started
Experiment Log Entry # 13	Isothermal Segment 3 min started
Experiment Log Entry # 15	Ramp Segment 10 C/min to -150 Started
Experiment Log Entry # 18	LN2P is filling
Experiment Log Entry # 19	Isothermal Segment 3 min started
Experiment Log Entry # 21	Current LN2P tank level (70.57%) not increasing during fill. Bulk tank may be empty.
Experiment Log Entry # 23	LN2P stopped filling
Experiment Log Entry # 24	Ramp Segment 10 C/min to 150 Started
Experiment Log Entry # 26	Isothermal Segment 3 min started
Experiment Log Entry # 28	Ramp Segment 10 C/min to 40 Started
[Method Log]
Method Log Entry # 1	(Ramp 569186) Ramp 10 °C/minute to 150 °C
Method Log Entry # 2	Isothermal 3 minutes
Method Log Entry # 3	(Ramp 569188) Ramp 10 °C/minute to -150 °C
Method Log Entry # 4	Isothermal 3 minutes
Method Log Entry # 5	(Ramp 569190) Ramp 10 °C/minute to 150 °C
Method Log Entry # 6	Isothermal 3 minutes
Method Log Entry # 7	(Ramp 569192) Ramp 10 °C/minute to -150 °C
Method Log Entry # 8	Isothermal 3 minutes
Method Log Entry # 9	(Ramp 569194) Ramp 10 °C/minute to 150 °C
Method Log Entry # 10	Isothermal 3 minutes
Method Log Entry # 11	(Ramp 569196) Ramp 10 °C/minute to 40 °C
Cell Serial	DRC2-03788
[T1 Calibration]
Date Applied	04/03/2021 14:58:04
Description
Gas Type	Nitrogen
Pan Type	None
Slope	-0.001800291
Offset	-0.1301359
Initial Temperature	-100.6228
GUID	a1d5a6be-decd-4ae4-b22f-d560f3a78a92
[TZero Calibration]
Date Applied	21/08/2024 09:53:38
Description	From -180.022 °C to 395.167 °C at 20.000°C/min
Gas Type	Nitrogen
Pan Type	None
Source Files 1	C:\ProgramData\TA Instruments\TRIOS\Data\TAService\PMV 20Aug2024\Tzero Cal.tri
Source Files 2	C:\ProgramData\TA Instruments\TRIOS\Data\TAService\PMV 20Aug2024\Tzero Cal sapphire.tri
Delta T Offset	1.787969
Delta T Slope	-0.003527276
Delta T0 Offset	0.06831977
Delta T0 Slope	0.02007191
[Temperature Calibration]
Date Applied	21/08/2024 11:06:35
Description	From 106.660 °C to 186.660 °C at 10.000°C/min
Gas Type	Nitrogen
Pan Type	Tzero Aluminum
Source Files 1	C:\ProgramData\TA Instruments\TRIOS\Data\TAService\PMV 20Aug2024\TA Indium cal.tri
Measured 1	157.9141
Known 1	156.66
[Cell Constant Calibration]
Date Applied	21/08/2024 11:06:35
Description	From 106.660 °C to 186.660 °C at 10.000°C/min
Gas Type	Nitrogen
Pan Type	Tzero Aluminum
Source Files 1	C:\ProgramData\TA Instruments\TRIOS\Data\TAService\PMV 20Aug2024\TA Indium cal.tri
T4P KCell	1.038055
Onset Slope	-66.72884 mW/°C
[Direct Cp Calibration]
Date Applied	19/11/2024 16:37:27
Description	From -89.996 °C to 396.697 °C at 20.000°C/min
Gas Type	Nitrogen
Pan Type	Tzero Aluminum
Source Files 1	C:\ProgramData\TA Instruments\TRIOS\Data\Sapphire Direct Heat Capacity(8).tri
GUID	544f8371-fe9b-4f4f-81ca-7980c172113e
Temperature	-89.99625 °C
Cp	1.464367
Temperature	-89.02287 °C
Cp	1.460558
Temperature	-88.04948 °C
Cp	1.456263
Temperature	-87.0761 °C
Cp	1.451626
Temperature	-86.10271 °C
Cp	1.446737
Temperature	-85.12933 °C
Cp	1.441723
Temperature	-84.15594 °C
Cp	1.436654
Temperature	-83.18256 °C
Cp	1.431684
Temperature	-82.20917 °C
Cp	1.426935
Temperature	-81.23578 °C
Cp	1.422396
Temperature	-80.2624 °C
Cp	1.418192
Temperature	-79.28901 °C
Cp	1.414363
Temperature	-78.31562 °C
Cp	1.410925
Temperature	-77.34224 °C
Cp	1.407865
Temperature	-76.36885 °C
Cp	1.405143
Temperature	-75.39546 °C
Cp	1.402789
Temperature	-74.42208 °C
Cp	1.400703
Temperature	-73.44869 °C
Cp	1.398837
Temperature	-72.4753 °C
Cp	1.397142
Temperature	-71.50192 °C
Cp	1.395565
Temperature	-70.52853 °C
Cp	1.394053
Temperature	-69.55515 °C
Cp	1.392558
Temperature	-68.58176 °C
Cp	1.391036
Temperature	-67.60838 °C
Cp	1.389483
Temperature	-66.63499 °C
Cp	1.387847
Temperature	-65.66161 °C
Cp	1.38616
Temperature	-64.68822 °C
Cp	1.384397
Temperature	-63.71483 °C
Cp	1.382535
Temperature	-62.74145 °C
Cp	1.380598
Temperature	-61.76806 °C
Cp	1.37865
Temperature	-60.79467 °C
Cp	1.376673
Temperature	-59.82129 °C
Cp	1.374677
Temperature	-58.8479 °C
Cp	1.372642
Temperature	-57.87452 °C
Cp	1.370686
Temperature	-56.90113 °C
Cp	1.368741
Temperature	-55.92775 °C
Cp	1.366786
Temperature	-54.95436 °C
Cp	1.364863
Temperature	-53.98097 °C
Cp	1.362959
Temperature	-53.00759 °C
Cp	1.361116
Temperature	-52.0342 °C
Cp	1.359247
Temperature	-51.06082 °C
Cp	1.357393
Temperature	-50.08743 °C
Cp	1.355593
Temperature	-49.11404 °C
Cp	1.353796
Temperature	-48.14066 °C
Cp	1.352008
Temperature	-47.16727 °C
Cp	1.350215
Temperature	-46.19389 °C
Cp	1.348396
Temperature	-45.2205 °C
Cp	1.346593
Temperature	-44.24712 °C
Cp	1.344755
Temperature	-43.27373 °C
Cp	1.342891
Temperature	-42.30034 °C
Cp	1.341008
Temperature	-41.32696 °C
Cp	1.339126
Temperature	-40.35357 °C
Cp	1.337236
Temperature	-39.38018 °C
Cp	1.335367
Temperature	-38.4068 °C
Cp	1.333522
Temperature	-37.43341 °C
Cp	1.331708
Temperature	-36.46003 °C
Cp	1.32991
Temperature	-35.48664 °C
Cp	1.328145
Temperature	-34.51326 °C
Cp	1.326414
Temperature	-33.53987 °C
Cp	1.32471
Temperature	-32.56648 °C
Cp	1.323012
Temperature	-31.5931 °C
Cp	1.321323
Temperature	-30.61971 °C
Cp	1.319657
Temperature	-29.64633 °C
Cp	1.317968
Temperature	-28.67294 °C
Cp	1.316286
Temperature	-27.69955 °C
Cp	1.314585
Temperature	-26.72617 °C
Cp	1.312857
Temperature	-25.75278 °C
Cp	1.31111
Temperature	-24.7794 °C
Cp	1.309333
Temperature	-23.80601 °C
Cp	1.307544
Temperature	-22.83262 °C
Cp	1.30575
Temperature	-21.85924 °C
Cp	1.303941
Temperature	-20.88585 °C
Cp	1.302132
Temperature	-19.91247 °C
Cp	1.300313
Temperature	-18.93908 °C
Cp	1.298512
Temperature	-17.96569 °C
Cp	1.296728
Temperature	-16.99231 °C
Cp	1.294939
Temperature	-16.01892 °C
Cp	1.293198
Temperature	-15.04554 °C
Cp	1.291453
Temperature	-14.07215 °C
Cp	1.289723
Temperature	-13.09876 °C
Cp	1.288007
Temperature	-12.12538 °C
Cp	1.286283
Temperature	-11.15199 °C
Cp	1.284578
Temperature	-10.17861 °C
Cp	1.282885
Temperature	-9.205221 °C
Cp	1.281173
Temperature	-8.231835 °C
Cp	1.279472
Temperature	-7.258449 °C
Cp	1.277766
Temperature	-6.285063 °C
Cp	1.276053
Temperature	-5.311677 °C
Cp	1.274341
Temperature	-4.338291 °C
Cp	1.272592
Temperature	-3.364905 °C
Cp	1.270844
Temperature	-2.391519 °C
Cp	1.269062
Temperature	-1.418133 °C
Cp	1.267264
Temperature	-0.4447474 °C
Cp	1.265435
Temperature	0.5286385 °C
Cp	1.263575
Temperature	1.502024 °C
Cp	1.261727
Temperature	2.47541 °C
Cp	1.259854
Temperature	3.448796 °C
Cp	1.257978
Temperature	4.422182 °C
Cp	1.256109
Temperature	5.395568 °C
Cp	1.254244
Temperature	6.368954 °C
Cp	1.252392
Temperature	7.34234 °C
Cp	1.250552
Temperature	8.315726 °C
Cp	1.248704
Temperature	9.289112 °C
Cp	1.246884
Temperature	10.2625 °C
Cp	1.245078
Temperature	11.23588 °C
Cp	1.243287
Temperature	12.20927 °C
Cp	1.241522
Temperature	13.18266 °C
Cp	1.239778
Temperature	14.15604 °C
Cp	1.238068
Temperature	15.12943 °C
Cp	1.236393
Temperature	16.10281 °C
Cp	1.234762
Temperature	17.0762 °C
Cp	1.233176
Temperature	18.04959 °C
Cp	1.231629
Temperature	19.02297 °C
Cp	1.230129
Temperature	19.99636 °C
Cp	1.228694
Temperature	20.96974 °C
Cp	1.22731
Temperature	21.94313 °C
Cp	1.225968
Temperature	22.91652 °C
Cp	1.224676
Temperature	23.8899 °C
Cp	1.223431
Temperature	24.86329 °C
Cp	1.222217
Temperature	25.83667 °C
Cp	1.221065
Temperature	26.81006 °C
Cp	1.219919
Temperature	27.78345 °C
Cp	1.218811
Temperature	28.75683 °C
Cp	1.21773
Temperature	29.73022 °C
Cp	1.216663
Temperature	30.7036 °C
Cp	1.2156
Temperature	31.67699 °C
Cp	1.214515
Temperature	32.65038 °C
Cp	1.213439
Temperature	33.62376 °C
Cp	1.21234
Temperature	34.59715 °C
Cp	1.211209
Temperature	35.57053 °C
Cp	1.210051
Temperature	36.54392 °C
Cp	1.208868
Temperature	37.5173 °C
Cp	1.207666
Temperature	38.49069 °C
Cp	1.206439
Temperature	39.46408 °C
Cp	1.205199
Temperature	40.43746 °C
Cp	1.203959
Temperature	41.41085 °C
Cp	1.202712
Temperature	42.38424 °C
Cp	1.20147
Temperature	43.35762 °C
Cp	1.200231
Temperature	44.33101 °C
Cp	1.199
Temperature	45.30439 °C
Cp	1.197777
Temperature	46.27778 °C
Cp	1.19657
Temperature	47.25116 °C
Cp	1.195367
Temperature	48.22455 °C
Cp	1.194179
Temperature	49.19794 °C
Cp	1.19301
Temperature	50.17132 °C
Cp	1.191849
Temperature	51.14471 °C
Cp	1.190694
Temperature	52.11809 °C
Cp	1.189555
Temperature	53.09148 °C
Cp	1.18843
Temperature	54.06487 °C
Cp	1.187311
Temperature	55.03825 °C
Cp	1.186195
Temperature	56.01164 °C
Cp	1.185095
Temperature	56.98502 °C
Cp	1.183997
Temperature	57.95841 °C
Cp	1.182894
Temperature	58.93179 °C
Cp	1.181793
Temperature	59.90518 °C
Cp	1.180693
Temperature	60.87857 °C
Cp	1.179595
Temperature	61.85195 °C
Cp	1.178501
Temperature	62.82534 °C
Cp	1.177406
Temperature	63.79873 °C
Cp	1.176313
Temperature	64.77211 °C
Cp	1.175239
Temperature	65.7455 °C
Cp	1.17417
Temperature	66.71888 °C
Cp	1.173105
Temperature	67.69227 °C
Cp	1.172037
Temperature	68.66566 °C
Cp	1.170989
Temperature	69.63904 °C
Cp	1.169948
Temperature	70.61243 °C
Cp	1.168905
Temperature	71.58582 °C
Cp	1.167872
Temperature	72.5592 °C
Cp	1.166849
Temperature	73.53259 °C
Cp	1.165851
Temperature	74.50597 °C
Cp	1.164848
Temperature	75.47935 °C
Cp	1.163876
Temperature	76.45274 °C
Cp	1.162926
Temperature	77.42612 °C
Cp	1.162008
Temperature	78.39951 °C
Cp	1.161113
Temperature	79.3729 °C
Cp	1.160219
Temperature	80.34628 °C
Cp	1.159377
Temperature	81.31967 °C
Cp	1.158546
Temperature	82.29306 °C
Cp	1.157726
Temperature	83.26644 °C
Cp	1.15692
Temperature	84.23983 °C
Cp	1.156126
Temperature	85.21322 °C
Cp	1.155375
Temperature	86.1866 °C
Cp	1.154604
Temperature	87.15999 °C
Cp	1.153869
Temperature	88.13337 °C
Cp	1.153158
Temperature	89.10676 °C
Cp	1.152474
Temperature	90.08015 °C
Cp	1.15181
Temperature	91.05353 °C
Cp	1.151134
Temperature	92.02692 °C
Cp	1.150513
Temperature	93.00031 °C
Cp	1.149892
Temperature	93.97369 °C
Cp	1.149266
Temperature	94.94707 °C
Cp	1.148642
Temperature	95.92046 °C
Cp	1.148019
Temperature	96.89384 °C
Cp	1.147402
Temperature	97.86723 °C
Cp	1.146799
Temperature	98.84062 °C
Cp	1.146191
Temperature	99.814 °C
Cp	1.145602
Temperature	100.7874 °C
Cp	1.14503
Temperature	101.7608 °C
Cp	1.144469
Temperature	102.7342 °C
Cp	1.143921
Temperature	103.7076 °C
Cp	1.143383
Temperature	104.6809 °C
Cp	1.142861
Temperature	105.6543 °C
Cp	1.142345
Temperature	106.6277 °C
Cp	1.141835
Temperature	107.6011 °C
Cp	1.141335
Temperature	108.5745 °C
Cp	1.140846
Temperature	109.5479 °C
Cp	1.140365
Temperature	110.5212 °C
Cp	1.139891
Temperature	111.4946 °C
Cp	1.139429
Temperature	112.468 °C
Cp	1.138976
Temperature	113.4414 °C
Cp	1.13853
Temperature	114.4148 °C
Cp	1.138092
Temperature	115.3882 °C
Cp	1.137654
Temperature	116.3616 °C
Cp	1.137223
Temperature	117.335 °C
Cp	1.136785
Temperature	118.3083 °C
Cp	1.136338
Temperature	119.2817 °C
Cp	1.13588
Temperature	120.2551 °C
Cp	1.13541
Temperature	121.2285 °C
Cp	1.134927
Temperature	122.2019 °C
Cp	1.134417
Temperature	123.1753 °C
Cp	1.133892
Temperature	124.1487 °C
Cp	1.133347
Temperature	125.122 °C
Cp	1.132786
Temperature	126.0954 °C
Cp	1.132206
Temperature	127.0688 °C
Cp	1.131606
Temperature	128.0422 °C
Cp	1.130999
Temperature	129.0156 °C
Cp	1.130384
Temperature	129.989 °C
Cp	1.129765
Temperature	130.9624 °C
Cp	1.129147
Temperature	131.9357 °C
Cp	1.12854
Temperature	132.9091 °C
Cp	1.127949
Temperature	133.8825 °C
Cp	1.127383
Temperature	134.8559 °C
Cp	1.126841
Temperature	135.8293 °C
Cp	1.126334
Temperature	136.8027 °C
Cp	1.125871
Temperature	137.7761 °C
Cp	1.125443
Temperature	138.7494 °C
Cp	1.125058
Temperature	139.7228 °C
Cp	1.124701
Temperature	140.6962 °C
Cp	1.124397
Temperature	141.6696 °C
Cp	1.124114
Temperature	142.643 °C
Cp	1.123854
Temperature	143.6164 °C
Cp	1.123612
Temperature	144.5898 °C
Cp	1.123385
Temperature	145.5631 °C
Cp	1.123182
Temperature	146.5365 °C
Cp	1.12296
Temperature	147.5099 °C
Cp	1.12275
Temperature	148.4833 °C
Cp	1.122543
Temperature	149.4567 °C
Cp	1.122327
Temperature	150.4301 °C
Cp	1.122099
Temperature	151.4035 °C
Cp	1.121837
Temperature	152.3768 °C
Cp	1.121582
Temperature	153.3502 °C
Cp	1.121289
Temperature	154.3236 °C
Cp	1.120967
Temperature	155.297 °C
Cp	1.120616
Temperature	156.2704 °C
Cp	1.120238
Temperature	157.2438 °C
Cp	1.119862
Temperature	158.2172 °C
Cp	1.119444
Temperature	159.1906 °C
Cp	1.119028
Temperature	160.1639 °C
Cp	1.118613
Temperature	161.1373 °C
Cp	1.118202
Temperature	162.1107 °C
Cp	1.117795
Temperature	163.0841 °C
Cp	1.117374
Temperature	164.0575 °C
Cp	1.116987
Temperature	165.0309 °C
Cp	1.116595
Temperature	166.0042 °C
Cp	1.116198
Temperature	166.9776 °C
Cp	1.1158
Temperature	167.951 °C
Cp	1.115402
Temperature	168.9244 °C
Cp	1.115006
Temperature	169.8978 °C
Cp	1.11462
Temperature	170.8712 °C
Cp	1.114223
Temperature	171.8446 °C
Cp	1.113836
Temperature	172.8179 °C
Cp	1.113458
Temperature	173.7913 °C
Cp	1.113085
Temperature	174.7647 °C
Cp	1.112712
Temperature	175.7381 °C
Cp	1.112323
Temperature	176.7115 °C
Cp	1.111957
Temperature	177.6849 °C
Cp	1.111578
Temperature	178.6583 °C
Cp	1.111185
Temperature	179.6317 °C
Cp	1.110789
Temperature	180.605 °C
Cp	1.110391
Temperature	181.5784 °C
Cp	1.110016
Temperature	182.5518 °C
Cp	1.109611
Temperature	183.5252 °C
Cp	1.109232
Temperature	184.4986 °C
Cp	1.108873
Temperature	185.472 °C
Cp	1.108531
Temperature	186.4454 °C
Cp	1.108199
Temperature	187.4187 °C
Cp	1.107851
Temperature	188.3921 °C
Cp	1.107551
Temperature	189.3655 °C
Cp	1.107238
Temperature	190.3389 °C
Cp	1.106917
Temperature	191.3123 °C
Cp	1.106589
Temperature	192.2857 °C
Cp	1.106259
Temperature	193.259 °C
Cp	1.105958
Temperature	194.2324 °C
Cp	1.105619
Temperature	195.2058 °C
Cp	1.105301
Temperature	196.1792 °C
Cp	1.105002
Temperature	197.1526 °C
Cp	1.104718
Temperature	198.126 °C
Cp	1.104445
Temperature	199.0994 °C
Cp	1.104161
Temperature	200.0728 °C
Cp	1.103914
Temperature	201.0461 °C
Cp	1.103657
Temperature	202.0195 °C
Cp	1.103395
Temperature	202.9929 °C
Cp	1.103125
Temperature	203.9663 °C
Cp	1.102847
Temperature	204.9397 °C
Cp	1.102563
Temperature	205.9131 °C
Cp	1.102283
Temperature	206.8865 °C
Cp	1.101985
Temperature	207.8598 °C
Cp	1.10169
Temperature	208.8332 °C
Cp	1.101394
Temperature	209.8066 °C
Cp	1.101099
Temperature	210.78 °C
Cp	1.1008
Temperature	211.7534 °C
Cp	1.10049
Temperature	212.7268 °C
Cp	1.100193
Temperature	213.7002 °C
Cp	1.099886
Temperature	214.6735 °C
Cp	1.099577
Temperature	215.6469 °C
Cp	1.099268
Temperature	216.6203 °C
Cp	1.098965
Temperature	217.5937 °C
Cp	1.098685
Temperature	218.5671 °C
Cp	1.098396
Temperature	219.5405 °C
Cp	1.098134
Temperature	220.5139 °C
Cp	1.097895
Temperature	221.4872 °C
Cp	1.09768
Temperature	222.4606 °C
Cp	1.097485
Temperature	223.434 °C
Cp	1.097292
Temperature	224.4074 °C
Cp	1.09714
Temperature	225.3808 °C
Cp	1.096991
Temperature	226.3542 °C
Cp	1.096844
Temperature	227.3276 °C
Cp	1.096699
Temperature	228.3009 °C
Cp	1.096559
Temperature	229.2743 °C
Cp	1.096442
Temperature	230.2477 °C
Cp	1.096296
Temperature	231.2211 °C
Cp	1.096164
Temperature	232.1945 °C
Cp	1.09604
Temperature	233.1679 °C
Cp	1.095924
Temperature	234.1413 °C
Cp	1.095807
Temperature	235.1147 °C
Cp	1.095665
Temperature	236.088 °C
Cp	1.095557
Temperature	237.0614 °C
Cp	1.095433
Temperature	238.0348 °C
Cp	1.095296
Temperature	239.0082 °C
Cp	1.095147
Temperature	239.9816 °C
Cp	1.094995
Temperature	240.955 °C
Cp	1.094843
Temperature	241.9283 °C
Cp	1.094705
Temperature	242.9017 °C
Cp	1.094562
Temperature	243.8751 °C
Cp	1.094442
Temperature	244.8485 °C
Cp	1.094344
Temperature	245.8219 °C
Cp	1.094266
Temperature	246.7953 °C
Cp	1.094209
Temperature	247.7687 °C
Cp	1.094161
Temperature	248.7421 °C
Cp	1.094144
Temperature	249.7154 °C
Cp	1.094133
Temperature	250.6888 °C
Cp	1.094127
Temperature	251.6622 °C
Cp	1.094126
Temperature	252.6356 °C
Cp	1.094127
Temperature	253.609 °C
Cp	1.094138
Temperature	254.5824 °C
Cp	1.09413
Temperature	255.5558 °C
Cp	1.094123
Temperature	256.5291 °C
Cp	1.094111
Temperature	257.5025 °C
Cp	1.094087
Temperature	258.4759 °C
Cp	1.094046
Temperature	259.4493 °C
Cp	1.093978
Temperature	260.4227 °C
Cp	1.093895
Temperature	261.3961 °C
Cp	1.093783
Temperature	262.3694 °C
Cp	1.093645
Temperature	263.3428 °C
Cp	1.093483
Temperature	264.3162 °C
Cp	1.093302
Temperature	265.2896 °C
Cp	1.093109
Temperature	266.263 °C
Cp	1.092906
Temperature	267.2364 °C
Cp	1.092704
Temperature	268.2098 °C
Cp	1.092511
Temperature	269.1832 °C
Cp	1.092331
Temperature	270.1566 °C
Cp	1.092174
Temperature	271.1299 °C
Cp	1.092046
Temperature	272.1033 °C
Cp	1.091947
Temperature	273.0767 °C
Cp	1.091882
Temperature	274.0501 °C
Cp	1.091853
Temperature	275.0235 °C
Cp	1.091859
Temperature	275.9969 °C
Cp	1.091895
Temperature	276.9702 °C
Cp	1.091957
Temperature	277.9436 °C
Cp	1.092036
Temperature	278.917 °C
Cp	1.092132
Temperature	279.8904 °C
Cp	1.09223
Temperature	280.8638 °C
Cp	1.092323
Temperature	281.8372 °C
Cp	1.092405
Temperature	282.8105 °C
Cp	1.092468
Temperature	283.7839 °C
Cp	1.092513
Temperature	284.7573 °C
Cp	1.092525
Temperature	285.7307 °C
Cp	1.092512
Temperature	286.7041 °C
Cp	1.092472
Temperature	287.6775 °C
Cp	1.092405
Temperature	288.6509 °C
Cp	1.092313
Temperature	289.6243 °C
Cp	1.092197
Temperature	290.5977 °C
Cp	1.09207
Temperature	291.571 °C
Cp	1.091931
Temperature	292.5444 °C
Cp	1.091785
Temperature	293.5178 °C
Cp	1.091641
Temperature	294.4912 °C
Cp	1.091506
Temperature	295.4646 °C
Cp	1.091387
Temperature	296.438 °C
Cp	1.091282
Temperature	297.4113 °C
Cp	1.091201
Temperature	298.3847 °C
Cp	1.091145
Temperature	299.3581 °C
Cp	1.091112
Temperature	300.3315 °C
Cp	1.091102
Temperature	301.3049 °C
Cp	1.091107
Temperature	302.2783 °C
Cp	1.091137
Temperature	303.2517 °C
Cp	1.091177
Temperature	304.2251 °C
Cp	1.091226
Temperature	305.1984 °C
Cp	1.09128
Temperature	306.1718 °C
Cp	1.091336
Temperature	307.1452 °C
Cp	1.091403
Temperature	308.1186 °C
Cp	1.091453
Temperature	309.092 °C
Cp	1.091506
Temperature	310.0654 °C
Cp	1.091561
Temperature	311.0388 °C
Cp	1.091617
Temperature	312.0121 °C
Cp	1.09167
Temperature	312.9855 °C
Cp	1.091716
Temperature	313.9589 °C
Cp	1.091762
Temperature	314.9323 °C
Cp	1.091805
Temperature	315.9057 °C
Cp	1.091838
Temperature	316.8791 °C
Cp	1.09186
Temperature	317.8524 °C
Cp	1.091871
Temperature	318.8258 °C
Cp	1.091872
Temperature	319.7992 °C
Cp	1.091867
Temperature	320.7726 °C
Cp	1.091838
Temperature	321.746 °C
Cp	1.0918
Temperature	322.7194 °C
Cp	1.091752
Temperature	323.6928 °C
Cp	1.091689
Temperature	324.6662 °C
Cp	1.091611
Temperature	325.6396 °C
Cp	1.091508
Temperature	326.6129 °C
Cp	1.091406
Temperature	327.5863 °C
Cp	1.091285
Temperature	328.5597 °C
Cp	1.09115
Temperature	329.5331 °C
Cp	1.091009
Temperature	330.5065 °C
Cp	1.09087
Temperature	331.4799 °C
Cp	1.090747
Temperature	332.4532 °C
Cp	1.090628
Temperature	333.4266 °C
Cp	1.090536
Temperature	334.4 °C
Cp	1.090472
Temperature	335.3734 °C
Cp	1.090437
Temperature	336.3468 °C
Cp	1.090431
Temperature	337.3202 °C
Cp	1.090455
Temperature	338.2935 °C
Cp	1.090503
Temperature	339.2669 °C
Cp	1.090573
Temperature	340.2403 °C
Cp	1.090658
Temperature	341.2137 °C
Cp	1.090753
Temperature	342.1871 °C
Cp	1.090853
Temperature	343.1605 °C
Cp	1.090952
Temperature	344.1339 °C
Cp	1.09105
Temperature	345.1073 °C
Cp	1.091141
Temperature	346.0807 °C
Cp	1.091225
Temperature	347.054 °C
Cp	1.091303
Temperature	348.0274 °C
Cp	1.091379
Temperature	349.0008 °C
Cp	1.091453
Temperature	349.9742 °C
Cp	1.091537
Temperature	350.9476 °C
Cp	1.091633
Temperature	351.921 °C
Cp	1.091743
Temperature	352.8943 °C
Cp	1.091874
Temperature	353.8677 °C
Cp	1.092028
Temperature	354.8411 °C
Cp	1.092206
Temperature	355.8145 °C
Cp	1.092411
Temperature	356.7879 °C
Cp	1.092628
Temperature	357.7613 °C
Cp	1.092862
Temperature	358.7346 °C
Cp	1.093102
Temperature	359.708 °C
Cp	1.093338
Temperature	360.6814 °C
Cp	1.093559
Temperature	361.6548 °C
Cp	1.093752
Temperature	362.6282 °C
Cp	1.093915
Temperature	363.6016 °C
Cp	1.094036
Temperature	364.575 °C
Cp	1.094117
Temperature	365.5484 °C
Cp	1.094159
Temperature	366.5218 °C
Cp	1.094172
Temperature	367.4951 °C
Cp	1.094165
Temperature	368.4685 °C
Cp	1.094163
Temperature	369.4419 °C
Cp	1.094182
Temperature	370.4153 °C
Cp	1.094244
Temperature	371.3887 °C
Cp	1.094375
Temperature	372.3621 °C
Cp	1.094598
Temperature	373.3354 °C
Cp	1.094937
Temperature	374.3088 °C
Cp	1.095389
Temperature	375.2822 °C
Cp	1.095973
Temperature	376.2556 °C
Cp	1.096685
Temperature	377.229 °C
Cp	1.097506
Temperature	378.2024 °C
Cp	1.098406
Temperature	379.1758 °C
Cp	1.099338
Temperature	380.1492 °C
Cp	1.10027
Temperature	381.1225 °C
Cp	1.10112
Temperature	382.0959 °C
Cp	1.101818
Temperature	383.0693 °C
Cp	1.10229
Temperature	384.0427 °C
Cp	1.102459
Temperature	385.0161 °C
Cp	1.102253
Temperature	385.9895 °C
Cp	1.101596
Temperature	386.9629 °C
Cp	1.100438
Temperature	387.9362 °C
Cp	1.098736
Temperature	388.9096 °C
Cp	1.096461
Temperature	389.883 °C
Cp	1.093614
Temperature	390.8564 °C
Cp	1.090208
Temperature	391.8298 °C
Cp	1.086278
Temperature	392.8032 °C
Cp	1.081887
Temperature	393.7766 °C
Cp	1.077096
Temperature	394.7499 °C
Cp	1.072007
Temperature	395.7233 °C
Cp	1.066707
[Rev Cp Calibration]
Date Applied	24/10/2024 12:37:31
Description	From -89.998 °C to 390.542 °C at 2.000°C/min
Gas Type	Nitrogen
Pan Type	Tzero Aluminum
Source Files 1	C:\ProgramData\TA Instruments\TRIOS\Data\Reverse Heat Capacity Calibration(6).tri
GUID	ba867d72-cfbb-486e-971e-e86aa544cc02
Temperature	-89.99799 °C
Cp	1.070076
Temperature	-89.03691 °C
Cp	1.072008
Temperature	-88.07584 °C
Cp	1.073556
Temperature	-87.11475 °C
Cp	1.074743
Temperature	-86.15367 °C
Cp	1.075597
Temperature	-85.1926 °C
Cp	1.076163
Temperature	-84.23151 °C
Cp	1.076477
Temperature	-83.27043 °C
Cp	1.076579
Temperature	-82.30936 °C
Cp	1.076527
Temperature	-81.34827 °C
Cp	1.076322
Temperature	-80.38719 °C
Cp	1.076039
Temperature	-79.42612 °C
Cp	1.07571
Temperature	-78.46503 °C
Cp	1.075361
Temperature	-77.50395 °C
Cp	1.075011
Temperature	-76.54288 °C
Cp	1.074656
Temperature	-75.58179 °C
Cp	1.074359
Temperature	-74.62071 °C
Cp	1.074086
Temperature	-73.65964 °C
Cp	1.073842
Temperature	-72.69855 °C
Cp	1.073627
Temperature	-71.73747 °C
Cp	1.073442
Temperature	-70.7764 °C
Cp	1.07329
Temperature	-69.81532 °C
Cp	1.073148
Temperature	-68.85423 °C
Cp	1.073021
Temperature	-67.89315 °C
Cp	1.072902
Temperature	-66.93208 °C
Cp	1.072782
Temperature	-65.97099 °C
Cp	1.072656
Temperature	-65.00991 °C
Cp	1.072518
Temperature	-64.04884 °C
Cp	1.072374
Temperature	-63.08775 °C
Cp	1.072201
Temperature	-62.12667 °C
Cp	1.072019
Temperature	-61.1656 °C
Cp	1.071827
Temperature	-60.20451 °C
Cp	1.071624
Temperature	-59.24343 °C
Cp	1.071411
Temperature	-58.28236 °C
Cp	1.071167
Temperature	-57.32127 °C
Cp	1.070956
Temperature	-56.3602 °C
Cp	1.070724
Temperature	-55.39911 °C
Cp	1.070483
Temperature	-54.43803 °C
Cp	1.070242
Temperature	-53.47696 °C
Cp	1.070009
Temperature	-52.51587 °C
Cp	1.069825
Temperature	-51.55479 °C
Cp	1.069601
Temperature	-50.59372 °C
Cp	1.069418
Temperature	-49.63263 °C
Cp	1.069267
Temperature	-48.67155 °C
Cp	1.069138
Temperature	-47.71048 °C
Cp	1.069021
Temperature	-46.74939 °C
Cp	1.068875
Temperature	-45.78831 °C
Cp	1.068771
Temperature	-44.82724 °C
Cp	1.068634
Temperature	-43.86615 °C
Cp	1.068462
Temperature	-42.90508 °C
Cp	1.068255
Temperature	-41.944 °C
Cp	1.068012
Temperature	-40.98291 °C
Cp	1.067742
Temperature	-40.02184 °C
Cp	1.067427
Temperature	-39.06076 °C
Cp	1.067088
Temperature	-38.09967 °C
Cp	1.066727
Temperature	-37.1386 °C
Cp	1.066349
Temperature	-36.17752 °C
Cp	1.065958
Temperature	-35.21643 °C
Cp	1.065559
Temperature	-34.25536 °C
Cp	1.065162
Temperature	-33.29427 °C
Cp	1.06476
Temperature	-32.33319 °C
Cp	1.064368
Temperature	-31.37212 °C
Cp	1.06399
Temperature	-30.41104 °C
Cp	1.063628
Temperature	-29.44995 °C
Cp	1.063283
Temperature	-28.48887 °C
Cp	1.06295
Temperature	-27.5278 °C
Cp	1.062645
Temperature	-26.56672 °C
Cp	1.062355
Temperature	-25.60563 °C
Cp	1.06208
Temperature	-24.64456 °C
Cp	1.061819
Temperature	-23.68348 °C
Cp	1.061573
Temperature	-22.72239 °C
Cp	1.061345
Temperature	-21.76132 °C
Cp	1.061123
Temperature	-20.80024 °C
Cp	1.060915
Temperature	-19.83916 °C
Cp	1.060719
Temperature	-18.87807 °C
Cp	1.060531
Temperature	-17.917 °C
Cp	1.06035
Temperature	-16.95592 °C
Cp	1.060161
Temperature	-15.99484 °C
Cp	1.059992
Temperature	-15.03376 °C
Cp	1.059817
Temperature	-14.07268 °C
Cp	1.059634
Temperature	-13.1116 °C
Cp	1.059445
Temperature	-12.15052 °C
Cp	1.059248
Temperature	-11.18944 °C
Cp	1.059043
Temperature	-10.22836 °C
Cp	1.058842
Temperature	-9.267276 °C
Cp	1.058615
Temperature	-8.306196 °C
Cp	1.058388
Temperature	-7.345116 °C
Cp	1.058155
Temperature	-6.384036 °C
Cp	1.057911
Temperature	-5.422956 °C
Cp	1.057652
Temperature	-4.461876 °C
Cp	1.057356
Temperature	-3.500796 °C
Cp	1.057063
Temperature	-2.539716 °C
Cp	1.056732
Temperature	-1.578636 °C
Cp	1.056364
Temperature	-0.6175562 °C
Cp	1.05596
Temperature	0.3435238 °C
Cp	1.055523
Temperature	1.304604 °C
Cp	1.055066
Temperature	2.265684 °C
Cp	1.054561
Temperature	3.226764 °C
Cp	1.054035
Temperature	4.187844 °C
Cp	1.053488
Temperature	5.148924 °C
Cp	1.052922
Temperature	6.110003 °C
Cp	1.052337
Temperature	7.071084 °C
Cp	1.051736
Temperature	8.032164 °C
Cp	1.051118
Temperature	8.993243 °C
Cp	1.050488
Temperature	9.954324 °C
Cp	1.049848
Temperature	10.9154 °C
Cp	1.049202
Temperature	11.87648 °C
Cp	1.048552
Temperature	12.83756 °C
Cp	1.047902
Temperature	13.79864 °C
Cp	1.047255
Temperature	14.75972 °C
Cp	1.046615
Temperature	15.7208 °C
Cp	1.045983
Temperature	16.68188 °C
Cp	1.045362
Temperature	17.64296 °C
Cp	1.044756
Temperature	18.60404 °C
Cp	1.044164
Temperature	19.56512 °C
Cp	1.04358
Temperature	20.5262 °C
Cp	1.043027
Temperature	21.48728 °C
Cp	1.042485
Temperature	22.44836 °C
Cp	1.041958
Temperature	23.40944 °C
Cp	1.041446
Temperature	24.37052 °C
Cp	1.040952
Temperature	25.3316 °C
Cp	1.040493
Temperature	26.29268 °C
Cp	1.040022
Temperature	27.25376 °C
Cp	1.039578
Temperature	28.21484 °C
Cp	1.039158
Temperature	29.17592 °C
Cp	1.038758
Temperature	30.137 °C
Cp	1.038373
Temperature	31.09808 °C
Cp	1.037981
Temperature	32.05916 °C
Cp	1.03763
Temperature	33.02024 °C
Cp	1.037276
Temperature	33.98132 °C
Cp	1.03692
Temperature	34.9424 °C
Cp	1.036565
Temperature	35.90348 °C
Cp	1.036213
Temperature	36.86456 °C
Cp	1.035866
Temperature	37.82564 °C
Cp	1.035529
Temperature	38.78672 °C
Cp	1.035195
Temperature	39.7478 °C
Cp	1.034875
Temperature	40.70888 °C
Cp	1.034568
Temperature	41.66996 °C
Cp	1.034276
Temperature	42.63104 °C
Cp	1.033996
Temperature	43.59212 °C
Cp	1.033726
Temperature	44.5532 °C
Cp	1.033469
Temperature	45.51428 °C
Cp	1.033221
Temperature	46.47536 °C
Cp	1.03298
Temperature	47.43644 °C
Cp	1.032744
Temperature	48.39752 °C
Cp	1.032514
Temperature	49.3586 °C
Cp	1.032289
Temperature	50.31968 °C
Cp	1.032065
Temperature	51.28076 °C
Cp	1.031844
Temperature	52.24184 °C
Cp	1.031627
Temperature	53.20292 °C
Cp	1.031413
Temperature	54.164 °C
Cp	1.031203
Temperature	55.12508 °C
Cp	1.030989
Temperature	56.08616 °C
Cp	1.030791
Temperature	57.04724 °C
Cp	1.030595
Temperature	58.00832 °C
Cp	1.030403
Temperature	58.9694 °C
Cp	1.030217
Temperature	59.93048 °C
Cp	1.03004
Temperature	60.89156 °C
Cp	1.029871
Temperature	61.85264 °C
Cp	1.029718
Temperature	62.81372 °C
Cp	1.029567
Temperature	63.7748 °C
Cp	1.02943
Temperature	64.73589 °C
Cp	1.029304
Temperature	65.69696 °C
Cp	1.029185
Temperature	66.65804 °C
Cp	1.02907
Temperature	67.61913 °C
Cp	1.028946
Temperature	68.5802 °C
Cp	1.028831
Temperature	69.54128 °C
Cp	1.028703
Temperature	70.50237 °C
Cp	1.028561
Temperature	71.46344 °C
Cp	1.028404
Temperature	72.42452 °C
Cp	1.028234
Temperature	73.3856 °C
Cp	1.028063
Temperature	74.34668 °C
Cp	1.027861
Temperature	75.30776 °C
Cp	1.027657
Temperature	76.26884 °C
Cp	1.027451
Temperature	77.22992 °C
Cp	1.027243
Temperature	78.191 °C
Cp	1.027036
Temperature	79.15208 °C
Cp	1.026812
Temperature	80.11316 °C
Cp	1.026623
Temperature	81.07424 °C
Cp	1.026431
Temperature	82.03532 °C
Cp	1.026241
Temperature	82.9964 °C
Cp	1.02606
Temperature	83.95748 °C
Cp	1.025891
Temperature	84.91856 °C
Cp	1.025739
Temperature	85.87964 °C
Cp	1.025614
Temperature	86.84072 °C
Cp	1.025493
Temperature	87.8018 °C
Cp	1.0254
Temperature	88.76288 °C
Cp	1.025329
Temperature	89.72396 °C
Cp	1.025274
Temperature	90.68504 °C
Cp	1.025229
Temperature	91.64612 °C
Cp	1.025174
Temperature	92.6072 °C
Cp	1.025138
Temperature	93.56828 °C
Cp	1.025083
Temperature	94.52936 °C
Cp	1.025008
Temperature	95.49044 °C
Cp	1.024912
Temperature	96.45152 °C
Cp	1.024796
Temperature	97.4126 °C
Cp	1.024671
Temperature	98.37368 °C
Cp	1.024506
Temperature	99.33476 °C
Cp	1.02433
Temperature	100.2958 °C
Cp	1.024144
Temperature	101.2569 °C
Cp	1.023948
Temperature	102.218 °C
Cp	1.023743
Temperature	103.1791 °C
Cp	1.023522
Temperature	104.1402 °C
Cp	1.023309
Temperature	105.1012 °C
Cp	1.023089
Temperature	106.0623 °C
Cp	1.022866
Temperature	107.0234 °C
Cp	1.022644
Temperature	107.9845 °C
Cp	1.022427
Temperature	108.9456 °C
Cp	1.022218
Temperature	109.9066 °C
Cp	1.022022
Temperature	110.8677 °C
Cp	1.021836
Temperature	111.8288 °C
Cp	1.021666
Temperature	112.7899 °C
Cp	1.021512
Temperature	113.751 °C
Cp	1.021374
Temperature	114.712 °C
Cp	1.02125
Temperature	115.6731 °C
Cp	1.021137
Temperature	116.6342 °C
Cp	1.021041
Temperature	117.5953 °C
Cp	1.020953
Temperature	118.5564 °C
Cp	1.020872
Temperature	119.5174 °C
Cp	1.020796
Temperature	120.4785 °C
Cp	1.020725
Temperature	121.4396 °C
Cp	1.020659
Temperature	122.4007 °C
Cp	1.020587
Temperature	123.3618 °C
Cp	1.020515
Temperature	124.3228 °C
Cp	1.02044
Temperature	125.2839 °C
Cp	1.020359
Temperature	126.245 °C
Cp	1.02027
Temperature	127.2061 °C
Cp	1.020167
Temperature	128.1672 °C
Cp	1.020057
Temperature	129.1282 °C
Cp	1.019933
Temperature	130.0893 °C
Cp	1.019793
Temperature	131.0504 °C
Cp	1.019638
Temperature	132.0115 °C
Cp	1.019471
Temperature	132.9726 °C
Cp	1.019292
Temperature	133.9336 °C
Cp	1.019107
Temperature	134.8947 °C
Cp	1.018912
Temperature	135.8558 °C
Cp	1.018717
Temperature	136.8169 °C
Cp	1.018527
Temperature	137.778 °C
Cp	1.018344
Temperature	138.739 °C
Cp	1.018171
Temperature	139.7001 °C
Cp	1.018004
Temperature	140.6612 °C
Cp	1.01787
Temperature	141.6223 °C
Cp	1.01775
Temperature	142.5834 °C
Cp	1.017652
Temperature	143.5444 °C
Cp	1.017578
Temperature	144.5055 °C
Cp	1.017534
Temperature	145.4666 °C
Cp	1.017536
Temperature	146.4277 °C
Cp	1.017545
Temperature	147.3888 °C
Cp	1.017595
Temperature	148.3498 °C
Cp	1.017679
Temperature	149.3109 °C
Cp	1.01779
Temperature	150.272 °C
Cp	1.01792
Temperature	151.2331 °C
Cp	1.018043
Temperature	152.1942 °C
Cp	1.018199
Temperature	153.1552 °C
Cp	1.018339
Temperature	154.1163 °C
Cp	1.018458
Temperature	155.0774 °C
Cp	1.018552
Temperature	156.0385 °C
Cp	1.018618
Temperature	156.9996 °C
Cp	1.018662
Temperature	157.9606 °C
Cp	1.018664
Temperature	158.9217 °C
Cp	1.018632
Temperature	159.8828 °C
Cp	1.018575
Temperature	160.8439 °C
Cp	1.018492
Temperature	161.805 °C
Cp	1.018383
Temperature	162.766 °C
Cp	1.01825
Temperature	163.7271 °C
Cp	1.018087
Temperature	164.6882 °C
Cp	1.017917
Temperature	165.6493 °C
Cp	1.017726
Temperature	166.6104 °C
Cp	1.017522
Temperature	167.5714 °C
Cp	1.01731
Temperature	168.5325 °C
Cp	1.017098
Temperature	169.4936 °C
Cp	1.016902
Temperature	170.4547 °C
Cp	1.016695
Temperature	171.4158 °C
Cp	1.016508
Temperature	172.3768 °C
Cp	1.016342
Temperature	173.3379 °C
Cp	1.016195
Temperature	174.299 °C
Cp	1.016065
Temperature	175.2601 °C
Cp	1.015927
Temperature	176.2212 °C
Cp	1.015838
Temperature	177.1822 °C
Cp	1.015746
Temperature	178.1433 °C
Cp	1.015651
Temperature	179.1044 °C
Cp	1.015555
Temperature	180.0655 °C
Cp	1.015459
Temperature	181.0266 °C
Cp	1.015401
Temperature	181.9876 °C
Cp	1.015288
Temperature	182.9487 °C
Cp	1.015195
Temperature	183.9098 °C
Cp	1.015117
Temperature	184.8709 °C
Cp	1.01505
Temperature	185.832 °C
Cp	1.014988
Temperature	186.793 °C
Cp	1.014927
Temperature	187.7541 °C
Cp	1.014849
Temperature	188.7152 °C
Cp	1.014789
Temperature	189.6763 °C
Cp	1.01471
Temperature	190.6374 °C
Cp	1.014614
Temperature	191.5984 °C
Cp	1.014503
Temperature	192.5595 °C
Cp	1.014381
Temperature	193.5206 °C
Cp	1.014268
Temperature	194.4817 °C
Cp	1.014122
Temperature	195.4428 °C
Cp	1.013984
Temperature	196.4038 °C
Cp	1.013853
Temperature	197.3649 °C
Cp	1.013726
Temperature	198.326 °C
Cp	1.013603
Temperature	199.2871 °C
Cp	1.013467
Temperature	200.2482 °C
Cp	1.013359
Temperature	201.2092 °C
Cp	1.013243
Temperature	202.1703 °C
Cp	1.013123
Temperature	203.1314 °C
Cp	1.013002
Temperature	204.0925 °C
Cp	1.012884
Temperature	205.0536 °C
Cp	1.012788
Temperature	206.0146 °C
Cp	1.012674
Temperature	206.9757 °C
Cp	1.012579
Temperature	207.9368 °C
Cp	1.012501
Temperature	208.8979 °C
Cp	1.012439
Temperature	209.859 °C
Cp	1.012389
Temperature	210.82 °C
Cp	1.012351
Temperature	211.7811 °C
Cp	1.012312
Temperature	212.7422 °C
Cp	1.01229
Temperature	213.7033 °C
Cp	1.012262
Temperature	214.6644 °C
Cp	1.012227
Temperature	215.6254 °C
Cp	1.012183
Temperature	216.5865 °C
Cp	1.012129
Temperature	217.5476 °C
Cp	1.012077
Temperature	218.5087 °C
Cp	1.01199
Temperature	219.4698 °C
Cp	1.011897
Temperature	220.4308 °C
Cp	1.011793
Temperature	221.3919 °C
Cp	1.011674
Temperature	222.353 °C
Cp	1.011537
Temperature	223.3141 °C
Cp	1.011362
Temperature	224.2752 °C
Cp	1.011194
Temperature	225.2362 °C
Cp	1.010993
Temperature	226.1973 °C
Cp	1.010766
Temperature	227.1584 °C
Cp	1.010517
Temperature	228.1195 °C
Cp	1.010251
Temperature	229.0806 °C
Cp	1.009998
Temperature	230.0416 °C
Cp	1.009703
Temperature	231.0027 °C
Cp	1.009422
Temperature	231.9638 °C
Cp	1.009156
Temperature	232.9249 °C
Cp	1.008906
Temperature	233.886 °C
Cp	1.008675
Temperature	234.847 °C
Cp	1.008462
Temperature	235.8081 °C
Cp	1.008258
Temperature	236.7692 °C
Cp	1.00809
Temperature	237.7303 °C
Cp	1.007934
Temperature	238.6914 °C
Cp	1.007793
Temperature	239.6524 °C
Cp	1.007668
Temperature	240.6135 °C
Cp	1.007562
Temperature	241.5746 °C
Cp	1.007487
Temperature	242.5357 °C
Cp	1.00741
Temperature	243.4967 °C
Cp	1.00736
Temperature	244.4578 °C
Cp	1.007332
Temperature	245.4189 °C
Cp	1.007321
Temperature	246.38 °C
Cp	1.007321
Temperature	247.3411 °C
Cp	1.007312
Temperature	248.3022 °C
Cp	1.007331
Temperature	249.2632 °C
Cp	1.007338
Temperature	250.2243 °C
Cp	1.007335
Temperature	251.1854 °C
Cp	1.00732
Temperature	252.1465 °C
Cp	1.007295
Temperature	253.1076 °C
Cp	1.007277
Temperature	254.0686 °C
Cp	1.007227
Temperature	255.0297 °C
Cp	1.007179
Temperature	255.9908 °C
Cp	1.007133
Temperature	256.9519 °C
Cp	1.00709
Temperature	257.913 °C
Cp	1.007049
Temperature	258.874 °C
Cp	1.007012
Temperature	259.8351 °C
Cp	1.006978
Temperature	260.7962 °C
Cp	1.006956
Temperature	261.7573 °C
Cp	1.00694
Temperature	262.7184 °C
Cp	1.006934
Temperature	263.6794 °C
Cp	1.006939
Temperature	264.6405 °C
Cp	1.00696
Temperature	265.6016 °C
Cp	1.006999
Temperature	266.5627 °C
Cp	1.007054
Temperature	267.5237 °C
Cp	1.007131
Temperature	268.4848 °C
Cp	1.00723
Temperature	269.4459 °C
Cp	1.00735
Temperature	270.407 °C
Cp	1.007493
Temperature	271.3681 °C
Cp	1.007656
Temperature	272.3292 °C
Cp	1.007839
Temperature	273.2902 °C
Cp	1.008039
Temperature	274.2513 °C
Cp	1.008257
Temperature	275.2124 °C
Cp	1.008488
Temperature	276.1735 °C
Cp	1.008731
Temperature	277.1346 °C
Cp	1.008977
Temperature	278.0956 °C
Cp	1.009237
Temperature	279.0567 °C
Cp	1.009498
Temperature	280.0178 °C
Cp	1.009757
Temperature	280.9789 °C
Cp	1.010014
Temperature	281.9399 °C
Cp	1.010267
Temperature	282.901 °C
Cp	1.010515
Temperature	283.8621 °C
Cp	1.01076
Temperature	284.8232 °C
Cp	1.010993
Temperature	285.7843 °C
Cp	1.011222
Temperature	286.7454 °C
Cp	1.011447
Temperature	287.7064 °C
Cp	1.011665
Temperature	288.6675 °C
Cp	1.011876
Temperature	289.6286 °C
Cp	1.012079
Temperature	290.5897 °C
Cp	1.01228
Temperature	291.5508 °C
Cp	1.012474
Temperature	292.5118 °C
Cp	1.012662
Temperature	293.4729 °C
Cp	1.012846
Temperature	294.434 °C
Cp	1.013028
Temperature	295.3951 °C
Cp	1.013211
Temperature	296.3561 °C
Cp	1.013391
Temperature	297.3172 °C
Cp	1.013574
Temperature	298.2783 °C
Cp	1.013759
Temperature	299.2394 °C
Cp	1.013947
Temperature	300.2005 °C
Cp	1.014136
Temperature	301.1616 °C
Cp	1.01432
Temperature	302.1226 °C
Cp	1.014511
Temperature	303.0837 °C
Cp	1.014695
Temperature	304.0448 °C
Cp	1.014872
Temperature	305.0059 °C
Cp	1.01504
Temperature	305.9669 °C
Cp	1.015198
Temperature	306.928 °C
Cp	1.015343
Temperature	307.8891 °C
Cp	1.015479
Temperature	308.8502 °C
Cp	1.015595
Temperature	309.8113 °C
Cp	1.015699
Temperature	310.7724 °C
Cp	1.015789
Temperature	311.7334 °C
Cp	1.015865
Temperature	312.6945 °C
Cp	1.015925
Temperature	313.6556 °C
Cp	1.015964
Temperature	314.6167 °C
Cp	1.015999
Temperature	315.5778 °C
Cp	1.016018
Temperature	316.5388 °C
Cp	1.016025
Temperature	317.4999 °C
Cp	1.016024
Temperature	318.461 °C
Cp	1.01602
Temperature	319.4221 °C
Cp	1.016029
Temperature	320.3831 °C
Cp	1.016025
Temperature	321.3442 °C
Cp	1.016037
Temperature	322.3053 °C
Cp	1.016066
Temperature	323.2664 °C
Cp	1.01611
Temperature	324.2275 °C
Cp	1.016169
Temperature	325.1886 °C
Cp	1.016225
Temperature	326.1496 °C
Cp	1.016318
Temperature	327.1107 °C
Cp	1.016411
Temperature	328.0718 °C
Cp	1.016504
Temperature	329.0329 °C
Cp	1.016596
Temperature	329.994 °C
Cp	1.016687
Temperature	330.955 °C
Cp	1.016775
Temperature	331.9161 °C
Cp	1.016864
Temperature	332.8772 °C
Cp	1.016942
Temperature	333.8383 °C
Cp	1.017019
Temperature	334.7993 °C
Cp	1.017093
Temperature	335.7604 °C
Cp	1.017163
Temperature	336.7215 °C
Cp	1.01723
Temperature	337.6826 °C
Cp	1.017295
Temperature	338.6437 °C
Cp	1.017358
[...]
151.5867	111.0292	0.3662
151.5950	110.9462	0.3661
151.6033	110.8629	0.3661
151.6117	110.7796	0.3661
151.6200	110.6963	0.3661
151.6283	110.6125	0.3660
151.6367	110.5302	0.3660
151.6450	110.4470	0.3660
151.6533	110.3649	0.3660
151.6617	110.2801	0.3660
151.6700	110.1974	0.3660
151.6783	110.1161	0.3658
151.6867	110.0316	0.3657
151.6950	109.9488	0.3657
151.7033	109.8660	0.3657
151.7117	109.7810	0.3657
151.7200	109.6990	0.3656
151.7283	109.6159	0.3656
151.7367	109.5326	0.3656
151.7450	109.4495	0.3656
151.7533	109.3664	0.3655
151.7617	109.2835	0.3655
151.7700	109.2004	0.3654
151.7783	109.1176	0.3654
151.7867	109.0351	0.3654
151.7950	108.9507	0.3654
151.8033	108.8682	0.3654
151.8117	108.7843	0.3654
151.8200	108.7009	0.3653
151.8283	108.6201	0.3652
151.8367	108.5359	0.3651
151.8450	108.4526	0.3651
151.8533	108.3682	0.3651
151.8617	108.2867	0.3651
151.8700	108.2031	0.3650
151.8783	108.1210	0.3650
151.8867	108.0359	0.3650
151.8950	107.9522	0.3650
151.9033	107.8690	0.3650
151.9117	107.7879	0.3649
151.9200	107.7037	0.3649
151.9283	107.6205	0.3649
151.9367	107.5372	0.3649
151.9450	107.4532	0.3649
151.9533	107.3710	0.3648
151.9617	107.2873	0.3648
151.9700	107.2047	0.3648
151.9783	107.1219	0.3648
151.9867	107.0386	0.3647
151.9950	106.9545	0.3647
152.0033	106.8717	0.3647
152.0117	106.7872	0.3647
152.0200	106.7055	0.3646
152.0283	106.6218	0.3646
152.0367	106.5387	0.3646
152.0450	106.4561	0.3646
152.0533	106.3735	0.3645
152.0617	106.2890	0.3645
152.0700	106.2070	0.3644
152.0783	106.1228	0.3644
152.0867	106.0414	0.3644
152.0950	105.9564	0.3643
152.1033	105.8742	0.3643
152.1117	105.7914	0.3642
152.1200	105.7081	0.3642
152.1283	105.6252	0.3642
152.1367	105.5420	0.3642
152.1450	105.4581	0.3641
152.1533	105.3743	0.3641
152.1617	105.2916	0.3641
152.1700	105.2097	0.3640
152.1783	105.1260	0.3640
152.1867	105.0426	0.3640
152.1950	104.9600	0.3640
152.2033	104.8765	0.3639
152.2117	104.7934	0.3639
152.2200	104.7094	0.3639
152.2283	104.6279	0.3639
152.2367	104.5436	0.3638
152.2450	104.4614	0.3638
152.2533	104.3782	0.3638
152.2617	104.2946	0.3637
152.2700	104.2118	0.3637
152.2783	104.1286	0.3636
152.2867	104.0458	0.3636
152.2950	103.9620	0.3636
152.3033	103.8785	0.3636
152.3117	103.7957	0.3635
152.3200	103.7134	0.3635
152.3283	103.6302	0.3635
152.3367	103.5459	0.3635
152.3450	103.4633	0.3635
152.3533	103.3797	0.3634
152.3617	103.2960	0.3634
152.3700	103.2138	0.3633
152.3783	103.1307	0.3633
152.3867	103.0478	0.3633
152.3950	102.9650	0.3633
152.4033	102.8811	0.3632
152.4117	102.7986	0.3632
152.4200	102.7147	0.3632
152.4283	102.6315	0.3631
152.4367	102.5491	0.3630
152.4450	102.4668	0.3630
152.4533	102.3834	0.3630
152.4617	102.2990	0.3630
152.4700	102.2180	0.3629
152.4783	102.1333	0.3629
152.4867	102.0506	0.3629
152.4950	101.9673	0.3628
152.5033	101.8845	0.3628
152.5117	101.8015	0.3628
152.5200	101.7172	0.3628
152.5283	101.6344	0.3628
152.5367	101.5514	0.3627
152.5450	101.4674	0.3627
152.5533	101.3856	0.3626
152.5617	101.3016	0.3626
152.5700	101.2180	0.3626
152.5783	101.1348	0.3626
152.5867	101.0517	0.3625
152.5950	100.9692	0.3625
152.6033	100.8866	0.3625
152.6117	100.8022	0.3625
152.6200	100.7198	0.3624
152.6283	100.6370	0.3624
152.6367	100.5529	0.3624
152.6450	100.4697	0.3623
152.6533	100.3873	0.3623
152.6617	100.3052	0.3623
152.6700	100.2223	0.3622
152.6783	100.1368	0.3622
152.6867	100.0549	0.3622
152.6950	99.9711	0.3621
152.7033	99.8880	0.3621
152.7117	99.8053	0.3621
152.7200	99.7224	0.3621
152.7283	99.6380	0.3620
152.7367	99.5553	0.3620
152.7450	99.4730	0.3619
152.7533	99.3900	0.3619
152.7617	99.3062	0.3619
152.7700	99.2231	0.3619
152.7783	99.1397	0.3619
152.7867	99.0563	0.3618
152.7950	98.9741	0.3618
152.8033	98.8917	0.3617
152.8117	98.8072	0.3617
152.8200	98.7250	0.3617
152.8283	98.6415	0.3616
152.8367	98.5573	0.3616
152.8450	98.4749	0.3616
152.8533	98.3919	0.3616
152.8617	98.3084	0.3615
152.8700	98.2248	0.3615
152.8783	98.1428	0.3615
152.8867	98.0590	0.3614
152.8950	97.9755	0.3614
152.9033	97.8934	0.3614
152.9117	97.8095	0.3613
152.9200	97.7271	0.3613
152.9283	97.6453	0.3612
152.9367	97.5615	0.3612
152.9450	97.4780	0.3612
152.9533	97.3935	0.3611
152.9617	97.3113	0.3611
152.9700	97.2286	0.3611
152.9783	97.1454	0.3610
152.9867	97.0625	0.3610
152.9950	96.9794	0.3610
153.0033	96.8962	0.3609
153.0117	96.8119	0.3609
153.0200	96.7299	0.3609
153.0283	96.6465	0.3609
153.0367	96.5634	0.3608
153.0450	96.4796	0.3608
153.0533	96.3971	0.3607
153.0617	96.3135	0.3607
153.0700	96.2320	0.3607
153.0783	96.1477	0.3606
153.0867	96.0639	0.3606
153.0950	95.9805	0.3606
153.1033	95.8976	0.3605
153.1117	95.8148	0.3605
153.1200	95.7317	0.3604
153.1283	95.6471	0.3604
153.1367	95.5655	0.3604
153.1450	95.4836	0.3604
153.1533	95.3999	0.3603
153.1617	95.3158	0.3603
153.1700	95.2326	0.3603
153.1783	95.1488	0.3603
153.1867	95.0658	0.3602
153.1950	94.9825	0.3602
153.2033	94.8995	0.3602
153.2117	94.8160	0.3601
153.2200	94.7337	0.3601
153.2283	94.6493	0.3600
153.2367	94.5669	0.3599
153.2450	94.4834	0.3598
153.2533	94.4005	0.3598
153.2617	94.3174	0.3597
153.2700	94.2345	0.3597
153.2783	94.1511	0.3597
153.2867	94.0679	0.3597
153.2950	93.9847	0.3596
153.3033	93.9021	0.3596
153.3117	93.8188	0.3595
153.3200	93.7355	0.3595
153.3283	93.6517	0.3595
153.3367	93.5695	0.3595
153.3450	93.4858	0.3595
153.3533	93.4036	0.3593
153.3617	93.3195	0.3591
153.3700	93.2379	0.3591
153.3783	93.1543	0.3591
153.3867	93.0703	0.3591
153.3950	92.9881	0.3590
153.4033	92.9045	0.3590
153.4117	92.8204	0.3590
153.4200	92.7386	0.3588
153.4283	92.6546	0.3588
153.4367	92.5710	0.3588
153.4450	92.4872	0.3588
153.4533	92.4048	0.3587
153.4617	92.3207	0.3587
153.4700	92.2380	0.3586
153.4783	92.1546	0.3586
153.4867	92.0719	0.3586
153.4950	91.9885	0.3586
153.5033	91.9055	0.3585
153.5117	91.8226	0.3585
153.5200	91.7392	0.3584
153.5283	91.6550	0.3584
153.5367	91.5717	0.3584
153.5450	91.4890	0.3584
153.5533	91.4063	0.3584
153.5617	91.3228	0.3583
153.5700	91.2396	0.3583
153.5783	91.1567	0.3583
153.5867	91.0728	0.3583
153.5950	90.9902	0.3582
153.6033	90.9066	0.3582
153.6117	90.8242	0.3581
153.6200	90.7417	0.3581
153.6283	90.6583	0.3581
153.6367	90.5752	0.3580
153.6450	90.4922	0.3580
153.6533	90.4081	0.3580
153.6617	90.3248	0.3579
153.6700	90.2418	0.3579
153.6783	90.1590	0.3578
153.6867	90.0762	0.3578
153.6950	89.9925	0.3578
153.7033	89.9097	0.3577
153.7117	89.8263	0.3577
153.7200	89.7436	0.3577
153.7283	89.6593	0.3576
153.7367	89.5767	0.3576
153.7450	89.4931	0.3576
153.7533	89.4099	0.3575
153.7617	89.3270	0.3575
153.7700	89.2452	0.3575
153.7783	89.1607	0.3574
153.7867	89.0776	0.3574
153.7950	88.9949	0.3574
153.8033	88.9113	0.3574
153.8117	88.8273	0.3573
153.8200	88.7456	0.3573
153.8283	88.6616	0.3573
153.8367	88.5789	0.3573
153.8450	88.4959	0.3572
153.8533	88.4125	0.3572
153.8617	88.3297	0.3572
153.8700	88.2473	0.3571
153.8783	88.1634	0.3571
153.8867	88.0808	0.3571
153.8950	87.9965	0.3570
153.9033	87.9138	0.3570
153.9117	87.8311	0.3569
153.9200	87.7480	0.3569
153.9283	87.6643	0.3569
153.9367	87.5812	0.3568
153.9450	87.4981	0.3568
153.9533	87.4151	0.3568
153.9617	87.3328	0.3567
153.9700	87.2489	0.3567
153.9783	87.1657	0.3567
153.9867	87.0818	0.3566
153.9950	87.0002	0.3566
154.0033	86.9151	0.3565
154.0117	86.8336	0.3565
154.0200	86.7506	0.3565
154.0283	86.6676	0.3564
154.0367	86.5833	0.3564
154.0450	86.5003	0.3564
154.0533	86.4172	0.3564
154.0617	86.3340	0.3563
154.0700	86.2513	0.3563
154.0783	86.1679	0.3563
154.0867	86.0842	0.3562
154.0950	86.0021	0.3562
154.1033	85.9187	0.3561
154.1117	85.8344	0.3561
154.1200	85.7514	0.3561
154.1283	85.6683	0.3560
154.1367	85.5841	0.3560
154.1450	85.5023	0.3560
154.1533	85.4193	0.3560
154.1617	85.3363	0.3559
154.1700	85.2536	0.3559
154.1783	85.1697	0.3559
154.1867	85.0873	0.3559
154.1950	85.0030	0.3558
154.2033	84.9211	0.3558
154.2117	84.8377	0.3557
154.2200	84.7539	0.3557
154.2283	84.6706	0.3557
154.2367	84.5879	0.3557
154.2450	84.5046	0.3556
154.2533	84.4220	0.3556
154.2617	84.3394	0.3556
154.2700	84.2544	0.3555
154.2783	84.1728	0.3554
154.2867	84.0895	0.3554
154.2950	84.0060	0.3554
154.3033	83.9222	0.3553
154.3117	83.8392	0.3553
154.3200	83.7566	0.3553
154.3283	83.6724	0.3553
154.3367	83.5902	0.3552
154.3450	83.5075	0.3551
154.3533	83.4236	0.3551
154.3617	83.3404	0.3551
154.3700	83.2570	0.3551
154.3783	83.1740	0.3550
154.3867	83.0919	0.3550
154.3950	83.0077	0.3550
154.4033	82.9242	0.3549
154.4117	82.8429	0.3549
154.4200	82.7587	0.3549
154.4283	82.6755	0.3548
154.4367	82.5928	0.3548
154.4450	82.5100	0.3548
154.4533	82.4264	0.3547
154.4617	82.3427	0.3546
154.4700	82.2601	0.3546
154.4783	82.1770	0.3546
154.4867	82.0936	0.3546
154.4950	82.0101	0.3546
154.5033	81.9281	0.3544
154.5117	81.8446	0.3544
154.5200	81.7610	0.3544
154.5283	81.6777	0.3543
154.5367	81.5950	0.3543
154.5450	81.5110	0.3543
154.5533	81.4284	0.3543
154.5617	81.3455	0.3543
154.5700	81.2613	0.3542
154.5783	81.1788	0.3542
154.5867	81.0958	0.3541
154.5950	81.0134	0.3540
154.6033	80.9297	0.3540
154.6117	80.8455	0.3540
154.6200	80.7631	0.3540
154.6283	80.6799	0.3539
154.6367	80.5962	0.3539
154.6450	80.5141	0.3539
154.6533	80.4297	0.3539
154.6617	80.3462	0.3538
154.6700	80.2632	0.3537
154.6783	80.1797	0.3537
154.6867	80.0970	0.3537
154.6950	80.0136	0.3536
154.7033	79.9306	0.3535
154.7117	79.8472	0.3535
154.7200	79.7639	0.3535
154.7283	79.6820	0.3534
154.7367	79.5977	0.3534
154.7450	79.5146	0.3534
154.7533	79.4317	0.3533
154.7617	79.3483	0.3533
154.7700	79.2653	0.3533
154.7783	79.1824	0.3532
154.7867	79.0991	0.3532
154.7950	79.0159	0.3532
154.8033	78.9329	0.3531
154.8117	78.8496	0.3531
154.8200	78.7657	0.3531
154.8283	78.6838	0.3530
154.8367	78.6002	0.3530
154.8450	78.5174	0.3530
154.8533	78.4347	0.3529
154.8617	78.3516	0.3529
154.8700	78.2676	0.3528
154.8783	78.1860	0.3527
154.8867	78.1022	0.3527
154.8950	78.0189	0.3527
154.9033	77.9356	0.3527
154.9117	77.8524	0.3526
154.9200	77.7692	0.3526
154.9283	77.6855	0.3526
154.9367	77.6017	0.3525
154.9450	77.5188	0.3525
154.9533	77.4352	0.3524
154.9617	77.3526	0.3524
154.9700	77.2700	0.3524
154.9783	77.1863	0.3523
154.9867	77.1020	0.3523
154.9950	77.0198	0.3523
155.0033	76.9359	0.3522
155.0117	76.8519	0.3522
155.0200	76.7692	0.3522
155.0283	76.6864	0.3520
155.0367	76.6034	0.3520
155.0450	76.5209	0.3519
155.0533	76.4375	0.3519
155.0617	76.3541	0.3519
155.0700	76.2712	0.3519
155.0783	76.1877	0.3518
155.0867	76.1051	0.3518
155.0950	76.0220	0.3517
155.1033	75.9390	0.3517
155.1117	75.8559	0.3517
155.1200	75.7723	0.3516
155.1283	75.6885	0.3516
155.1367	75.6062	0.3515
155.1450	75.5229	0.3515
155.1533	75.4394	0.3515
155.1617	75.3568	0.3514
155.1700	75.2724	0.3513
155.1783	75.1901	0.3513
155.1867	75.1064	0.3512
155.1950	75.0233	0.3512
155.2033	74.9398	0.3512
155.2117	74.8569	0.3511
155.2200	74.7732	0.3510
155.2283	74.6910	0.3510
155.2367	74.6081	0.3509
155.2450	74.5248	0.3509
155.2533	74.4414	0.3509
155.2617	74.3569	0.3508
155.2700	74.2756	0.3508
155.2783	74.1921	0.3508
155.2867	74.1086	0.3507
155.2950	74.0257	0.3506
155.3033	73.9429	0.3506
155.3117	73.8600	0.3506
155.3200	73.7765	0.3505
155.3283	73.6933	0.3505
155.3367	73.6098	0.3504
155.3450	73.5267	0.3504
155.3533	73.4437	0.3503
155.3617	73.3601	0.3503
155.3700	73.2767	0.3503
155.3783	73.1933	0.3502
155.3867	73.1109	0.3502
155.3950	73.0275	0.3501
155.4033	72.9438	0.3501
155.4117	72.8597	0.3501
155.4200	72.7781	0.3500
155.4283	72.6951	0.3500
155.4367	72.6110	0.3499
155.4450	72.5277	0.3498
155.4533	72.4456	0.3496
155.4617	72.3621	0.3496
155.4700	72.2794	0.3495
155.4783	72.1951	0.3495
155.4867	72.1127	0.3495
155.4950	72.0290	0.3494
155.5033	71.9447	0.3494
155.5117	71.8634	0.3493
155.5200	71.7791	0.3493
155.5283	71.6970	0.3492
155.5367	71.6140	0.3492
155.5450	71.5307	0.3492
155.5533	71.4467	0.3492
155.5617	71.3641	0.3491
155.5700	71.2807	0.3491
155.5783	71.1965	0.3491
155.5867	71.1139	0.3491
155.5950	71.0322	0.3490
155.6033	70.9477	0.3490
155.6117	70.8645	0.3489
155.6200	70.7818	0.3489
155.6283	70.6986	0.3488
155.6367	70.6163	0.3488
155.6450	70.5323	0.3488
155.6533	70.4490	0.3487
155.6617	70.3652	0.3487
155.6700	70.2825	0.3486
155.6783	70.1994	0.3486
155.6867	70.1176	0.3485
155.6950	70.0331	0.3485
155.7033	69.9506	0.3485
155.7117	69.8670	0.3484
155.7200	69.7839	0.3484
155.7283	69.7015	0.3483
155.7367	69.6181	0.3483
155.7450	69.5345	0.3483
155.7533	69.4517	0.3482
155.7617	69.3679	0.3482
155.7700	69.2846	0.3481
155.7783	69.2015	0.3481
155.7867	69.1179	0.3481
155.7950	69.0345	0.3480
155.8033	68.9512	0.3480
155.8117	68.8686	0.3480
155.8200	68.7858	0.3479
155.8283	68.7018	0.3479
155.8367	68.6200	0.3479
155.8450	68.5352	0.3478
155.8533	68.4530	0.3478
155.8617	68.3701	0.3478
155.8700	68.2861	0.3478
155.8783	68.2025	0.3477
155.8867	68.1191	0.3477
155.8950	68.0364	0.3476
155.9033	67.9531	0.3476
155.9117	67.8700	0.3475
155.9200	67.7866	0.3475
155.9283	67.7043	0.3475
155.9367	67.6209	0.3474
155.9450	67.5371	0.3474
155.9533	67.4536	0.3473
155.9617	67.3726	0.3473
155.9700	67.2885	0.3472
155.9783	67.2052	0.3472
155.9867	67.1215	0.3472
155.9950	67.0392	0.3471
156.0033	66.9549	0.3471
156.0117	66.8728	0.3470
156.0200	66.7895	0.3470
156.0283	66.7061	0.3469
156.0367	66.6232	0.3469
156.0450	66.5390	0.3468
156.0533	66.4559	0.3468
156.0617	66.3734	0.3467
156.0700	66.2895	0.3467
156.0783	66.2068	0.3466
156.0867	66.1236	0.3465
156.0950	66.0406	0.3465
156.1033	65.9569	0.3465
156.1117	65.8740	0.3464
156.1200	65.7914	0.3464
156.1283	65.7079	0.3464
156.1367	65.6237	0.3462
156.1450	65.5419	0.3462
156.1533	65.4582	0.3461
156.1617	65.3755	0.3461
156.1700	65.2918	0.3461
156.1783	65.2083	0.3461
156.1867	65.1255	0.3460
156.1950	65.0429	0.3460
156.2033	64.9590	0.3459
156.2117	64.8759	0.3458
156.2200	64.7931	0.3458
156.2283	64.7087	0.3457
156.2367	64.6259	0.3457
156.2450	64.5427	0.3456
156.2533	64.4600	0.3456
156.2617	64.3769	0.3456
156.2700	64.2951	0.3455
156.2783	64.2112	0.3455
156.2867	64.1274	0.3455
156.2950	64.0444	0.3454
156.3033	63.9613	0.3454
156.3117	63.8783	0.3454
156.3200	63.7949	0.3454
156.3283	63.7107	0.3453
156.3367	63.6281	0.3453
156.3450	63.5443	0.3453
156.3533	63.4622	0.3453
156.3617	63.3788	0.3452
156.3700	63.2956	0.3452
156.3783	63.2128	0.3452
156.3867	63.1297	0.3452
156.3950	63.0455	0.3452
156.4033	62.9650	0.3453
156.4117	62.8805	0.3453
156.4200	62.7968	0.3453
156.4283	62.7150	0.3456
156.4367	62.6315	0.3461
156.4450	62.5495	0.3473
156.4533	62.4662	0.3493
156.4617	62.3835	0.3525
156.4700	62.3007	0.3549
156.4783	62.2188	0.3598
156.4867	62.1378	0.3648
156.4950	62.0552	0.3694
156.5033	61.9744	0.3747
156.5117	61.8928	0.3810
156.5200	61.8112	0.3900
156.5283	61.7327	0.4003
156.5367	61.6529	0.4117
156.5450	61.5726	0.4249
156.5533	61.4958	0.4400
156.5617	61.4196	0.4592
156.5700	61.3433	0.4812
156.5783	61.2683	0.5058
156.5867	61.1953	0.5351
156.5950	61.1244	0.5694
156.6033	61.0543	0.6107
156.6117	60.9888	0.6569
156.6200	60.9235	0.7107
156.6283	60.8623	0.7721
156.6367	60.8050	0.8412
156.6450	60.7509	0.9207
156.6533	60.7023	1.0076
156.6617	60.6546	1.1016
156.6700	60.6151	1.2029
156.6783	60.5781	1.3104
156.6867	60.5463	1.4219
156.6950	60.5184	1.5327
156.7033	60.4957	1.6452
156.7117	60.4744	1.7560
156.7200	60.4560	1.8636
156.7283	60.4409	1.9648
156.7367	60.4257	2.0618
156.7450	60.4126	2.1534
156.7533	60.3990	2.2378
156.7617	60.3850	2.3188
156.7700	60.3707	2.3928
156.7783	60.3556	2.4599
156.7867	60.3375	2.5264
156.7950	60.3187	2.5861
156.8033	60.2978	2.6426
156.8117	60.2753	2.6964
156.8200	60.2508	2.7467
156.8283	60.2242	2.7935
156.8367	60.1958	2.8390
156.8450	60.1646	2.8836
156.8533	60.1349	2.9243
156.8617	60.1004	2.9641
156.8700	60.0647	3.0019
156.8783	60.0260	3.0378
156.8867	59.9874	3.0711
156.8950	59.9470	3.1046
156.9033	59.9036	3.1373
156.9117	59.8598	3.1662
156.9200	59.8145	3.1952
156.9283	59.7672	3.2223
156.9367	59.7181	3.2475
156.9450	59.6687	3.2719
156.9533	59.6176	3.2940
156.9617	59.5649	3.3141
156.9700	59.5101	3.3320
156.9783	59.4542	3.3491
156.9867	59.3973	3.3648
156.9950	59.3388	3.3776
157.0033	59.2790	3.3880
157.0117	59.2164	3.3959
157.0200	59.1532	3.4021
157.0283	59.0880	3.4067
157.0367	59.0217	3.4076
157.0450	58.9538	3.4061
157.0533	58.8826	3.4026
157.0617	58.8120	3.3957
157.0700	58.7390	3.3867
157.0783	58.6644	3.3743
157.0867	58.5865	3.3589
157.0950	58.5066	3.3412
157.1033	58.4270	3.3210
157.1117	58.3425	3.2968
157.1200	58.2584	3.2699
157.1283	58.1704	3.2404
157.1367	58.0812	3.2080
157.1450	57.9887	3.1734
157.1533	57.8948	3.1346
157.1617	57.7995	3.0928
157.1700	57.7010	3.0505
157.1783	57.6005	3.0045
157.1867	57.4979	2.9550
157.1950	57.3937	2.9045
157.2033	57.2865	2.8496
157.2117	57.1774	2.7953
157.2200	57.0656	2.7384
157.2283	56.9534	2.6797
157.2367	56.8380	2.6200
157.2450	56.7217	2.5607
157.2533	56.6034	2.5018
157.2617	56.4843	2.4429
157.2700	56.3648	2.3849
157.2783	56.2409	2.3257
157.2867	56.1192	2.2704
157.2950	55.9968	2.2167
157.3033	55.8738	2.1633
157.3117	55.7503	2.1120
157.3200	55.6266	2.0633
157.3283	55.5034	2.0155
157.3367	55.3800	1.9707
157.3450	55.2567	1.9262
157.3533	55.1340	1.8835
157.3617	55.0119	1.8427
157.3700	54.8906	1.8036
157.3783	54.7700	1.7659
157.3867	54.6495	1.7297
157.3950	54.5304	1.6960
157.4033	54.4119	1.6621
157.4117	54.2938	1.6305
157.4200	54.1780	1.6007
157.4283	54.0623	1.5715
157.4367	53.9469	1.5423
157.4450	53.8330	1.5170
157.4533	53.7199	1.4905
157.4617	53.6068	1.4662
157.4700	53.4960	1.4442
157.4783	53.3862	1.4202
157.4867	53.2763	1.3902
157.4950	53.1669	1.3643
157.5033	53.0580	1.3415
157.5117	52.9493	1.3187
157.5200	52.8423	1.2943
157.5283	52.7351	1.2696
157.5367	52.6283	1.2469
157.5450	52.5220	1.2263
157.5533	52.4165	1.2033
157.5617	52.3123	1.1846
157.5700	52.2065	1.1660
157.5783	52.1027	1.1473
157.5867	51.9994	1.1300
157.5950	51.8970	1.1130
157.6033	51.7955	1.0965
157.6117	51.6931	1.0808
157.6200	51.5922	1.0647
157.6283	51.4928	1.0495
157.6367	51.3919	1.0353
157.6450	51.2920	1.0199
157.6533	51.1933	1.0065
157.6617	51.0940	0.9924
157.6700	50.9960	0.9792
157.6783	50.8981	0.9653
157.6867	50.8016	0.9521
157.6950	50.7045	0.9397
157.7033	50.6078	0.9270
157.7117	50.5114	0.9147
157.7200	50.4144	0.9028
157.7283	50.3191	0.8918
157.7367	50.2225	0.8815
157.7450	50.1265	0.8703
157.7533	50.0327	0.8582
157.7617	49.9390	0.8479
157.7700	49.8459	0.8388
157.7783	49.7507	0.8297
157.7867	49.6567	0.8194
157.7950	49.5636	0.8095
157.8033	49.4713	0.7997
157.8117	49.3784	0.7917
157.8200	49.2862	0.7830
157.8283	49.1934	0.7739
157.8367	49.0990	0.7667
157.8450	49.0079	0.7586
157.8533	48.9171	0.7502
157.8617	48.8247	0.7428
157.8700	48.7335	0.7352
157.8783	48.6428	0.7283
157.8867	48.5507	0.7211
157.8950	48.4605	0.7144
157.9033	48.3700	0.7079
157.9117	48.2800	0.7018
157.9200	48.1896	0.6952
157.9283	48.1009	0.6902
157.9367	48.0102	0.6839
157.9450	47.9212	0.6774
157.9533	47.8317	0.6731
157.9617	47.7422	0.6668
157.9700	47.6539	0.6630
157.9783	47.5637	0.6576
157.9867	47.4760	0.6524
157.9950	47.3877	0.6496
158.0033	47.2994	0.6436
158.0117	47.2110	0.6404
158.0200	47.1235	0.6359
158.0283	47.0357	0.6320
158.0367	46.9485	0.6271
158.0450	46.8597	0.6244
158.0533	46.7723	0.6200
158.0617	46.6850	0.6177
158.0700	46.5972	0.6154
158.0783	46.5104	0.6113
158.0867	46.4256	0.6076
158.0950	46.3375	0.6045
158.1033	46.2509	0.6022
158.1117	46.1639	0.5988
158.1200	46.0774	0.5966
158.1283	45.9915	0.5929
158.1367	45.9055	0.5917
158.1450	45.8190	0.5884
158.1533	45.7340	0.5857
158.1617	45.6489	0.5822
158.1700	45.5615	0.5815
158.1783	45.4758	0.5791
158.1867	45.3897	0.5761
158.1950	45.3047	0.5732
158.2033	45.2181	0.5709
158.2117	45.1332	0.5692
158.2200	45.0480	0.5665
158.2283	44.9618	0.5642
158.2367	44.8772	0.5614
158.2450	44.7913	0.5596
158.2533	44.7047	0.5579
158.2617	44.6200	0.5544
158.2700	44.5356	0.5527
158.2783	44.4496	0.5514
158.2867	44.3636	0.5493
158.2950	44.2794	0.5463
158.3033	44.1945	0.5437
158.3117	44.1092	0.5417
158.3200	44.0241	0.5406
158.3283	43.9377	0.5381
158.3367	43.8535	0.5350
158.3450	43.7682	0.5335
158.3533	43.6832	0.5316
158.3617	43.5979	0.5289
158.3700	43.5130	0.5275
158.3783	43.4287	0.5253
158.3867	43.3432	0.5232
158.3950	43.2577	0.5206
158.4033	43.1728	0.5186
158.4117	43.0887	0.5171
158.4200	43.0036	0.5158
158.4283	42.9182	0.5136
158.4367	42.8335
158.4450	42.7493
158.4533	42.6650
158.4617	42.5783
158.4700	42.4938
158.4783	42.4084
158.4867
158.4933