File: Example Date/My Sample/DSC/test01/DSC TA/YN019 -150-150.txt
Filename	YN019 -150-150
Instrument name	DSC2A-01799 (192.168.1.250)
Operator
rundate	10/12/2024
Sample name	YN019 -150-150
proceduresegments	Ramp 10.00 °C/min to 150.0000 °C; Isothermal 3.0 min; Ramp 10.00 °C/min to -150.0000 °C; Isothermal 3.0 min; Ramp 10.00 °C/min to 150.0000 °C; Isothermal 3.0 min; Ramp 10.00 °C/min to -150.0000 °C; Isothermal 3.0 min; Ramp 10.00 °C/min to 150.0000 °C; Isothermal 3.0 min; Ramp 10.00 °C/min to 40.0000 °C
[File Parameters]
Run Date	10/12/2024 03:50:58
Trios version	5.7.0.56
Original File Name	C:\Users\TA Instruments DSC\Desktop\Data\Yutong Niu\YN019 -150-150.tri
Current File Name	C:\Users\TA Instruments DSC\Desktop\Data\Yutong Niu\YN019 -150-150.tri
User at run start	DESKTOP-CFGN8IT\TA Instruments DSC
[Procedure]
Procedure Name	polyether
Sample Name	YN019 -150-150
Sample Mass	15.5 mg
Reference Sample Mass	0 mg
Pan Mass	60.77 mg
Pan Number	23
Reference Pan Mass	60.81 mg
Reference Pan Number	45
Pan Type	Tzero Aluminum Pin Hole Hermetic
Comments
Project Name
Operator
Test	Custom
Unload Max Temperature	25
Unload Min Temperature	25
FillCooler	Do not fill
Load Max Temperature	25
Load Min Temperature	25
Discard pan in waste bin at end of test	Yes
Stop on Gas Flow Error	No
[Signal List]
Signal #1	Time (min)
Signal #2	Temperature (°C)
Signal #3	Heat Flow (mW)
Signal #4	Delta T (µV)
Signal #5	Delta Tzero (µV)
Signal #6	Tzero Temperature (°C)
Signal #7	Cell Purge (mL/min)
Signal #8	Heater Temp (°C)
Signal #9	Power Delivered (W)
Signal #10	Reference Junction Temperature (°C)
Signal #11	Flange Temperature (°C)
Signal #12	Heat Flow Phase (rad)
Signal #13	Total Heat Capacity (J/°C)
Signal #14	Heat Capacity (J/°C)
Signal #15	LN Pump Tank level (%)
[Configuration]
Company Name	Warwick University
Instrument Name	DSC2A-01799
Instrument Type	DSC2500
Serial Number	DSC2A-01799
IP	192.168.1.250
Location of Instrument	Polymer RTP
DisplayType	TianmaV2andV3
Sample Interval 	0.1 s/pt
Selected Heat Flow	T4P
Exotherm Direction	Up
Cell Serial	DRC2-03788
Lid Type	High Temperature
Cooler	LN Pump
Leave Cooler on at End of Sequence	Off
Gas 2	Air
Gas Selected	Channel 1: Nitrogen
Flow Rate	50 mL/min
Secondary Purge	On
Licensed Heat Flow	Heat Flow T4P
Modulation Licensed	Yes
[Versions]
Common IDD Version	1
Cortex Version	VER 2.11.0.729
Driver	5.0.0.6
GDM Version	1.0.3.3
TouchscreenVersion	1.0.3.1841
FEP Version	1.2.1.21
FEP Bootloader	2.0.0.5
AutoSampler Version	2.1.2.1
Auto Sampler Bootloader	2.0.0.5
FCM Version	1.1.0.3
FCM Bootloader	2.0.0.5
LN Pump Version	10.17.0.0
LN Pump Bootloader	2.0.0.5
[Experiment Logs]
Experiment Log Entry # 1	Ramp Segment 10 C/min to 150 Started
Experiment Log Entry # 3	Air Cool is off.
Experiment Log Entry # 5	Isothermal Segment 3 min started
Experiment Log Entry # 7	Auto sampler has detected that LNP has gone offline
Experiment Log Entry # 9	Ramp Segment 10 C/min to -150 Started
Experiment Log Entry # 11	FEP has detected that LNP has gone offline
Experiment Log Entry # 13	Isothermal Segment 3 min started
Experiment Log Entry # 15	Ramp Segment 10 C/min to 150 Started
Experiment Log Entry # 17	Isothermal Segment 3 min started
Experiment Log Entry # 19	Ramp Segment 10 C/min to -150 Started
Experiment Log Entry # 21	Isothermal Segment 3 min started
Experiment Log Entry # 23	Ending Experiment because of critical or major error
Experiment Log Entry # 25	LN2P Tank Empty - Liquid level sensor reports 0% full.
Experiment Log Entry # 26	Ending Experiment because of critical or major error
[Method Log]
Method Log Entry # 1	(Ramp 647132) Ramp 10 °C/minute to 150 °C
Method Log Entry # 2	Isothermal 3 minutes
Method Log Entry # 3	(Ramp 647134) Ramp 10 °C/minute to -150 °C
Method Log Entry # 4	Isothermal 3 minutes
Method Log Entry # 5	(Ramp 647136) Ramp 10 °C/minute to 150 °C
Method Log Entry # 6	Isothermal 3 minutes
Method Log Entry # 7	(Ramp 647138) Ramp 10 °C/minute to -150 °C
Method Log Entry # 8	Isothermal 3 minutes
Cell Serial	DRC2-03788
[T1 Calibration]
Date Applied	04/03/2021 14:58:04
Description
Gas Type	Nitrogen
Pan Type	None
Slope	-0.001800291
Offset	-0.1301359
Initial Temperature	-100.6228
GUID	a1d5a6be-decd-4ae4-b22f-d560f3a78a92
[TZero Calibration]
Date Applied	21/08/2024 09:53:38
Description	From -180.022 °C to 395.167 °C at 20.000°C/min
Gas Type	Nitrogen
Pan Type	None
Source Files 1	C:\ProgramData\TA Instruments\TRIOS\Data\TAService\PMV 20Aug2024\Tzero Cal.tri
Source Files 2	C:\ProgramData\TA Instruments\TRIOS\Data\TAService\PMV 20Aug2024\Tzero Cal sapphire.tri
Delta T Offset	1.787969
Delta T Slope	-0.003527276
Delta T0 Offset	0.06831977
Delta T0 Slope	0.02007191
[Temperature Calibration]
Date Applied	21/08/2024 11:06:35
Description	From 106.660 °C to 186.660 °C at 10.000°C/min
Gas Type	Nitrogen
Pan Type	Tzero Aluminum
Source Files 1	C:\ProgramData\TA Instruments\TRIOS\Data\TAService\PMV 20Aug2024\TA Indium cal.tri
Measured 1	157.9141
Known 1	156.66
[Cell Constant Calibration]
Date Applied	21/08/2024 11:06:35
Description	From 106.660 °C to 186.660 °C at 10.000°C/min
Gas Type	Nitrogen
Pan Type	Tzero Aluminum
Source Files 1	C:\ProgramData\TA Instruments\TRIOS\Data\TAService\PMV 20Aug2024\TA Indium cal.tri
T4P KCell	1.038055
Onset Slope	-66.72884 mW/°C
[Direct Cp Calibration]
Date Applied	19/11/2024 16:37:27
Description	From -89.996 °C to 396.697 °C at 20.000°C/min
Gas Type	Nitrogen
Pan Type	Tzero Aluminum
Source Files 1	C:\ProgramData\TA Instruments\TRIOS\Data\Sapphire Direct Heat Capacity(8).tri
GUID	544f8371-fe9b-4f4f-81ca-7980c172113e
Temperature	-89.99625 °C
Cp	1.464367
Temperature	-89.02287 °C
Cp	1.460558
Temperature	-88.04948 °C
Cp	1.456263
Temperature	-87.0761 °C
Cp	1.451626
Temperature	-86.10271 °C
Cp	1.446737
Temperature	-85.12933 °C
Cp	1.441723
Temperature	-84.15594 °C
Cp	1.436654
Temperature	-83.18256 °C
Cp	1.431684
Temperature	-82.20917 °C
Cp	1.426935
Temperature	-81.23578 °C
Cp	1.422396
Temperature	-80.2624 °C
Cp	1.418192
Temperature	-79.28901 °C
Cp	1.414363
Temperature	-78.31562 °C
Cp	1.410925
Temperature	-77.34224 °C
Cp	1.407865
Temperature	-76.36885 °C
Cp	1.405143
Temperature	-75.39546 °C
Cp	1.402789
Temperature	-74.42208 °C
Cp	1.400703
Temperature	-73.44869 °C
Cp	1.398837
Temperature	-72.4753 °C
Cp	1.397142
Temperature	-71.50192 °C
Cp	1.395565
Temperature	-70.52853 °C
Cp	1.394053
Temperature	-69.55515 °C
Cp	1.392558
Temperature	-68.58176 °C
Cp	1.391036
Temperature	-67.60838 °C
Cp	1.389483
Temperature	-66.63499 °C
Cp	1.387847
Temperature	-65.66161 °C
Cp	1.38616
Temperature	-64.68822 °C
Cp	1.384397
Temperature	-63.71483 °C
Cp	1.382535
Temperature	-62.74145 °C
Cp	1.380598
Temperature	-61.76806 °C
Cp	1.37865
Temperature	-60.79467 °C
Cp	1.376673
Temperature	-59.82129 °C
Cp	1.374677
Temperature	-58.8479 °C
Cp	1.372642
Temperature	-57.87452 °C
Cp	1.370686
Temperature	-56.90113 °C
Cp	1.368741
Temperature	-55.92775 °C
Cp	1.366786
Temperature	-54.95436 °C
Cp	1.364863
Temperature	-53.98097 °C
Cp	1.362959
Temperature	-53.00759 °C
Cp	1.361116
Temperature	-52.0342 °C
Cp	1.359247
Temperature	-51.06082 °C
Cp	1.357393
Temperature	-50.08743 °C
Cp	1.355593
Temperature	-49.11404 °C
Cp	1.353796
Temperature	-48.14066 °C
Cp	1.352008
Temperature	-47.16727 °C
Cp	1.350215
Temperature	-46.19389 °C
Cp	1.348396
Temperature	-45.2205 °C
Cp	1.346593
Temperature	-44.24712 °C
Cp	1.344755
Temperature	-43.27373 °C
Cp	1.342891
Temperature	-42.30034 °C
Cp	1.341008
Temperature	-41.32696 °C
Cp	1.339126
Temperature	-40.35357 °C
Cp	1.337236
Temperature	-39.38018 °C
Cp	1.335367
Temperature	-38.4068 °C
Cp	1.333522
Temperature	-37.43341 °C
Cp	1.331708
Temperature	-36.46003 °C
Cp	1.32991
Temperature	-35.48664 °C
Cp	1.328145
Temperature	-34.51326 °C
Cp	1.326414
Temperature	-33.53987 °C
Cp	1.32471
Temperature	-32.56648 °C
Cp	1.323012
Temperature	-31.5931 °C
Cp	1.321323
Temperature	-30.61971 °C
Cp	1.319657
Temperature	-29.64633 °C
Cp	1.317968
Temperature	-28.67294 °C
Cp	1.316286
Temperature	-27.69955 °C
Cp	1.314585
Temperature	-26.72617 °C
Cp	1.312857
Temperature	-25.75278 °C
Cp	1.31111
Temperature	-24.7794 °C
Cp	1.309333
Temperature	-23.80601 °C
Cp	1.307544
Temperature	-22.83262 °C
Cp	1.30575
Temperature	-21.85924 °C
Cp	1.303941
Temperature	-20.88585 °C
Cp	1.302132
Temperature	-19.91247 °C
Cp	1.300313
Temperature	-18.93908 °C
Cp	1.298512
Temperature	-17.96569 °C
Cp	1.296728
Temperature	-16.99231 °C
Cp	1.294939
Temperature	-16.01892 °C
Cp	1.293198
Temperature	-15.04554 °C
Cp	1.291453
Temperature	-14.07215 °C
Cp	1.289723
Temperature	-13.09876 °C
Cp	1.288007
Temperature	-12.12538 °C
Cp	1.286283
Temperature	-11.15199 °C
Cp	1.284578
Temperature	-10.17861 °C
Cp	1.282885
Temperature	-9.205221 °C
Cp	1.281173
Temperature	-8.231835 °C
Cp	1.279472
Temperature	-7.258449 °C
Cp	1.277766
Temperature	-6.285063 °C
Cp	1.276053
Temperature	-5.311677 °C
Cp	1.274341
Temperature	-4.338291 °C
Cp	1.272592
Temperature	-3.364905 °C
Cp	1.270844
Temperature	-2.391519 °C
Cp	1.269062
Temperature	-1.418133 °C
Cp	1.267264
Temperature	-0.4447474 °C
Cp	1.265435
Temperature	0.5286385 °C
Cp	1.263575
Temperature	1.502024 °C
Cp	1.261727
Temperature	2.47541 °C
Cp	1.259854
Temperature	3.448796 °C
Cp	1.257978
Temperature	4.422182 °C
Cp	1.256109
Temperature	5.395568 °C
Cp	1.254244
Temperature	6.368954 °C
Cp	1.252392
Temperature	7.34234 °C
Cp	1.250552
Temperature	8.315726 °C
Cp	1.248704
Temperature	9.289112 °C
Cp	1.246884
Temperature	10.2625 °C
Cp	1.245078
Temperature	11.23588 °C
Cp	1.243287
Temperature	12.20927 °C
Cp	1.241522
Temperature	13.18266 °C
Cp	1.239778
Temperature	14.15604 °C
Cp	1.238068
Temperature	15.12943 °C
Cp	1.236393
Temperature	16.10281 °C
Cp	1.234762
Temperature	17.0762 °C
Cp	1.233176
Temperature	18.04959 °C
Cp	1.231629
Temperature	19.02297 °C
Cp	1.230129
Temperature	19.99636 °C
Cp	1.228694
Temperature	20.96974 °C
Cp	1.22731
Temperature	21.94313 °C
Cp	1.225968
Temperature	22.91652 °C
Cp	1.224676
Temperature	23.8899 °C
Cp	1.223431
Temperature	24.86329 °C
Cp	1.222217
Temperature	25.83667 °C
Cp	1.221065
Temperature	26.81006 °C
Cp	1.219919
Temperature	27.78345 °C
Cp	1.218811
Temperature	28.75683 °C
Cp	1.21773
Temperature	29.73022 °C
Cp	1.216663
Temperature	30.7036 °C
Cp	1.2156
Temperature	31.67699 °C
Cp	1.214515
Temperature	32.65038 °C
Cp	1.213439
Temperature	33.62376 °C
Cp	1.21234
Temperature	34.59715 °C
Cp	1.211209
Temperature	35.57053 °C
Cp	1.210051
Temperature	36.54392 °C
Cp	1.208868
Temperature	37.5173 °C
Cp	1.207666
Temperature	38.49069 °C
Cp	1.206439
Temperature	39.46408 °C
Cp	1.205199
Temperature	40.43746 °C
Cp	1.203959
Temperature	41.41085 °C
Cp	1.202712
Temperature	42.38424 °C
Cp	1.20147
Temperature	43.35762 °C
Cp	1.200231
Temperature	44.33101 °C
Cp	1.199
Temperature	45.30439 °C
Cp	1.197777
Temperature	46.27778 °C
Cp	1.19657
Temperature	47.25116 °C
Cp	1.195367
Temperature	48.22455 °C
Cp	1.194179
Temperature	49.19794 °C
Cp	1.19301
Temperature	50.17132 °C
Cp	1.191849
Temperature	51.14471 °C
Cp	1.190694
Temperature	52.11809 °C
Cp	1.189555
Temperature	53.09148 °C
Cp	1.18843
Temperature	54.06487 °C
Cp	1.187311
Temperature	55.03825 °C
Cp	1.186195
Temperature	56.01164 °C
Cp	1.185095
Temperature	56.98502 °C
Cp	1.183997
Temperature	57.95841 °C
Cp	1.182894
Temperature	58.93179 °C
Cp	1.181793
Temperature	59.90518 °C
Cp	1.180693
Temperature	60.87857 °C
Cp	1.179595
Temperature	61.85195 °C
Cp	1.178501
Temperature	62.82534 °C
Cp	1.177406
Temperature	63.79873 °C
Cp	1.176313
Temperature	64.77211 °C
Cp	1.175239
Temperature	65.7455 °C
Cp	1.17417
Temperature	66.71888 °C
Cp	1.173105
Temperature	67.69227 °C
Cp	1.172037
Temperature	68.66566 °C
Cp	1.170989
Temperature	69.63904 °C
Cp	1.169948
Temperature	70.61243 °C
Cp	1.168905
Temperature	71.58582 °C
Cp	1.167872
Temperature	72.5592 °C
Cp	1.166849
Temperature	73.53259 °C
Cp	1.165851
Temperature	74.50597 °C
Cp	1.164848
Temperature	75.47935 °C
Cp	1.163876
Temperature	76.45274 °C
Cp	1.162926
Temperature	77.42612 °C
Cp	1.162008
Temperature	78.39951 °C
Cp	1.161113
Temperature	79.3729 °C
Cp	1.160219
Temperature	80.34628 °C
Cp	1.159377
Temperature	81.31967 °C
Cp	1.158546
Temperature	82.29306 °C
Cp	1.157726
Temperature	83.26644 °C
Cp	1.15692
Temperature	84.23983 °C
Cp	1.156126
Temperature	85.21322 °C
Cp	1.155375
Temperature	86.1866 °C
Cp	1.154604
Temperature	87.15999 °C
Cp	1.153869
Temperature	88.13337 °C
Cp	1.153158
Temperature	89.10676 °C
Cp	1.152474
Temperature	90.08015 °C
Cp	1.15181
Temperature	91.05353 °C
Cp	1.151134
Temperature	92.02692 °C
Cp	1.150513
Temperature	93.00031 °C
Cp	1.149892
Temperature	93.97369 °C
Cp	1.149266
Temperature	94.94707 °C
Cp	1.148642
Temperature	95.92046 °C
Cp	1.148019
Temperature	96.89384 °C
Cp	1.147402
Temperature	97.86723 °C
Cp	1.146799
Temperature	98.84062 °C
Cp	1.146191
Temperature	99.814 °C
Cp	1.145602
Temperature	100.7874 °C
Cp	1.14503
Temperature	101.7608 °C
Cp	1.144469
Temperature	102.7342 °C
Cp	1.143921
Temperature	103.7076 °C
Cp	1.143383
Temperature	104.6809 °C
Cp	1.142861
Temperature	105.6543 °C
Cp	1.142345
Temperature	106.6277 °C
Cp	1.141835
Temperature	107.6011 °C
Cp	1.141335
Temperature	108.5745 °C
Cp	1.140846
Temperature	109.5479 °C
Cp	1.140365
Temperature	110.5212 °C
Cp	1.139891
Temperature	111.4946 °C
Cp	1.139429
Temperature	112.468 °C
Cp	1.138976
Temperature	113.4414 °C
Cp	1.13853
Temperature	114.4148 °C
Cp	1.138092
Temperature	115.3882 °C
Cp	1.137654
Temperature	116.3616 °C
Cp	1.137223
Temperature	117.335 °C
Cp	1.136785
Temperature	118.3083 °C
Cp	1.136338
Temperature	119.2817 °C
Cp	1.13588
Temperature	120.2551 °C
Cp	1.13541
Temperature	121.2285 °C
Cp	1.134927
Temperature	122.2019 °C
Cp	1.134417
Temperature	123.1753 °C
Cp	1.133892
Temperature	124.1487 °C
Cp	1.133347
Temperature	125.122 °C
Cp	1.132786
Temperature	126.0954 °C
Cp	1.132206
Temperature	127.0688 °C
Cp	1.131606
Temperature	128.0422 °C
Cp	1.130999
Temperature	129.0156 °C
Cp	1.130384
Temperature	129.989 °C
Cp	1.129765
Temperature	130.9624 °C
Cp	1.129147
Temperature	131.9357 °C
Cp	1.12854
Temperature	132.9091 °C
Cp	1.127949
Temperature	133.8825 °C
Cp	1.127383
Temperature	134.8559 °C
Cp	1.126841
Temperature	135.8293 °C
Cp	1.126334
Temperature	136.8027 °C
Cp	1.125871
Temperature	137.7761 °C
Cp	1.125443
Temperature	138.7494 °C
Cp	1.125058
Temperature	139.7228 °C
Cp	1.124701
Temperature	140.6962 °C
Cp	1.124397
Temperature	141.6696 °C
Cp	1.124114
Temperature	142.643 °C
Cp	1.123854
Temperature	143.6164 °C
Cp	1.123612
Temperature	144.5898 °C
Cp	1.123385
Temperature	145.5631 °C
Cp	1.123182
Temperature	146.5365 °C
Cp	1.12296
Temperature	147.5099 °C
Cp	1.12275
Temperature	148.4833 °C
Cp	1.122543
Temperature	149.4567 °C
Cp	1.122327
Temperature	150.4301 °C
Cp	1.122099
Temperature	151.4035 °C
Cp	1.121837
Temperature	152.3768 °C
Cp	1.121582
Temperature	153.3502 °C
Cp	1.121289
Temperature	154.3236 °C
Cp	1.120967
Temperature	155.297 °C
Cp	1.120616
Temperature	156.2704 °C
Cp	1.120238
Temperature	157.2438 °C
Cp	1.119862
Temperature	158.2172 °C
Cp	1.119444
Temperature	159.1906 °C
Cp	1.119028
Temperature	160.1639 °C
Cp	1.118613
Temperature	161.1373 °C
Cp	1.118202
Temperature	162.1107 °C
Cp	1.117795
Temperature	163.0841 °C
Cp	1.117374
Temperature	164.0575 °C
Cp	1.116987
Temperature	165.0309 °C
Cp	1.116595
Temperature	166.0042 °C
Cp	1.116198
Temperature	166.9776 °C
Cp	1.1158
Temperature	167.951 °C
Cp	1.115402
Temperature	168.9244 °C
Cp	1.115006
Temperature	169.8978 °C
Cp	1.11462
Temperature	170.8712 °C
Cp	1.114223
Temperature	171.8446 °C
Cp	1.113836
Temperature	172.8179 °C
Cp	1.113458
Temperature	173.7913 °C
Cp	1.113085
Temperature	174.7647 °C
Cp	1.112712
Temperature	175.7381 °C
Cp	1.112323
Temperature	176.7115 °C
Cp	1.111957
Temperature	177.6849 °C
Cp	1.111578
Temperature	178.6583 °C
Cp	1.111185
Temperature	179.6317 °C
Cp	1.110789
Temperature	180.605 °C
Cp	1.110391
Temperature	181.5784 °C
Cp	1.110016
Temperature	182.5518 °C
Cp	1.109611
Temperature	183.5252 °C
Cp	1.109232
Temperature	184.4986 °C
Cp	1.108873
Temperature	185.472 °C
Cp	1.108531
Temperature	186.4454 °C
Cp	1.108199
Temperature	187.4187 °C
Cp	1.107851
Temperature	188.3921 °C
Cp	1.107551
Temperature	189.3655 °C
Cp	1.107238
Temperature	190.3389 °C
Cp	1.106917
Temperature	191.3123 °C
Cp	1.106589
Temperature	192.2857 °C
Cp	1.106259
Temperature	193.259 °C
Cp	1.105958
Temperature	194.2324 °C
Cp	1.105619
Temperature	195.2058 °C
Cp	1.105301
Temperature	196.1792 °C
Cp	1.105002
Temperature	197.1526 °C
Cp	1.104718
Temperature	198.126 °C
Cp	1.104445
Temperature	199.0994 °C
Cp	1.104161
Temperature	200.0728 °C
Cp	1.103914
Temperature	201.0461 °C
Cp	1.103657
Temperature	202.0195 °C
Cp	1.103395
Temperature	202.9929 °C
Cp	1.103125
Temperature	203.9663 °C
Cp	1.102847
Temperature	204.9397 °C
Cp	1.102563
Temperature	205.9131 °C
Cp	1.102283
Temperature	206.8865 °C
Cp	1.101985
Temperature	207.8598 °C
Cp	1.10169
Temperature	208.8332 °C
Cp	1.101394
Temperature	209.8066 °C
Cp	1.101099
Temperature	210.78 °C
Cp	1.1008
Temperature	211.7534 °C
Cp	1.10049
Temperature	212.7268 °C
Cp	1.100193
Temperature	213.7002 °C
Cp	1.099886
Temperature	214.6735 °C
Cp	1.099577
Temperature	215.6469 °C
Cp	1.099268
Temperature	216.6203 °C
Cp	1.098965
Temperature	217.5937 °C
Cp	1.098685
Temperature	218.5671 °C
Cp	1.098396
Temperature	219.5405 °C
Cp	1.098134
Temperature	220.5139 °C
Cp	1.097895
Temperature	221.4872 °C
Cp	1.09768
Temperature	222.4606 °C
Cp	1.097485
Temperature	223.434 °C
Cp	1.097292
Temperature	224.4074 °C
Cp	1.09714
Temperature	225.3808 °C
Cp	1.096991
Temperature	226.3542 °C
Cp	1.096844
Temperature	227.3276 °C
Cp	1.096699
Temperature	228.3009 °C
Cp	1.096559
Temperature	229.2743 °C
Cp	1.096442
Temperature	230.2477 °C
Cp	1.096296
Temperature	231.2211 °C
Cp	1.096164
Temperature	232.1945 °C
Cp	1.09604
Temperature	233.1679 °C
Cp	1.095924
Temperature	234.1413 °C
Cp	1.095807
Temperature	235.1147 °C
Cp	1.095665
Temperature	236.088 °C
Cp	1.095557
Temperature	237.0614 °C
Cp	1.095433
Temperature	238.0348 °C
Cp	1.095296
Temperature	239.0082 °C
Cp	1.095147
Temperature	239.9816 °C
Cp	1.094995
Temperature	240.955 °C
Cp	1.094843
Temperature	241.9283 °C
Cp	1.094705
Temperature	242.9017 °C
Cp	1.094562
Temperature	243.8751 °C
Cp	1.094442
Temperature	244.8485 °C
Cp	1.094344
Temperature	245.8219 °C
Cp	1.094266
Temperature	246.7953 °C
Cp	1.094209
Temperature	247.7687 °C
Cp	1.094161
Temperature	248.7421 °C
Cp	1.094144
Temperature	249.7154 °C
Cp	1.094133
Temperature	250.6888 °C
Cp	1.094127
Temperature	251.6622 °C
Cp	1.094126
Temperature	252.6356 °C
Cp	1.094127
Temperature	253.609 °C
Cp	1.094138
Temperature	254.5824 °C
Cp	1.09413
Temperature	255.5558 °C
Cp	1.094123
Temperature	256.5291 °C
Cp	1.094111
Temperature	257.5025 °C
Cp	1.094087
Temperature	258.4759 °C
Cp	1.094046
Temperature	259.4493 °C
Cp	1.093978
Temperature	260.4227 °C
Cp	1.093895
Temperature	261.3961 °C
Cp	1.093783
Temperature	262.3694 °C
Cp	1.093645
Temperature	263.3428 °C
Cp	1.093483
Temperature	264.3162 °C
Cp	1.093302
Temperature	265.2896 °C
Cp	1.093109
Temperature	266.263 °C
Cp	1.092906
Temperature	267.2364 °C
Cp	1.092704
Temperature	268.2098 °C
Cp	1.092511
Temperature	269.1832 °C
Cp	1.092331
Temperature	270.1566 °C
Cp	1.092174
Temperature	271.1299 °C
Cp	1.092046
Temperature	272.1033 °C
Cp	1.091947
Temperature	273.0767 °C
Cp	1.091882
Temperature	274.0501 °C
Cp	1.091853
Temperature	275.0235 °C
Cp	1.091859
Temperature	275.9969 °C
Cp	1.091895
Temperature	276.9702 °C
Cp	1.091957
Temperature	277.9436 °C
Cp	1.092036
Temperature	278.917 °C
Cp	1.092132
Temperature	279.8904 °C
Cp	1.09223
Temperature	280.8638 °C
Cp	1.092323
Temperature	281.8372 °C
Cp	1.092405
Temperature	282.8105 °C
Cp	1.092468
Temperature	283.7839 °C
Cp	1.092513
Temperature	284.7573 °C
Cp	1.092525
Temperature	285.7307 °C
Cp	1.092512
Temperature	286.7041 °C
Cp	1.092472
Temperature	287.6775 °C
Cp	1.092405
Temperature	288.6509 °C
Cp	1.092313
Temperature	289.6243 °C
Cp	1.092197
Temperature	290.5977 °C
Cp	1.09207
Temperature	291.571 °C
Cp	1.091931
Temperature	292.5444 °C
Cp	1.091785
Temperature	293.5178 °C
Cp	1.091641
Temperature	294.4912 °C
Cp	1.091506
Temperature	295.4646 °C
Cp	1.091387
Temperature	296.438 °C
Cp	1.091282
Temperature	297.4113 °C
Cp	1.091201
Temperature	298.3847 °C
Cp	1.091145
Temperature	299.3581 °C
Cp	1.091112
Temperature	300.3315 °C
Cp	1.091102
Temperature	301.3049 °C
Cp	1.091107
Temperature	302.2783 °C
Cp	1.091137
Temperature	303.2517 °C
Cp	1.091177
Temperature	304.2251 °C
Cp	1.091226
Temperature	305.1984 °C
Cp	1.09128
Temperature	306.1718 °C
Cp	1.091336
Temperature	307.1452 °C
Cp	1.091403
Temperature	308.1186 °C
Cp	1.091453
Temperature	309.092 °C
Cp	1.091506
Temperature	310.0654 °C
Cp	1.091561
Temperature	311.0388 °C
Cp	1.091617
Temperature	312.0121 °C
Cp	1.09167
Temperature	312.9855 °C
Cp	1.091716
Temperature	313.9589 °C
Cp	1.091762
Temperature	314.9323 °C
Cp	1.091805
Temperature	315.9057 °C
Cp	1.091838
Temperature	316.8791 °C
Cp	1.09186
Temperature	317.8524 °C
Cp	1.091871
Temperature	318.8258 °C
Cp	1.091872
Temperature	319.7992 °C
Cp	1.091867
Temperature	320.7726 °C
Cp	1.091838
Temperature	321.746 °C
Cp	1.0918
Temperature	322.7194 °C
Cp	1.091752
Temperature	323.6928 °C
Cp	1.091689
Temperature	324.6662 °C
Cp	1.091611
Temperature	325.6396 °C
Cp	1.091508
Temperature	326.6129 °C
Cp	1.091406
Temperature	327.5863 °C
Cp	1.091285
Temperature	328.5597 °C
Cp	1.09115
Temperature	329.5331 °C
Cp	1.091009
Temperature	330.5065 °C
Cp	1.09087
Temperature	331.4799 °C
Cp	1.090747
Temperature	332.4532 °C
Cp	1.090628
Temperature	333.4266 °C
Cp	1.090536
Temperature	334.4 °C
Cp	1.090472
Temperature	335.3734 °C
Cp	1.090437
Temperature	336.3468 °C
Cp	1.090431
Temperature	337.3202 °C
Cp	1.090455
Temperature	338.2935 °C
Cp	1.090503
Temperature	339.2669 °C
Cp	1.090573
Temperature	340.2403 °C
Cp	1.090658
Temperature	341.2137 °C
Cp	1.090753
Temperature	342.1871 °C
Cp	1.090853
Temperature	343.1605 °C
Cp	1.090952
Temperature	344.1339 °C
Cp	1.09105
Temperature	345.1073 °C
Cp	1.091141
Temperature	346.0807 °C
Cp	1.091225
Temperature	347.054 °C
Cp	1.091303
Temperature	348.0274 °C
Cp	1.091379
Temperature	349.0008 °C
Cp	1.091453
Temperature	349.9742 °C
Cp	1.091537
Temperature	350.9476 °C
Cp	1.091633
Temperature	351.921 °C
Cp	1.091743
Temperature	352.8943 °C
Cp	1.091874
Temperature	353.8677 °C
Cp	1.092028
Temperature	354.8411 °C
Cp	1.092206
Temperature	355.8145 °C
Cp	1.092411
Temperature	356.7879 °C
Cp	1.092628
Temperature	357.7613 °C
Cp	1.092862
Temperature	358.7346 °C
Cp	1.093102
Temperature	359.708 °C
Cp	1.093338
Temperature	360.6814 °C
Cp	1.093559
Temperature	361.6548 °C
Cp	1.093752
Temperature	362.6282 °C
Cp	1.093915
Temperature	363.6016 °C
Cp	1.094036
Temperature	364.575 °C
Cp	1.094117
Temperature	365.5484 °C
Cp	1.094159
Temperature	366.5218 °C
Cp	1.094172
Temperature	367.4951 °C
Cp	1.094165
Temperature	368.4685 °C
Cp	1.094163
Temperature	369.4419 °C
Cp	1.094182
Temperature	370.4153 °C
Cp	1.094244
Temperature	371.3887 °C
Cp	1.094375
Temperature	372.3621 °C
Cp	1.094598
Temperature	373.3354 °C
Cp	1.094937
Temperature	374.3088 °C
Cp	1.095389
Temperature	375.2822 °C
Cp	1.095973
Temperature	376.2556 °C
Cp	1.096685
Temperature	377.229 °C
Cp	1.097506
Temperature	378.2024 °C
Cp	1.098406
Temperature	379.1758 °C
Cp	1.099338
Temperature	380.1492 °C
Cp	1.10027
Temperature	381.1225 °C
Cp	1.10112
Temperature	382.0959 °C
Cp	1.101818
Temperature	383.0693 °C
Cp	1.10229
Temperature	384.0427 °C
Cp	1.102459
Temperature	385.0161 °C
Cp	1.102253
Temperature	385.9895 °C
Cp	1.101596
Temperature	386.9629 °C
Cp	1.100438
Temperature	387.9362 °C
Cp	1.098736
Temperature	388.9096 °C
Cp	1.096461
Temperature	389.883 °C
Cp	1.093614
Temperature	390.8564 °C
Cp	1.090208
Temperature	391.8298 °C
Cp	1.086278
Temperature	392.8032 °C
Cp	1.081887
Temperature	393.7766 °C
Cp	1.077096
Temperature	394.7499 °C
Cp	1.072007
Temperature	395.7233 °C
Cp	1.066707
[Rev Cp Calibration]
Date Applied	24/10/2024 12:37:31
Description	From -89.998 °C to 390.542 °C at 2.000°C/min
Gas Type	Nitrogen
Pan Type	Tzero Aluminum
Source Files 1	C:\ProgramData\TA Instruments\TRIOS\Data\Reverse Heat Capacity Calibration(6).tri
GUID	ba867d72-cfbb-486e-971e-e86aa544cc02
Temperature	-89.99799 °C
Cp	1.070076
Temperature	-89.03691 °C
Cp	1.072008
Temperature	-88.07584 °C
Cp	1.073556
Temperature	-87.11475 °C
Cp	1.074743
Temperature	-86.15367 °C
Cp	1.075597
Temperature	-85.1926 °C
Cp	1.076163
Temperature	-84.23151 °C
Cp	1.076477
Temperature	-83.27043 °C
Cp	1.076579
Temperature	-82.30936 °C
Cp	1.076527
Temperature	-81.34827 °C
Cp	1.076322
Temperature	-80.38719 °C
Cp	1.076039
Temperature	-79.42612 °C
Cp	1.07571
Temperature	-78.46503 °C
Cp	1.075361
Temperature	-77.50395 °C
Cp	1.075011
Temperature	-76.54288 °C
Cp	1.074656
Temperature	-75.58179 °C
Cp	1.074359
Temperature	-74.62071 °C
Cp	1.074086
Temperature	-73.65964 °C
Cp	1.073842
Temperature	-72.69855 °C
Cp	1.073627
Temperature	-71.73747 °C
Cp	1.073442
Temperature	-70.7764 °C
Cp	1.07329
Temperature	-69.81532 °C
Cp	1.073148
Temperature	-68.85423 °C
Cp	1.073021
Temperature	-67.89315 °C
Cp	1.072902
Temperature	-66.93208 °C
Cp	1.072782
Temperature	-65.97099 °C
Cp	1.072656
Temperature	-65.00991 °C
Cp	1.072518
Temperature	-64.04884 °C
Cp	1.072374
Temperature	-63.08775 °C
Cp	1.072201
Temperature	-62.12667 °C
Cp	1.072019
Temperature	-61.1656 °C
Cp	1.071827
Temperature	-60.20451 °C
Cp	1.071624
Temperature	-59.24343 °C
Cp	1.071411
Temperature	-58.28236 °C
Cp	1.071167
Temperature	-57.32127 °C
Cp	1.070956
Temperature	-56.3602 °C
Cp	1.070724
Temperature	-55.39911 °C
Cp	1.070483
Temperature	-54.43803 °C
Cp	1.070242
Temperature	-53.47696 °C
Cp	1.070009
Temperature	-52.51587 °C
Cp	1.069825
Temperature	-51.55479 °C
Cp	1.069601
Temperature	-50.59372 °C
Cp	1.069418
Temperature	-49.63263 °C
Cp	1.069267
Temperature	-48.67155 °C
Cp	1.069138
Temperature	-47.71048 °C
Cp	1.069021
Temperature	-46.74939 °C
Cp	1.068875
Temperature	-45.78831 °C
Cp	1.068771
Temperature	-44.82724 °C
Cp	1.068634
Temperature	-43.86615 °C
Cp	1.068462
Temperature	-42.90508 °C
Cp	1.068255
Temperature	-41.944 °C
Cp	1.068012
Temperature	-40.98291 °C
Cp	1.067742
Temperature	-40.02184 °C
Cp	1.067427
Temperature	-39.06076 °C
Cp	1.067088
Temperature	-38.09967 °C
Cp	1.066727
Temperature	-37.1386 °C
Cp	1.066349
Temperature	-36.17752 °C
Cp	1.065958
Temperature	-35.21643 °C
Cp	1.065559
Temperature	-34.25536 °C
Cp	1.065162
Temperature	-33.29427 °C
Cp	1.06476
Temperature	-32.33319 °C
Cp	1.064368
Temperature	-31.37212 °C
Cp	1.06399
Temperature	-30.41104 °C
Cp	1.063628
Temperature	-29.44995 °C
Cp	1.063283
Temperature	-28.48887 °C
Cp	1.06295
Temperature	-27.5278 °C
Cp	1.062645
Temperature	-26.56672 °C
Cp	1.062355
Temperature	-25.60563 °C
Cp	1.06208
Temperature	-24.64456 °C
Cp	1.061819
Temperature	-23.68348 °C
Cp	1.061573
Temperature	-22.72239 °C
Cp	1.061345
Temperature	-21.76132 °C
Cp	1.061123
Temperature	-20.80024 °C
Cp	1.060915
Temperature	-19.83916 °C
Cp	1.060719
Temperature	-18.87807 °C
Cp	1.060531
Temperature	-17.917 °C
Cp	1.06035
Temperature	-16.95592 °C
Cp	1.060161
Temperature	-15.99484 °C
Cp	1.059992
Temperature	-15.03376 °C
Cp	1.059817
Temperature	-14.07268 °C
Cp	1.059634
Temperature	-13.1116 °C
Cp	1.059445
Temperature	-12.15052 °C
Cp	1.059248
Temperature	-11.18944 °C
Cp	1.059043
Temperature	-10.22836 °C
Cp	1.058842
Temperature	-9.267276 °C
Cp	1.058615
Temperature	-8.306196 °C
Cp	1.058388
Temperature	-7.345116 °C
Cp	1.058155
Temperature	-6.384036 °C
Cp	1.057911
Temperature	-5.422956 °C
Cp	1.057652
Temperature	-4.461876 °C
Cp	1.057356
Temperature	-3.500796 °C
Cp	1.057063
Temperature	-2.539716 °C
Cp	1.056732
Temperature	-1.578636 °C
Cp	1.056364
Temperature	-0.6175562 °C
Cp	1.05596
Temperature	0.3435238 °C
Cp	1.055523
Temperature	1.304604 °C
Cp	1.055066
Temperature	2.265684 °C
Cp	1.054561
Temperature	3.226764 °C
Cp	1.054035
Temperature	4.187844 °C
Cp	1.053488
Temperature	5.148924 °C
Cp	1.052922
Temperature	6.110003 °C
Cp	1.052337
Temperature	7.071084 °C
Cp	1.051736
Temperature	8.032164 °C
Cp	1.051118
Temperature	8.993243 °C
Cp	1.050488
Temperature	9.954324 °C
Cp	1.049848
Temperature	10.9154 °C
Cp	1.049202
Temperature	11.87648 °C
Cp	1.048552
Temperature	12.83756 °C
Cp	1.047902
Temperature	13.79864 °C
Cp	1.047255
Temperature	14.75972 °C
Cp	1.046615
Temperature	15.7208 °C
Cp	1.045983
Temperature	16.68188 °C
Cp	1.045362
Temperature	17.64296 °C
Cp	1.044756
Temperature	18.60404 °C
Cp	1.044164
Temperature	19.56512 °C
Cp	1.04358
Temperature	20.5262 °C
Cp	1.043027
Temperature	21.48728 °C
Cp	1.042485
Temperature	22.44836 °C
Cp	1.041958
Temperature	23.40944 °C
Cp	1.041446
Temperature	24.37052 °C
Cp	1.040952
Temperature	25.3316 °C
Cp	1.040493
Temperature	26.29268 °C
Cp	1.040022
Temperature	27.25376 °C
Cp	1.039578
Temperature	28.21484 °C
Cp	1.039158
Temperature	29.17592 °C
Cp	1.038758
Temperature	30.137 °C
Cp	1.038373
Temperature	31.09808 °C
Cp	1.037981
Temperature	32.05916 °C
Cp	1.03763
Temperature	33.02024 °C
Cp	1.037276
Temperature	33.98132 °C
Cp	1.03692
Temperature	34.9424 °C
Cp	1.036565
Temperature	35.90348 °C
Cp	1.036213
Temperature	36.86456 °C
Cp	1.035866
Temperature	37.82564 °C
Cp	1.035529
Temperature	38.78672 °C
Cp	1.035195
Temperature	39.7478 °C
Cp	1.034875
Temperature	40.70888 °C
Cp	1.034568
Temperature	41.66996 °C
Cp	1.034276
Temperature	42.63104 °C
Cp	1.033996
Temperature	43.59212 °C
Cp	1.033726
Temperature	44.5532 °C
Cp	1.033469
Temperature	45.51428 °C
Cp	1.033221
Temperature	46.47536 °C
Cp	1.03298
Temperature	47.43644 °C
Cp	1.032744
Temperature	48.39752 °C
Cp	1.032514
Temperature	49.3586 °C
Cp	1.032289
Temperature	50.31968 °C
Cp	1.032065
Temperature	51.28076 °C
Cp	1.031844
Temperature	52.24184 °C
Cp	1.031627
Temperature	53.20292 °C
Cp	1.031413
Temperature	54.164 °C
Cp	1.031203
Temperature	55.12508 °C
Cp	1.030989
Temperature	56.08616 °C
Cp	1.030791
Temperature	57.04724 °C
Cp	1.030595
Temperature	58.00832 °C
Cp	1.030403
Temperature	58.9694 °C
Cp	1.030217
Temperature	59.93048 °C
Cp	1.03004
Temperature	60.89156 °C
Cp	1.029871
Temperature	61.85264 °C
Cp	1.029718
Temperature	62.81372 °C
Cp	1.029567
Temperature	63.7748 °C
Cp	1.02943
Temperature	64.73589 °C
Cp	1.029304
Temperature	65.69696 °C
Cp	1.029185
Temperature	66.65804 °C
Cp	1.02907
Temperature	67.61913 °C
Cp	1.028946
Temperature	68.5802 °C
Cp	1.028831
Temperature	69.54128 °C
Cp	1.028703
Temperature	70.50237 °C
Cp	1.028561
Temperature	71.46344 °C
Cp	1.028404
Temperature	72.42452 °C
Cp	1.028234
Temperature	73.3856 °C
Cp	1.028063
Temperature	74.34668 °C
Cp	1.027861
Temperature	75.30776 °C
Cp	1.027657
Temperature	76.26884 °C
Cp	1.027451
Temperature	77.22992 °C
Cp	1.027243
Temperature	78.191 °C
Cp	1.027036
Temperature	79.15208 °C
Cp	1.026812
Temperature	80.11316 °C
Cp	1.026623
Temperature	81.07424 °C
Cp	1.026431
Temperature	82.03532 °C
Cp	1.026241
Temperature	82.9964 °C
Cp	1.02606
Temperature	83.95748 °C
Cp	1.025891
Temperature	84.91856 °C
Cp	1.025739
Temperature	85.87964 °C
Cp	1.025614
Temperature	86.84072 °C
Cp	1.025493
Temperature	87.8018 °C
Cp	1.0254
Temperature	88.76288 °C
Cp	1.025329
Temperature	89.72396 °C
Cp	1.025274
Temperature	90.68504 °C
Cp	1.025229
Temperature	91.64612 °C
Cp	1.025174
Temperature	92.6072 °C
Cp	1.025138
Temperature	93.56828 °C
Cp	1.025083
Temperature	94.52936 °C
Cp	1.025008
Temperature	95.49044 °C
Cp	1.024912
Temperature	96.45152 °C
Cp	1.024796
Temperature	97.4126 °C
Cp	1.024671
Temperature	98.37368 °C
Cp	1.024506
Temperature	99.33476 °C
Cp	1.02433
Temperature	100.2958 °C
Cp	1.024144
Temperature	101.2569 °C
Cp	1.023948
Temperature	102.218 °C
Cp	1.023743
Temperature	103.1791 °C
Cp	1.023522
Temperature	104.1402 °C
Cp	1.023309
Temperature	105.1012 °C
Cp	1.023089
Temperature	106.0623 °C
Cp	1.022866
Temperature	107.0234 °C
Cp	1.022644
Temperature	107.9845 °C
Cp	1.022427
Temperature	108.9456 °C
Cp	1.022218
Temperature	109.9066 °C
Cp	1.022022
Temperature	110.8677 °C
Cp	1.021836
Temperature	111.8288 °C
Cp	1.021666
Temperature	112.7899 °C
Cp	1.021512
Temperature	113.751 °C
Cp	1.021374
Temperature	114.712 °C
Cp	1.02125
Temperature	115.6731 °C
Cp	1.021137
Temperature	116.6342 °C
Cp	1.021041
Temperature	117.5953 °C
Cp	1.020953
Temperature	118.5564 °C
Cp	1.020872
Temperature	119.5174 °C
Cp	1.020796
Temperature	120.4785 °C
Cp	1.020725
Temperature	121.4396 °C
Cp	1.020659
Temperature	122.4007 °C
Cp	1.020587
Temperature	123.3618 °C
Cp	1.020515
Temperature	124.3228 °C
Cp	1.02044
Temperature	125.2839 °C
Cp	1.020359
Temperature	126.245 °C
Cp	1.02027
Temperature	127.2061 °C
Cp	1.020167
Temperature	128.1672 °C
Cp	1.020057
Temperature	129.1282 °C
Cp	1.019933
Temperature	130.0893 °C
Cp	1.019793
Temperature	131.0504 °C
Cp	1.019638
Temperature	132.0115 °C
Cp	1.019471
Temperature	132.9726 °C
Cp	1.019292
Temperature	133.9336 °C
Cp	1.019107
Temperature	134.8947 °C
Cp	1.018912
Temperature	135.8558 °C
Cp	1.018717
Temperature	136.8169 °C
Cp	1.018527
Temperature	137.778 °C
Cp	1.018344
Temperature	138.739 °C
Cp	1.018171
Temperature	139.7001 °C
Cp	1.018004
Temperature	140.6612 °C
Cp	1.01787
Temperature	141.6223 °C
Cp	1.01775
Temperature	142.5834 °C
Cp	1.017652
Temperature	143.5444 °C
Cp	1.017578
Temperature	144.5055 °C
Cp	1.017534
Temperature	145.4666 °C
Cp	1.017536
Temperature	146.4277 °C
Cp	1.017545
Temperature	147.3888 °C
Cp	1.017595
Temperature	148.3498 °C
Cp	1.017679
Temperature	149.3109 °C
Cp	1.01779
Temperature	150.272 °C
Cp	1.01792
Temperature	151.2331 °C
Cp	1.018043
Temperature	152.1942 °C
Cp	1.018199
Temperature	153.1552 °C
Cp	1.018339
Temperature	154.1163 °C
Cp	1.018458
Temperature	155.0774 °C
Cp	1.018552
Temperature	156.0385 °C
Cp	1.018618
Temperature	156.9996 °C
Cp	1.018662
Temperature	157.9606 °C
Cp	1.018664
Temperature	158.9217 °C
Cp	1.018632
Temperature	159.8828 °C
Cp	1.018575
Temperature	160.8439 °C
Cp	1.018492
Temperature	161.805 °C
Cp	1.018383
Temperature	162.766 °C
Cp	1.01825
Temperature	163.7271 °C
Cp	1.018087
Temperature	164.6882 °C
Cp	1.017917
Temperature	165.6493 °C
Cp	1.017726
Temperature	166.6104 °C
Cp	1.017522
Temperature	167.5714 °C
Cp	1.01731
Temperature	168.5325 °C
Cp	1.017098
Temperature	169.4936 °C
Cp	1.016902
Temperature	170.4547 °C
Cp	1.016695
Temperature	171.4158 °C
Cp	1.016508
Temperature	172.3768 °C
Cp	1.016342
Temperature	173.3379 °C
Cp	1.016195
Temperature	174.299 °C
Cp	1.016065
Temperature	175.2601 °C
Cp	1.015927
Temperature	176.2212 °C
Cp	1.015838
Temperature	177.1822 °C
Cp	1.015746
Temperature	178.1433 °C
Cp	1.015651
Temperature	179.1044 °C
Cp	1.015555
Temperature	180.0655 °C
Cp	1.015459
Temperature	181.0266 °C
Cp	1.015401
Temperature	181.9876 °C
Cp	1.015288
Temperature	182.9487 °C
Cp	1.015195
Temperature	183.9098 °C
Cp	1.015117
Temperature	184.8709 °C
Cp	1.01505
Temperature	185.832 °C
Cp	1.014988
Temperature	186.793 °C
Cp	1.014927
Temperature	187.7541 °C
Cp	1.014849
Temperature	188.7152 °C
Cp	1.014789
Temperature	189.6763 °C
Cp	1.01471
Temperature	190.6374 °C
Cp	1.014614
Temperature	191.5984 °C
Cp	1.014503
Temperature	192.5595 °C
Cp	1.014381
Temperature	193.5206 °C
Cp	1.014268
Temperature	194.4817 °C
Cp	1.014122
Temperature	195.4428 °C
Cp	1.013984
Temperature	196.4038 °C
Cp	1.013853
Temperature	197.3649 °C
Cp	1.013726
Temperature	198.326 °C
Cp	1.013603
Temperature	199.2871 °C
Cp	1.013467
Temperature	200.2482 °C
Cp	1.013359
Temperature	201.2092 °C
Cp	1.013243
Temperature	202.1703 °C
Cp	1.013123
Temperature	203.1314 °C
Cp	1.013002
Temperature	204.0925 °C
Cp	1.012884
Temperature	205.0536 °C
Cp	1.012788
Temperature	206.0146 °C
Cp	1.012674
Temperature	206.9757 °C
Cp	1.012579
Temperature	207.9368 °C
Cp	1.012501
Temperature	208.8979 °C
Cp	1.012439
Temperature	209.859 °C
Cp	1.012389
Temperature	210.82 °C
Cp	1.012351
Temperature	211.7811 °C
Cp	1.012312
Temperature	212.7422 °C
Cp	1.01229
Temperature	213.7033 °C
Cp	1.012262
Temperature	214.6644 °C
Cp	1.012227
Temperature	215.6254 °C
Cp	1.012183
Temperature	216.5865 °C
Cp	1.012129
Temperature	217.5476 °C
Cp	1.012077
Temperature	218.5087 °C
Cp	1.01199
Temperature	219.4698 °C
Cp	1.011897
Temperature	220.4308 °C
Cp	1.011793
Temperature	221.3919 °C
Cp	1.011674
Temperature	222.353 °C
Cp	1.011537
Temperature	223.3141 °C
Cp	1.011362
Temperature	224.2752 °C
Cp	1.011194
Temperature	225.2362 °C
Cp	1.010993
Temperature	226.1973 °C
Cp	1.010766
Temperature	227.1584 °C
Cp	1.010517
Temperature	228.1195 °C
Cp	1.010251
Temperature	229.0806 °C
Cp	1.009998
Temperature	230.0416 °C
Cp	1.009703
Temperature	231.0027 °C
Cp	1.009422
Temperature	231.9638 °C
Cp	1.009156
Temperature	232.9249 °C
Cp	1.008906
Temperature	233.886 °C
Cp	1.008675
Temperature	234.847 °C
Cp	1.008462
Temperature	235.8081 °C
Cp	1.008258
Temperature	236.7692 °C
Cp	1.00809
Temperature	237.7303 °C
Cp	1.007934
Temperature	238.6914 °C
Cp	1.007793
Temperature	239.6524 °C
Cp	1.007668
Temperature	240.6135 °C
Cp	1.007562
Temperature	241.5746 °C
Cp	1.007487
Temperature	242.5357 °C
Cp	1.00741
Temperature	243.4967 °C
Cp	1.00736
Temperature	244.4578 °C
Cp	1.007332
Temperature	245.4189 °C
Cp	1.007321
Temperature	246.38 °C
Cp	1.007321
Temperature	247.3411 °C
Cp	1.007312
Temperature	248.3022 °C
Cp	1.007331
Temperature	249.2632 °C
Cp	1.007338
Temperature	250.2243 °C
Cp	1.007335
Temperature	251.1854 °C
Cp	1.00732
Temperature	252.1465 °C
Cp	1.007295
Temperature	253.1076 °C
Cp	1.007277
Temperature	254.0686 °C
Cp	1.007227
Temperature	255.0297 °C
Cp	1.007179
Temperature	255.9908 °C
Cp	1.007133
Temperature	256.9519 °C
Cp	1.00709
Temperature	257.913 °C
Cp	1.007049
Temperature	258.874 °C
Cp	1.007012
Temperature	259.8351 °C
Cp	1.006978
Temperature	260.7962 °C
Cp	1.006956
Temperature	261.7573 °C
Cp	1.00694
Temperature	262.7184 °C
Cp	1.006934
Temperature	263.6794 °C
Cp	1.006939
Temperature	264.6405 °C
Cp	1.00696
Temperature	265.6016 °C
Cp	1.006999
Temperature	266.5627 °C
Cp	1.007054
Temperature	267.5237 °C
Cp	1.007131
Temperature	268.4848 °C
Cp	1.00723
Temperature	269.4459 °C
Cp	1.00735
Temperature	270.407 °C
Cp	1.007493
Temperature	271.3681 °C
Cp	1.007656
Temperature	272.3292 °C
Cp	1.007839
Temperature	273.2902 °C
Cp	1.008039
Temperature	274.2513 °C
Cp	1.008257
Temperature	275.2124 °C
Cp	1.008488
Temperature	276.1735 °C
Cp	1.008731
Temperature	277.1346 °C
Cp	1.008977
Temperature	278.0956 °C
Cp	1.009237
Temperature	279.0567 °C
Cp	1.009498
Temperature	280.0178 °C
Cp	1.009757
Temperature	280.9789 °C
Cp	1.010014
Temperature	281.9399 °C
Cp	1.010267
Temperature	282.901 °C
Cp	1.010515
Temperature	283.8621 °C
Cp	1.01076
Temperature	284.8232 °C
Cp	1.010993
Temperature	285.7843 °C
Cp	1.011222
Temperature	286.7454 °C
Cp	1.011447
Temperature	287.7064 °C
Cp	1.011665
Temperature	288.6675 °C
Cp	1.011876
Temperature	289.6286 °C
Cp	1.012079
Temperature	290.5897 °C
Cp	1.01228
Temperature	291.5508 °C
Cp	1.012474
Temperature	292.5118 °C
Cp	1.012662
Temperature	293.4729 °C
Cp	1.012846
Temperature	294.434 °C
Cp	1.013028
Temperature	295.3951 °C
Cp	1.013211
Temperature	296.3561 °C
Cp	1.013391
Temperature	297.3172 °C
Cp	1.013574
Temperature	298.2783 °C
Cp	1.013759
Temperature	299.2394 °C
Cp	1.013947
Temperature	300.2005 °C
Cp	1.014136
Temperature	301.1616 °C
Cp	1.01432
Temperature	302.1226 °C
Cp	1.014511
Temperature	303.0837 °C
Cp	1.014695
Temperature	304.0448 °C
Cp	1.014872
Temperature	305.0059 °C
Cp	1.01504
Temperature	305.9669 °C
Cp	1.015198
Temperature	306.928 °C
Cp	1.015343
Temperature	307.8891 °C
Cp	1.015479
Temperature	308.8502 °C
Cp	1.015595
Temperature	309.8113 °C
Cp	1.015699
Temperature	310.7724 °C
Cp	1.015789
Temperature	311.7334 °C
Cp	1.015865
Temperature	312.6945 °C
Cp	1.015925
Temperature	313.6556 °C
Cp	1.015964
Temperature	314.6167 °C
Cp	1.015999
Temperature	315.5778 °C
Cp	1.016018
Temperature	316.5388 °C
Cp	1.016025
Temperature	317.4999 °C
Cp	1.016024
Temperature	318.461 °C
Cp	1.01602
Temperature	319.4221 °C
Cp	1.016029
Temperature	320.3831 °C
Cp	1.016025
Temperature	321.3442 °C
Cp	1.016037
Temperature	322.3053 °C
Cp	1.016066
Temperature	323.2664 °C
Cp	1.01611
Temperature	324.2275 °C
Cp	1.016169
Temperature	325.1886 °C
Cp	1.016225
Temperature	326.1496 °C
Cp	1.016318
Temperature	327.1107 °C
Cp	1.016411
Temperature	328.0718 °C
Cp	1.016504
Temperature	329.0329 °C
Cp	1.016596
Temperature	329.994 °C
Cp	1.016687
Temperature	330.955 °C
Cp	1.016775
Temperature	331.9161 °C
Cp	1.016864
Temperature	332.8772 °C
Cp	1.016942
Temperature	333.8383 °C
Cp	1.017019
Temperature	334.7993 °C
Cp	1.017093
Temperature	335.7604 °C
Cp	1.017163
Temperature	336.7215 °C
Cp	1.01723
Temperature	337.6826 °C
Cp	1.017295
Temperature	338.6437 °C
Cp	1.017358
Temperature	339.6048 °C
Cp	1.017423
Temperature	340.5658 °C
Cp	1.017491
Temperature	341.5269 °C
Cp	1.017567
Temperature	342.488 °C
Cp	1.017651
Temperature	343.4491 °C
[...]
95.5117	12.0455	0.3010
95.5333	11.8294	0.3000
95.5550	11.6116	0.2997
95.5767	11.3950	0.2992
95.5983	11.1776	0.2985
95.6200	10.9616	0.2976
95.6417	10.7447	0.2968
95.6633	10.5289	0.2965
95.6850	10.3106	0.2958
95.7067	10.0939	0.2954
95.7283	9.8766	0.2949
95.7500	9.6605	0.2943
95.7717	9.4440	0.2936
95.7933	9.2265	0.2934
95.8150	9.0094	0.2924
95.8367	8.7936	0.2916
95.8583	8.5755	0.2913
95.8800	8.3604	0.2903
95.9017	8.1423	0.2898
95.9233	7.9256	0.2893
95.9450	7.7081	0.2885
95.9667	7.4913	0.2880
95.9883	7.2753	0.2875
96.0100	7.0593	0.2871
96.0317	6.8423	0.2862
96.0533	6.6255	0.2855
96.0750	6.4087	0.2853
96.0967	6.1917	0.2844
96.1183	5.9746	0.2840
96.1400	5.7580	0.2836
96.1617	5.5413	0.2832
96.1833	5.3237	0.2821
96.2050	5.1067	0.2818
96.2267	4.8899	0.2814
96.2483	4.6734	0.2807
96.2700	4.4567	0.2800
96.2917	4.2394	0.2795
96.3133	4.0233	0.2787
96.3350	3.8064	0.2780
96.3567	3.5891	0.2776
96.3783	3.3726	0.2772
96.4000	3.1548	0.2766
96.4217	2.9399	0.2759
96.4433	2.7231	0.2757
96.4650	2.5047	0.2750
96.4867	2.2880	0.2744
96.5083	2.0723	0.2739
96.5300	1.8555	0.2734
96.5517	1.6378	0.2732
96.5733	1.4227	0.2721
96.5950	1.2065	0.2718
96.6167	0.9880	0.2709
96.6383	0.7717	0.2706
96.6600	0.5544	0.2700
96.6817	0.3387	0.2697
96.7033	0.1207	0.2692
96.7250	-0.0961	0.2690
96.7467	-0.3124	0.2682
96.7683	-0.5303	0.2677
96.7900	-0.7474	0.2663
96.8117	-0.9623	0.2660
96.8333	-1.1790	0.2657
96.8550	-1.3952	0.2651
96.8767	-1.6111	0.2648
96.8983	-1.8276	0.2646
96.9200	-2.0447	0.2639
96.9417	-2.2632	0.2635
96.9633	-2.4784	0.2632
96.9850	-2.6950	0.2626
97.0067	-2.9117	0.2623
97.0283	-3.1299	0.2619
97.0500	-3.3465	0.2615
97.0717	-3.5623	0.2611
97.0933	-3.7780	0.2603
97.1150	-3.9955	0.2597
97.1367	-4.2119	0.2594
97.1583	-4.4278	0.2589
97.1800	-4.6455	0.2585
97.2017	-4.8620	0.2580
97.2233	-5.0784	0.2570
97.2450	-5.2964	0.2568
97.2667	-5.5118	0.2561
97.2883	-5.7280	0.2559
97.3100	-5.9445	0.2550
97.3317	-6.1611	0.2546
97.3533	-6.3793	0.2544
97.3750	-6.5964	0.2539
97.3967	-6.8129	0.2535
97.4183	-7.0294	0.2533
97.4400	-7.2450	0.2526
97.4617	-7.4630	0.2522
97.4833	-7.6785	0.2517
97.5050	-7.8948	0.2514
97.5267	-8.1128	0.2507
97.5483	-8.3295	0.2498
97.5700	-8.5449	0.2492
97.5917	-8.7632	0.2491
97.6133	-8.9788	0.2476
97.6350	-9.1945	0.2474
97.6567	-9.4120	0.2472
97.6783	-9.6272	0.2469
97.7000	-9.8456	0.2464
97.7217	-10.0624	0.2462
97.7433	-10.2792	0.2457
97.7650	-10.4952	0.2454
97.7867	-10.7118	0.2448
97.8083	-10.9282	0.2443
97.8300	-11.1456	0.2441
97.8517	-11.3622	0.2437
97.8733	-11.5787	0.2434
97.8950	-11.7954	0.2430
97.9167	-12.0121	0.2423
97.9383	-12.2281	0.2421
97.9600	-12.4447	0.2417
97.9817	-12.6621	0.2413
98.0033	-12.8792	0.2410
98.0250	-13.0956	0.2405
98.0467	-13.3119	0.2403
98.0683	-13.5280	0.2398
98.0900	-13.7437	0.2395
98.1117	-13.9617	0.2386
98.1333	-14.1774	0.2380
98.1550	-14.3948	0.2378
98.1767	-14.6117	0.2376
98.1983	-14.8278	0.2372
98.2200	-15.0455	0.2367
98.2417	-15.2619	0.2365
98.2633	-15.4788	0.2360
98.2850	-15.6944	0.2354
98.3067	-15.9128	0.2351
98.3283	-16.1270	0.2345
98.3500	-16.3437	0.2343
98.3717	-16.5605	0.2342
98.3933	-16.7783	0.2333
98.4150	-16.9944	0.2330
98.4367	-17.2119	0.2323
98.4583	-17.4280	0.2321
98.4800	-17.6454	0.2313
98.5017	-17.8612	0.2308
98.5233	-18.0773	0.2307
98.5450	-18.2936	0.2303
98.5667	-18.5106	0.2300
98.5883	-18.7288	0.2294
98.6100	-18.9439	0.2290
98.6317	-19.1603	0.2288
98.6533	-19.3771	0.2285
98.6750	-19.5951	0.2284
98.6967	-19.8108	0.2275
98.7183	-20.0279	0.2269
98.7400	-20.2441	0.2266
98.7617	-20.4606	0.2264
98.7833	-20.6769	0.2261
98.8050	-20.8940	0.2258
98.8267	-21.1122	0.2252
98.8483	-21.3271	0.2249
98.8700	-21.5444	0.2246
98.8917	-21.7607	0.2240
98.9133	-21.9780	0.2237
98.9350	-22.1947	0.2232
98.9567	-22.4115	0.2227
98.9783	-22.6268	0.2226
99.0000	-22.8437	0.2222
99.0217	-23.0604	0.2218
99.0433	-23.2763	0.2216
99.0650	-23.4943	0.2214
99.0867	-23.7101	0.2205
99.1083	-23.9260	0.2204
99.1300	-24.1424	0.2230
99.1517	-24.3596	0.2228
99.1733	-24.5748	0.2208
99.1950	-24.7918	0.2193
99.2167	-25.0070	0.2184
99.2383	-25.2258	0.2181
99.2600	-25.4418	0.2178
99.2817	-25.6597	0.2173
99.3033	-25.8758	0.2164
99.3250	-26.0929	0.2162
99.3467	-26.3083	0.2159
99.3683	-26.5251	0.2156
99.3900	-26.7409	0.2155
99.4117	-26.9576	0.2157
99.4333	-27.1743	0.2152
99.4550	-27.3909	0.2144
99.4767	-27.6078	0.2140
99.4983	-27.8252	0.2137
99.5200	-28.0412	0.2134
99.5417	-28.2588	0.2128
99.5633	-28.4749	0.2127
99.5850	-28.6919	0.2121
99.6067	-28.9090	0.2120
99.6283	-29.1254	0.2119
99.6500	-29.3412	0.2117
99.6717	-29.5574	0.2111
99.6933	-29.7757	0.2104
99.7150	-29.9918	0.2086
99.7367	-30.2090	0.2086
99.7583	-30.4240	0.2084
99.7800	-30.6409	0.2084
99.8017	-30.8573	0.2083
99.8233	-31.0742	0.2079
99.8450	-31.2911	0.2077
99.8667	-31.5080	0.2075
99.8883	-31.7232	0.2072
99.9100	-31.9413	0.2067
99.9317	-32.1578	0.2065
99.9533	-32.3741	0.2060
99.9750	-32.5904	0.2058
99.9967	-32.8083	0.2052
100.0183	-33.0225	0.2049
100.0400	-33.2406	0.2048
100.0617	-33.4564	0.2046
100.0833	-33.6733	0.2044
100.1050	-33.8908	0.2040
100.1267	-34.1071	0.2038
100.1483	-34.3232	0.2034
100.1700	-34.5395	0.2026
100.1917	-34.7563	0.2022
100.2133	-34.9738	0.2020
100.2350	-35.1899	0.2017
100.2567	-35.4074	0.2013
100.2783	-35.6242	0.2004
100.3000	-35.8416	0.1967
100.3217	-36.0581	0.1965
100.3433	-36.2751	0.1966
100.3650	-36.4924	0.1968
100.3867	-36.7087	0.1968
100.4083	-36.9242	0.1968
100.4300	-37.1398	0.1968
100.4517	-37.3578	0.1967
100.4733	-37.5735	0.1963
100.4950	-37.7898	0.1963
100.5167	-38.0078	0.1962
100.5383	-38.2239	0.1962
100.5600	-38.4403	0.1960
100.5817	-38.6557	0.1957
100.6033	-38.8713	0.1955
100.6250	-39.0898	0.1953
100.6467	-39.3060	0.1952
100.6683	-39.5227	0.1948
100.6900	-39.7387	0.1945
100.7117	-39.9548	0.1942
100.7333	-40.1724	0.1940
100.7550	-40.3884	0.1937
100.7767	-40.6053	0.1934
100.7983	-40.8224	0.1931
100.8200	-41.0399	0.1929
100.8417	-41.2565	0.1928
100.8633	-41.4708	0.1926
100.8850	-41.6882	0.1920
100.9067	-41.9047	0.1918
100.9283	-42.1204	0.1912
100.9500	-42.3375	0.1911
100.9717	-42.5561	0.1909
100.9933	-42.7714	0.1901
101.0150	-42.9872	0.1900
101.0367	-43.2040	0.1895
101.0583	-43.4207	0.1893
101.0800	-43.6379	0.1890
101.1017	-43.8546	0.1888
101.1233	-44.0703	0.1886
101.1450	-44.2879	0.1883
101.1667	-44.5047	0.1877
101.1883	-44.7192	0.1875
101.2100	-44.9384	0.1873
101.2317	-45.1538	0.1871
101.2533	-45.3685	0.1868
101.2750	-45.5859	0.1866
101.2967	-45.8023	0.1864
101.3183	-46.0193	0.1859
101.3400	-46.2351	0.1858
101.3617	-46.4519	0.1854
101.3833	-46.6689	0.1849
101.4050	-46.8858	0.1844
101.4267	-47.1018	0.1842
101.4483	-47.3197	0.1839
101.4700	-47.5346	0.1838
101.4917	-47.7507	0.1837
101.5133	-47.9678	0.1833
101.5350	-48.1854	0.1831
101.5567	-48.4009	0.1829
101.5783	-48.6168	0.1828
101.6000	-48.8335	0.1825
101.6217	-49.0512	0.1824
101.6433	-49.2678	0.1819
101.6650	-49.4860	0.1816
101.6867	-49.6996	0.1813
101.7083	-49.9176	0.1811
101.7300	-50.1329	0.1805
101.7517	-50.3506	0.1804
101.7733	-50.5655	0.1801
101.7950	-50.7819	0.1795
101.8167	-50.9992	0.1794
101.8383	-51.2166	0.1792
101.8600	-51.4329	0.1762
101.8817	-51.6504	0.1752
101.9033	-51.8665	0.1752
101.9250	-52.0844	0.1753
101.9467	-52.3005	0.1753
101.9683	-52.5151	0.1753
101.9900	-52.7335	0.1753
102.0117	-52.9496	0.1753
102.0333	-53.1654	0.1752
102.0550	-53.3826	0.1751
102.0767	-53.5999	0.1750
102.0983	-53.8156	0.1746
102.1200	-54.0324	0.1745
102.1417	-54.2475	0.1744
102.1633	-54.4653	0.1742
102.1850	-54.6825	0.1741
102.2067	-54.8989	0.1739
102.2283	-55.1156	0.1736
102.2500	-55.3310	0.1733
102.2717	-55.5472	0.1733
102.2933	-55.7655	0.1731
102.3150	-55.9802	0.1726
102.3367	-56.1974	0.1724
102.3583	-56.4140	0.1723
102.3800	-56.6300	0.1721
102.4017	-56.8468	0.1716
102.4233	-57.0629	0.1713
102.4450	-57.2785	0.1708
102.4667	-57.4950	0.1704
102.4883	-57.7103	0.1696
102.5100	-57.9276	0.1683
102.5317	-58.1466	0.1683
102.5533	-58.3633	0.1683
102.5750	-58.5818	0.1683
102.5967	-58.7947	0.1681
102.6183	-59.0116	0.1680
102.6400	-59.2279	0.1679
102.6617	-59.4454	0.1677
102.6833	-59.6628	0.1675
102.7050	-59.8781	0.1675
102.7267	-60.0940	0.1673
102.7483	-60.3122	0.1670
102.7700	-60.5273	0.1665
102.7917	-60.7443	0.1663
102.8133	-60.9616	0.1661
102.8350	-61.1780	0.1660
102.8567	-61.3946	0.1659
102.8783	-61.6104	0.1657
102.9000	-61.8268	0.1656
102.9217	-62.0428	0.1654
102.9433	-62.2612	0.1652
102.9650	-62.4786	0.1650
102.9867	-62.6919	0.1648
103.0083	-62.9085	0.1647
103.0300	-63.1253	0.1644
103.0517	-63.3418	0.1640
103.0733	-63.5589	0.1638
103.0950	-63.7748	0.1637
103.1167	-63.9907	0.1635
103.1383	-64.2071	0.1634
103.1600	-64.4237	0.1660
103.1817	-64.6384	0.1657
103.2033	-64.8575	0.1652
103.2250	-65.0719	0.1641
103.2467	-65.2884	0.1636
103.2683	-65.5057	0.1634
103.2900	-65.7209	0.1634
103.3117	-65.9391	0.1632
103.3333	-66.1544	0.1626
103.3550	-66.3716	0.1622
103.3767	-66.5877	0.1616
103.3983	-66.8045	0.1614
103.4200	-67.0206	0.1612
103.4417	-67.2356	0.1606
103.4633	-67.4535	0.1603
103.4850	-67.6694	0.1592
103.5067	-67.8880	0.1589
103.5283	-68.1039	0.1587
103.5500	-68.3201	0.1585
103.5717	-68.5363	0.1584
103.5933	-68.7523	0.1582
103.6150	-68.9701	0.1581
103.6367	-69.1845	0.1579
103.6583	-69.4027	0.1577
103.6800	-69.6200	0.1576
103.7017	-69.8356	0.1575
103.7233	-70.0516	0.1572
103.7450	-70.2659	0.1569
103.7667	-70.4842	0.1565
103.7883	-70.7004	0.1565
103.8100	-70.9169	0.1563
103.8317	-71.1341	0.1561
103.8533	-71.3495	0.1559
103.8750	-71.5683	0.1556
103.8967	-71.7833	0.1555
103.9183	-71.9984	0.1554
103.9400	-72.2157	0.1552
103.9617	-72.4312	0.1550
103.9833	-72.6495	0.1549
104.0050	-72.8666	0.1547
104.0267	-73.0825	0.1542
104.0483	-73.2975	0.1540
104.0700	-73.5156	0.1537
104.0917	-73.7318	0.1535
104.1133	-73.9480	0.1534
104.1350	-74.1627	0.1532
104.1567	-74.3805	0.1529
104.1783	-74.5962	0.1526
104.2000	-74.8119	0.1524
104.2217	-75.0314	0.1521
104.2433	-75.2460	0.1518
104.2650	-75.4632	0.1517
104.2867	-75.6797	0.1513
104.3083	-75.8970	0.1512
104.3300	-76.1144	0.1510
104.3517	-76.3284	0.1507
104.3733	-76.5462	0.1506
104.3950	-76.7612	0.1504
104.4167	-76.9786	0.1497
104.4383	-77.1949	0.1496
104.4600	-77.4111	0.1495
104.4817	-77.6269	0.1486
104.5033	-77.8453	0.1484
104.5250	-78.0617	0.1484
104.5467	-78.2773	0.1483
104.5683	-78.4930	0.1483
104.5900	-78.7097	0.1480
104.6117	-78.9269	0.1477
104.6333	-79.1430	0.1476
104.6550	-79.3583	0.1472
104.6767	-79.5738	0.1468
104.6983	-79.7921	0.1468
104.7200	-80.0088	0.1467
104.7417	-80.2251	0.1466
104.7633	-80.4414	0.1460
104.7850	-80.6572	0.1459
104.8067	-80.8729	0.1457
104.8283	-81.0892	0.1456
104.8500	-81.3054	0.1453
104.8717	-81.5228	0.1450
104.8933	-81.7391	0.1449
104.9150	-81.9543	0.1448
104.9367	-82.1716	0.1447
104.9583	-82.3902	0.1445
104.9800	-82.6046	0.1443
105.0017	-82.8211	0.1442
105.0233	-83.0376	0.1440
105.0450	-83.2545	0.1438
105.0667	-83.4707	0.1437
105.0883	-83.6872	0.1434
105.1100	-83.9052	0.1433
105.1317	-84.1165	0.1461
105.1533	-84.3341	0.1455
105.1750	-84.5492	0.1448
105.1967	-84.7650	0.1585
105.2183	-84.9707	0.1630
105.2400	-85.1867	0.1544
105.2617	-85.4031	0.1495
105.2833	-85.6203	0.1482
105.3050	-85.8361	0.1461
105.3267	-86.0537	0.1460
105.3483	-86.2715	0.1458
105.3700	-86.4885	0.1457
105.3917	-86.7076	0.1453
105.4133	-86.9243	0.1451
105.4350	-87.1411	0.1449
105.4567	-87.3571	0.1442
105.4783	-87.5755	0.1437
105.5000	-87.7926	0.1435
105.5217	-88.0083	0.1432
105.5433	-88.2265	0.1431
105.5650	-88.4444	0.1430
105.5867	-88.6615	0.1424
105.6083	-88.8764	0.1424
105.6300	-89.0939	0.1421
105.6517	-89.3115	0.1418
105.6733	-89.5281	0.1418
105.6950	-89.7439	0.1415
105.7167	-89.9613	0.1412
105.7383	-90.1785	0.1410
105.7600	-90.3951	0.1409
105.7817	-90.6115	0.1399
105.8033	-90.8283	0.1397
105.8250	-91.0464	0.1396
105.8467	-91.2625	0.1396
105.8683	-91.4806	0.1395
105.8900	-91.6967	0.1395
105.9117	-91.9155	0.1392
105.9333	-92.1316	0.1391
105.9550	-92.3483	0.1391
105.9767	-92.5663	0.1390
105.9983	-92.7816	0.1386
106.0200	-92.9996	0.1385
106.0417	-93.2175	0.1384
106.0633	-93.4346	0.1382
106.0850	-93.6515	0.1378
106.1067	-93.8680	0.1376
106.1283	-94.0855	0.1376
106.1500	-94.3030	0.1375
106.1717	-94.5197	0.1373
106.1933	-94.7368	0.1371
106.2150	-94.9543	0.1366
106.2367	-95.1706	0.1366
106.2583	-95.3885	0.1366
106.2800	-95.6044	0.1364
106.3017	-95.8221	0.1363
106.3233	-96.0406	0.1361
106.3450	-96.2564	0.1361
106.3667	-96.4749	0.1357
106.3883	-96.6921	0.1356
106.4100	-96.9077	0.1352
106.4317	-97.1246	0.1351
106.4533	-97.3428	0.1343
106.4750	-97.5585	0.1345
106.4967	-97.7750	0.1344
106.5183	-97.9928	0.1338
106.5400	-98.2113	0.1332
106.5617	-98.4273	0.1332
106.5833	-98.6440	0.1331
106.6050	-98.8620	0.1331
106.6267	-99.0782	0.1331
106.6483	-99.2959	0.1331
106.6700	-99.5140	0.1327
106.6917	-99.7316	0.1327
106.7133	-99.9482	0.1326
106.7350	-100.1641	0.1317
106.7567	-100.3823	0.1316
106.7783	-100.5975	0.1316
106.8000	-100.8153	0.1315
106.8217	-101.0335	0.1315
106.8433	-101.2491	0.1312
106.8650	-101.4673	0.1312
106.8867	-101.6849	0.1310
106.9083	-101.9002	0.1306
106.9300	-102.1182	0.1305
106.9517	-102.3348	0.1304
106.9733	-102.5496	0.1303
106.9950	-102.7685	0.1301
107.0167	-102.9850	0.1302
107.0383	-103.2029	0.1299
107.0600	-103.4182	0.1296
107.0817	-103.6360	0.1296
107.1033	-103.8522	0.1294
107.1250	-104.0700	0.1291
107.1467	-104.2882	0.1287
107.1683	-104.5049	0.1285
107.1900	-104.7218	0.1285
107.2117	-104.9399	0.1285
107.2333	-105.1550	0.1284
107.2550	-105.3718	0.1281
107.2767	-105.5884	0.1280
107.2983	-105.8076	0.1278
107.3200	-106.0254	0.1277
107.3417	-106.2400	0.1274
107.3633	-106.4576	0.1272
107.3850	-106.6734	0.1271
107.4067	-106.8916	0.1270
107.4283	-107.1109	0.1267
107.4500	-107.3258	0.1266
107.4717	-107.5423	0.1264
107.4933	-107.7605	0.1262
107.5150	-107.9773	0.1261
107.5367	-108.1951	0.1258
107.5583	-108.4101	0.1255
107.5800	-108.6275	0.1255
107.6017	-108.8443	0.1253
107.6233	-109.0630	0.1250
107.6450	-109.2790	0.1248
107.6667	-109.4965	0.1248
107.6883	-109.7126	0.1246
107.7100	-109.9283	0.1243
107.7317	-110.1475	0.1243
107.7533	-110.3640	0.1239
107.7750	-110.5809	0.1237
107.7967	-110.7983	0.1237
107.8183	-111.0143	0.1235
107.8400	-111.2326	0.1231
107.8617	-111.4502	0.1229
107.8833	-111.6657	0.1227
107.9050	-111.8831	0.1226
107.9267	-112.0989	0.1226
107.9483	-112.3190	0.1224
107.9700	-112.5362	0.1224
107.9917	-112.7514	0.1220
108.0133	-112.9692	0.1220
108.0350	-113.1854	0.1220
108.0567	-113.4027	0.1213
108.0783	-113.6181	0.1215
108.1000	-113.8358	0.1214
108.1217	-114.0531	0.1214
108.1433	-114.2719	0.1211
108.1650	-114.4859	0.1211
108.1867	-114.7051	0.1200
108.2083	-114.9218	0.1205
108.2300	-115.1382	0.1202
108.2517	-115.3560	0.1201
108.2733	-115.5727	0.1200
108.2950	-115.7896	0.1200
108.3167	-116.0078	0.1200
108.3383	-116.2235	0.1199
108.3600	-116.4401	0.1199
108.3817	-116.6580	0.1197
108.4033	-116.8744	0.1196
108.4250	-117.0930	0.1196
108.4467	-117.3124	0.1194
108.4683	-117.5250	0.1193
108.4900	-117.7432	0.1191
108.5117	-117.9610	0.1190
108.5333	-118.1801	0.1190
108.5550	-118.3959	0.1189
108.5767	-118.6140	0.1187
108.5983	-118.8287	0.1185
108.6200	-119.0464	0.1183
108.6417	-119.2639	0.1181
108.6633	-119.4793	0.1179
108.6850	-119.6966	0.1179
108.7067	-119.9144	0.1177
108.7283	-120.1307	0.1177
108.7500	-120.3487	0.1177
108.7717	-120.5646	0.1176
108.7933	-120.7831	0.1176
108.8150	-121.0011	0.1175
108.8367	-121.2163	0.1173
108.8583	-121.4343	0.1173
108.8800	-121.6506	0.1172
108.9017	-121.8681	0.1172
108.9233	-122.0847	0.1170
108.9450	-122.3020	0.1170
108.9667	-122.5200	0.1169
108.9883	-122.7358	0.1169
109.0100	-122.9550	0.1169
109.0317	-123.1703	0.1169
109.0533	-123.3881	0.1168
109.0750	-123.6065	0.1168
109.0967	-123.8233	0.1167
109.1183	-124.0390	0.1166
109.1400	-124.2557	0.1166
109.1617	-124.4721	0.1166
109.1833	-124.6910	0.1166
109.2050	-124.9061	0.1165
109.2267	-125.1239	0.1164
109.2483	-125.3406	0.1164
109.2700	-125.5569	0.1163
109.2917	-125.7758	0.1165
109.3133	-125.9948	0.1163
109.3350	-126.2101	0.1163
109.3567	-126.4276	0.1163
109.3783	-126.6425	0.1163
109.4000	-126.8593	0.1162
109.4217	-127.0801	0.1165
109.4433	-127.2954	0.1163
109.4650	-127.5115	0.1161
109.4867	-127.7305	0.1161
109.5083	-127.9452	0.1161
109.5300	-128.1660	0.1161
109.5517	-128.3824	0.1162
109.5733	-128.5986	0.1162
109.5950	-128.8169	0.1162
109.6167	-129.0333	0.1162
109.6383	-129.2497	0.1162
109.6600	-129.4671	0.1161
109.6817	-129.6853	0.1164
109.7033	-129.9023	0.1164
109.7250	-130.1186	0.1162
109.7467	-130.3358	0.1164
109.7683	-130.5533	0.1164
109.7900	-130.7722	0.1163
109.8117	-130.9882	0.1164
109.8333	-131.2053	0.1163
109.8550	-131.4208	0.1164
109.8767	-131.6407	0.1165
109.8983	-131.8563	0.1165
109.9200	-132.0745	0.1165
109.9417	-132.2916	0.1165
109.9633	-132.5068	0.1164
109.9850	-132.7244	0.1165
110.0067	-132.9434	0.1165
110.0283	-133.1610	0.1165
110.0500	-133.3793	0.1166
110.0717	-133.5939	0.1167
110.0933	-133.8132	0.1166
110.1150	-134.0303	0.1166
110.1367	-134.2458	0.1166
110.1583	-134.4637	0.1166
110.1800	-134.6808	0.1166
110.2017	-134.8996	0.1166
110.2233	-135.1171	0.1166
110.2450	-135.3330	0.1167
110.2667	-135.5514	0.1167
110.2883	-135.7677	0.1167
110.3100	-135.9854	0.1167
110.3317	-136.2009	0.1167
110.3533	-136.4204	0.1167
110.3750	-136.6376	0.1167
110.3967	-136.8562	0.1167
110.4183	-137.0735	0.1169
110.4400	-137.2896	0.1162
110.4617	-137.5056	0.1163
110.4833	-137.7272	0.1163
110.5050	-137.9404	0.1163
110.5267	-138.1592	0.1163
110.5483	-138.3753	0.1163
110.5700	-138.5944	0.1164
110.5917	-138.8108	0.1164
110.6133	-139.0294	0.1164
110.6350	-139.2445	0.1165
110.6567	-139.4628	0.1164
110.6783	-139.6802	0.1161
110.7000	-139.8979	0.1162
110.7217	-140.1150	0.1161
110.7433	-140.3330	0.1160
110.7650	-140.5490	0.1158
110.7867	-140.7675	0.1164
110.8083	-140.9843	0.1164
110.8300	-141.2010	0.1163
110.8517	-141.4217	0.1162
110.8733	-141.6384	0.1162
110.8950	-141.8533	0.1163
110.9167	-142.0731	0.1161
110.9383	-142.2888	0.1154
110.9600	-142.5054	0.1154
110.9817	-142.7249	0.1153
111.0033	-142.9428	0.1154
111.0250	-143.1606	0.1152
111.0467	-143.3748	0.1152
111.0683	-143.5944	0.1152
111.0900	-143.8130	0.1151
111.1117	-144.0301	0.1151
111.1333	-144.2478	0.1151
111.1550	-144.4645	0.1150
111.1767	-144.6829	0.1150
111.1983	-144.8973	0.1142
111.2200	-145.1151	0.1141
111.2417	-145.3336	0.1141
111.2633	-145.5511	0.1141
111.2850	-145.7676	0.1139
111.3067	-145.9874	0.1139
111.3283	-146.2019	0.1139
111.3500	-146.4240	0.1136
111.3717	-146.6400	0.1133
111.3933	-146.8553	0.1131
111.4150	-147.0735	0.1130
111.4367	-147.2923	0.1128
111.4583	-147.5113	0.1128
111.4800	-147.7280	0.1127
111.4933	-147.8599	0.1124

[step]
Isothermal 3.0 min
Time	Temperature	Heat Flow (Normalized)
min	°C	W/g
111.4950	-147.8758	0.1124
111.4967	-147.8940	0.1124
111.4983	-147.9105	0.1124
111.5000	-147.9270	0.1124
111.5017	-147.9452	0.1124
111.5033	-147.9617	0.1124
111.5050	-147.9799	0.1124
111.5067	-147.9953	0.1124
111.5083	-148.0119	0.1124
111.5100	-148.0273	0.1124
111.5117	-148.0436	0.1124
111.5133	-148.0590	0.1124
111.5150	-148.0742	0.1123
111.5167	-148.0897	0.1123
111.5183	-148.1078	0.1123
111.5200	-148.1237	0.1123
111.5217	-148.1387	0.1123
111.5233	-148.1534	0.1123
111.5250	-148.1703	0.1123
111.5267	-148.1858	0.1123
111.5283	-148.2021	0.1123
111.5300	-148.2191	0.1123
111.5317	-148.2333	0.1123
111.5333	-148.2475	0.1123
111.5350	-148.2629	0.1123
111.5367	-148.2803	0.1122
111.5383	-148.2941	0.1122
111.5400	-148.3106	0.1122
111.5417	-148.3232	0.1122
111.5433	-148.3388	0.1122
111.5450	-148.3481	0.1122
111.5467	-148.3636	0.1122
111.5483	-148.3788	0.1121
111.5500	-148.3917	0.1121
111.5517	-148.4036	0.1121
111.5533	-148.4182	0.1121
111.5550	-148.4304	0.1121
111.5567	-148.4430
111.5583	-148.4559
111.5600	-148.4670
111.5617	-148.4790
111.5633	-148.4908
111.5650	-148.5009
111.5667	-148.5126
111.5683	-148.5214
111.5700	-148.5319
111.5717	-148.5425
111.5733	-148.5504
111.5750	-148.5607
111.5767	-148.5697
111.5783	-148.5802
111.5800	-148.5871
111.5817	-148.5972
111.5833	-148.6071
111.5850	-148.6138
111.5867	-148.6221
111.5883	-148.6297
111.5900	-148.6385
111.5917	-148.6450
111.5933	-148.6530
111.5950	-148.6611
111.5967	-148.6687
111.5983	-148.6755
111.6000	-148.6839
111.6017	-148.6929
111.6033	-148.6980
111.6050	-148.7036
111.6067
111.6083
111.6100
111.6117
111.6133