File: Example Date/My Sample/DSC/test01/DSC TA/YN038-a.txt
Filename	YN038-a
Instrument name	DSC2A-01799 (192.168.1.250)
Operator
rundate	02/12/2024
Sample name	YN038-a
proceduresegments	Ramp 10.00 °C/min to 150.0000 °C; Isothermal 3.0 min; Ramp 10.00 °C/min to -100.0000 °C; Isothermal 3.0 min; Ramp 10.00 °C/min to 150.0000 °C; Isothermal 3.0 min; Ramp 10.00 °C/min to -100.0000 °C; Isothermal 3.0 min; Ramp 10.00 °C/min to 150.0000 °C; Isothermal 3.0 min; Ramp 10.00 °C/min to -100.0000 °C; Isothermal 3.0 min; Ramp 10.00 °C/min to 150.0000 °C; Isothermal 3.0 min; Ramp 10.00 °C/min to 40.0000 °C
[File Parameters]
Run Date	02/12/2024 23:06:05
Trios version	5.7.0.56
Original File Name
Current File Name	C:\Users\TA Instruments DSC\Desktop\Data\Yutong Niu\2024-1126\YN038-a.tri
User at run start	DESKTOP-CFGN8IT\TA Instruments DSC
[Procedure]
Procedure Name	polyether
Sample Name	YN038-a
Sample Mass	12.68 mg
Reference Sample Mass	0 mg
Pan Mass	62.08 mg
Pan Number	5
Reference Pan Mass	60.81 mg
Reference Pan Number	45
Pan Type	Tzero Aluminum Pin Hole Hermetic
Comments
Project Name
Operator
Test	Custom
Unload Max Temperature	25
Unload Min Temperature	25
FillCooler	Do not fill
Load Max Temperature	25
Load Min Temperature	25
Discard pan in waste bin at end of test	Yes
Stop on Gas Flow Error	No
[Signal List]
Signal #1	Time (min)
Signal #2	Temperature (°C)
Signal #3	Heat Flow (mW)
Signal #4	Delta T (µV)
Signal #5	Delta Tzero (µV)
Signal #6	Tzero Temperature (°C)
Signal #7	Cell Purge (mL/min)
Signal #8	Heater Temp (°C)
Signal #9	Power Delivered (W)
Signal #10	Reference Junction Temperature (°C)
Signal #11	Flange Temperature (°C)
Signal #12	Heat Flow Phase (rad)
Signal #13	Total Heat Capacity (J/°C)
Signal #14	Heat Capacity (J/°C)
Signal #15	LN Pump Tank level (%)
[Configuration]
Company Name	Warwick University
Instrument Name	DSC2A-01799
Instrument Type	DSC2500
Serial Number	DSC2A-01799
IP	192.168.1.250
Location of Instrument	Polymer RTP
DisplayType	TianmaV2andV3
Sample Interval 	0.1 s/pt
Selected Heat Flow	T4P
Exotherm Direction	Up
Cell Serial	DRC2-03788
Lid Type	High Temperature
Cooler	LN Pump
Leave Cooler on at End of Sequence	Off
Gas 2	Air
Gas Selected	Channel 1: Nitrogen
Flow Rate	50 mL/min
Secondary Purge	On
Licensed Heat Flow	Heat Flow T4P
Modulation Licensed	Yes
[Versions]
Common IDD Version	1
Cortex Version	VER 2.11.0.729
Driver	5.0.0.6
GDM Version	1.0.3.3
TouchscreenVersion	1.0.3.1841
FEP Version	1.2.1.21
FEP Bootloader	2.0.0.5
AutoSampler Version	2.1.2.1
Auto Sampler Bootloader	2.0.0.5
FCM Version	1.1.0.3
FCM Bootloader	2.0.0.5
LN Pump Version	10.17.0.0
LN Pump Bootloader	2.0.0.5
[Experiment Logs]
Experiment Log Entry # 1	Ramp Segment 10 C/min to 150 Started
Experiment Log Entry # 3	Air Cool is off.
Experiment Log Entry # 5	Isothermal Segment 3 min started
Experiment Log Entry # 7	Ramp Segment 10 C/min to -100 Started
Experiment Log Entry # 9	Isothermal Segment 3 min started
Experiment Log Entry # 11	Ramp Segment 10 C/min to 150 Started
Experiment Log Entry # 13	Isothermal Segment 3 min started
Experiment Log Entry # 15	Ramp Segment 10 C/min to -100 Started
Experiment Log Entry # 17	Isothermal Segment 3 min started
Experiment Log Entry # 19	Ramp Segment 10 C/min to 150 Started
Experiment Log Entry # 21	Isothermal Segment 3 min started
Experiment Log Entry # 23	Ramp Segment 10 C/min to -100 Started
Experiment Log Entry # 25	Isothermal Segment 3 min started
Experiment Log Entry # 27	Ramp Segment 10 C/min to 150 Started
Experiment Log Entry # 29	Isothermal Segment 3 min started
Experiment Log Entry # 31	Ramp Segment 10 C/min to 40 Started
[Method Log]
Method Log Entry # 1	(Ramp 2108709) Ramp 10 °C/minute to 150 °C
Method Log Entry # 2	Isothermal 3 minutes
Method Log Entry # 3	(Ramp 2108711) Ramp 10 °C/minute to -100 °C
Method Log Entry # 4	Isothermal 3 minutes
Method Log Entry # 5	(Ramp 2108713) Ramp 10 °C/minute to 150 °C
Method Log Entry # 6	Isothermal 3 minutes
Method Log Entry # 7	(Ramp 2108715) Ramp 10 °C/minute to -100 °C
Method Log Entry # 8	Isothermal 3 minutes
Method Log Entry # 9	(Ramp 2108717) Ramp 10 °C/minute to 150 °C
Method Log Entry # 10	Isothermal 3 minutes
Method Log Entry # 11	(Ramp 2108719) Ramp 10 °C/minute to -100 °C
Method Log Entry # 12	Isothermal 3 minutes
Method Log Entry # 13	(Ramp 2108721) Ramp 10 °C/minute to 150 °C
Method Log Entry # 14	Isothermal 3 minutes
Method Log Entry # 15	(Ramp 2108723) Ramp 10 °C/minute to 40 °C
Cell Serial	DRC2-03788
[T1 Calibration]
Date Applied	04/03/2021 14:58:04
Description
Gas Type	Nitrogen
Pan Type	None
Slope	-0.001800291
Offset	-0.1301359
Initial Temperature	-100.6228
GUID	a1d5a6be-decd-4ae4-b22f-d560f3a78a92
[TZero Calibration]
Date Applied	21/08/2024 09:53:38
Description	From -180.022 °C to 395.167 °C at 20.000°C/min
Gas Type	Nitrogen
Pan Type	None
Source Files 1	C:\ProgramData\TA Instruments\TRIOS\Data\TAService\PMV 20Aug2024\Tzero Cal.tri
Source Files 2	C:\ProgramData\TA Instruments\TRIOS\Data\TAService\PMV 20Aug2024\Tzero Cal sapphire.tri
Delta T Offset	1.787969
Delta T Slope	-0.003527276
Delta T0 Offset	0.06831977
Delta T0 Slope	0.02007191
[Temperature Calibration]
Date Applied	21/08/2024 11:06:35
Description	From 106.660 °C to 186.660 °C at 10.000°C/min
Gas Type	Nitrogen
Pan Type	Tzero Aluminum
Source Files 1	C:\ProgramData\TA Instruments\TRIOS\Data\TAService\PMV 20Aug2024\TA Indium cal.tri
Measured 1	157.9141
Known 1	156.66
[Cell Constant Calibration]
Date Applied	21/08/2024 11:06:35
Description	From 106.660 °C to 186.660 °C at 10.000°C/min
Gas Type	Nitrogen
Pan Type	Tzero Aluminum
Source Files 1	C:\ProgramData\TA Instruments\TRIOS\Data\TAService\PMV 20Aug2024\TA Indium cal.tri
T4P KCell	1.038055
Onset Slope	-66.72884 mW/°C
[Direct Cp Calibration]
Date Applied	19/11/2024 16:37:27
Description	From -89.996 °C to 396.697 °C at 20.000°C/min
Gas Type	Nitrogen
Pan Type	Tzero Aluminum
Source Files 1	C:\ProgramData\TA Instruments\TRIOS\Data\Sapphire Direct Heat Capacity(8).tri
GUID	544f8371-fe9b-4f4f-81ca-7980c172113e
Temperature	-89.99625 °C
Cp	1.464367
Temperature	-89.02287 °C
Cp	1.460558
Temperature	-88.04948 °C
Cp	1.456263
Temperature	-87.0761 °C
Cp	1.451626
Temperature	-86.10271 °C
Cp	1.446737
Temperature	-85.12933 °C
Cp	1.441723
Temperature	-84.15594 °C
Cp	1.436654
Temperature	-83.18256 °C
Cp	1.431684
Temperature	-82.20917 °C
Cp	1.426935
Temperature	-81.23578 °C
Cp	1.422396
Temperature	-80.2624 °C
Cp	1.418192
Temperature	-79.28901 °C
Cp	1.414363
Temperature	-78.31562 °C
Cp	1.410925
Temperature	-77.34224 °C
Cp	1.407865
Temperature	-76.36885 °C
Cp	1.405143
Temperature	-75.39546 °C
Cp	1.402789
Temperature	-74.42208 °C
Cp	1.400703
Temperature	-73.44869 °C
Cp	1.398837
Temperature	-72.4753 °C
Cp	1.397142
Temperature	-71.50192 °C
Cp	1.395565
Temperature	-70.52853 °C
Cp	1.394053
Temperature	-69.55515 °C
Cp	1.392558
Temperature	-68.58176 °C
Cp	1.391036
Temperature	-67.60838 °C
Cp	1.389483
Temperature	-66.63499 °C
Cp	1.387847
Temperature	-65.66161 °C
Cp	1.38616
Temperature	-64.68822 °C
Cp	1.384397
Temperature	-63.71483 °C
Cp	1.382535
Temperature	-62.74145 °C
Cp	1.380598
Temperature	-61.76806 °C
Cp	1.37865
Temperature	-60.79467 °C
Cp	1.376673
Temperature	-59.82129 °C
Cp	1.374677
Temperature	-58.8479 °C
Cp	1.372642
Temperature	-57.87452 °C
Cp	1.370686
Temperature	-56.90113 °C
Cp	1.368741
Temperature	-55.92775 °C
Cp	1.366786
Temperature	-54.95436 °C
Cp	1.364863
Temperature	-53.98097 °C
Cp	1.362959
Temperature	-53.00759 °C
Cp	1.361116
Temperature	-52.0342 °C
Cp	1.359247
Temperature	-51.06082 °C
Cp	1.357393
Temperature	-50.08743 °C
Cp	1.355593
Temperature	-49.11404 °C
Cp	1.353796
Temperature	-48.14066 °C
Cp	1.352008
Temperature	-47.16727 °C
Cp	1.350215
Temperature	-46.19389 °C
Cp	1.348396
Temperature	-45.2205 °C
Cp	1.346593
Temperature	-44.24712 °C
Cp	1.344755
Temperature	-43.27373 °C
Cp	1.342891
Temperature	-42.30034 °C
Cp	1.341008
Temperature	-41.32696 °C
Cp	1.339126
Temperature	-40.35357 °C
Cp	1.337236
Temperature	-39.38018 °C
Cp	1.335367
Temperature	-38.4068 °C
Cp	1.333522
Temperature	-37.43341 °C
Cp	1.331708
Temperature	-36.46003 °C
Cp	1.32991
Temperature	-35.48664 °C
Cp	1.328145
Temperature	-34.51326 °C
Cp	1.326414
Temperature	-33.53987 °C
Cp	1.32471
Temperature	-32.56648 °C
Cp	1.323012
Temperature	-31.5931 °C
Cp	1.321323
Temperature	-30.61971 °C
Cp	1.319657
Temperature	-29.64633 °C
Cp	1.317968
Temperature	-28.67294 °C
Cp	1.316286
Temperature	-27.69955 °C
Cp	1.314585
Temperature	-26.72617 °C
Cp	1.312857
Temperature	-25.75278 °C
Cp	1.31111
Temperature	-24.7794 °C
Cp	1.309333
Temperature	-23.80601 °C
Cp	1.307544
Temperature	-22.83262 °C
Cp	1.30575
Temperature	-21.85924 °C
Cp	1.303941
Temperature	-20.88585 °C
Cp	1.302132
Temperature	-19.91247 °C
Cp	1.300313
Temperature	-18.93908 °C
Cp	1.298512
Temperature	-17.96569 °C
Cp	1.296728
Temperature	-16.99231 °C
Cp	1.294939
Temperature	-16.01892 °C
Cp	1.293198
Temperature	-15.04554 °C
Cp	1.291453
Temperature	-14.07215 °C
Cp	1.289723
Temperature	-13.09876 °C
Cp	1.288007
Temperature	-12.12538 °C
Cp	1.286283
Temperature	-11.15199 °C
Cp	1.284578
Temperature	-10.17861 °C
Cp	1.282885
Temperature	-9.205221 °C
Cp	1.281173
Temperature	-8.231835 °C
Cp	1.279472
Temperature	-7.258449 °C
Cp	1.277766
Temperature	-6.285063 °C
Cp	1.276053
Temperature	-5.311677 °C
Cp	1.274341
Temperature	-4.338291 °C
Cp	1.272592
Temperature	-3.364905 °C
Cp	1.270844
Temperature	-2.391519 °C
Cp	1.269062
Temperature	-1.418133 °C
Cp	1.267264
Temperature	-0.4447474 °C
Cp	1.265435
Temperature	0.5286385 °C
Cp	1.263575
Temperature	1.502024 °C
Cp	1.261727
Temperature	2.47541 °C
Cp	1.259854
Temperature	3.448796 °C
Cp	1.257978
Temperature	4.422182 °C
Cp	1.256109
Temperature	5.395568 °C
Cp	1.254244
Temperature	6.368954 °C
Cp	1.252392
Temperature	7.34234 °C
Cp	1.250552
Temperature	8.315726 °C
Cp	1.248704
Temperature	9.289112 °C
Cp	1.246884
Temperature	10.2625 °C
Cp	1.245078
Temperature	11.23588 °C
Cp	1.243287
Temperature	12.20927 °C
Cp	1.241522
Temperature	13.18266 °C
Cp	1.239778
Temperature	14.15604 °C
Cp	1.238068
Temperature	15.12943 °C
Cp	1.236393
Temperature	16.10281 °C
Cp	1.234762
Temperature	17.0762 °C
Cp	1.233176
Temperature	18.04959 °C
Cp	1.231629
Temperature	19.02297 °C
Cp	1.230129
Temperature	19.99636 °C
Cp	1.228694
Temperature	20.96974 °C
Cp	1.22731
Temperature	21.94313 °C
Cp	1.225968
Temperature	22.91652 °C
Cp	1.224676
Temperature	23.8899 °C
Cp	1.223431
Temperature	24.86329 °C
Cp	1.222217
Temperature	25.83667 °C
Cp	1.221065
Temperature	26.81006 °C
Cp	1.219919
Temperature	27.78345 °C
Cp	1.218811
Temperature	28.75683 °C
Cp	1.21773
Temperature	29.73022 °C
Cp	1.216663
Temperature	30.7036 °C
Cp	1.2156
Temperature	31.67699 °C
Cp	1.214515
Temperature	32.65038 °C
Cp	1.213439
Temperature	33.62376 °C
Cp	1.21234
Temperature	34.59715 °C
Cp	1.211209
Temperature	35.57053 °C
Cp	1.210051
Temperature	36.54392 °C
Cp	1.208868
Temperature	37.5173 °C
Cp	1.207666
Temperature	38.49069 °C
Cp	1.206439
Temperature	39.46408 °C
Cp	1.205199
Temperature	40.43746 °C
Cp	1.203959
Temperature	41.41085 °C
Cp	1.202712
Temperature	42.38424 °C
Cp	1.20147
Temperature	43.35762 °C
Cp	1.200231
Temperature	44.33101 °C
Cp	1.199
Temperature	45.30439 °C
Cp	1.197777
Temperature	46.27778 °C
Cp	1.19657
Temperature	47.25116 °C
Cp	1.195367
Temperature	48.22455 °C
Cp	1.194179
Temperature	49.19794 °C
Cp	1.19301
Temperature	50.17132 °C
Cp	1.191849
Temperature	51.14471 °C
Cp	1.190694
Temperature	52.11809 °C
Cp	1.189555
Temperature	53.09148 °C
Cp	1.18843
Temperature	54.06487 °C
Cp	1.187311
Temperature	55.03825 °C
Cp	1.186195
Temperature	56.01164 °C
Cp	1.185095
Temperature	56.98502 °C
Cp	1.183997
Temperature	57.95841 °C
Cp	1.182894
Temperature	58.93179 °C
Cp	1.181793
Temperature	59.90518 °C
Cp	1.180693
Temperature	60.87857 °C
Cp	1.179595
Temperature	61.85195 °C
Cp	1.178501
Temperature	62.82534 °C
Cp	1.177406
Temperature	63.79873 °C
Cp	1.176313
Temperature	64.77211 °C
Cp	1.175239
Temperature	65.7455 °C
Cp	1.17417
Temperature	66.71888 °C
Cp	1.173105
Temperature	67.69227 °C
Cp	1.172037
Temperature	68.66566 °C
Cp	1.170989
Temperature	69.63904 °C
Cp	1.169948
Temperature	70.61243 °C
Cp	1.168905
Temperature	71.58582 °C
Cp	1.167872
Temperature	72.5592 °C
Cp	1.166849
Temperature	73.53259 °C
Cp	1.165851
Temperature	74.50597 °C
Cp	1.164848
Temperature	75.47935 °C
Cp	1.163876
Temperature	76.45274 °C
Cp	1.162926
Temperature	77.42612 °C
Cp	1.162008
Temperature	78.39951 °C
Cp	1.161113
Temperature	79.3729 °C
Cp	1.160219
Temperature	80.34628 °C
Cp	1.159377
Temperature	81.31967 °C
Cp	1.158546
Temperature	82.29306 °C
Cp	1.157726
Temperature	83.26644 °C
Cp	1.15692
Temperature	84.23983 °C
Cp	1.156126
Temperature	85.21322 °C
Cp	1.155375
Temperature	86.1866 °C
Cp	1.154604
Temperature	87.15999 °C
Cp	1.153869
Temperature	88.13337 °C
Cp	1.153158
Temperature	89.10676 °C
Cp	1.152474
Temperature	90.08015 °C
Cp	1.15181
Temperature	91.05353 °C
Cp	1.151134
Temperature	92.02692 °C
Cp	1.150513
Temperature	93.00031 °C
Cp	1.149892
Temperature	93.97369 °C
Cp	1.149266
Temperature	94.94707 °C
Cp	1.148642
Temperature	95.92046 °C
Cp	1.148019
Temperature	96.89384 °C
Cp	1.147402
Temperature	97.86723 °C
Cp	1.146799
Temperature	98.84062 °C
Cp	1.146191
Temperature	99.814 °C
Cp	1.145602
Temperature	100.7874 °C
Cp	1.14503
Temperature	101.7608 °C
Cp	1.144469
Temperature	102.7342 °C
Cp	1.143921
Temperature	103.7076 °C
Cp	1.143383
Temperature	104.6809 °C
Cp	1.142861
Temperature	105.6543 °C
Cp	1.142345
Temperature	106.6277 °C
Cp	1.141835
Temperature	107.6011 °C
Cp	1.141335
Temperature	108.5745 °C
Cp	1.140846
Temperature	109.5479 °C
Cp	1.140365
Temperature	110.5212 °C
Cp	1.139891
Temperature	111.4946 °C
Cp	1.139429
Temperature	112.468 °C
Cp	1.138976
Temperature	113.4414 °C
Cp	1.13853
Temperature	114.4148 °C
Cp	1.138092
Temperature	115.3882 °C
Cp	1.137654
Temperature	116.3616 °C
Cp	1.137223
Temperature	117.335 °C
Cp	1.136785
Temperature	118.3083 °C
Cp	1.136338
Temperature	119.2817 °C
Cp	1.13588
Temperature	120.2551 °C
Cp	1.13541
Temperature	121.2285 °C
Cp	1.134927
Temperature	122.2019 °C
Cp	1.134417
Temperature	123.1753 °C
Cp	1.133892
Temperature	124.1487 °C
Cp	1.133347
Temperature	125.122 °C
Cp	1.132786
Temperature	126.0954 °C
Cp	1.132206
Temperature	127.0688 °C
Cp	1.131606
Temperature	128.0422 °C
Cp	1.130999
Temperature	129.0156 °C
Cp	1.130384
Temperature	129.989 °C
Cp	1.129765
Temperature	130.9624 °C
Cp	1.129147
Temperature	131.9357 °C
Cp	1.12854
Temperature	132.9091 °C
Cp	1.127949
Temperature	133.8825 °C
Cp	1.127383
Temperature	134.8559 °C
Cp	1.126841
Temperature	135.8293 °C
Cp	1.126334
Temperature	136.8027 °C
Cp	1.125871
Temperature	137.7761 °C
Cp	1.125443
Temperature	138.7494 °C
Cp	1.125058
Temperature	139.7228 °C
Cp	1.124701
Temperature	140.6962 °C
Cp	1.124397
Temperature	141.6696 °C
Cp	1.124114
Temperature	142.643 °C
Cp	1.123854
Temperature	143.6164 °C
Cp	1.123612
Temperature	144.5898 °C
Cp	1.123385
Temperature	145.5631 °C
Cp	1.123182
Temperature	146.5365 °C
Cp	1.12296
Temperature	147.5099 °C
Cp	1.12275
Temperature	148.4833 °C
Cp	1.122543
Temperature	149.4567 °C
Cp	1.122327
Temperature	150.4301 °C
Cp	1.122099
Temperature	151.4035 °C
Cp	1.121837
Temperature	152.3768 °C
Cp	1.121582
Temperature	153.3502 °C
Cp	1.121289
Temperature	154.3236 °C
Cp	1.120967
Temperature	155.297 °C
Cp	1.120616
Temperature	156.2704 °C
Cp	1.120238
Temperature	157.2438 °C
Cp	1.119862
Temperature	158.2172 °C
Cp	1.119444
Temperature	159.1906 °C
Cp	1.119028
Temperature	160.1639 °C
Cp	1.118613
Temperature	161.1373 °C
Cp	1.118202
Temperature	162.1107 °C
Cp	1.117795
Temperature	163.0841 °C
Cp	1.117374
Temperature	164.0575 °C
Cp	1.116987
Temperature	165.0309 °C
Cp	1.116595
Temperature	166.0042 °C
Cp	1.116198
Temperature	166.9776 °C
Cp	1.1158
Temperature	167.951 °C
Cp	1.115402
Temperature	168.9244 °C
Cp	1.115006
Temperature	169.8978 °C
Cp	1.11462
Temperature	170.8712 °C
Cp	1.114223
Temperature	171.8446 °C
Cp	1.113836
Temperature	172.8179 °C
Cp	1.113458
Temperature	173.7913 °C
Cp	1.113085
Temperature	174.7647 °C
Cp	1.112712
Temperature	175.7381 °C
Cp	1.112323
Temperature	176.7115 °C
Cp	1.111957
Temperature	177.6849 °C
Cp	1.111578
Temperature	178.6583 °C
Cp	1.111185
Temperature	179.6317 °C
Cp	1.110789
Temperature	180.605 °C
Cp	1.110391
Temperature	181.5784 °C
Cp	1.110016
Temperature	182.5518 °C
Cp	1.109611
Temperature	183.5252 °C
Cp	1.109232
Temperature	184.4986 °C
Cp	1.108873
Temperature	185.472 °C
Cp	1.108531
Temperature	186.4454 °C
Cp	1.108199
Temperature	187.4187 °C
Cp	1.107851
Temperature	188.3921 °C
Cp	1.107551
Temperature	189.3655 °C
Cp	1.107238
Temperature	190.3389 °C
Cp	1.106917
Temperature	191.3123 °C
Cp	1.106589
Temperature	192.2857 °C
Cp	1.106259
Temperature	193.259 °C
Cp	1.105958
Temperature	194.2324 °C
Cp	1.105619
Temperature	195.2058 °C
Cp	1.105301
Temperature	196.1792 °C
Cp	1.105002
Temperature	197.1526 °C
Cp	1.104718
Temperature	198.126 °C
Cp	1.104445
Temperature	199.0994 °C
Cp	1.104161
Temperature	200.0728 °C
Cp	1.103914
Temperature	201.0461 °C
Cp	1.103657
Temperature	202.0195 °C
Cp	1.103395
Temperature	202.9929 °C
Cp	1.103125
Temperature	203.9663 °C
Cp	1.102847
Temperature	204.9397 °C
Cp	1.102563
Temperature	205.9131 °C
Cp	1.102283
Temperature	206.8865 °C
Cp	1.101985
Temperature	207.8598 °C
Cp	1.10169
Temperature	208.8332 °C
Cp	1.101394
Temperature	209.8066 °C
Cp	1.101099
Temperature	210.78 °C
Cp	1.1008
Temperature	211.7534 °C
Cp	1.10049
Temperature	212.7268 °C
Cp	1.100193
Temperature	213.7002 °C
Cp	1.099886
Temperature	214.6735 °C
Cp	1.099577
Temperature	215.6469 °C
Cp	1.099268
Temperature	216.6203 °C
Cp	1.098965
Temperature	217.5937 °C
Cp	1.098685
Temperature	218.5671 °C
Cp	1.098396
Temperature	219.5405 °C
Cp	1.098134
Temperature	220.5139 °C
Cp	1.097895
Temperature	221.4872 °C
Cp	1.09768
Temperature	222.4606 °C
Cp	1.097485
Temperature	223.434 °C
Cp	1.097292
Temperature	224.4074 °C
Cp	1.09714
Temperature	225.3808 °C
Cp	1.096991
Temperature	226.3542 °C
Cp	1.096844
Temperature	227.3276 °C
Cp	1.096699
Temperature	228.3009 °C
Cp	1.096559
Temperature	229.2743 °C
Cp	1.096442
Temperature	230.2477 °C
Cp	1.096296
Temperature	231.2211 °C
Cp	1.096164
Temperature	232.1945 °C
Cp	1.09604
Temperature	233.1679 °C
Cp	1.095924
Temperature	234.1413 °C
Cp	1.095807
Temperature	235.1147 °C
Cp	1.095665
Temperature	236.088 °C
Cp	1.095557
Temperature	237.0614 °C
Cp	1.095433
Temperature	238.0348 °C
Cp	1.095296
Temperature	239.0082 °C
Cp	1.095147
Temperature	239.9816 °C
Cp	1.094995
Temperature	240.955 °C
Cp	1.094843
Temperature	241.9283 °C
Cp	1.094705
Temperature	242.9017 °C
Cp	1.094562
Temperature	243.8751 °C
Cp	1.094442
Temperature	244.8485 °C
Cp	1.094344
Temperature	245.8219 °C
Cp	1.094266
Temperature	246.7953 °C
Cp	1.094209
Temperature	247.7687 °C
Cp	1.094161
Temperature	248.7421 °C
Cp	1.094144
Temperature	249.7154 °C
Cp	1.094133
Temperature	250.6888 °C
Cp	1.094127
Temperature	251.6622 °C
Cp	1.094126
Temperature	252.6356 °C
Cp	1.094127
Temperature	253.609 °C
Cp	1.094138
Temperature	254.5824 °C
Cp	1.09413
Temperature	255.5558 °C
Cp	1.094123
Temperature	256.5291 °C
Cp	1.094111
Temperature	257.5025 °C
Cp	1.094087
Temperature	258.4759 °C
Cp	1.094046
Temperature	259.4493 °C
Cp	1.093978
Temperature	260.4227 °C
Cp	1.093895
Temperature	261.3961 °C
Cp	1.093783
Temperature	262.3694 °C
Cp	1.093645
Temperature	263.3428 °C
Cp	1.093483
Temperature	264.3162 °C
Cp	1.093302
Temperature	265.2896 °C
Cp	1.093109
Temperature	266.263 °C
Cp	1.092906
Temperature	267.2364 °C
Cp	1.092704
Temperature	268.2098 °C
Cp	1.092511
Temperature	269.1832 °C
Cp	1.092331
Temperature	270.1566 °C
Cp	1.092174
Temperature	271.1299 °C
Cp	1.092046
Temperature	272.1033 °C
Cp	1.091947
Temperature	273.0767 °C
Cp	1.091882
Temperature	274.0501 °C
Cp	1.091853
Temperature	275.0235 °C
Cp	1.091859
Temperature	275.9969 °C
Cp	1.091895
Temperature	276.9702 °C
Cp	1.091957
Temperature	277.9436 °C
Cp	1.092036
Temperature	278.917 °C
Cp	1.092132
Temperature	279.8904 °C
Cp	1.09223
Temperature	280.8638 °C
Cp	1.092323
Temperature	281.8372 °C
Cp	1.092405
Temperature	282.8105 °C
Cp	1.092468
Temperature	283.7839 °C
Cp	1.092513
Temperature	284.7573 °C
Cp	1.092525
Temperature	285.7307 °C
Cp	1.092512
Temperature	286.7041 °C
Cp	1.092472
Temperature	287.6775 °C
Cp	1.092405
Temperature	288.6509 °C
Cp	1.092313
Temperature	289.6243 °C
Cp	1.092197
Temperature	290.5977 °C
Cp	1.09207
Temperature	291.571 °C
Cp	1.091931
Temperature	292.5444 °C
Cp	1.091785
Temperature	293.5178 °C
Cp	1.091641
Temperature	294.4912 °C
Cp	1.091506
Temperature	295.4646 °C
Cp	1.091387
Temperature	296.438 °C
Cp	1.091282
Temperature	297.4113 °C
Cp	1.091201
Temperature	298.3847 °C
Cp	1.091145
Temperature	299.3581 °C
Cp	1.091112
Temperature	300.3315 °C
Cp	1.091102
Temperature	301.3049 °C
Cp	1.091107
Temperature	302.2783 °C
Cp	1.091137
Temperature	303.2517 °C
Cp	1.091177
Temperature	304.2251 °C
Cp	1.091226
Temperature	305.1984 °C
Cp	1.09128
Temperature	306.1718 °C
Cp	1.091336
Temperature	307.1452 °C
Cp	1.091403
Temperature	308.1186 °C
Cp	1.091453
Temperature	309.092 °C
Cp	1.091506
Temperature	310.0654 °C
Cp	1.091561
Temperature	311.0388 °C
Cp	1.091617
Temperature	312.0121 °C
Cp	1.09167
Temperature	312.9855 °C
Cp	1.091716
Temperature	313.9589 °C
Cp	1.091762
Temperature	314.9323 °C
Cp	1.091805
Temperature	315.9057 °C
Cp	1.091838
Temperature	316.8791 °C
Cp	1.09186
Temperature	317.8524 °C
Cp	1.091871
Temperature	318.8258 °C
Cp	1.091872
Temperature	319.7992 °C
Cp	1.091867
Temperature	320.7726 °C
Cp	1.091838
Temperature	321.746 °C
Cp	1.0918
Temperature	322.7194 °C
Cp	1.091752
Temperature	323.6928 °C
Cp	1.091689
Temperature	324.6662 °C
Cp	1.091611
Temperature	325.6396 °C
Cp	1.091508
Temperature	326.6129 °C
Cp	1.091406
Temperature	327.5863 °C
Cp	1.091285
Temperature	328.5597 °C
Cp	1.09115
Temperature	329.5331 °C
Cp	1.091009
Temperature	330.5065 °C
Cp	1.09087
Temperature	331.4799 °C
Cp	1.090747
Temperature	332.4532 °C
Cp	1.090628
Temperature	333.4266 °C
Cp	1.090536
Temperature	334.4 °C
Cp	1.090472
Temperature	335.3734 °C
Cp	1.090437
Temperature	336.3468 °C
Cp	1.090431
Temperature	337.3202 °C
Cp	1.090455
Temperature	338.2935 °C
Cp	1.090503
Temperature	339.2669 °C
Cp	1.090573
Temperature	340.2403 °C
Cp	1.090658
Temperature	341.2137 °C
Cp	1.090753
Temperature	342.1871 °C
Cp	1.090853
Temperature	343.1605 °C
Cp	1.090952
Temperature	344.1339 °C
Cp	1.09105
Temperature	345.1073 °C
Cp	1.091141
Temperature	346.0807 °C
Cp	1.091225
Temperature	347.054 °C
Cp	1.091303
Temperature	348.0274 °C
Cp	1.091379
Temperature	349.0008 °C
Cp	1.091453
Temperature	349.9742 °C
Cp	1.091537
Temperature	350.9476 °C
Cp	1.091633
Temperature	351.921 °C
Cp	1.091743
Temperature	352.8943 °C
Cp	1.091874
Temperature	353.8677 °C
Cp	1.092028
Temperature	354.8411 °C
Cp	1.092206
Temperature	355.8145 °C
Cp	1.092411
Temperature	356.7879 °C
Cp	1.092628
Temperature	357.7613 °C
Cp	1.092862
Temperature	358.7346 °C
Cp	1.093102
Temperature	359.708 °C
Cp	1.093338
Temperature	360.6814 °C
Cp	1.093559
Temperature	361.6548 °C
Cp	1.093752
Temperature	362.6282 °C
Cp	1.093915
Temperature	363.6016 °C
Cp	1.094036
Temperature	364.575 °C
Cp	1.094117
Temperature	365.5484 °C
Cp	1.094159
Temperature	366.5218 °C
Cp	1.094172
Temperature	367.4951 °C
Cp	1.094165
Temperature	368.4685 °C
Cp	1.094163
Temperature	369.4419 °C
Cp	1.094182
Temperature	370.4153 °C
Cp	1.094244
Temperature	371.3887 °C
Cp	1.094375
Temperature	372.3621 °C
Cp	1.094598
Temperature	373.3354 °C
Cp	1.094937
Temperature	374.3088 °C
Cp	1.095389
Temperature	375.2822 °C
Cp	1.095973
Temperature	376.2556 °C
Cp	1.096685
Temperature	377.229 °C
Cp	1.097506
Temperature	378.2024 °C
Cp	1.098406
Temperature	379.1758 °C
Cp	1.099338
Temperature	380.1492 °C
Cp	1.10027
Temperature	381.1225 °C
Cp	1.10112
Temperature	382.0959 °C
Cp	1.101818
Temperature	383.0693 °C
Cp	1.10229
Temperature	384.0427 °C
Cp	1.102459
Temperature	385.0161 °C
Cp	1.102253
Temperature	385.9895 °C
Cp	1.101596
Temperature	386.9629 °C
Cp	1.100438
Temperature	387.9362 °C
Cp	1.098736
Temperature	388.9096 °C
Cp	1.096461
Temperature	389.883 °C
Cp	1.093614
Temperature	390.8564 °C
Cp	1.090208
Temperature	391.8298 °C
Cp	1.086278
Temperature	392.8032 °C
Cp	1.081887
Temperature	393.7766 °C
Cp	1.077096
Temperature	394.7499 °C
Cp	1.072007
Temperature	395.7233 °C
Cp	1.066707
[Rev Cp Calibration]
Date Applied	24/10/2024 12:37:31
Description	From -89.998 °C to 390.542 °C at 2.000°C/min
Gas Type	Nitrogen
Pan Type	Tzero Aluminum
Source Files 1	C:\ProgramData\TA Instruments\TRIOS\Data\Reverse Heat Capacity Calibration(6).tri
GUID	ba867d72-cfbb-486e-971e-e86aa544cc02
Temperature	-89.99799 °C
Cp	1.070076
Temperature	-89.03691 °C
Cp	1.072008
Temperature	-88.07584 °C
Cp	1.073556
Temperature	-87.11475 °C
Cp	1.074743
Temperature	-86.15367 °C
Cp	1.075597
Temperature	-85.1926 °C
Cp	1.076163
Temperature	-84.23151 °C
Cp	1.076477
Temperature	-83.27043 °C
Cp	1.076579
Temperature	-82.30936 °C
Cp	1.076527
Temperature	-81.34827 °C
Cp	1.076322
Temperature	-80.38719 °C
Cp	1.076039
Temperature	-79.42612 °C
Cp	1.07571
Temperature	-78.46503 °C
Cp	1.075361
Temperature	-77.50395 °C
Cp	1.075011
Temperature	-76.54288 °C
Cp	1.074656
Temperature	-75.58179 °C
Cp	1.074359
Temperature	-74.62071 °C
Cp	1.074086
Temperature	-73.65964 °C
Cp	1.073842
Temperature	-72.69855 °C
Cp	1.073627
Temperature	-71.73747 °C
Cp	1.073442
Temperature	-70.7764 °C
Cp	1.07329
Temperature	-69.81532 °C
Cp	1.073148
Temperature	-68.85423 °C
Cp	1.073021
Temperature	-67.89315 °C
Cp	1.072902
Temperature	-66.93208 °C
Cp	1.072782
Temperature	-65.97099 °C
Cp	1.072656
Temperature	-65.00991 °C
Cp	1.072518
Temperature	-64.04884 °C
Cp	1.072374
Temperature	-63.08775 °C
Cp	1.072201
Temperature	-62.12667 °C
Cp	1.072019
Temperature	-61.1656 °C
Cp	1.071827
Temperature	-60.20451 °C
Cp	1.071624
Temperature	-59.24343 °C
Cp	1.071411
Temperature	-58.28236 °C
Cp	1.071167
Temperature	-57.32127 °C
Cp	1.070956
Temperature	-56.3602 °C
Cp	1.070724
Temperature	-55.39911 °C
Cp	1.070483
Temperature	-54.43803 °C
Cp	1.070242
Temperature	-53.47696 °C
Cp	1.070009
Temperature	-52.51587 °C
Cp	1.069825
Temperature	-51.55479 °C
Cp	1.069601
Temperature	-50.59372 °C
Cp	1.069418
Temperature	-49.63263 °C
Cp	1.069267
Temperature	-48.67155 °C
Cp	1.069138
Temperature	-47.71048 °C
Cp	1.069021
Temperature	-46.74939 °C
Cp	1.068875
Temperature	-45.78831 °C
Cp	1.068771
Temperature	-44.82724 °C
Cp	1.068634
Temperature	-43.86615 °C
Cp	1.068462
Temperature	-42.90508 °C
Cp	1.068255
Temperature	-41.944 °C
Cp	1.068012
Temperature	-40.98291 °C
Cp	1.067742
Temperature	-40.02184 °C
Cp	1.067427
Temperature	-39.06076 °C
Cp	1.067088
Temperature	-38.09967 °C
Cp	1.066727
Temperature	-37.1386 °C
Cp	1.066349
Temperature	-36.17752 °C
Cp	1.065958
Temperature	-35.21643 °C
Cp	1.065559
Temperature	-34.25536 °C
Cp	1.065162
Temperature	-33.29427 °C
Cp	1.06476
Temperature	-32.33319 °C
Cp	1.064368
Temperature	-31.37212 °C
Cp	1.06399
Temperature	-30.41104 °C
Cp	1.063628
Temperature	-29.44995 °C
Cp	1.063283
Temperature	-28.48887 °C
Cp	1.06295
Temperature	-27.5278 °C
Cp	1.062645
Temperature	-26.56672 °C
Cp	1.062355
Temperature	-25.60563 °C
Cp	1.06208
Temperature	-24.64456 °C
Cp	1.061819
Temperature	-23.68348 °C
Cp	1.061573
Temperature	-22.72239 °C
Cp	1.061345
Temperature	-21.76132 °C
Cp	1.061123
Temperature	-20.80024 °C
Cp	1.060915
Temperature	-19.83916 °C
Cp	1.060719
Temperature	-18.87807 °C
Cp	1.060531
Temperature	-17.917 °C
Cp	1.06035
Temperature	-16.95592 °C
Cp	1.060161
Temperature	-15.99484 °C
Cp	1.059992
Temperature	-15.03376 °C
Cp	1.059817
Temperature	-14.07268 °C
Cp	1.059634
Temperature	-13.1116 °C
Cp	1.059445
Temperature	-12.15052 °C
Cp	1.059248
Temperature	-11.18944 °C
Cp	1.059043
Temperature	-10.22836 °C
Cp	1.058842
Temperature	-9.267276 °C
Cp	1.058615
Temperature	-8.306196 °C
Cp	1.058388
Temperature	-7.345116 °C
Cp	1.058155
Temperature	-6.384036 °C
Cp	1.057911
Temperature	-5.422956 °C
Cp	1.057652
Temperature	-4.461876 °C
Cp	1.057356
Temperature	-3.500796 °C
Cp	1.057063
Temperature	-2.539716 °C
Cp	1.056732
Temperature	-1.578636 °C
Cp	1.056364
Temperature	-0.6175562 °C
Cp	1.05596
Temperature	0.3435238 °C
Cp	1.055523
Temperature	1.304604 °C
Cp	1.055066
Temperature	2.265684 °C
Cp	1.054561
Temperature	3.226764 °C
Cp	1.054035
Temperature	4.187844 °C
Cp	1.053488
Temperature	5.148924 °C
Cp	1.052922
Temperature	6.110003 °C
Cp	1.052337
Temperature	7.071084 °C
Cp	1.051736
Temperature	8.032164 °C
Cp	1.051118
Temperature	8.993243 °C
Cp	1.050488
Temperature	9.954324 °C
Cp	1.049848
Temperature	10.9154 °C
Cp	1.049202
Temperature	11.87648 °C
Cp	1.048552
Temperature	12.83756 °C
Cp	1.047902
Temperature	13.79864 °C
Cp	1.047255
Temperature	14.75972 °C
Cp	1.046615
Temperature	15.7208 °C
Cp	1.045983
Temperature	16.68188 °C
Cp	1.045362
Temperature	17.64296 °C
Cp	1.044756
Temperature	18.60404 °C
Cp	1.044164
Temperature	19.56512 °C
Cp	1.04358
Temperature	20.5262 °C
Cp	1.043027
Temperature	21.48728 °C
Cp	1.042485
Temperature	22.44836 °C
Cp	1.041958
Temperature	23.40944 °C
Cp	1.041446
Temperature	24.37052 °C
Cp	1.040952
Temperature	25.3316 °C
Cp	1.040493
Temperature	26.29268 °C
Cp	1.040022
Temperature	27.25376 °C
Cp	1.039578
Temperature	28.21484 °C
Cp	1.039158
Temperature	29.17592 °C
Cp	1.038758
Temperature	30.137 °C
Cp	1.038373
Temperature	31.09808 °C
Cp	1.037981
Temperature	32.05916 °C
Cp	1.03763
Temperature	33.02024 °C
Cp	1.037276
Temperature	33.98132 °C
Cp	1.03692
Temperature	34.9424 °C
Cp	1.036565
Temperature	35.90348 °C
Cp	1.036213
Temperature	36.86456 °C
Cp	1.035866
Temperature	37.82564 °C
Cp	1.035529
Temperature	38.78672 °C
Cp	1.035195
Temperature	39.7478 °C
Cp	1.034875
Temperature	40.70888 °C
Cp	1.034568
Temperature	41.66996 °C
Cp	1.034276
Temperature	42.63104 °C
Cp	1.033996
Temperature	43.59212 °C
Cp	1.033726
Temperature	44.5532 °C
Cp	1.033469
Temperature	45.51428 °C
Cp	1.033221
Temperature	46.47536 °C
Cp	1.03298
Temperature	47.43644 °C
Cp	1.032744
Temperature	48.39752 °C
Cp	1.032514
Temperature	49.3586 °C
Cp	1.032289
Temperature	50.31968 °C
Cp	1.032065
Temperature	51.28076 °C
Cp	1.031844
Temperature	52.24184 °C
Cp	1.031627
Temperature	53.20292 °C
Cp	1.031413
Temperature	54.164 °C
Cp	1.031203
Temperature	55.12508 °C
Cp	1.030989
Temperature	56.08616 °C
Cp	1.030791
Temperature	57.04724 °C
Cp	1.030595
Temperature	58.00832 °C
Cp	1.030403
Temperature	58.9694 °C
Cp	1.030217
Temperature	59.93048 °C
Cp	1.03004
Temperature	60.89156 °C
Cp	1.029871
Temperature	61.85264 °C
Cp	1.029718
Temperature	62.81372 °C
Cp	1.029567
Temperature	63.7748 °C
Cp	1.02943
Temperature	64.73589 °C
Cp	1.029304
Temperature	65.69696 °C
Cp	1.029185
Temperature	66.65804 °C
Cp	1.02907
Temperature	67.61913 °C
Cp	1.028946
Temperature	68.5802 °C
Cp	1.028831
Temperature	69.54128 °C
Cp	1.028703
Temperature	70.50237 °C
Cp	1.028561
Temperature	71.46344 °C
Cp	1.028404
Temperature	72.42452 °C
Cp	1.028234
Temperature	73.3856 °C
Cp	1.028063
Temperature	74.34668 °C
Cp	1.027861
Temperature	75.30776 °C
Cp	1.027657
Temperature	76.26884 °C
Cp	1.027451
Temperature	77.22992 °C
Cp	1.027243
Temperature	78.191 °C
Cp	1.027036
Temperature	79.15208 °C
Cp	1.026812
Temperature	80.11316 °C
Cp	1.026623
Temperature	81.07424 °C
Cp	1.026431
Temperature	82.03532 °C
Cp	1.026241
Temperature	82.9964 °C
Cp	1.02606
Temperature	83.95748 °C
Cp	1.025891
Temperature	84.91856 °C
Cp	1.025739
Temperature	85.87964 °C
Cp	1.025614
Temperature	86.84072 °C
Cp	1.025493
Temperature	87.8018 °C
Cp	1.0254
Temperature	88.76288 °C
Cp	1.025329
Temperature	89.72396 °C
Cp	1.025274
Temperature	90.68504 °C
Cp	1.025229
Temperature	91.64612 °C
Cp	1.025174
Temperature	92.6072 °C
Cp	1.025138
Temperature	93.56828 °C
Cp	1.025083
Temperature	94.52936 °C
Cp	1.025008
Temperature	95.49044 °C
Cp	1.024912
Temperature	96.45152 °C
Cp	1.024796
Temperature	97.4126 °C
Cp	1.024671
Temperature	98.37368 °C
Cp	1.024506
Temperature	99.33476 °C
Cp	1.02433
Temperature	100.2958 °C
Cp	1.024144
Temperature	101.2569 °C
Cp	1.023948
Temperature	102.218 °C
Cp	1.023743
Temperature	103.1791 °C
Cp	1.023522
Temperature	104.1402 °C
Cp	1.023309
Temperature	105.1012 °C
Cp	1.023089
Temperature	106.0623 °C
Cp	1.022866
Temperature	107.0234 °C
Cp	1.022644
Temperature	107.9845 °C
Cp	1.022427
Temperature	108.9456 °C
Cp	1.022218
Temperature	109.9066 °C
Cp	1.022022
Temperature	110.8677 °C
Cp	1.021836
Temperature	111.8288 °C
Cp	1.021666
Temperature	112.7899 °C
Cp	1.021512
Temperature	113.751 °C
Cp	1.021374
Temperature	114.712 °C
Cp	1.02125
Temperature	115.6731 °C
Cp	1.021137
Temperature	116.6342 °C
Cp	1.021041
Temperature	117.5953 °C
Cp	1.020953
Temperature	118.5564 °C
Cp	1.020872
Temperature	119.5174 °C
Cp	1.020796
Temperature	120.4785 °C
Cp	1.020725
Temperature	121.4396 °C
Cp	1.020659
Temperature	122.4007 °C
Cp	1.020587
Temperature	123.3618 °C
Cp	1.020515
Temperature	124.3228 °C
Cp	1.02044
Temperature	125.2839 °C
Cp	1.020359
Temperature	126.245 °C
Cp	1.02027
Temperature	127.2061 °C
Cp	1.020167
Temperature	128.1672 °C
Cp	1.020057
Temperature	129.1282 °C
Cp	1.019933
Temperature	130.0893 °C
Cp	1.019793
Temperature	131.0504 °C
Cp	1.019638
Temperature	132.0115 °C
Cp	1.019471
Temperature	132.9726 °C
Cp	1.019292
Temperature	133.9336 °C
Cp	1.019107
Temperature	134.8947 °C
Cp	1.018912
Temperature	135.8558 °C
Cp	1.018717
Temperature	136.8169 °C
Cp	1.018527
Temperature	137.778 °C
Cp	1.018344
Temperature	138.739 °C
Cp	1.018171
Temperature	139.7001 °C
Cp	1.018004
Temperature	140.6612 °C
Cp	1.01787
Temperature	141.6223 °C
Cp	1.01775
Temperature	142.5834 °C
Cp	1.017652
Temperature	143.5444 °C
Cp	1.017578
Temperature	144.5055 °C
Cp	1.017534
Temperature	145.4666 °C
Cp	1.017536
Temperature	146.4277 °C
Cp	1.017545
Temperature	147.3888 °C
Cp	1.017595
Temperature	148.3498 °C
Cp	1.017679
Temperature	149.3109 °C
Cp	1.01779
Temperature	150.272 °C
Cp	1.01792
Temperature	151.2331 °C
Cp	1.018043
Temperature	152.1942 °C
Cp	1.018199
Temperature	153.1552 °C
Cp	1.018339
Temperature	154.1163 °C
Cp	1.018458
Temperature	155.0774 °C
Cp	1.018552
Temperature	156.0385 °C
Cp	1.018618
Temperature	156.9996 °C
Cp	1.018662
Temperature	157.9606 °C
Cp	1.018664
Temperature	158.9217 °C
Cp	1.018632
Temperature	159.8828 °C
Cp	1.018575
Temperature	160.8439 °C
Cp	1.018492
Temperature	161.805 °C
Cp	1.018383
Temperature	162.766 °C
Cp	1.01825
Temperature	163.7271 °C
Cp	1.018087
Temperature	164.6882 °C
Cp	1.017917
Temperature	165.6493 °C
Cp	1.017726
Temperature	166.6104 °C
Cp	1.017522
Temperature	167.5714 °C
Cp	1.01731
Temperature	168.5325 °C
Cp	1.017098
Temperature	169.4936 °C
Cp	1.016902
Temperature	170.4547 °C
Cp	1.016695
Temperature	171.4158 °C
Cp	1.016508
Temperature	172.3768 °C
Cp	1.016342
Temperature	173.3379 °C
Cp	1.016195
Temperature	174.299 °C
Cp	1.016065
Temperature	175.2601 °C
Cp	1.015927
Temperature	176.2212 °C
Cp	1.015838
Temperature	177.1822 °C
Cp	1.015746
Temperature	178.1433 °C
Cp	1.015651
Temperature	179.1044 °C
Cp	1.015555
Temperature	180.0655 °C
Cp	1.015459
Temperature	181.0266 °C
Cp	1.015401
Temperature	181.9876 °C
Cp	1.015288
Temperature	182.9487 °C
Cp	1.015195
Temperature	183.9098 °C
Cp	1.015117
Temperature	184.8709 °C
Cp	1.01505
Temperature	185.832 °C
Cp	1.014988
Temperature	186.793 °C
Cp	1.014927
Temperature	187.7541 °C
Cp	1.014849
Temperature	188.7152 °C
Cp	1.014789
Temperature	189.6763 °C
Cp	1.01471
Temperature	190.6374 °C
Cp	1.014614
Temperature	191.5984 °C
Cp	1.014503
Temperature	192.5595 °C
Cp	1.014381
Temperature	193.5206 °C
Cp	1.014268
Temperature	194.4817 °C
Cp	1.014122
Temperature	195.4428 °C
Cp	1.013984
Temperature	196.4038 °C
Cp	1.013853
Temperature	197.3649 °C
Cp	1.013726
Temperature	198.326 °C
Cp	1.013603
Temperature	199.2871 °C
Cp	1.013467
Temperature	200.2482 °C
Cp	1.013359
Temperature	201.2092 °C
Cp	1.013243
Temperature	202.1703 °C
Cp	1.013123
Temperature	203.1314 °C
Cp	1.013002
Temperature	204.0925 °C
Cp	1.012884
Temperature	205.0536 °C
Cp	1.012788
Temperature	206.0146 °C
Cp	1.012674
Temperature	206.9757 °C
Cp	1.012579
Temperature	207.9368 °C
Cp	1.012501
Temperature	208.8979 °C
Cp	1.012439
Temperature	209.859 °C
Cp	1.012389
Temperature	210.82 °C
Cp	1.012351
Temperature	211.7811 °C
Cp	1.012312
Temperature	212.7422 °C
Cp	1.01229
Temperature	213.7033 °C
Cp	1.012262
Temperature	214.6644 °C
Cp	1.012227
Temperature	215.6254 °C
Cp	1.012183
Temperature	216.5865 °C
Cp	1.012129
Temperature	217.5476 °C
Cp	1.012077
Temperature	218.5087 °C
Cp	1.01199
Temperature	219.4698 °C
Cp	1.011897
Temperature	220.4308 °C
Cp	1.011793
Temperature	221.3919 °C
Cp	1.011674
Temperature	222.353 °C
Cp	1.011537
Temperature	223.3141 °C
Cp	1.011362
Temperature	224.2752 °C
Cp	1.011194
Temperature	225.2362 °C
Cp	1.010993
Temperature	226.1973 °C
Cp	1.010766
Temperature	227.1584 °C
Cp	1.010517
Temperature	228.1195 °C
Cp	1.010251
Temperature	229.0806 °C
Cp	1.009998
Temperature	230.0416 °C
Cp	1.009703
Temperature	231.0027 °C
Cp	1.009422
Temperature	231.9638 °C
Cp	1.009156
Temperature	232.9249 °C
Cp	1.008906
Temperature	233.886 °C
Cp	1.008675
Temperature	234.847 °C
Cp	1.008462
Temperature	235.8081 °C
Cp	1.008258
Temperature	236.7692 °C
Cp	1.00809
Temperature	237.7303 °C
Cp	1.007934
Temperature	238.6914 °C
Cp	1.007793
Temperature	239.6524 °C
Cp	1.007668
Temperature	240.6135 °C
Cp	1.007562
Temperature	241.5746 °C
Cp	1.007487
Temperature	242.5357 °C
Cp	1.00741
Temperature	243.4967 °C
Cp	1.00736
Temperature	244.4578 °C
Cp	1.007332
Temperature	245.4189 °C
Cp	1.007321
Temperature	246.38 °C
Cp	1.007321
Temperature	247.3411 °C
Cp	1.007312
Temperature	248.3022 °C
Cp	1.007331
Temperature	249.2632 °C
Cp	1.007338
Temperature	250.2243 °C
Cp	1.007335
Temperature	251.1854 °C
Cp	1.00732
Temperature	252.1465 °C
Cp	1.007295
Temperature	253.1076 °C
Cp	1.007277
Temperature	254.0686 °C
Cp	1.007227
Temperature	255.0297 °C
Cp	1.007179
Temperature	255.9908 °C
Cp	1.007133
Temperature	256.9519 °C
Cp	1.00709
Temperature	257.913 °C
Cp	1.007049
Temperature	258.874 °C
Cp	1.007012
Temperature	259.8351 °C
Cp	1.006978
Temperature	260.7962 °C
Cp	1.006956
Temperature	261.7573 °C
Cp	1.00694
Temperature	262.7184 °C
Cp	1.006934
Temperature	263.6794 °C
Cp	1.006939
Temperature	264.6405 °C
Cp	1.00696
Temperature	265.6016 °C
Cp	1.006999
Temperature	266.5627 °C
Cp	1.007054
Temperature	267.5237 °C
Cp	1.007131
Temperature	268.4848 °C
Cp	1.00723
Temperature	269.4459 °C
Cp	1.00735
Temperature	270.407 °C
Cp	1.007493
Temperature	271.3681 °C
Cp	1.007656
Temperature	272.3292 °C
Cp	1.007839
Temperature	273.2902 °C
Cp	1.008039
Temperature	274.2513 °C
Cp	1.008257
Temperature	275.2124 °C
Cp	1.008488
Temperature	276.1735 °C
Cp	1.008731
Temperature	277.1346 °C
Cp	1.008977
Temperature	278.0956 °C
Cp	1.009237
Temperature	279.0567 °C
Cp	1.009498
Temperature	280.0178 °C
Cp	1.009757
Temperature	280.9789 °C
Cp	1.010014
Temperature	281.9399 °C
Cp	1.010267
Temperature	282.901 °C
Cp	1.010515
Temperature	283.8621 °C
Cp	1.01076
Temperature	284.8232 °C
Cp	1.010993
Temperature	285.7843 °C
Cp	1.011222
Temperature	286.7454 °C
Cp	1.011447
Temperature	287.7064 °C
Cp	1.011665
Temperature	288.6675 °C
Cp	1.011876
Temperature	289.6286 °C
Cp	1.012079
Temperature	290.5897 °C
Cp	1.01228
Temperature	291.5508 °C
Cp	1.012474
Temperature	292.5118 °C
Cp	1.012662
Temperature	293.4729 °C
Cp	1.012846
Temperature	294.434 °C
Cp	1.013028
Temperature	295.3951 °C
Cp	1.013211
Temperature	296.3561 °C
Cp	1.013391
Temperature	297.3172 °C
Cp	1.013574
Temperature	298.2783 °C
Cp	1.013759
Temperature	299.2394 °C
Cp	1.013947
Temperature	300.2005 °C
Cp	1.014136
Temperature	301.1616 °C
Cp	1.01432
Temperature	302.1226 °C
Cp	1.014511
Temperature	303.0837 °C
Cp	1.014695
Temperature	304.0448 °C
Cp	1.014872
Temperature	305.0059 °C
Cp	1.01504
Temperature	305.9669 °C
Cp	1.015198
Temperature	306.928 °C
Cp	1.015343
Temperature	307.8891 °C
Cp	1.015479
Temperature	308.8502 °C
Cp	1.015595
Temperature	309.8113 °C
Cp	1.015699
Temperature	310.7724 °C
Cp	1.015789
Temperature	311.7334 °C
Cp	1.015865
Temperature	312.6945 °C
Cp	1.015925
Temperature	313.6556 °C
Cp	1.015964
Temperature	314.6167 °C
Cp	1.015999
Temperature	315.5778 °C
Cp	1.016018
Temperature	316.5388 °C
Cp	1.016025
Temperature	317.4999 °C
Cp	1.016024
Temperature	318.461 °C
Cp	1.01602
Temperature	319.4221 °C
Cp	1.016029
Temperature	320.3831 °C
Cp	1.016025
Temperature	321.3442 °C
Cp	1.016037
Temperature	322.3053 °C
Cp	1.016066
Temperature	323.2664 °C
Cp	1.01611
Temperature	324.2275 °C
Cp	1.016169
Temperature	325.1886 °C
Cp	1.016225
Temperature	326.1496 °C
Cp	1.016318
Temperature	327.1107 °C
Cp	1.016411
Temperature	328.0718 °C
Cp	1.016504
Temperature	329.0329 °C
Cp	1.016596
Temperature	329.994 °C
Cp	1.016687
Temperature	330.955 °C
Cp	1.016775
[...]
187.5950	111.0662	0.3381
187.6033	110.9832	0.3381
187.6117	110.9004	0.3379
187.6200	110.8170	0.3379
187.6283	110.7330	0.3378
187.6367	110.6511	0.3378
187.6450	110.5682	0.3377
187.6533	110.4838	0.3377
187.6617	110.4021	0.3376
187.6700	110.3179	0.3376
187.6783	110.2347	0.3375
187.6867	110.1519	0.3375
187.6950	110.0679	0.3375
187.7033	109.9849	0.3374
187.7117	109.9016	0.3374
187.7200	109.8188	0.3373
187.7283	109.7353	0.3373
187.7367	109.6526	0.3373
187.7450	109.5702	0.3372
187.7533	109.4876	0.3371
187.7617	109.4045	0.3371
187.7700	109.3198	0.3370
187.7783	109.2371	0.3370
187.7867	109.1539	0.3369
187.7950	109.0715	0.3368
187.8033	108.9887	0.3368
187.8117	108.9051	0.3368
187.8200	108.8219	0.3367
187.8283	108.7375	0.3367
187.8367	108.6562	0.3366
187.8450	108.5726	0.3366
187.8533	108.4888	0.3365
187.8617	108.4065	0.3365
187.8700	108.3228	0.3364
187.8783	108.2392	0.3364
187.8867	108.1557	0.3363
187.8950	108.0737	0.3363
187.9033	107.9906	0.3362
187.9117	107.9070	0.3362
187.9200	107.8230	0.3362
187.9283	107.7399	0.3361
187.9367	107.6584	0.3361
187.9450	107.5742	0.3359
187.9533	107.4902	0.3359
187.9617	107.4079	0.3358
187.9700	107.3259	0.3358
187.9783	107.2413	0.3358
187.9867	107.1584	0.3357
187.9950	107.0754	0.3357
188.0033	106.9930	0.3356
188.0117	106.9094	0.3356
188.0200	106.8260	0.3356
188.0283	106.7427	0.3355
188.0367	106.6598	0.3355
188.0450	106.5769	0.3354
188.0533	106.4937	0.3354
188.0617	106.4112	0.3353
188.0700	106.3275	0.3353
188.0783	106.2444	0.3352
188.0867	106.1606	0.3351
188.0950	106.0789	0.3351
188.1033	105.9954	0.3350
188.1117	105.9118	0.3349
188.1200	105.8285	0.3349
188.1283	105.7454	0.3349
188.1367	105.6628	0.3348
188.1450	105.5797	0.3348
188.1533	105.4963	0.3347
188.1617	105.4138	0.3346
188.1700	105.3294	0.3345
188.1783	105.2473	0.3345
188.1867	105.1646	0.3345
188.1950	105.0806	0.3344
188.2033	104.9981	0.3344
188.2117	104.9139	0.3344
188.2200	104.8297	0.3343
188.2283	104.7474	0.3343
188.2367	104.6656	0.3342
188.2450	104.5819	0.3342
188.2533	104.4988	0.3342
188.2617	104.4150	0.3341
188.2700	104.3330	0.3341
188.2783	104.2481	0.3340
188.2867	104.1661	0.3340
188.2950	104.0827	0.3340
188.3033	103.9989	0.3339
188.3117	103.9165	0.3339
188.3200	103.8329	0.3338
188.3283	103.7497	0.3338
188.3367	103.6665	0.3337
188.3450	103.5838	0.3337
188.3533	103.5007	0.3336
188.3617	103.4175	0.3336
188.3700	103.3342	0.3335
188.3783	103.2506	0.3335
188.3867	103.1681	0.3334
188.3950	103.0842	0.3334
188.4033	103.0029	0.3333
188.4117	102.9190	0.3333
188.4200	102.8357	0.3333
188.4283	102.7526	0.3332
188.4367	102.6695	0.3331
188.4450	102.5872	0.3331
188.4533	102.5036	0.3330
188.4617	102.4194	0.3329
188.4700	102.3366	0.3328
188.4783	102.2539	0.3328
188.4867	102.1699	0.3328
188.4950	102.0885	0.3327
188.5033	102.0041	0.3327
188.5117	101.9225	0.3326
188.5200	101.8381	0.3326
188.5283	101.7550	0.3326
188.5367	101.6712	0.3325
188.5450	101.5883	0.3325
188.5533	101.5059	0.3324
188.5617	101.4222	0.3323
188.5700	101.3397	0.3323
188.5783	101.2561	0.3322
188.5867	101.1738	0.3321
188.5950	101.0901	0.3320
188.6033	101.0071	0.3320
188.6117	100.9237	0.3319
188.6200	100.8403	0.3319
188.6283	100.7568	0.3318
188.6367	100.6739	0.3318
188.6450	100.5906	0.3317
188.6533	100.5078	0.3317
188.6617	100.4245	0.3316
188.6700	100.3406	0.3316
188.6783	100.2574	0.3316
188.6867	100.1749	0.3315
188.6950	100.0909	0.3315
188.7033	100.0086	0.3314
188.7117	99.9255	0.3313
188.7200	99.8427	0.3313
188.7283	99.7584	0.3313
188.7367	99.6766	0.3312
188.7450	99.5924	0.3312
188.7533	99.5088	0.3311
188.7617	99.4273	0.3310
188.7700	99.3422	0.3310
188.7783	99.2605	0.3310
188.7867	99.1766	0.3309
188.7950	99.0938	0.3309
188.8033	99.0115	0.3308
188.8117	98.9277	0.3307
188.8200	98.8447	0.3307
188.8283	98.7611	0.3306
188.8367	98.6774	0.3306
188.8450	98.5936	0.3305
188.8533	98.5119	0.3305
188.8617	98.4291	0.3304
188.8700	98.3449	0.3304
188.8783	98.2623	0.3304
188.8867	98.1798	0.3303
188.8950	98.0955	0.3303
188.9033	98.0127	0.3301
188.9117	97.9299	0.3300
188.9200	97.8460	0.3300
188.9283	97.7633	0.3298
188.9367	97.6819	0.3298
188.9450	97.5985	0.3298
188.9533	97.5141	0.3297
188.9617	97.4315	0.3296
188.9700	97.3489	0.3296
188.9783	97.2647	0.3296
188.9867	97.1815	0.3294
188.9950	97.0981	0.3293
189.0033	97.0159	0.3293
189.0117	96.9323	0.3293
189.0200	96.8499	0.3292
189.0283	96.7665	0.3292
189.0367	96.6830	0.3291
189.0450	96.5995	0.3291
189.0533	96.5164	0.3290
189.0617	96.4338	0.3290
189.0700	96.3504	0.3289
189.0783	96.2665	0.3289
189.0867	96.1847	0.3289
189.0950	96.1009	0.3288
189.1033	96.0184	0.3287
189.1117	95.9346	0.3287
189.1200	95.8509	0.3287
189.1283	95.7680	0.3286
189.1367	95.6863	0.3286
189.1450	95.6031	0.3285
189.1533	95.5204	0.3285
189.1617	95.4372	0.3284
189.1700	95.3520	0.3284
189.1783	95.2697	0.3283
189.1867	95.1864	0.3283
189.1950	95.1031	0.3282
189.2033	95.0204	0.3282
189.2117	94.9375	0.3281
189.2200	94.8541	0.3280
189.2283	94.7714	0.3280
189.2367	94.6868	0.3279
189.2450	94.6045	0.3279
189.2533	94.5211	0.3278
189.2617	94.4376	0.3278
189.2700	94.3552	0.3277
189.2783	94.2727	0.3277
189.2867	94.1884	0.3277
189.2950	94.1060	0.3276
189.3033	94.0221	0.3276
189.3117	93.9398	0.3275
189.3200	93.8557	0.3274
189.3283	93.7722	0.3274
189.3367	93.6887	0.3273
189.3450	93.6059	0.3273
189.3533	93.5239	0.3273
189.3617	93.4412	0.3272
189.3700	93.3577	0.3271
189.3783	93.2740	0.3271
189.3867	93.1914	0.3270
189.3950	93.1077	0.3269
189.4033	93.0243	0.3269
189.4117	92.9419	0.3268
189.4200	92.8580	0.3268
189.4283	92.7756	0.3267
189.4367	92.6910	0.3267
189.4450	92.6086	0.3266
189.4533	92.5258	0.3265
189.4617	92.4429	0.3265
189.4700	92.3592	0.3264
189.4783	92.2763	0.3264
189.4867	92.1933	0.3264
189.4950	92.1093	0.3263
189.5033	92.0268	0.3263
189.5117	91.9435	0.3262
189.5200	91.8613	0.3262
189.5283	91.7768	0.3262
189.5367	91.6934	0.3261
189.5450	91.6101	0.3257
189.5533	91.5265	0.3257
189.5617	91.4449	0.3257
189.5700	91.3615	0.3256
189.5783	91.2787	0.3256
189.5867	91.1946	0.3255
189.5950	91.1123	0.3255
189.6033	91.0288	0.3255
189.6117	90.9457	0.3254
189.6200	90.8627	0.3254
189.6283	90.7806	0.3253
189.6367	90.6961	0.3253
189.6450	90.6133	0.3252
189.6533	90.5297	0.3251
189.6617	90.4469	0.3251
189.6700	90.3642	0.3250
189.6783	90.2815	0.3250
189.6867	90.1980	0.3250
189.6950	90.1146	0.3249
189.7033	90.0307	0.3249
189.7117	89.9485	0.3248
189.7200	89.8645	0.3248
189.7283	89.7824	0.3247
189.7367	89.6981	0.3246
189.7450	89.6149	0.3246
189.7533	89.5326	0.3245
189.7617	89.4496	0.3245
189.7700	89.3663	0.3245
189.7783	89.2825	0.3244
189.7867	89.1991	0.3244
189.7950	89.1175	0.3243
189.8033	89.0334	0.3243
189.8117	88.9509	0.3243
189.8200	88.8673	0.3242
189.8283	88.7839	0.3241
189.8367	88.7008	0.3241
189.8450	88.6179	0.3240
189.8533	88.5334	0.3240
189.8617	88.4517	0.3239
189.8700	88.3673	0.3239
189.8783	88.2844	0.3238
189.8867	88.2019	0.3237
189.8950	88.1182	0.3237
189.9033	88.0352	0.3236
189.9117	87.9523	0.3236
189.9200	87.8687	0.3236
189.9283	87.7853	0.3235
189.9367	87.7028	0.3235
189.9450	87.6197	0.3234
189.9533	87.5359	0.3234
189.9617	87.4525	0.3234
189.9700	87.3699	0.3233
189.9783	87.2866	0.3232
189.9867	87.2045	0.3232
189.9950	87.1211	0.3232
190.0033	87.0381	0.3231
190.0117	86.9536	0.3231
190.0200	86.8721	0.3230
190.0283	86.7885	0.3229
190.0367	86.7052	0.3229
190.0450	86.6225	0.3229
190.0533	86.5386	0.3228
190.0617	86.4563	0.3225
190.0700	86.3728	0.3225
190.0783	86.2885	0.3224
190.0867	86.2066	0.3224
190.0950	86.1234	0.3224
190.1033	86.0392	0.3221
190.1117	85.9570	0.3220
190.1200	85.8738	0.3220
190.1283	85.7898	0.3220
190.1367	85.7067	0.3220
190.1450	85.6244	0.3219
190.1533	85.5409	0.3219
190.1617	85.4575	0.3218
190.1700	85.3756	0.3218
190.1783	85.2921	0.3218
190.1867	85.2086	0.3217
190.1950	85.1254	0.3217
190.2033	85.0424	0.3216
190.2117	84.9588	0.3216
190.2200	84.8763	0.3215
190.2283	84.7926	0.3215
190.2367	84.7096	0.3214
190.2450	84.6262	0.3214
190.2533	84.5428	0.3214
190.2617	84.4604	0.3213
190.2700	84.3772	0.3212
190.2783	84.2950	0.3212
190.2867	84.2110	0.3212
190.2950	84.1288	0.3211
190.3033	84.0442	0.3211
190.3117	83.9621	0.3210
190.3200	83.8784	0.3209
190.3283	83.7946	0.3209
190.3367	83.7132	0.3209
190.3450	83.6290	0.3208
190.3533	83.5449	0.3208
190.3617	83.4637	0.3207
190.3700	83.3797	0.3207
190.3783	83.2973	0.3206
190.3867	83.2128	0.3206
190.3950	83.1302	0.3205
190.4033	83.0480	0.3205
190.4117	82.9637	0.3204
190.4200	82.8812	0.3204
190.4283	82.7976	0.3203
190.4367	82.7147	0.3203
190.4450	82.6308	0.3203
190.4533	82.5479	0.3202
190.4617	82.4658	0.3202
190.4700	82.3820	0.3201
190.4783	82.2990	0.3201
190.4867	82.2159	0.3200
190.4950	82.1311	0.3199
190.5033	82.0498	0.3199
190.5117	81.9661	0.3199
190.5200	81.8829	0.3198
190.5283	81.7997	0.3198
190.5367	81.7168	0.3197
190.5450	81.6329	0.3197
190.5533	81.5502	0.3196
190.5617	81.4669	0.3196
190.5700	81.3843	0.3195
190.5783	81.3003	0.3195
190.5867	81.2167	0.3194
190.5950	81.1351	0.3194
190.6033	81.0520	0.3193
190.6117	80.9681	0.3192
190.6200	80.8838	0.3192
190.6283	80.8019	0.3189
190.6367	80.7191	0.3188
190.6450	80.6343	0.3188
190.6533	80.5526	0.3188
190.6617	80.4693	0.3187
190.6700	80.3864	0.3186
190.6783	80.3032	0.3186
190.6867	80.2196	0.3186
190.6950	80.1367	0.3185
190.7033	80.0535	0.3185
190.7117	79.9713	0.3184
190.7200	79.8879	0.3184
190.7283	79.8037	0.3183
190.7367	79.7209	0.3183
190.7450	79.6370	0.3183
190.7533	79.5535	0.3182
190.7617	79.4715	0.3181
190.7700	79.3871	0.3181
190.7783	79.3048	0.3180
190.7867	79.2219	0.3180
190.7950	79.1378	0.3180
190.8033	79.0559	0.3179
190.8117	78.9721	0.3178
190.8200	78.8897	0.3178
190.8283	78.8060	0.3178
190.8367	78.7222	0.3177
190.8450	78.6397	0.3176
190.8533	78.5579	0.3176
190.8617	78.4731	0.3175
190.8700	78.3908	0.3175
190.8783	78.3076	0.3174
190.8867	78.2240	0.3173
190.8950	78.1412	0.3173
190.9033	78.0579	0.3172
190.9117	77.9748	0.3172
190.9200	77.8926	0.3171
190.9283	77.8089	0.3170
190.9367	77.7252	0.3170
190.9450	77.6424	0.3169
190.9533	77.5582	0.3169
190.9617	77.4762	0.3168
190.9700	77.3927	0.3168
190.9783	77.3095	0.3167
190.9867	77.2265	0.3167
190.9950	77.1436	0.3166
191.0033	77.0590	0.3166
191.0117	76.9764	0.3165
191.0200	76.8939	0.3165
191.0283	76.8097	0.3164
191.0367	76.7270	0.3164
191.0450	76.6439	0.3163
191.0533	76.5603	0.3162
191.0617	76.4770	0.3162
191.0700	76.3945	0.3161
191.0783	76.3097	0.3161
191.0867	76.2273	0.3160
191.0950	76.1446	0.3157
191.1033	76.0613	0.3156
191.1117	75.9792	0.3156
191.1200	75.8948	0.3155
191.1283	75.8130	0.3155
191.1367	75.7292	0.3154
191.1450	75.6458	0.3154
191.1533	75.5631	0.3154
191.1617	75.4804	0.3153
191.1700	75.3957	0.3152
191.1783	75.3137	0.3152
191.1867	75.2301	0.3151
191.1950	75.1461	0.3151
191.2033	75.0644	0.3151
191.2117	74.9796	0.3150
191.2200	74.8972	0.3150
191.2283	74.8149	0.3149
191.2367	74.7313	0.3148
191.2450	74.6482	0.3148
191.2533	74.5659	0.3148
191.2617	74.4826	0.3147
191.2700	74.3990	0.3146
191.2783	74.3154	0.3146
191.2867	74.2316	0.3145
191.2950	74.1488	0.3145
191.3033	74.0659	0.3144
191.3117	73.9821	0.3144
191.3200	73.9005	0.3144
191.3283	73.8166	0.3143
191.3367	73.7333	0.3142
191.3450	73.6511	0.3142
191.3533	73.5671	0.3141
191.3617	73.4834	0.3141
191.3700	73.4010	0.3140
191.3783	73.3174	0.3139
191.3867	73.2340	0.3138
191.3950	73.1519	0.3137
191.4033	73.0682	0.3136
191.4117	72.9837	0.3136
191.4200	72.9013	0.3135
191.4283	72.8184	0.3135
191.4367	72.7357	0.3134
191.4450	72.6533	0.3132
191.4533	72.5694	0.3132
191.4617	72.4866	0.3132
191.4700	72.4031	0.3131
191.4783	72.3201	0.3130
191.4867	72.2366	0.3129
191.4950	72.1538	0.3128
191.5033	72.0708	0.3128
191.5117	71.9876	0.3127
191.5200	71.9036	0.3126
191.5283	71.8206	0.3126
191.5367	71.7373	0.3125
191.5450	71.6553	0.3125
191.5533	71.5707	0.3124
191.5617	71.4881	0.3124
191.5700	71.4051	0.3122
191.5783	71.3228	0.3121
191.5867	71.2395	0.3121
191.5950	71.1562	0.3121
191.6033	71.0717	0.3120
191.6117	70.9893	0.3120
191.6200	70.9058	0.3120
191.6283	70.8233	0.3119
191.6367	70.7410	0.3116
191.6450	70.6577	0.3116
191.6533	70.5742	0.3116
191.6617	70.4910	0.3115
191.6700	70.4080	0.3115
191.6783	70.3246	0.3114
191.6867	70.2412	0.3114
191.6950	70.1574	0.3114
191.7033	70.0740	0.3113
191.7117	69.9912	0.3113
191.7200	69.9079	0.3113
191.7283	69.8243	0.3112
191.7367	69.7418	0.3112
191.7450	69.6578	0.3111
191.7533	69.5757	0.3111
191.7617	69.4924	0.3111
191.7700	69.4090	0.3110
191.7783	69.3260	0.3110
191.7867	69.2423	0.3109
191.7950	69.1588	0.3109
191.8033	69.0764	0.3108
191.8117	68.9934	0.3108
191.8200	68.9102	0.3107
191.8283	68.8269	0.3107
191.8367	68.7432	0.3107
191.8450	68.6614	0.3106
191.8533	68.5774	0.3105
191.8617	68.4940	0.3105
191.8700	68.4114	0.3104
191.8783	68.3282	0.3103
191.8867	68.2451	0.3103
191.8950	68.1623	0.3102
191.9033	68.0778	0.3102
191.9117	67.9958	0.3101
191.9200	67.9122	0.3101
191.9283	67.8297	0.3101
191.9367	67.7456	0.3100
191.9450	67.6624	0.3100
191.9533	67.5797	0.3099
191.9617	67.4964	0.3099
191.9700	67.4133	0.3098
191.9783	67.3295	0.3096
191.9867	67.2475	0.3096
191.9950	67.1634	0.3095
192.0033	67.0801	0.3095
192.0117	66.9979	0.3094
192.0200	66.9143	0.3094
192.0283	66.8307	0.3093
192.0367	66.7490	0.3093
192.0450	66.6658	0.3092
192.0533	66.5819	0.3092
192.0617	66.4985	0.3091
192.0700	66.4149	0.3090
192.0783	66.3324	0.3090
192.0867	66.2485	0.3089
192.0950	66.1660	0.3089
192.1033	66.0833	0.3087
192.1117	65.9996	0.3086
192.1200	65.9172	0.3086
192.1283	65.8334	0.3085
192.1367	65.7511	0.3085
192.1450	65.6672	0.3083
192.1533	65.5844	0.3083
192.1617	65.5005	0.3082
192.1700	65.4170	0.3082
192.1783	65.3342	0.3081
192.1867	65.2501	0.3081
192.1950	65.1678	0.3080
192.2033	65.0851	0.3079
192.2117	65.0012	0.3079
192.2200	64.9178	0.3078
192.2283	64.8350	0.3078
192.2367	64.7528	0.3077
192.2450	64.6694	0.3075
192.2533	64.5853	0.3075
192.2617	64.5038	0.3074
192.2700	64.4202	0.3071
192.2783	64.3371	0.3071
192.2867	64.2528	0.3071
192.2950	64.1714	0.3070
192.3033	64.0887	0.3070
192.3117	64.0039	0.3070
192.3200	63.9202	0.3070
192.3283	63.8387	0.3068
192.3367	63.7546	0.3068
192.3450	63.6702	0.3067
192.3533	63.5880	0.3067
192.3617	63.5057	0.3067
192.3700	63.4224	0.3066
192.3783	63.3389	0.3065
192.3867	63.2562	0.3065
192.3950	63.1724	0.3065
192.4033	63.0894	0.3064
192.4117	63.0052	0.3064
192.4200	62.9226	0.3063
192.4283	62.8396	0.3062
192.4367	62.7563	0.3062
192.4450	62.6730	0.3060
192.4533	62.5891	0.3060
192.4617	62.5060	0.3060
192.4700	62.4231	0.3059
192.4783	62.3415	0.3059
192.4867	62.2568	0.3058
192.4950	62.1735	0.3058
192.5033	62.0916	0.3055
192.5117	62.0074	0.3054
192.5200	61.9246	0.3054
192.5283	61.8405	0.3053
192.5367	61.7573	0.3052
192.5450	61.6759	0.3052
192.5533	61.5916	0.3051
192.5617	61.5095	0.3051
192.5700	61.4266	0.3050
192.5783	61.3422	0.3049
192.5867	61.2594	0.3048
192.5950	61.1772	0.3048
192.6033	61.0934	0.3048
192.6117	61.0102	0.3047
192.6200	60.9269	0.3047
192.6283	60.8432	0.3046
192.6367	60.7605	0.3046
192.6450	60.6773	0.3045
192.6533	60.5943	0.3045
192.6617	60.5114	0.3044
192.6700	60.4278	0.3043
192.6783	60.3451	0.3043
192.6867	60.2625	0.3042
192.6950	60.1793	0.3042
192.7033	60.0958	0.3041
192.7117	60.0123	0.3041
192.7200	59.9288	0.3041
192.7283	59.8445	0.3040
192.7367	59.7619	0.3040
192.7450	59.6785	0.3040
192.7533	59.5965	0.3039
192.7617	59.5125	0.3039
192.7700	59.4306	0.3036
192.7783	59.3463	0.3036
192.7867	59.2640	0.3036
192.7950	59.1810	0.3035
192.8033	59.0973	0.3034
192.8117	59.0139	0.3034
192.8200	58.9311	0.3034
192.8283	58.8481	0.3033
192.8367	58.7653	0.3033
192.8450	58.6817	0.3033
192.8533	58.5976	0.3033
192.8617	58.5154	0.3032
192.8700	58.4322	0.3032
192.8783	58.3493	0.3031
192.8867	58.2649	0.3031
192.8950	58.1825	0.3031
192.9033	58.0992	0.3031
192.9117	58.0172	0.3031
192.9200	57.9349	0.3032
192.9283	57.8499	0.3033
192.9367	57.7678	0.3033
192.9450	57.6853	0.3040
192.9533	57.6022	0.3051
192.9617	57.5194	0.3063
192.9700	57.4370	0.3083
192.9783	57.3541	0.3112
192.9867	57.2721	0.3157
192.9950	57.1897	0.3190
193.0033	57.1075	0.3245
193.0117	57.0261	0.3310
193.0200	56.9451	0.3374
193.0283	56.8644	0.3485
193.0367	56.7847	0.3615
193.0450	56.7070	0.3790
193.0533	56.6293	0.3995
193.0617	56.5533	0.4255
193.0700	56.4799	0.4583
193.0783	56.4092	0.4993
193.0867	56.3404	0.5484
193.0950	56.2761	0.6076
193.1033	56.2150	0.6783
193.1117	56.1582	0.7607
193.1200	56.1086	0.8558
193.1283	56.0640	0.9624
193.1367	56.0260	1.0795
193.1450	55.9940	1.2048
193.1533	55.9689	1.3369
193.1617	55.9483	1.4701
193.1700	55.9349	1.6015
193.1783	55.9263	1.7318
193.1867	55.9196	1.8549
193.1950	55.9164	1.9704
193.2033	55.9154	2.0765
193.2117	55.9165	2.1738
193.2200	55.9145	2.2624
193.2283	55.9128	2.3425
193.2367	55.9100	2.4158
193.2450	55.9055	2.4818
193.2533	55.8978	2.5428
193.2617	55.8864	2.5983
193.2700	55.8750	2.6496
193.2783	55.8604	2.6977
193.2867	55.8423	2.7406
193.2950	55.8222	2.7841
193.3033	55.7979	2.8240
193.3117	55.7733	2.8617
193.3200	55.7455	2.8985
193.3283	55.7143	2.9326
193.3367	55.6819	2.9646
193.3450	55.6475	2.9951
193.3533	55.6107	3.0263
193.3617	55.5708	3.0546
193.3700	55.5319	3.0800
193.3783	55.4874	3.1063
193.3867	55.4435	3.1292
193.3950	55.3963	3.1500
193.4033	55.3493	3.1692
193.4117	55.2992	3.1882
193.4200	55.2463	3.2016
193.4283	55.1948	3.2156
193.4367	55.1390	3.2286
193.4450	55.0806	3.2378
193.4533	55.0216	3.2428
193.4617	54.9616	3.2461
193.4700	54.8995	3.2494
193.4783	54.8352	3.2487
193.4867	54.7665	3.2457
193.4950	54.6978	3.2378
193.5033	54.6288	3.2289
193.5117	54.5557	3.2173
193.5200	54.4806	3.2013
193.5283	54.4030	3.1831
193.5367	54.3233	3.1608
193.5450	54.2419	3.1360
193.5533	54.1583	3.1092
193.5617	54.0708	3.0797
193.5700	53.9821	3.0474
193.5783	53.8903	3.0127
193.5867	53.7972	2.9765
193.5950	53.7018	2.9379
193.6033	53.6035	2.8976
193.6117	53.5039	2.8580
193.6200	53.4018	2.8160
193.6283	53.2979	2.7724
193.6367	53.1926	2.7288
193.6450	53.0857	2.6869
193.6533	52.9778	2.6424
193.6617	52.8681	2.5980
193.6700	52.7571	2.5526
193.6783	52.6459	2.5075
193.6867	52.5324	2.4625
193.6950	52.4191	2.4175
193.7033	52.3029	2.3716
193.7117	52.1875	2.3270
193.7200	52.0704	2.2818
193.7283	51.9536	2.2374
193.7367	51.8351	2.1946
193.7450	51.7166	2.1503
193.7533	51.5979	2.1091
193.7617	51.4801	2.0661
193.7700	51.3627	2.0258
193.7783	51.2441	1.9851
193.7867	51.1247	1.9460
193.7950	51.0060	1.9075
193.8033	50.8873	1.8700
193.8117	50.7702	1.8332
193.8200	50.6507	1.7980
193.8283	50.5330	1.7615
193.8367	50.4164	1.7261
193.8450	50.2992	1.6925
193.8533	50.1831	1.6586
193.8617	50.0658	1.6253
193.8700	49.9500	1.5943
193.8783	49.8345	1.5623
193.8867	49.7190	1.5322
193.8950	49.6043	1.5037
193.9033	49.4912	1.4744
193.9117	49.3760	1.4472
193.9200	49.2629	1.4195
193.9283	49.1525	1.3926
193.9367	49.0395	1.3649
193.9450	48.9284	1.3372
193.9533	48.8166	1.3103
193.9617	48.7068	1.2844
193.9700	48.5951	1.2602
193.9783	48.4855	1.2367
193.9867	48.3763	1.2115
193.9950	48.2678	1.1887
194.0033	48.1596	1.1668
194.0117	48.0518	1.1443
194.0200	47.9440	1.1243
194.0283	47.8372	1.1036
194.0367	47.7312	1.0826
194.0450	47.6254	1.0636
194.0533	47.5198	1.0444
194.0617	47.4151	1.0265
194.0700	47.3108	1.0077
194.0783	47.2074	0.9906
194.0867	47.1039	0.9753
194.0950	47.0011	0.9581
194.1033	46.8994	0.9421
194.1117	46.7969	0.9271
194.1200	46.6973	0.9120
194.1283	46.5957	0.8979
194.1367	46.4948	0.8838
194.1450	46.3958	0.8697
194.1533	46.2961	0.8569
194.1617	46.1967	0.8446
194.1700	46.0988	0.8323
194.1783	46.0009	0.8204
194.1867	45.9039	0.8092
194.1950	45.8055	0.7981
194.2033	45.7089	0.7874
194.2117	45.6132	0.7768
194.2200	45.5163	0.7666
194.2283	45.4218	0.7580
194.2367	45.3262	0.7485
194.2450	45.2306	0.7393
194.2533	45.1375	0.7313
194.2617	45.0431	0.7238
194.2700	44.9479	0.7148
194.2783	44.8559	0.7062
194.2867	44.7623	0.6996
194.2950	44.6700	0.6935
194.3033	44.5777	0.6865
194.3117	44.4845	0.6796
194.3200	44.3938	0.6740
194.3283	44.3024	0.6686
194.3367	44.2105	0.6624
194.3450	44.1207	0.6576
194.3533	44.0304	0.6518
194.3617	43.9390	0.6484
194.3700	43.8492	0.6427
194.3783	43.7604	0.6387
194.3867	43.6701	0.6347
194.3950	43.5813	0.6296
194.4033	43.4919	0.6263
194.4117	43.4038	0.6219
194.4200	43.3163	0.6194
194.4283	43.2264	0.6145
194.4367	43.1393	0.6111
194.4450	43.0521	0.6084
194.4533	42.9633
194.4617	42.8762
194.4700	42.7883
194.4783	42.6993
194.4867	42.6137
194.4950	42.5256
194.5033