File: Example Date/My Sample/DSC/test01/DSC TA/YN039.txt
Filename	YN039
Instrument name	DSC2A-01799 (192.168.1.250)
Operator
rundate	02/12/2024
Sample name	YN039
proceduresegments	Ramp 10.00 °C/min to 150.0000 °C; Isothermal 3.0 min; Ramp 10.00 °C/min to -100.0000 °C; Isothermal 3.0 min; Ramp 10.00 °C/min to 150.0000 °C; Isothermal 3.0 min; Ramp 10.00 °C/min to -100.0000 °C; Isothermal 3.0 min; Ramp 10.00 °C/min to 150.0000 °C; Isothermal 3.0 min; Ramp 10.00 °C/min to -100.0000 °C; Isothermal 3.0 min; Ramp 10.00 °C/min to 150.0000 °C; Isothermal 3.0 min; Ramp 10.00 °C/min to 40.0000 °C
[File Parameters]
Run Date	02/12/2024 09:55:50
Trios version	5.7.0.56
Original File Name
Current File Name	C:\Users\TA Instruments DSC\Desktop\Data\Yutong Niu\2024-1126\YN039.tri
User at run start	DESKTOP-CFGN8IT\TA Instruments DSC
[Procedure]
Procedure Name	polyether
Sample Name	YN039
Sample Mass	10.79 mg
Reference Sample Mass	0 mg
Pan Mass	73.19 mg
Pan Number	26
Reference Pan Mass	60.81 mg
Reference Pan Number	45
Pan Type	Tzero Aluminum Pin Hole Hermetic
Comments
Project Name
Operator
Test	Custom
Unload Max Temperature	25
Unload Min Temperature	25
FillCooler	Do not fill
Load Max Temperature	25
Load Min Temperature	25
Discard pan in waste bin at end of test	Yes
Stop on Gas Flow Error	No
[Signal List]
Signal #1	Time (min)
Signal #2	Temperature (°C)
Signal #3	Heat Flow (mW)
Signal #4	Delta T (µV)
Signal #5	Delta Tzero (µV)
Signal #6	Tzero Temperature (°C)
Signal #7	Cell Purge (mL/min)
Signal #8	Heater Temp (°C)
Signal #9	Power Delivered (W)
Signal #10	Reference Junction Temperature (°C)
Signal #11	Flange Temperature (°C)
Signal #12	Heat Flow Phase (rad)
Signal #13	Total Heat Capacity (J/°C)
Signal #14	Heat Capacity (J/°C)
Signal #15	LN Pump Tank level (%)
[Configuration]
Company Name	Warwick University
Instrument Name	DSC2A-01799
Instrument Type	DSC2500
Serial Number	DSC2A-01799
IP	192.168.1.250
Location of Instrument	Polymer RTP
DisplayType	TianmaV2andV3
Sample Interval 	0.1 s/pt
Selected Heat Flow	T4P
Exotherm Direction	Up
Cell Serial	DRC2-03788
Lid Type	High Temperature
Cooler	LN Pump
Leave Cooler on at End of Sequence	Off
Gas 2	Air
Gas Selected	Channel 1: Nitrogen
Flow Rate	50 mL/min
Secondary Purge	On
Licensed Heat Flow	Heat Flow T4P
Modulation Licensed	Yes
[Versions]
Common IDD Version	1
Cortex Version	VER 2.11.0.729
Driver	5.0.0.6
GDM Version	1.0.3.3
TouchscreenVersion	1.0.3.1841
FEP Version	1.2.1.21
FEP Bootloader	2.0.0.5
AutoSampler Version	2.1.2.1
Auto Sampler Bootloader	2.0.0.5
FCM Version	1.1.0.3
FCM Bootloader	2.0.0.5
LN Pump Version	10.17.0.0
LN Pump Bootloader	2.0.0.5
[Experiment Logs]
Experiment Log Entry # 1	Ramp Segment 10 C/min to 150 Started
Experiment Log Entry # 3	Air Cool is off.
Experiment Log Entry # 5	Isothermal Segment 3 min started
Experiment Log Entry # 7	Ramp Segment 10 C/min to -100 Started
Experiment Log Entry # 10	LN2P is filling
Experiment Log Entry # 11	Isothermal Segment 3 min started
Experiment Log Entry # 14	LN2P stopped filling
Experiment Log Entry # 15	Ramp Segment 10 C/min to 150 Started
Experiment Log Entry # 17	Isothermal Segment 3 min started
Experiment Log Entry # 19	Ramp Segment 10 C/min to -100 Started
Experiment Log Entry # 21	Isothermal Segment 3 min started
Experiment Log Entry # 23	Ramp Segment 10 C/min to 150 Started
Experiment Log Entry # 25	Isothermal Segment 3 min started
Experiment Log Entry # 27	Ramp Segment 10 C/min to -100 Started
Experiment Log Entry # 29	Isothermal Segment 3 min started
Experiment Log Entry # 31	Ramp Segment 10 C/min to 150 Started
Experiment Log Entry # 33	Isothermal Segment 3 min started
Experiment Log Entry # 35	Ramp Segment 10 C/min to 40 Started
[Method Log]
Method Log Entry # 1	(Ramp 1965487) Ramp 10 °C/minute to 150 °C
Method Log Entry # 2	Isothermal 3 minutes
Method Log Entry # 3	(Ramp 1965489) Ramp 10 °C/minute to -100 °C
Method Log Entry # 4	Isothermal 3 minutes
Method Log Entry # 5	(Ramp 1965491) Ramp 10 °C/minute to 150 °C
Method Log Entry # 6	Isothermal 3 minutes
Method Log Entry # 7	(Ramp 1965493) Ramp 10 °C/minute to -100 °C
Method Log Entry # 8	Isothermal 3 minutes
Method Log Entry # 9	(Ramp 1965495) Ramp 10 °C/minute to 150 °C
Method Log Entry # 10	Isothermal 3 minutes
Method Log Entry # 11	(Ramp 1965497) Ramp 10 °C/minute to -100 °C
Method Log Entry # 12	Isothermal 3 minutes
Method Log Entry # 13	(Ramp 1965499) Ramp 10 °C/minute to 150 °C
Method Log Entry # 14	Isothermal 3 minutes
Method Log Entry # 15	(Ramp 1965501) Ramp 10 °C/minute to 40 °C
Cell Serial	DRC2-03788
[T1 Calibration]
Date Applied	04/03/2021 14:58:04
Description
Gas Type	Nitrogen
Pan Type	None
Slope	-0.001800291
Offset	-0.1301359
Initial Temperature	-100.6228
GUID	a1d5a6be-decd-4ae4-b22f-d560f3a78a92
[TZero Calibration]
Date Applied	21/08/2024 09:53:38
Description	From -180.022 °C to 395.167 °C at 20.000°C/min
Gas Type	Nitrogen
Pan Type	None
Source Files 1	C:\ProgramData\TA Instruments\TRIOS\Data\TAService\PMV 20Aug2024\Tzero Cal.tri
Source Files 2	C:\ProgramData\TA Instruments\TRIOS\Data\TAService\PMV 20Aug2024\Tzero Cal sapphire.tri
Delta T Offset	1.787969
Delta T Slope	-0.003527276
Delta T0 Offset	0.06831977
Delta T0 Slope	0.02007191
[Temperature Calibration]
Date Applied	21/08/2024 11:06:35
Description	From 106.660 °C to 186.660 °C at 10.000°C/min
Gas Type	Nitrogen
Pan Type	Tzero Aluminum
Source Files 1	C:\ProgramData\TA Instruments\TRIOS\Data\TAService\PMV 20Aug2024\TA Indium cal.tri
Measured 1	157.9141
Known 1	156.66
[Cell Constant Calibration]
Date Applied	21/08/2024 11:06:35
Description	From 106.660 °C to 186.660 °C at 10.000°C/min
Gas Type	Nitrogen
Pan Type	Tzero Aluminum
Source Files 1	C:\ProgramData\TA Instruments\TRIOS\Data\TAService\PMV 20Aug2024\TA Indium cal.tri
T4P KCell	1.038055
Onset Slope	-66.72884 mW/°C
[Direct Cp Calibration]
Date Applied	19/11/2024 16:37:27
Description	From -89.996 °C to 396.697 °C at 20.000°C/min
Gas Type	Nitrogen
Pan Type	Tzero Aluminum
Source Files 1	C:\ProgramData\TA Instruments\TRIOS\Data\Sapphire Direct Heat Capacity(8).tri
GUID	544f8371-fe9b-4f4f-81ca-7980c172113e
Temperature	-89.99625 °C
Cp	1.464367
Temperature	-89.02287 °C
Cp	1.460558
Temperature	-88.04948 °C
Cp	1.456263
Temperature	-87.0761 °C
Cp	1.451626
Temperature	-86.10271 °C
Cp	1.446737
Temperature	-85.12933 °C
Cp	1.441723
Temperature	-84.15594 °C
Cp	1.436654
Temperature	-83.18256 °C
Cp	1.431684
Temperature	-82.20917 °C
Cp	1.426935
Temperature	-81.23578 °C
Cp	1.422396
Temperature	-80.2624 °C
Cp	1.418192
Temperature	-79.28901 °C
Cp	1.414363
Temperature	-78.31562 °C
Cp	1.410925
Temperature	-77.34224 °C
Cp	1.407865
Temperature	-76.36885 °C
Cp	1.405143
Temperature	-75.39546 °C
Cp	1.402789
Temperature	-74.42208 °C
Cp	1.400703
Temperature	-73.44869 °C
Cp	1.398837
Temperature	-72.4753 °C
Cp	1.397142
Temperature	-71.50192 °C
Cp	1.395565
Temperature	-70.52853 °C
Cp	1.394053
Temperature	-69.55515 °C
Cp	1.392558
Temperature	-68.58176 °C
Cp	1.391036
Temperature	-67.60838 °C
Cp	1.389483
Temperature	-66.63499 °C
Cp	1.387847
Temperature	-65.66161 °C
Cp	1.38616
Temperature	-64.68822 °C
Cp	1.384397
Temperature	-63.71483 °C
Cp	1.382535
Temperature	-62.74145 °C
Cp	1.380598
Temperature	-61.76806 °C
Cp	1.37865
Temperature	-60.79467 °C
Cp	1.376673
Temperature	-59.82129 °C
Cp	1.374677
Temperature	-58.8479 °C
Cp	1.372642
Temperature	-57.87452 °C
Cp	1.370686
Temperature	-56.90113 °C
Cp	1.368741
Temperature	-55.92775 °C
Cp	1.366786
Temperature	-54.95436 °C
Cp	1.364863
Temperature	-53.98097 °C
Cp	1.362959
Temperature	-53.00759 °C
Cp	1.361116
Temperature	-52.0342 °C
Cp	1.359247
Temperature	-51.06082 °C
Cp	1.357393
Temperature	-50.08743 °C
Cp	1.355593
Temperature	-49.11404 °C
Cp	1.353796
Temperature	-48.14066 °C
Cp	1.352008
Temperature	-47.16727 °C
Cp	1.350215
Temperature	-46.19389 °C
Cp	1.348396
Temperature	-45.2205 °C
Cp	1.346593
Temperature	-44.24712 °C
Cp	1.344755
Temperature	-43.27373 °C
Cp	1.342891
Temperature	-42.30034 °C
Cp	1.341008
Temperature	-41.32696 °C
Cp	1.339126
Temperature	-40.35357 °C
Cp	1.337236
Temperature	-39.38018 °C
Cp	1.335367
Temperature	-38.4068 °C
Cp	1.333522
Temperature	-37.43341 °C
Cp	1.331708
Temperature	-36.46003 °C
Cp	1.32991
Temperature	-35.48664 °C
Cp	1.328145
Temperature	-34.51326 °C
Cp	1.326414
Temperature	-33.53987 °C
Cp	1.32471
Temperature	-32.56648 °C
Cp	1.323012
Temperature	-31.5931 °C
Cp	1.321323
Temperature	-30.61971 °C
Cp	1.319657
Temperature	-29.64633 °C
Cp	1.317968
Temperature	-28.67294 °C
Cp	1.316286
Temperature	-27.69955 °C
Cp	1.314585
Temperature	-26.72617 °C
Cp	1.312857
Temperature	-25.75278 °C
Cp	1.31111
Temperature	-24.7794 °C
Cp	1.309333
Temperature	-23.80601 °C
Cp	1.307544
Temperature	-22.83262 °C
Cp	1.30575
Temperature	-21.85924 °C
Cp	1.303941
Temperature	-20.88585 °C
Cp	1.302132
Temperature	-19.91247 °C
Cp	1.300313
Temperature	-18.93908 °C
Cp	1.298512
Temperature	-17.96569 °C
Cp	1.296728
Temperature	-16.99231 °C
Cp	1.294939
Temperature	-16.01892 °C
Cp	1.293198
Temperature	-15.04554 °C
Cp	1.291453
Temperature	-14.07215 °C
Cp	1.289723
Temperature	-13.09876 °C
Cp	1.288007
Temperature	-12.12538 °C
Cp	1.286283
Temperature	-11.15199 °C
Cp	1.284578
Temperature	-10.17861 °C
Cp	1.282885
Temperature	-9.205221 °C
Cp	1.281173
Temperature	-8.231835 °C
Cp	1.279472
Temperature	-7.258449 °C
Cp	1.277766
Temperature	-6.285063 °C
Cp	1.276053
Temperature	-5.311677 °C
Cp	1.274341
Temperature	-4.338291 °C
Cp	1.272592
Temperature	-3.364905 °C
Cp	1.270844
Temperature	-2.391519 °C
Cp	1.269062
Temperature	-1.418133 °C
Cp	1.267264
Temperature	-0.4447474 °C
Cp	1.265435
Temperature	0.5286385 °C
Cp	1.263575
Temperature	1.502024 °C
Cp	1.261727
Temperature	2.47541 °C
Cp	1.259854
Temperature	3.448796 °C
Cp	1.257978
Temperature	4.422182 °C
Cp	1.256109
Temperature	5.395568 °C
Cp	1.254244
Temperature	6.368954 °C
Cp	1.252392
Temperature	7.34234 °C
Cp	1.250552
Temperature	8.315726 °C
Cp	1.248704
Temperature	9.289112 °C
Cp	1.246884
Temperature	10.2625 °C
Cp	1.245078
Temperature	11.23588 °C
Cp	1.243287
Temperature	12.20927 °C
Cp	1.241522
Temperature	13.18266 °C
Cp	1.239778
Temperature	14.15604 °C
Cp	1.238068
Temperature	15.12943 °C
Cp	1.236393
Temperature	16.10281 °C
Cp	1.234762
Temperature	17.0762 °C
Cp	1.233176
Temperature	18.04959 °C
Cp	1.231629
Temperature	19.02297 °C
Cp	1.230129
Temperature	19.99636 °C
Cp	1.228694
Temperature	20.96974 °C
Cp	1.22731
Temperature	21.94313 °C
Cp	1.225968
Temperature	22.91652 °C
Cp	1.224676
Temperature	23.8899 °C
Cp	1.223431
Temperature	24.86329 °C
Cp	1.222217
Temperature	25.83667 °C
Cp	1.221065
Temperature	26.81006 °C
Cp	1.219919
Temperature	27.78345 °C
Cp	1.218811
Temperature	28.75683 °C
Cp	1.21773
Temperature	29.73022 °C
Cp	1.216663
Temperature	30.7036 °C
Cp	1.2156
Temperature	31.67699 °C
Cp	1.214515
Temperature	32.65038 °C
Cp	1.213439
Temperature	33.62376 °C
Cp	1.21234
Temperature	34.59715 °C
Cp	1.211209
Temperature	35.57053 °C
Cp	1.210051
Temperature	36.54392 °C
Cp	1.208868
Temperature	37.5173 °C
Cp	1.207666
Temperature	38.49069 °C
Cp	1.206439
Temperature	39.46408 °C
Cp	1.205199
Temperature	40.43746 °C
Cp	1.203959
Temperature	41.41085 °C
Cp	1.202712
Temperature	42.38424 °C
Cp	1.20147
Temperature	43.35762 °C
Cp	1.200231
Temperature	44.33101 °C
Cp	1.199
Temperature	45.30439 °C
Cp	1.197777
Temperature	46.27778 °C
Cp	1.19657
Temperature	47.25116 °C
Cp	1.195367
Temperature	48.22455 °C
Cp	1.194179
Temperature	49.19794 °C
Cp	1.19301
Temperature	50.17132 °C
Cp	1.191849
Temperature	51.14471 °C
Cp	1.190694
Temperature	52.11809 °C
Cp	1.189555
Temperature	53.09148 °C
Cp	1.18843
Temperature	54.06487 °C
Cp	1.187311
Temperature	55.03825 °C
Cp	1.186195
Temperature	56.01164 °C
Cp	1.185095
Temperature	56.98502 °C
Cp	1.183997
Temperature	57.95841 °C
Cp	1.182894
Temperature	58.93179 °C
Cp	1.181793
Temperature	59.90518 °C
Cp	1.180693
Temperature	60.87857 °C
Cp	1.179595
Temperature	61.85195 °C
Cp	1.178501
Temperature	62.82534 °C
Cp	1.177406
Temperature	63.79873 °C
Cp	1.176313
Temperature	64.77211 °C
Cp	1.175239
Temperature	65.7455 °C
Cp	1.17417
Temperature	66.71888 °C
Cp	1.173105
Temperature	67.69227 °C
Cp	1.172037
Temperature	68.66566 °C
Cp	1.170989
Temperature	69.63904 °C
Cp	1.169948
Temperature	70.61243 °C
Cp	1.168905
Temperature	71.58582 °C
Cp	1.167872
Temperature	72.5592 °C
Cp	1.166849
Temperature	73.53259 °C
Cp	1.165851
Temperature	74.50597 °C
Cp	1.164848
Temperature	75.47935 °C
Cp	1.163876
Temperature	76.45274 °C
Cp	1.162926
Temperature	77.42612 °C
Cp	1.162008
Temperature	78.39951 °C
Cp	1.161113
Temperature	79.3729 °C
Cp	1.160219
Temperature	80.34628 °C
Cp	1.159377
Temperature	81.31967 °C
Cp	1.158546
Temperature	82.29306 °C
Cp	1.157726
Temperature	83.26644 °C
Cp	1.15692
Temperature	84.23983 °C
Cp	1.156126
Temperature	85.21322 °C
Cp	1.155375
Temperature	86.1866 °C
Cp	1.154604
Temperature	87.15999 °C
Cp	1.153869
Temperature	88.13337 °C
Cp	1.153158
Temperature	89.10676 °C
Cp	1.152474
Temperature	90.08015 °C
Cp	1.15181
Temperature	91.05353 °C
Cp	1.151134
Temperature	92.02692 °C
Cp	1.150513
Temperature	93.00031 °C
Cp	1.149892
Temperature	93.97369 °C
Cp	1.149266
Temperature	94.94707 °C
Cp	1.148642
Temperature	95.92046 °C
Cp	1.148019
Temperature	96.89384 °C
Cp	1.147402
Temperature	97.86723 °C
Cp	1.146799
Temperature	98.84062 °C
Cp	1.146191
Temperature	99.814 °C
Cp	1.145602
Temperature	100.7874 °C
Cp	1.14503
Temperature	101.7608 °C
Cp	1.144469
Temperature	102.7342 °C
Cp	1.143921
Temperature	103.7076 °C
Cp	1.143383
Temperature	104.6809 °C
Cp	1.142861
Temperature	105.6543 °C
Cp	1.142345
Temperature	106.6277 °C
Cp	1.141835
Temperature	107.6011 °C
Cp	1.141335
Temperature	108.5745 °C
Cp	1.140846
Temperature	109.5479 °C
Cp	1.140365
Temperature	110.5212 °C
Cp	1.139891
Temperature	111.4946 °C
Cp	1.139429
Temperature	112.468 °C
Cp	1.138976
Temperature	113.4414 °C
Cp	1.13853
Temperature	114.4148 °C
Cp	1.138092
Temperature	115.3882 °C
Cp	1.137654
Temperature	116.3616 °C
Cp	1.137223
Temperature	117.335 °C
Cp	1.136785
Temperature	118.3083 °C
Cp	1.136338
Temperature	119.2817 °C
Cp	1.13588
Temperature	120.2551 °C
Cp	1.13541
Temperature	121.2285 °C
Cp	1.134927
Temperature	122.2019 °C
Cp	1.134417
Temperature	123.1753 °C
Cp	1.133892
Temperature	124.1487 °C
Cp	1.133347
Temperature	125.122 °C
Cp	1.132786
Temperature	126.0954 °C
Cp	1.132206
Temperature	127.0688 °C
Cp	1.131606
Temperature	128.0422 °C
Cp	1.130999
Temperature	129.0156 °C
Cp	1.130384
Temperature	129.989 °C
Cp	1.129765
Temperature	130.9624 °C
Cp	1.129147
Temperature	131.9357 °C
Cp	1.12854
Temperature	132.9091 °C
Cp	1.127949
Temperature	133.8825 °C
Cp	1.127383
Temperature	134.8559 °C
Cp	1.126841
Temperature	135.8293 °C
Cp	1.126334
Temperature	136.8027 °C
Cp	1.125871
Temperature	137.7761 °C
Cp	1.125443
Temperature	138.7494 °C
Cp	1.125058
Temperature	139.7228 °C
Cp	1.124701
Temperature	140.6962 °C
Cp	1.124397
Temperature	141.6696 °C
Cp	1.124114
Temperature	142.643 °C
Cp	1.123854
Temperature	143.6164 °C
Cp	1.123612
Temperature	144.5898 °C
Cp	1.123385
Temperature	145.5631 °C
Cp	1.123182
Temperature	146.5365 °C
Cp	1.12296
Temperature	147.5099 °C
Cp	1.12275
Temperature	148.4833 °C
Cp	1.122543
Temperature	149.4567 °C
Cp	1.122327
Temperature	150.4301 °C
Cp	1.122099
Temperature	151.4035 °C
Cp	1.121837
Temperature	152.3768 °C
Cp	1.121582
Temperature	153.3502 °C
Cp	1.121289
Temperature	154.3236 °C
Cp	1.120967
Temperature	155.297 °C
Cp	1.120616
Temperature	156.2704 °C
Cp	1.120238
Temperature	157.2438 °C
Cp	1.119862
Temperature	158.2172 °C
Cp	1.119444
Temperature	159.1906 °C
Cp	1.119028
Temperature	160.1639 °C
Cp	1.118613
Temperature	161.1373 °C
Cp	1.118202
Temperature	162.1107 °C
Cp	1.117795
Temperature	163.0841 °C
Cp	1.117374
Temperature	164.0575 °C
Cp	1.116987
Temperature	165.0309 °C
Cp	1.116595
Temperature	166.0042 °C
Cp	1.116198
Temperature	166.9776 °C
Cp	1.1158
Temperature	167.951 °C
Cp	1.115402
Temperature	168.9244 °C
Cp	1.115006
Temperature	169.8978 °C
Cp	1.11462
Temperature	170.8712 °C
Cp	1.114223
Temperature	171.8446 °C
Cp	1.113836
Temperature	172.8179 °C
Cp	1.113458
Temperature	173.7913 °C
Cp	1.113085
Temperature	174.7647 °C
Cp	1.112712
Temperature	175.7381 °C
Cp	1.112323
Temperature	176.7115 °C
Cp	1.111957
Temperature	177.6849 °C
Cp	1.111578
Temperature	178.6583 °C
Cp	1.111185
Temperature	179.6317 °C
Cp	1.110789
Temperature	180.605 °C
Cp	1.110391
Temperature	181.5784 °C
Cp	1.110016
Temperature	182.5518 °C
Cp	1.109611
Temperature	183.5252 °C
Cp	1.109232
Temperature	184.4986 °C
Cp	1.108873
Temperature	185.472 °C
Cp	1.108531
Temperature	186.4454 °C
Cp	1.108199
Temperature	187.4187 °C
Cp	1.107851
Temperature	188.3921 °C
Cp	1.107551
Temperature	189.3655 °C
Cp	1.107238
Temperature	190.3389 °C
Cp	1.106917
Temperature	191.3123 °C
Cp	1.106589
Temperature	192.2857 °C
Cp	1.106259
Temperature	193.259 °C
Cp	1.105958
Temperature	194.2324 °C
Cp	1.105619
Temperature	195.2058 °C
Cp	1.105301
Temperature	196.1792 °C
Cp	1.105002
Temperature	197.1526 °C
Cp	1.104718
Temperature	198.126 °C
Cp	1.104445
Temperature	199.0994 °C
Cp	1.104161
Temperature	200.0728 °C
Cp	1.103914
Temperature	201.0461 °C
Cp	1.103657
Temperature	202.0195 °C
Cp	1.103395
Temperature	202.9929 °C
Cp	1.103125
Temperature	203.9663 °C
Cp	1.102847
Temperature	204.9397 °C
Cp	1.102563
Temperature	205.9131 °C
Cp	1.102283
Temperature	206.8865 °C
Cp	1.101985
Temperature	207.8598 °C
Cp	1.10169
Temperature	208.8332 °C
Cp	1.101394
Temperature	209.8066 °C
Cp	1.101099
Temperature	210.78 °C
Cp	1.1008
Temperature	211.7534 °C
Cp	1.10049
Temperature	212.7268 °C
Cp	1.100193
Temperature	213.7002 °C
Cp	1.099886
Temperature	214.6735 °C
Cp	1.099577
Temperature	215.6469 °C
Cp	1.099268
Temperature	216.6203 °C
Cp	1.098965
Temperature	217.5937 °C
Cp	1.098685
Temperature	218.5671 °C
Cp	1.098396
Temperature	219.5405 °C
Cp	1.098134
Temperature	220.5139 °C
Cp	1.097895
Temperature	221.4872 °C
Cp	1.09768
Temperature	222.4606 °C
Cp	1.097485
Temperature	223.434 °C
Cp	1.097292
Temperature	224.4074 °C
Cp	1.09714
Temperature	225.3808 °C
Cp	1.096991
Temperature	226.3542 °C
Cp	1.096844
Temperature	227.3276 °C
Cp	1.096699
Temperature	228.3009 °C
Cp	1.096559
Temperature	229.2743 °C
Cp	1.096442
Temperature	230.2477 °C
Cp	1.096296
Temperature	231.2211 °C
Cp	1.096164
Temperature	232.1945 °C
Cp	1.09604
Temperature	233.1679 °C
Cp	1.095924
Temperature	234.1413 °C
Cp	1.095807
Temperature	235.1147 °C
Cp	1.095665
Temperature	236.088 °C
Cp	1.095557
Temperature	237.0614 °C
Cp	1.095433
Temperature	238.0348 °C
Cp	1.095296
Temperature	239.0082 °C
Cp	1.095147
Temperature	239.9816 °C
Cp	1.094995
Temperature	240.955 °C
Cp	1.094843
Temperature	241.9283 °C
Cp	1.094705
Temperature	242.9017 °C
Cp	1.094562
Temperature	243.8751 °C
Cp	1.094442
Temperature	244.8485 °C
Cp	1.094344
Temperature	245.8219 °C
Cp	1.094266
Temperature	246.7953 °C
Cp	1.094209
Temperature	247.7687 °C
Cp	1.094161
Temperature	248.7421 °C
Cp	1.094144
Temperature	249.7154 °C
Cp	1.094133
Temperature	250.6888 °C
Cp	1.094127
Temperature	251.6622 °C
Cp	1.094126
Temperature	252.6356 °C
Cp	1.094127
Temperature	253.609 °C
Cp	1.094138
Temperature	254.5824 °C
Cp	1.09413
Temperature	255.5558 °C
Cp	1.094123
Temperature	256.5291 °C
Cp	1.094111
Temperature	257.5025 °C
Cp	1.094087
Temperature	258.4759 °C
Cp	1.094046
Temperature	259.4493 °C
Cp	1.093978
Temperature	260.4227 °C
Cp	1.093895
Temperature	261.3961 °C
Cp	1.093783
Temperature	262.3694 °C
Cp	1.093645
Temperature	263.3428 °C
Cp	1.093483
Temperature	264.3162 °C
Cp	1.093302
Temperature	265.2896 °C
Cp	1.093109
Temperature	266.263 °C
Cp	1.092906
Temperature	267.2364 °C
Cp	1.092704
Temperature	268.2098 °C
Cp	1.092511
Temperature	269.1832 °C
Cp	1.092331
Temperature	270.1566 °C
Cp	1.092174
Temperature	271.1299 °C
Cp	1.092046
Temperature	272.1033 °C
Cp	1.091947
Temperature	273.0767 °C
Cp	1.091882
Temperature	274.0501 °C
Cp	1.091853
Temperature	275.0235 °C
Cp	1.091859
Temperature	275.9969 °C
Cp	1.091895
Temperature	276.9702 °C
Cp	1.091957
Temperature	277.9436 °C
Cp	1.092036
Temperature	278.917 °C
Cp	1.092132
Temperature	279.8904 °C
Cp	1.09223
Temperature	280.8638 °C
Cp	1.092323
Temperature	281.8372 °C
Cp	1.092405
Temperature	282.8105 °C
Cp	1.092468
Temperature	283.7839 °C
Cp	1.092513
Temperature	284.7573 °C
Cp	1.092525
Temperature	285.7307 °C
Cp	1.092512
Temperature	286.7041 °C
Cp	1.092472
Temperature	287.6775 °C
Cp	1.092405
Temperature	288.6509 °C
Cp	1.092313
Temperature	289.6243 °C
Cp	1.092197
Temperature	290.5977 °C
Cp	1.09207
Temperature	291.571 °C
Cp	1.091931
Temperature	292.5444 °C
Cp	1.091785
Temperature	293.5178 °C
Cp	1.091641
Temperature	294.4912 °C
Cp	1.091506
Temperature	295.4646 °C
Cp	1.091387
Temperature	296.438 °C
Cp	1.091282
Temperature	297.4113 °C
Cp	1.091201
Temperature	298.3847 °C
Cp	1.091145
Temperature	299.3581 °C
Cp	1.091112
Temperature	300.3315 °C
Cp	1.091102
Temperature	301.3049 °C
Cp	1.091107
Temperature	302.2783 °C
Cp	1.091137
Temperature	303.2517 °C
Cp	1.091177
Temperature	304.2251 °C
Cp	1.091226
Temperature	305.1984 °C
Cp	1.09128
Temperature	306.1718 °C
Cp	1.091336
Temperature	307.1452 °C
Cp	1.091403
Temperature	308.1186 °C
Cp	1.091453
Temperature	309.092 °C
Cp	1.091506
Temperature	310.0654 °C
Cp	1.091561
Temperature	311.0388 °C
Cp	1.091617
Temperature	312.0121 °C
Cp	1.09167
Temperature	312.9855 °C
Cp	1.091716
Temperature	313.9589 °C
Cp	1.091762
Temperature	314.9323 °C
Cp	1.091805
Temperature	315.9057 °C
Cp	1.091838
Temperature	316.8791 °C
Cp	1.09186
Temperature	317.8524 °C
Cp	1.091871
Temperature	318.8258 °C
Cp	1.091872
Temperature	319.7992 °C
Cp	1.091867
Temperature	320.7726 °C
Cp	1.091838
Temperature	321.746 °C
Cp	1.0918
Temperature	322.7194 °C
Cp	1.091752
Temperature	323.6928 °C
Cp	1.091689
Temperature	324.6662 °C
Cp	1.091611
Temperature	325.6396 °C
Cp	1.091508
Temperature	326.6129 °C
Cp	1.091406
Temperature	327.5863 °C
Cp	1.091285
Temperature	328.5597 °C
Cp	1.09115
Temperature	329.5331 °C
Cp	1.091009
Temperature	330.5065 °C
Cp	1.09087
Temperature	331.4799 °C
Cp	1.090747
Temperature	332.4532 °C
Cp	1.090628
Temperature	333.4266 °C
Cp	1.090536
Temperature	334.4 °C
Cp	1.090472
Temperature	335.3734 °C
Cp	1.090437
Temperature	336.3468 °C
Cp	1.090431
Temperature	337.3202 °C
Cp	1.090455
Temperature	338.2935 °C
Cp	1.090503
Temperature	339.2669 °C
Cp	1.090573
Temperature	340.2403 °C
Cp	1.090658
Temperature	341.2137 °C
Cp	1.090753
Temperature	342.1871 °C
Cp	1.090853
Temperature	343.1605 °C
Cp	1.090952
Temperature	344.1339 °C
Cp	1.09105
Temperature	345.1073 °C
Cp	1.091141
Temperature	346.0807 °C
Cp	1.091225
Temperature	347.054 °C
Cp	1.091303
Temperature	348.0274 °C
Cp	1.091379
Temperature	349.0008 °C
Cp	1.091453
Temperature	349.9742 °C
Cp	1.091537
Temperature	350.9476 °C
Cp	1.091633
Temperature	351.921 °C
Cp	1.091743
Temperature	352.8943 °C
Cp	1.091874
Temperature	353.8677 °C
Cp	1.092028
Temperature	354.8411 °C
Cp	1.092206
Temperature	355.8145 °C
Cp	1.092411
Temperature	356.7879 °C
Cp	1.092628
Temperature	357.7613 °C
Cp	1.092862
Temperature	358.7346 °C
Cp	1.093102
Temperature	359.708 °C
Cp	1.093338
Temperature	360.6814 °C
Cp	1.093559
Temperature	361.6548 °C
Cp	1.093752
Temperature	362.6282 °C
Cp	1.093915
Temperature	363.6016 °C
Cp	1.094036
Temperature	364.575 °C
Cp	1.094117
Temperature	365.5484 °C
Cp	1.094159
Temperature	366.5218 °C
Cp	1.094172
Temperature	367.4951 °C
Cp	1.094165
Temperature	368.4685 °C
Cp	1.094163
Temperature	369.4419 °C
Cp	1.094182
Temperature	370.4153 °C
Cp	1.094244
Temperature	371.3887 °C
Cp	1.094375
Temperature	372.3621 °C
Cp	1.094598
Temperature	373.3354 °C
Cp	1.094937
Temperature	374.3088 °C
Cp	1.095389
Temperature	375.2822 °C
Cp	1.095973
Temperature	376.2556 °C
Cp	1.096685
Temperature	377.229 °C
Cp	1.097506
Temperature	378.2024 °C
Cp	1.098406
Temperature	379.1758 °C
Cp	1.099338
Temperature	380.1492 °C
Cp	1.10027
Temperature	381.1225 °C
Cp	1.10112
Temperature	382.0959 °C
Cp	1.101818
Temperature	383.0693 °C
Cp	1.10229
Temperature	384.0427 °C
Cp	1.102459
Temperature	385.0161 °C
Cp	1.102253
Temperature	385.9895 °C
Cp	1.101596
Temperature	386.9629 °C
Cp	1.100438
Temperature	387.9362 °C
Cp	1.098736
Temperature	388.9096 °C
Cp	1.096461
Temperature	389.883 °C
Cp	1.093614
Temperature	390.8564 °C
Cp	1.090208
Temperature	391.8298 °C
Cp	1.086278
Temperature	392.8032 °C
Cp	1.081887
Temperature	393.7766 °C
Cp	1.077096
Temperature	394.7499 °C
Cp	1.072007
Temperature	395.7233 °C
Cp	1.066707
[Rev Cp Calibration]
Date Applied	24/10/2024 12:37:31
Description	From -89.998 °C to 390.542 °C at 2.000°C/min
Gas Type	Nitrogen
Pan Type	Tzero Aluminum
Source Files 1	C:\ProgramData\TA Instruments\TRIOS\Data\Reverse Heat Capacity Calibration(6).tri
GUID	ba867d72-cfbb-486e-971e-e86aa544cc02
Temperature	-89.99799 °C
Cp	1.070076
Temperature	-89.03691 °C
Cp	1.072008
Temperature	-88.07584 °C
Cp	1.073556
Temperature	-87.11475 °C
Cp	1.074743
Temperature	-86.15367 °C
Cp	1.075597
Temperature	-85.1926 °C
Cp	1.076163
Temperature	-84.23151 °C
Cp	1.076477
Temperature	-83.27043 °C
Cp	1.076579
Temperature	-82.30936 °C
Cp	1.076527
Temperature	-81.34827 °C
Cp	1.076322
Temperature	-80.38719 °C
Cp	1.076039
Temperature	-79.42612 °C
Cp	1.07571
Temperature	-78.46503 °C
Cp	1.075361
Temperature	-77.50395 °C
Cp	1.075011
Temperature	-76.54288 °C
Cp	1.074656
Temperature	-75.58179 °C
Cp	1.074359
Temperature	-74.62071 °C
Cp	1.074086
Temperature	-73.65964 °C
Cp	1.073842
Temperature	-72.69855 °C
Cp	1.073627
Temperature	-71.73747 °C
Cp	1.073442
Temperature	-70.7764 °C
Cp	1.07329
Temperature	-69.81532 °C
Cp	1.073148
Temperature	-68.85423 °C
Cp	1.073021
Temperature	-67.89315 °C
Cp	1.072902
Temperature	-66.93208 °C
Cp	1.072782
Temperature	-65.97099 °C
Cp	1.072656
Temperature	-65.00991 °C
Cp	1.072518
Temperature	-64.04884 °C
Cp	1.072374
Temperature	-63.08775 °C
Cp	1.072201
Temperature	-62.12667 °C
Cp	1.072019
Temperature	-61.1656 °C
Cp	1.071827
Temperature	-60.20451 °C
Cp	1.071624
Temperature	-59.24343 °C
Cp	1.071411
Temperature	-58.28236 °C
Cp	1.071167
Temperature	-57.32127 °C
Cp	1.070956
Temperature	-56.3602 °C
Cp	1.070724
Temperature	-55.39911 °C
Cp	1.070483
Temperature	-54.43803 °C
Cp	1.070242
Temperature	-53.47696 °C
Cp	1.070009
Temperature	-52.51587 °C
Cp	1.069825
Temperature	-51.55479 °C
Cp	1.069601
Temperature	-50.59372 °C
Cp	1.069418
Temperature	-49.63263 °C
Cp	1.069267
Temperature	-48.67155 °C
Cp	1.069138
Temperature	-47.71048 °C
Cp	1.069021
Temperature	-46.74939 °C
Cp	1.068875
Temperature	-45.78831 °C
Cp	1.068771
Temperature	-44.82724 °C
Cp	1.068634
Temperature	-43.86615 °C
Cp	1.068462
Temperature	-42.90508 °C
Cp	1.068255
Temperature	-41.944 °C
Cp	1.068012
Temperature	-40.98291 °C
Cp	1.067742
Temperature	-40.02184 °C
Cp	1.067427
Temperature	-39.06076 °C
Cp	1.067088
Temperature	-38.09967 °C
Cp	1.066727
Temperature	-37.1386 °C
Cp	1.066349
Temperature	-36.17752 °C
Cp	1.065958
Temperature	-35.21643 °C
Cp	1.065559
Temperature	-34.25536 °C
Cp	1.065162
Temperature	-33.29427 °C
Cp	1.06476
Temperature	-32.33319 °C
Cp	1.064368
Temperature	-31.37212 °C
Cp	1.06399
Temperature	-30.41104 °C
Cp	1.063628
Temperature	-29.44995 °C
Cp	1.063283
Temperature	-28.48887 °C
Cp	1.06295
Temperature	-27.5278 °C
Cp	1.062645
Temperature	-26.56672 °C
Cp	1.062355
Temperature	-25.60563 °C
Cp	1.06208
Temperature	-24.64456 °C
Cp	1.061819
Temperature	-23.68348 °C
Cp	1.061573
Temperature	-22.72239 °C
Cp	1.061345
Temperature	-21.76132 °C
Cp	1.061123
Temperature	-20.80024 °C
Cp	1.060915
Temperature	-19.83916 °C
Cp	1.060719
Temperature	-18.87807 °C
Cp	1.060531
Temperature	-17.917 °C
Cp	1.06035
Temperature	-16.95592 °C
Cp	1.060161
Temperature	-15.99484 °C
Cp	1.059992
Temperature	-15.03376 °C
Cp	1.059817
Temperature	-14.07268 °C
Cp	1.059634
Temperature	-13.1116 °C
Cp	1.059445
Temperature	-12.15052 °C
Cp	1.059248
Temperature	-11.18944 °C
Cp	1.059043
Temperature	-10.22836 °C
Cp	1.058842
Temperature	-9.267276 °C
Cp	1.058615
Temperature	-8.306196 °C
Cp	1.058388
Temperature	-7.345116 °C
Cp	1.058155
Temperature	-6.384036 °C
Cp	1.057911
Temperature	-5.422956 °C
Cp	1.057652
Temperature	-4.461876 °C
Cp	1.057356
Temperature	-3.500796 °C
Cp	1.057063
Temperature	-2.539716 °C
Cp	1.056732
Temperature	-1.578636 °C
Cp	1.056364
Temperature	-0.6175562 °C
Cp	1.05596
Temperature	0.3435238 °C
Cp	1.055523
Temperature	1.304604 °C
Cp	1.055066
Temperature	2.265684 °C
Cp	1.054561
Temperature	3.226764 °C
Cp	1.054035
Temperature	4.187844 °C
Cp	1.053488
Temperature	5.148924 °C
Cp	1.052922
Temperature	6.110003 °C
Cp	1.052337
Temperature	7.071084 °C
Cp	1.051736
Temperature	8.032164 °C
Cp	1.051118
Temperature	8.993243 °C
Cp	1.050488
Temperature	9.954324 °C
Cp	1.049848
Temperature	10.9154 °C
Cp	1.049202
Temperature	11.87648 °C
Cp	1.048552
Temperature	12.83756 °C
Cp	1.047902
Temperature	13.79864 °C
Cp	1.047255
Temperature	14.75972 °C
Cp	1.046615
Temperature	15.7208 °C
Cp	1.045983
Temperature	16.68188 °C
Cp	1.045362
Temperature	17.64296 °C
Cp	1.044756
Temperature	18.60404 °C
Cp	1.044164
Temperature	19.56512 °C
Cp	1.04358
Temperature	20.5262 °C
Cp	1.043027
Temperature	21.48728 °C
Cp	1.042485
Temperature	22.44836 °C
Cp	1.041958
Temperature	23.40944 °C
Cp	1.041446
Temperature	24.37052 °C
Cp	1.040952
Temperature	25.3316 °C
Cp	1.040493
Temperature	26.29268 °C
Cp	1.040022
Temperature	27.25376 °C
Cp	1.039578
Temperature	28.21484 °C
Cp	1.039158
Temperature	29.17592 °C
Cp	1.038758
Temperature	30.137 °C
Cp	1.038373
Temperature	31.09808 °C
Cp	1.037981
Temperature	32.05916 °C
Cp	1.03763
Temperature	33.02024 °C
Cp	1.037276
Temperature	33.98132 °C
Cp	1.03692
Temperature	34.9424 °C
Cp	1.036565
Temperature	35.90348 °C
Cp	1.036213
Temperature	36.86456 °C
Cp	1.035866
Temperature	37.82564 °C
Cp	1.035529
Temperature	38.78672 °C
Cp	1.035195
Temperature	39.7478 °C
Cp	1.034875
Temperature	40.70888 °C
Cp	1.034568
Temperature	41.66996 °C
Cp	1.034276
Temperature	42.63104 °C
Cp	1.033996
Temperature	43.59212 °C
Cp	1.033726
Temperature	44.5532 °C
Cp	1.033469
Temperature	45.51428 °C
Cp	1.033221
Temperature	46.47536 °C
Cp	1.03298
Temperature	47.43644 °C
Cp	1.032744
Temperature	48.39752 °C
Cp	1.032514
Temperature	49.3586 °C
Cp	1.032289
Temperature	50.31968 °C
Cp	1.032065
Temperature	51.28076 °C
Cp	1.031844
Temperature	52.24184 °C
Cp	1.031627
Temperature	53.20292 °C
Cp	1.031413
Temperature	54.164 °C
Cp	1.031203
Temperature	55.12508 °C
Cp	1.030989
Temperature	56.08616 °C
Cp	1.030791
Temperature	57.04724 °C
Cp	1.030595
Temperature	58.00832 °C
Cp	1.030403
Temperature	58.9694 °C
Cp	1.030217
Temperature	59.93048 °C
Cp	1.03004
Temperature	60.89156 °C
Cp	1.029871
Temperature	61.85264 °C
Cp	1.029718
Temperature	62.81372 °C
Cp	1.029567
Temperature	63.7748 °C
Cp	1.02943
Temperature	64.73589 °C
Cp	1.029304
Temperature	65.69696 °C
Cp	1.029185
Temperature	66.65804 °C
Cp	1.02907
Temperature	67.61913 °C
Cp	1.028946
Temperature	68.5802 °C
Cp	1.028831
Temperature	69.54128 °C
Cp	1.028703
Temperature	70.50237 °C
Cp	1.028561
Temperature	71.46344 °C
Cp	1.028404
Temperature	72.42452 °C
Cp	1.028234
Temperature	73.3856 °C
Cp	1.028063
Temperature	74.34668 °C
Cp	1.027861
Temperature	75.30776 °C
Cp	1.027657
Temperature	76.26884 °C
Cp	1.027451
Temperature	77.22992 °C
Cp	1.027243
Temperature	78.191 °C
Cp	1.027036
Temperature	79.15208 °C
Cp	1.026812
Temperature	80.11316 °C
Cp	1.026623
Temperature	81.07424 °C
Cp	1.026431
Temperature	82.03532 °C
Cp	1.026241
Temperature	82.9964 °C
Cp	1.02606
Temperature	83.95748 °C
Cp	1.025891
Temperature	84.91856 °C
Cp	1.025739
Temperature	85.87964 °C
Cp	1.025614
Temperature	86.84072 °C
Cp	1.025493
Temperature	87.8018 °C
Cp	1.0254
Temperature	88.76288 °C
Cp	1.025329
Temperature	89.72396 °C
Cp	1.025274
Temperature	90.68504 °C
Cp	1.025229
Temperature	91.64612 °C
Cp	1.025174
Temperature	92.6072 °C
Cp	1.025138
Temperature	93.56828 °C
Cp	1.025083
Temperature	94.52936 °C
Cp	1.025008
Temperature	95.49044 °C
Cp	1.024912
Temperature	96.45152 °C
Cp	1.024796
Temperature	97.4126 °C
Cp	1.024671
Temperature	98.37368 °C
Cp	1.024506
Temperature	99.33476 °C
Cp	1.02433
Temperature	100.2958 °C
Cp	1.024144
Temperature	101.2569 °C
Cp	1.023948
Temperature	102.218 °C
Cp	1.023743
Temperature	103.1791 °C
Cp	1.023522
Temperature	104.1402 °C
Cp	1.023309
Temperature	105.1012 °C
Cp	1.023089
Temperature	106.0623 °C
Cp	1.022866
Temperature	107.0234 °C
Cp	1.022644
Temperature	107.9845 °C
Cp	1.022427
Temperature	108.9456 °C
Cp	1.022218
Temperature	109.9066 °C
Cp	1.022022
Temperature	110.8677 °C
Cp	1.021836
Temperature	111.8288 °C
Cp	1.021666
Temperature	112.7899 °C
Cp	1.021512
Temperature	113.751 °C
Cp	1.021374
Temperature	114.712 °C
Cp	1.02125
Temperature	115.6731 °C
Cp	1.021137
Temperature	116.6342 °C
Cp	1.021041
Temperature	117.5953 °C
Cp	1.020953
Temperature	118.5564 °C
Cp	1.020872
Temperature	119.5174 °C
Cp	1.020796
Temperature	120.4785 °C
Cp	1.020725
Temperature	121.4396 °C
Cp	1.020659
Temperature	122.4007 °C
Cp	1.020587
Temperature	123.3618 °C
Cp	1.020515
Temperature	124.3228 °C
Cp	1.02044
Temperature	125.2839 °C
Cp	1.020359
Temperature	126.245 °C
Cp	1.02027
Temperature	127.2061 °C
Cp	1.020167
Temperature	128.1672 °C
Cp	1.020057
Temperature	129.1282 °C
Cp	1.019933
Temperature	130.0893 °C
Cp	1.019793
Temperature	131.0504 °C
Cp	1.019638
Temperature	132.0115 °C
Cp	1.019471
Temperature	132.9726 °C
Cp	1.019292
Temperature	133.9336 °C
Cp	1.019107
Temperature	134.8947 °C
Cp	1.018912
Temperature	135.8558 °C
Cp	1.018717
Temperature	136.8169 °C
Cp	1.018527
Temperature	137.778 °C
Cp	1.018344
Temperature	138.739 °C
Cp	1.018171
Temperature	139.7001 °C
Cp	1.018004
Temperature	140.6612 °C
Cp	1.01787
Temperature	141.6223 °C
Cp	1.01775
Temperature	142.5834 °C
Cp	1.017652
Temperature	143.5444 °C
Cp	1.017578
Temperature	144.5055 °C
Cp	1.017534
Temperature	145.4666 °C
Cp	1.017536
Temperature	146.4277 °C
Cp	1.017545
Temperature	147.3888 °C
Cp	1.017595
Temperature	148.3498 °C
Cp	1.017679
Temperature	149.3109 °C
Cp	1.01779
Temperature	150.272 °C
Cp	1.01792
Temperature	151.2331 °C
Cp	1.018043
Temperature	152.1942 °C
Cp	1.018199
Temperature	153.1552 °C
Cp	1.018339
Temperature	154.1163 °C
Cp	1.018458
Temperature	155.0774 °C
Cp	1.018552
Temperature	156.0385 °C
Cp	1.018618
Temperature	156.9996 °C
Cp	1.018662
Temperature	157.9606 °C
Cp	1.018664
Temperature	158.9217 °C
Cp	1.018632
Temperature	159.8828 °C
Cp	1.018575
Temperature	160.8439 °C
Cp	1.018492
Temperature	161.805 °C
Cp	1.018383
Temperature	162.766 °C
Cp	1.01825
Temperature	163.7271 °C
Cp	1.018087
Temperature	164.6882 °C
Cp	1.017917
Temperature	165.6493 °C
Cp	1.017726
Temperature	166.6104 °C
Cp	1.017522
Temperature	167.5714 °C
Cp	1.01731
Temperature	168.5325 °C
Cp	1.017098
Temperature	169.4936 °C
Cp	1.016902
Temperature	170.4547 °C
Cp	1.016695
Temperature	171.4158 °C
Cp	1.016508
Temperature	172.3768 °C
Cp	1.016342
Temperature	173.3379 °C
Cp	1.016195
Temperature	174.299 °C
Cp	1.016065
Temperature	175.2601 °C
Cp	1.015927
Temperature	176.2212 °C
Cp	1.015838
Temperature	177.1822 °C
Cp	1.015746
Temperature	178.1433 °C
Cp	1.015651
Temperature	179.1044 °C
Cp	1.015555
Temperature	180.0655 °C
Cp	1.015459
Temperature	181.0266 °C
Cp	1.015401
Temperature	181.9876 °C
Cp	1.015288
Temperature	182.9487 °C
Cp	1.015195
Temperature	183.9098 °C
Cp	1.015117
Temperature	184.8709 °C
Cp	1.01505
Temperature	185.832 °C
Cp	1.014988
Temperature	186.793 °C
Cp	1.014927
Temperature	187.7541 °C
Cp	1.014849
Temperature	188.7152 °C
Cp	1.014789
Temperature	189.6763 °C
Cp	1.01471
Temperature	190.6374 °C
Cp	1.014614
Temperature	191.5984 °C
Cp	1.014503
Temperature	192.5595 °C
Cp	1.014381
Temperature	193.5206 °C
Cp	1.014268
Temperature	194.4817 °C
Cp	1.014122
Temperature	195.4428 °C
Cp	1.013984
Temperature	196.4038 °C
Cp	1.013853
Temperature	197.3649 °C
Cp	1.013726
Temperature	198.326 °C
Cp	1.013603
Temperature	199.2871 °C
Cp	1.013467
Temperature	200.2482 °C
Cp	1.013359
Temperature	201.2092 °C
Cp	1.013243
Temperature	202.1703 °C
Cp	1.013123
Temperature	203.1314 °C
Cp	1.013002
Temperature	204.0925 °C
Cp	1.012884
Temperature	205.0536 °C
Cp	1.012788
Temperature	206.0146 °C
Cp	1.012674
Temperature	206.9757 °C
Cp	1.012579
Temperature	207.9368 °C
Cp	1.012501
Temperature	208.8979 °C
Cp	1.012439
Temperature	209.859 °C
Cp	1.012389
Temperature	210.82 °C
Cp	1.012351
Temperature	211.7811 °C
Cp	1.012312
Temperature	212.7422 °C
Cp	1.01229
Temperature	213.7033 °C
Cp	1.012262
Temperature	214.6644 °C
Cp	1.012227
Temperature	215.6254 °C
Cp	1.012183
Temperature	216.5865 °C
Cp	1.012129
Temperature	217.5476 °C
Cp	1.012077
Temperature	218.5087 °C
Cp	1.01199
Temperature	219.4698 °C
Cp	1.011897
Temperature	220.4308 °C
Cp	1.011793
Temperature	221.3919 °C
Cp	1.011674
Temperature	222.353 °C
Cp	1.011537
Temperature	223.3141 °C
Cp	1.011362
Temperature	224.2752 °C
Cp	1.011194
Temperature	225.2362 °C
Cp	1.010993
Temperature	226.1973 °C
Cp	1.010766
Temperature	227.1584 °C
Cp	1.010517
Temperature	228.1195 °C
Cp	1.010251
Temperature	229.0806 °C
Cp	1.009998
Temperature	230.0416 °C
Cp	1.009703
Temperature	231.0027 °C
Cp	1.009422
Temperature	231.9638 °C
Cp	1.009156
Temperature	232.9249 °C
Cp	1.008906
Temperature	233.886 °C
Cp	1.008675
Temperature	234.847 °C
Cp	1.008462
Temperature	235.8081 °C
Cp	1.008258
Temperature	236.7692 °C
Cp	1.00809
Temperature	237.7303 °C
Cp	1.007934
Temperature	238.6914 °C
Cp	1.007793
Temperature	239.6524 °C
Cp	1.007668
Temperature	240.6135 °C
Cp	1.007562
Temperature	241.5746 °C
Cp	1.007487
Temperature	242.5357 °C
Cp	1.00741
Temperature	243.4967 °C
Cp	1.00736
Temperature	244.4578 °C
Cp	1.007332
Temperature	245.4189 °C
Cp	1.007321
Temperature	246.38 °C
Cp	1.007321
Temperature	247.3411 °C
Cp	1.007312
Temperature	248.3022 °C
Cp	1.007331
Temperature	249.2632 °C
Cp	1.007338
Temperature	250.2243 °C
Cp	1.007335
Temperature	251.1854 °C
Cp	1.00732
Temperature	252.1465 °C
Cp	1.007295
Temperature	253.1076 °C
Cp	1.007277
Temperature	254.0686 °C
Cp	1.007227
Temperature	255.0297 °C
Cp	1.007179
Temperature	255.9908 °C
Cp	1.007133
Temperature	256.9519 °C
Cp	1.00709
Temperature	257.913 °C
Cp	1.007049
Temperature	258.874 °C
Cp	1.007012
Temperature	259.8351 °C
Cp	1.006978
Temperature	260.7962 °C
Cp	1.006956
Temperature	261.7573 °C
Cp	1.00694
Temperature	262.7184 °C
Cp	1.006934
Temperature	263.6794 °C
Cp	1.006939
Temperature	264.6405 °C
Cp	1.00696
Temperature	265.6016 °C
Cp	1.006999
Temperature	266.5627 °C
Cp	1.007054
Temperature	267.5237 °C
Cp	1.007131
Temperature	268.4848 °C
Cp	1.00723
Temperature	269.4459 °C
Cp	1.00735
Temperature	270.407 °C
Cp	1.007493
Temperature	271.3681 °C
Cp	1.007656
Temperature	272.3292 °C
Cp	1.007839
Temperature	273.2902 °C
Cp	1.008039
Temperature	274.2513 °C
Cp	1.008257
Temperature	275.2124 °C
Cp	1.008488
Temperature	276.1735 °C
Cp	1.008731
Temperature	277.1346 °C
Cp	1.008977
Temperature	278.0956 °C
Cp	1.009237
Temperature	279.0567 °C
Cp	1.009498
Temperature	280.0178 °C
Cp	1.009757
Temperature	280.9789 °C
Cp	1.010014
Temperature	281.9399 °C
Cp	1.010267
Temperature	282.901 °C
Cp	1.010515
Temperature	283.8621 °C
Cp	1.01076
Temperature	284.8232 °C
Cp	1.010993
Temperature	285.7843 °C
Cp	1.011222
Temperature	286.7454 °C
Cp	1.011447
Temperature	287.7064 °C
Cp	1.011665
Temperature	288.6675 °C
Cp	1.011876
Temperature	289.6286 °C
Cp	1.012079
Temperature	290.5897 °C
Cp	1.01228
Temperature	291.5508 °C
Cp	1.012474
Temperature	292.5118 °C
Cp	1.012662
Temperature	293.4729 °C
Cp	1.012846
Temperature	294.434 °C
Cp	1.013028
Temperature	295.3951 °C
Cp	1.013211
Temperature	296.3561 °C
Cp	1.013391
Temperature	297.3172 °C
Cp	1.013574
Temperature	298.2783 °C
Cp	1.013759
Temperature	299.2394 °C
Cp	1.013947
Temperature	300.2005 °C
Cp	1.014136
Temperature	301.1616 °C
Cp	1.01432
Temperature	302.1226 °C
Cp	1.014511
Temperature	303.0837 °C
Cp	1.014695
Temperature	304.0448 °C
Cp	1.014872
Temperature	305.0059 °C
Cp	1.01504
Temperature	305.9669 °C
Cp	1.015198
Temperature	306.928 °C
Cp	1.015343
Temperature	307.8891 °C
Cp	1.015479
Temperature	308.8502 °C
Cp	1.015595
Temperature	309.8113 °C
Cp	1.015699
Temperature	310.7724 °C
Cp	1.015789
Temperature	311.7334 °C
Cp	1.015865
Temperature	312.6945 °C
Cp	1.015925
Temperature	313.6556 °C
Cp	1.015964
Temperature	314.6167 °C
Cp	1.015999
Temperature	315.5778 °C
Cp	1.016018
Temperature	316.5388 °C
Cp	1.016025
Temperature	317.4999 °C
Cp	1.016024
Temperature	318.461 °C
Cp	1.01602
Temperature	319.4221 °C
Cp	1.016029
Temperature	320.3831 °C
Cp	1.016025
Temperature	321.3442 °C
Cp	1.016037
Temperature	322.3053 °C
Cp	1.016066
Temperature	323.2664 °C
Cp	1.01611
Temperature	324.2275 °C
Cp	1.016169
Temperature	325.1886 °C
Cp	1.016225
Temperature	326.1496 °C
Cp	1.016318
Temperature	327.1107 °C
Cp	1.016411
Temperature	328.0718 °C
Cp	1.016504
Temperature	329.0329 °C
[...]
187.5883	110.9831	0.0914
187.5967	110.9007	0.0914
187.6050	110.8174	0.0913
187.6133	110.7329	0.0913
187.6217	110.6510	0.0911
187.6300	110.5679	0.0907
187.6383	110.4841	0.0907
187.6467	110.4015	0.0906
187.6550	110.3174	0.0906
187.6633	110.2351	0.0906
187.6717	110.1511	0.0905
187.6800	110.0685	0.0905
187.6883	109.9848	0.0905
187.6967	109.9011	0.0904
187.7050	109.8194	0.0904
187.7133	109.7350	0.0904
187.7217	109.6520	0.0904
187.7300	109.5692	0.0903
187.7383	109.4868	0.0902
187.7467	109.4025	0.0902
187.7550	109.3195	0.0901
187.7633	109.2376	0.0901
187.7717	109.1538	0.0900
187.7800	109.0698	0.0899
187.7883	108.9875	0.0899
187.7967	108.9044	0.0898
187.8050	108.8210	0.0898
187.8133	108.7384	0.0895
187.8217	108.6542	0.0894
187.8300	108.5707	0.0894
187.8383	108.4875	0.0894
187.8467	108.4062	0.0892
187.8550	108.3219	0.0892
187.8633	108.2381	0.0891
187.8717	108.1559	0.0891
187.8800	108.0728	0.0890
187.8883	107.9890	0.0889
187.8967	107.9056	0.0889
187.9050	107.8218	0.0889
187.9133	107.7384	0.0888
187.9217	107.6561	0.0887
187.9300	107.5730	0.0887
187.9383	107.4902	0.0886
187.9467	107.4054	0.0886
187.9550	107.3241	0.0885
187.9633	107.2423	0.0884
187.9717	107.1571	0.0885
187.9800	107.0744	0.0884
187.9883	106.9918	0.0883
187.9967	106.9083	0.0881
188.0050	106.8259	0.0881
188.0133	106.7412	0.0881
188.0217	106.6580	0.0881
188.0300	106.5762	0.0879
188.0383	106.4918	0.0878
188.0467	106.4093	0.0877
188.0550	106.3260	0.0877
188.0633	106.2431	0.0873
188.0717	106.1601	0.0872
188.0800	106.0768	0.0871
188.0883	105.9933	0.0871
188.0967	105.9105	0.0871
188.1050	105.8274	0.0870
188.1133	105.7437	0.0870
188.1217	105.6617	0.0867
188.1300	105.5784	0.0866
188.1383	105.4940	0.0866
188.1467	105.4109	0.0865
188.1550	105.3279	0.0864
188.1633	105.2442	0.0864
188.1717	105.1622	0.0863
188.1800	105.0787	0.0863
188.1883	104.9950	0.0862
188.1967	104.9123	0.0861
188.2050	104.8291	0.0861
188.2133	104.7456	0.0860
188.2217	104.6622	0.0860
188.2300	104.5788	0.0860
188.2383	104.4966	0.0859
188.2467	104.4130	0.0853
188.2550	104.3296	0.0853
188.2633	104.2455	0.0853
188.2717	104.1643	0.0853
188.2800	104.0799	0.0852
188.2883	103.9966	0.0852
188.2967	103.9137	0.0852
188.3050	103.8302	0.0851
188.3133	103.7480	0.0851
188.3217	103.6651	0.0851
188.3300	103.5816	0.0850
188.3383	103.4987	0.0850
188.3467	103.4155	0.0850
188.3550	103.3322	0.0849
188.3633	103.2496	0.0849
188.3717	103.1659	0.0849
188.3800	103.0826	0.0848
188.3883	103.0004	0.0846
188.3967	102.9169	0.0845
188.4050	102.8343	0.0844
188.4133	102.7506	0.0844
188.4217	102.6670	0.0843
188.4300	102.5838	0.0842
188.4383	102.5008	0.0839
188.4467	102.4168	0.0839
188.4550	102.3344	0.0838
188.4633	102.2509	0.0836
188.4717	102.1673	0.0836
188.4800	102.0852	0.0835
188.4883	102.0017	0.0835
188.4967	101.9176	0.0835
188.5050	101.8357	0.0834
188.5133	101.7516	0.0834
188.5217	101.6686	0.0834
188.5300	101.5858	0.0832
188.5383	101.5027	0.0831
188.5467	101.4191	0.0831
188.5550	101.3364	0.0830
188.5633	101.2534	0.0830
188.5717	101.1700	0.0830
188.5800	101.0875	0.0830
188.5883	101.0037	0.0823
188.5967	100.9204	0.0821
188.6050	100.8373	0.0821
188.6133	100.7536	0.0821
188.6217	100.6701	0.0821
188.6300	100.5871	0.0821
188.6383	100.5052	0.0820
188.6467	100.4211	0.0819
188.6550	100.3377	0.0819
188.6633	100.2545	0.0819
188.6717	100.1724	0.0818
188.6800	100.0889	0.0818
188.6883	100.0045	0.0818
188.6967	99.9217	0.0818
188.7050	99.8372	0.0818
188.7133	99.7552	0.0817
188.7217	99.6728	0.0816
188.7300	99.5902	0.0816
188.7383	99.5061	0.0816
188.7467	99.4220	0.0815
188.7550	99.3399	0.0814
188.7633	99.2565	0.0814
188.7717	99.1735	0.0813
188.7800	99.0906	0.0813
188.7883	99.0067	0.0812
188.7967	98.9245	0.0811
188.8050	98.8402	0.0810
188.8133	98.7573	0.0810
188.8217	98.6745	0.0810
188.8300	98.5911	0.0809
188.8383	98.5084	0.0809
188.8467	98.4252	0.0808
188.8550	98.3418	0.0808
188.8633	98.2586	0.0808
188.8717	98.1755	0.0808
188.8800	98.0919	0.0806
188.8883	98.0098	0.0805
188.8967	97.9264	0.0805
188.9050	97.8437	0.0804
188.9133	97.7593	0.0805
188.9217	97.6765	0.0800
188.9300	97.5937	0.0796
188.9383	97.5104	0.0796
188.9467	97.4263	0.0795
188.9550	97.3433	0.0795
188.9633	97.2615	0.0793
188.9717	97.1774	0.0793
188.9800	97.0937	0.0793
188.9883	97.0108	0.0793
188.9967	96.9286	0.0792
189.0050	96.8445	0.0792
189.0133	96.7604	0.0792
189.0217	96.6779	0.0792
189.0300	96.5939	0.0791
189.0383	96.5118	0.0791
189.0467	96.4285	0.0790
189.0550	96.3447	0.0790
189.0633	96.2631	0.0789
189.0717	96.1797	0.0789
189.0800	96.0964	0.0789
189.0883	96.0127	0.0788
189.0967	95.9286	0.0788
189.1050	95.8472	0.0788
189.1133	95.7642	0.0786
189.1217	95.6809	0.0786
189.1300	95.5975	0.0785
189.1383	95.5138	0.0785
189.1467	95.4305	0.0784
189.1550	95.3478	0.0784
189.1633	95.2652	0.0783
189.1717	95.1821	0.0783
189.1800	95.0986	0.0782
189.1883	95.0142	0.0781
189.1967	94.9316	0.0781
189.2050	94.8470	0.0781
189.2133	94.7656	0.0778
189.2217	94.6818	0.0778
189.2300	94.5993	0.0777
189.2383	94.5151	0.0777
189.2467	94.4324	0.0774
189.2550	94.3484	0.0774
189.2633	94.2667	0.0774
189.2717	94.1836	0.0773
189.2800	94.0996	0.0773
189.2883	94.0166	0.0772
189.2967	93.9334	0.0772
189.3050	93.8498	0.0771
189.3133	93.7676	0.0770
189.3217	93.6840	0.0770
189.3300	93.6010	0.0769
189.3383	93.5178	0.0769
189.3467	93.4353	0.0768
189.3550	93.3513	0.0768
189.3633	93.2679	0.0767
189.3717	93.1834	0.0766
189.3800	93.1016	0.0765
189.3883	93.0185	0.0762
189.3967	92.9348	0.0762
189.4050	92.8521	0.0761
189.4133	92.7685	0.0760
189.4217	92.6855	0.0760
189.4300	92.6015	0.0759
189.4383	92.5190	0.0759
189.4467	92.4372	0.0758
189.4550	92.3536	0.0757
189.4633	92.2697	0.0756
189.4717	92.1865	0.0756
189.4800	92.1036	0.0755
189.4883	92.0193	0.0755
189.4967	91.9357	0.0754
189.5050	91.8532	0.0754
189.5133	91.7709	0.0753
189.5217	91.6876	0.0751
189.5300	91.6044	0.0751
189.5383	91.5213	0.0750
189.5467	91.4380	0.0750
189.5550	91.3564	0.0750
189.5633	91.2729	0.0749
189.5717	91.1887	0.0749
189.5800	91.1059	0.0749
189.5883	91.0229	0.0748
189.5967	90.9389	0.0748
189.6050	90.8559	0.0747
189.6133	90.7728	0.0747
189.6217	90.6892	0.0746
189.6300	90.6066	0.0744
189.6383	90.5235	0.0744
189.6467	90.4406	0.0744
189.6550	90.3568	0.0743
189.6633	90.2735	0.0742
189.6717	90.1909	0.0741
189.6800	90.1076	0.0741
189.6883	90.0243	0.0741
189.6967	89.9401	0.0740
189.7050	89.8577	0.0739
189.7133	89.7739	0.0739
189.7217	89.6921	0.0738
189.7300	89.6084	0.0737
189.7383	89.5259	0.0737
189.7467	89.4426	0.0734
189.7550	89.3591	0.0734
189.7633	89.2751	0.0734
189.7717	89.1924	0.0731
189.7800	89.1093	0.0730
189.7883	89.0256	0.0730
189.7967	88.9417	0.0729
189.8050	88.8594	0.0729
189.8133	88.7748	0.0729
189.8217	88.6920	0.0726
189.8300	88.6093	0.0725
189.8383	88.5242	0.0725
189.8467	88.4427	0.0724
189.8550	88.3601	0.0724
189.8633	88.2762	0.0724
189.8717	88.1940	0.0723
189.8800	88.1104	0.0723
189.8883	88.0277	0.0722
189.8967	87.9438	0.0722
189.9050	87.8615	0.0721
189.9133	87.7785	0.0721
189.9217	87.6945	0.0721
189.9300	87.6120	0.0720
189.9383	87.5288	0.0720
189.9467	87.4457	0.0719
189.9550	87.3636	0.0717
189.9633	87.2792	0.0717
189.9717	87.1954	0.0716
189.9800	87.1129	0.0716
189.9883	87.0298	0.0716
189.9967	86.9460	0.0715
190.0050	86.8640	0.0711
190.0133	86.7792	0.0709
190.0217	86.6955	0.0709
190.0300	86.6136	0.0709
190.0383	86.5315	0.0709
190.0467	86.4469	0.0708
190.0550	86.3634	0.0708
190.0633	86.2805	0.0707
190.0717	86.1982	0.0707
190.0800	86.1143	0.0706
190.0883	86.0313	0.0706
190.0967	85.9484	0.0705
190.1050	85.8652	0.0705
190.1133	85.7816	0.0705
190.1217	85.6993	0.0705
190.1300	85.6158	0.0704
190.1383	85.5327	0.0703
190.1467	85.4498	0.0703
190.1550	85.3666	0.0702
190.1633	85.2821	0.0702
190.1717	85.2005	0.0699
190.1800	85.1169	0.0699
190.1883	85.0335	0.0699
190.1967	84.9501	0.0698
190.2050	84.8669	0.0695
190.2133	84.7828	0.0693
190.2217	84.7008	0.0692
190.2300	84.6164	0.0692
190.2383	84.5331	0.0691
190.2467	84.4509	0.0691
190.2550	84.3669	0.0691
190.2633	84.2850	0.0690
190.2717	84.2013	0.0690
190.2800	84.1181	0.0689
190.2883	84.0344	0.0689
190.2967	83.9520	0.0689
190.3050	83.8681	0.0689
190.3133	83.7860	0.0688
190.3217	83.7020	0.0686
190.3300	83.6187	0.0686
190.3383	83.5360	0.0686
190.3467	83.4519	0.0685
190.3550	83.3700	0.0684
190.3633	83.2863	0.0684
190.3717	83.2040	0.0684
190.3800	83.1206	0.0683
190.3883	83.0374	0.0683
190.3967	82.9546	0.0683
190.4050	82.8718	0.0680
190.4133	82.7876	0.0679
190.4217	82.7052	0.0679
190.4300	82.6212	0.0679
190.4383	82.5390	0.0678
190.4467	82.4550	0.0678
190.4550	82.3714	0.0676
190.4633	82.2893	0.0675
190.4717	82.2059	0.0675
190.4800	82.1217	0.0674
190.4883	82.0390	0.0673
190.4967	81.9562	0.0673
190.5050	81.8729	0.0673
190.5133	81.7903	0.0672
190.5217	81.7059	0.0672
190.5300	81.6233	0.0672
190.5383	81.5403	0.0671
190.5467	81.4565	0.0670
190.5550	81.3733	0.0670
190.5633	81.2908	0.0669
190.5717	81.2074	0.0669
190.5800	81.1243	0.0666
190.5883	81.0409	0.0666
190.5967	80.9582	0.0666
190.6050	80.8750	0.0665
190.6133	80.7915	0.0664
190.6217	80.7083	0.0664
190.6300	80.6272	0.0662
190.6383	80.5423	0.0661
190.6467	80.4587	0.0661
190.6550	80.3755	0.0661
190.6633	80.2917	0.0660
190.6717	80.2096	0.0660
190.6800	80.1257	0.0659
190.6883	80.0428	0.0659
190.6967	79.9595	0.0658
190.7050	79.8758	0.0657
190.7133	79.7937	0.0657
190.7217	79.7097	0.0656
190.7300	79.6263	0.0656
190.7383	79.5436	0.0654
190.7467	79.4597	0.0654
190.7550	79.3765	0.0654
190.7633	79.2935	0.0654
190.7717	79.2095	0.0653
190.7800	79.1270	0.0653
190.7883	79.0447	0.0650
190.7967	78.9612	0.0650
190.8050	78.8771	0.0649
190.8133	78.7947	0.0648
190.8217	78.7122	0.0648
190.8300	78.6287	0.0648
190.8383	78.5454	0.0648
190.8467	78.4624	0.0645
190.8550	78.3789	0.0645
190.8633	78.2950	0.0645
190.8717	78.2117	0.0645
190.8800	78.1292	0.0644
190.8883	78.0459	0.0642
190.8967	77.9630	0.0641
190.9050	77.8800	0.0640
190.9133	77.7964	0.0639
190.9217	77.7135	0.0638
190.9300	77.6295	0.0638
190.9383	77.5475	0.0637
190.9467	77.4640	0.0635
190.9550	77.3799	0.0635
190.9633	77.2972	0.0635
190.9717	77.2134	0.0634
190.9800	77.1305	0.0634
190.9883	77.0471	0.0634
190.9967	76.9628	0.0632
191.0050	76.8807	0.0630
191.0133	76.7971	0.0630
191.0217	76.7140	0.0629
191.0300	76.6316	0.0629
191.0383	76.5480	0.0629
191.0467	76.4652	0.0629
191.0550	76.3814	0.0629
191.0633	76.2996	0.0627
191.0717	76.2147	0.0627
191.0800	76.1327	0.0627
191.0883	76.0487	0.0625
191.0967	75.9667	0.0624
191.1050	75.8837	0.0624
191.1133	75.7993	0.0624
191.1217	75.7174	0.0623
191.1300	75.6335	0.0622
191.1383	75.5508	0.0622
191.1467	75.4671	0.0622
191.1550	75.3849	0.0622
191.1633	75.3014	0.0622
191.1717	75.2176	0.0622
191.1800	75.1341	0.0622
191.1883	75.0514	0.0622
191.1967	74.9682	0.0623
191.2050	74.8857	0.0624
191.2133	74.8023	0.0624
191.2217	74.7207	0.0626
191.2300	74.6373	0.0651
191.2383	74.5545	0.0674
191.2467	74.4722	0.0685
191.2550	74.3883	0.0725
191.2633	74.3068	0.0771
191.2717	74.2259	0.0819
191.2800	74.1433	0.0921
191.2883	74.0621	0.1038
191.2967	73.9820	0.1203
191.3050	73.9033	0.1454
191.3133	73.8258	0.1790
191.3217	73.7506	0.2279
191.3300	73.6798	0.2943
191.3383	73.6114	0.3839
191.3467	73.5510	0.4970
191.3550	73.4969	0.6363
191.3633	73.4498	0.7965
191.3717	73.4114	0.9687
191.3800	73.3818	1.1421
191.3883	73.3590	1.3089
191.3967	73.3403	1.4588
191.4050	73.3260	1.5896
191.4133	73.3130	1.6992
191.4217	73.2990	1.7909
191.4300	73.2862	1.8640
191.4383	73.2694	1.9279
191.4467	73.2503	1.9794
191.4550	73.2296	2.0228
191.4633	73.2046	2.0629
191.4717	73.1765	2.0978
191.4800	73.1466	2.1295
191.4883	73.1134	2.1639
191.4967	73.0778	2.1932
191.5050	73.0402	2.2213
191.5133	72.9997	2.2519
191.5217	72.9576	2.2809
191.5300	72.9144	2.3087
191.5383	72.8679	2.3362
191.5467	72.8220	2.3628
191.5550	72.7721	2.3898
191.5633	72.7228	2.4142
191.5717	72.6710	2.4395
191.5800	72.6184	2.4632
191.5883	72.5641	2.4842
191.5967	72.5097	2.5061
191.6050	72.4530	2.5270
191.6133	72.3952	2.5452
191.6217	72.3374	2.5617
191.6300	72.2780	2.5760
191.6383	72.2173	2.5913
191.6467	72.1557	2.6041
191.6550	72.0919	2.6155
191.6633	72.0284	2.6268
191.6717	71.9625	2.6357
191.6800	71.8966	2.6433
191.6883	71.8309	2.6516
191.6967	71.7611	2.6595
191.7050	71.6925	2.6622
191.7133	71.6212	2.6654
191.7217	71.5511	2.6673
191.7300	71.4794	2.6708
191.7383	71.4061	2.6691
191.7467	71.3325	2.6695
191.7550	71.2573	2.6671
191.7633	71.1820	2.6650
191.7717	71.1050	2.6623
191.7800	71.0277	2.6567
191.7883	70.9495	2.6522
191.7967	70.8709	2.6460
191.8050	70.7911	2.6362
191.8133	70.7111	2.6287
191.8217	70.6297	2.6198
191.8300	70.5465	2.6097
191.8383	70.4635	2.5969
191.8467	70.3805	2.5842
191.8550	70.2946	2.5703
191.8633	70.2098	2.5557
191.8717	70.1236	2.5418
191.8800	70.0361	2.5260
191.8883	69.9493	2.5097
191.8967	69.8613	2.4933
191.9050	69.7713	2.4762
191.9133	69.6827	2.4596
191.9217	69.5921	2.4410
191.9300	69.5015	2.4215
191.9383	69.4095	2.4021
191.9467	69.3184	2.3790
191.9550	69.2249	2.3547
191.9633	69.1307	2.3264
191.9717	69.0374	2.2988
191.9800	68.9415	2.2721
191.9883	68.8457	2.2441
191.9967	68.7485	2.2171
192.0050	68.6517	2.1880
192.0133	68.5531	2.1585
192.0217	68.4552	2.1292
192.0300	68.3556	2.0990
192.0383	68.2564	2.0707
192.0467	68.1552	2.0414
192.0550	68.0548	2.0110
192.0633	67.9543	1.9780
192.0717	67.8512	1.9449
192.0800	67.7506	1.9151
192.0883	67.6477	1.8831
192.0967	67.5453	1.8525
192.1050	67.4415	1.8218
192.1133	67.3382	1.7926
192.1217	67.2341	1.7617
192.1300	67.1319	1.7309
192.1383	67.0280	1.7024
192.1467	66.9235	1.6770
192.1550	66.8196	1.6476
192.1633	66.7144	1.6215
192.1717	66.6115	1.5945
192.1800	66.5086	1.5699
192.1883	66.4043	1.5453
192.1967	66.3022	1.5219
192.2050	66.1983	1.4979
192.2133	66.0966	1.4725
192.2217	65.9939	1.4506
192.2300	65.8916	1.4278
192.2383	65.7891	1.4058
192.2467	65.6869	1.3844
192.2550	65.5844	1.3636
192.2633	65.4845	1.3412
192.2717	65.3841	1.3206
192.2800	65.2819	1.2995
192.2883	65.1816	1.2803
192.2967	65.0813	1.2598
192.3050	64.9802	1.2398
192.3133	64.8797	1.2196
192.3217	64.7806	1.1998
192.3300	64.6815	1.1810
192.3383	64.5814	1.1632
192.3467	64.4829	1.1436
192.3550	64.3830	1.1242
192.3633	64.2835	1.1064
192.3717	64.1857	1.0885
192.3800	64.0861	1.0696
192.3883	63.9887	1.0512
192.3967	63.8915	1.0353
192.4050	63.7933	1.0183
192.4133	63.6951	1.0013
192.4217	63.5969	0.9835
192.4300	63.5013	0.9675
192.4383	63.4037	0.9526
192.4467	63.3054	0.9363
192.4550	63.2093	0.9208
192.4633	63.1121	0.9053
192.4717	63.0160	0.8920
192.4800	62.9196	0.8760
192.4883	62.8243	0.8613
192.4967	62.7281	0.8497
192.5050	62.6325	0.8327
192.5133	62.5376	0.8181
192.5217	62.4421	0.8064
192.5300	62.3477	0.7926
192.5383	62.2528	0.7787
192.5467	62.1578	0.7685
192.5550	62.0625	0.7544
192.5633	61.9680	0.7421
192.5717	61.8734	0.7295
192.5800	61.7801	0.7157
192.5883	61.6865	0.7056
192.5967	61.5929	0.6938
192.6050	61.4986	0.6818
192.6133	61.4059	0.6709
192.6217	61.3118	0.6598
192.6300	61.2191	0.6486
192.6383	61.1258	0.6382
192.6467	61.0331	0.6280
192.6550	60.9410	0.6172
192.6633	60.8493	0.6065
192.6717	60.7567	0.5979
192.6800	60.6645	0.5887
192.6883	60.5731	0.5783
192.6967	60.4806	0.5677
192.7050	60.3900	0.5605
192.7133	60.2985	0.5517
192.7217	60.2061	0.5432
192.7300	60.1144	0.5348
192.7383	60.0234	0.5242
192.7467	59.9346	0.5160
192.7550	59.8437	0.5097
192.7633	59.7530	0.5008
192.7717	59.6624	0.4933
192.7800	59.5719	0.4854
192.7883	59.4812	0.4782
192.7967	59.3919	0.4705
192.8050	59.3019	0.4639
192.8133	59.2115	0.4576
192.8217	59.1222	0.4489
192.8300	59.0322	0.4429
192.8383	58.9435	0.4365
192.8467	58.8544	0.4307
192.8550	58.7635	0.4250
192.8633	58.6751	0.4189
192.8717	58.5866	0.4118
192.8800	58.4974	0.4048
192.8883	58.4082	0.4011
192.8967	58.3207	0.3946
192.9050	58.2319	0.3894
192.9133	58.1430	0.3848
192.9217	58.0550	0.3782
192.9300	57.9676	0.3752
192.9383	57.8781	0.3684
192.9467	57.7911	0.3621
192.9550	57.7043	0.3589
192.9633	57.6151	0.3540
192.9717	57.5291	0.3494
192.9800	57.4405	0.3453
192.9883	57.3536	0.3411
192.9967	57.2650	0.3368
193.0050	57.1781	0.3325
193.0133	57.0909	0.3282
193.0217	57.0038	0.3246
193.0300	56.9174	0.3198
193.0383	56.8294	0.3170
193.0467	56.7437	0.3110
193.0550	56.6569	0.3087
193.0633	56.5702	0.3058
193.0717	56.4839	0.3022
193.0800	56.3974	0.2984
193.0883	56.3109	0.2947
193.0967	56.2246	0.2915
193.1050	56.1377	0.2889
193.1133	56.0518	0.2842
193.1217	55.9652	0.2818
193.1300	55.8797	0.2788
193.1383	55.7928	0.2755
193.1467	55.7070	0.2729
193.1550	55.6208	0.2701
193.1633	55.5361	0.2665
193.1717	55.4504	0.2624
193.1800	55.3652	0.2607
193.1883	55.2786	0.2586
193.1967	55.1933	0.2562
193.2050	55.1063	0.2541
193.2133	55.0220	0.2503
193.2217	54.9360	0.2481
193.2300	54.8512	0.2448
193.2383	54.7656	0.2437
193.2467	54.6796	0.2411
193.2550	54.5949	0.2390
193.2633	54.5096	0.2356
193.2717	54.4243	0.2341
193.2800	54.3385	0.2317
193.2883	54.2526	0.2296
193.2967	54.1693	0.2280
193.3050	54.0834	0.2252
193.3133	53.9987	0.2231
193.3217	53.9139	0.2209
193.3300	53.8288	0.2188
193.3383	53.7431	0.2175
193.3467	53.6585	0.2152
193.3550	53.5742	0.2140
193.3633	53.4889	0.2115
193.3717	53.4034	0.2103
193.3800	53.3197	0.2069
193.3883	53.2348	0.2062
193.3967	53.1506	0.2050
193.4050	53.0642	0.2033
193.4133	52.9802	0.2000
193.4217	52.8960	0.1999
193.4300	52.8118	0.1980
193.4383	52.7261	0.1963
193.4467	52.6411	0.1947
193.4550	52.5582	0.1925
193.4633	52.4728	0.1922
193.4717	52.3886	0.1919
193.4800	52.3043	0.1903
193.4883	52.2176	0.1880
193.4967	52.1342	0.1862
193.5050	52.0499	0.1851
193.5133	51.9661	0.1826
193.5217	51.8819	0.1830
193.5300	51.7967	0.1823
193.5383	51.7124	0.1797
193.5467	51.6300	0.1776
193.5550	51.5453	0.1773
193.5633	51.4605	0.1778
193.5717	51.3766	0.1761
193.5800	51.2913	0.1742
193.5883	51.2077	0.1721
193.5967	51.1238	0.1711
193.6050	51.0388	0.1703
193.6133	50.9556	0.1693
193.6217	50.8713	0.1691
193.6300	50.7877	0.1675
193.6383	50.7037	0.1664
193.6467	50.6187	0.1664
193.6550	50.5349	0.1649
193.6633	50.4506	0.1641
193.6717	50.3678	0.1632
193.6800	50.2836	0.1611
193.6883	50.1986	0.1611
193.6967	50.1156	0.1609
193.7050	50.0311	0.1604
193.7133	49.9491	0.1594
193.7217	49.8644	0.1583
193.7300	49.7791	0.1581
193.7383	49.6939	0.1578
193.7467	49.6118	0.1556
193.7550	49.5274	0.1546
193.7633	49.4447	0.1537
193.7717	49.3611	0.1538
193.7800	49.2776	0.1533
193.7883	49.1923	0.1537
193.7967	49.1090	0.1531
193.8050	49.0258	0.1517
193.8133	48.9420	0.1507
193.8217	48.8574	0.1501
193.8300	48.7743	0.1481
193.8383	48.6913	0.1478
193.8467	48.6065	0.1475
193.8550	48.5228	0.1472
193.8633	48.4399	0.1471
193.8717	48.3555	0.1463
193.8800	48.2724	0.1460
193.8883	48.1878	0.1459
193.8967	48.1044	0.1458
193.9050	48.0210	0.1448
193.9133	47.9377	0.1422
193.9217	47.8541	0.1426
193.9300	47.7702	0.1423
193.9383	47.6867	0.1410
193.9467	47.6030	0.1407
193.9550	47.5192	0.1407
193.9633	47.4349	0.1407
193.9717	47.3514	0.1400
193.9800	47.2684	0.1394
193.9883	47.1849	0.1387
193.9967	47.1007	0.1385
194.0050	47.0180	0.1372
194.0133	46.9336	0.1364
194.0217	46.8503	0.1363
194.0300	46.7666	0.1359
194.0383	46.6824	0.1350
194.0467	46.6003	0.1348
194.0550	46.5152	0.1340
194.0633	46.4325	0.1334
194.0717	46.3495	0.1306
194.0800	46.2662	0.1293
194.0883	46.1821	0.1295
194.0967	46.0972	0.1296
194.1050	46.0146	0.1289
194.1133	45.9315	0.1277
194.1217	45.8475	0.1277
194.1300	45.7636	0.1272
194.1383	45.6811	0.1263
194.1467	45.5966	0.1251
194.1550	45.5130	0.1245
194.1633	45.4284	0.1239
194.1717	45.3449	0.1234
194.1800	45.2616	0.1229
194.1883	45.1780	0.1225
194.1967	45.0941	0.1221
194.2050	45.0104	0.1205
194.2133	44.9271	0.1194
194.2217	44.8430	0.1191
194.2300	44.7585	0.1193
194.2383	44.6747	0.1181
194.2467	44.5919	0.1171
194.2550	44.5085	0.1151
194.2633	44.4248	0.1145
194.2717	44.3411	0.1144
194.2800	44.2570	0.1136
194.2883	44.1728	0.1132
194.2967	44.0893	0.1120
194.3050	44.0070	0.1106
194.3133	43.9225	0.1094
194.3217	43.8379	0.1092
194.3300	43.7558	0.1088
194.3383	43.6710	0.1080
194.3467	43.5870	0.1071
194.3550	43.5024	0.1061
194.3633	43.4194	0.1053
194.3717	43.3353	0.1042
194.3800	43.2513	0.1039
194.3883	43.1684	0.1026
194.3967	43.0845	0.1024
194.4050	43.0006	0.1008
194.4133	42.9161	0.0997
194.4217	42.8337	0.0995
194.4300	42.7496	0.0990
194.4383	42.6647	0.0984
194.4467	42.5815
194.4550	42.4983
194.4633	42.4147
194.4717	42.3314
194.4800	42.2480
194.4883	42.1624
194.4967