File: Example Date/My Sample/DSC/test01/DSC TA/YN038 -150-150.txt
Filename	YN038 -150-150
Instrument name	DSC2A-01799 (192.168.1.250)
Operator
rundate	09/12/2024
Sample name	YN038 -150-150
proceduresegments	Ramp 10.00 °C/min to 150.0000 °C; Isothermal 3.0 min; Ramp 10.00 °C/min to -150.0000 °C; Isothermal 3.0 min; Ramp 10.00 °C/min to 150.0000 °C; Isothermal 3.0 min; Ramp 10.00 °C/min to -150.0000 °C; Isothermal 3.0 min; Ramp 10.00 °C/min to 150.0000 °C; Isothermal 3.0 min; Ramp 10.00 °C/min to 40.0000 °C
[File Parameters]
Run Date	09/12/2024 11:41:40
Trios version	5.7.0.56
Original File Name	C:\Users\TA Instruments DSC\Desktop\Data\Yutong Niu\YN038 -150-150.tri
Current File Name	C:\Users\TA Instruments DSC\Desktop\Data\Yutong Niu\YN038 -150-150.tri
User at run start	DESKTOP-CFGN8IT\TA Instruments DSC
[Procedure]
Procedure Name	polyether
Sample Name	YN038 -150-150
Sample Mass	16.28 mg
Reference Sample Mass	0 mg
Pan Mass	61.94 mg
Pan Number	24
Reference Pan Mass	60.81 mg
Reference Pan Number	45
Pan Type	Tzero Aluminum Pin Hole Hermetic
Comments
Project Name
Operator
Test	Custom
Unload Max Temperature	25
Unload Min Temperature	25
FillCooler	Do not fill
Load Max Temperature	25
Load Min Temperature	25
Discard pan in waste bin at end of test	Yes
Stop on Gas Flow Error	No
[Signal List]
Signal #1	Time (min)
Signal #2	Temperature (°C)
Signal #3	Heat Flow (mW)
Signal #4	Delta T (µV)
Signal #5	Delta Tzero (µV)
Signal #6	Tzero Temperature (°C)
Signal #7	Cell Purge (mL/min)
Signal #8	Heater Temp (°C)
Signal #9	Power Delivered (W)
Signal #10	Reference Junction Temperature (°C)
Signal #11	Flange Temperature (°C)
Signal #12	Heat Flow Phase (rad)
Signal #13	Total Heat Capacity (J/°C)
Signal #14	Heat Capacity (J/°C)
Signal #15	LN Pump Tank level (%)
[Configuration]
Company Name	Warwick University
Instrument Name	DSC2A-01799
Instrument Type	DSC2500
Serial Number	DSC2A-01799
IP	192.168.1.250
Location of Instrument	Polymer RTP
DisplayType	TianmaV2andV3
Sample Interval 	0.1 s/pt
Selected Heat Flow	T4P
Exotherm Direction	Up
Cell Serial	DRC2-03788
Lid Type	High Temperature
Cooler	LN Pump
Leave Cooler on at End of Sequence	Off
Gas 2	Air
Gas Selected	Channel 1: Nitrogen
Flow Rate	50 mL/min
Secondary Purge	On
Licensed Heat Flow	Heat Flow T4P
Modulation Licensed	Yes
[Versions]
Common IDD Version	1
Cortex Version	VER 2.11.0.729
Driver	5.0.0.6
GDM Version	1.0.3.3
TouchscreenVersion	1.0.3.1841
FEP Version	1.2.1.21
FEP Bootloader	2.0.0.5
AutoSampler Version	2.1.2.1
Auto Sampler Bootloader	2.0.0.5
FCM Version	1.1.0.3
FCM Bootloader	2.0.0.5
LN Pump Version	10.17.0.0
LN Pump Bootloader	2.0.0.5
[Experiment Logs]
Experiment Log Entry # 1	Ramp Segment 10 C/min to 150 Started
Experiment Log Entry # 3	Air Cool is off.
Experiment Log Entry # 5	Isothermal Segment 3 min started
Experiment Log Entry # 7	Ramp Segment 10 C/min to -150 Started
Experiment Log Entry # 10	LN2P is filling
Experiment Log Entry # 11	Isothermal Segment 3 min started
Experiment Log Entry # 13	Ramp Segment 10 C/min to 150 Started
Experiment Log Entry # 16	LN2P stopped filling
Experiment Log Entry # 17	Isothermal Segment 3 min started
Experiment Log Entry # 19	Ramp Segment 10 C/min to -150 Started
Experiment Log Entry # 21	Isothermal Segment 3 min started
Experiment Log Entry # 23	Ramp Segment 10 C/min to 150 Started
Experiment Log Entry # 26	LN2P is filling
Experiment Log Entry # 28	LN2P stopped filling
Experiment Log Entry # 29	Isothermal Segment 3 min started
Experiment Log Entry # 31	Ramp Segment 10 C/min to 40 Started
Experiment Log Entry # 34	LN2P is filling
Experiment Log Entry # 36	LN2P stopped filling
[Method Log]
Method Log Entry # 1	(Ramp 490634) Ramp 10 °C/minute to 150 °C
Method Log Entry # 2	Isothermal 3 minutes
Method Log Entry # 3	(Ramp 490636) Ramp 10 °C/minute to -150 °C
Method Log Entry # 4	Isothermal 3 minutes
Method Log Entry # 5	(Ramp 490638) Ramp 10 °C/minute to 150 °C
Method Log Entry # 6	Isothermal 3 minutes
Method Log Entry # 7	(Ramp 490640) Ramp 10 °C/minute to -150 °C
Method Log Entry # 8	Isothermal 3 minutes
Method Log Entry # 9	(Ramp 490642) Ramp 10 °C/minute to 150 °C
Method Log Entry # 10	Isothermal 3 minutes
Method Log Entry # 11	(Ramp 490644) Ramp 10 °C/minute to 40 °C
Cell Serial	DRC2-03788
[T1 Calibration]
Date Applied	04/03/2021 14:58:04
Description
Gas Type	Nitrogen
Pan Type	None
Slope	-0.001800291
Offset	-0.1301359
Initial Temperature	-100.6228
GUID	a1d5a6be-decd-4ae4-b22f-d560f3a78a92
[TZero Calibration]
Date Applied	21/08/2024 09:53:38
Description	From -180.022 °C to 395.167 °C at 20.000°C/min
Gas Type	Nitrogen
Pan Type	None
Source Files 1	C:\ProgramData\TA Instruments\TRIOS\Data\TAService\PMV 20Aug2024\Tzero Cal.tri
Source Files 2	C:\ProgramData\TA Instruments\TRIOS\Data\TAService\PMV 20Aug2024\Tzero Cal sapphire.tri
Delta T Offset	1.787969
Delta T Slope	-0.003527276
Delta T0 Offset	0.06831977
Delta T0 Slope	0.02007191
[Temperature Calibration]
Date Applied	21/08/2024 11:06:35
Description	From 106.660 °C to 186.660 °C at 10.000°C/min
Gas Type	Nitrogen
Pan Type	Tzero Aluminum
Source Files 1	C:\ProgramData\TA Instruments\TRIOS\Data\TAService\PMV 20Aug2024\TA Indium cal.tri
Measured 1	157.9141
Known 1	156.66
[Cell Constant Calibration]
Date Applied	21/08/2024 11:06:35
Description	From 106.660 °C to 186.660 °C at 10.000°C/min
Gas Type	Nitrogen
Pan Type	Tzero Aluminum
Source Files 1	C:\ProgramData\TA Instruments\TRIOS\Data\TAService\PMV 20Aug2024\TA Indium cal.tri
T4P KCell	1.038055
Onset Slope	-66.72884 mW/°C
[Direct Cp Calibration]
Date Applied	19/11/2024 16:37:27
Description	From -89.996 °C to 396.697 °C at 20.000°C/min
Gas Type	Nitrogen
Pan Type	Tzero Aluminum
Source Files 1	C:\ProgramData\TA Instruments\TRIOS\Data\Sapphire Direct Heat Capacity(8).tri
GUID	544f8371-fe9b-4f4f-81ca-7980c172113e
Temperature	-89.99625 °C
Cp	1.464367
Temperature	-89.02287 °C
Cp	1.460558
Temperature	-88.04948 °C
Cp	1.456263
Temperature	-87.0761 °C
Cp	1.451626
Temperature	-86.10271 °C
Cp	1.446737
Temperature	-85.12933 °C
Cp	1.441723
Temperature	-84.15594 °C
Cp	1.436654
Temperature	-83.18256 °C
Cp	1.431684
Temperature	-82.20917 °C
Cp	1.426935
Temperature	-81.23578 °C
Cp	1.422396
Temperature	-80.2624 °C
Cp	1.418192
Temperature	-79.28901 °C
Cp	1.414363
Temperature	-78.31562 °C
Cp	1.410925
Temperature	-77.34224 °C
Cp	1.407865
Temperature	-76.36885 °C
Cp	1.405143
Temperature	-75.39546 °C
Cp	1.402789
Temperature	-74.42208 °C
Cp	1.400703
Temperature	-73.44869 °C
Cp	1.398837
Temperature	-72.4753 °C
Cp	1.397142
Temperature	-71.50192 °C
Cp	1.395565
Temperature	-70.52853 °C
Cp	1.394053
Temperature	-69.55515 °C
Cp	1.392558
Temperature	-68.58176 °C
Cp	1.391036
Temperature	-67.60838 °C
Cp	1.389483
Temperature	-66.63499 °C
Cp	1.387847
Temperature	-65.66161 °C
Cp	1.38616
Temperature	-64.68822 °C
Cp	1.384397
Temperature	-63.71483 °C
Cp	1.382535
Temperature	-62.74145 °C
Cp	1.380598
Temperature	-61.76806 °C
Cp	1.37865
Temperature	-60.79467 °C
Cp	1.376673
Temperature	-59.82129 °C
Cp	1.374677
Temperature	-58.8479 °C
Cp	1.372642
Temperature	-57.87452 °C
Cp	1.370686
Temperature	-56.90113 °C
Cp	1.368741
Temperature	-55.92775 °C
Cp	1.366786
Temperature	-54.95436 °C
Cp	1.364863
Temperature	-53.98097 °C
Cp	1.362959
Temperature	-53.00759 °C
Cp	1.361116
Temperature	-52.0342 °C
Cp	1.359247
Temperature	-51.06082 °C
Cp	1.357393
Temperature	-50.08743 °C
Cp	1.355593
Temperature	-49.11404 °C
Cp	1.353796
Temperature	-48.14066 °C
Cp	1.352008
Temperature	-47.16727 °C
Cp	1.350215
Temperature	-46.19389 °C
Cp	1.348396
Temperature	-45.2205 °C
Cp	1.346593
Temperature	-44.24712 °C
Cp	1.344755
Temperature	-43.27373 °C
Cp	1.342891
Temperature	-42.30034 °C
Cp	1.341008
Temperature	-41.32696 °C
Cp	1.339126
Temperature	-40.35357 °C
Cp	1.337236
Temperature	-39.38018 °C
Cp	1.335367
Temperature	-38.4068 °C
Cp	1.333522
Temperature	-37.43341 °C
Cp	1.331708
Temperature	-36.46003 °C
Cp	1.32991
Temperature	-35.48664 °C
Cp	1.328145
Temperature	-34.51326 °C
Cp	1.326414
Temperature	-33.53987 °C
Cp	1.32471
Temperature	-32.56648 °C
Cp	1.323012
Temperature	-31.5931 °C
Cp	1.321323
Temperature	-30.61971 °C
Cp	1.319657
Temperature	-29.64633 °C
Cp	1.317968
Temperature	-28.67294 °C
Cp	1.316286
Temperature	-27.69955 °C
Cp	1.314585
Temperature	-26.72617 °C
Cp	1.312857
Temperature	-25.75278 °C
Cp	1.31111
Temperature	-24.7794 °C
Cp	1.309333
Temperature	-23.80601 °C
Cp	1.307544
Temperature	-22.83262 °C
Cp	1.30575
Temperature	-21.85924 °C
Cp	1.303941
Temperature	-20.88585 °C
Cp	1.302132
Temperature	-19.91247 °C
Cp	1.300313
Temperature	-18.93908 °C
Cp	1.298512
Temperature	-17.96569 °C
Cp	1.296728
Temperature	-16.99231 °C
Cp	1.294939
Temperature	-16.01892 °C
Cp	1.293198
Temperature	-15.04554 °C
Cp	1.291453
Temperature	-14.07215 °C
Cp	1.289723
Temperature	-13.09876 °C
Cp	1.288007
Temperature	-12.12538 °C
Cp	1.286283
Temperature	-11.15199 °C
Cp	1.284578
Temperature	-10.17861 °C
Cp	1.282885
Temperature	-9.205221 °C
Cp	1.281173
Temperature	-8.231835 °C
Cp	1.279472
Temperature	-7.258449 °C
Cp	1.277766
Temperature	-6.285063 °C
Cp	1.276053
Temperature	-5.311677 °C
Cp	1.274341
Temperature	-4.338291 °C
Cp	1.272592
Temperature	-3.364905 °C
Cp	1.270844
Temperature	-2.391519 °C
Cp	1.269062
Temperature	-1.418133 °C
Cp	1.267264
Temperature	-0.4447474 °C
Cp	1.265435
Temperature	0.5286385 °C
Cp	1.263575
Temperature	1.502024 °C
Cp	1.261727
Temperature	2.47541 °C
Cp	1.259854
Temperature	3.448796 °C
Cp	1.257978
Temperature	4.422182 °C
Cp	1.256109
Temperature	5.395568 °C
Cp	1.254244
Temperature	6.368954 °C
Cp	1.252392
Temperature	7.34234 °C
Cp	1.250552
Temperature	8.315726 °C
Cp	1.248704
Temperature	9.289112 °C
Cp	1.246884
Temperature	10.2625 °C
Cp	1.245078
Temperature	11.23588 °C
Cp	1.243287
Temperature	12.20927 °C
Cp	1.241522
Temperature	13.18266 °C
Cp	1.239778
Temperature	14.15604 °C
Cp	1.238068
Temperature	15.12943 °C
Cp	1.236393
Temperature	16.10281 °C
Cp	1.234762
Temperature	17.0762 °C
Cp	1.233176
Temperature	18.04959 °C
Cp	1.231629
Temperature	19.02297 °C
Cp	1.230129
Temperature	19.99636 °C
Cp	1.228694
Temperature	20.96974 °C
Cp	1.22731
Temperature	21.94313 °C
Cp	1.225968
Temperature	22.91652 °C
Cp	1.224676
Temperature	23.8899 °C
Cp	1.223431
Temperature	24.86329 °C
Cp	1.222217
Temperature	25.83667 °C
Cp	1.221065
Temperature	26.81006 °C
Cp	1.219919
Temperature	27.78345 °C
Cp	1.218811
Temperature	28.75683 °C
Cp	1.21773
Temperature	29.73022 °C
Cp	1.216663
Temperature	30.7036 °C
Cp	1.2156
Temperature	31.67699 °C
Cp	1.214515
Temperature	32.65038 °C
Cp	1.213439
Temperature	33.62376 °C
Cp	1.21234
Temperature	34.59715 °C
Cp	1.211209
Temperature	35.57053 °C
Cp	1.210051
Temperature	36.54392 °C
Cp	1.208868
Temperature	37.5173 °C
Cp	1.207666
Temperature	38.49069 °C
Cp	1.206439
Temperature	39.46408 °C
Cp	1.205199
Temperature	40.43746 °C
Cp	1.203959
Temperature	41.41085 °C
Cp	1.202712
Temperature	42.38424 °C
Cp	1.20147
Temperature	43.35762 °C
Cp	1.200231
Temperature	44.33101 °C
Cp	1.199
Temperature	45.30439 °C
Cp	1.197777
Temperature	46.27778 °C
Cp	1.19657
Temperature	47.25116 °C
Cp	1.195367
Temperature	48.22455 °C
Cp	1.194179
Temperature	49.19794 °C
Cp	1.19301
Temperature	50.17132 °C
Cp	1.191849
Temperature	51.14471 °C
Cp	1.190694
Temperature	52.11809 °C
Cp	1.189555
Temperature	53.09148 °C
Cp	1.18843
Temperature	54.06487 °C
Cp	1.187311
Temperature	55.03825 °C
Cp	1.186195
Temperature	56.01164 °C
Cp	1.185095
Temperature	56.98502 °C
Cp	1.183997
Temperature	57.95841 °C
Cp	1.182894
Temperature	58.93179 °C
Cp	1.181793
Temperature	59.90518 °C
Cp	1.180693
Temperature	60.87857 °C
Cp	1.179595
Temperature	61.85195 °C
Cp	1.178501
Temperature	62.82534 °C
Cp	1.177406
Temperature	63.79873 °C
Cp	1.176313
Temperature	64.77211 °C
Cp	1.175239
Temperature	65.7455 °C
Cp	1.17417
Temperature	66.71888 °C
Cp	1.173105
Temperature	67.69227 °C
Cp	1.172037
Temperature	68.66566 °C
Cp	1.170989
Temperature	69.63904 °C
Cp	1.169948
Temperature	70.61243 °C
Cp	1.168905
Temperature	71.58582 °C
Cp	1.167872
Temperature	72.5592 °C
Cp	1.166849
Temperature	73.53259 °C
Cp	1.165851
Temperature	74.50597 °C
Cp	1.164848
Temperature	75.47935 °C
Cp	1.163876
Temperature	76.45274 °C
Cp	1.162926
Temperature	77.42612 °C
Cp	1.162008
Temperature	78.39951 °C
Cp	1.161113
Temperature	79.3729 °C
Cp	1.160219
Temperature	80.34628 °C
Cp	1.159377
Temperature	81.31967 °C
Cp	1.158546
Temperature	82.29306 °C
Cp	1.157726
Temperature	83.26644 °C
Cp	1.15692
Temperature	84.23983 °C
Cp	1.156126
Temperature	85.21322 °C
Cp	1.155375
Temperature	86.1866 °C
Cp	1.154604
Temperature	87.15999 °C
Cp	1.153869
Temperature	88.13337 °C
Cp	1.153158
Temperature	89.10676 °C
Cp	1.152474
Temperature	90.08015 °C
Cp	1.15181
Temperature	91.05353 °C
Cp	1.151134
Temperature	92.02692 °C
Cp	1.150513
Temperature	93.00031 °C
Cp	1.149892
Temperature	93.97369 °C
Cp	1.149266
Temperature	94.94707 °C
Cp	1.148642
Temperature	95.92046 °C
Cp	1.148019
Temperature	96.89384 °C
Cp	1.147402
Temperature	97.86723 °C
Cp	1.146799
Temperature	98.84062 °C
Cp	1.146191
Temperature	99.814 °C
Cp	1.145602
Temperature	100.7874 °C
Cp	1.14503
Temperature	101.7608 °C
Cp	1.144469
Temperature	102.7342 °C
Cp	1.143921
Temperature	103.7076 °C
Cp	1.143383
Temperature	104.6809 °C
Cp	1.142861
Temperature	105.6543 °C
Cp	1.142345
Temperature	106.6277 °C
Cp	1.141835
Temperature	107.6011 °C
Cp	1.141335
Temperature	108.5745 °C
Cp	1.140846
Temperature	109.5479 °C
Cp	1.140365
Temperature	110.5212 °C
Cp	1.139891
Temperature	111.4946 °C
Cp	1.139429
Temperature	112.468 °C
Cp	1.138976
Temperature	113.4414 °C
Cp	1.13853
Temperature	114.4148 °C
Cp	1.138092
Temperature	115.3882 °C
Cp	1.137654
Temperature	116.3616 °C
Cp	1.137223
Temperature	117.335 °C
Cp	1.136785
Temperature	118.3083 °C
Cp	1.136338
Temperature	119.2817 °C
Cp	1.13588
Temperature	120.2551 °C
Cp	1.13541
Temperature	121.2285 °C
Cp	1.134927
Temperature	122.2019 °C
Cp	1.134417
Temperature	123.1753 °C
Cp	1.133892
Temperature	124.1487 °C
Cp	1.133347
Temperature	125.122 °C
Cp	1.132786
Temperature	126.0954 °C
Cp	1.132206
Temperature	127.0688 °C
Cp	1.131606
Temperature	128.0422 °C
Cp	1.130999
Temperature	129.0156 °C
Cp	1.130384
Temperature	129.989 °C
Cp	1.129765
Temperature	130.9624 °C
Cp	1.129147
Temperature	131.9357 °C
Cp	1.12854
Temperature	132.9091 °C
Cp	1.127949
Temperature	133.8825 °C
Cp	1.127383
Temperature	134.8559 °C
Cp	1.126841
Temperature	135.8293 °C
Cp	1.126334
Temperature	136.8027 °C
Cp	1.125871
Temperature	137.7761 °C
Cp	1.125443
Temperature	138.7494 °C
Cp	1.125058
Temperature	139.7228 °C
Cp	1.124701
Temperature	140.6962 °C
Cp	1.124397
Temperature	141.6696 °C
Cp	1.124114
Temperature	142.643 °C
Cp	1.123854
Temperature	143.6164 °C
Cp	1.123612
Temperature	144.5898 °C
Cp	1.123385
Temperature	145.5631 °C
Cp	1.123182
Temperature	146.5365 °C
Cp	1.12296
Temperature	147.5099 °C
Cp	1.12275
Temperature	148.4833 °C
Cp	1.122543
Temperature	149.4567 °C
Cp	1.122327
Temperature	150.4301 °C
Cp	1.122099
Temperature	151.4035 °C
Cp	1.121837
Temperature	152.3768 °C
Cp	1.121582
Temperature	153.3502 °C
Cp	1.121289
Temperature	154.3236 °C
Cp	1.120967
Temperature	155.297 °C
Cp	1.120616
Temperature	156.2704 °C
Cp	1.120238
Temperature	157.2438 °C
Cp	1.119862
Temperature	158.2172 °C
Cp	1.119444
Temperature	159.1906 °C
Cp	1.119028
Temperature	160.1639 °C
Cp	1.118613
Temperature	161.1373 °C
Cp	1.118202
Temperature	162.1107 °C
Cp	1.117795
Temperature	163.0841 °C
Cp	1.117374
Temperature	164.0575 °C
Cp	1.116987
Temperature	165.0309 °C
Cp	1.116595
Temperature	166.0042 °C
Cp	1.116198
Temperature	166.9776 °C
Cp	1.1158
Temperature	167.951 °C
Cp	1.115402
Temperature	168.9244 °C
Cp	1.115006
Temperature	169.8978 °C
Cp	1.11462
Temperature	170.8712 °C
Cp	1.114223
Temperature	171.8446 °C
Cp	1.113836
Temperature	172.8179 °C
Cp	1.113458
Temperature	173.7913 °C
Cp	1.113085
Temperature	174.7647 °C
Cp	1.112712
Temperature	175.7381 °C
Cp	1.112323
Temperature	176.7115 °C
Cp	1.111957
Temperature	177.6849 °C
Cp	1.111578
Temperature	178.6583 °C
Cp	1.111185
Temperature	179.6317 °C
Cp	1.110789
Temperature	180.605 °C
Cp	1.110391
Temperature	181.5784 °C
Cp	1.110016
Temperature	182.5518 °C
Cp	1.109611
Temperature	183.5252 °C
Cp	1.109232
Temperature	184.4986 °C
Cp	1.108873
Temperature	185.472 °C
Cp	1.108531
Temperature	186.4454 °C
Cp	1.108199
Temperature	187.4187 °C
Cp	1.107851
Temperature	188.3921 °C
Cp	1.107551
Temperature	189.3655 °C
Cp	1.107238
Temperature	190.3389 °C
Cp	1.106917
Temperature	191.3123 °C
Cp	1.106589
Temperature	192.2857 °C
Cp	1.106259
Temperature	193.259 °C
Cp	1.105958
Temperature	194.2324 °C
Cp	1.105619
Temperature	195.2058 °C
Cp	1.105301
Temperature	196.1792 °C
Cp	1.105002
Temperature	197.1526 °C
Cp	1.104718
Temperature	198.126 °C
Cp	1.104445
Temperature	199.0994 °C
Cp	1.104161
Temperature	200.0728 °C
Cp	1.103914
Temperature	201.0461 °C
Cp	1.103657
Temperature	202.0195 °C
Cp	1.103395
Temperature	202.9929 °C
Cp	1.103125
Temperature	203.9663 °C
Cp	1.102847
Temperature	204.9397 °C
Cp	1.102563
Temperature	205.9131 °C
Cp	1.102283
Temperature	206.8865 °C
Cp	1.101985
Temperature	207.8598 °C
Cp	1.10169
Temperature	208.8332 °C
Cp	1.101394
Temperature	209.8066 °C
Cp	1.101099
Temperature	210.78 °C
Cp	1.1008
Temperature	211.7534 °C
Cp	1.10049
Temperature	212.7268 °C
Cp	1.100193
Temperature	213.7002 °C
Cp	1.099886
Temperature	214.6735 °C
Cp	1.099577
Temperature	215.6469 °C
Cp	1.099268
Temperature	216.6203 °C
Cp	1.098965
Temperature	217.5937 °C
Cp	1.098685
Temperature	218.5671 °C
Cp	1.098396
Temperature	219.5405 °C
Cp	1.098134
Temperature	220.5139 °C
Cp	1.097895
Temperature	221.4872 °C
Cp	1.09768
Temperature	222.4606 °C
Cp	1.097485
Temperature	223.434 °C
Cp	1.097292
Temperature	224.4074 °C
Cp	1.09714
Temperature	225.3808 °C
Cp	1.096991
Temperature	226.3542 °C
Cp	1.096844
Temperature	227.3276 °C
Cp	1.096699
Temperature	228.3009 °C
Cp	1.096559
Temperature	229.2743 °C
Cp	1.096442
Temperature	230.2477 °C
Cp	1.096296
Temperature	231.2211 °C
Cp	1.096164
Temperature	232.1945 °C
Cp	1.09604
Temperature	233.1679 °C
Cp	1.095924
Temperature	234.1413 °C
Cp	1.095807
Temperature	235.1147 °C
Cp	1.095665
Temperature	236.088 °C
Cp	1.095557
Temperature	237.0614 °C
Cp	1.095433
Temperature	238.0348 °C
Cp	1.095296
Temperature	239.0082 °C
Cp	1.095147
Temperature	239.9816 °C
Cp	1.094995
Temperature	240.955 °C
Cp	1.094843
Temperature	241.9283 °C
Cp	1.094705
Temperature	242.9017 °C
Cp	1.094562
Temperature	243.8751 °C
Cp	1.094442
Temperature	244.8485 °C
Cp	1.094344
Temperature	245.8219 °C
Cp	1.094266
Temperature	246.7953 °C
Cp	1.094209
Temperature	247.7687 °C
Cp	1.094161
Temperature	248.7421 °C
Cp	1.094144
Temperature	249.7154 °C
Cp	1.094133
Temperature	250.6888 °C
Cp	1.094127
Temperature	251.6622 °C
Cp	1.094126
Temperature	252.6356 °C
Cp	1.094127
Temperature	253.609 °C
Cp	1.094138
Temperature	254.5824 °C
Cp	1.09413
Temperature	255.5558 °C
Cp	1.094123
Temperature	256.5291 °C
Cp	1.094111
Temperature	257.5025 °C
Cp	1.094087
Temperature	258.4759 °C
Cp	1.094046
Temperature	259.4493 °C
Cp	1.093978
Temperature	260.4227 °C
Cp	1.093895
Temperature	261.3961 °C
Cp	1.093783
Temperature	262.3694 °C
Cp	1.093645
Temperature	263.3428 °C
Cp	1.093483
Temperature	264.3162 °C
Cp	1.093302
Temperature	265.2896 °C
Cp	1.093109
Temperature	266.263 °C
Cp	1.092906
Temperature	267.2364 °C
Cp	1.092704
Temperature	268.2098 °C
Cp	1.092511
Temperature	269.1832 °C
Cp	1.092331
Temperature	270.1566 °C
Cp	1.092174
Temperature	271.1299 °C
Cp	1.092046
Temperature	272.1033 °C
Cp	1.091947
Temperature	273.0767 °C
Cp	1.091882
Temperature	274.0501 °C
Cp	1.091853
Temperature	275.0235 °C
Cp	1.091859
Temperature	275.9969 °C
Cp	1.091895
Temperature	276.9702 °C
Cp	1.091957
Temperature	277.9436 °C
Cp	1.092036
Temperature	278.917 °C
Cp	1.092132
Temperature	279.8904 °C
Cp	1.09223
Temperature	280.8638 °C
Cp	1.092323
Temperature	281.8372 °C
Cp	1.092405
Temperature	282.8105 °C
Cp	1.092468
Temperature	283.7839 °C
Cp	1.092513
Temperature	284.7573 °C
Cp	1.092525
Temperature	285.7307 °C
Cp	1.092512
Temperature	286.7041 °C
Cp	1.092472
Temperature	287.6775 °C
Cp	1.092405
Temperature	288.6509 °C
Cp	1.092313
Temperature	289.6243 °C
Cp	1.092197
Temperature	290.5977 °C
Cp	1.09207
Temperature	291.571 °C
Cp	1.091931
Temperature	292.5444 °C
Cp	1.091785
Temperature	293.5178 °C
Cp	1.091641
Temperature	294.4912 °C
Cp	1.091506
Temperature	295.4646 °C
Cp	1.091387
Temperature	296.438 °C
Cp	1.091282
Temperature	297.4113 °C
Cp	1.091201
Temperature	298.3847 °C
Cp	1.091145
Temperature	299.3581 °C
Cp	1.091112
Temperature	300.3315 °C
Cp	1.091102
Temperature	301.3049 °C
Cp	1.091107
Temperature	302.2783 °C
Cp	1.091137
Temperature	303.2517 °C
Cp	1.091177
Temperature	304.2251 °C
Cp	1.091226
Temperature	305.1984 °C
Cp	1.09128
Temperature	306.1718 °C
Cp	1.091336
Temperature	307.1452 °C
Cp	1.091403
Temperature	308.1186 °C
Cp	1.091453
Temperature	309.092 °C
Cp	1.091506
Temperature	310.0654 °C
Cp	1.091561
Temperature	311.0388 °C
Cp	1.091617
Temperature	312.0121 °C
Cp	1.09167
Temperature	312.9855 °C
Cp	1.091716
Temperature	313.9589 °C
Cp	1.091762
Temperature	314.9323 °C
Cp	1.091805
Temperature	315.9057 °C
Cp	1.091838
Temperature	316.8791 °C
Cp	1.09186
Temperature	317.8524 °C
Cp	1.091871
Temperature	318.8258 °C
Cp	1.091872
Temperature	319.7992 °C
Cp	1.091867
Temperature	320.7726 °C
Cp	1.091838
Temperature	321.746 °C
Cp	1.0918
Temperature	322.7194 °C
Cp	1.091752
Temperature	323.6928 °C
Cp	1.091689
Temperature	324.6662 °C
Cp	1.091611
Temperature	325.6396 °C
Cp	1.091508
Temperature	326.6129 °C
Cp	1.091406
Temperature	327.5863 °C
Cp	1.091285
Temperature	328.5597 °C
Cp	1.09115
Temperature	329.5331 °C
Cp	1.091009
Temperature	330.5065 °C
Cp	1.09087
Temperature	331.4799 °C
Cp	1.090747
Temperature	332.4532 °C
Cp	1.090628
Temperature	333.4266 °C
Cp	1.090536
Temperature	334.4 °C
Cp	1.090472
Temperature	335.3734 °C
Cp	1.090437
Temperature	336.3468 °C
Cp	1.090431
Temperature	337.3202 °C
Cp	1.090455
Temperature	338.2935 °C
Cp	1.090503
Temperature	339.2669 °C
Cp	1.090573
Temperature	340.2403 °C
Cp	1.090658
Temperature	341.2137 °C
Cp	1.090753
Temperature	342.1871 °C
Cp	1.090853
Temperature	343.1605 °C
Cp	1.090952
Temperature	344.1339 °C
Cp	1.09105
Temperature	345.1073 °C
Cp	1.091141
Temperature	346.0807 °C
Cp	1.091225
Temperature	347.054 °C
Cp	1.091303
Temperature	348.0274 °C
Cp	1.091379
Temperature	349.0008 °C
Cp	1.091453
Temperature	349.9742 °C
Cp	1.091537
Temperature	350.9476 °C
Cp	1.091633
Temperature	351.921 °C
Cp	1.091743
Temperature	352.8943 °C
Cp	1.091874
Temperature	353.8677 °C
Cp	1.092028
Temperature	354.8411 °C
Cp	1.092206
Temperature	355.8145 °C
Cp	1.092411
Temperature	356.7879 °C
Cp	1.092628
Temperature	357.7613 °C
Cp	1.092862
Temperature	358.7346 °C
Cp	1.093102
Temperature	359.708 °C
Cp	1.093338
Temperature	360.6814 °C
Cp	1.093559
Temperature	361.6548 °C
Cp	1.093752
Temperature	362.6282 °C
Cp	1.093915
Temperature	363.6016 °C
Cp	1.094036
Temperature	364.575 °C
Cp	1.094117
Temperature	365.5484 °C
Cp	1.094159
Temperature	366.5218 °C
Cp	1.094172
Temperature	367.4951 °C
Cp	1.094165
Temperature	368.4685 °C
Cp	1.094163
Temperature	369.4419 °C
Cp	1.094182
Temperature	370.4153 °C
Cp	1.094244
Temperature	371.3887 °C
Cp	1.094375
Temperature	372.3621 °C
Cp	1.094598
Temperature	373.3354 °C
Cp	1.094937
Temperature	374.3088 °C
Cp	1.095389
Temperature	375.2822 °C
Cp	1.095973
Temperature	376.2556 °C
Cp	1.096685
Temperature	377.229 °C
Cp	1.097506
Temperature	378.2024 °C
Cp	1.098406
Temperature	379.1758 °C
Cp	1.099338
Temperature	380.1492 °C
Cp	1.10027
Temperature	381.1225 °C
Cp	1.10112
Temperature	382.0959 °C
Cp	1.101818
Temperature	383.0693 °C
Cp	1.10229
Temperature	384.0427 °C
Cp	1.102459
Temperature	385.0161 °C
Cp	1.102253
Temperature	385.9895 °C
Cp	1.101596
Temperature	386.9629 °C
Cp	1.100438
Temperature	387.9362 °C
Cp	1.098736
Temperature	388.9096 °C
Cp	1.096461
Temperature	389.883 °C
Cp	1.093614
Temperature	390.8564 °C
Cp	1.090208
Temperature	391.8298 °C
Cp	1.086278
Temperature	392.8032 °C
Cp	1.081887
Temperature	393.7766 °C
Cp	1.077096
Temperature	394.7499 °C
Cp	1.072007
Temperature	395.7233 °C
Cp	1.066707
[Rev Cp Calibration]
Date Applied	24/10/2024 12:37:31
Description	From -89.998 °C to 390.542 °C at 2.000°C/min
Gas Type	Nitrogen
Pan Type	Tzero Aluminum
Source Files 1	C:\ProgramData\TA Instruments\TRIOS\Data\Reverse Heat Capacity Calibration(6).tri
GUID	ba867d72-cfbb-486e-971e-e86aa544cc02
Temperature	-89.99799 °C
Cp	1.070076
Temperature	-89.03691 °C
Cp	1.072008
Temperature	-88.07584 °C
Cp	1.073556
Temperature	-87.11475 °C
Cp	1.074743
Temperature	-86.15367 °C
Cp	1.075597
Temperature	-85.1926 °C
Cp	1.076163
Temperature	-84.23151 °C
Cp	1.076477
Temperature	-83.27043 °C
Cp	1.076579
Temperature	-82.30936 °C
Cp	1.076527
Temperature	-81.34827 °C
Cp	1.076322
Temperature	-80.38719 °C
Cp	1.076039
Temperature	-79.42612 °C
Cp	1.07571
Temperature	-78.46503 °C
Cp	1.075361
Temperature	-77.50395 °C
Cp	1.075011
Temperature	-76.54288 °C
Cp	1.074656
Temperature	-75.58179 °C
Cp	1.074359
Temperature	-74.62071 °C
Cp	1.074086
Temperature	-73.65964 °C
Cp	1.073842
Temperature	-72.69855 °C
Cp	1.073627
Temperature	-71.73747 °C
Cp	1.073442
Temperature	-70.7764 °C
Cp	1.07329
Temperature	-69.81532 °C
Cp	1.073148
Temperature	-68.85423 °C
Cp	1.073021
Temperature	-67.89315 °C
Cp	1.072902
Temperature	-66.93208 °C
Cp	1.072782
Temperature	-65.97099 °C
Cp	1.072656
Temperature	-65.00991 °C
Cp	1.072518
Temperature	-64.04884 °C
Cp	1.072374
Temperature	-63.08775 °C
Cp	1.072201
Temperature	-62.12667 °C
Cp	1.072019
Temperature	-61.1656 °C
Cp	1.071827
Temperature	-60.20451 °C
Cp	1.071624
Temperature	-59.24343 °C
Cp	1.071411
Temperature	-58.28236 °C
Cp	1.071167
Temperature	-57.32127 °C
Cp	1.070956
Temperature	-56.3602 °C
Cp	1.070724
Temperature	-55.39911 °C
Cp	1.070483
Temperature	-54.43803 °C
Cp	1.070242
Temperature	-53.47696 °C
Cp	1.070009
Temperature	-52.51587 °C
Cp	1.069825
Temperature	-51.55479 °C
Cp	1.069601
Temperature	-50.59372 °C
Cp	1.069418
Temperature	-49.63263 °C
Cp	1.069267
Temperature	-48.67155 °C
Cp	1.069138
Temperature	-47.71048 °C
Cp	1.069021
Temperature	-46.74939 °C
Cp	1.068875
Temperature	-45.78831 °C
Cp	1.068771
Temperature	-44.82724 °C
Cp	1.068634
Temperature	-43.86615 °C
Cp	1.068462
Temperature	-42.90508 °C
Cp	1.068255
Temperature	-41.944 °C
Cp	1.068012
Temperature	-40.98291 °C
Cp	1.067742
Temperature	-40.02184 °C
Cp	1.067427
Temperature	-39.06076 °C
Cp	1.067088
Temperature	-38.09967 °C
Cp	1.066727
Temperature	-37.1386 °C
Cp	1.066349
Temperature	-36.17752 °C
Cp	1.065958
Temperature	-35.21643 °C
Cp	1.065559
Temperature	-34.25536 °C
Cp	1.065162
Temperature	-33.29427 °C
Cp	1.06476
Temperature	-32.33319 °C
Cp	1.064368
Temperature	-31.37212 °C
Cp	1.06399
Temperature	-30.41104 °C
Cp	1.063628
Temperature	-29.44995 °C
Cp	1.063283
Temperature	-28.48887 °C
Cp	1.06295
Temperature	-27.5278 °C
Cp	1.062645
Temperature	-26.56672 °C
Cp	1.062355
Temperature	-25.60563 °C
Cp	1.06208
Temperature	-24.64456 °C
Cp	1.061819
Temperature	-23.68348 °C
Cp	1.061573
Temperature	-22.72239 °C
Cp	1.061345
Temperature	-21.76132 °C
Cp	1.061123
Temperature	-20.80024 °C
Cp	1.060915
Temperature	-19.83916 °C
Cp	1.060719
Temperature	-18.87807 °C
Cp	1.060531
Temperature	-17.917 °C
Cp	1.06035
Temperature	-16.95592 °C
Cp	1.060161
Temperature	-15.99484 °C
Cp	1.059992
Temperature	-15.03376 °C
Cp	1.059817
Temperature	-14.07268 °C
Cp	1.059634
Temperature	-13.1116 °C
Cp	1.059445
Temperature	-12.15052 °C
Cp	1.059248
Temperature	-11.18944 °C
Cp	1.059043
Temperature	-10.22836 °C
Cp	1.058842
Temperature	-9.267276 °C
Cp	1.058615
Temperature	-8.306196 °C
Cp	1.058388
Temperature	-7.345116 °C
Cp	1.058155
Temperature	-6.384036 °C
Cp	1.057911
Temperature	-5.422956 °C
Cp	1.057652
Temperature	-4.461876 °C
Cp	1.057356
Temperature	-3.500796 °C
Cp	1.057063
Temperature	-2.539716 °C
Cp	1.056732
Temperature	-1.578636 °C
Cp	1.056364
Temperature	-0.6175562 °C
Cp	1.05596
Temperature	0.3435238 °C
Cp	1.055523
Temperature	1.304604 °C
Cp	1.055066
Temperature	2.265684 °C
Cp	1.054561
Temperature	3.226764 °C
Cp	1.054035
Temperature	4.187844 °C
Cp	1.053488
Temperature	5.148924 °C
Cp	1.052922
Temperature	6.110003 °C
Cp	1.052337
Temperature	7.071084 °C
Cp	1.051736
Temperature	8.032164 °C
Cp	1.051118
Temperature	8.993243 °C
Cp	1.050488
Temperature	9.954324 °C
Cp	1.049848
Temperature	10.9154 °C
Cp	1.049202
Temperature	11.87648 °C
Cp	1.048552
Temperature	12.83756 °C
Cp	1.047902
Temperature	13.79864 °C
Cp	1.047255
Temperature	14.75972 °C
Cp	1.046615
Temperature	15.7208 °C
Cp	1.045983
Temperature	16.68188 °C
Cp	1.045362
Temperature	17.64296 °C
Cp	1.044756
Temperature	18.60404 °C
Cp	1.044164
Temperature	19.56512 °C
Cp	1.04358
Temperature	20.5262 °C
Cp	1.043027
Temperature	21.48728 °C
Cp	1.042485
Temperature	22.44836 °C
Cp	1.041958
Temperature	23.40944 °C
Cp	1.041446
Temperature	24.37052 °C
Cp	1.040952
Temperature	25.3316 °C
Cp	1.040493
Temperature	26.29268 °C
Cp	1.040022
Temperature	27.25376 °C
Cp	1.039578
Temperature	28.21484 °C
Cp	1.039158
Temperature	29.17592 °C
Cp	1.038758
Temperature	30.137 °C
Cp	1.038373
Temperature	31.09808 °C
Cp	1.037981
Temperature	32.05916 °C
Cp	1.03763
Temperature	33.02024 °C
Cp	1.037276
Temperature	33.98132 °C
Cp	1.03692
Temperature	34.9424 °C
Cp	1.036565
Temperature	35.90348 °C
Cp	1.036213
Temperature	36.86456 °C
Cp	1.035866
Temperature	37.82564 °C
Cp	1.035529
Temperature	38.78672 °C
Cp	1.035195
Temperature	39.7478 °C
Cp	1.034875
Temperature	40.70888 °C
Cp	1.034568
Temperature	41.66996 °C
Cp	1.034276
Temperature	42.63104 °C
Cp	1.033996
Temperature	43.59212 °C
Cp	1.033726
Temperature	44.5532 °C
Cp	1.033469
Temperature	45.51428 °C
Cp	1.033221
Temperature	46.47536 °C
Cp	1.03298
Temperature	47.43644 °C
Cp	1.032744
Temperature	48.39752 °C
Cp	1.032514
Temperature	49.3586 °C
Cp	1.032289
Temperature	50.31968 °C
Cp	1.032065
Temperature	51.28076 °C
Cp	1.031844
Temperature	52.24184 °C
Cp	1.031627
Temperature	53.20292 °C
Cp	1.031413
Temperature	54.164 °C
Cp	1.031203
Temperature	55.12508 °C
Cp	1.030989
Temperature	56.08616 °C
Cp	1.030791
Temperature	57.04724 °C
Cp	1.030595
Temperature	58.00832 °C
Cp	1.030403
Temperature	58.9694 °C
Cp	1.030217
Temperature	59.93048 °C
Cp	1.03004
Temperature	60.89156 °C
Cp	1.029871
Temperature	61.85264 °C
Cp	1.029718
Temperature	62.81372 °C
Cp	1.029567
Temperature	63.7748 °C
Cp	1.02943
Temperature	64.73589 °C
Cp	1.029304
Temperature	65.69696 °C
Cp	1.029185
Temperature	66.65804 °C
Cp	1.02907
Temperature	67.61913 °C
Cp	1.028946
Temperature	68.5802 °C
Cp	1.028831
Temperature	69.54128 °C
Cp	1.028703
Temperature	70.50237 °C
Cp	1.028561
Temperature	71.46344 °C
Cp	1.028404
Temperature	72.42452 °C
Cp	1.028234
Temperature	73.3856 °C
Cp	1.028063
Temperature	74.34668 °C
Cp	1.027861
Temperature	75.30776 °C
Cp	1.027657
Temperature	76.26884 °C
Cp	1.027451
Temperature	77.22992 °C
Cp	1.027243
Temperature	78.191 °C
Cp	1.027036
Temperature	79.15208 °C
Cp	1.026812
Temperature	80.11316 °C
Cp	1.026623
Temperature	81.07424 °C
Cp	1.026431
Temperature	82.03532 °C
Cp	1.026241
Temperature	82.9964 °C
Cp	1.02606
Temperature	83.95748 °C
Cp	1.025891
Temperature	84.91856 °C
Cp	1.025739
Temperature	85.87964 °C
Cp	1.025614
Temperature	86.84072 °C
Cp	1.025493
Temperature	87.8018 °C
Cp	1.0254
Temperature	88.76288 °C
Cp	1.025329
Temperature	89.72396 °C
Cp	1.025274
Temperature	90.68504 °C
Cp	1.025229
Temperature	91.64612 °C
Cp	1.025174
Temperature	92.6072 °C
Cp	1.025138
Temperature	93.56828 °C
Cp	1.025083
Temperature	94.52936 °C
Cp	1.025008
Temperature	95.49044 °C
Cp	1.024912
Temperature	96.45152 °C
Cp	1.024796
Temperature	97.4126 °C
Cp	1.024671
Temperature	98.37368 °C
Cp	1.024506
Temperature	99.33476 °C
Cp	1.02433
Temperature	100.2958 °C
Cp	1.024144
Temperature	101.2569 °C
Cp	1.023948
Temperature	102.218 °C
Cp	1.023743
Temperature	103.1791 °C
Cp	1.023522
Temperature	104.1402 °C
Cp	1.023309
Temperature	105.1012 °C
Cp	1.023089
Temperature	106.0623 °C
Cp	1.022866
Temperature	107.0234 °C
Cp	1.022644
Temperature	107.9845 °C
Cp	1.022427
Temperature	108.9456 °C
Cp	1.022218
Temperature	109.9066 °C
Cp	1.022022
Temperature	110.8677 °C
Cp	1.021836
Temperature	111.8288 °C
Cp	1.021666
Temperature	112.7899 °C
Cp	1.021512
Temperature	113.751 °C
Cp	1.021374
Temperature	114.712 °C
Cp	1.02125
Temperature	115.6731 °C
Cp	1.021137
Temperature	116.6342 °C
Cp	1.021041
Temperature	117.5953 °C
Cp	1.020953
Temperature	118.5564 °C
Cp	1.020872
Temperature	119.5174 °C
Cp	1.020796
Temperature	120.4785 °C
Cp	1.020725
Temperature	121.4396 °C
Cp	1.020659
Temperature	122.4007 °C
Cp	1.020587
Temperature	123.3618 °C
Cp	1.020515
Temperature	124.3228 °C
Cp	1.02044
Temperature	125.2839 °C
Cp	1.020359
Temperature	126.245 °C
Cp	1.02027
Temperature	127.2061 °C
Cp	1.020167
Temperature	128.1672 °C
Cp	1.020057
Temperature	129.1282 °C
Cp	1.019933
Temperature	130.0893 °C
Cp	1.019793
Temperature	131.0504 °C
Cp	1.019638
Temperature	132.0115 °C
Cp	1.019471
Temperature	132.9726 °C
Cp	1.019292
Temperature	133.9336 °C
Cp	1.019107
Temperature	134.8947 °C
Cp	1.018912
Temperature	135.8558 °C
Cp	1.018717
Temperature	136.8169 °C
Cp	1.018527
Temperature	137.778 °C
Cp	1.018344
Temperature	138.739 °C
Cp	1.018171
Temperature	139.7001 °C
Cp	1.018004
Temperature	140.6612 °C
Cp	1.01787
Temperature	141.6223 °C
Cp	1.01775
Temperature	142.5834 °C
Cp	1.017652
Temperature	143.5444 °C
Cp	1.017578
Temperature	144.5055 °C
Cp	1.017534
Temperature	145.4666 °C
Cp	1.017536
Temperature	146.4277 °C
Cp	1.017545
Temperature	147.3888 °C
Cp	1.017595
Temperature	148.3498 °C
Cp	1.017679
Temperature	149.3109 °C
Cp	1.01779
Temperature	150.272 °C
Cp	1.01792
Temperature	151.2331 °C
Cp	1.018043
Temperature	152.1942 °C
Cp	1.018199
Temperature	153.1552 °C
Cp	1.018339
Temperature	154.1163 °C
Cp	1.018458
Temperature	155.0774 °C
Cp	1.018552
Temperature	156.0385 °C
Cp	1.018618
Temperature	156.9996 °C
Cp	1.018662
Temperature	157.9606 °C
Cp	1.018664
Temperature	158.9217 °C
Cp	1.018632
Temperature	159.8828 °C
Cp	1.018575
Temperature	160.8439 °C
Cp	1.018492
Temperature	161.805 °C
Cp	1.018383
Temperature	162.766 °C
Cp	1.01825
Temperature	163.7271 °C
Cp	1.018087
Temperature	164.6882 °C
Cp	1.017917
Temperature	165.6493 °C
Cp	1.017726
Temperature	166.6104 °C
Cp	1.017522
Temperature	167.5714 °C
Cp	1.01731
Temperature	168.5325 °C
Cp	1.017098
Temperature	169.4936 °C
Cp	1.016902
Temperature	170.4547 °C
Cp	1.016695
Temperature	171.4158 °C
Cp	1.016508
Temperature	172.3768 °C
Cp	1.016342
Temperature	173.3379 °C
Cp	1.016195
Temperature	174.299 °C
Cp	1.016065
Temperature	175.2601 °C
Cp	1.015927
Temperature	176.2212 °C
Cp	1.015838
Temperature	177.1822 °C
Cp	1.015746
Temperature	178.1433 °C
Cp	1.015651
Temperature	179.1044 °C
Cp	1.015555
Temperature	180.0655 °C
Cp	1.015459
Temperature	181.0266 °C
Cp	1.015401
Temperature	181.9876 °C
Cp	1.015288
Temperature	182.9487 °C
Cp	1.015195
Temperature	183.9098 °C
Cp	1.015117
Temperature	184.8709 °C
Cp	1.01505
Temperature	185.832 °C
Cp	1.014988
Temperature	186.793 °C
Cp	1.014927
Temperature	187.7541 °C
Cp	1.014849
Temperature	188.7152 °C
Cp	1.014789
Temperature	189.6763 °C
Cp	1.01471
Temperature	190.6374 °C
Cp	1.014614
Temperature	191.5984 °C
Cp	1.014503
Temperature	192.5595 °C
Cp	1.014381
Temperature	193.5206 °C
Cp	1.014268
Temperature	194.4817 °C
Cp	1.014122
Temperature	195.4428 °C
Cp	1.013984
Temperature	196.4038 °C
Cp	1.013853
Temperature	197.3649 °C
Cp	1.013726
Temperature	198.326 °C
Cp	1.013603
Temperature	199.2871 °C
Cp	1.013467
Temperature	200.2482 °C
Cp	1.013359
Temperature	201.2092 °C
Cp	1.013243
Temperature	202.1703 °C
Cp	1.013123
Temperature	203.1314 °C
Cp	1.013002
Temperature	204.0925 °C
Cp	1.012884
Temperature	205.0536 °C
Cp	1.012788
Temperature	206.0146 °C
Cp	1.012674
Temperature	206.9757 °C
Cp	1.012579
Temperature	207.9368 °C
Cp	1.012501
Temperature	208.8979 °C
Cp	1.012439
Temperature	209.859 °C
Cp	1.012389
Temperature	210.82 °C
Cp	1.012351
Temperature	211.7811 °C
Cp	1.012312
Temperature	212.7422 °C
Cp	1.01229
Temperature	213.7033 °C
Cp	1.012262
Temperature	214.6644 °C
Cp	1.012227
Temperature	215.6254 °C
Cp	1.012183
Temperature	216.5865 °C
Cp	1.012129
Temperature	217.5476 °C
Cp	1.012077
Temperature	218.5087 °C
Cp	1.01199
Temperature	219.4698 °C
Cp	1.011897
Temperature	220.4308 °C
Cp	1.011793
Temperature	221.3919 °C
Cp	1.011674
Temperature	222.353 °C
Cp	1.011537
Temperature	223.3141 °C
Cp	1.011362
Temperature	224.2752 °C
Cp	1.011194
Temperature	225.2362 °C
Cp	1.010993
Temperature	226.1973 °C
Cp	1.010766
Temperature	227.1584 °C
Cp	1.010517
Temperature	228.1195 °C
Cp	1.010251
Temperature	229.0806 °C
Cp	1.009998
Temperature	230.0416 °C
Cp	1.009703
Temperature	231.0027 °C
Cp	1.009422
Temperature	231.9638 °C
Cp	1.009156
Temperature	232.9249 °C
Cp	1.008906
Temperature	233.886 °C
Cp	1.008675
Temperature	234.847 °C
Cp	1.008462
Temperature	235.8081 °C
Cp	1.008258
Temperature	236.7692 °C
Cp	1.00809
Temperature	237.7303 °C
Cp	1.007934
Temperature	238.6914 °C
Cp	1.007793
Temperature	239.6524 °C
Cp	1.007668
Temperature	240.6135 °C
Cp	1.007562
Temperature	241.5746 °C
Cp	1.007487
Temperature	242.5357 °C
Cp	1.00741
Temperature	243.4967 °C
Cp	1.00736
Temperature	244.4578 °C
Cp	1.007332
Temperature	245.4189 °C
Cp	1.007321
Temperature	246.38 °C
Cp	1.007321
Temperature	247.3411 °C
Cp	1.007312
Temperature	248.3022 °C
Cp	1.007331
Temperature	249.2632 °C
Cp	1.007338
Temperature	250.2243 °C
Cp	1.007335
Temperature	251.1854 °C
Cp	1.00732
Temperature	252.1465 °C
Cp	1.007295
Temperature	253.1076 °C
Cp	1.007277
Temperature	254.0686 °C
Cp	1.007227
Temperature	255.0297 °C
Cp	1.007179
Temperature	255.9908 °C
Cp	1.007133
Temperature	256.9519 °C
Cp	1.00709
Temperature	257.913 °C
Cp	1.007049
Temperature	258.874 °C
Cp	1.007012
Temperature	259.8351 °C
Cp	1.006978
Temperature	260.7962 °C
Cp	1.006956
Temperature	261.7573 °C
Cp	1.00694
Temperature	262.7184 °C
Cp	1.006934
Temperature	263.6794 °C
Cp	1.006939
Temperature	264.6405 °C
Cp	1.00696
Temperature	265.6016 °C
Cp	1.006999
Temperature	266.5627 °C
Cp	1.007054
Temperature	267.5237 °C
Cp	1.007131
Temperature	268.4848 °C
Cp	1.00723
Temperature	269.4459 °C
Cp	1.00735
Temperature	270.407 °C
Cp	1.007493
Temperature	271.3681 °C
Cp	1.007656
Temperature	272.3292 °C
Cp	1.007839
Temperature	273.2902 °C
Cp	1.008039
Temperature	274.2513 °C
Cp	1.008257
Temperature	275.2124 °C
Cp	1.008488
Temperature	276.1735 °C
Cp	1.008731
Temperature	277.1346 °C
Cp	1.008977
Temperature	278.0956 °C
Cp	1.009237
Temperature	279.0567 °C
Cp	1.009498
Temperature	280.0178 °C
Cp	1.009757
Temperature	280.9789 °C
Cp	1.010014
Temperature	281.9399 °C
Cp	1.010267
Temperature	282.901 °C
Cp	1.010515
Temperature	283.8621 °C
Cp	1.01076
Temperature	284.8232 °C
Cp	1.010993
Temperature	285.7843 °C
Cp	1.011222
Temperature	286.7454 °C
Cp	1.011447
Temperature	287.7064 °C
Cp	1.011665
Temperature	288.6675 °C
Cp	1.011876
Temperature	289.6286 °C
Cp	1.012079
Temperature	290.5897 °C
Cp	1.01228
Temperature	291.5508 °C
Cp	1.012474
Temperature	292.5118 °C
Cp	1.012662
Temperature	293.4729 °C
Cp	1.012846
Temperature	294.434 °C
Cp	1.013028
Temperature	295.3951 °C
Cp	1.013211
Temperature	296.3561 °C
Cp	1.013391
Temperature	297.3172 °C
Cp	1.013574
Temperature	298.2783 °C
Cp	1.013759
Temperature	299.2394 °C
Cp	1.013947
Temperature	300.2005 °C
Cp	1.014136
Temperature	301.1616 °C
Cp	1.01432
Temperature	302.1226 °C
Cp	1.014511
Temperature	303.0837 °C
Cp	1.014695
Temperature	304.0448 °C
Cp	1.014872
Temperature	305.0059 °C
Cp	1.01504
Temperature	305.9669 °C
Cp	1.015198
Temperature	306.928 °C
Cp	1.015343
Temperature	307.8891 °C
Cp	1.015479
Temperature	308.8502 °C
Cp	1.015595
Temperature	309.8113 °C
Cp	1.015699
Temperature	310.7724 °C
Cp	1.015789
Temperature	311.7334 °C
Cp	1.015865
Temperature	312.6945 °C
Cp	1.015925
Temperature	313.6556 °C
Cp	1.015964
Temperature	314.6167 °C
Cp	1.015999
Temperature	315.5778 °C
Cp	1.016018
Temperature	316.5388 °C
Cp	1.016025
Temperature	317.4999 °C
Cp	1.016024
Temperature	318.461 °C
Cp	1.01602
Temperature	319.4221 °C
Cp	1.016029
Temperature	320.3831 °C
Cp	1.016025
Temperature	321.3442 °C
Cp	1.016037
Temperature	322.3053 °C
Cp	1.016066
Temperature	323.2664 °C
Cp	1.01611
Temperature	324.2275 °C
Cp	1.016169
Temperature	325.1886 °C
Cp	1.016225
Temperature	326.1496 °C
Cp	1.016318
Temperature	327.1107 °C
Cp	1.016411
Temperature	328.0718 °C
Cp	1.016504
Temperature	329.0329 °C
Cp	1.016596
Temperature	329.994 °C
Cp	1.016687
Temperature	330.955 °C
Cp	1.016775
Temperature	331.9161 °C
Cp	1.016864
Temperature	332.8772 °C
Cp	1.016942
Temperature	333.8383 °C
Cp	1.017019
Temperature	334.7993 °C
Cp	1.017093
Temperature	335.7604 °C
Cp	1.017163
Temperature	336.7215 °C
Cp	1.01723
[...]
151.5383	111.1653	0.3767
151.5467	111.0817	0.3767
151.5550	110.9984	0.3767
151.5633	110.9161	0.3767
151.5717	110.8322	0.3766
151.5800	110.7493	0.3766
151.5883	110.6664	0.3766
151.5967	110.5833	0.3766
151.6050	110.4998	0.3765
151.6133	110.4159	0.3765
151.6217	110.3335	0.3765
151.6300	110.2497	0.3765
151.6383	110.1675	0.3765
151.6467	110.0852	0.3764
151.6550	110.0011	0.3764
151.6633	109.9175	0.3764
151.6717	109.8345	0.3763
151.6800	109.7507	0.3763
151.6883	109.6683	0.3763
151.6967	109.5847	0.3762
151.7050	109.5016	0.3762
151.7133	109.4189	0.3762
151.7217	109.3360	0.3761
151.7300	109.2523	0.3761
151.7383	109.1704	0.3761
151.7467	109.0864	0.3761
151.7550	109.0027	0.3761
151.7633	108.9198	0.3760
151.7717	108.8368	0.3760
151.7800	108.7535	0.3760
151.7883	108.6708	0.3760
151.7967	108.5869	0.3759
151.8050	108.5047	0.3759
151.8133	108.4220	0.3759
151.8217	108.3391	0.3758
151.8300	108.2557	0.3758
151.8383	108.1719	0.3758
151.8467	108.0904	0.3758
151.8550	108.0054	0.3758
151.8633	107.9229	0.3757
151.8717	107.8398	0.3757
151.8800	107.7580	0.3757
151.8883	107.6742	0.3757
151.8967	107.5902	0.3756
151.9050	107.5073	0.3756
151.9133	107.4243	0.3756
151.9217	107.3414	0.3756
151.9300	107.2574	0.3756
151.9383	107.1752	0.3755
151.9467	107.0930	0.3755
151.9550	107.0081	0.3755
151.9633	106.9242	0.3755
151.9717	106.8418	0.3754
151.9800	106.7592	0.3754
151.9883	106.6758	0.3753
151.9967	106.5918	0.3753
152.0050	106.5099	0.3753
152.0133	106.4266	0.3753
152.0217	106.3429	0.3752
152.0300	106.2594	0.3752
152.0383	106.1768	0.3752
152.0467	106.0935	0.3752
152.0550	106.0118	0.3751
152.0633	105.9284	0.3751
152.0717	105.8452	0.3751
152.0800	105.7624	0.3751
152.0883	105.6783	0.3750
152.0967	105.5958	0.3750
152.1050	105.5130	0.3750
152.1133	105.4297	0.3750
152.1217	105.3470	0.3749
152.1300	105.2632	0.3749
152.1383	105.1794	0.3749
152.1467	105.0968	0.3749
152.1550	105.0136	0.3748
152.1633	104.9296	0.3748
152.1717	104.8472	0.3748
152.1800	104.7647	0.3747
152.1883	104.6814	0.3747
152.1967	104.5965	0.3747
152.2050	104.5146	0.3747
152.2133	104.4307	0.3747
152.2217	104.3483	0.3747
152.2300	104.2648	0.3746
152.2383	104.1804	0.3746
152.2467	104.0981	0.3746
152.2550	104.0148	0.3746
152.2633	103.9306	0.3745
152.2717	103.8489	0.3745
152.2800	103.7658	0.3745
152.2883	103.6838	0.3745
152.2967	103.5996	0.3744
152.3050	103.5167	0.3744
152.3133	103.4341	0.3744
152.3217	103.3515	0.3743
152.3300	103.2679	0.3743
152.3383	103.1848	0.3743
152.3467	103.1024	0.3743
152.3550	103.0190	0.3742
152.3633	102.9350	0.3742
152.3717	102.8519	0.3741
152.3800	102.7685	0.3741
152.3883	102.6861	0.3741
152.3967	102.6030	0.3741
152.4050	102.5189	0.3740
152.4133	102.4372	0.3740
152.4217	102.3527	0.3740
152.4300	102.2701	0.3740
152.4383	102.1866	0.3740
152.4467	102.1036	0.3739
152.4550	102.0204	0.3739
152.4633	101.9371	0.3739
152.4717	101.8542	0.3739
152.4800	101.7708	0.3738
152.4883	101.6876	0.3738
152.4967	101.6043	0.3738
152.5050	101.5216	0.3737
152.5133	101.4371	0.3737
152.5217	101.3553	0.3737
152.5300	101.2720	0.3737
152.5383	101.1907	0.3736
152.5467	101.1068	0.3736
152.5550	101.0229	0.3736
152.5633	100.9400	0.3736
152.5717	100.8561	0.3735
152.5800	100.7738	0.3735
152.5883	100.6906	0.3735
152.5967	100.6070	0.3735
152.6050	100.5244	0.3734
152.6133	100.4410	0.3734
152.6217	100.3581	0.3734
152.6300	100.2747	0.3734
152.6383	100.1908	0.3733
152.6467	100.1077	0.3733
152.6550	100.0249	0.3733
152.6633	99.9409	0.3733
152.6717	99.8588	0.3732
152.6800	99.7762	0.3732
152.6883	99.6943	0.3731
152.6967	99.6097	0.3731
152.7050	99.5262	0.3731
152.7133	99.4424	0.3731
152.7217	99.3597	0.3731
152.7300	99.2771	0.3730
152.7383	99.1949	0.3730
152.7467	99.1107	0.3730
152.7550	99.0278	0.3729
152.7633	98.9443	0.3729
152.7717	98.8616	0.3729
152.7800	98.7774	0.3729
152.7883	98.6949	0.3728
152.7967	98.6104	0.3728
152.8050	98.5281	0.3728
152.8133	98.4450	0.3728
152.8217	98.3615	0.3727
152.8300	98.2776	0.3727
152.8383	98.1949	0.3727
152.8467	98.1126	0.3726
152.8550	98.0298	0.3726
152.8633	97.9468	0.3726
152.8717	97.8622	0.3725
152.8800	97.7797	0.3725
152.8883	97.6963	0.3725
152.8967	97.6130	0.3724
152.9050	97.5306	0.3724
152.9133	97.4471	0.3723
152.9217	97.3657	0.3723
152.9300	97.2813	0.3723
152.9383	97.1980	0.3722
152.9467	97.1152	0.3722
152.9550	97.0324	0.3722
152.9633	96.9479	0.3721
152.9717	96.8652	0.3721
152.9800	96.7832	0.3721
152.9883	96.6996	0.3720
152.9967	96.6162	0.3720
153.0050	96.5333	0.3720
153.0133	96.4500	0.3719
153.0217	96.3658	0.3719
153.0300	96.2831	0.3719
153.0383	96.2002	0.3719
153.0467	96.1181	0.3718
153.0550	96.0343	0.3718
153.0633	95.9512	0.3718
153.0717	95.8681	0.3717
153.0800	95.7849	0.3717
153.0883	95.7020	0.3716
153.0967	95.6191	0.3716
153.1050	95.5368	0.3716
153.1133	95.4533	0.3716
153.1217	95.3700	0.3715
153.1300	95.2868	0.3715
153.1383	95.2031	0.3715
153.1467	95.1207	0.3714
153.1550	95.0377	0.3714
153.1633	94.9531	0.3713
153.1717	94.8709	0.3713
153.1800	94.7864	0.3713
153.1883	94.7040	0.3713
153.1967	94.6210	0.3712
153.2050	94.5383	0.3712
153.2133	94.4547	0.3711
153.2217	94.3723	0.3711
153.2300	94.2889	0.3711
153.2383	94.2063	0.3710
153.2467	94.1236	0.3710
153.2550	94.0397	0.3710
153.2633	93.9559	0.3710
153.2717	93.8734	0.3709
153.2800	93.7904	0.3709
153.2883	93.7075	0.3709
153.2967	93.6236	0.3708
153.3050	93.5412	0.3708
153.3133	93.4585	0.3707
153.3217	93.3752	0.3707
153.3300	93.2914	0.3707
153.3383	93.2100	0.3707
153.3467	93.1250	0.3706
153.3550	93.0431	0.3706
153.3633	92.9592	0.3706
153.3717	92.8756	0.3706
153.3800	92.7926	0.3705
153.3883	92.7100	0.3705
153.3967	92.6269	0.3705
153.4050	92.5430	0.3705
153.4133	92.4598	0.3705
153.4217	92.3770	0.3704
153.4300	92.2942	0.3704
153.4383	92.2111	0.3704
153.4467	92.1273	0.3704
153.4550	92.0443	0.3703
153.4633	91.9621	0.3703
153.4717	91.8781	0.3703
153.4800	91.7961	0.3702
153.4883	91.7117	0.3702
153.4967	91.6289	0.3702
153.5050	91.5465	0.3702
153.5133	91.4625	0.3702
153.5217	91.3794	0.3701
153.5300	91.2961	0.3701
153.5383	91.2130	0.3701
153.5467	91.1310	0.3700
153.5550	91.0480	0.3700
153.5633	90.9645	0.3700
153.5717	90.8813	0.3700
153.5800	90.7978	0.3700
153.5883	90.7148	0.3700
153.5967	90.6324	0.3699
153.6050	90.5487	0.3698
153.6133	90.4648	0.3698
153.6217	90.3819	0.3698
153.6300	90.2990	0.3698
153.6383	90.2157	0.3698
153.6467	90.1332	0.3697
153.6550	90.0497	0.3697
153.6633	89.9673	0.3697
153.6717	89.8837	0.3697
153.6800	89.8007	0.3696
153.6883	89.7174	0.3696
153.6967	89.6343	0.3695
153.7050	89.5517	0.3695
153.7133	89.4679	0.3695
153.7217	89.3853	0.3695
153.7300	89.3032	0.3695
153.7383	89.2194	0.3695
153.7467	89.1351	0.3695
153.7550	89.0512	0.3695
153.7633	88.9684	0.3695
153.7717	88.8849	0.3694
153.7800	88.8018	0.3694
153.7883	88.7189	0.3694
153.7967	88.6357	0.3694
153.8050	88.5528	0.3694
153.8133	88.4699	0.3694
153.8217	88.3863	0.3693
153.8300	88.3026	0.3693
153.8383	88.2196	0.3693
153.8467	88.1356	0.3693
153.8550	88.0535	0.3692
153.8633	87.9702	0.3692
153.8717	87.8876	0.3692
153.8800	87.8038	0.3692
153.8883	87.7204	0.3691
153.8967	87.6375	0.3691
153.9050	87.5546	0.3691
153.9133	87.4707	0.3690
153.9217	87.3887	0.3690
153.9300	87.3042	0.3690
153.9383	87.2223	0.3689
153.9467	87.1382	0.3689
153.9550	87.0542	0.3689
153.9633	86.9705	0.3689
153.9717	86.8891	0.3688
153.9800	86.8046	0.3687
153.9883	86.7217	0.3687
153.9967	86.6390	0.3686
154.0050	86.5562	0.3686
154.0133	86.4733	0.3686
154.0217	86.3888	0.3686
154.0300	86.3066	0.3685
154.0383	86.2234	0.3684
154.0467	86.1401	0.3683
154.0550	86.0558	0.3683
154.0633	85.9734	0.3683
154.0717	85.8904	0.3683
154.0800	85.8070	0.3682
154.0883	85.7251	0.3682
154.0967	85.6413	0.3682
154.1050	85.5583	0.3681
154.1133	85.4746	0.3681
154.1217	85.3911	0.3681
154.1300	85.3085	0.3680
154.1383	85.2252	0.3679
154.1467	85.1411	0.3679
154.1550	85.0579	0.3679
154.1633	84.9752	0.3679
154.1717	84.8911	0.3678
154.1800	84.8095	0.3678
154.1883	84.7261	0.3678
154.1967	84.6435	0.3677
154.2050	84.5595	0.3677
154.2133	84.4768	0.3677
154.2217	84.3935	0.3676
154.2300	84.3097	0.3676
154.2383	84.2269	0.3676
154.2467	84.1444	0.3674
154.2550	84.0610	0.3674
154.2633	83.9771	0.3674
154.2717	83.8952	0.3674
154.2800	83.8114	0.3673
154.2883	83.7287	0.3673
154.2967	83.6439	0.3673
154.3050	83.5624	0.3672
154.3133	83.4781	0.3672
154.3217	83.3956	0.3672
154.3300	83.3123	0.3672
154.3383	83.2296	0.3671
154.3467	83.1472	0.3671
154.3550	83.0638	0.3670
154.3633	82.9809	0.3670
154.3717	82.8970	0.3670
154.3800	82.8148	0.3669
154.3883	82.7318	0.3669
154.3967	82.6481	0.3669
154.4050	82.5649	0.3668
154.4133	82.4820	0.3668
154.4217	82.3983	0.3668
154.4300	82.3160	0.3667
154.4383	82.2330	0.3667
154.4467	82.1496	0.3666
154.4550	82.0662	0.3666
154.4633	81.9831	0.3666
154.4717	81.8999	0.3666
154.4800	81.8161	0.3665
154.4883	81.7333	0.3665
154.4967	81.6501	0.3665
154.5050	81.5656	0.3665
154.5133	81.4836	0.3664
154.5217	81.4000	0.3664
154.5300	81.3186	0.3664
154.5383	81.2335	0.3663
154.5467	81.1509	0.3663
154.5550	81.0680	0.3663
154.5633	80.9843	0.3663
154.5717	80.9013	0.3663
154.5800	80.8188	0.3662
154.5883	80.7352	0.3662
154.5967	80.6520	0.3661
154.6050	80.5690	0.3661
154.6133	80.4858	0.3661
154.6217	80.4020	0.3660
154.6300	80.3186	0.3660
154.6383	80.2362	0.3659
154.6467	80.1523	0.3659
154.6550	80.0699	0.3659
154.6633	79.9858	0.3659
154.6717	79.9035	0.3658
154.6800	79.8206	0.3658
154.6883	79.7366	0.3658
154.6967	79.6534	0.3657
154.7050	79.5705	0.3657
154.7133	79.4883	0.3656
154.7217	79.4049	0.3656
154.7300	79.3224	0.3656
154.7383	79.2383	0.3655
154.7467	79.1539	0.3655
154.7550	79.0723	0.3654
154.7633	78.9884	0.3654
154.7717	78.9059	0.3654
154.7800	78.8220	0.3653
154.7883	78.7392	0.3653
154.7967	78.6554	0.3653
154.8050	78.5724	0.3653
154.8133	78.4897	0.3652
154.8217	78.4067	0.3652
154.8300	78.3233	0.3652
154.8383	78.2408	0.3652
154.8467	78.1578	0.3651
154.8550	78.0737	0.3651
154.8633	77.9913	0.3649
154.8717	77.9076	0.3649
154.8800	77.8252	0.3649
154.8883	77.7427	0.3649
154.8967	77.6585	0.3649
154.9050	77.5743	0.3648
154.9133	77.4914	0.3647
154.9217	77.4091	0.3647
154.9300	77.3253	0.3647
154.9383	77.2427	0.3647
154.9467	77.1588	0.3646
154.9550	77.0747	0.3646
154.9633	76.9925	0.3646
154.9717	76.9099	0.3646
154.9800	76.8272	0.3645
154.9883	76.7431	0.3645
154.9967	76.6606	0.3645
155.0050	76.5767	0.3645
155.0133	76.4936	0.3644
155.0217	76.4109	0.3644
155.0300	76.3275	0.3644
155.0383	76.2457	0.3644
155.0467	76.1617	0.3643
155.0550	76.0794	0.3643
155.0633	75.9956	0.3642
155.0717	75.9123	0.3642
155.0800	75.8298	0.3642
155.0883	75.7463	0.3641
155.0967	75.6638	0.3641
155.1050	75.5793	0.3641
155.1133	75.4959	0.3641
155.1217	75.4140	0.3640
155.1300	75.3312	0.3639
155.1383	75.2470	0.3639
155.1467	75.1644	0.3639
155.1550	75.0805	0.3638
155.1633	74.9981	0.3638
155.1717	74.9153	0.3638
155.1800	74.8322	0.3637
155.1883	74.7489	0.3637
155.1967	74.6662	0.3637
155.2050	74.5826	0.3637
155.2133	74.4993	0.3636
155.2217	74.4157	0.3636
155.2300	74.3325	0.3635
155.2383	74.2499	0.3635
155.2467	74.1667	0.3635
155.2550	74.0832	0.3634
155.2633	74.0004	0.3634
155.2717	73.9169	0.3634
155.2800	73.8325	0.3634
155.2883	73.7505	0.3633
155.2967	73.6666	0.3632
155.3050	73.5840	0.3632
155.3133	73.5001	0.3632
155.3217	73.4178	0.3631
155.3300	73.3350	0.3631
155.3383	73.2529	0.3630
155.3467	73.1695	0.3630
155.3550	73.0855	0.3630
155.3633	73.0028	0.3629
155.3717	72.9182	0.3629
155.3800	72.8365	0.3629
155.3883	72.7530	0.3629
155.3967	72.6706	0.3628
155.4050	72.5869	0.3628
155.4133	72.5031	0.3628
155.4217	72.4203	0.3627
155.4300	72.3379	0.3627
155.4383	72.2550	0.3626
155.4467	72.1710	0.3626
155.4550	72.0887	0.3626
155.4633	72.0053	0.3625
155.4717	71.9215	0.3625
155.4800	71.8386	0.3625
155.4883	71.7548	0.3624
155.4967	71.6726	0.3624
155.5050	71.5895	0.3624
155.5133	71.5060	0.3623
155.5217	71.4234	0.3623
155.5300	71.3399	0.3622
155.5383	71.2562	0.3622
155.5467	71.1730	0.3622
155.5550	71.0907	0.3622
155.5633	71.0075	0.3622
155.5717	70.9243	0.3621
155.5800	70.8401	0.3621
155.5883	70.7574	0.3621
155.5967	70.6759	0.3620
155.6050	70.5915	0.3620
155.6133	70.5093	0.3620
155.6217	70.4252	0.3620
155.6300	70.3422	0.3619
155.6383	70.2584	0.3619
155.6467	70.1753	0.3619
155.6550	70.0926	0.3618
155.6633	70.0093	0.3618
155.6717	69.9268	0.3618
155.6800	69.8425	0.3618
155.6883	69.7595	0.3618
155.6967	69.6758	0.3617
155.7050	69.5931	0.3617
155.7133	69.5108	0.3617
155.7217	69.4260	0.3617
155.7300	69.3432	0.3616
155.7383	69.2611	0.3616
155.7467	69.1778	0.3615
155.7550	69.0944	0.3615
155.7633	69.0106	0.3615
155.7717	68.9280	0.3614
155.7800	68.8445	0.3613
155.7883	68.7617	0.3613
155.7967	68.6790	0.3613
155.8050	68.5957	0.3612
155.8133	68.5127	0.3612
155.8217	68.4294	0.3611
155.8300	68.3462	0.3611
155.8383	68.2630	0.3611
155.8467	68.1793	0.3611
155.8550	68.0968	0.3610
155.8633	68.0137	0.3610
155.8717	67.9305	0.3610
155.8800	67.8468	0.3609
155.8883	67.7639	0.3609
155.8967	67.6814	0.3609
155.9050	67.5988	0.3608
155.9133	67.5147	0.3608
155.9217	67.4318	0.3607
155.9300	67.3483	0.3607
155.9383	67.2657	0.3607
155.9467	67.1813	0.3607
155.9550	67.0994	0.3606
155.9633	67.0165	0.3606
155.9717	66.9322	0.3606
155.9800	66.8497	0.3605
155.9883	66.7670	0.3605
155.9967	66.6838	0.3605
156.0050	66.5997	0.3604
156.0133	66.5167	0.3604
156.0217	66.4338	0.3604
156.0300	66.3502	0.3603
156.0383	66.2670	0.3603
156.0467	66.1846	0.3603
156.0550	66.1011	0.3602
156.0633	66.0195	0.3602
156.0717	65.9361	0.3601
156.0800	65.8526	0.3601
156.0883	65.7692	0.3601
156.0967	65.6855	0.3601
156.1050	65.6033	0.3600
156.1133	65.5201	0.3600
156.1217	65.4361	0.3599
156.1300	65.3531	0.3599
156.1383	65.2703	0.3599
156.1467	65.1876	0.3598
156.1550	65.1031	0.3598
156.1633	65.0206	0.3598
156.1717	64.9374	0.3597
156.1800	64.8546	0.3597
156.1883	64.7715	0.3597
156.1967	64.6875	0.3596
156.2050	64.6051	0.3596
156.2133	64.5219	0.3596
156.2217	64.4386	0.3595
156.2300	64.3562	0.3595
156.2383	64.2730	0.3595
156.2467	64.1889	0.3595
156.2550	64.1067	0.3594
156.2633	64.0238	0.3594
156.2717	63.9409	0.3593
156.2800	63.8559	0.3593
156.2883	63.7730	0.3593
156.2967	63.6897	0.3592
156.3050	63.6068	0.3592
156.3133	63.5242	0.3591
156.3217	63.4405	0.3591
156.3300	63.3572	0.3591
156.3383	63.2745	0.3591
156.3467	63.1915	0.3590
156.3550	63.1076	0.3590
156.3633	63.0244	0.3590
156.3717	62.9412	0.3589
156.3800	62.8589	0.3588
156.3883	62.7760	0.3588
156.3967	62.6921	0.3587
156.4050	62.6088	0.3587
156.4133	62.5261	0.3587
156.4217	62.4434	0.3587
156.4300	62.3589	0.3587
156.4383	62.2753	0.3586
156.4467	62.1926	0.3585
156.4550	62.1099	0.3585
156.4633	62.0263	0.3585
156.4717	61.9439	0.3585
156.4800	61.8610	0.3584
156.4883	61.7774	0.3584
156.4967	61.6934	0.3584
156.5050	61.6106	0.3583
156.5133	61.5272	0.3583
156.5217	61.4432	0.3583
156.5300	61.3614	0.3582
156.5383	61.2780	0.3582
156.5467	61.1953	0.3582
156.5550	61.1121	0.3581
156.5633	61.0288	0.3581
156.5717	60.9449	0.3581
156.5800	60.8625	0.3580
156.5883	60.7794	0.3580
156.5967	60.6963	0.3579
156.6050	60.6133	0.3579
156.6133	60.5302	0.3579
156.6217	60.4465	0.3578
156.6300	60.3639	0.3578
156.6383	60.2801	0.3578
156.6467	60.1978	0.3577
156.6550	60.1147	0.3577
156.6633	60.0309	0.3577
156.6717	59.9479	0.3576
156.6800	59.8652	0.3576
156.6883	59.7823	0.3576
156.6967	59.6984	0.3575
156.7050	59.6158	0.3575
156.7133	59.5324	0.3574
156.7217	59.4496	0.3574
156.7300	59.3656	0.3574
156.7383	59.2831	0.3573
156.7467	59.1992	0.3573
156.7550	59.1169	0.3573
156.7633	59.0337	0.3572
156.7717	58.9499	0.3572
156.7800	58.8666	0.3572
156.7883	58.7839	0.3572
156.7967	58.7010	0.3571
156.8050	58.6176	0.3571
156.8133	58.5345	0.3570
156.8217	58.4518	0.3570
156.8300	58.3682	0.3570
156.8383	58.2852	0.3570
156.8467	58.2019	0.3570
156.8550	58.1188	0.3570
156.8633	58.0353	0.3570
156.8717	57.9529	0.3570
156.8800	57.8689	0.3570
156.8883	57.7863	0.3573
156.8967	57.7033	0.3575
156.9050	57.6219	0.3576
156.9133	57.5370	0.3580
156.9217	57.4546	0.3593
156.9300	57.3727	0.3601
156.9383	57.2905	0.3633
156.9467	57.2073	0.3656
156.9550	57.1257	0.3694
156.9633	57.0437	0.3724
156.9717	56.9625	0.3768
156.9800	56.8820	0.3841
156.9883	56.8022	0.3932
156.9967	56.7222	0.4037
157.0050	56.6442	0.4176
157.0133	56.5668	0.4358
157.0217	56.4924	0.4585
157.0300	56.4197	0.4878
157.0383	56.3503	0.5239
157.0467	56.2832	0.5688
157.0550	56.2221	0.6226
157.0633	56.1642	0.6864
157.0717	56.1135	0.7622
157.0800	56.0681	0.8488
157.0883	56.0309	0.9456
157.0967	55.9994	1.0500
157.1050	55.9777	1.1617
157.1133	55.9621	1.2769
157.1217	55.9518	1.3917
157.1300	55.9490	1.5053
157.1383	55.9494	1.6131
157.1467	55.9559	1.7145
157.1550	55.9614	1.8079
157.1633	55.9703	1.8938
157.1717	55.9776	1.9714
157.1800	55.9838	2.0411
157.1883	55.9897	2.1042
157.1967	55.9930	2.1616
157.2050	55.9934	2.2147
157.2133	55.9911	2.2624
157.2217	55.9858	2.3072
157.2300	55.9785	2.3493
157.2383	55.9674	2.3886
157.2467	55.9532	2.4251
157.2550	55.9364	2.4620
157.2633	55.9168	2.4955
157.2717	55.8944	2.5272
157.2800	55.8696	2.5590
157.2883	55.8426	2.5903
157.2967	55.8129	2.6196
157.3050	55.7821	2.6478
157.3133	55.7499	2.6749
157.3217	55.7137	2.7020
157.3300	55.6777	2.7282
157.3383	55.6387	2.7530
157.3467	55.5988	2.7762
157.3550	55.5576	2.7997
157.3633	55.5140	2.8210
157.3717	55.4698	2.8419
157.3800	55.4223	2.8612
157.3883	55.3751	2.8794
157.3967	55.3251	2.8970
157.4050	55.2751	2.9128
157.4133	55.2229	2.9271
157.4217	55.1687	2.9400
157.4300	55.1133	2.9517
157.4383	55.0554	2.9628
157.4467	54.9982	2.9710
157.4550	54.9382	2.9781
157.4633	54.8771	2.9831
157.4717	54.8137	2.9871
157.4800	54.7494	2.9899
157.4883	54.6830	2.9898
157.4967	54.6157	2.9886
157.5050	54.5457	2.9852
157.5133	54.4747	2.9813
157.5217	54.4017	2.9749
157.5300	54.3260	2.9665
157.5383	54.2488	2.9562
157.5467	54.1708	2.9442
157.5550	54.0894	2.9319
157.5633	54.0079	2.9178
157.5717	53.9233	2.9013
157.5800	53.8385	2.8832
157.5883	53.7507	2.8629
157.5967	53.6608	2.8414
157.6050	53.5689	2.8185
157.6133	53.4774	2.7933
157.6217	53.3812	2.7681
157.6300	53.2839	2.7414
157.6383	53.1845	2.7133
157.6467	53.0854	2.6840
157.6550	52.9834	2.6541
157.6633	52.8800	2.6230
157.6717	52.7750	2.5909
157.6800	52.6682	2.5584
157.6883	52.5594	2.5255
157.6967	52.4495	2.4908
157.7050	52.3400	2.4564
157.7133	52.2299	2.4212
157.7217	52.1170	2.3859
157.7300	52.0024	2.3508
157.7383	51.8877	2.3145
157.7467	51.7726	2.2792
157.7550	51.6546	2.2433
157.7633	51.5371	2.2071
157.7717	51.4202	2.1728
157.7800	51.3017	2.1403
157.7883	51.1830	2.1047
157.7967	51.0643	2.0686
157.8050	50.9441	2.0334
157.8133	50.8244	1.9985
157.8217	50.7041	1.9635
157.8300	50.5834	1.9317
157.8383	50.4632	1.8999
157.8467	50.3432	1.8672
157.8550	50.2229	1.8354
157.8633	50.1029	1.8033
157.8717	49.9831	1.7729
157.8800	49.8623	1.7436
157.8883	49.7441	1.7156
157.8967	49.6236	1.6874
157.9050	49.5047	1.6588
157.9133	49.3863	1.6307
157.9217	49.2690	1.6042
157.9300	49.1510	1.5779
157.9383	49.0327	1.5475
157.9467	48.9168	1.5179
157.9550	48.7987	1.4885
157.9633	48.6806	1.4603
157.9717	48.5648	1.4336
157.9800	48.4479	1.4080
157.9883	48.3311	1.3830
157.9967	48.2150	1.3586
158.0050	48.0992	1.3343
158.0133	47.9850	1.3115
158.0217	47.8697	1.2893
158.0300	47.7559	1.2674
158.0383	47.6422	1.2454
158.0467	47.5294	1.2240
158.0550	47.4186	1.2041
158.0633	47.3071	1.1840
158.0717	47.1950	1.1645
158.0800	47.0849	1.1456
158.0883	46.9750	1.1274
158.0967	46.8647	1.1090
158.1050	46.7568	1.0905
158.1133	46.6471	1.0738
158.1217	46.5405	1.0576
158.1300	46.4334	1.0406
158.1383	46.3275	1.0252
158.1467	46.2202	1.0109
158.1550	46.1143	0.9961
158.1633	46.0106	0.9831
158.1717	45.9066	0.9694
158.1800	45.8026	0.9564
158.1883	45.6985	0.9442
158.1967	45.5960	0.9310
158.2050	45.4946	0.9201
158.2133	45.3933	0.9076
158.2217	45.2921	0.8962
158.2300	45.1922	0.8857
158.2383	45.0911	0.8747
158.2467	44.9911	0.8644
158.2550	44.8922	0.8548
158.2633	44.7932	0.8453
158.2717	44.6959	0.8364
158.2800	44.5977	0.8274
158.2883	44.5003	0.8190
158.2967	44.4035	0.8110
158.3050	44.3077	0.8038
158.3133	44.2115	0.7959
158.3217	44.1164	0.7894
158.3300	44.0212	0.7833
158.3383	43.9262	0.7767
158.3467	43.8332	0.7702
158.3550	43.7386	0.7640
158.3633	43.6458	0.7586
158.3717	43.5521	0.7536
158.3800	43.4586	0.7468
158.3883	43.3662	0.7410
158.3967	43.2753
158.4050	43.1837
158.4133	43.0913
158.4217	42.9995
158.4300	42.9092
158.4383	42.8167
158.4467