File: Example Date/My Sample/DSC/test01/DSC TA/YN039 -150-150.txt
Filename	YN039 -150-150
Instrument name	DSC2A-01799 (192.168.1.250)
Operator
rundate	09/12/2024
Sample name	YN039 -150-150
proceduresegments	Ramp 10.00 °C/min to 150.0000 °C; Isothermal 3.0 min; Ramp 10.00 °C/min to -150.0000 °C; Isothermal 3.0 min; Ramp 10.00 °C/min to 150.0000 °C; Isothermal 3.0 min; Ramp 10.00 °C/min to -150.0000 °C; Isothermal 3.0 min; Ramp 10.00 °C/min to 150.0000 °C; Isothermal 3.0 min; Ramp 10.00 °C/min to 40.0000 °C
[File Parameters]
Run Date	09/12/2024 14:23:16
Trios version	5.7.0.56
Original File Name	C:\Users\TA Instruments DSC\Desktop\Data\Yutong Niu\YN039 -150-150.tri
Current File Name	C:\Users\TA Instruments DSC\Desktop\Data\Yutong Niu\YN039 -150-150.tri
User at run start	DESKTOP-CFGN8IT\TA Instruments DSC
[Procedure]
Procedure Name	polyether
Sample Name	YN039 -150-150
Sample Mass	8.5 mg
Reference Sample Mass	0 mg
Pan Mass	61.69 mg
Pan Number	25
Reference Pan Mass	60.81 mg
Reference Pan Number	45
Pan Type	Tzero Aluminum Pin Hole Hermetic
Comments
Project Name
Operator
Test	Custom
Unload Max Temperature	25
Unload Min Temperature	25
FillCooler	Do not fill
Load Max Temperature	25
Load Min Temperature	25
Discard pan in waste bin at end of test	Yes
Stop on Gas Flow Error	No
[Signal List]
Signal #1	Time (min)
Signal #2	Temperature (°C)
Signal #3	Heat Flow (mW)
Signal #4	Delta T (µV)
Signal #5	Delta Tzero (µV)
Signal #6	Tzero Temperature (°C)
Signal #7	Cell Purge (mL/min)
Signal #8	Heater Temp (°C)
Signal #9	Power Delivered (W)
Signal #10	Reference Junction Temperature (°C)
Signal #11	Flange Temperature (°C)
Signal #12	Heat Flow Phase (rad)
Signal #13	Total Heat Capacity (J/°C)
Signal #14	Heat Capacity (J/°C)
Signal #15	LN Pump Tank level (%)
[Configuration]
Company Name	Warwick University
Instrument Name	DSC2A-01799
Instrument Type	DSC2500
Serial Number	DSC2A-01799
IP	192.168.1.250
Location of Instrument	Polymer RTP
DisplayType	TianmaV2andV3
Sample Interval 	0.1 s/pt
Selected Heat Flow	T4P
Exotherm Direction	Up
Cell Serial	DRC2-03788
Lid Type	High Temperature
Cooler	LN Pump
Leave Cooler on at End of Sequence	Off
Gas 2	Air
Gas Selected	Channel 1: Nitrogen
Flow Rate	50 mL/min
Secondary Purge	On
Licensed Heat Flow	Heat Flow T4P
Modulation Licensed	Yes
[Versions]
Common IDD Version	1
Cortex Version	VER 2.11.0.729
Driver	5.0.0.6
GDM Version	1.0.3.3
TouchscreenVersion	1.0.3.1841
FEP Version	1.2.1.21
FEP Bootloader	2.0.0.5
AutoSampler Version	2.1.2.1
Auto Sampler Bootloader	2.0.0.5
FCM Version	1.1.0.3
FCM Bootloader	2.0.0.5
LN Pump Version	10.17.0.0
LN Pump Bootloader	2.0.0.5
[Experiment Logs]
Experiment Log Entry # 1	Ramp Segment 10 C/min to 150 Started
Experiment Log Entry # 3	Isothermal Segment 3 min started
Experiment Log Entry # 5	Ramp Segment 10 C/min to -150 Started
Experiment Log Entry # 7	Isothermal Segment 3 min started
Experiment Log Entry # 9	Ramp Segment 10 C/min to 150 Started
Experiment Log Entry # 11	Isothermal Segment 3 min started
Experiment Log Entry # 13	Ramp Segment 10 C/min to -150 Started
Experiment Log Entry # 15	Isothermal Segment 3 min started
Experiment Log Entry # 17	Ramp Segment 10 C/min to 150 Started
Experiment Log Entry # 19	Isothermal Segment 3 min started
Experiment Log Entry # 21	Ramp Segment 10 C/min to 40 Started
[Method Log]
Method Log Entry # 1	(Ramp 516991) Ramp 10 °C/minute to 150 °C
Method Log Entry # 2	Isothermal 3 minutes
Method Log Entry # 3	(Ramp 516993) Ramp 10 °C/minute to -150 °C
Method Log Entry # 4	Isothermal 3 minutes
Method Log Entry # 5	(Ramp 516995) Ramp 10 °C/minute to 150 °C
Method Log Entry # 6	Isothermal 3 minutes
Method Log Entry # 7	(Ramp 516997) Ramp 10 °C/minute to -150 °C
Method Log Entry # 8	Isothermal 3 minutes
Method Log Entry # 9	(Ramp 516999) Ramp 10 °C/minute to 150 °C
Method Log Entry # 10	Isothermal 3 minutes
Method Log Entry # 11	(Ramp 517001) Ramp 10 °C/minute to 40 °C
Cell Serial	DRC2-03788
[T1 Calibration]
Date Applied	04/03/2021 14:58:04
Description
Gas Type	Nitrogen
Pan Type	None
Slope	-0.001800291
Offset	-0.1301359
Initial Temperature	-100.6228
GUID	a1d5a6be-decd-4ae4-b22f-d560f3a78a92
[TZero Calibration]
Date Applied	21/08/2024 09:53:38
Description	From -180.022 °C to 395.167 °C at 20.000°C/min
Gas Type	Nitrogen
Pan Type	None
Source Files 1	C:\ProgramData\TA Instruments\TRIOS\Data\TAService\PMV 20Aug2024\Tzero Cal.tri
Source Files 2	C:\ProgramData\TA Instruments\TRIOS\Data\TAService\PMV 20Aug2024\Tzero Cal sapphire.tri
Delta T Offset	1.787969
Delta T Slope	-0.003527276
Delta T0 Offset	0.06831977
Delta T0 Slope	0.02007191
[Temperature Calibration]
Date Applied	21/08/2024 11:06:35
Description	From 106.660 °C to 186.660 °C at 10.000°C/min
Gas Type	Nitrogen
Pan Type	Tzero Aluminum
Source Files 1	C:\ProgramData\TA Instruments\TRIOS\Data\TAService\PMV 20Aug2024\TA Indium cal.tri
Measured 1	157.9141
Known 1	156.66
[Cell Constant Calibration]
Date Applied	21/08/2024 11:06:35
Description	From 106.660 °C to 186.660 °C at 10.000°C/min
Gas Type	Nitrogen
Pan Type	Tzero Aluminum
Source Files 1	C:\ProgramData\TA Instruments\TRIOS\Data\TAService\PMV 20Aug2024\TA Indium cal.tri
T4P KCell	1.038055
Onset Slope	-66.72884 mW/°C
[Direct Cp Calibration]
Date Applied	19/11/2024 16:37:27
Description	From -89.996 °C to 396.697 °C at 20.000°C/min
Gas Type	Nitrogen
Pan Type	Tzero Aluminum
Source Files 1	C:\ProgramData\TA Instruments\TRIOS\Data\Sapphire Direct Heat Capacity(8).tri
GUID	544f8371-fe9b-4f4f-81ca-7980c172113e
Temperature	-89.99625 °C
Cp	1.464367
Temperature	-89.02287 °C
Cp	1.460558
Temperature	-88.04948 °C
Cp	1.456263
Temperature	-87.0761 °C
Cp	1.451626
Temperature	-86.10271 °C
Cp	1.446737
Temperature	-85.12933 °C
Cp	1.441723
Temperature	-84.15594 °C
Cp	1.436654
Temperature	-83.18256 °C
Cp	1.431684
Temperature	-82.20917 °C
Cp	1.426935
Temperature	-81.23578 °C
Cp	1.422396
Temperature	-80.2624 °C
Cp	1.418192
Temperature	-79.28901 °C
Cp	1.414363
Temperature	-78.31562 °C
Cp	1.410925
Temperature	-77.34224 °C
Cp	1.407865
Temperature	-76.36885 °C
Cp	1.405143
Temperature	-75.39546 °C
Cp	1.402789
Temperature	-74.42208 °C
Cp	1.400703
Temperature	-73.44869 °C
Cp	1.398837
Temperature	-72.4753 °C
Cp	1.397142
Temperature	-71.50192 °C
Cp	1.395565
Temperature	-70.52853 °C
Cp	1.394053
Temperature	-69.55515 °C
Cp	1.392558
Temperature	-68.58176 °C
Cp	1.391036
Temperature	-67.60838 °C
Cp	1.389483
Temperature	-66.63499 °C
Cp	1.387847
Temperature	-65.66161 °C
Cp	1.38616
Temperature	-64.68822 °C
Cp	1.384397
Temperature	-63.71483 °C
Cp	1.382535
Temperature	-62.74145 °C
Cp	1.380598
Temperature	-61.76806 °C
Cp	1.37865
Temperature	-60.79467 °C
Cp	1.376673
Temperature	-59.82129 °C
Cp	1.374677
Temperature	-58.8479 °C
Cp	1.372642
Temperature	-57.87452 °C
Cp	1.370686
Temperature	-56.90113 °C
Cp	1.368741
Temperature	-55.92775 °C
Cp	1.366786
Temperature	-54.95436 °C
Cp	1.364863
Temperature	-53.98097 °C
Cp	1.362959
Temperature	-53.00759 °C
Cp	1.361116
Temperature	-52.0342 °C
Cp	1.359247
Temperature	-51.06082 °C
Cp	1.357393
Temperature	-50.08743 °C
Cp	1.355593
Temperature	-49.11404 °C
Cp	1.353796
Temperature	-48.14066 °C
Cp	1.352008
Temperature	-47.16727 °C
Cp	1.350215
Temperature	-46.19389 °C
Cp	1.348396
Temperature	-45.2205 °C
Cp	1.346593
Temperature	-44.24712 °C
Cp	1.344755
Temperature	-43.27373 °C
Cp	1.342891
Temperature	-42.30034 °C
Cp	1.341008
Temperature	-41.32696 °C
Cp	1.339126
Temperature	-40.35357 °C
Cp	1.337236
Temperature	-39.38018 °C
Cp	1.335367
Temperature	-38.4068 °C
Cp	1.333522
Temperature	-37.43341 °C
Cp	1.331708
Temperature	-36.46003 °C
Cp	1.32991
Temperature	-35.48664 °C
Cp	1.328145
Temperature	-34.51326 °C
Cp	1.326414
Temperature	-33.53987 °C
Cp	1.32471
Temperature	-32.56648 °C
Cp	1.323012
Temperature	-31.5931 °C
Cp	1.321323
Temperature	-30.61971 °C
Cp	1.319657
Temperature	-29.64633 °C
Cp	1.317968
Temperature	-28.67294 °C
Cp	1.316286
Temperature	-27.69955 °C
Cp	1.314585
Temperature	-26.72617 °C
Cp	1.312857
Temperature	-25.75278 °C
Cp	1.31111
Temperature	-24.7794 °C
Cp	1.309333
Temperature	-23.80601 °C
Cp	1.307544
Temperature	-22.83262 °C
Cp	1.30575
Temperature	-21.85924 °C
Cp	1.303941
Temperature	-20.88585 °C
Cp	1.302132
Temperature	-19.91247 °C
Cp	1.300313
Temperature	-18.93908 °C
Cp	1.298512
Temperature	-17.96569 °C
Cp	1.296728
Temperature	-16.99231 °C
Cp	1.294939
Temperature	-16.01892 °C
Cp	1.293198
Temperature	-15.04554 °C
Cp	1.291453
Temperature	-14.07215 °C
Cp	1.289723
Temperature	-13.09876 °C
Cp	1.288007
Temperature	-12.12538 °C
Cp	1.286283
Temperature	-11.15199 °C
Cp	1.284578
Temperature	-10.17861 °C
Cp	1.282885
Temperature	-9.205221 °C
Cp	1.281173
Temperature	-8.231835 °C
Cp	1.279472
Temperature	-7.258449 °C
Cp	1.277766
Temperature	-6.285063 °C
Cp	1.276053
Temperature	-5.311677 °C
Cp	1.274341
Temperature	-4.338291 °C
Cp	1.272592
Temperature	-3.364905 °C
Cp	1.270844
Temperature	-2.391519 °C
Cp	1.269062
Temperature	-1.418133 °C
Cp	1.267264
Temperature	-0.4447474 °C
Cp	1.265435
Temperature	0.5286385 °C
Cp	1.263575
Temperature	1.502024 °C
Cp	1.261727
Temperature	2.47541 °C
Cp	1.259854
Temperature	3.448796 °C
Cp	1.257978
Temperature	4.422182 °C
Cp	1.256109
Temperature	5.395568 °C
Cp	1.254244
Temperature	6.368954 °C
Cp	1.252392
Temperature	7.34234 °C
Cp	1.250552
Temperature	8.315726 °C
Cp	1.248704
Temperature	9.289112 °C
Cp	1.246884
Temperature	10.2625 °C
Cp	1.245078
Temperature	11.23588 °C
Cp	1.243287
Temperature	12.20927 °C
Cp	1.241522
Temperature	13.18266 °C
Cp	1.239778
Temperature	14.15604 °C
Cp	1.238068
Temperature	15.12943 °C
Cp	1.236393
Temperature	16.10281 °C
Cp	1.234762
Temperature	17.0762 °C
Cp	1.233176
Temperature	18.04959 °C
Cp	1.231629
Temperature	19.02297 °C
Cp	1.230129
Temperature	19.99636 °C
Cp	1.228694
Temperature	20.96974 °C
Cp	1.22731
Temperature	21.94313 °C
Cp	1.225968
Temperature	22.91652 °C
Cp	1.224676
Temperature	23.8899 °C
Cp	1.223431
Temperature	24.86329 °C
Cp	1.222217
Temperature	25.83667 °C
Cp	1.221065
Temperature	26.81006 °C
Cp	1.219919
Temperature	27.78345 °C
Cp	1.218811
Temperature	28.75683 °C
Cp	1.21773
Temperature	29.73022 °C
Cp	1.216663
Temperature	30.7036 °C
Cp	1.2156
Temperature	31.67699 °C
Cp	1.214515
Temperature	32.65038 °C
Cp	1.213439
Temperature	33.62376 °C
Cp	1.21234
Temperature	34.59715 °C
Cp	1.211209
Temperature	35.57053 °C
Cp	1.210051
Temperature	36.54392 °C
Cp	1.208868
Temperature	37.5173 °C
Cp	1.207666
Temperature	38.49069 °C
Cp	1.206439
Temperature	39.46408 °C
Cp	1.205199
Temperature	40.43746 °C
Cp	1.203959
Temperature	41.41085 °C
Cp	1.202712
Temperature	42.38424 °C
Cp	1.20147
Temperature	43.35762 °C
Cp	1.200231
Temperature	44.33101 °C
Cp	1.199
Temperature	45.30439 °C
Cp	1.197777
Temperature	46.27778 °C
Cp	1.19657
Temperature	47.25116 °C
Cp	1.195367
Temperature	48.22455 °C
Cp	1.194179
Temperature	49.19794 °C
Cp	1.19301
Temperature	50.17132 °C
Cp	1.191849
Temperature	51.14471 °C
Cp	1.190694
Temperature	52.11809 °C
Cp	1.189555
Temperature	53.09148 °C
Cp	1.18843
Temperature	54.06487 °C
Cp	1.187311
Temperature	55.03825 °C
Cp	1.186195
Temperature	56.01164 °C
Cp	1.185095
Temperature	56.98502 °C
Cp	1.183997
Temperature	57.95841 °C
Cp	1.182894
Temperature	58.93179 °C
Cp	1.181793
Temperature	59.90518 °C
Cp	1.180693
Temperature	60.87857 °C
Cp	1.179595
Temperature	61.85195 °C
Cp	1.178501
Temperature	62.82534 °C
Cp	1.177406
Temperature	63.79873 °C
Cp	1.176313
Temperature	64.77211 °C
Cp	1.175239
Temperature	65.7455 °C
Cp	1.17417
Temperature	66.71888 °C
Cp	1.173105
Temperature	67.69227 °C
Cp	1.172037
Temperature	68.66566 °C
Cp	1.170989
Temperature	69.63904 °C
Cp	1.169948
Temperature	70.61243 °C
Cp	1.168905
Temperature	71.58582 °C
Cp	1.167872
Temperature	72.5592 °C
Cp	1.166849
Temperature	73.53259 °C
Cp	1.165851
Temperature	74.50597 °C
Cp	1.164848
Temperature	75.47935 °C
Cp	1.163876
Temperature	76.45274 °C
Cp	1.162926
Temperature	77.42612 °C
Cp	1.162008
Temperature	78.39951 °C
Cp	1.161113
Temperature	79.3729 °C
Cp	1.160219
Temperature	80.34628 °C
Cp	1.159377
Temperature	81.31967 °C
Cp	1.158546
Temperature	82.29306 °C
Cp	1.157726
Temperature	83.26644 °C
Cp	1.15692
Temperature	84.23983 °C
Cp	1.156126
Temperature	85.21322 °C
Cp	1.155375
Temperature	86.1866 °C
Cp	1.154604
Temperature	87.15999 °C
Cp	1.153869
Temperature	88.13337 °C
Cp	1.153158
Temperature	89.10676 °C
Cp	1.152474
Temperature	90.08015 °C
Cp	1.15181
Temperature	91.05353 °C
Cp	1.151134
Temperature	92.02692 °C
Cp	1.150513
Temperature	93.00031 °C
Cp	1.149892
Temperature	93.97369 °C
Cp	1.149266
Temperature	94.94707 °C
Cp	1.148642
Temperature	95.92046 °C
Cp	1.148019
Temperature	96.89384 °C
Cp	1.147402
Temperature	97.86723 °C
Cp	1.146799
Temperature	98.84062 °C
Cp	1.146191
Temperature	99.814 °C
Cp	1.145602
Temperature	100.7874 °C
Cp	1.14503
Temperature	101.7608 °C
Cp	1.144469
Temperature	102.7342 °C
Cp	1.143921
Temperature	103.7076 °C
Cp	1.143383
Temperature	104.6809 °C
Cp	1.142861
Temperature	105.6543 °C
Cp	1.142345
Temperature	106.6277 °C
Cp	1.141835
Temperature	107.6011 °C
Cp	1.141335
Temperature	108.5745 °C
Cp	1.140846
Temperature	109.5479 °C
Cp	1.140365
Temperature	110.5212 °C
Cp	1.139891
Temperature	111.4946 °C
Cp	1.139429
Temperature	112.468 °C
Cp	1.138976
Temperature	113.4414 °C
Cp	1.13853
Temperature	114.4148 °C
Cp	1.138092
Temperature	115.3882 °C
Cp	1.137654
Temperature	116.3616 °C
Cp	1.137223
Temperature	117.335 °C
Cp	1.136785
Temperature	118.3083 °C
Cp	1.136338
Temperature	119.2817 °C
Cp	1.13588
Temperature	120.2551 °C
Cp	1.13541
Temperature	121.2285 °C
Cp	1.134927
Temperature	122.2019 °C
Cp	1.134417
Temperature	123.1753 °C
Cp	1.133892
Temperature	124.1487 °C
Cp	1.133347
Temperature	125.122 °C
Cp	1.132786
Temperature	126.0954 °C
Cp	1.132206
Temperature	127.0688 °C
Cp	1.131606
Temperature	128.0422 °C
Cp	1.130999
Temperature	129.0156 °C
Cp	1.130384
Temperature	129.989 °C
Cp	1.129765
Temperature	130.9624 °C
Cp	1.129147
Temperature	131.9357 °C
Cp	1.12854
Temperature	132.9091 °C
Cp	1.127949
Temperature	133.8825 °C
Cp	1.127383
Temperature	134.8559 °C
Cp	1.126841
Temperature	135.8293 °C
Cp	1.126334
Temperature	136.8027 °C
Cp	1.125871
Temperature	137.7761 °C
Cp	1.125443
Temperature	138.7494 °C
Cp	1.125058
Temperature	139.7228 °C
Cp	1.124701
Temperature	140.6962 °C
Cp	1.124397
Temperature	141.6696 °C
Cp	1.124114
Temperature	142.643 °C
Cp	1.123854
Temperature	143.6164 °C
Cp	1.123612
Temperature	144.5898 °C
Cp	1.123385
Temperature	145.5631 °C
Cp	1.123182
Temperature	146.5365 °C
Cp	1.12296
Temperature	147.5099 °C
Cp	1.12275
Temperature	148.4833 °C
Cp	1.122543
Temperature	149.4567 °C
Cp	1.122327
Temperature	150.4301 °C
Cp	1.122099
Temperature	151.4035 °C
Cp	1.121837
Temperature	152.3768 °C
Cp	1.121582
Temperature	153.3502 °C
Cp	1.121289
Temperature	154.3236 °C
Cp	1.120967
Temperature	155.297 °C
Cp	1.120616
Temperature	156.2704 °C
Cp	1.120238
Temperature	157.2438 °C
Cp	1.119862
Temperature	158.2172 °C
Cp	1.119444
Temperature	159.1906 °C
Cp	1.119028
Temperature	160.1639 °C
Cp	1.118613
Temperature	161.1373 °C
Cp	1.118202
Temperature	162.1107 °C
Cp	1.117795
Temperature	163.0841 °C
Cp	1.117374
Temperature	164.0575 °C
Cp	1.116987
Temperature	165.0309 °C
Cp	1.116595
Temperature	166.0042 °C
Cp	1.116198
Temperature	166.9776 °C
Cp	1.1158
Temperature	167.951 °C
Cp	1.115402
Temperature	168.9244 °C
Cp	1.115006
Temperature	169.8978 °C
Cp	1.11462
Temperature	170.8712 °C
Cp	1.114223
Temperature	171.8446 °C
Cp	1.113836
Temperature	172.8179 °C
Cp	1.113458
Temperature	173.7913 °C
Cp	1.113085
Temperature	174.7647 °C
Cp	1.112712
Temperature	175.7381 °C
Cp	1.112323
Temperature	176.7115 °C
Cp	1.111957
Temperature	177.6849 °C
Cp	1.111578
Temperature	178.6583 °C
Cp	1.111185
Temperature	179.6317 °C
Cp	1.110789
Temperature	180.605 °C
Cp	1.110391
Temperature	181.5784 °C
Cp	1.110016
Temperature	182.5518 °C
Cp	1.109611
Temperature	183.5252 °C
Cp	1.109232
Temperature	184.4986 °C
Cp	1.108873
Temperature	185.472 °C
Cp	1.108531
Temperature	186.4454 °C
Cp	1.108199
Temperature	187.4187 °C
Cp	1.107851
Temperature	188.3921 °C
Cp	1.107551
Temperature	189.3655 °C
Cp	1.107238
Temperature	190.3389 °C
Cp	1.106917
Temperature	191.3123 °C
Cp	1.106589
Temperature	192.2857 °C
Cp	1.106259
Temperature	193.259 °C
Cp	1.105958
Temperature	194.2324 °C
Cp	1.105619
Temperature	195.2058 °C
Cp	1.105301
Temperature	196.1792 °C
Cp	1.105002
Temperature	197.1526 °C
Cp	1.104718
Temperature	198.126 °C
Cp	1.104445
Temperature	199.0994 °C
Cp	1.104161
Temperature	200.0728 °C
Cp	1.103914
Temperature	201.0461 °C
Cp	1.103657
Temperature	202.0195 °C
Cp	1.103395
Temperature	202.9929 °C
Cp	1.103125
Temperature	203.9663 °C
Cp	1.102847
Temperature	204.9397 °C
Cp	1.102563
Temperature	205.9131 °C
Cp	1.102283
Temperature	206.8865 °C
Cp	1.101985
Temperature	207.8598 °C
Cp	1.10169
Temperature	208.8332 °C
Cp	1.101394
Temperature	209.8066 °C
Cp	1.101099
Temperature	210.78 °C
Cp	1.1008
Temperature	211.7534 °C
Cp	1.10049
Temperature	212.7268 °C
Cp	1.100193
Temperature	213.7002 °C
Cp	1.099886
Temperature	214.6735 °C
Cp	1.099577
Temperature	215.6469 °C
Cp	1.099268
Temperature	216.6203 °C
Cp	1.098965
Temperature	217.5937 °C
Cp	1.098685
Temperature	218.5671 °C
Cp	1.098396
Temperature	219.5405 °C
Cp	1.098134
Temperature	220.5139 °C
Cp	1.097895
Temperature	221.4872 °C
Cp	1.09768
Temperature	222.4606 °C
Cp	1.097485
Temperature	223.434 °C
Cp	1.097292
Temperature	224.4074 °C
Cp	1.09714
Temperature	225.3808 °C
Cp	1.096991
Temperature	226.3542 °C
Cp	1.096844
Temperature	227.3276 °C
Cp	1.096699
Temperature	228.3009 °C
Cp	1.096559
Temperature	229.2743 °C
Cp	1.096442
Temperature	230.2477 °C
Cp	1.096296
Temperature	231.2211 °C
Cp	1.096164
Temperature	232.1945 °C
Cp	1.09604
Temperature	233.1679 °C
Cp	1.095924
Temperature	234.1413 °C
Cp	1.095807
Temperature	235.1147 °C
Cp	1.095665
Temperature	236.088 °C
Cp	1.095557
Temperature	237.0614 °C
Cp	1.095433
Temperature	238.0348 °C
Cp	1.095296
Temperature	239.0082 °C
Cp	1.095147
Temperature	239.9816 °C
Cp	1.094995
Temperature	240.955 °C
Cp	1.094843
Temperature	241.9283 °C
Cp	1.094705
Temperature	242.9017 °C
Cp	1.094562
Temperature	243.8751 °C
Cp	1.094442
Temperature	244.8485 °C
Cp	1.094344
Temperature	245.8219 °C
Cp	1.094266
Temperature	246.7953 °C
Cp	1.094209
Temperature	247.7687 °C
Cp	1.094161
Temperature	248.7421 °C
Cp	1.094144
Temperature	249.7154 °C
Cp	1.094133
Temperature	250.6888 °C
Cp	1.094127
Temperature	251.6622 °C
Cp	1.094126
Temperature	252.6356 °C
Cp	1.094127
Temperature	253.609 °C
Cp	1.094138
Temperature	254.5824 °C
Cp	1.09413
Temperature	255.5558 °C
Cp	1.094123
Temperature	256.5291 °C
Cp	1.094111
Temperature	257.5025 °C
Cp	1.094087
Temperature	258.4759 °C
Cp	1.094046
Temperature	259.4493 °C
Cp	1.093978
Temperature	260.4227 °C
Cp	1.093895
Temperature	261.3961 °C
Cp	1.093783
Temperature	262.3694 °C
Cp	1.093645
Temperature	263.3428 °C
Cp	1.093483
Temperature	264.3162 °C
Cp	1.093302
Temperature	265.2896 °C
Cp	1.093109
Temperature	266.263 °C
Cp	1.092906
Temperature	267.2364 °C
Cp	1.092704
Temperature	268.2098 °C
Cp	1.092511
Temperature	269.1832 °C
Cp	1.092331
Temperature	270.1566 °C
Cp	1.092174
Temperature	271.1299 °C
Cp	1.092046
Temperature	272.1033 °C
Cp	1.091947
Temperature	273.0767 °C
Cp	1.091882
Temperature	274.0501 °C
Cp	1.091853
Temperature	275.0235 °C
Cp	1.091859
Temperature	275.9969 °C
Cp	1.091895
Temperature	276.9702 °C
Cp	1.091957
Temperature	277.9436 °C
Cp	1.092036
Temperature	278.917 °C
Cp	1.092132
Temperature	279.8904 °C
Cp	1.09223
Temperature	280.8638 °C
Cp	1.092323
Temperature	281.8372 °C
Cp	1.092405
Temperature	282.8105 °C
Cp	1.092468
Temperature	283.7839 °C
Cp	1.092513
Temperature	284.7573 °C
Cp	1.092525
Temperature	285.7307 °C
Cp	1.092512
Temperature	286.7041 °C
Cp	1.092472
Temperature	287.6775 °C
Cp	1.092405
Temperature	288.6509 °C
Cp	1.092313
Temperature	289.6243 °C
Cp	1.092197
Temperature	290.5977 °C
Cp	1.09207
Temperature	291.571 °C
Cp	1.091931
Temperature	292.5444 °C
Cp	1.091785
Temperature	293.5178 °C
Cp	1.091641
Temperature	294.4912 °C
Cp	1.091506
Temperature	295.4646 °C
Cp	1.091387
Temperature	296.438 °C
Cp	1.091282
Temperature	297.4113 °C
Cp	1.091201
Temperature	298.3847 °C
Cp	1.091145
Temperature	299.3581 °C
Cp	1.091112
Temperature	300.3315 °C
Cp	1.091102
Temperature	301.3049 °C
Cp	1.091107
Temperature	302.2783 °C
Cp	1.091137
Temperature	303.2517 °C
Cp	1.091177
Temperature	304.2251 °C
Cp	1.091226
Temperature	305.1984 °C
Cp	1.09128
Temperature	306.1718 °C
Cp	1.091336
Temperature	307.1452 °C
Cp	1.091403
Temperature	308.1186 °C
Cp	1.091453
Temperature	309.092 °C
Cp	1.091506
Temperature	310.0654 °C
Cp	1.091561
Temperature	311.0388 °C
Cp	1.091617
Temperature	312.0121 °C
Cp	1.09167
Temperature	312.9855 °C
Cp	1.091716
Temperature	313.9589 °C
Cp	1.091762
Temperature	314.9323 °C
Cp	1.091805
Temperature	315.9057 °C
Cp	1.091838
Temperature	316.8791 °C
Cp	1.09186
Temperature	317.8524 °C
Cp	1.091871
Temperature	318.8258 °C
Cp	1.091872
Temperature	319.7992 °C
Cp	1.091867
Temperature	320.7726 °C
Cp	1.091838
Temperature	321.746 °C
Cp	1.0918
Temperature	322.7194 °C
Cp	1.091752
Temperature	323.6928 °C
Cp	1.091689
Temperature	324.6662 °C
Cp	1.091611
Temperature	325.6396 °C
Cp	1.091508
Temperature	326.6129 °C
Cp	1.091406
Temperature	327.5863 °C
Cp	1.091285
Temperature	328.5597 °C
Cp	1.09115
Temperature	329.5331 °C
Cp	1.091009
Temperature	330.5065 °C
Cp	1.09087
Temperature	331.4799 °C
Cp	1.090747
Temperature	332.4532 °C
Cp	1.090628
Temperature	333.4266 °C
Cp	1.090536
Temperature	334.4 °C
Cp	1.090472
Temperature	335.3734 °C
Cp	1.090437
Temperature	336.3468 °C
Cp	1.090431
Temperature	337.3202 °C
Cp	1.090455
Temperature	338.2935 °C
Cp	1.090503
Temperature	339.2669 °C
Cp	1.090573
Temperature	340.2403 °C
Cp	1.090658
Temperature	341.2137 °C
Cp	1.090753
Temperature	342.1871 °C
Cp	1.090853
Temperature	343.1605 °C
Cp	1.090952
Temperature	344.1339 °C
Cp	1.09105
Temperature	345.1073 °C
Cp	1.091141
Temperature	346.0807 °C
Cp	1.091225
Temperature	347.054 °C
Cp	1.091303
Temperature	348.0274 °C
Cp	1.091379
Temperature	349.0008 °C
Cp	1.091453
Temperature	349.9742 °C
Cp	1.091537
Temperature	350.9476 °C
Cp	1.091633
Temperature	351.921 °C
Cp	1.091743
Temperature	352.8943 °C
Cp	1.091874
Temperature	353.8677 °C
Cp	1.092028
Temperature	354.8411 °C
Cp	1.092206
Temperature	355.8145 °C
Cp	1.092411
Temperature	356.7879 °C
Cp	1.092628
Temperature	357.7613 °C
Cp	1.092862
Temperature	358.7346 °C
Cp	1.093102
Temperature	359.708 °C
Cp	1.093338
Temperature	360.6814 °C
Cp	1.093559
Temperature	361.6548 °C
Cp	1.093752
Temperature	362.6282 °C
Cp	1.093915
Temperature	363.6016 °C
Cp	1.094036
Temperature	364.575 °C
Cp	1.094117
Temperature	365.5484 °C
Cp	1.094159
Temperature	366.5218 °C
Cp	1.094172
Temperature	367.4951 °C
Cp	1.094165
Temperature	368.4685 °C
Cp	1.094163
Temperature	369.4419 °C
Cp	1.094182
Temperature	370.4153 °C
Cp	1.094244
Temperature	371.3887 °C
Cp	1.094375
Temperature	372.3621 °C
Cp	1.094598
Temperature	373.3354 °C
Cp	1.094937
Temperature	374.3088 °C
Cp	1.095389
Temperature	375.2822 °C
Cp	1.095973
Temperature	376.2556 °C
Cp	1.096685
Temperature	377.229 °C
Cp	1.097506
Temperature	378.2024 °C
Cp	1.098406
Temperature	379.1758 °C
Cp	1.099338
Temperature	380.1492 °C
Cp	1.10027
Temperature	381.1225 °C
Cp	1.10112
Temperature	382.0959 °C
Cp	1.101818
Temperature	383.0693 °C
Cp	1.10229
Temperature	384.0427 °C
Cp	1.102459
Temperature	385.0161 °C
Cp	1.102253
Temperature	385.9895 °C
Cp	1.101596
Temperature	386.9629 °C
Cp	1.100438
Temperature	387.9362 °C
Cp	1.098736
Temperature	388.9096 °C
Cp	1.096461
Temperature	389.883 °C
Cp	1.093614
Temperature	390.8564 °C
Cp	1.090208
Temperature	391.8298 °C
Cp	1.086278
Temperature	392.8032 °C
Cp	1.081887
Temperature	393.7766 °C
Cp	1.077096
Temperature	394.7499 °C
Cp	1.072007
Temperature	395.7233 °C
Cp	1.066707
[Rev Cp Calibration]
Date Applied	24/10/2024 12:37:31
Description	From -89.998 °C to 390.542 °C at 2.000°C/min
Gas Type	Nitrogen
Pan Type	Tzero Aluminum
Source Files 1	C:\ProgramData\TA Instruments\TRIOS\Data\Reverse Heat Capacity Calibration(6).tri
GUID	ba867d72-cfbb-486e-971e-e86aa544cc02
Temperature	-89.99799 °C
Cp	1.070076
Temperature	-89.03691 °C
Cp	1.072008
Temperature	-88.07584 °C
Cp	1.073556
Temperature	-87.11475 °C
Cp	1.074743
Temperature	-86.15367 °C
Cp	1.075597
Temperature	-85.1926 °C
Cp	1.076163
Temperature	-84.23151 °C
Cp	1.076477
Temperature	-83.27043 °C
Cp	1.076579
Temperature	-82.30936 °C
Cp	1.076527
Temperature	-81.34827 °C
Cp	1.076322
Temperature	-80.38719 °C
Cp	1.076039
Temperature	-79.42612 °C
Cp	1.07571
Temperature	-78.46503 °C
Cp	1.075361
Temperature	-77.50395 °C
Cp	1.075011
Temperature	-76.54288 °C
Cp	1.074656
Temperature	-75.58179 °C
Cp	1.074359
Temperature	-74.62071 °C
Cp	1.074086
Temperature	-73.65964 °C
Cp	1.073842
Temperature	-72.69855 °C
Cp	1.073627
Temperature	-71.73747 °C
Cp	1.073442
Temperature	-70.7764 °C
Cp	1.07329
Temperature	-69.81532 °C
Cp	1.073148
Temperature	-68.85423 °C
Cp	1.073021
Temperature	-67.89315 °C
Cp	1.072902
Temperature	-66.93208 °C
Cp	1.072782
Temperature	-65.97099 °C
Cp	1.072656
Temperature	-65.00991 °C
Cp	1.072518
Temperature	-64.04884 °C
Cp	1.072374
Temperature	-63.08775 °C
Cp	1.072201
Temperature	-62.12667 °C
Cp	1.072019
Temperature	-61.1656 °C
Cp	1.071827
Temperature	-60.20451 °C
Cp	1.071624
Temperature	-59.24343 °C
Cp	1.071411
Temperature	-58.28236 °C
Cp	1.071167
Temperature	-57.32127 °C
Cp	1.070956
Temperature	-56.3602 °C
Cp	1.070724
Temperature	-55.39911 °C
Cp	1.070483
Temperature	-54.43803 °C
Cp	1.070242
Temperature	-53.47696 °C
Cp	1.070009
Temperature	-52.51587 °C
Cp	1.069825
Temperature	-51.55479 °C
Cp	1.069601
Temperature	-50.59372 °C
Cp	1.069418
Temperature	-49.63263 °C
Cp	1.069267
Temperature	-48.67155 °C
Cp	1.069138
Temperature	-47.71048 °C
Cp	1.069021
Temperature	-46.74939 °C
Cp	1.068875
Temperature	-45.78831 °C
Cp	1.068771
Temperature	-44.82724 °C
Cp	1.068634
Temperature	-43.86615 °C
Cp	1.068462
Temperature	-42.90508 °C
Cp	1.068255
Temperature	-41.944 °C
Cp	1.068012
Temperature	-40.98291 °C
Cp	1.067742
Temperature	-40.02184 °C
Cp	1.067427
Temperature	-39.06076 °C
Cp	1.067088
Temperature	-38.09967 °C
Cp	1.066727
Temperature	-37.1386 °C
Cp	1.066349
Temperature	-36.17752 °C
Cp	1.065958
Temperature	-35.21643 °C
Cp	1.065559
Temperature	-34.25536 °C
Cp	1.065162
Temperature	-33.29427 °C
Cp	1.06476
Temperature	-32.33319 °C
Cp	1.064368
Temperature	-31.37212 °C
Cp	1.06399
Temperature	-30.41104 °C
Cp	1.063628
Temperature	-29.44995 °C
Cp	1.063283
Temperature	-28.48887 °C
Cp	1.06295
Temperature	-27.5278 °C
Cp	1.062645
Temperature	-26.56672 °C
Cp	1.062355
Temperature	-25.60563 °C
Cp	1.06208
Temperature	-24.64456 °C
Cp	1.061819
Temperature	-23.68348 °C
Cp	1.061573
Temperature	-22.72239 °C
Cp	1.061345
Temperature	-21.76132 °C
Cp	1.061123
Temperature	-20.80024 °C
Cp	1.060915
Temperature	-19.83916 °C
Cp	1.060719
Temperature	-18.87807 °C
Cp	1.060531
Temperature	-17.917 °C
Cp	1.06035
Temperature	-16.95592 °C
Cp	1.060161
Temperature	-15.99484 °C
Cp	1.059992
Temperature	-15.03376 °C
Cp	1.059817
Temperature	-14.07268 °C
Cp	1.059634
Temperature	-13.1116 °C
Cp	1.059445
Temperature	-12.15052 °C
Cp	1.059248
Temperature	-11.18944 °C
Cp	1.059043
Temperature	-10.22836 °C
Cp	1.058842
Temperature	-9.267276 °C
Cp	1.058615
Temperature	-8.306196 °C
Cp	1.058388
Temperature	-7.345116 °C
Cp	1.058155
Temperature	-6.384036 °C
Cp	1.057911
Temperature	-5.422956 °C
Cp	1.057652
Temperature	-4.461876 °C
Cp	1.057356
Temperature	-3.500796 °C
Cp	1.057063
Temperature	-2.539716 °C
Cp	1.056732
Temperature	-1.578636 °C
Cp	1.056364
Temperature	-0.6175562 °C
Cp	1.05596
Temperature	0.3435238 °C
Cp	1.055523
Temperature	1.304604 °C
Cp	1.055066
Temperature	2.265684 °C
Cp	1.054561
Temperature	3.226764 °C
Cp	1.054035
Temperature	4.187844 °C
Cp	1.053488
Temperature	5.148924 °C
Cp	1.052922
Temperature	6.110003 °C
Cp	1.052337
Temperature	7.071084 °C
Cp	1.051736
Temperature	8.032164 °C
Cp	1.051118
Temperature	8.993243 °C
Cp	1.050488
Temperature	9.954324 °C
Cp	1.049848
Temperature	10.9154 °C
Cp	1.049202
Temperature	11.87648 °C
Cp	1.048552
Temperature	12.83756 °C
Cp	1.047902
Temperature	13.79864 °C
Cp	1.047255
Temperature	14.75972 °C
Cp	1.046615
Temperature	15.7208 °C
Cp	1.045983
Temperature	16.68188 °C
Cp	1.045362
Temperature	17.64296 °C
Cp	1.044756
Temperature	18.60404 °C
Cp	1.044164
Temperature	19.56512 °C
Cp	1.04358
Temperature	20.5262 °C
Cp	1.043027
Temperature	21.48728 °C
Cp	1.042485
Temperature	22.44836 °C
Cp	1.041958
Temperature	23.40944 °C
Cp	1.041446
Temperature	24.37052 °C
Cp	1.040952
Temperature	25.3316 °C
Cp	1.040493
Temperature	26.29268 °C
Cp	1.040022
Temperature	27.25376 °C
Cp	1.039578
Temperature	28.21484 °C
Cp	1.039158
Temperature	29.17592 °C
Cp	1.038758
Temperature	30.137 °C
Cp	1.038373
Temperature	31.09808 °C
Cp	1.037981
Temperature	32.05916 °C
Cp	1.03763
Temperature	33.02024 °C
Cp	1.037276
Temperature	33.98132 °C
Cp	1.03692
Temperature	34.9424 °C
Cp	1.036565
Temperature	35.90348 °C
Cp	1.036213
Temperature	36.86456 °C
Cp	1.035866
Temperature	37.82564 °C
Cp	1.035529
Temperature	38.78672 °C
Cp	1.035195
Temperature	39.7478 °C
Cp	1.034875
Temperature	40.70888 °C
Cp	1.034568
Temperature	41.66996 °C
Cp	1.034276
Temperature	42.63104 °C
Cp	1.033996
Temperature	43.59212 °C
Cp	1.033726
Temperature	44.5532 °C
Cp	1.033469
Temperature	45.51428 °C
Cp	1.033221
Temperature	46.47536 °C
Cp	1.03298
Temperature	47.43644 °C
Cp	1.032744
Temperature	48.39752 °C
Cp	1.032514
Temperature	49.3586 °C
Cp	1.032289
Temperature	50.31968 °C
Cp	1.032065
Temperature	51.28076 °C
Cp	1.031844
Temperature	52.24184 °C
Cp	1.031627
Temperature	53.20292 °C
Cp	1.031413
Temperature	54.164 °C
Cp	1.031203
Temperature	55.12508 °C
Cp	1.030989
Temperature	56.08616 °C
Cp	1.030791
Temperature	57.04724 °C
Cp	1.030595
Temperature	58.00832 °C
Cp	1.030403
Temperature	58.9694 °C
Cp	1.030217
Temperature	59.93048 °C
Cp	1.03004
Temperature	60.89156 °C
Cp	1.029871
Temperature	61.85264 °C
Cp	1.029718
Temperature	62.81372 °C
Cp	1.029567
Temperature	63.7748 °C
Cp	1.02943
Temperature	64.73589 °C
Cp	1.029304
Temperature	65.69696 °C
Cp	1.029185
Temperature	66.65804 °C
Cp	1.02907
Temperature	67.61913 °C
Cp	1.028946
Temperature	68.5802 °C
Cp	1.028831
Temperature	69.54128 °C
Cp	1.028703
Temperature	70.50237 °C
Cp	1.028561
Temperature	71.46344 °C
Cp	1.028404
Temperature	72.42452 °C
Cp	1.028234
Temperature	73.3856 °C
Cp	1.028063
Temperature	74.34668 °C
Cp	1.027861
Temperature	75.30776 °C
Cp	1.027657
Temperature	76.26884 °C
Cp	1.027451
Temperature	77.22992 °C
Cp	1.027243
Temperature	78.191 °C
Cp	1.027036
Temperature	79.15208 °C
Cp	1.026812
Temperature	80.11316 °C
Cp	1.026623
Temperature	81.07424 °C
Cp	1.026431
Temperature	82.03532 °C
Cp	1.026241
Temperature	82.9964 °C
Cp	1.02606
Temperature	83.95748 °C
Cp	1.025891
Temperature	84.91856 °C
Cp	1.025739
Temperature	85.87964 °C
Cp	1.025614
Temperature	86.84072 °C
Cp	1.025493
Temperature	87.8018 °C
Cp	1.0254
Temperature	88.76288 °C
Cp	1.025329
Temperature	89.72396 °C
Cp	1.025274
Temperature	90.68504 °C
Cp	1.025229
Temperature	91.64612 °C
Cp	1.025174
Temperature	92.6072 °C
Cp	1.025138
Temperature	93.56828 °C
Cp	1.025083
Temperature	94.52936 °C
Cp	1.025008
Temperature	95.49044 °C
Cp	1.024912
Temperature	96.45152 °C
Cp	1.024796
Temperature	97.4126 °C
Cp	1.024671
Temperature	98.37368 °C
Cp	1.024506
Temperature	99.33476 °C
Cp	1.02433
Temperature	100.2958 °C
Cp	1.024144
Temperature	101.2569 °C
Cp	1.023948
Temperature	102.218 °C
Cp	1.023743
Temperature	103.1791 °C
Cp	1.023522
Temperature	104.1402 °C
Cp	1.023309
Temperature	105.1012 °C
Cp	1.023089
Temperature	106.0623 °C
Cp	1.022866
Temperature	107.0234 °C
Cp	1.022644
Temperature	107.9845 °C
Cp	1.022427
Temperature	108.9456 °C
Cp	1.022218
Temperature	109.9066 °C
Cp	1.022022
Temperature	110.8677 °C
Cp	1.021836
Temperature	111.8288 °C
Cp	1.021666
Temperature	112.7899 °C
Cp	1.021512
Temperature	113.751 °C
Cp	1.021374
Temperature	114.712 °C
Cp	1.02125
Temperature	115.6731 °C
Cp	1.021137
Temperature	116.6342 °C
Cp	1.021041
Temperature	117.5953 °C
Cp	1.020953
Temperature	118.5564 °C
Cp	1.020872
Temperature	119.5174 °C
Cp	1.020796
Temperature	120.4785 °C
Cp	1.020725
Temperature	121.4396 °C
Cp	1.020659
Temperature	122.4007 °C
Cp	1.020587
Temperature	123.3618 °C
Cp	1.020515
Temperature	124.3228 °C
Cp	1.02044
Temperature	125.2839 °C
Cp	1.020359
Temperature	126.245 °C
Cp	1.02027
Temperature	127.2061 °C
Cp	1.020167
Temperature	128.1672 °C
Cp	1.020057
Temperature	129.1282 °C
Cp	1.019933
Temperature	130.0893 °C
Cp	1.019793
Temperature	131.0504 °C
Cp	1.019638
Temperature	132.0115 °C
Cp	1.019471
Temperature	132.9726 °C
Cp	1.019292
Temperature	133.9336 °C
Cp	1.019107
Temperature	134.8947 °C
Cp	1.018912
Temperature	135.8558 °C
Cp	1.018717
Temperature	136.8169 °C
Cp	1.018527
Temperature	137.778 °C
Cp	1.018344
Temperature	138.739 °C
Cp	1.018171
Temperature	139.7001 °C
Cp	1.018004
Temperature	140.6612 °C
Cp	1.01787
Temperature	141.6223 °C
Cp	1.01775
Temperature	142.5834 °C
Cp	1.017652
Temperature	143.5444 °C
Cp	1.017578
Temperature	144.5055 °C
Cp	1.017534
Temperature	145.4666 °C
Cp	1.017536
Temperature	146.4277 °C
Cp	1.017545
Temperature	147.3888 °C
Cp	1.017595
Temperature	148.3498 °C
Cp	1.017679
Temperature	149.3109 °C
Cp	1.01779
Temperature	150.272 °C
Cp	1.01792
Temperature	151.2331 °C
Cp	1.018043
Temperature	152.1942 °C
Cp	1.018199
Temperature	153.1552 °C
Cp	1.018339
Temperature	154.1163 °C
Cp	1.018458
Temperature	155.0774 °C
Cp	1.018552
Temperature	156.0385 °C
Cp	1.018618
Temperature	156.9996 °C
Cp	1.018662
Temperature	157.9606 °C
Cp	1.018664
Temperature	158.9217 °C
Cp	1.018632
Temperature	159.8828 °C
Cp	1.018575
Temperature	160.8439 °C
Cp	1.018492
Temperature	161.805 °C
Cp	1.018383
Temperature	162.766 °C
Cp	1.01825
Temperature	163.7271 °C
Cp	1.018087
Temperature	164.6882 °C
Cp	1.017917
Temperature	165.6493 °C
Cp	1.017726
Temperature	166.6104 °C
Cp	1.017522
Temperature	167.5714 °C
Cp	1.01731
Temperature	168.5325 °C
Cp	1.017098
Temperature	169.4936 °C
Cp	1.016902
Temperature	170.4547 °C
Cp	1.016695
Temperature	171.4158 °C
Cp	1.016508
Temperature	172.3768 °C
Cp	1.016342
Temperature	173.3379 °C
Cp	1.016195
Temperature	174.299 °C
Cp	1.016065
Temperature	175.2601 °C
Cp	1.015927
Temperature	176.2212 °C
Cp	1.015838
Temperature	177.1822 °C
Cp	1.015746
Temperature	178.1433 °C
Cp	1.015651
Temperature	179.1044 °C
Cp	1.015555
Temperature	180.0655 °C
Cp	1.015459
Temperature	181.0266 °C
Cp	1.015401
Temperature	181.9876 °C
Cp	1.015288
Temperature	182.9487 °C
Cp	1.015195
Temperature	183.9098 °C
Cp	1.015117
Temperature	184.8709 °C
Cp	1.01505
Temperature	185.832 °C
Cp	1.014988
Temperature	186.793 °C
Cp	1.014927
Temperature	187.7541 °C
Cp	1.014849
Temperature	188.7152 °C
Cp	1.014789
Temperature	189.6763 °C
Cp	1.01471
Temperature	190.6374 °C
Cp	1.014614
Temperature	191.5984 °C
Cp	1.014503
Temperature	192.5595 °C
Cp	1.014381
Temperature	193.5206 °C
Cp	1.014268
Temperature	194.4817 °C
Cp	1.014122
Temperature	195.4428 °C
Cp	1.013984
Temperature	196.4038 °C
Cp	1.013853
Temperature	197.3649 °C
Cp	1.013726
Temperature	198.326 °C
Cp	1.013603
Temperature	199.2871 °C
Cp	1.013467
Temperature	200.2482 °C
Cp	1.013359
Temperature	201.2092 °C
Cp	1.013243
Temperature	202.1703 °C
Cp	1.013123
Temperature	203.1314 °C
Cp	1.013002
Temperature	204.0925 °C
Cp	1.012884
Temperature	205.0536 °C
Cp	1.012788
Temperature	206.0146 °C
Cp	1.012674
Temperature	206.9757 °C
Cp	1.012579
Temperature	207.9368 °C
Cp	1.012501
Temperature	208.8979 °C
Cp	1.012439
Temperature	209.859 °C
Cp	1.012389
Temperature	210.82 °C
Cp	1.012351
Temperature	211.7811 °C
Cp	1.012312
Temperature	212.7422 °C
Cp	1.01229
Temperature	213.7033 °C
Cp	1.012262
Temperature	214.6644 °C
Cp	1.012227
Temperature	215.6254 °C
Cp	1.012183
Temperature	216.5865 °C
Cp	1.012129
Temperature	217.5476 °C
Cp	1.012077
Temperature	218.5087 °C
Cp	1.01199
Temperature	219.4698 °C
Cp	1.011897
Temperature	220.4308 °C
Cp	1.011793
Temperature	221.3919 °C
Cp	1.011674
Temperature	222.353 °C
Cp	1.011537
Temperature	223.3141 °C
Cp	1.011362
Temperature	224.2752 °C
Cp	1.011194
Temperature	225.2362 °C
Cp	1.010993
Temperature	226.1973 °C
Cp	1.010766
Temperature	227.1584 °C
Cp	1.010517
Temperature	228.1195 °C
Cp	1.010251
Temperature	229.0806 °C
Cp	1.009998
Temperature	230.0416 °C
Cp	1.009703
Temperature	231.0027 °C
Cp	1.009422
Temperature	231.9638 °C
Cp	1.009156
Temperature	232.9249 °C
Cp	1.008906
Temperature	233.886 °C
Cp	1.008675
Temperature	234.847 °C
Cp	1.008462
Temperature	235.8081 °C
Cp	1.008258
Temperature	236.7692 °C
Cp	1.00809
Temperature	237.7303 °C
Cp	1.007934
Temperature	238.6914 °C
Cp	1.007793
Temperature	239.6524 °C
Cp	1.007668
Temperature	240.6135 °C
Cp	1.007562
Temperature	241.5746 °C
Cp	1.007487
Temperature	242.5357 °C
Cp	1.00741
Temperature	243.4967 °C
Cp	1.00736
Temperature	244.4578 °C
Cp	1.007332
Temperature	245.4189 °C
Cp	1.007321
Temperature	246.38 °C
Cp	1.007321
Temperature	247.3411 °C
Cp	1.007312
Temperature	248.3022 °C
Cp	1.007331
Temperature	249.2632 °C
Cp	1.007338
Temperature	250.2243 °C
Cp	1.007335
Temperature	251.1854 °C
Cp	1.00732
Temperature	252.1465 °C
Cp	1.007295
Temperature	253.1076 °C
Cp	1.007277
Temperature	254.0686 °C
Cp	1.007227
Temperature	255.0297 °C
Cp	1.007179
Temperature	255.9908 °C
Cp	1.007133
Temperature	256.9519 °C
Cp	1.00709
Temperature	257.913 °C
Cp	1.007049
Temperature	258.874 °C
Cp	1.007012
Temperature	259.8351 °C
Cp	1.006978
Temperature	260.7962 °C
Cp	1.006956
Temperature	261.7573 °C
Cp	1.00694
Temperature	262.7184 °C
Cp	1.006934
Temperature	263.6794 °C
Cp	1.006939
Temperature	264.6405 °C
Cp	1.00696
Temperature	265.6016 °C
Cp	1.006999
Temperature	266.5627 °C
Cp	1.007054
Temperature	267.5237 °C
Cp	1.007131
Temperature	268.4848 °C
Cp	1.00723
Temperature	269.4459 °C
Cp	1.00735
Temperature	270.407 °C
Cp	1.007493
Temperature	271.3681 °C
Cp	1.007656
Temperature	272.3292 °C
Cp	1.007839
Temperature	273.2902 °C
Cp	1.008039
Temperature	274.2513 °C
Cp	1.008257
Temperature	275.2124 °C
Cp	1.008488
Temperature	276.1735 °C
Cp	1.008731
Temperature	277.1346 °C
Cp	1.008977
Temperature	278.0956 °C
Cp	1.009237
Temperature	279.0567 °C
Cp	1.009498
Temperature	280.0178 °C
Cp	1.009757
Temperature	280.9789 °C
Cp	1.010014
Temperature	281.9399 °C
Cp	1.010267
Temperature	282.901 °C
Cp	1.010515
Temperature	283.8621 °C
Cp	1.01076
Temperature	284.8232 °C
Cp	1.010993
Temperature	285.7843 °C
Cp	1.011222
Temperature	286.7454 °C
Cp	1.011447
Temperature	287.7064 °C
Cp	1.011665
Temperature	288.6675 °C
Cp	1.011876
Temperature	289.6286 °C
Cp	1.012079
Temperature	290.5897 °C
Cp	1.01228
Temperature	291.5508 °C
Cp	1.012474
Temperature	292.5118 °C
Cp	1.012662
Temperature	293.4729 °C
Cp	1.012846
Temperature	294.434 °C
Cp	1.013028
Temperature	295.3951 °C
Cp	1.013211
Temperature	296.3561 °C
Cp	1.013391
Temperature	297.3172 °C
Cp	1.013574
Temperature	298.2783 °C
Cp	1.013759
Temperature	299.2394 °C
Cp	1.013947
Temperature	300.2005 °C
Cp	1.014136
Temperature	301.1616 °C
Cp	1.01432
Temperature	302.1226 °C
Cp	1.014511
Temperature	303.0837 °C
Cp	1.014695
Temperature	304.0448 °C
Cp	1.014872
Temperature	305.0059 °C
Cp	1.01504
Temperature	305.9669 °C
Cp	1.015198
Temperature	306.928 °C
Cp	1.015343
Temperature	307.8891 °C
Cp	1.015479
Temperature	308.8502 °C
Cp	1.015595
Temperature	309.8113 °C
Cp	1.015699
Temperature	310.7724 °C
Cp	1.015789
Temperature	311.7334 °C
Cp	1.015865
Temperature	312.6945 °C
Cp	1.015925
Temperature	313.6556 °C
Cp	1.015964
Temperature	314.6167 °C
Cp	1.015999
Temperature	315.5778 °C
Cp	1.016018
Temperature	316.5388 °C
Cp	1.016025
Temperature	317.4999 °C
Cp	1.016024
Temperature	318.461 °C
Cp	1.01602
Temperature	319.4221 °C
Cp	1.016029
Temperature	320.3831 °C
Cp	1.016025
Temperature	321.3442 °C
Cp	1.016037
Temperature	322.3053 °C
Cp	1.016066
Temperature	323.2664 °C
Cp	1.01611
Temperature	324.2275 °C
Cp	1.016169
Temperature	325.1886 °C
Cp	1.016225
Temperature	326.1496 °C
Cp	1.016318
Temperature	327.1107 °C
Cp	1.016411
Temperature	328.0718 °C
Cp	1.016504
Temperature	329.0329 °C
Cp	1.016596
Temperature	329.994 °C
Cp	1.016687
Temperature	330.955 °C
Cp	1.016775
Temperature	331.9161 °C
Cp	1.016864
Temperature	332.8772 °C
Cp	1.016942
Temperature	333.8383 °C
Cp	1.017019
Temperature	334.7993 °C
Cp	1.017093
Temperature	335.7604 °C
Cp	1.017163
Temperature	336.7215 °C
Cp	1.01723
Temperature	337.6826 °C
Cp	1.017295
Temperature	338.6437 °C
Cp	1.017358
Temperature	339.6048 °C
Cp	1.017423
Temperature	340.5658 °C
Cp	1.017491
Temperature	341.5269 °C
Cp	1.017567
Temperature	342.488 °C
Cp	1.017651
Temperature	343.4491 °C
Cp	1.017747
Temperature	344.4102 °C
Cp	1.017859
Temperature	345.3712 °C
Cp	1.017987
[...]
151.5883	110.9742	0.3752
151.5967	110.8906	0.3752
151.6050	110.8068	0.3751
151.6133	110.7249	0.3751
151.6217	110.6399	0.3751
151.6300	110.5578	0.3750
151.6383	110.4752	0.3750
151.6467	110.3918	0.3750
151.6550	110.3088	0.3749
151.6633	110.2253	0.3749
151.6717	110.1430	0.3749
151.6800	110.0588	0.3748
151.6883	109.9752	0.3748
151.6967	109.8918	0.3748
151.7050	109.8091	0.3748
151.7133	109.7254	0.3748
151.7217	109.6434	0.3747
151.7300	109.5606	0.3747
151.7383	109.4765	0.3746
151.7467	109.3938	0.3747
151.7550	109.3107	0.3747
151.7633	109.2275	0.3746
151.7717	109.1439	0.3746
151.7800	109.0610	0.3746
151.7883	108.9780	0.3745
151.7967	108.8946	0.3745
151.8050	108.8115	0.3745
151.8133	108.7289	0.3745
151.8217	108.6450	0.3745
151.8300	108.5626	0.3745
151.8383	108.4799	0.3744
151.8467	108.3959	0.3744
151.8550	108.3125	0.3744
151.8633	108.2302	0.3743
151.8717	108.1473	0.3743
151.8800	108.0636	0.3743
151.8883	107.9792	0.3743
151.8967	107.8968	0.3742
151.9050	107.8140	0.3742
151.9133	107.7301	0.3742
151.9217	107.6477	0.3742
151.9300	107.5640	0.3742
151.9383	107.4809	0.3741
151.9467	107.3970	0.3741
151.9550	107.3149	0.3741
151.9633	107.2317	0.3740
151.9717	107.1486	0.3740
151.9800	107.0654	0.3740
151.9883	106.9829	0.3739
151.9967	106.8987	0.3739
152.0050	106.8162	0.3738
152.0133	106.7330	0.3738
152.0217	106.6486	0.3737
152.0300	106.5662	0.3737
152.0383	106.4837	0.3737
152.0467	106.4007	0.3736
152.0550	106.3171	0.3737
152.0633	106.2354	0.3737
152.0717	106.1513	0.3736
152.0800	106.0683	0.3736
152.0883	105.9852	0.3736
152.0967	105.9021	0.3735
152.1050	105.8183	0.3735
152.1133	105.7355	0.3735
152.1217	105.6527	0.3734
152.1300	105.5699	0.3734
152.1383	105.4852	0.3734
152.1467	105.4038	0.3734
152.1550	105.3193	0.3734
152.1633	105.2360	0.3733
152.1717	105.1544	0.3732
152.1800	105.0706	0.3732
152.1883	104.9864	0.3732
152.1967	104.9035	0.3732
152.2050	104.8208	0.3732
152.2133	104.7373	0.3731
152.2217	104.6545	0.3731
152.2300	104.5705	0.3731
152.2383	104.4881	0.3731
152.2467	104.4044	0.3731
152.2550	104.3216	0.3731
152.2633	104.2376	0.3730
152.2717	104.1551	0.3730
152.2800	104.0721	0.3730
152.2883	103.9890	0.3729
152.2967	103.9060	0.3729
152.3050	103.8216	0.3729
152.3133	103.7393	0.3730
152.3217	103.6561	0.3729
152.3300	103.5733	0.3729
152.3383	103.4901	0.3729
152.3467	103.4064	0.3728
152.3550	103.3248	0.3728
152.3633	103.2402	0.3728
152.3717	103.1576	0.3728
152.3800	103.0742	0.3727
152.3883	102.9912	0.3727
152.3967	102.9077	0.3726
152.4050	102.8247	0.3725
152.4133	102.7418	0.3725
152.4217	102.6584	0.3725
152.4300	102.5745	0.3724
152.4383	102.4921	0.3724
152.4467	102.4092	0.3724
152.4550	102.3258	0.3724
152.4633	102.2436	0.3723
152.4717	102.1596	0.3722
152.4800	102.0758	0.3722
152.4883	101.9932	0.3722
152.4967	101.9099	0.3722
152.5050	101.8284	0.3722
152.5133	101.7431	0.3722
152.5217	101.6596	0.3721
152.5300	101.5771	0.3721
152.5383	101.4951	0.3720
152.5467	101.4113	0.3720
152.5550	101.3275	0.3720
152.5633	101.2449	0.3719
152.5717	101.1625	0.3719
152.5800	101.0781	0.3719
152.5883	100.9969	0.3718
152.5967	100.9117	0.3718
152.6050	100.8291	0.3718
152.6133	100.7452	0.3717
152.6217	100.6631	0.3717
152.6300	100.5800	0.3717
152.6383	100.4958	0.3716
152.6467	100.4121	0.3717
152.6550	100.3288	0.3716
152.6633	100.2471	0.3716
152.6717	100.1623	0.3716
152.6800	100.0807	0.3716
152.6883	99.9972	0.3716
152.6967	99.9139	0.3715
152.7050	99.8312	0.3715
152.7133	99.7476	0.3714
152.7217	99.6650	0.3714
152.7300	99.5816	0.3713
152.7383	99.4983	0.3713
152.7467	99.4144	0.3713
152.7550	99.3328	0.3712
152.7633	99.2494	0.3712
152.7717	99.1660	0.3712
152.7800	99.0827	0.3712
152.7883	98.9997	0.3712
152.7967	98.9171	0.3711
152.8050	98.8329	0.3710
152.8133	98.7507	0.3710
152.8217	98.6671	0.3709
152.8300	98.5840	0.3709
152.8383	98.5006	0.3709
152.8467	98.4182	0.3709
152.8550	98.3345	0.3709
152.8633	98.2514	0.3708
152.8717	98.1685	0.3708
152.8800	98.0847	0.3708
152.8883	98.0022	0.3708
152.8967	97.9189	0.3708
152.9050	97.8362	0.3707
152.9133	97.7518	0.3707
152.9217	97.6698	0.3707
152.9300	97.5864	0.3706
152.9383	97.5030	0.3706
152.9467	97.4205	0.3706
152.9550	97.3366	0.3705
152.9633	97.2541	0.3705
152.9717	97.1699	0.3705
152.9800	97.0866	0.3704
152.9883	97.0041	0.3704
152.9967	96.9213	0.3704
153.0050	96.8377	0.3704
153.0133	96.7539	0.3704
153.0217	96.6719	0.3703
153.0300	96.5877	0.3703
153.0383	96.5054	0.3703
153.0467	96.4217	0.3702
153.0550	96.3384	0.3702
153.0633	96.2552	0.3702
153.0717	96.1721	0.3701
153.0800	96.0886	0.3701
153.0883	96.0063	0.3700
153.0967	95.9231	0.3700
153.1050	95.8403	0.3700
153.1133	95.7565	0.3699
153.1217	95.6740	0.3699
153.1300	95.5902	0.3698
153.1383	95.5067	0.3698
153.1467	95.4243	0.3697
153.1550	95.3411	0.3698
153.1633	95.2577	0.3697
153.1717	95.1743	0.3697
153.1800	95.0921	0.3696
153.1883	95.0084	0.3696
153.1967	94.9249	0.3695
153.2050	94.8427	0.3695
153.2133	94.7589	0.3695
153.2217	94.6752	0.3695
153.2300	94.5918	0.3695
153.2383	94.5090	0.3693
153.2467	94.4265	0.3693
153.2550	94.3432	0.3693
153.2633	94.2599	0.3692
153.2717	94.1757	0.3692
153.2800	94.0935	0.3692
153.2883	94.0105	0.3692
153.2967	93.9265	0.3691
153.3050	93.8437	0.3691
153.3133	93.7600	0.3691
153.3217	93.6782	0.3690
153.3300	93.5947	0.3690
153.3383	93.5113	0.3690
153.3467	93.4276	0.3689
153.3550	93.3457	0.3689
153.3633	93.2620	0.3688
153.3717	93.1786	0.3688
153.3800	93.0965	0.3688
153.3883	93.0123	0.3688
153.3967	92.9292	0.3687
153.4050	92.8456	0.3686
153.4133	92.7625	0.3686
153.4217	92.6811	0.3686
153.4300	92.5974	0.3686
153.4383	92.5129	0.3685
153.4467	92.4297	0.3685
153.4550	92.3466	0.3685
153.4633	92.2632	0.3685
153.4717	92.1806	0.3684
153.4800	92.0973	0.3684
153.4883	92.0147	0.3684
153.4967	91.9311	0.3683
153.5050	91.8479	0.3683
153.5133	91.7654	0.3682
153.5217	91.6807	0.3682
153.5300	91.5989	0.3681
153.5383	91.5150	0.3681
153.5467	91.4328	0.3681
153.5550	91.3486	0.3681
153.5633	91.2658	0.3681
153.5717	91.1826	0.3680
153.5800	91.1001	0.3679
153.5883	91.0171	0.3678
153.5967	90.9335	0.3678
153.6050	90.8498	0.3678
153.6133	90.7685	0.3678
153.6217	90.6835	0.3678
153.6300	90.6010	0.3677
153.6383	90.5173	0.3677
153.6467	90.4346	0.3677
153.6550	90.3513	0.3677
153.6633	90.2684	0.3676
153.6717	90.1848	0.3675
153.6800	90.1021	0.3673
153.6883	90.0182	0.3673
153.6967	89.9362	0.3673
153.7050	89.8515	0.3673
153.7133	89.7700	0.3673
153.7217	89.6858	0.3672
153.7300	89.6030	0.3672
153.7383	89.5186	0.3672
153.7467	89.4368	0.3671
153.7550	89.3540	0.3670
153.7633	89.2706	0.3670
153.7717	89.1878	0.3670
153.7800	89.1050	0.3670
153.7883	89.0217	0.3670
153.7967	88.9374	0.3670
153.8050	88.8544	0.3670
153.8133	88.7713	0.3669
153.8217	88.6884	0.3669
153.8300	88.6052	0.3669
153.8383	88.5219	0.3669
153.8467	88.4378	0.3669
153.8550	88.3554	0.3668
153.8633	88.2721	0.3668
153.8717	88.1891	0.3668
153.8800	88.1074	0.3668
153.8883	88.0223	0.3668
153.8967	87.9392	0.3668
153.9050	87.8564	0.3667
153.9133	87.7732	0.3667
153.9217	87.6904	0.3667
153.9300	87.6074	0.3666
153.9383	87.5239	0.3666
153.9467	87.4411	0.3666
153.9550	87.3586	0.3665
153.9633	87.2751	0.3665
153.9717	87.1916	0.3665
153.9800	87.1092	0.3664
153.9883	87.0260	0.3664
153.9967	86.9431	0.3664
154.0050	86.8591	0.3663
154.0133	86.7764	0.3663
154.0217	86.6921	0.3663
154.0300	86.6095	0.3663
154.0383	86.5263	0.3662
154.0467	86.4435	0.3662
154.0550	86.3604	0.3662
154.0633	86.2773	0.3662
154.0717	86.1942	0.3661
154.0800	86.1111	0.3661
154.0883	86.0283	0.3661
154.0967	85.9442	0.3660
154.1050	85.8617	0.3660
154.1133	85.7787	0.3660
154.1217	85.6950	0.3660
154.1300	85.6121	0.3660
154.1383	85.5292	0.3659
154.1467	85.4463	0.3659
154.1550	85.3621	0.3659
154.1633	85.2800	0.3657
154.1717	85.1969	0.3657
154.1800	85.1124	0.3657
154.1883	85.0306	0.3657
154.1967	84.9473	0.3657
154.2050	84.8638	0.3656
154.2133	84.7803	0.3656
154.2217	84.6976	0.3656
154.2300	84.6136	0.3656
154.2383	84.5305	0.3655
154.2467	84.4471	0.3655
154.2550	84.3649	0.3655
154.2633	84.2816	0.3654
154.2717	84.1983	0.3654
154.2800	84.1151	0.3654
154.2883	84.0323	0.3654
154.2967	83.9488	0.3653
154.3050	83.8658	0.3653
154.3133	83.7818	0.3653
154.3217	83.6993	0.3653
154.3300	83.6160	0.3653
154.3383	83.5320	0.3652
154.3467	83.4496	0.3652
154.3550	83.3656	0.3651
154.3633	83.2823	0.3651
154.3717	83.2001	0.3651
154.3800	83.1162	0.3651
154.3883	83.0339	0.3651
154.3967	82.9501	0.3651
154.4050	82.8681	0.3650
154.4133	82.7847	0.3650
154.4217	82.7007	0.3649
154.4300	82.6176	0.3649
154.4383	82.5345	0.3649
154.4467	82.4526	0.3649
154.4550	82.3696	0.3649
154.4633	82.2853	0.3648
154.4717	82.2029	0.3646
154.4800	82.1196	0.3646
154.4883	82.0366	0.3645
154.4967	81.9526	0.3644
154.5050	81.8696	0.3644
154.5133	81.7858	0.3644
154.5217	81.7033	0.3644
154.5300	81.6203	0.3643
154.5383	81.5376	0.3642
154.5467	81.4537	0.3642
154.5550	81.3709	0.3642
154.5633	81.2882	0.3642
154.5717	81.2053	0.3642
154.5800	81.1215	0.3641
154.5883	81.0385	0.3641
154.5967	80.9553	0.3641
154.6050	80.8714	0.3640
154.6133	80.7883	0.3640
154.6217	80.7048	0.3640
154.6300	80.6222	0.3639
154.6383	80.5380	0.3639
154.6467	80.4559	0.3639
154.6550	80.3728	0.3638
154.6633	80.2901	0.3636
154.6717	80.2068	0.3636
154.6800	80.1229	0.3636
154.6883	80.0403	0.3636
154.6967	79.9566	0.3636
154.7050	79.8736	0.3636
154.7133	79.7896	0.3635
154.7217	79.7078	0.3635
154.7300	79.6222	0.3635
154.7383	79.5409	0.3631
154.7467	79.4571	0.3631
154.7550	79.3740	0.3631
154.7633	79.2913	0.3631
154.7717	79.2073	0.3631
154.7800	79.1236	0.3631
154.7883	79.0412	0.3630
154.7967	78.9587	0.3629
154.8050	78.8757	0.3629
154.8133	78.7922	0.3629
154.8217	78.7082	0.3629
154.8300	78.6250	0.3629
154.8383	78.5420	0.3628
154.8467	78.4582	0.3628
154.8550	78.3762	0.3627
154.8633	78.2935	0.3627
154.8717	78.2099	0.3628
154.8800	78.1276	0.3627
154.8883	78.0437	0.3627
154.8967	77.9613	0.3627
154.9050	77.8783	0.3627
154.9133	77.7947	0.3626
154.9217	77.7116	0.3626
154.9300	77.6292	0.3625
154.9383	77.5447	0.3625
154.9467	77.4619	0.3625
154.9550	77.3795	0.3625
154.9633	77.2957	0.3624
154.9717	77.2126	0.3624
154.9800	77.1288	0.3624
154.9883	77.0454	0.3624
154.9967	76.9616	0.3624
155.0050	76.8785	0.3623
155.0133	76.7951	0.3623
155.0217	76.7117	0.3623
155.0300	76.6285	0.3622
155.0383	76.5456	0.3622
155.0467	76.4616	0.3622
155.0550	76.3792	0.3622
155.0633	76.2958	0.3622
155.0717	76.2134	0.3621
155.0800	76.1301	0.3621
155.0883	76.0471	0.3621
155.0967	75.9640	0.3620
155.1050	75.8797	0.3620
155.1133	75.7985	0.3620
155.1217	75.7149	0.3619
155.1300	75.6312	0.3619
155.1383	75.5484	0.3619
155.1467	75.4645	0.3619
155.1550	75.3820	0.3618
155.1633	75.2988	0.3618
155.1717	75.2163	0.3619
155.1800	75.1335	0.3622
155.1883	75.0496	0.3627
155.1967	74.9673	0.3627
155.2050	74.8852	0.3647
155.2133	74.8008	0.3671
155.2217	74.7188	0.3700
155.2300	74.6363	0.3759
155.2383	74.5546	0.3817
155.2467	74.4727	0.3911
155.2550	74.3906	0.4037
155.2633	74.3104	0.4237
155.2717	74.2308	0.4526
155.2800	74.1547	0.4963
155.2883	74.0795	0.5608
155.2967	74.0104	0.6525
155.3050	73.9438	0.7826
155.3133	73.8879	0.9587
155.3217	73.8412	1.1770
155.3300	73.8054	1.4321
155.3383	73.7813	1.7101
155.3467	73.7688	1.9856
155.3550	73.7642	2.2404
155.3633	73.7668	2.4636
155.3717	73.7709	2.6516
155.3800	73.7758	2.8030
155.3883	73.7799	2.9237
155.3967	73.7808	3.0223
155.4050	73.7784	3.1035
155.4133	73.7710	3.1692
155.4217	73.7600	3.2285
155.4300	73.7431	3.2795
155.4383	73.7241	3.3271
155.4467	73.7003	3.3719
155.4550	73.6729	3.4124
155.4633	73.6421	3.4544
155.4717	73.6091	3.4918
155.4800	73.5727	3.5269
155.4883	73.5344	3.5637
155.4967	73.4908	3.5969
155.5050	73.4476	3.6283
155.5133	73.4011	3.6574
155.5217	73.3520	3.6808
155.5300	73.3014	3.7060
155.5383	73.2488	3.7297
155.5467	73.1954	3.7503
155.5550	73.1387	3.7677
155.5633	73.0815	3.7816
155.5717	73.0210	3.7936
155.5800	72.9595	3.8050
155.5883	72.8960	3.8111
155.5967	72.8314	3.8124
155.6050	72.7643	3.8163
155.6133	72.6965	3.8155
155.6217	72.6275	3.8128
155.6300	72.5549	3.8072
155.6383	72.4832	3.7984
155.6467	72.4080	3.7887
155.6550	72.3309	3.7766
155.6633	72.2536	3.7585
155.6717	72.1748	3.7399
155.6800	72.0942	3.7189
155.6883	72.0116	3.6942
155.6967	71.9281	3.6668
155.7050	71.8418	3.6357
155.7133	71.7543	3.6011
155.7217	71.6660	3.5660
155.7300	71.5746	3.5304
155.7383	71.4825	3.4874
155.7467	71.3891	3.4430
155.7550	71.2934	3.3975
155.7633	71.1970	3.3497
155.7717	71.0982	3.3015
155.7800	70.9977	3.2511
155.7883	70.8978	3.1995
155.7967	70.7949	3.1491
155.8050	70.6926	3.0978
155.8133	70.5874	3.0436
155.8217	70.4827	2.9895
155.8300	70.3759	2.9378
155.8383	70.2692	2.8850
155.8467	70.1618	2.8313
155.8550	70.0541	2.7791
155.8633	69.9453	2.7280
155.8717	69.8371	2.6783
155.8800	69.7273	2.6284
155.8883	69.6172	2.5792
155.8967	69.5077	2.5305
155.9050	69.3973	2.4845
155.9133	69.2884	2.4386
155.9217	69.1782	2.3941
155.9300	69.0687	2.3501
155.9383	68.9587	2.3064
155.9467	68.8493	2.2649
155.9550	68.7396	2.2221
155.9633	68.6297	2.1828
155.9717	68.5219	2.1436
155.9800	68.4127	2.1047
155.9883	68.3045	2.0668
155.9967	68.1970	2.0310
156.0050	68.0901	1.9963
156.0133	67.9837	1.9610
156.0217	67.8764	1.9287
156.0300	67.7706	1.8969
156.0383	67.6659	1.8711
156.0467	67.5605	1.8474
156.0550	67.4559	1.8206
156.0633	67.3531	1.7921
156.0717	67.2514	1.7634
156.0800	67.1477	1.7367
156.0883	67.0444	1.7109
156.0967	66.9435	1.6870
156.1050	66.8423	1.6634
156.1133	66.7413	1.6387
156.1217	66.6393	1.6149
156.1300	66.5405	1.5911
156.1383	66.4400	1.5693
156.1467	66.3415	1.5502
156.1550	66.2424	1.5333
156.1633	66.1434	1.5157
156.1717	66.0463	1.4916
156.1800	65.9480	1.4693
156.1883	65.8507	1.4491
156.1967	65.7530	1.4243
156.2050	65.6559	1.4002
156.2133	65.5580	1.3783
156.2217	65.4616	1.3576
156.2300	65.3650	1.3373
156.2383	65.2673	1.3158
156.2467	65.1704	1.2953
156.2550	65.0738	1.2781
156.2633	64.9772	1.2604
156.2717	64.8816	1.2397
156.2800	64.7858	1.2229
156.2883	64.6903	1.2069
156.2967	64.5946	1.1891
156.3050	64.4994	1.1720
156.3133	64.4047	1.1574
156.3217	64.3111	1.1404
156.3300	64.2164	1.1260
156.3383	64.1227	1.1109
156.3467	64.0289	1.0963
156.3550	63.9355	1.0835
156.3633	63.8413	1.0681
156.3717	63.7491	1.0542
156.3800	63.6564	1.0429
156.3883	63.5634	1.0294
156.3967	63.4708	1.0148
156.4050	63.3792	1.0030
156.4133	63.2854	0.9912
156.4217	63.1944	0.9798
156.4300	63.1018	0.9674
156.4383	63.0114	0.9574
156.4467	62.9191	0.9460
156.4550	62.8291	0.9344
156.4633	62.7384	0.9256
156.4717	62.6480	0.9160
156.4800	62.5570	0.9052
156.4883	62.4648	0.8940
156.4967	62.3756	0.8844
156.5050	62.2855	0.8757
156.5133	62.1953	0.8665
156.5217	62.1049	0.8590
156.5300	62.0152	0.8505
156.5383	61.9258	0.8418
156.5467	61.8369	0.8324
156.5550	61.7480	0.8256
156.5633	61.6587	0.8182
156.5717	61.5694	0.8099
156.5800	61.4812	0.8032
156.5883	61.3922	0.7947
156.5967	61.3032	0.7881
156.6050	61.2144	0.7793
156.6133	61.1272	0.7713
156.6217	61.0391	0.7658
156.6300	60.9506	0.7583
156.6383	60.8631	0.7519
156.6467	60.7749	0.7465
156.6550	60.6860	0.7390
156.6633	60.5986	0.7327
156.6717	60.5114	0.7266
156.6800	60.4237	0.7216
156.6883	60.3356	0.7147
156.6967	60.2486	0.7087
156.7050	60.1623	0.7041
156.7133	60.0742	0.6984
156.7217	59.9879	0.6936
156.7300	59.9004	0.6883
156.7383	59.8128	0.6824
156.7467	59.7266	0.6772
156.7550	59.6402	0.6735
156.7633	59.5532	0.6692
156.7717	59.4665	0.6644
156.7800	59.3792	0.6576
156.7883	59.2941	0.6546
156.7967	59.2073	0.6506
156.8050	59.1203	0.6462
156.8133	59.0353	0.6424
156.8217	58.9479	0.6374
156.8300	58.8625	0.6350
156.8383	58.7764	0.6317
156.8467	58.6899	0.6276
156.8550	58.6049	0.6218
156.8633	58.5188	0.6187
156.8717	58.4339	0.6148
156.8800	58.3466	0.6119
156.8883	58.2609	0.6083
156.8967	58.1742	0.6060
156.9050	58.0902	0.6021
156.9133	58.0051	0.6005
156.9217	57.9188	0.5966
156.9300	57.8331	0.5932
156.9383	57.7487	0.5922
156.9467	57.6628	0.5877
156.9550	57.5771	0.5853
156.9633	57.4936	0.5841
156.9717	57.4070	0.5812
156.9800	57.3229	0.5787
156.9883	57.2364	0.5757
156.9967	57.1516	0.5714
157.0050	57.0683	0.5702
157.0133	56.9821	0.5676
157.0217	56.8979	0.5646
157.0300	56.8113	0.5626
157.0383	56.7276	0.5603
157.0467	56.6437	0.5584
157.0550	56.5579	0.5571
157.0633	56.4730	0.5531
157.0717	56.3894	0.5506
157.0800	56.3041	0.5478
157.0883	56.2196	0.5465
157.0967	56.1351	0.5452
157.1050	56.0501	0.5427
157.1133	55.9663	0.5410
157.1217	55.8817	0.5381
157.1300	55.7971	0.5369
157.1383	55.7129	0.5347
157.1467	55.6280	0.5332
157.1550	55.5429	0.5310
157.1633	55.4601	0.5293
157.1717	55.3741	0.5289
157.1800	55.2902	0.5267
157.1883	55.2047	0.5250
157.1967	55.1206	0.5224
157.2050	55.0372	0.5206
157.2133	54.9518	0.5202
157.2217	54.8679	0.5177
157.2300	54.7833	0.5152
157.2383	54.6992	0.5145
157.2467	54.6153	0.5134
157.2550	54.5301	0.5118
157.2633	54.4468	0.5098
157.2717	54.3617	0.5079
157.2800	54.2781	0.5063
157.2883	54.1951	0.5059
157.2967	54.1099	0.5045
157.3050	54.0253	0.5021
157.3133	53.9422	0.5018
157.3217	53.8578	0.5002
157.3300	53.7746	0.4976
157.3383	53.6890	0.4969
157.3467	53.6052	0.4966
157.3550	53.5233	0.4943
157.3633	53.4373	0.4935
157.3717	53.3536	0.4913
157.3800	53.2695	0.4903
157.3883	53.1853	0.4904
157.3967	53.1019	0.4887
157.4050	53.0179	0.4877
157.4133	52.9334	0.4870
157.4217	52.8500	0.4845
157.4300	52.7652	0.4832
157.4383	52.6817	0.4834
157.4467	52.5964	0.4828
157.4550	52.5145	0.4808
157.4633	52.4297	0.4801
157.4717	52.3452	0.4792
157.4800	52.2619	0.4787
157.4883	52.1777	0.4781
157.4967	52.0939	0.4765
157.5050	52.0109	0.4751
157.5133	51.9265	0.4744
157.5217	51.8432	0.4741
157.5300	51.7586	0.4735
157.5383	51.6746	0.4732
157.5467	51.5923	0.4725
157.5550	51.5086	0.4710
157.5633	51.4241	0.4700
157.5717	51.3406	0.4696
157.5800	51.2568	0.4690
157.5883	51.1733	0.4681
157.5967	51.0895	0.4665
157.6050	51.0063	0.4661
157.6133	50.9218	0.4657
157.6217	50.8386	0.4648
157.6300	50.7560	0.4643
157.6383	50.6719	0.4638
157.6467	50.5883	0.4630
157.6550	50.5041	0.4622
157.6633	50.4193	0.4621
157.6717	50.3374	0.4615
157.6800	50.2549	0.4611
157.6883	50.1701	0.4606
157.6967	50.0867	0.4588
157.7050	50.0027	0.4575
157.7133	49.9198	0.4573
157.7217	49.8366	0.4574
157.7300	49.7524	0.4568
157.7383	49.6684	0.4560
157.7467	49.5831	0.4559
157.7550	49.5003	0.4550
157.7633	49.4184	0.4547
157.7717	49.3349	0.4543
157.7800	49.2509	0.4531
157.7883	49.1680	0.4525
157.7967	49.0851	0.4525
157.8050	49.0002	0.4519
157.8133	48.9183	0.4506
157.8217	48.8344	0.4504
157.8300	48.7506	0.4503
157.8383	48.6674	0.4500
157.8467	48.5842	0.4499
157.8550	48.5002	0.4498
157.8633	48.4160	0.4496
157.8717	48.3323	0.4491
157.8800	48.2499	0.4490
157.8883	48.1662	0.4484
157.8967	48.0817	0.4478
157.9050	47.9990	0.4469
157.9133	47.9146	0.4467
157.9217	47.8318	0.4463
157.9300	47.7493	0.4459
157.9383	47.6652	0.4453
157.9467	47.5821	0.4447
157.9550	47.4982	0.4445
157.9633	47.4145	0.4433
157.9717	47.3302	0.4430
157.9800	47.2475	0.4427
157.9883	47.1637	0.4419
157.9967	47.0807	0.4412
158.0050	46.9973	0.4408
158.0133	46.9147	0.4403
158.0217	46.8310	0.4400
158.0300	46.7473	0.4393
158.0383	46.6639	0.4383
158.0467	46.5812	0.4381
158.0550	46.4967	0.4373
158.0633	46.4130	0.4368
158.0717	46.3290	0.4364
158.0800	46.2465	0.4351
158.0883	46.1634	0.4345
158.0967	46.0792	0.4343
158.1050	45.9942	0.4329
158.1133	45.9113	0.4301
158.1217	45.8281	0.4298
158.1300	45.7453	0.4297
158.1383	45.6610	0.4296
158.1467	45.5770	0.4286
158.1550	45.4936	0.4276
158.1633	45.4108	0.4272
158.1717	45.3263	0.4266
158.1800	45.2435	0.4254
158.1883	45.1585	0.4245
158.1967	45.0761	0.4242
158.2050	44.9918	0.4230
158.2133	44.9086	0.4228
158.2217	44.8252	0.4221
158.2300	44.7410	0.4211
158.2383	44.6575	0.4207
158.2467	44.5738	0.4199
158.2550	44.4909	0.4192
158.2633	44.4075	0.4183
158.2717	44.3230	0.4167
158.2800	44.2400	0.4161
158.2883	44.1576	0.4156
158.2967	44.0723	0.4144
158.3050	43.9894	0.4137
158.3133	43.9056	0.4129
158.3217	43.8224	0.4117
158.3300	43.7387	0.4111
158.3383	43.6538	0.4103
158.3467	43.5717	0.4097
158.3550	43.4881	0.4085
158.3633	43.4047	0.4075
158.3717	43.3204	0.4073
158.3800	43.2364	0.4061
158.3883	43.1541	0.4056
158.3967	43.0701	0.4048
158.4050	42.9859	0.4043
158.4133	42.9022	0.4037
158.4217	42.8191	0.4032
158.4300	42.7344	0.4020
158.4383	42.6512	0.4009
158.4467	42.5681
158.4550	42.4832
158.4633	42.3997
158.4717	42.3160
158.4800	42.2325
158.4883	42.1482
158.4967