File: Example Date/My Sample/DSC/test01/DSC TA/YN040 -150-150.txt
Filename	YN040 -150-150
Instrument name	DSC2A-01799 (192.168.1.250)
Operator
rundate	09/12/2024
Sample name	YN040 -150-150
proceduresegments	Ramp 10.00 °C/min to 150.0000 °C; Isothermal 3.0 min; Ramp 10.00 °C/min to -150.0000 °C; Isothermal 3.0 min; Ramp 10.00 °C/min to 150.0000 °C; Isothermal 3.0 min; Ramp 10.00 °C/min to -150.0000 °C; Isothermal 3.0 min; Ramp 10.00 °C/min to 150.0000 °C; Isothermal 3.0 min; Ramp 10.00 °C/min to 40.0000 °C
[File Parameters]
Run Date	09/12/2024 17:04:57
Trios version	5.7.0.56
Original File Name	C:\Users\TA Instruments DSC\Desktop\Data\Yutong Niu\YN040 -150-150.tri
Current File Name	C:\Users\TA Instruments DSC\Desktop\Data\Yutong Niu\YN040 -150-150.tri
User at run start	DESKTOP-CFGN8IT\TA Instruments DSC
[Procedure]
Procedure Name	polyether
Sample Name	YN040 -150-150
Sample Mass	9.54 mg
Reference Sample Mass	0 mg
Pan Mass	61.11 mg
Pan Number	27
Reference Pan Mass	60.81 mg
Reference Pan Number	45
Pan Type	Tzero Aluminum Pin Hole Hermetic
Comments
Project Name
Operator
Test	Custom
Unload Max Temperature	25
Unload Min Temperature	25
FillCooler	Do not fill
Load Max Temperature	25
Load Min Temperature	25
Discard pan in waste bin at end of test	Yes
Stop on Gas Flow Error	No
[Signal List]
Signal #1	Time (min)
Signal #2	Temperature (°C)
Signal #3	Heat Flow (mW)
Signal #4	Delta T (µV)
Signal #5	Delta Tzero (µV)
Signal #6	Tzero Temperature (°C)
Signal #7	Cell Purge (mL/min)
Signal #8	Heater Temp (°C)
Signal #9	Power Delivered (W)
Signal #10	Reference Junction Temperature (°C)
Signal #11	Flange Temperature (°C)
Signal #12	Heat Flow Phase (rad)
Signal #13	Total Heat Capacity (J/°C)
Signal #14	Heat Capacity (J/°C)
Signal #15	LN Pump Tank level (%)
[Configuration]
Company Name	Warwick University
Instrument Name	DSC2A-01799
Instrument Type	DSC2500
Serial Number	DSC2A-01799
IP	192.168.1.250
Location of Instrument	Polymer RTP
DisplayType	TianmaV2andV3
Sample Interval 	0.1 s/pt
Selected Heat Flow	T4P
Exotherm Direction	Up
Cell Serial	DRC2-03788
Lid Type	High Temperature
Cooler	LN Pump
Leave Cooler on at End of Sequence	Off
Gas 2	Air
Gas Selected	Channel 1: Nitrogen
Flow Rate	50 mL/min
Secondary Purge	On
Licensed Heat Flow	Heat Flow T4P
Modulation Licensed	Yes
[Versions]
Common IDD Version	1
Cortex Version	VER 2.11.0.729
Driver	5.0.0.6
GDM Version	1.0.3.3
TouchscreenVersion	1.0.3.1841
FEP Version	1.2.1.21
FEP Bootloader	2.0.0.5
AutoSampler Version	2.1.2.1
Auto Sampler Bootloader	2.0.0.5
FCM Version	1.1.0.3
FCM Bootloader	2.0.0.5
LN Pump Version	10.17.0.0
LN Pump Bootloader	2.0.0.5
[Experiment Logs]
Experiment Log Entry # 1	Air Cool is off.
Experiment Log Entry # 3	Ramp Segment 10 C/min to 150 Started
Experiment Log Entry # 5	Isothermal Segment 3 min started
Experiment Log Entry # 7	Ramp Segment 10 C/min to -150 Started
Experiment Log Entry # 9	Isothermal Segment 3 min started
Experiment Log Entry # 11	Ramp Segment 10 C/min to 150 Started
Experiment Log Entry # 13	Isothermal Segment 3 min started
Experiment Log Entry # 15	Ramp Segment 10 C/min to -150 Started
Experiment Log Entry # 17	Isothermal Segment 3 min started
Experiment Log Entry # 19	Ramp Segment 10 C/min to 150 Started
Experiment Log Entry # 21	Isothermal Segment 3 min started
Experiment Log Entry # 23	Ramp Segment 10 C/min to 40 Started
[Method Log]
Method Log Entry # 1	(Ramp 542920) Ramp 10 °C/minute to 150 °C
Method Log Entry # 2	Isothermal 3 minutes
Method Log Entry # 3	(Ramp 542922) Ramp 10 °C/minute to -150 °C
Method Log Entry # 4	Isothermal 3 minutes
Method Log Entry # 5	(Ramp 542924) Ramp 10 °C/minute to 150 °C
Method Log Entry # 6	Isothermal 3 minutes
Method Log Entry # 7	(Ramp 542926) Ramp 10 °C/minute to -150 °C
Method Log Entry # 8	Isothermal 3 minutes
Method Log Entry # 9	(Ramp 542928) Ramp 10 °C/minute to 150 °C
Method Log Entry # 10	Isothermal 3 minutes
Method Log Entry # 11	(Ramp 542930) Ramp 10 °C/minute to 40 °C
Cell Serial	DRC2-03788
[T1 Calibration]
Date Applied	04/03/2021 14:58:04
Description
Gas Type	Nitrogen
Pan Type	None
Slope	-0.001800291
Offset	-0.1301359
Initial Temperature	-100.6228
GUID	a1d5a6be-decd-4ae4-b22f-d560f3a78a92
[TZero Calibration]
Date Applied	21/08/2024 09:53:38
Description	From -180.022 °C to 395.167 °C at 20.000°C/min
Gas Type	Nitrogen
Pan Type	None
Source Files 1	C:\ProgramData\TA Instruments\TRIOS\Data\TAService\PMV 20Aug2024\Tzero Cal.tri
Source Files 2	C:\ProgramData\TA Instruments\TRIOS\Data\TAService\PMV 20Aug2024\Tzero Cal sapphire.tri
Delta T Offset	1.787969
Delta T Slope	-0.003527276
Delta T0 Offset	0.06831977
Delta T0 Slope	0.02007191
[Temperature Calibration]
Date Applied	21/08/2024 11:06:35
Description	From 106.660 °C to 186.660 °C at 10.000°C/min
Gas Type	Nitrogen
Pan Type	Tzero Aluminum
Source Files 1	C:\ProgramData\TA Instruments\TRIOS\Data\TAService\PMV 20Aug2024\TA Indium cal.tri
Measured 1	157.9141
Known 1	156.66
[Cell Constant Calibration]
Date Applied	21/08/2024 11:06:35
Description	From 106.660 °C to 186.660 °C at 10.000°C/min
Gas Type	Nitrogen
Pan Type	Tzero Aluminum
Source Files 1	C:\ProgramData\TA Instruments\TRIOS\Data\TAService\PMV 20Aug2024\TA Indium cal.tri
T4P KCell	1.038055
Onset Slope	-66.72884 mW/°C
[Direct Cp Calibration]
Date Applied	19/11/2024 16:37:27
Description	From -89.996 °C to 396.697 °C at 20.000°C/min
Gas Type	Nitrogen
Pan Type	Tzero Aluminum
Source Files 1	C:\ProgramData\TA Instruments\TRIOS\Data\Sapphire Direct Heat Capacity(8).tri
GUID	544f8371-fe9b-4f4f-81ca-7980c172113e
Temperature	-89.99625 °C
Cp	1.464367
Temperature	-89.02287 °C
Cp	1.460558
Temperature	-88.04948 °C
Cp	1.456263
Temperature	-87.0761 °C
Cp	1.451626
Temperature	-86.10271 °C
Cp	1.446737
Temperature	-85.12933 °C
Cp	1.441723
Temperature	-84.15594 °C
Cp	1.436654
Temperature	-83.18256 °C
Cp	1.431684
Temperature	-82.20917 °C
Cp	1.426935
Temperature	-81.23578 °C
Cp	1.422396
Temperature	-80.2624 °C
Cp	1.418192
Temperature	-79.28901 °C
Cp	1.414363
Temperature	-78.31562 °C
Cp	1.410925
Temperature	-77.34224 °C
Cp	1.407865
Temperature	-76.36885 °C
Cp	1.405143
Temperature	-75.39546 °C
Cp	1.402789
Temperature	-74.42208 °C
Cp	1.400703
Temperature	-73.44869 °C
Cp	1.398837
Temperature	-72.4753 °C
Cp	1.397142
Temperature	-71.50192 °C
Cp	1.395565
Temperature	-70.52853 °C
Cp	1.394053
Temperature	-69.55515 °C
Cp	1.392558
Temperature	-68.58176 °C
Cp	1.391036
Temperature	-67.60838 °C
Cp	1.389483
Temperature	-66.63499 °C
Cp	1.387847
Temperature	-65.66161 °C
Cp	1.38616
Temperature	-64.68822 °C
Cp	1.384397
Temperature	-63.71483 °C
Cp	1.382535
Temperature	-62.74145 °C
Cp	1.380598
Temperature	-61.76806 °C
Cp	1.37865
Temperature	-60.79467 °C
Cp	1.376673
Temperature	-59.82129 °C
Cp	1.374677
Temperature	-58.8479 °C
Cp	1.372642
Temperature	-57.87452 °C
Cp	1.370686
Temperature	-56.90113 °C
Cp	1.368741
Temperature	-55.92775 °C
Cp	1.366786
Temperature	-54.95436 °C
Cp	1.364863
Temperature	-53.98097 °C
Cp	1.362959
Temperature	-53.00759 °C
Cp	1.361116
Temperature	-52.0342 °C
Cp	1.359247
Temperature	-51.06082 °C
Cp	1.357393
Temperature	-50.08743 °C
Cp	1.355593
Temperature	-49.11404 °C
Cp	1.353796
Temperature	-48.14066 °C
Cp	1.352008
Temperature	-47.16727 °C
Cp	1.350215
Temperature	-46.19389 °C
Cp	1.348396
Temperature	-45.2205 °C
Cp	1.346593
Temperature	-44.24712 °C
Cp	1.344755
Temperature	-43.27373 °C
Cp	1.342891
Temperature	-42.30034 °C
Cp	1.341008
Temperature	-41.32696 °C
Cp	1.339126
Temperature	-40.35357 °C
Cp	1.337236
Temperature	-39.38018 °C
Cp	1.335367
Temperature	-38.4068 °C
Cp	1.333522
Temperature	-37.43341 °C
Cp	1.331708
Temperature	-36.46003 °C
Cp	1.32991
Temperature	-35.48664 °C
Cp	1.328145
Temperature	-34.51326 °C
Cp	1.326414
Temperature	-33.53987 °C
Cp	1.32471
Temperature	-32.56648 °C
Cp	1.323012
Temperature	-31.5931 °C
Cp	1.321323
Temperature	-30.61971 °C
Cp	1.319657
Temperature	-29.64633 °C
Cp	1.317968
Temperature	-28.67294 °C
Cp	1.316286
Temperature	-27.69955 °C
Cp	1.314585
Temperature	-26.72617 °C
Cp	1.312857
Temperature	-25.75278 °C
Cp	1.31111
Temperature	-24.7794 °C
Cp	1.309333
Temperature	-23.80601 °C
Cp	1.307544
Temperature	-22.83262 °C
Cp	1.30575
Temperature	-21.85924 °C
Cp	1.303941
Temperature	-20.88585 °C
Cp	1.302132
Temperature	-19.91247 °C
Cp	1.300313
Temperature	-18.93908 °C
Cp	1.298512
Temperature	-17.96569 °C
Cp	1.296728
Temperature	-16.99231 °C
Cp	1.294939
Temperature	-16.01892 °C
Cp	1.293198
Temperature	-15.04554 °C
Cp	1.291453
Temperature	-14.07215 °C
Cp	1.289723
Temperature	-13.09876 °C
Cp	1.288007
Temperature	-12.12538 °C
Cp	1.286283
Temperature	-11.15199 °C
Cp	1.284578
Temperature	-10.17861 °C
Cp	1.282885
Temperature	-9.205221 °C
Cp	1.281173
Temperature	-8.231835 °C
Cp	1.279472
Temperature	-7.258449 °C
Cp	1.277766
Temperature	-6.285063 °C
Cp	1.276053
Temperature	-5.311677 °C
Cp	1.274341
Temperature	-4.338291 °C
Cp	1.272592
Temperature	-3.364905 °C
Cp	1.270844
Temperature	-2.391519 °C
Cp	1.269062
Temperature	-1.418133 °C
Cp	1.267264
Temperature	-0.4447474 °C
Cp	1.265435
Temperature	0.5286385 °C
Cp	1.263575
Temperature	1.502024 °C
Cp	1.261727
Temperature	2.47541 °C
Cp	1.259854
Temperature	3.448796 °C
Cp	1.257978
Temperature	4.422182 °C
Cp	1.256109
Temperature	5.395568 °C
Cp	1.254244
Temperature	6.368954 °C
Cp	1.252392
Temperature	7.34234 °C
Cp	1.250552
Temperature	8.315726 °C
Cp	1.248704
Temperature	9.289112 °C
Cp	1.246884
Temperature	10.2625 °C
Cp	1.245078
Temperature	11.23588 °C
Cp	1.243287
Temperature	12.20927 °C
Cp	1.241522
Temperature	13.18266 °C
Cp	1.239778
Temperature	14.15604 °C
Cp	1.238068
Temperature	15.12943 °C
Cp	1.236393
Temperature	16.10281 °C
Cp	1.234762
Temperature	17.0762 °C
Cp	1.233176
Temperature	18.04959 °C
Cp	1.231629
Temperature	19.02297 °C
Cp	1.230129
Temperature	19.99636 °C
Cp	1.228694
Temperature	20.96974 °C
Cp	1.22731
Temperature	21.94313 °C
Cp	1.225968
Temperature	22.91652 °C
Cp	1.224676
Temperature	23.8899 °C
Cp	1.223431
Temperature	24.86329 °C
Cp	1.222217
Temperature	25.83667 °C
Cp	1.221065
Temperature	26.81006 °C
Cp	1.219919
Temperature	27.78345 °C
Cp	1.218811
Temperature	28.75683 °C
Cp	1.21773
Temperature	29.73022 °C
Cp	1.216663
Temperature	30.7036 °C
Cp	1.2156
Temperature	31.67699 °C
Cp	1.214515
Temperature	32.65038 °C
Cp	1.213439
Temperature	33.62376 °C
Cp	1.21234
Temperature	34.59715 °C
Cp	1.211209
Temperature	35.57053 °C
Cp	1.210051
Temperature	36.54392 °C
Cp	1.208868
Temperature	37.5173 °C
Cp	1.207666
Temperature	38.49069 °C
Cp	1.206439
Temperature	39.46408 °C
Cp	1.205199
Temperature	40.43746 °C
Cp	1.203959
Temperature	41.41085 °C
Cp	1.202712
Temperature	42.38424 °C
Cp	1.20147
Temperature	43.35762 °C
Cp	1.200231
Temperature	44.33101 °C
Cp	1.199
Temperature	45.30439 °C
Cp	1.197777
Temperature	46.27778 °C
Cp	1.19657
Temperature	47.25116 °C
Cp	1.195367
Temperature	48.22455 °C
Cp	1.194179
Temperature	49.19794 °C
Cp	1.19301
Temperature	50.17132 °C
Cp	1.191849
Temperature	51.14471 °C
Cp	1.190694
Temperature	52.11809 °C
Cp	1.189555
Temperature	53.09148 °C
Cp	1.18843
Temperature	54.06487 °C
Cp	1.187311
Temperature	55.03825 °C
Cp	1.186195
Temperature	56.01164 °C
Cp	1.185095
Temperature	56.98502 °C
Cp	1.183997
Temperature	57.95841 °C
Cp	1.182894
Temperature	58.93179 °C
Cp	1.181793
Temperature	59.90518 °C
Cp	1.180693
Temperature	60.87857 °C
Cp	1.179595
Temperature	61.85195 °C
Cp	1.178501
Temperature	62.82534 °C
Cp	1.177406
Temperature	63.79873 °C
Cp	1.176313
Temperature	64.77211 °C
Cp	1.175239
Temperature	65.7455 °C
Cp	1.17417
Temperature	66.71888 °C
Cp	1.173105
Temperature	67.69227 °C
Cp	1.172037
Temperature	68.66566 °C
Cp	1.170989
Temperature	69.63904 °C
Cp	1.169948
Temperature	70.61243 °C
Cp	1.168905
Temperature	71.58582 °C
Cp	1.167872
Temperature	72.5592 °C
Cp	1.166849
Temperature	73.53259 °C
Cp	1.165851
Temperature	74.50597 °C
Cp	1.164848
Temperature	75.47935 °C
Cp	1.163876
Temperature	76.45274 °C
Cp	1.162926
Temperature	77.42612 °C
Cp	1.162008
Temperature	78.39951 °C
Cp	1.161113
Temperature	79.3729 °C
Cp	1.160219
Temperature	80.34628 °C
Cp	1.159377
Temperature	81.31967 °C
Cp	1.158546
Temperature	82.29306 °C
Cp	1.157726
Temperature	83.26644 °C
Cp	1.15692
Temperature	84.23983 °C
Cp	1.156126
Temperature	85.21322 °C
Cp	1.155375
Temperature	86.1866 °C
Cp	1.154604
Temperature	87.15999 °C
Cp	1.153869
Temperature	88.13337 °C
Cp	1.153158
Temperature	89.10676 °C
Cp	1.152474
Temperature	90.08015 °C
Cp	1.15181
Temperature	91.05353 °C
Cp	1.151134
Temperature	92.02692 °C
Cp	1.150513
Temperature	93.00031 °C
Cp	1.149892
Temperature	93.97369 °C
Cp	1.149266
Temperature	94.94707 °C
Cp	1.148642
Temperature	95.92046 °C
Cp	1.148019
Temperature	96.89384 °C
Cp	1.147402
Temperature	97.86723 °C
Cp	1.146799
Temperature	98.84062 °C
Cp	1.146191
Temperature	99.814 °C
Cp	1.145602
Temperature	100.7874 °C
Cp	1.14503
Temperature	101.7608 °C
Cp	1.144469
Temperature	102.7342 °C
Cp	1.143921
Temperature	103.7076 °C
Cp	1.143383
Temperature	104.6809 °C
Cp	1.142861
Temperature	105.6543 °C
Cp	1.142345
Temperature	106.6277 °C
Cp	1.141835
Temperature	107.6011 °C
Cp	1.141335
Temperature	108.5745 °C
Cp	1.140846
Temperature	109.5479 °C
Cp	1.140365
Temperature	110.5212 °C
Cp	1.139891
Temperature	111.4946 °C
Cp	1.139429
Temperature	112.468 °C
Cp	1.138976
Temperature	113.4414 °C
Cp	1.13853
Temperature	114.4148 °C
Cp	1.138092
Temperature	115.3882 °C
Cp	1.137654
Temperature	116.3616 °C
Cp	1.137223
Temperature	117.335 °C
Cp	1.136785
Temperature	118.3083 °C
Cp	1.136338
Temperature	119.2817 °C
Cp	1.13588
Temperature	120.2551 °C
Cp	1.13541
Temperature	121.2285 °C
Cp	1.134927
Temperature	122.2019 °C
Cp	1.134417
Temperature	123.1753 °C
Cp	1.133892
Temperature	124.1487 °C
Cp	1.133347
Temperature	125.122 °C
Cp	1.132786
Temperature	126.0954 °C
Cp	1.132206
Temperature	127.0688 °C
Cp	1.131606
Temperature	128.0422 °C
Cp	1.130999
Temperature	129.0156 °C
Cp	1.130384
Temperature	129.989 °C
Cp	1.129765
Temperature	130.9624 °C
Cp	1.129147
Temperature	131.9357 °C
Cp	1.12854
Temperature	132.9091 °C
Cp	1.127949
Temperature	133.8825 °C
Cp	1.127383
Temperature	134.8559 °C
Cp	1.126841
Temperature	135.8293 °C
Cp	1.126334
Temperature	136.8027 °C
Cp	1.125871
Temperature	137.7761 °C
Cp	1.125443
Temperature	138.7494 °C
Cp	1.125058
Temperature	139.7228 °C
Cp	1.124701
Temperature	140.6962 °C
Cp	1.124397
Temperature	141.6696 °C
Cp	1.124114
Temperature	142.643 °C
Cp	1.123854
Temperature	143.6164 °C
Cp	1.123612
Temperature	144.5898 °C
Cp	1.123385
Temperature	145.5631 °C
Cp	1.123182
Temperature	146.5365 °C
Cp	1.12296
Temperature	147.5099 °C
Cp	1.12275
Temperature	148.4833 °C
Cp	1.122543
Temperature	149.4567 °C
Cp	1.122327
Temperature	150.4301 °C
Cp	1.122099
Temperature	151.4035 °C
Cp	1.121837
Temperature	152.3768 °C
Cp	1.121582
Temperature	153.3502 °C
Cp	1.121289
Temperature	154.3236 °C
Cp	1.120967
Temperature	155.297 °C
Cp	1.120616
Temperature	156.2704 °C
Cp	1.120238
Temperature	157.2438 °C
Cp	1.119862
Temperature	158.2172 °C
Cp	1.119444
Temperature	159.1906 °C
Cp	1.119028
Temperature	160.1639 °C
Cp	1.118613
Temperature	161.1373 °C
Cp	1.118202
Temperature	162.1107 °C
Cp	1.117795
Temperature	163.0841 °C
Cp	1.117374
Temperature	164.0575 °C
Cp	1.116987
Temperature	165.0309 °C
Cp	1.116595
Temperature	166.0042 °C
Cp	1.116198
Temperature	166.9776 °C
Cp	1.1158
Temperature	167.951 °C
Cp	1.115402
Temperature	168.9244 °C
Cp	1.115006
Temperature	169.8978 °C
Cp	1.11462
Temperature	170.8712 °C
Cp	1.114223
Temperature	171.8446 °C
Cp	1.113836
Temperature	172.8179 °C
Cp	1.113458
Temperature	173.7913 °C
Cp	1.113085
Temperature	174.7647 °C
Cp	1.112712
Temperature	175.7381 °C
Cp	1.112323
Temperature	176.7115 °C
Cp	1.111957
Temperature	177.6849 °C
Cp	1.111578
Temperature	178.6583 °C
Cp	1.111185
Temperature	179.6317 °C
Cp	1.110789
Temperature	180.605 °C
Cp	1.110391
Temperature	181.5784 °C
Cp	1.110016
Temperature	182.5518 °C
Cp	1.109611
Temperature	183.5252 °C
Cp	1.109232
Temperature	184.4986 °C
Cp	1.108873
Temperature	185.472 °C
Cp	1.108531
Temperature	186.4454 °C
Cp	1.108199
Temperature	187.4187 °C
Cp	1.107851
Temperature	188.3921 °C
Cp	1.107551
Temperature	189.3655 °C
Cp	1.107238
Temperature	190.3389 °C
Cp	1.106917
Temperature	191.3123 °C
Cp	1.106589
Temperature	192.2857 °C
Cp	1.106259
Temperature	193.259 °C
Cp	1.105958
Temperature	194.2324 °C
Cp	1.105619
Temperature	195.2058 °C
Cp	1.105301
Temperature	196.1792 °C
Cp	1.105002
Temperature	197.1526 °C
Cp	1.104718
Temperature	198.126 °C
Cp	1.104445
Temperature	199.0994 °C
Cp	1.104161
Temperature	200.0728 °C
Cp	1.103914
Temperature	201.0461 °C
Cp	1.103657
Temperature	202.0195 °C
Cp	1.103395
Temperature	202.9929 °C
Cp	1.103125
Temperature	203.9663 °C
Cp	1.102847
Temperature	204.9397 °C
Cp	1.102563
Temperature	205.9131 °C
Cp	1.102283
Temperature	206.8865 °C
Cp	1.101985
Temperature	207.8598 °C
Cp	1.10169
Temperature	208.8332 °C
Cp	1.101394
Temperature	209.8066 °C
Cp	1.101099
Temperature	210.78 °C
Cp	1.1008
Temperature	211.7534 °C
Cp	1.10049
Temperature	212.7268 °C
Cp	1.100193
Temperature	213.7002 °C
Cp	1.099886
Temperature	214.6735 °C
Cp	1.099577
Temperature	215.6469 °C
Cp	1.099268
Temperature	216.6203 °C
Cp	1.098965
Temperature	217.5937 °C
Cp	1.098685
Temperature	218.5671 °C
Cp	1.098396
Temperature	219.5405 °C
Cp	1.098134
Temperature	220.5139 °C
Cp	1.097895
Temperature	221.4872 °C
Cp	1.09768
Temperature	222.4606 °C
Cp	1.097485
Temperature	223.434 °C
Cp	1.097292
Temperature	224.4074 °C
Cp	1.09714
Temperature	225.3808 °C
Cp	1.096991
Temperature	226.3542 °C
Cp	1.096844
Temperature	227.3276 °C
Cp	1.096699
Temperature	228.3009 °C
Cp	1.096559
Temperature	229.2743 °C
Cp	1.096442
Temperature	230.2477 °C
Cp	1.096296
Temperature	231.2211 °C
Cp	1.096164
Temperature	232.1945 °C
Cp	1.09604
Temperature	233.1679 °C
Cp	1.095924
Temperature	234.1413 °C
Cp	1.095807
Temperature	235.1147 °C
Cp	1.095665
Temperature	236.088 °C
Cp	1.095557
Temperature	237.0614 °C
Cp	1.095433
Temperature	238.0348 °C
Cp	1.095296
Temperature	239.0082 °C
Cp	1.095147
Temperature	239.9816 °C
Cp	1.094995
Temperature	240.955 °C
Cp	1.094843
Temperature	241.9283 °C
Cp	1.094705
Temperature	242.9017 °C
Cp	1.094562
Temperature	243.8751 °C
Cp	1.094442
Temperature	244.8485 °C
Cp	1.094344
Temperature	245.8219 °C
Cp	1.094266
Temperature	246.7953 °C
Cp	1.094209
Temperature	247.7687 °C
Cp	1.094161
Temperature	248.7421 °C
Cp	1.094144
Temperature	249.7154 °C
Cp	1.094133
Temperature	250.6888 °C
Cp	1.094127
Temperature	251.6622 °C
Cp	1.094126
Temperature	252.6356 °C
Cp	1.094127
Temperature	253.609 °C
Cp	1.094138
Temperature	254.5824 °C
Cp	1.09413
Temperature	255.5558 °C
Cp	1.094123
Temperature	256.5291 °C
Cp	1.094111
Temperature	257.5025 °C
Cp	1.094087
Temperature	258.4759 °C
Cp	1.094046
Temperature	259.4493 °C
Cp	1.093978
Temperature	260.4227 °C
Cp	1.093895
Temperature	261.3961 °C
Cp	1.093783
Temperature	262.3694 °C
Cp	1.093645
Temperature	263.3428 °C
Cp	1.093483
Temperature	264.3162 °C
Cp	1.093302
Temperature	265.2896 °C
Cp	1.093109
Temperature	266.263 °C
Cp	1.092906
Temperature	267.2364 °C
Cp	1.092704
Temperature	268.2098 °C
Cp	1.092511
Temperature	269.1832 °C
Cp	1.092331
Temperature	270.1566 °C
Cp	1.092174
Temperature	271.1299 °C
Cp	1.092046
Temperature	272.1033 °C
Cp	1.091947
Temperature	273.0767 °C
Cp	1.091882
Temperature	274.0501 °C
Cp	1.091853
Temperature	275.0235 °C
Cp	1.091859
Temperature	275.9969 °C
Cp	1.091895
Temperature	276.9702 °C
Cp	1.091957
Temperature	277.9436 °C
Cp	1.092036
Temperature	278.917 °C
Cp	1.092132
Temperature	279.8904 °C
Cp	1.09223
Temperature	280.8638 °C
Cp	1.092323
Temperature	281.8372 °C
Cp	1.092405
Temperature	282.8105 °C
Cp	1.092468
Temperature	283.7839 °C
Cp	1.092513
Temperature	284.7573 °C
Cp	1.092525
Temperature	285.7307 °C
Cp	1.092512
Temperature	286.7041 °C
Cp	1.092472
Temperature	287.6775 °C
Cp	1.092405
Temperature	288.6509 °C
Cp	1.092313
Temperature	289.6243 °C
Cp	1.092197
Temperature	290.5977 °C
Cp	1.09207
Temperature	291.571 °C
Cp	1.091931
Temperature	292.5444 °C
Cp	1.091785
Temperature	293.5178 °C
Cp	1.091641
Temperature	294.4912 °C
Cp	1.091506
Temperature	295.4646 °C
Cp	1.091387
Temperature	296.438 °C
Cp	1.091282
Temperature	297.4113 °C
Cp	1.091201
Temperature	298.3847 °C
Cp	1.091145
Temperature	299.3581 °C
Cp	1.091112
Temperature	300.3315 °C
Cp	1.091102
Temperature	301.3049 °C
Cp	1.091107
Temperature	302.2783 °C
Cp	1.091137
Temperature	303.2517 °C
Cp	1.091177
Temperature	304.2251 °C
Cp	1.091226
Temperature	305.1984 °C
Cp	1.09128
Temperature	306.1718 °C
Cp	1.091336
Temperature	307.1452 °C
Cp	1.091403
Temperature	308.1186 °C
Cp	1.091453
Temperature	309.092 °C
Cp	1.091506
Temperature	310.0654 °C
Cp	1.091561
Temperature	311.0388 °C
Cp	1.091617
Temperature	312.0121 °C
Cp	1.09167
Temperature	312.9855 °C
Cp	1.091716
Temperature	313.9589 °C
Cp	1.091762
Temperature	314.9323 °C
Cp	1.091805
Temperature	315.9057 °C
Cp	1.091838
Temperature	316.8791 °C
Cp	1.09186
Temperature	317.8524 °C
Cp	1.091871
Temperature	318.8258 °C
Cp	1.091872
Temperature	319.7992 °C
Cp	1.091867
Temperature	320.7726 °C
Cp	1.091838
Temperature	321.746 °C
Cp	1.0918
Temperature	322.7194 °C
Cp	1.091752
Temperature	323.6928 °C
Cp	1.091689
Temperature	324.6662 °C
Cp	1.091611
Temperature	325.6396 °C
Cp	1.091508
Temperature	326.6129 °C
Cp	1.091406
Temperature	327.5863 °C
Cp	1.091285
Temperature	328.5597 °C
Cp	1.09115
Temperature	329.5331 °C
Cp	1.091009
Temperature	330.5065 °C
Cp	1.09087
Temperature	331.4799 °C
Cp	1.090747
Temperature	332.4532 °C
Cp	1.090628
Temperature	333.4266 °C
Cp	1.090536
Temperature	334.4 °C
Cp	1.090472
Temperature	335.3734 °C
Cp	1.090437
Temperature	336.3468 °C
Cp	1.090431
Temperature	337.3202 °C
Cp	1.090455
Temperature	338.2935 °C
Cp	1.090503
Temperature	339.2669 °C
Cp	1.090573
Temperature	340.2403 °C
Cp	1.090658
Temperature	341.2137 °C
Cp	1.090753
Temperature	342.1871 °C
Cp	1.090853
Temperature	343.1605 °C
Cp	1.090952
Temperature	344.1339 °C
Cp	1.09105
Temperature	345.1073 °C
Cp	1.091141
Temperature	346.0807 °C
Cp	1.091225
Temperature	347.054 °C
Cp	1.091303
Temperature	348.0274 °C
Cp	1.091379
Temperature	349.0008 °C
Cp	1.091453
Temperature	349.9742 °C
Cp	1.091537
Temperature	350.9476 °C
Cp	1.091633
Temperature	351.921 °C
Cp	1.091743
Temperature	352.8943 °C
Cp	1.091874
Temperature	353.8677 °C
Cp	1.092028
Temperature	354.8411 °C
Cp	1.092206
Temperature	355.8145 °C
Cp	1.092411
Temperature	356.7879 °C
Cp	1.092628
Temperature	357.7613 °C
Cp	1.092862
Temperature	358.7346 °C
Cp	1.093102
Temperature	359.708 °C
Cp	1.093338
Temperature	360.6814 °C
Cp	1.093559
Temperature	361.6548 °C
Cp	1.093752
Temperature	362.6282 °C
Cp	1.093915
Temperature	363.6016 °C
Cp	1.094036
Temperature	364.575 °C
Cp	1.094117
Temperature	365.5484 °C
Cp	1.094159
Temperature	366.5218 °C
Cp	1.094172
Temperature	367.4951 °C
Cp	1.094165
Temperature	368.4685 °C
Cp	1.094163
Temperature	369.4419 °C
Cp	1.094182
Temperature	370.4153 °C
Cp	1.094244
Temperature	371.3887 °C
Cp	1.094375
Temperature	372.3621 °C
Cp	1.094598
Temperature	373.3354 °C
Cp	1.094937
Temperature	374.3088 °C
Cp	1.095389
Temperature	375.2822 °C
Cp	1.095973
Temperature	376.2556 °C
Cp	1.096685
Temperature	377.229 °C
Cp	1.097506
Temperature	378.2024 °C
Cp	1.098406
Temperature	379.1758 °C
Cp	1.099338
Temperature	380.1492 °C
Cp	1.10027
Temperature	381.1225 °C
Cp	1.10112
Temperature	382.0959 °C
Cp	1.101818
Temperature	383.0693 °C
Cp	1.10229
Temperature	384.0427 °C
Cp	1.102459
Temperature	385.0161 °C
Cp	1.102253
Temperature	385.9895 °C
Cp	1.101596
Temperature	386.9629 °C
Cp	1.100438
Temperature	387.9362 °C
Cp	1.098736
Temperature	388.9096 °C
Cp	1.096461
Temperature	389.883 °C
Cp	1.093614
Temperature	390.8564 °C
Cp	1.090208
Temperature	391.8298 °C
Cp	1.086278
Temperature	392.8032 °C
Cp	1.081887
Temperature	393.7766 °C
Cp	1.077096
Temperature	394.7499 °C
Cp	1.072007
Temperature	395.7233 °C
Cp	1.066707
[Rev Cp Calibration]
Date Applied	24/10/2024 12:37:31
Description	From -89.998 °C to 390.542 °C at 2.000°C/min
Gas Type	Nitrogen
Pan Type	Tzero Aluminum
Source Files 1	C:\ProgramData\TA Instruments\TRIOS\Data\Reverse Heat Capacity Calibration(6).tri
GUID	ba867d72-cfbb-486e-971e-e86aa544cc02
Temperature	-89.99799 °C
Cp	1.070076
Temperature	-89.03691 °C
Cp	1.072008
Temperature	-88.07584 °C
Cp	1.073556
Temperature	-87.11475 °C
Cp	1.074743
Temperature	-86.15367 °C
Cp	1.075597
Temperature	-85.1926 °C
Cp	1.076163
Temperature	-84.23151 °C
Cp	1.076477
Temperature	-83.27043 °C
Cp	1.076579
Temperature	-82.30936 °C
Cp	1.076527
Temperature	-81.34827 °C
Cp	1.076322
Temperature	-80.38719 °C
Cp	1.076039
Temperature	-79.42612 °C
Cp	1.07571
Temperature	-78.46503 °C
Cp	1.075361
Temperature	-77.50395 °C
Cp	1.075011
Temperature	-76.54288 °C
Cp	1.074656
Temperature	-75.58179 °C
Cp	1.074359
Temperature	-74.62071 °C
Cp	1.074086
Temperature	-73.65964 °C
Cp	1.073842
Temperature	-72.69855 °C
Cp	1.073627
Temperature	-71.73747 °C
Cp	1.073442
Temperature	-70.7764 °C
Cp	1.07329
Temperature	-69.81532 °C
Cp	1.073148
Temperature	-68.85423 °C
Cp	1.073021
Temperature	-67.89315 °C
Cp	1.072902
Temperature	-66.93208 °C
Cp	1.072782
Temperature	-65.97099 °C
Cp	1.072656
Temperature	-65.00991 °C
Cp	1.072518
Temperature	-64.04884 °C
Cp	1.072374
Temperature	-63.08775 °C
Cp	1.072201
Temperature	-62.12667 °C
Cp	1.072019
Temperature	-61.1656 °C
Cp	1.071827
Temperature	-60.20451 °C
Cp	1.071624
Temperature	-59.24343 °C
Cp	1.071411
Temperature	-58.28236 °C
Cp	1.071167
Temperature	-57.32127 °C
Cp	1.070956
Temperature	-56.3602 °C
Cp	1.070724
Temperature	-55.39911 °C
Cp	1.070483
Temperature	-54.43803 °C
Cp	1.070242
Temperature	-53.47696 °C
Cp	1.070009
Temperature	-52.51587 °C
Cp	1.069825
Temperature	-51.55479 °C
Cp	1.069601
Temperature	-50.59372 °C
Cp	1.069418
Temperature	-49.63263 °C
Cp	1.069267
Temperature	-48.67155 °C
Cp	1.069138
Temperature	-47.71048 °C
Cp	1.069021
Temperature	-46.74939 °C
Cp	1.068875
Temperature	-45.78831 °C
Cp	1.068771
Temperature	-44.82724 °C
Cp	1.068634
Temperature	-43.86615 °C
Cp	1.068462
Temperature	-42.90508 °C
Cp	1.068255
Temperature	-41.944 °C
Cp	1.068012
Temperature	-40.98291 °C
Cp	1.067742
Temperature	-40.02184 °C
Cp	1.067427
Temperature	-39.06076 °C
Cp	1.067088
Temperature	-38.09967 °C
Cp	1.066727
Temperature	-37.1386 °C
Cp	1.066349
Temperature	-36.17752 °C
Cp	1.065958
Temperature	-35.21643 °C
Cp	1.065559
Temperature	-34.25536 °C
Cp	1.065162
Temperature	-33.29427 °C
Cp	1.06476
Temperature	-32.33319 °C
Cp	1.064368
Temperature	-31.37212 °C
Cp	1.06399
Temperature	-30.41104 °C
Cp	1.063628
Temperature	-29.44995 °C
Cp	1.063283
Temperature	-28.48887 °C
Cp	1.06295
Temperature	-27.5278 °C
Cp	1.062645
Temperature	-26.56672 °C
Cp	1.062355
Temperature	-25.60563 °C
Cp	1.06208
Temperature	-24.64456 °C
Cp	1.061819
Temperature	-23.68348 °C
Cp	1.061573
Temperature	-22.72239 °C
Cp	1.061345
Temperature	-21.76132 °C
Cp	1.061123
Temperature	-20.80024 °C
Cp	1.060915
Temperature	-19.83916 °C
Cp	1.060719
Temperature	-18.87807 °C
Cp	1.060531
Temperature	-17.917 °C
Cp	1.06035
Temperature	-16.95592 °C
Cp	1.060161
Temperature	-15.99484 °C
Cp	1.059992
Temperature	-15.03376 °C
Cp	1.059817
Temperature	-14.07268 °C
Cp	1.059634
Temperature	-13.1116 °C
Cp	1.059445
Temperature	-12.15052 °C
Cp	1.059248
Temperature	-11.18944 °C
Cp	1.059043
Temperature	-10.22836 °C
Cp	1.058842
Temperature	-9.267276 °C
Cp	1.058615
Temperature	-8.306196 °C
Cp	1.058388
Temperature	-7.345116 °C
Cp	1.058155
Temperature	-6.384036 °C
Cp	1.057911
Temperature	-5.422956 °C
Cp	1.057652
Temperature	-4.461876 °C
Cp	1.057356
Temperature	-3.500796 °C
Cp	1.057063
Temperature	-2.539716 °C
Cp	1.056732
Temperature	-1.578636 °C
Cp	1.056364
Temperature	-0.6175562 °C
Cp	1.05596
Temperature	0.3435238 °C
Cp	1.055523
Temperature	1.304604 °C
Cp	1.055066
Temperature	2.265684 °C
Cp	1.054561
Temperature	3.226764 °C
Cp	1.054035
Temperature	4.187844 °C
Cp	1.053488
Temperature	5.148924 °C
Cp	1.052922
Temperature	6.110003 °C
Cp	1.052337
Temperature	7.071084 °C
Cp	1.051736
Temperature	8.032164 °C
Cp	1.051118
Temperature	8.993243 °C
Cp	1.050488
Temperature	9.954324 °C
Cp	1.049848
Temperature	10.9154 °C
Cp	1.049202
Temperature	11.87648 °C
Cp	1.048552
Temperature	12.83756 °C
Cp	1.047902
Temperature	13.79864 °C
Cp	1.047255
Temperature	14.75972 °C
Cp	1.046615
Temperature	15.7208 °C
Cp	1.045983
Temperature	16.68188 °C
Cp	1.045362
Temperature	17.64296 °C
Cp	1.044756
Temperature	18.60404 °C
Cp	1.044164
Temperature	19.56512 °C
Cp	1.04358
Temperature	20.5262 °C
Cp	1.043027
Temperature	21.48728 °C
Cp	1.042485
Temperature	22.44836 °C
Cp	1.041958
Temperature	23.40944 °C
Cp	1.041446
Temperature	24.37052 °C
Cp	1.040952
Temperature	25.3316 °C
Cp	1.040493
Temperature	26.29268 °C
Cp	1.040022
Temperature	27.25376 °C
Cp	1.039578
Temperature	28.21484 °C
Cp	1.039158
Temperature	29.17592 °C
Cp	1.038758
Temperature	30.137 °C
Cp	1.038373
Temperature	31.09808 °C
Cp	1.037981
Temperature	32.05916 °C
Cp	1.03763
Temperature	33.02024 °C
Cp	1.037276
Temperature	33.98132 °C
Cp	1.03692
Temperature	34.9424 °C
Cp	1.036565
Temperature	35.90348 °C
Cp	1.036213
Temperature	36.86456 °C
Cp	1.035866
Temperature	37.82564 °C
Cp	1.035529
Temperature	38.78672 °C
Cp	1.035195
Temperature	39.7478 °C
Cp	1.034875
Temperature	40.70888 °C
Cp	1.034568
Temperature	41.66996 °C
Cp	1.034276
Temperature	42.63104 °C
Cp	1.033996
Temperature	43.59212 °C
Cp	1.033726
Temperature	44.5532 °C
Cp	1.033469
Temperature	45.51428 °C
Cp	1.033221
Temperature	46.47536 °C
Cp	1.03298
Temperature	47.43644 °C
Cp	1.032744
Temperature	48.39752 °C
Cp	1.032514
Temperature	49.3586 °C
Cp	1.032289
Temperature	50.31968 °C
Cp	1.032065
Temperature	51.28076 °C
Cp	1.031844
Temperature	52.24184 °C
Cp	1.031627
Temperature	53.20292 °C
Cp	1.031413
Temperature	54.164 °C
Cp	1.031203
Temperature	55.12508 °C
Cp	1.030989
Temperature	56.08616 °C
Cp	1.030791
Temperature	57.04724 °C
Cp	1.030595
Temperature	58.00832 °C
Cp	1.030403
Temperature	58.9694 °C
Cp	1.030217
Temperature	59.93048 °C
Cp	1.03004
Temperature	60.89156 °C
Cp	1.029871
Temperature	61.85264 °C
Cp	1.029718
Temperature	62.81372 °C
Cp	1.029567
Temperature	63.7748 °C
Cp	1.02943
Temperature	64.73589 °C
Cp	1.029304
Temperature	65.69696 °C
Cp	1.029185
Temperature	66.65804 °C
Cp	1.02907
Temperature	67.61913 °C
Cp	1.028946
Temperature	68.5802 °C
Cp	1.028831
Temperature	69.54128 °C
Cp	1.028703
Temperature	70.50237 °C
Cp	1.028561
Temperature	71.46344 °C
Cp	1.028404
Temperature	72.42452 °C
Cp	1.028234
Temperature	73.3856 °C
Cp	1.028063
Temperature	74.34668 °C
Cp	1.027861
Temperature	75.30776 °C
Cp	1.027657
Temperature	76.26884 °C
Cp	1.027451
Temperature	77.22992 °C
Cp	1.027243
Temperature	78.191 °C
Cp	1.027036
Temperature	79.15208 °C
Cp	1.026812
Temperature	80.11316 °C
Cp	1.026623
Temperature	81.07424 °C
Cp	1.026431
Temperature	82.03532 °C
Cp	1.026241
Temperature	82.9964 °C
Cp	1.02606
Temperature	83.95748 °C
Cp	1.025891
Temperature	84.91856 °C
Cp	1.025739
Temperature	85.87964 °C
Cp	1.025614
Temperature	86.84072 °C
Cp	1.025493
Temperature	87.8018 °C
Cp	1.0254
Temperature	88.76288 °C
Cp	1.025329
Temperature	89.72396 °C
Cp	1.025274
Temperature	90.68504 °C
Cp	1.025229
Temperature	91.64612 °C
Cp	1.025174
Temperature	92.6072 °C
Cp	1.025138
Temperature	93.56828 °C
Cp	1.025083
Temperature	94.52936 °C
Cp	1.025008
Temperature	95.49044 °C
Cp	1.024912
Temperature	96.45152 °C
Cp	1.024796
Temperature	97.4126 °C
Cp	1.024671
Temperature	98.37368 °C
Cp	1.024506
Temperature	99.33476 °C
Cp	1.02433
Temperature	100.2958 °C
Cp	1.024144
Temperature	101.2569 °C
Cp	1.023948
Temperature	102.218 °C
Cp	1.023743
Temperature	103.1791 °C
Cp	1.023522
Temperature	104.1402 °C
Cp	1.023309
Temperature	105.1012 °C
Cp	1.023089
Temperature	106.0623 °C
Cp	1.022866
Temperature	107.0234 °C
Cp	1.022644
Temperature	107.9845 °C
Cp	1.022427
Temperature	108.9456 °C
Cp	1.022218
Temperature	109.9066 °C
Cp	1.022022
Temperature	110.8677 °C
Cp	1.021836
Temperature	111.8288 °C
Cp	1.021666
Temperature	112.7899 °C
Cp	1.021512
Temperature	113.751 °C
Cp	1.021374
Temperature	114.712 °C
Cp	1.02125
Temperature	115.6731 °C
Cp	1.021137
Temperature	116.6342 °C
Cp	1.021041
Temperature	117.5953 °C
Cp	1.020953
Temperature	118.5564 °C
Cp	1.020872
Temperature	119.5174 °C
Cp	1.020796
Temperature	120.4785 °C
Cp	1.020725
Temperature	121.4396 °C
Cp	1.020659
Temperature	122.4007 °C
Cp	1.020587
Temperature	123.3618 °C
Cp	1.020515
Temperature	124.3228 °C
Cp	1.02044
Temperature	125.2839 °C
Cp	1.020359
Temperature	126.245 °C
Cp	1.02027
Temperature	127.2061 °C
Cp	1.020167
Temperature	128.1672 °C
Cp	1.020057
Temperature	129.1282 °C
Cp	1.019933
Temperature	130.0893 °C
Cp	1.019793
Temperature	131.0504 °C
Cp	1.019638
Temperature	132.0115 °C
Cp	1.019471
Temperature	132.9726 °C
Cp	1.019292
Temperature	133.9336 °C
Cp	1.019107
Temperature	134.8947 °C
Cp	1.018912
Temperature	135.8558 °C
Cp	1.018717
Temperature	136.8169 °C
Cp	1.018527
Temperature	137.778 °C
Cp	1.018344
Temperature	138.739 °C
Cp	1.018171
Temperature	139.7001 °C
Cp	1.018004
Temperature	140.6612 °C
Cp	1.01787
Temperature	141.6223 °C
Cp	1.01775
Temperature	142.5834 °C
Cp	1.017652
Temperature	143.5444 °C
Cp	1.017578
Temperature	144.5055 °C
Cp	1.017534
Temperature	145.4666 °C
Cp	1.017536
Temperature	146.4277 °C
Cp	1.017545
Temperature	147.3888 °C
Cp	1.017595
Temperature	148.3498 °C
Cp	1.017679
Temperature	149.3109 °C
Cp	1.01779
Temperature	150.272 °C
Cp	1.01792
Temperature	151.2331 °C
Cp	1.018043
Temperature	152.1942 °C
Cp	1.018199
Temperature	153.1552 °C
Cp	1.018339
Temperature	154.1163 °C
Cp	1.018458
Temperature	155.0774 °C
Cp	1.018552
Temperature	156.0385 °C
Cp	1.018618
Temperature	156.9996 °C
Cp	1.018662
Temperature	157.9606 °C
Cp	1.018664
Temperature	158.9217 °C
Cp	1.018632
Temperature	159.8828 °C
Cp	1.018575
Temperature	160.8439 °C
Cp	1.018492
Temperature	161.805 °C
Cp	1.018383
Temperature	162.766 °C
Cp	1.01825
Temperature	163.7271 °C
Cp	1.018087
Temperature	164.6882 °C
Cp	1.017917
Temperature	165.6493 °C
Cp	1.017726
Temperature	166.6104 °C
Cp	1.017522
Temperature	167.5714 °C
Cp	1.01731
Temperature	168.5325 °C
Cp	1.017098
Temperature	169.4936 °C
Cp	1.016902
Temperature	170.4547 °C
Cp	1.016695
Temperature	171.4158 °C
Cp	1.016508
Temperature	172.3768 °C
Cp	1.016342
Temperature	173.3379 °C
Cp	1.016195
Temperature	174.299 °C
Cp	1.016065
Temperature	175.2601 °C
Cp	1.015927
Temperature	176.2212 °C
Cp	1.015838
Temperature	177.1822 °C
Cp	1.015746
Temperature	178.1433 °C
Cp	1.015651
Temperature	179.1044 °C
Cp	1.015555
Temperature	180.0655 °C
Cp	1.015459
Temperature	181.0266 °C
Cp	1.015401
Temperature	181.9876 °C
Cp	1.015288
Temperature	182.9487 °C
Cp	1.015195
Temperature	183.9098 °C
Cp	1.015117
Temperature	184.8709 °C
Cp	1.01505
Temperature	185.832 °C
Cp	1.014988
Temperature	186.793 °C
Cp	1.014927
Temperature	187.7541 °C
Cp	1.014849
Temperature	188.7152 °C
Cp	1.014789
Temperature	189.6763 °C
Cp	1.01471
Temperature	190.6374 °C
Cp	1.014614
Temperature	191.5984 °C
Cp	1.014503
Temperature	192.5595 °C
Cp	1.014381
Temperature	193.5206 °C
Cp	1.014268
Temperature	194.4817 °C
Cp	1.014122
Temperature	195.4428 °C
Cp	1.013984
Temperature	196.4038 °C
Cp	1.013853
Temperature	197.3649 °C
Cp	1.013726
Temperature	198.326 °C
Cp	1.013603
Temperature	199.2871 °C
Cp	1.013467
Temperature	200.2482 °C
Cp	1.013359
Temperature	201.2092 °C
Cp	1.013243
Temperature	202.1703 °C
Cp	1.013123
Temperature	203.1314 °C
Cp	1.013002
Temperature	204.0925 °C
Cp	1.012884
Temperature	205.0536 °C
Cp	1.012788
Temperature	206.0146 °C
Cp	1.012674
Temperature	206.9757 °C
Cp	1.012579
Temperature	207.9368 °C
Cp	1.012501
Temperature	208.8979 °C
Cp	1.012439
Temperature	209.859 °C
Cp	1.012389
Temperature	210.82 °C
Cp	1.012351
Temperature	211.7811 °C
Cp	1.012312
Temperature	212.7422 °C
Cp	1.01229
Temperature	213.7033 °C
Cp	1.012262
Temperature	214.6644 °C
Cp	1.012227
Temperature	215.6254 °C
Cp	1.012183
Temperature	216.5865 °C
Cp	1.012129
Temperature	217.5476 °C
Cp	1.012077
Temperature	218.5087 °C
Cp	1.01199
Temperature	219.4698 °C
Cp	1.011897
Temperature	220.4308 °C
Cp	1.011793
Temperature	221.3919 °C
Cp	1.011674
Temperature	222.353 °C
Cp	1.011537
Temperature	223.3141 °C
Cp	1.011362
Temperature	224.2752 °C
Cp	1.011194
Temperature	225.2362 °C
Cp	1.010993
Temperature	226.1973 °C
Cp	1.010766
Temperature	227.1584 °C
Cp	1.010517
Temperature	228.1195 °C
Cp	1.010251
Temperature	229.0806 °C
Cp	1.009998
Temperature	230.0416 °C
Cp	1.009703
Temperature	231.0027 °C
Cp	1.009422
Temperature	231.9638 °C
Cp	1.009156
Temperature	232.9249 °C
Cp	1.008906
Temperature	233.886 °C
Cp	1.008675
Temperature	234.847 °C
Cp	1.008462
Temperature	235.8081 °C
Cp	1.008258
Temperature	236.7692 °C
Cp	1.00809
Temperature	237.7303 °C
Cp	1.007934
Temperature	238.6914 °C
Cp	1.007793
Temperature	239.6524 °C
Cp	1.007668
Temperature	240.6135 °C
Cp	1.007562
Temperature	241.5746 °C
Cp	1.007487
Temperature	242.5357 °C
Cp	1.00741
Temperature	243.4967 °C
Cp	1.00736
Temperature	244.4578 °C
Cp	1.007332
Temperature	245.4189 °C
Cp	1.007321
Temperature	246.38 °C
Cp	1.007321
Temperature	247.3411 °C
Cp	1.007312
Temperature	248.3022 °C
Cp	1.007331
Temperature	249.2632 °C
Cp	1.007338
Temperature	250.2243 °C
Cp	1.007335
Temperature	251.1854 °C
Cp	1.00732
Temperature	252.1465 °C
Cp	1.007295
Temperature	253.1076 °C
Cp	1.007277
Temperature	254.0686 °C
Cp	1.007227
Temperature	255.0297 °C
Cp	1.007179
Temperature	255.9908 °C
Cp	1.007133
Temperature	256.9519 °C
Cp	1.00709
Temperature	257.913 °C
Cp	1.007049
Temperature	258.874 °C
Cp	1.007012
Temperature	259.8351 °C
Cp	1.006978
Temperature	260.7962 °C
Cp	1.006956
Temperature	261.7573 °C
Cp	1.00694
Temperature	262.7184 °C
Cp	1.006934
Temperature	263.6794 °C
Cp	1.006939
Temperature	264.6405 °C
Cp	1.00696
Temperature	265.6016 °C
Cp	1.006999
Temperature	266.5627 °C
Cp	1.007054
Temperature	267.5237 °C
Cp	1.007131
Temperature	268.4848 °C
Cp	1.00723
Temperature	269.4459 °C
Cp	1.00735
Temperature	270.407 °C
Cp	1.007493
Temperature	271.3681 °C
Cp	1.007656
Temperature	272.3292 °C
Cp	1.007839
Temperature	273.2902 °C
Cp	1.008039
Temperature	274.2513 °C
Cp	1.008257
Temperature	275.2124 °C
Cp	1.008488
Temperature	276.1735 °C
Cp	1.008731
Temperature	277.1346 °C
Cp	1.008977
Temperature	278.0956 °C
Cp	1.009237
Temperature	279.0567 °C
Cp	1.009498
Temperature	280.0178 °C
Cp	1.009757
Temperature	280.9789 °C
Cp	1.010014
Temperature	281.9399 °C
Cp	1.010267
Temperature	282.901 °C
Cp	1.010515
Temperature	283.8621 °C
Cp	1.01076
Temperature	284.8232 °C
Cp	1.010993
Temperature	285.7843 °C
Cp	1.011222
Temperature	286.7454 °C
Cp	1.011447
Temperature	287.7064 °C
Cp	1.011665
Temperature	288.6675 °C
Cp	1.011876
Temperature	289.6286 °C
Cp	1.012079
Temperature	290.5897 °C
Cp	1.01228
Temperature	291.5508 °C
Cp	1.012474
Temperature	292.5118 °C
Cp	1.012662
Temperature	293.4729 °C
Cp	1.012846
Temperature	294.434 °C
Cp	1.013028
Temperature	295.3951 °C
Cp	1.013211
Temperature	296.3561 °C
Cp	1.013391
Temperature	297.3172 °C
Cp	1.013574
Temperature	298.2783 °C
Cp	1.013759
Temperature	299.2394 °C
Cp	1.013947
Temperature	300.2005 °C
Cp	1.014136
Temperature	301.1616 °C
Cp	1.01432
Temperature	302.1226 °C
Cp	1.014511
Temperature	303.0837 °C
Cp	1.014695
Temperature	304.0448 °C
Cp	1.014872
Temperature	305.0059 °C
Cp	1.01504
Temperature	305.9669 °C
Cp	1.015198
Temperature	306.928 °C
Cp	1.015343
Temperature	307.8891 °C
Cp	1.015479
Temperature	308.8502 °C
Cp	1.015595
Temperature	309.8113 °C
Cp	1.015699
Temperature	310.7724 °C
Cp	1.015789
Temperature	311.7334 °C
Cp	1.015865
Temperature	312.6945 °C
Cp	1.015925
Temperature	313.6556 °C
Cp	1.015964
Temperature	314.6167 °C
Cp	1.015999
Temperature	315.5778 °C
Cp	1.016018
Temperature	316.5388 °C
Cp	1.016025
Temperature	317.4999 °C
Cp	1.016024
Temperature	318.461 °C
Cp	1.01602
Temperature	319.4221 °C
Cp	1.016029
Temperature	320.3831 °C
Cp	1.016025
Temperature	321.3442 °C
Cp	1.016037
Temperature	322.3053 °C
Cp	1.016066
Temperature	323.2664 °C
Cp	1.01611
Temperature	324.2275 °C
Cp	1.016169
Temperature	325.1886 °C
Cp	1.016225
Temperature	326.1496 °C
Cp	1.016318
Temperature	327.1107 °C
Cp	1.016411
Temperature	328.0718 °C
Cp	1.016504
Temperature	329.0329 °C
Cp	1.016596
Temperature	329.994 °C
Cp	1.016687
Temperature	330.955 °C
Cp	1.016775
Temperature	331.9161 °C
Cp	1.016864
Temperature	332.8772 °C
Cp	1.016942
Temperature	333.8383 °C
Cp	1.017019
Temperature	334.7993 °C
Cp	1.017093
Temperature	335.7604 °C
Cp	1.017163
Temperature	336.7215 °C
Cp	1.01723
Temperature	337.6826 °C
Cp	1.017295
Temperature	338.6437 °C
Cp	1.017358
Temperature	339.6048 °C
Cp	1.017423
Temperature	340.5658 °C
Cp	1.017491
Temperature	341.5269 °C
Cp	1.017567
Temperature	342.488 °C
Cp	1.017651
Temperature	343.4491 °C
Cp	1.017747
Temperature	344.4102 °C
[...]
151.5900	110.9875	0.3763
151.5983	110.9044	0.3763
151.6067	110.8210	0.3762
151.6150	110.7376	0.3762
151.6233	110.6547	0.3762
151.6317	110.5708	0.3762
151.6400	110.4887	0.3761
151.6483	110.4053	0.3761
151.6567	110.3215	0.3761
151.6650	110.2383	0.3760
151.6733	110.1556	0.3760
151.6817	110.0730	0.3760
151.6900	109.9891	0.3759
151.6983	109.9064	0.3758
151.7067	109.8228	0.3758
151.7150	109.7399	0.3758
151.7233	109.6564	0.3758
151.7317	109.5727	0.3757
151.7400	109.4898	0.3757
151.7483	109.4071	0.3756
151.7567	109.3242	0.3756
151.7650	109.2403	0.3756
151.7733	109.1570	0.3756
151.7817	109.0748	0.3755
151.7900	108.9904	0.3755
151.7983	108.9076	0.3755
151.8067	108.8242	0.3754
151.8150	108.7423	0.3754
151.8233	108.6591	0.3754
151.8317	108.5756	0.3753
151.8400	108.4931	0.3753
151.8483	108.4100	0.3753
151.8567	108.3268	0.3752
151.8650	108.2433	0.3752
151.8733	108.1607	0.3752
151.8817	108.0763	0.3751
151.8900	107.9925	0.3751
151.8983	107.9097	0.3751
151.9067	107.8270	0.3750
151.9150	107.7450	0.3750
151.9233	107.6603	0.3750
151.9317	107.5778	0.3750
151.9400	107.4943	0.3749
151.9483	107.4108	0.3749
151.9567	107.3290	0.3749
151.9650	107.2455	0.3748
151.9733	107.1613	0.3748
151.9817	107.0797	0.3748
151.9900	106.9950	0.3748
151.9983	106.9117	0.3747
152.0067	106.8287	0.3747
152.0150	106.7446	0.3746
152.0233	106.6627	0.3746
152.0317	106.5789	0.3746
152.0400	106.4967	0.3745
152.0483	106.4135	0.3744
152.0567	106.3300	0.3744
152.0650	106.2457	0.3744
152.0733	106.1638	0.3744
152.0817	106.0803	0.3743
152.0900	105.9974	0.3743
152.0983	105.9154	0.3742
152.1067	105.8317	0.3742
152.1150	105.7486	0.3742
152.1233	105.6659	0.3741
152.1317	105.5822	0.3741
152.1400	105.4988	0.3741
152.1483	105.4156	0.3740
152.1567	105.3327	0.3740
152.1650	105.2484	0.3740
152.1733	105.1667	0.3739
152.1817	105.0837	0.3739
152.1900	105.0006	0.3739
152.1983	104.9172	0.3738
152.2067	104.8341	0.3738
152.2150	104.7511	0.3738
152.2233	104.6670	0.3738
152.2317	104.5841	0.3737
152.2400	104.4999	0.3737
152.2483	104.4175	0.3737
152.2567	104.3341	0.3737
152.2650	104.2511	0.3736
152.2733	104.1690	0.3736
152.2817	104.0851	0.3736
152.2900	104.0013	0.3736
152.2983	103.9183	0.3735
152.3067	103.8359	0.3735
152.3150	103.7518	0.3735
152.3233	103.6699	0.3735
152.3317	103.5872	0.3735
152.3400	103.5026	0.3734
152.3483	103.4196	0.3734
152.3567	103.3368	0.3733
152.3650	103.2533	0.3733
152.3733	103.1712	0.3733
152.3817	103.0888	0.3732
152.3900	103.0042	0.3732
152.3983	102.9203	0.3732
152.4067	102.8387	0.3731
152.4150	102.7559	0.3731
152.4233	102.6727	0.3731
152.4317	102.5882	0.3730
152.4400	102.5051	0.3730
152.4483	102.4224	0.3729
152.4567	102.3399	0.3729
152.4650	102.2561	0.3729
152.4733	102.1727	0.3728
152.4817	102.0890	0.3728
152.4900	102.0053	0.3728
152.4983	101.9238	0.3727
152.5067	101.8402	0.3727
152.5150	101.7562	0.3726
152.5233	101.6744	0.3726
152.5317	101.5909	0.3726
152.5400	101.5071	0.3725
152.5483	101.4242	0.3725
152.5567	101.3407	0.3725
152.5650	101.2584	0.3724
152.5733	101.1749	0.3724
152.5817	101.0919	0.3724
152.5900	101.0088	0.3723
152.5983	100.9260	0.3723
152.6067	100.8425	0.3723
152.6150	100.7585	0.3722
152.6233	100.6765	0.3722
152.6317	100.5924	0.3722
152.6400	100.5104	0.3721
152.6483	100.4263	0.3721
152.6567	100.3432	0.3720
152.6650	100.2605	0.3720
152.6733	100.1757	0.3720
152.6817	100.0925	0.3719
152.6900	100.0105	0.3719
152.6983	99.9266	0.3719
152.7067	99.8443	0.3719
152.7150	99.7608	0.3718
152.7233	99.6772	0.3718
152.7317	99.5928	0.3717
152.7400	99.5119	0.3717
152.7483	99.4280	0.3717
152.7567	99.3459	0.3716
152.7650	99.2610	0.3716
152.7733	99.1787	0.3715
152.7817	99.0959	0.3715
152.7900	99.0127	0.3714
152.7983	98.9281	0.3714
152.8067	98.8468	0.3714
152.8150	98.7629	0.3713
152.8233	98.6809	0.3713
152.8317	98.5970	0.3713
152.8400	98.5134	0.3713
152.8483	98.4309	0.3712
152.8567	98.3468	0.3712
152.8650	98.2635	0.3711
152.8733	98.1804	0.3711
152.8817	98.0971	0.3711
152.8900	98.0139	0.3710
152.8983	97.9308	0.3709
152.9067	97.8476	0.3708
152.9150	97.7654	0.3708
152.9233	97.6813	0.3708
152.9317	97.5977	0.3707
152.9400	97.5157	0.3707
152.9483	97.4321	0.3707
152.9567	97.3492	0.3706
152.9650	97.2663	0.3706
152.9733	97.1817	0.3706
152.9817	97.0997	0.3705
152.9900	97.0165	0.3705
152.9983	96.9332	0.3704
153.0067	96.8496	0.3704
153.0150	96.7674	0.3704
153.0233	96.6835	0.3703
153.0317	96.6010	0.3703
153.0400	96.5180	0.3702
153.0483	96.4353	0.3702
153.0567	96.3518	0.3702
153.0650	96.2686	0.3702
153.0733	96.1848	0.3701
153.0817	96.1020	0.3701
153.0900	96.0203	0.3700
153.0983	95.9355	0.3700
153.1067	95.8526	0.3699
153.1150	95.7691	0.3699
153.1233	95.6862	0.3699
153.1317	95.6032	0.3699
153.1400	95.5207	0.3698
153.1483	95.4378	0.3698
153.1567	95.3532	0.3697
153.1650	95.2702	0.3697
153.1733	95.1884	0.3696
153.1817	95.1046	0.3696
153.1900	95.0210	0.3696
153.1983	94.9371	0.3696
153.2067	94.8551	0.3695
153.2150	94.7721	0.3695
153.2233	94.6882	0.3695
153.2317	94.6051	0.3694
153.2400	94.5224	0.3694
153.2483	94.4392	0.3694
153.2567	94.3549	0.3694
153.2650	94.2717	0.3693
153.2733	94.1884	0.3693
153.2817	94.1061	0.3693
153.2900	94.0233	0.3692
153.2983	93.9401	0.3692
153.3067	93.8575	0.3691
153.3150	93.7741	0.3691
153.3233	93.6901	0.3690
153.3317	93.6082	0.3690
153.3400	93.5245	0.3688
153.3483	93.4419	0.3688
153.3567	93.3590	0.3688
153.3650	93.2751	0.3688
153.3733	93.1918	0.3687
153.3817	93.1084	0.3687
153.3900	93.0250	0.3686
153.3983	92.9430	0.3686
153.4067	92.8596	0.3686
153.4150	92.7765	0.3685
153.4233	92.6940	0.3685
153.4317	92.6108	0.3685
153.4400	92.5254	0.3684
153.4483	92.4441	0.3684
153.4567	92.3608	0.3684
153.4650	92.2771	0.3684
153.4733	92.1939	0.3684
153.4817	92.1105	0.3683
153.4900	92.0273	0.3683
153.4983	91.9443	0.3683
153.5067	91.8613	0.3681
153.5150	91.7781	0.3681
153.5233	91.6949	0.3681
153.5317	91.6108	0.3681
153.5400	91.5292	0.3680
153.5483	91.4440	0.3680
153.5567	91.3613	0.3680
153.5650	91.2784	0.3680
153.5733	91.1949	0.3680
153.5817	91.1114	0.3679
153.5900	91.0279	0.3678
153.5983	90.9457	0.3678
153.6067	90.8623	0.3677
153.6150	90.7803	0.3677
153.6233	90.6959	0.3677
153.6317	90.6137	0.3676
153.6400	90.5302	0.3676
153.6483	90.4475	0.3675
153.6567	90.3643	0.3675
153.6650	90.2797	0.3675
153.6733	90.1977	0.3675
153.6817	90.1156	0.3674
153.6900	90.0314	0.3674
153.6983	89.9482	0.3674
153.7067	89.8658	0.3673
153.7150	89.7820	0.3672
153.7233	89.6993	0.3672
153.7317	89.6167	0.3672
153.7400	89.5322	0.3671
153.7483	89.4493	0.3671
153.7567	89.3654	0.3670
153.7650	89.2829	0.3670
153.7733	89.1991	0.3670
153.7817	89.1165	0.3670
153.7900	89.0339	0.3669
153.7983	88.9494	0.3669
153.8067	88.8661	0.3669
153.8150	88.7832	0.3668
153.8233	88.7004	0.3668
153.8317	88.6174	0.3668
153.8400	88.5338	0.3668
153.8483	88.4504	0.3668
153.8567	88.3676	0.3666
153.8650	88.2842	0.3666
153.8733	88.2009	0.3666
153.8817	88.1175	0.3666
153.8900	88.0347	0.3665
153.8983	87.9519	0.3664
153.9067	87.8685	0.3664
153.9150	87.7856	0.3664
153.9233	87.7019	0.3664
153.9317	87.6200	0.3663
153.9400	87.5353	0.3663
153.9483	87.4536	0.3662
153.9567	87.3708	0.3661
153.9650	87.2869	0.3661
153.9733	87.2029	0.3660
153.9817	87.1207	0.3660
153.9900	87.0369	0.3660
153.9983	86.9542	0.3659
154.0067	86.8707	0.3659
154.0150	86.7884	0.3658
154.0233	86.7058	0.3658
154.0317	86.6211	0.3658
154.0400	86.5377	0.3658
154.0483	86.4555	0.3657
154.0567	86.3727	0.3657
154.0650	86.2896	0.3657
154.0733	86.2052	0.3657
154.0817	86.1226	0.3656
154.0900	86.0403	0.3656
154.0983	85.9580	0.3655
154.1067	85.8737	0.3655
154.1150	85.7903	0.3654
154.1233	85.7072	0.3654
154.1317	85.6239	0.3654
154.1400	85.5417	0.3654
154.1483	85.4578	0.3654
154.1567	85.3743	0.3653
154.1650	85.2926	0.3653
154.1733	85.2073	0.3653
154.1817	85.1250	0.3652
154.1900	85.0416	0.3652
154.1983	84.9594	0.3652
154.2067	84.8762	0.3651
154.2150	84.7929	0.3651
154.2233	84.7092	0.3651
154.2317	84.6260	0.3650
154.2400	84.5423	0.3649
154.2483	84.4600	0.3649
154.2567	84.3766	0.3649
154.2650	84.2935	0.3649
154.2733	84.2105	0.3649
154.2817	84.1280	0.3649
154.2900	84.0437	0.3648
154.2983	83.9605	0.3648
154.3067	83.8777	0.3646
154.3150	83.7960	0.3645
154.3233	83.7114	0.3645
154.3317	83.6283	0.3645
154.3400	83.5453	0.3645
154.3483	83.4616	0.3644
154.3567	83.3785	0.3644
154.3650	83.2961	0.3644
154.3733	83.2123	0.3644
154.3817	83.1287	0.3643
154.3900	83.0473	0.3643
154.3983	82.9638	0.3642
154.4067	82.8803	0.3642
154.4150	82.7961	0.3642
154.4233	82.7137	0.3641
154.4317	82.6315	0.3641
154.4400	82.5467	0.3641
154.4483	82.4642	0.3641
154.4567	82.3810	0.3640
154.4650	82.2975	0.3640
154.4733	82.2146	0.3640
154.4817	82.1317	0.3640
154.4900	82.0466	0.3640
154.4983	81.9653	0.3639
154.5067	81.8827	0.3638
154.5150	81.7991	0.3638
154.5233	81.7165	0.3638
154.5317	81.6327	0.3638
154.5400	81.5490	0.3638
154.5483	81.4662	0.3637
154.5567	81.3829	0.3637
154.5650	81.2994	0.3636
154.5733	81.2165	0.3635
154.5817	81.1330	0.3635
154.5900	81.0499	0.3635
154.5983	80.9672	0.3635
154.6067	80.8845	0.3634
154.6150	80.8001	0.3634
154.6233	80.7168	0.3634
154.6317	80.6342	0.3633
154.6400	80.5508	0.3633
154.6483	80.4673	0.3633
154.6567	80.3853	0.3632
154.6650	80.3008	0.3632
154.6733	80.2180	0.3631
154.6817	80.1353	0.3630
154.6900	80.0521	0.3630
154.6983	79.9682	0.3630
154.7067	79.8864	0.3629
154.7150	79.8029	0.3629
154.7233	79.7197	0.3628
154.7317	79.6367	0.3628
154.7400	79.5543	0.3628
154.7483	79.4694	0.3627
154.7567	79.3858	0.3627
154.7650	79.3030	0.3627
154.7733	79.2204	0.3626
154.7817	79.1368	0.3626
154.7900	79.0543	0.3626
154.7983	78.9700	0.3625
154.8067	78.8868	0.3625
154.8150	78.8051	0.3625
154.8233	78.7214	0.3624
154.8317	78.6373	0.3624
154.8400	78.5547	0.3623
154.8483	78.4714	0.3623
154.8567	78.3887	0.3622
154.8650	78.3056	0.3622
154.8733	78.2219	0.3621
154.8817	78.1383	0.3621
154.8900	78.0556	0.3620
154.8983	77.9728	0.3619
154.9067	77.8900	0.3618
154.9150	77.8062	0.3618
154.9233	77.7240	0.3617
154.9317	77.6403	0.3617
154.9400	77.5566	0.3617
154.9483	77.4733	0.3616
154.9567	77.3905	0.3616
154.9650	77.3075	0.3615
154.9733	77.2231	0.3615
154.9817	77.1406	0.3615
154.9900	77.0579	0.3614
154.9983	76.9737	0.3614
155.0067	76.8904	0.3614
155.0150	76.8074	0.3613
155.0233	76.7238	0.3613
155.0317	76.6408	0.3613
155.0400	76.5574	0.3612
155.0483	76.4748	0.3612
155.0567	76.3910	0.3611
155.0650	76.3084	0.3611
155.0733	76.2243	0.3611
155.0817	76.1416	0.3610
155.0900	76.0589	0.3610
155.0983	75.9751	0.3610
155.1067	75.8931	0.3609
155.1150	75.8104	0.3608
155.1233	75.7267	0.3608
155.1317	75.6431	0.3608
155.1400	75.5600	0.3607
155.1483	75.4766	0.3607
155.1567	75.3931	0.3606
155.1650	75.3113	0.3606
155.1733	75.2274	0.3605
155.1817	75.1444	0.3605
155.1900	75.0619	0.3605
155.1983	74.9780	0.3604
155.2067	74.8949	0.3604
155.2150	74.8123	0.3604
155.2233	74.7282	0.3603
155.2317	74.6459	0.3603
155.2400	74.5628	0.3603
155.2483	74.4794	0.3602
155.2567	74.3969	0.3602
155.2650	74.3134	0.3602
155.2733	74.2300	0.3602
155.2817	74.1464	0.3601
155.2900	74.0627	0.3601
155.2983	73.9802	0.3600
155.3067	73.8975	0.3600
155.3150	73.8135	0.3600
155.3233	73.7314	0.3600
155.3317	73.6486	0.3599
155.3400	73.5646	0.3599
155.3483	73.4812	0.3599
155.3567	73.3987	0.3598
155.3650	73.3149	0.3598
155.3733	73.2326	0.3598
155.3817	73.1488	0.3598
155.3900	73.0653	0.3597
155.3983	72.9823	0.3597
155.4067	72.9001	0.3596
155.4150	72.8165	0.3596
155.4233	72.7331	0.3596
155.4317	72.6496	0.3595
155.4400	72.5669	0.3595
155.4483	72.4838	0.3595
155.4567	72.4009	0.3595
155.4650	72.3169	0.3594
155.4733	72.2343	0.3594
155.4817	72.1507	0.3594
155.4900	72.0677	0.3594
155.4983	71.9848	0.3594
155.5067	71.8999	0.3594
155.5150	71.8190	0.3594
155.5233	71.7350	0.3595
155.5317	71.6525	0.3595
155.5400	71.5692	0.3597
155.5483	71.4864	0.3615
155.5567	71.4024	0.3629
155.5650	71.3199	0.3638
155.5733	71.2384	0.3652
155.5817	71.1559	0.3715
155.5900	71.0734	0.3763
155.5983	70.9918	0.3815
155.6067	70.9096	0.3905
155.6150	70.8288	0.4011
155.6233	70.7473	0.4166
155.6317	70.6685	0.4333
155.6400	70.5908	0.4585
155.6483	70.5136	0.4897
155.6567	70.4385	0.5288
155.6650	70.3648	0.5786
155.6733	70.2961	0.6394
155.6817	70.2290	0.7143
155.6900	70.1667	0.8023
155.6983	70.1097	0.9059
155.7067	70.0570	1.0230
155.7150	70.0098	1.1553
155.7233	69.9690	1.2958
155.7317	69.9338	1.4457
155.7400	69.9041	1.5998
155.7483	69.8788	1.7549
155.7567	69.8595	1.9082
155.7650	69.8412	2.0551
155.7733	69.8285	2.1975
155.7817	69.8164	2.3308
155.7900	69.8061	2.4561
155.7983	69.7969	2.5746
155.8067	69.7871	2.6842
155.8150	69.7763	2.7882
155.8233	69.7651	2.8844
155.8317	69.7533	2.9755
155.8400	69.7392	3.0627
155.8483	69.7235	3.1450
155.8567	69.7062	3.2231
155.8650	69.6881	3.3003
155.8733	69.6673	3.3741
155.8817	69.6459	3.4452
155.8900	69.6218	3.5134
155.8983	69.5972	3.5819
155.9067	69.5696	3.6471
155.9150	69.5414	3.7105
155.9233	69.5125	3.7723
155.9317	69.4816	3.8327
155.9400	69.4485	3.8920
155.9483	69.4158	3.9470
155.9567	69.3818	4.0027
155.9650	69.3452	4.0554
155.9733	69.3062	4.1055
155.9817	69.2681	4.1547
155.9900	69.2281	4.2023
155.9983	69.1859	4.2457
156.0067	69.1432	4.2869
156.0150	69.0986	4.3264
156.0233	69.0533	4.3620
156.0317	69.0050	4.3946
156.0400	68.9561	4.4244
156.0483	68.9065	4.4514
156.0567	68.8546	4.4755
156.0650	68.8005	4.4951
156.0733	68.7434	4.5086
156.0817	68.6855	4.5179
156.0900	68.6259	4.5244
156.0983	68.5658	4.5244
156.1067	68.5007	4.5207
156.1150	68.4335	4.5101
156.1233	68.3639	4.4944
156.1317	68.2908	4.4706
156.1400	68.2170	4.4418
156.1483	68.1378	4.4073
156.1567	68.0572	4.3624
156.1650	67.9731	4.3133
156.1733	67.8847	4.2577
156.1817	67.7925	4.1933
156.1900	67.6974	4.1198
156.1983	67.5977	4.0359
156.2067	67.4960	3.9504
156.2150	67.3869	3.8570
156.2233	67.2765	3.7577
156.2317	67.1616	3.6507
156.2400	67.0428	3.5411
156.2483	66.9192	3.4284
156.2567	66.7933	3.3142
156.2650	66.6630	3.2036
156.2733	66.5308	3.0938
156.2817	66.3966	2.9876
156.2900	66.2609	2.8885
156.2983	66.1222	2.7954
156.3067	65.9857	2.7056
156.3150	65.8473	2.6206
156.3233	65.7099	2.5407
156.3317	65.5737	2.4662
156.3400	65.4367	2.3922
156.3483	65.2998	2.3237
156.3567	65.1656	2.2566
156.3650	65.0309	2.1905
156.3733	64.8972	2.1259
156.3817	64.7656	2.0636
156.3900	64.6343	2.0056
156.3983	64.5022	1.9485
156.4067	64.3739	1.8945
156.4150	64.2448	1.8423
156.4233	64.1181	1.7928
156.4317	63.9922	1.7461
156.4400	63.8683	1.7016
156.4483	63.7451	1.6593
156.4567	63.6217	1.6180
156.4650	63.5026	1.5797
156.4733	63.3820	1.5437
156.4817	63.2644	1.5078
156.4900	63.1465	1.4745
156.4983	63.0308	1.4441
156.5067	62.9168	1.4126
156.5150	62.8031	1.3849
156.5233	62.6918	1.3572
156.5317	62.5806	1.3307
156.5400	62.4709	1.3044
156.5483	62.3617	1.2802
156.5567	62.2539	1.2569
156.5650	62.1470	1.2322
156.5733	62.0409	1.2106
156.5817	61.9350	1.1877
156.5900	61.8311	1.1652
156.5983	61.7276	1.1444
156.6067	61.6226	1.1234
156.6150	61.5215	1.1023
156.6233	61.4192	1.0815
156.6317	61.3179	1.0643
156.6400	61.2172	1.0445
156.6483	61.1167	1.0253
156.6567	61.0168	1.0082
156.6650	60.9182	0.9901
156.6733	60.8189	0.9736
156.6817	60.7209	0.9556
156.6900	60.6225	0.9407
156.6983	60.5256	0.9243
156.7067	60.4262	0.9103
156.7150	60.3298	0.8938
156.7233	60.2342	0.8810
156.7317	60.1382	0.8677
156.7400	60.0440	0.8536
156.7483	59.9485	0.8412
156.7567	59.8531	0.8282
156.7650	59.7597	0.8165
156.7733	59.6651	0.8055
156.7817	59.5711	0.7934
156.7900	59.4775	0.7831
156.7983	59.3841	0.7731
156.8067	59.2932	0.7630
156.8150	59.1987	0.7530
156.8233	59.1075	0.7432
156.8317	59.0142	0.7335
156.8400	58.9244	0.7254
156.8483	58.8334	0.7165
156.8567	58.7403	0.7094
156.8650	58.6498	0.7016
156.8733	58.5593	0.6931
156.8817	58.4701	0.6857
156.8900	58.3794	0.6778
156.8983	58.2905	0.6709
156.9067	58.2008	0.6657
156.9150	58.1108	0.6591
156.9233	58.0213	0.6519
156.9317	57.9329	0.6449
156.9400	57.8440	0.6410
156.9483	57.7553	0.6352
156.9567	57.6661	0.6292
156.9650	57.5794	0.6237
156.9733	57.4903	0.6196
156.9817	57.4029	0.6136
156.9900	57.3155	0.6100
156.9983	57.2286	0.6043
157.0067	57.1408	0.6003
157.0150	57.0522	0.5971
157.0233	56.9660	0.5924
157.0317	56.8782	0.5887
157.0400	56.7922	0.5840
157.0483	56.7051	0.5808
157.0567	56.6182	0.5773
157.0650	56.5311	0.5740
157.0733	56.4447	0.5710
157.0817	56.3585	0.5678
157.0900	56.2730	0.5640
157.0983	56.1862	0.5623
157.1067	56.1001	0.5594
157.1150	56.0147	0.5570
157.1233	55.9294	0.5549
157.1317	55.8431	0.5526
157.1400	55.7583	0.5506
157.1483	55.6723	0.5472
157.1567	55.5874	0.5453
157.1650	55.5009	0.5438
157.1733	55.4174	0.5424
157.1817	55.3311	0.5400
157.1900	55.2464	0.5381
157.1983	55.1612	0.5362
157.2067	55.0767	0.5330
157.2150	54.9922	0.5315
157.2233	54.9058	0.5298
157.2317	54.8221	0.5286
157.2400	54.7369	0.5259
157.2483	54.6529	0.5248
157.2567	54.5674	0.5226
157.2650	54.4835	0.5206
157.2733	54.3982	0.5186
157.2817	54.3148	0.5178
157.2900	54.2294	0.5160
157.2983	54.1454	0.5145
157.3067	54.0599	0.5122
157.3150	53.9758	0.5101
157.3233	53.8916	0.5101
157.3317	53.8065	0.5085
157.3400	53.7227	0.5068
157.3483	53.6379	0.5052
157.3567	53.5532	0.5028
157.3650	53.4692	0.5015
157.3733	53.3848	0.5005
157.3817	53.3016	0.4994
157.3900	53.2170	0.4972
157.3983	53.1326	0.4965
157.4067	53.0484	0.4946
157.4150	52.9639	0.4931
157.4233	52.8791	0.4918
157.4317	52.7951	0.4911
157.4400	52.7123	0.4892
157.4483	52.6277	0.4886
157.4567	52.5436	0.4876
157.4650	52.4582	0.4857
157.4733	52.3749	0.4844
157.4817	52.2917	0.4837
157.4900	52.2059	0.4828
157.4983	52.1222	0.4819
157.5067	52.0385	0.4796
157.5150	51.9549	0.4778
157.5233	51.8694	0.4778
157.5317	51.7854	0.4763
157.5400	51.7027	0.4748
157.5483	51.6192	0.4733
157.5567	51.5340	0.4725
157.5650	51.4503	0.4708
157.5733	51.3646	0.4706
157.5817	51.2813	0.4698
157.5900	51.1989	0.4665
157.5983	51.1150	0.4663
157.6067	51.0304	0.4659
157.6150	50.9472	0.4651
157.6233	50.8616	0.4637
157.6317	50.7790	0.4621
157.6400	50.6953	0.4614
157.6483	50.6108	0.4608
157.6567	50.5275	0.4590
157.6650	50.4433	0.4584
157.6733	50.3607	0.4571
157.6817	50.2759	0.4562
157.6900	50.1914	0.4554
157.6983	50.1080	0.4541
157.7067	50.0239	0.4534
157.7150	49.9407	0.4525
157.7233	49.8556	0.4509
157.7317	49.7705	0.4507
157.7400	49.6883	0.4502
157.7483	49.6043	0.4497
157.7567	49.5203	0.4488
157.7650	49.4367	0.4469
157.7733	49.3530	0.4461
157.7817	49.2690	0.4451
157.7900	49.1857	0.4449
157.7983	49.1015	0.4447
157.8067	49.0179	0.4436
157.8150	48.9344	0.4429
157.8233	48.8503	0.4417
157.8317	48.7660	0.4409
157.8400	48.6838	0.4405
157.8483	48.5985	0.4406
157.8567	48.5152	0.4393
157.8650	48.4319	0.4382
157.8733	48.3490	0.4380
157.8817	48.2656	0.4372
157.8900	48.1805	0.4366
157.8983	48.0965	0.4361
157.9067	48.0134	0.4356
157.9150	47.9292	0.4343
157.9233	47.8455	0.4329
157.9317	47.7627	0.4319
157.9400	47.6781	0.4311
157.9483	47.5940	0.4304
157.9567	47.5106	0.4283
157.9650	47.4268	0.4281
157.9733	47.3425	0.4277
157.9817	47.2589	0.4260
157.9900	47.1757	0.4254
157.9983	47.0921	0.4251
158.0067	47.0075	0.4247
158.0150	46.9236	0.4245
158.0233	46.8406	0.4231
158.0317	46.7570	0.4229
158.0400	46.6729	0.4220
158.0483	46.5907	0.4212
158.0567	46.5063	0.4205
158.0650	46.4224	0.4199
158.0733	46.3396	0.4195
158.0817	46.2549	0.4191
158.0900	46.1726	0.4190
158.0983	46.0893	0.4185
158.1067	46.0030	0.4180
158.1150	45.9207	0.4174
158.1233	45.8378	0.4172
158.1317	45.7541	0.4169
158.1400	45.6701	0.4165
158.1483	45.5868	0.4159
158.1567	45.5028	0.4153
158.1650	45.4196	0.4151
158.1733	45.3365	0.4143
158.1817	45.2531	0.4137
158.1900	45.1698	0.4136
158.1983	45.0862	0.4133
158.2067	45.0026	0.4132
158.2150	44.9178	0.4130
158.2233	44.8350	0.4119
158.2317	44.7520	0.4115
158.2400	44.6690	0.4114
158.2483	44.5842	0.4112
158.2567	44.5018	0.4111
158.2650	44.4195	0.4109
158.2733	44.3344	0.4107
158.2817	44.2507	0.4105
158.2900	44.1682	0.4103
158.2983	44.0855	0.4102
158.3067	44.0012	0.4100
158.3150	43.9184	0.4099
158.3233	43.8358	0.4098
158.3317	43.7510	0.4097
158.3400	43.6682	0.4094
158.3483	43.5853	0.4092
158.3567	43.5016	0.4090
158.3650	43.4186	0.4089
158.3733	43.3352	0.4088
158.3817	43.2511	0.4084
158.3900	43.1683	0.4076
158.3983	43.0849	0.4075
158.4067	43.0016	0.4075
158.4150	42.9170	0.4074
158.4233	42.8346	0.4068
158.4317	42.7521	0.4067
158.4400	42.6702	0.4063
158.4483	42.5854
158.4567	42.5018
158.4650	42.4180
158.4733	42.3341
158.4817	42.2519
158.4900	42.1676
158.4983