File: Example Date/My Sample/DSC/test01/DSC TA/YN045 -150-150.txt
Filename	YN045 -150-150
Instrument name	DSC2A-01799 (192.168.1.250)
Operator
rundate	10/12/2024
Sample name	YN045 -150-150
proceduresegments	Ramp 10.00 °C/min to 150.0000 °C; Isothermal 3.0 min; Ramp 10.00 °C/min to -150.0000 °C; Isothermal 3.0 min; Ramp 10.00 °C/min to 150.0000 °C; Isothermal 3.0 min; Ramp 10.00 °C/min to -150.0000 °C; Isothermal 3.0 min; Ramp 10.00 °C/min to 150.0000 °C; Isothermal 3.0 min; Ramp 10.00 °C/min to 40.0000 °C
[File Parameters]
Run Date	10/12/2024 07:08:50
Trios version	5.7.0.56
Original File Name	C:\Users\TA Instruments DSC\Desktop\Data\Yutong Niu\YN045 -150-150.tri
Current File Name	C:\Users\TA Instruments DSC\Desktop\Data\Yutong Niu\YN045 -150-150.tri
User at run start	DESKTOP-CFGN8IT\TA Instruments DSC
[Procedure]
Procedure Name	polyether
Sample Name	YN045 -150-150
Sample Mass	14.3 mg
Reference Sample Mass	0 mg
Pan Mass	61.19 mg
Pan Number	26
Reference Pan Mass	60.81 mg
Reference Pan Number	45
Pan Type	Tzero Aluminum Pin Hole Hermetic
Comments
Project Name
Operator
Test	Custom
Unload Max Temperature	25
Unload Min Temperature	25
FillCooler	Do not fill
Load Max Temperature	25
Load Min Temperature	25
Discard pan in waste bin at end of test	Yes
Stop on Gas Flow Error	No
[Signal List]
Signal #1	Time (min)
Signal #2	Temperature (°C)
Signal #3	Heat Flow (mW)
Signal #4	Delta T (µV)
Signal #5	Delta Tzero (µV)
Signal #6	Tzero Temperature (°C)
Signal #7	Cell Purge (mL/min)
Signal #8	Heater Temp (°C)
Signal #9	Power Delivered (W)
Signal #10	Reference Junction Temperature (°C)
Signal #11	Flange Temperature (°C)
Signal #12	Heat Flow Phase (rad)
Signal #13	Total Heat Capacity (J/°C)
Signal #14	Heat Capacity (J/°C)
Signal #15	LN Pump Tank level (%)
[Configuration]
Company Name	Warwick University
Instrument Name	DSC2A-01799
Instrument Type	DSC2500
Serial Number	DSC2A-01799
IP	192.168.1.250
Location of Instrument	Polymer RTP
DisplayType	TianmaV2andV3
Sample Interval 	0.1 s/pt
Selected Heat Flow	T4P
Exotherm Direction	Up
Cell Serial	DRC2-03788
Lid Type	High Temperature
Cooler	LN Pump
Leave Cooler on at End of Sequence	Off
Gas 2	Air
Gas Selected	Channel 1: Nitrogen
Flow Rate	50 mL/min
Secondary Purge	On
Licensed Heat Flow	Heat Flow T4P
Modulation Licensed	Yes
[Versions]
Common IDD Version	1
Cortex Version	VER 2.11.0.729
Driver	5.0.0.6
GDM Version	1.0.3.3
TouchscreenVersion	1.0.3.1841
FEP Version	1.2.1.21
FEP Bootloader	2.0.0.5
AutoSampler Version	2.1.2.1
Auto Sampler Bootloader	2.0.0.5
FCM Version	1.1.0.3
FCM Bootloader	2.0.0.5
LN Pump Version	10.17.0.0
LN Pump Bootloader	2.0.0.5
[Experiment Logs]
Experiment Log Entry # 1	Ramp Segment 10 C/min to 150 Started
Experiment Log Entry # 3	Air Cool is off.
Experiment Log Entry # 5	Isothermal Segment 3 min started
Experiment Log Entry # 7	Ramp Segment 10 C/min to -150 Started
Experiment Log Entry # 10	LN2P stopped filling
Experiment Log Entry # 11	Isothermal Segment 3 min started
Experiment Log Entry # 13	Ramp Segment 10 C/min to 150 Started
Experiment Log Entry # 15	Isothermal Segment 3 min started
Experiment Log Entry # 17	Ramp Segment 10 C/min to -150 Started
Experiment Log Entry # 19	Isothermal Segment 3 min started
Experiment Log Entry # 21	Ramp Segment 10 C/min to 150 Started
Experiment Log Entry # 23	Isothermal Segment 3 min started
Experiment Log Entry # 25	Ramp Segment 10 C/min to 40 Started
Experiment Log Entry # 28	LN2P is filling
[Method Log]
Method Log Entry # 1	(Ramp 665762) Ramp 10 °C/minute to 150 °C
Method Log Entry # 2	Isothermal 3 minutes
Method Log Entry # 3	(Ramp 665764) Ramp 10 °C/minute to -150 °C
Method Log Entry # 4	Isothermal 3 minutes
Method Log Entry # 5	(Ramp 665766) Ramp 10 °C/minute to 150 °C
Method Log Entry # 6	Isothermal 3 minutes
Method Log Entry # 7	(Ramp 665768) Ramp 10 °C/minute to -150 °C
Method Log Entry # 8	Isothermal 3 minutes
Method Log Entry # 9	(Ramp 665770) Ramp 10 °C/minute to 150 °C
Method Log Entry # 10	Isothermal 3 minutes
Method Log Entry # 11	(Ramp 665772) Ramp 10 °C/minute to 40 °C
Cell Serial	DRC2-03788
[T1 Calibration]
Date Applied	04/03/2021 14:58:04
Description
Gas Type	Nitrogen
Pan Type	None
Slope	-0.001800291
Offset	-0.1301359
Initial Temperature	-100.6228
GUID	a1d5a6be-decd-4ae4-b22f-d560f3a78a92
[TZero Calibration]
Date Applied	21/08/2024 09:53:38
Description	From -180.022 °C to 395.167 °C at 20.000°C/min
Gas Type	Nitrogen
Pan Type	None
Source Files 1	C:\ProgramData\TA Instruments\TRIOS\Data\TAService\PMV 20Aug2024\Tzero Cal.tri
Source Files 2	C:\ProgramData\TA Instruments\TRIOS\Data\TAService\PMV 20Aug2024\Tzero Cal sapphire.tri
Delta T Offset	1.787969
Delta T Slope	-0.003527276
Delta T0 Offset	0.06831977
Delta T0 Slope	0.02007191
[Temperature Calibration]
Date Applied	21/08/2024 11:06:35
Description	From 106.660 °C to 186.660 °C at 10.000°C/min
Gas Type	Nitrogen
Pan Type	Tzero Aluminum
Source Files 1	C:\ProgramData\TA Instruments\TRIOS\Data\TAService\PMV 20Aug2024\TA Indium cal.tri
Measured 1	157.9141
Known 1	156.66
[Cell Constant Calibration]
Date Applied	21/08/2024 11:06:35
Description	From 106.660 °C to 186.660 °C at 10.000°C/min
Gas Type	Nitrogen
Pan Type	Tzero Aluminum
Source Files 1	C:\ProgramData\TA Instruments\TRIOS\Data\TAService\PMV 20Aug2024\TA Indium cal.tri
T4P KCell	1.038055
Onset Slope	-66.72884 mW/°C
[Direct Cp Calibration]
Date Applied	19/11/2024 16:37:27
Description	From -89.996 °C to 396.697 °C at 20.000°C/min
Gas Type	Nitrogen
Pan Type	Tzero Aluminum
Source Files 1	C:\ProgramData\TA Instruments\TRIOS\Data\Sapphire Direct Heat Capacity(8).tri
GUID	544f8371-fe9b-4f4f-81ca-7980c172113e
Temperature	-89.99625 °C
Cp	1.464367
Temperature	-89.02287 °C
Cp	1.460558
Temperature	-88.04948 °C
Cp	1.456263
Temperature	-87.0761 °C
Cp	1.451626
Temperature	-86.10271 °C
Cp	1.446737
Temperature	-85.12933 °C
Cp	1.441723
Temperature	-84.15594 °C
Cp	1.436654
Temperature	-83.18256 °C
Cp	1.431684
Temperature	-82.20917 °C
Cp	1.426935
Temperature	-81.23578 °C
Cp	1.422396
Temperature	-80.2624 °C
Cp	1.418192
Temperature	-79.28901 °C
Cp	1.414363
Temperature	-78.31562 °C
Cp	1.410925
Temperature	-77.34224 °C
Cp	1.407865
Temperature	-76.36885 °C
Cp	1.405143
Temperature	-75.39546 °C
Cp	1.402789
Temperature	-74.42208 °C
Cp	1.400703
Temperature	-73.44869 °C
Cp	1.398837
Temperature	-72.4753 °C
Cp	1.397142
Temperature	-71.50192 °C
Cp	1.395565
Temperature	-70.52853 °C
Cp	1.394053
Temperature	-69.55515 °C
Cp	1.392558
Temperature	-68.58176 °C
Cp	1.391036
Temperature	-67.60838 °C
Cp	1.389483
Temperature	-66.63499 °C
Cp	1.387847
Temperature	-65.66161 °C
Cp	1.38616
Temperature	-64.68822 °C
Cp	1.384397
Temperature	-63.71483 °C
Cp	1.382535
Temperature	-62.74145 °C
Cp	1.380598
Temperature	-61.76806 °C
Cp	1.37865
Temperature	-60.79467 °C
Cp	1.376673
Temperature	-59.82129 °C
Cp	1.374677
Temperature	-58.8479 °C
Cp	1.372642
Temperature	-57.87452 °C
Cp	1.370686
Temperature	-56.90113 °C
Cp	1.368741
Temperature	-55.92775 °C
Cp	1.366786
Temperature	-54.95436 °C
Cp	1.364863
Temperature	-53.98097 °C
Cp	1.362959
Temperature	-53.00759 °C
Cp	1.361116
Temperature	-52.0342 °C
Cp	1.359247
Temperature	-51.06082 °C
Cp	1.357393
Temperature	-50.08743 °C
Cp	1.355593
Temperature	-49.11404 °C
Cp	1.353796
Temperature	-48.14066 °C
Cp	1.352008
Temperature	-47.16727 °C
Cp	1.350215
Temperature	-46.19389 °C
Cp	1.348396
Temperature	-45.2205 °C
Cp	1.346593
Temperature	-44.24712 °C
Cp	1.344755
Temperature	-43.27373 °C
Cp	1.342891
Temperature	-42.30034 °C
Cp	1.341008
Temperature	-41.32696 °C
Cp	1.339126
Temperature	-40.35357 °C
Cp	1.337236
Temperature	-39.38018 °C
Cp	1.335367
Temperature	-38.4068 °C
Cp	1.333522
Temperature	-37.43341 °C
Cp	1.331708
Temperature	-36.46003 °C
Cp	1.32991
Temperature	-35.48664 °C
Cp	1.328145
Temperature	-34.51326 °C
Cp	1.326414
Temperature	-33.53987 °C
Cp	1.32471
Temperature	-32.56648 °C
Cp	1.323012
Temperature	-31.5931 °C
Cp	1.321323
Temperature	-30.61971 °C
Cp	1.319657
Temperature	-29.64633 °C
Cp	1.317968
Temperature	-28.67294 °C
Cp	1.316286
Temperature	-27.69955 °C
Cp	1.314585
Temperature	-26.72617 °C
Cp	1.312857
Temperature	-25.75278 °C
Cp	1.31111
Temperature	-24.7794 °C
Cp	1.309333
Temperature	-23.80601 °C
Cp	1.307544
Temperature	-22.83262 °C
Cp	1.30575
Temperature	-21.85924 °C
Cp	1.303941
Temperature	-20.88585 °C
Cp	1.302132
Temperature	-19.91247 °C
Cp	1.300313
Temperature	-18.93908 °C
Cp	1.298512
Temperature	-17.96569 °C
Cp	1.296728
Temperature	-16.99231 °C
Cp	1.294939
Temperature	-16.01892 °C
Cp	1.293198
Temperature	-15.04554 °C
Cp	1.291453
Temperature	-14.07215 °C
Cp	1.289723
Temperature	-13.09876 °C
Cp	1.288007
Temperature	-12.12538 °C
Cp	1.286283
Temperature	-11.15199 °C
Cp	1.284578
Temperature	-10.17861 °C
Cp	1.282885
Temperature	-9.205221 °C
Cp	1.281173
Temperature	-8.231835 °C
Cp	1.279472
Temperature	-7.258449 °C
Cp	1.277766
Temperature	-6.285063 °C
Cp	1.276053
Temperature	-5.311677 °C
Cp	1.274341
Temperature	-4.338291 °C
Cp	1.272592
Temperature	-3.364905 °C
Cp	1.270844
Temperature	-2.391519 °C
Cp	1.269062
Temperature	-1.418133 °C
Cp	1.267264
Temperature	-0.4447474 °C
Cp	1.265435
Temperature	0.5286385 °C
Cp	1.263575
Temperature	1.502024 °C
Cp	1.261727
Temperature	2.47541 °C
Cp	1.259854
Temperature	3.448796 °C
Cp	1.257978
Temperature	4.422182 °C
Cp	1.256109
Temperature	5.395568 °C
Cp	1.254244
Temperature	6.368954 °C
Cp	1.252392
Temperature	7.34234 °C
Cp	1.250552
Temperature	8.315726 °C
Cp	1.248704
Temperature	9.289112 °C
Cp	1.246884
Temperature	10.2625 °C
Cp	1.245078
Temperature	11.23588 °C
Cp	1.243287
Temperature	12.20927 °C
Cp	1.241522
Temperature	13.18266 °C
Cp	1.239778
Temperature	14.15604 °C
Cp	1.238068
Temperature	15.12943 °C
Cp	1.236393
Temperature	16.10281 °C
Cp	1.234762
Temperature	17.0762 °C
Cp	1.233176
Temperature	18.04959 °C
Cp	1.231629
Temperature	19.02297 °C
Cp	1.230129
Temperature	19.99636 °C
Cp	1.228694
Temperature	20.96974 °C
Cp	1.22731
Temperature	21.94313 °C
Cp	1.225968
Temperature	22.91652 °C
Cp	1.224676
Temperature	23.8899 °C
Cp	1.223431
Temperature	24.86329 °C
Cp	1.222217
Temperature	25.83667 °C
Cp	1.221065
Temperature	26.81006 °C
Cp	1.219919
Temperature	27.78345 °C
Cp	1.218811
Temperature	28.75683 °C
Cp	1.21773
Temperature	29.73022 °C
Cp	1.216663
Temperature	30.7036 °C
Cp	1.2156
Temperature	31.67699 °C
Cp	1.214515
Temperature	32.65038 °C
Cp	1.213439
Temperature	33.62376 °C
Cp	1.21234
Temperature	34.59715 °C
Cp	1.211209
Temperature	35.57053 °C
Cp	1.210051
Temperature	36.54392 °C
Cp	1.208868
Temperature	37.5173 °C
Cp	1.207666
Temperature	38.49069 °C
Cp	1.206439
Temperature	39.46408 °C
Cp	1.205199
Temperature	40.43746 °C
Cp	1.203959
Temperature	41.41085 °C
Cp	1.202712
Temperature	42.38424 °C
Cp	1.20147
Temperature	43.35762 °C
Cp	1.200231
Temperature	44.33101 °C
Cp	1.199
Temperature	45.30439 °C
Cp	1.197777
Temperature	46.27778 °C
Cp	1.19657
Temperature	47.25116 °C
Cp	1.195367
Temperature	48.22455 °C
Cp	1.194179
Temperature	49.19794 °C
Cp	1.19301
Temperature	50.17132 °C
Cp	1.191849
Temperature	51.14471 °C
Cp	1.190694
Temperature	52.11809 °C
Cp	1.189555
Temperature	53.09148 °C
Cp	1.18843
Temperature	54.06487 °C
Cp	1.187311
Temperature	55.03825 °C
Cp	1.186195
Temperature	56.01164 °C
Cp	1.185095
Temperature	56.98502 °C
Cp	1.183997
Temperature	57.95841 °C
Cp	1.182894
Temperature	58.93179 °C
Cp	1.181793
Temperature	59.90518 °C
Cp	1.180693
Temperature	60.87857 °C
Cp	1.179595
Temperature	61.85195 °C
Cp	1.178501
Temperature	62.82534 °C
Cp	1.177406
Temperature	63.79873 °C
Cp	1.176313
Temperature	64.77211 °C
Cp	1.175239
Temperature	65.7455 °C
Cp	1.17417
Temperature	66.71888 °C
Cp	1.173105
Temperature	67.69227 °C
Cp	1.172037
Temperature	68.66566 °C
Cp	1.170989
Temperature	69.63904 °C
Cp	1.169948
Temperature	70.61243 °C
Cp	1.168905
Temperature	71.58582 °C
Cp	1.167872
Temperature	72.5592 °C
Cp	1.166849
Temperature	73.53259 °C
Cp	1.165851
Temperature	74.50597 °C
Cp	1.164848
Temperature	75.47935 °C
Cp	1.163876
Temperature	76.45274 °C
Cp	1.162926
Temperature	77.42612 °C
Cp	1.162008
Temperature	78.39951 °C
Cp	1.161113
Temperature	79.3729 °C
Cp	1.160219
Temperature	80.34628 °C
Cp	1.159377
Temperature	81.31967 °C
Cp	1.158546
Temperature	82.29306 °C
Cp	1.157726
Temperature	83.26644 °C
Cp	1.15692
Temperature	84.23983 °C
Cp	1.156126
Temperature	85.21322 °C
Cp	1.155375
Temperature	86.1866 °C
Cp	1.154604
Temperature	87.15999 °C
Cp	1.153869
Temperature	88.13337 °C
Cp	1.153158
Temperature	89.10676 °C
Cp	1.152474
Temperature	90.08015 °C
Cp	1.15181
Temperature	91.05353 °C
Cp	1.151134
Temperature	92.02692 °C
Cp	1.150513
Temperature	93.00031 °C
Cp	1.149892
Temperature	93.97369 °C
Cp	1.149266
Temperature	94.94707 °C
Cp	1.148642
Temperature	95.92046 °C
Cp	1.148019
Temperature	96.89384 °C
Cp	1.147402
Temperature	97.86723 °C
Cp	1.146799
Temperature	98.84062 °C
Cp	1.146191
Temperature	99.814 °C
Cp	1.145602
Temperature	100.7874 °C
Cp	1.14503
Temperature	101.7608 °C
Cp	1.144469
Temperature	102.7342 °C
Cp	1.143921
Temperature	103.7076 °C
Cp	1.143383
Temperature	104.6809 °C
Cp	1.142861
Temperature	105.6543 °C
Cp	1.142345
Temperature	106.6277 °C
Cp	1.141835
Temperature	107.6011 °C
Cp	1.141335
Temperature	108.5745 °C
Cp	1.140846
Temperature	109.5479 °C
Cp	1.140365
Temperature	110.5212 °C
Cp	1.139891
Temperature	111.4946 °C
Cp	1.139429
Temperature	112.468 °C
Cp	1.138976
Temperature	113.4414 °C
Cp	1.13853
Temperature	114.4148 °C
Cp	1.138092
Temperature	115.3882 °C
Cp	1.137654
Temperature	116.3616 °C
Cp	1.137223
Temperature	117.335 °C
Cp	1.136785
Temperature	118.3083 °C
Cp	1.136338
Temperature	119.2817 °C
Cp	1.13588
Temperature	120.2551 °C
Cp	1.13541
Temperature	121.2285 °C
Cp	1.134927
Temperature	122.2019 °C
Cp	1.134417
Temperature	123.1753 °C
Cp	1.133892
Temperature	124.1487 °C
Cp	1.133347
Temperature	125.122 °C
Cp	1.132786
Temperature	126.0954 °C
Cp	1.132206
Temperature	127.0688 °C
Cp	1.131606
Temperature	128.0422 °C
Cp	1.130999
Temperature	129.0156 °C
Cp	1.130384
Temperature	129.989 °C
Cp	1.129765
Temperature	130.9624 °C
Cp	1.129147
Temperature	131.9357 °C
Cp	1.12854
Temperature	132.9091 °C
Cp	1.127949
Temperature	133.8825 °C
Cp	1.127383
Temperature	134.8559 °C
Cp	1.126841
Temperature	135.8293 °C
Cp	1.126334
Temperature	136.8027 °C
Cp	1.125871
Temperature	137.7761 °C
Cp	1.125443
Temperature	138.7494 °C
Cp	1.125058
Temperature	139.7228 °C
Cp	1.124701
Temperature	140.6962 °C
Cp	1.124397
Temperature	141.6696 °C
Cp	1.124114
Temperature	142.643 °C
Cp	1.123854
Temperature	143.6164 °C
Cp	1.123612
Temperature	144.5898 °C
Cp	1.123385
Temperature	145.5631 °C
Cp	1.123182
Temperature	146.5365 °C
Cp	1.12296
Temperature	147.5099 °C
Cp	1.12275
Temperature	148.4833 °C
Cp	1.122543
Temperature	149.4567 °C
Cp	1.122327
Temperature	150.4301 °C
Cp	1.122099
Temperature	151.4035 °C
Cp	1.121837
Temperature	152.3768 °C
Cp	1.121582
Temperature	153.3502 °C
Cp	1.121289
Temperature	154.3236 °C
Cp	1.120967
Temperature	155.297 °C
Cp	1.120616
Temperature	156.2704 °C
Cp	1.120238
Temperature	157.2438 °C
Cp	1.119862
Temperature	158.2172 °C
Cp	1.119444
Temperature	159.1906 °C
Cp	1.119028
Temperature	160.1639 °C
Cp	1.118613
Temperature	161.1373 °C
Cp	1.118202
Temperature	162.1107 °C
Cp	1.117795
Temperature	163.0841 °C
Cp	1.117374
Temperature	164.0575 °C
Cp	1.116987
Temperature	165.0309 °C
Cp	1.116595
Temperature	166.0042 °C
Cp	1.116198
Temperature	166.9776 °C
Cp	1.1158
Temperature	167.951 °C
Cp	1.115402
Temperature	168.9244 °C
Cp	1.115006
Temperature	169.8978 °C
Cp	1.11462
Temperature	170.8712 °C
Cp	1.114223
Temperature	171.8446 °C
Cp	1.113836
Temperature	172.8179 °C
Cp	1.113458
Temperature	173.7913 °C
Cp	1.113085
Temperature	174.7647 °C
Cp	1.112712
Temperature	175.7381 °C
Cp	1.112323
Temperature	176.7115 °C
Cp	1.111957
Temperature	177.6849 °C
Cp	1.111578
Temperature	178.6583 °C
Cp	1.111185
Temperature	179.6317 °C
Cp	1.110789
Temperature	180.605 °C
Cp	1.110391
Temperature	181.5784 °C
Cp	1.110016
Temperature	182.5518 °C
Cp	1.109611
Temperature	183.5252 °C
Cp	1.109232
Temperature	184.4986 °C
Cp	1.108873
Temperature	185.472 °C
Cp	1.108531
Temperature	186.4454 °C
Cp	1.108199
Temperature	187.4187 °C
Cp	1.107851
Temperature	188.3921 °C
Cp	1.107551
Temperature	189.3655 °C
Cp	1.107238
Temperature	190.3389 °C
Cp	1.106917
Temperature	191.3123 °C
Cp	1.106589
Temperature	192.2857 °C
Cp	1.106259
Temperature	193.259 °C
Cp	1.105958
Temperature	194.2324 °C
Cp	1.105619
Temperature	195.2058 °C
Cp	1.105301
Temperature	196.1792 °C
Cp	1.105002
Temperature	197.1526 °C
Cp	1.104718
Temperature	198.126 °C
Cp	1.104445
Temperature	199.0994 °C
Cp	1.104161
Temperature	200.0728 °C
Cp	1.103914
Temperature	201.0461 °C
Cp	1.103657
Temperature	202.0195 °C
Cp	1.103395
Temperature	202.9929 °C
Cp	1.103125
Temperature	203.9663 °C
Cp	1.102847
Temperature	204.9397 °C
Cp	1.102563
Temperature	205.9131 °C
Cp	1.102283
Temperature	206.8865 °C
Cp	1.101985
Temperature	207.8598 °C
Cp	1.10169
Temperature	208.8332 °C
Cp	1.101394
Temperature	209.8066 °C
Cp	1.101099
Temperature	210.78 °C
Cp	1.1008
Temperature	211.7534 °C
Cp	1.10049
Temperature	212.7268 °C
Cp	1.100193
Temperature	213.7002 °C
Cp	1.099886
Temperature	214.6735 °C
Cp	1.099577
Temperature	215.6469 °C
Cp	1.099268
Temperature	216.6203 °C
Cp	1.098965
Temperature	217.5937 °C
Cp	1.098685
Temperature	218.5671 °C
Cp	1.098396
Temperature	219.5405 °C
Cp	1.098134
Temperature	220.5139 °C
Cp	1.097895
Temperature	221.4872 °C
Cp	1.09768
Temperature	222.4606 °C
Cp	1.097485
Temperature	223.434 °C
Cp	1.097292
Temperature	224.4074 °C
Cp	1.09714
Temperature	225.3808 °C
Cp	1.096991
Temperature	226.3542 °C
Cp	1.096844
Temperature	227.3276 °C
Cp	1.096699
Temperature	228.3009 °C
Cp	1.096559
Temperature	229.2743 °C
Cp	1.096442
Temperature	230.2477 °C
Cp	1.096296
Temperature	231.2211 °C
Cp	1.096164
Temperature	232.1945 °C
Cp	1.09604
Temperature	233.1679 °C
Cp	1.095924
Temperature	234.1413 °C
Cp	1.095807
Temperature	235.1147 °C
Cp	1.095665
Temperature	236.088 °C
Cp	1.095557
Temperature	237.0614 °C
Cp	1.095433
Temperature	238.0348 °C
Cp	1.095296
Temperature	239.0082 °C
Cp	1.095147
Temperature	239.9816 °C
Cp	1.094995
Temperature	240.955 °C
Cp	1.094843
Temperature	241.9283 °C
Cp	1.094705
Temperature	242.9017 °C
Cp	1.094562
Temperature	243.8751 °C
Cp	1.094442
Temperature	244.8485 °C
Cp	1.094344
Temperature	245.8219 °C
Cp	1.094266
Temperature	246.7953 °C
Cp	1.094209
Temperature	247.7687 °C
Cp	1.094161
Temperature	248.7421 °C
Cp	1.094144
Temperature	249.7154 °C
Cp	1.094133
Temperature	250.6888 °C
Cp	1.094127
Temperature	251.6622 °C
Cp	1.094126
Temperature	252.6356 °C
Cp	1.094127
Temperature	253.609 °C
Cp	1.094138
Temperature	254.5824 °C
Cp	1.09413
Temperature	255.5558 °C
Cp	1.094123
Temperature	256.5291 °C
Cp	1.094111
Temperature	257.5025 °C
Cp	1.094087
Temperature	258.4759 °C
Cp	1.094046
Temperature	259.4493 °C
Cp	1.093978
Temperature	260.4227 °C
Cp	1.093895
Temperature	261.3961 °C
Cp	1.093783
Temperature	262.3694 °C
Cp	1.093645
Temperature	263.3428 °C
Cp	1.093483
Temperature	264.3162 °C
Cp	1.093302
Temperature	265.2896 °C
Cp	1.093109
Temperature	266.263 °C
Cp	1.092906
Temperature	267.2364 °C
Cp	1.092704
Temperature	268.2098 °C
Cp	1.092511
Temperature	269.1832 °C
Cp	1.092331
Temperature	270.1566 °C
Cp	1.092174
Temperature	271.1299 °C
Cp	1.092046
Temperature	272.1033 °C
Cp	1.091947
Temperature	273.0767 °C
Cp	1.091882
Temperature	274.0501 °C
Cp	1.091853
Temperature	275.0235 °C
Cp	1.091859
Temperature	275.9969 °C
Cp	1.091895
Temperature	276.9702 °C
Cp	1.091957
Temperature	277.9436 °C
Cp	1.092036
Temperature	278.917 °C
Cp	1.092132
Temperature	279.8904 °C
Cp	1.09223
Temperature	280.8638 °C
Cp	1.092323
Temperature	281.8372 °C
Cp	1.092405
Temperature	282.8105 °C
Cp	1.092468
Temperature	283.7839 °C
Cp	1.092513
Temperature	284.7573 °C
Cp	1.092525
Temperature	285.7307 °C
Cp	1.092512
Temperature	286.7041 °C
Cp	1.092472
Temperature	287.6775 °C
Cp	1.092405
Temperature	288.6509 °C
Cp	1.092313
Temperature	289.6243 °C
Cp	1.092197
Temperature	290.5977 °C
Cp	1.09207
Temperature	291.571 °C
Cp	1.091931
Temperature	292.5444 °C
Cp	1.091785
Temperature	293.5178 °C
Cp	1.091641
Temperature	294.4912 °C
Cp	1.091506
Temperature	295.4646 °C
Cp	1.091387
Temperature	296.438 °C
Cp	1.091282
Temperature	297.4113 °C
Cp	1.091201
Temperature	298.3847 °C
Cp	1.091145
Temperature	299.3581 °C
Cp	1.091112
Temperature	300.3315 °C
Cp	1.091102
Temperature	301.3049 °C
Cp	1.091107
Temperature	302.2783 °C
Cp	1.091137
Temperature	303.2517 °C
Cp	1.091177
Temperature	304.2251 °C
Cp	1.091226
Temperature	305.1984 °C
Cp	1.09128
Temperature	306.1718 °C
Cp	1.091336
Temperature	307.1452 °C
Cp	1.091403
Temperature	308.1186 °C
Cp	1.091453
Temperature	309.092 °C
Cp	1.091506
Temperature	310.0654 °C
Cp	1.091561
Temperature	311.0388 °C
Cp	1.091617
Temperature	312.0121 °C
Cp	1.09167
Temperature	312.9855 °C
Cp	1.091716
Temperature	313.9589 °C
Cp	1.091762
Temperature	314.9323 °C
Cp	1.091805
Temperature	315.9057 °C
Cp	1.091838
Temperature	316.8791 °C
Cp	1.09186
Temperature	317.8524 °C
Cp	1.091871
Temperature	318.8258 °C
Cp	1.091872
Temperature	319.7992 °C
Cp	1.091867
Temperature	320.7726 °C
Cp	1.091838
Temperature	321.746 °C
Cp	1.0918
Temperature	322.7194 °C
Cp	1.091752
Temperature	323.6928 °C
Cp	1.091689
Temperature	324.6662 °C
Cp	1.091611
Temperature	325.6396 °C
Cp	1.091508
Temperature	326.6129 °C
Cp	1.091406
Temperature	327.5863 °C
Cp	1.091285
Temperature	328.5597 °C
Cp	1.09115
Temperature	329.5331 °C
Cp	1.091009
Temperature	330.5065 °C
Cp	1.09087
Temperature	331.4799 °C
Cp	1.090747
Temperature	332.4532 °C
Cp	1.090628
Temperature	333.4266 °C
Cp	1.090536
Temperature	334.4 °C
Cp	1.090472
Temperature	335.3734 °C
Cp	1.090437
Temperature	336.3468 °C
Cp	1.090431
Temperature	337.3202 °C
Cp	1.090455
Temperature	338.2935 °C
Cp	1.090503
Temperature	339.2669 °C
Cp	1.090573
Temperature	340.2403 °C
Cp	1.090658
Temperature	341.2137 °C
Cp	1.090753
Temperature	342.1871 °C
Cp	1.090853
Temperature	343.1605 °C
Cp	1.090952
Temperature	344.1339 °C
Cp	1.09105
Temperature	345.1073 °C
Cp	1.091141
Temperature	346.0807 °C
Cp	1.091225
Temperature	347.054 °C
Cp	1.091303
Temperature	348.0274 °C
Cp	1.091379
Temperature	349.0008 °C
Cp	1.091453
Temperature	349.9742 °C
Cp	1.091537
Temperature	350.9476 °C
Cp	1.091633
Temperature	351.921 °C
Cp	1.091743
Temperature	352.8943 °C
Cp	1.091874
Temperature	353.8677 °C
Cp	1.092028
Temperature	354.8411 °C
Cp	1.092206
Temperature	355.8145 °C
Cp	1.092411
Temperature	356.7879 °C
Cp	1.092628
Temperature	357.7613 °C
Cp	1.092862
Temperature	358.7346 °C
Cp	1.093102
Temperature	359.708 °C
Cp	1.093338
Temperature	360.6814 °C
Cp	1.093559
Temperature	361.6548 °C
Cp	1.093752
Temperature	362.6282 °C
Cp	1.093915
Temperature	363.6016 °C
Cp	1.094036
Temperature	364.575 °C
Cp	1.094117
Temperature	365.5484 °C
Cp	1.094159
Temperature	366.5218 °C
Cp	1.094172
Temperature	367.4951 °C
Cp	1.094165
Temperature	368.4685 °C
Cp	1.094163
Temperature	369.4419 °C
Cp	1.094182
Temperature	370.4153 °C
Cp	1.094244
Temperature	371.3887 °C
Cp	1.094375
Temperature	372.3621 °C
Cp	1.094598
Temperature	373.3354 °C
Cp	1.094937
Temperature	374.3088 °C
Cp	1.095389
Temperature	375.2822 °C
Cp	1.095973
Temperature	376.2556 °C
Cp	1.096685
Temperature	377.229 °C
Cp	1.097506
Temperature	378.2024 °C
Cp	1.098406
Temperature	379.1758 °C
Cp	1.099338
Temperature	380.1492 °C
Cp	1.10027
Temperature	381.1225 °C
Cp	1.10112
Temperature	382.0959 °C
Cp	1.101818
Temperature	383.0693 °C
Cp	1.10229
Temperature	384.0427 °C
Cp	1.102459
Temperature	385.0161 °C
Cp	1.102253
Temperature	385.9895 °C
Cp	1.101596
Temperature	386.9629 °C
Cp	1.100438
Temperature	387.9362 °C
Cp	1.098736
Temperature	388.9096 °C
Cp	1.096461
Temperature	389.883 °C
Cp	1.093614
Temperature	390.8564 °C
Cp	1.090208
Temperature	391.8298 °C
Cp	1.086278
Temperature	392.8032 °C
Cp	1.081887
Temperature	393.7766 °C
Cp	1.077096
Temperature	394.7499 °C
Cp	1.072007
Temperature	395.7233 °C
Cp	1.066707
[Rev Cp Calibration]
Date Applied	24/10/2024 12:37:31
Description	From -89.998 °C to 390.542 °C at 2.000°C/min
Gas Type	Nitrogen
Pan Type	Tzero Aluminum
Source Files 1	C:\ProgramData\TA Instruments\TRIOS\Data\Reverse Heat Capacity Calibration(6).tri
GUID	ba867d72-cfbb-486e-971e-e86aa544cc02
Temperature	-89.99799 °C
Cp	1.070076
Temperature	-89.03691 °C
Cp	1.072008
Temperature	-88.07584 °C
Cp	1.073556
Temperature	-87.11475 °C
Cp	1.074743
Temperature	-86.15367 °C
Cp	1.075597
Temperature	-85.1926 °C
Cp	1.076163
Temperature	-84.23151 °C
Cp	1.076477
Temperature	-83.27043 °C
Cp	1.076579
Temperature	-82.30936 °C
Cp	1.076527
Temperature	-81.34827 °C
Cp	1.076322
Temperature	-80.38719 °C
Cp	1.076039
Temperature	-79.42612 °C
Cp	1.07571
Temperature	-78.46503 °C
Cp	1.075361
Temperature	-77.50395 °C
Cp	1.075011
Temperature	-76.54288 °C
Cp	1.074656
Temperature	-75.58179 °C
Cp	1.074359
Temperature	-74.62071 °C
Cp	1.074086
Temperature	-73.65964 °C
Cp	1.073842
Temperature	-72.69855 °C
Cp	1.073627
Temperature	-71.73747 °C
Cp	1.073442
Temperature	-70.7764 °C
Cp	1.07329
Temperature	-69.81532 °C
Cp	1.073148
Temperature	-68.85423 °C
Cp	1.073021
Temperature	-67.89315 °C
Cp	1.072902
Temperature	-66.93208 °C
Cp	1.072782
Temperature	-65.97099 °C
Cp	1.072656
Temperature	-65.00991 °C
Cp	1.072518
Temperature	-64.04884 °C
Cp	1.072374
Temperature	-63.08775 °C
Cp	1.072201
Temperature	-62.12667 °C
Cp	1.072019
Temperature	-61.1656 °C
Cp	1.071827
Temperature	-60.20451 °C
Cp	1.071624
Temperature	-59.24343 °C
Cp	1.071411
Temperature	-58.28236 °C
Cp	1.071167
Temperature	-57.32127 °C
Cp	1.070956
Temperature	-56.3602 °C
Cp	1.070724
Temperature	-55.39911 °C
Cp	1.070483
Temperature	-54.43803 °C
Cp	1.070242
Temperature	-53.47696 °C
Cp	1.070009
Temperature	-52.51587 °C
Cp	1.069825
Temperature	-51.55479 °C
Cp	1.069601
Temperature	-50.59372 °C
Cp	1.069418
Temperature	-49.63263 °C
Cp	1.069267
Temperature	-48.67155 °C
Cp	1.069138
Temperature	-47.71048 °C
Cp	1.069021
Temperature	-46.74939 °C
Cp	1.068875
Temperature	-45.78831 °C
Cp	1.068771
Temperature	-44.82724 °C
Cp	1.068634
Temperature	-43.86615 °C
Cp	1.068462
Temperature	-42.90508 °C
Cp	1.068255
Temperature	-41.944 °C
Cp	1.068012
Temperature	-40.98291 °C
Cp	1.067742
Temperature	-40.02184 °C
Cp	1.067427
Temperature	-39.06076 °C
Cp	1.067088
Temperature	-38.09967 °C
Cp	1.066727
Temperature	-37.1386 °C
Cp	1.066349
Temperature	-36.17752 °C
Cp	1.065958
Temperature	-35.21643 °C
Cp	1.065559
Temperature	-34.25536 °C
Cp	1.065162
Temperature	-33.29427 °C
Cp	1.06476
Temperature	-32.33319 °C
Cp	1.064368
Temperature	-31.37212 °C
Cp	1.06399
Temperature	-30.41104 °C
Cp	1.063628
Temperature	-29.44995 °C
Cp	1.063283
Temperature	-28.48887 °C
Cp	1.06295
Temperature	-27.5278 °C
Cp	1.062645
Temperature	-26.56672 °C
Cp	1.062355
Temperature	-25.60563 °C
Cp	1.06208
Temperature	-24.64456 °C
Cp	1.061819
Temperature	-23.68348 °C
Cp	1.061573
Temperature	-22.72239 °C
Cp	1.061345
Temperature	-21.76132 °C
Cp	1.061123
Temperature	-20.80024 °C
Cp	1.060915
Temperature	-19.83916 °C
Cp	1.060719
Temperature	-18.87807 °C
Cp	1.060531
Temperature	-17.917 °C
Cp	1.06035
Temperature	-16.95592 °C
Cp	1.060161
Temperature	-15.99484 °C
Cp	1.059992
Temperature	-15.03376 °C
Cp	1.059817
Temperature	-14.07268 °C
Cp	1.059634
Temperature	-13.1116 °C
Cp	1.059445
Temperature	-12.15052 °C
Cp	1.059248
Temperature	-11.18944 °C
Cp	1.059043
Temperature	-10.22836 °C
Cp	1.058842
Temperature	-9.267276 °C
Cp	1.058615
Temperature	-8.306196 °C
Cp	1.058388
Temperature	-7.345116 °C
Cp	1.058155
Temperature	-6.384036 °C
Cp	1.057911
Temperature	-5.422956 °C
Cp	1.057652
Temperature	-4.461876 °C
Cp	1.057356
Temperature	-3.500796 °C
Cp	1.057063
Temperature	-2.539716 °C
Cp	1.056732
Temperature	-1.578636 °C
Cp	1.056364
Temperature	-0.6175562 °C
Cp	1.05596
Temperature	0.3435238 °C
Cp	1.055523
Temperature	1.304604 °C
Cp	1.055066
Temperature	2.265684 °C
Cp	1.054561
Temperature	3.226764 °C
Cp	1.054035
Temperature	4.187844 °C
Cp	1.053488
Temperature	5.148924 °C
Cp	1.052922
Temperature	6.110003 °C
Cp	1.052337
Temperature	7.071084 °C
Cp	1.051736
Temperature	8.032164 °C
Cp	1.051118
Temperature	8.993243 °C
Cp	1.050488
Temperature	9.954324 °C
Cp	1.049848
Temperature	10.9154 °C
Cp	1.049202
Temperature	11.87648 °C
Cp	1.048552
Temperature	12.83756 °C
Cp	1.047902
Temperature	13.79864 °C
Cp	1.047255
Temperature	14.75972 °C
Cp	1.046615
Temperature	15.7208 °C
Cp	1.045983
Temperature	16.68188 °C
Cp	1.045362
Temperature	17.64296 °C
Cp	1.044756
Temperature	18.60404 °C
Cp	1.044164
Temperature	19.56512 °C
Cp	1.04358
Temperature	20.5262 °C
Cp	1.043027
Temperature	21.48728 °C
Cp	1.042485
Temperature	22.44836 °C
Cp	1.041958
Temperature	23.40944 °C
Cp	1.041446
Temperature	24.37052 °C
Cp	1.040952
Temperature	25.3316 °C
Cp	1.040493
Temperature	26.29268 °C
Cp	1.040022
Temperature	27.25376 °C
Cp	1.039578
Temperature	28.21484 °C
Cp	1.039158
Temperature	29.17592 °C
Cp	1.038758
Temperature	30.137 °C
Cp	1.038373
Temperature	31.09808 °C
Cp	1.037981
Temperature	32.05916 °C
Cp	1.03763
Temperature	33.02024 °C
Cp	1.037276
Temperature	33.98132 °C
Cp	1.03692
Temperature	34.9424 °C
Cp	1.036565
Temperature	35.90348 °C
Cp	1.036213
Temperature	36.86456 °C
Cp	1.035866
Temperature	37.82564 °C
Cp	1.035529
Temperature	38.78672 °C
Cp	1.035195
Temperature	39.7478 °C
Cp	1.034875
Temperature	40.70888 °C
Cp	1.034568
Temperature	41.66996 °C
Cp	1.034276
Temperature	42.63104 °C
Cp	1.033996
Temperature	43.59212 °C
Cp	1.033726
Temperature	44.5532 °C
Cp	1.033469
Temperature	45.51428 °C
Cp	1.033221
Temperature	46.47536 °C
Cp	1.03298
Temperature	47.43644 °C
Cp	1.032744
Temperature	48.39752 °C
Cp	1.032514
Temperature	49.3586 °C
Cp	1.032289
Temperature	50.31968 °C
Cp	1.032065
Temperature	51.28076 °C
Cp	1.031844
Temperature	52.24184 °C
Cp	1.031627
Temperature	53.20292 °C
Cp	1.031413
Temperature	54.164 °C
Cp	1.031203
Temperature	55.12508 °C
Cp	1.030989
Temperature	56.08616 °C
Cp	1.030791
Temperature	57.04724 °C
Cp	1.030595
Temperature	58.00832 °C
Cp	1.030403
Temperature	58.9694 °C
Cp	1.030217
Temperature	59.93048 °C
Cp	1.03004
Temperature	60.89156 °C
Cp	1.029871
Temperature	61.85264 °C
Cp	1.029718
Temperature	62.81372 °C
Cp	1.029567
Temperature	63.7748 °C
Cp	1.02943
Temperature	64.73589 °C
Cp	1.029304
Temperature	65.69696 °C
Cp	1.029185
Temperature	66.65804 °C
Cp	1.02907
Temperature	67.61913 °C
Cp	1.028946
Temperature	68.5802 °C
Cp	1.028831
Temperature	69.54128 °C
Cp	1.028703
Temperature	70.50237 °C
Cp	1.028561
Temperature	71.46344 °C
Cp	1.028404
Temperature	72.42452 °C
Cp	1.028234
Temperature	73.3856 °C
Cp	1.028063
Temperature	74.34668 °C
Cp	1.027861
Temperature	75.30776 °C
Cp	1.027657
Temperature	76.26884 °C
Cp	1.027451
Temperature	77.22992 °C
Cp	1.027243
Temperature	78.191 °C
Cp	1.027036
Temperature	79.15208 °C
Cp	1.026812
Temperature	80.11316 °C
Cp	1.026623
Temperature	81.07424 °C
Cp	1.026431
Temperature	82.03532 °C
Cp	1.026241
Temperature	82.9964 °C
Cp	1.02606
Temperature	83.95748 °C
Cp	1.025891
Temperature	84.91856 °C
Cp	1.025739
Temperature	85.87964 °C
Cp	1.025614
Temperature	86.84072 °C
Cp	1.025493
Temperature	87.8018 °C
Cp	1.0254
Temperature	88.76288 °C
Cp	1.025329
Temperature	89.72396 °C
Cp	1.025274
Temperature	90.68504 °C
Cp	1.025229
Temperature	91.64612 °C
Cp	1.025174
Temperature	92.6072 °C
Cp	1.025138
Temperature	93.56828 °C
Cp	1.025083
Temperature	94.52936 °C
Cp	1.025008
Temperature	95.49044 °C
Cp	1.024912
Temperature	96.45152 °C
Cp	1.024796
Temperature	97.4126 °C
Cp	1.024671
Temperature	98.37368 °C
Cp	1.024506
Temperature	99.33476 °C
Cp	1.02433
Temperature	100.2958 °C
Cp	1.024144
Temperature	101.2569 °C
Cp	1.023948
Temperature	102.218 °C
Cp	1.023743
Temperature	103.1791 °C
Cp	1.023522
Temperature	104.1402 °C
Cp	1.023309
Temperature	105.1012 °C
Cp	1.023089
Temperature	106.0623 °C
Cp	1.022866
Temperature	107.0234 °C
Cp	1.022644
Temperature	107.9845 °C
Cp	1.022427
Temperature	108.9456 °C
Cp	1.022218
Temperature	109.9066 °C
Cp	1.022022
Temperature	110.8677 °C
Cp	1.021836
Temperature	111.8288 °C
Cp	1.021666
Temperature	112.7899 °C
Cp	1.021512
Temperature	113.751 °C
Cp	1.021374
Temperature	114.712 °C
Cp	1.02125
Temperature	115.6731 °C
Cp	1.021137
Temperature	116.6342 °C
Cp	1.021041
Temperature	117.5953 °C
Cp	1.020953
Temperature	118.5564 °C
Cp	1.020872
Temperature	119.5174 °C
Cp	1.020796
Temperature	120.4785 °C
Cp	1.020725
Temperature	121.4396 °C
Cp	1.020659
Temperature	122.4007 °C
Cp	1.020587
Temperature	123.3618 °C
Cp	1.020515
Temperature	124.3228 °C
Cp	1.02044
Temperature	125.2839 °C
Cp	1.020359
Temperature	126.245 °C
Cp	1.02027
Temperature	127.2061 °C
Cp	1.020167
Temperature	128.1672 °C
Cp	1.020057
Temperature	129.1282 °C
Cp	1.019933
Temperature	130.0893 °C
Cp	1.019793
Temperature	131.0504 °C
Cp	1.019638
Temperature	132.0115 °C
Cp	1.019471
Temperature	132.9726 °C
Cp	1.019292
Temperature	133.9336 °C
Cp	1.019107
Temperature	134.8947 °C
Cp	1.018912
Temperature	135.8558 °C
Cp	1.018717
Temperature	136.8169 °C
Cp	1.018527
Temperature	137.778 °C
Cp	1.018344
Temperature	138.739 °C
Cp	1.018171
Temperature	139.7001 °C
Cp	1.018004
Temperature	140.6612 °C
Cp	1.01787
Temperature	141.6223 °C
Cp	1.01775
Temperature	142.5834 °C
Cp	1.017652
Temperature	143.5444 °C
Cp	1.017578
Temperature	144.5055 °C
Cp	1.017534
Temperature	145.4666 °C
Cp	1.017536
Temperature	146.4277 °C
Cp	1.017545
Temperature	147.3888 °C
Cp	1.017595
Temperature	148.3498 °C
Cp	1.017679
Temperature	149.3109 °C
Cp	1.01779
Temperature	150.272 °C
Cp	1.01792
Temperature	151.2331 °C
Cp	1.018043
Temperature	152.1942 °C
Cp	1.018199
Temperature	153.1552 °C
Cp	1.018339
Temperature	154.1163 °C
Cp	1.018458
Temperature	155.0774 °C
Cp	1.018552
Temperature	156.0385 °C
Cp	1.018618
Temperature	156.9996 °C
Cp	1.018662
Temperature	157.9606 °C
Cp	1.018664
Temperature	158.9217 °C
Cp	1.018632
Temperature	159.8828 °C
Cp	1.018575
Temperature	160.8439 °C
Cp	1.018492
Temperature	161.805 °C
Cp	1.018383
Temperature	162.766 °C
Cp	1.01825
Temperature	163.7271 °C
Cp	1.018087
Temperature	164.6882 °C
Cp	1.017917
Temperature	165.6493 °C
Cp	1.017726
Temperature	166.6104 °C
Cp	1.017522
Temperature	167.5714 °C
Cp	1.01731
Temperature	168.5325 °C
Cp	1.017098
Temperature	169.4936 °C
Cp	1.016902
Temperature	170.4547 °C
Cp	1.016695
Temperature	171.4158 °C
Cp	1.016508
Temperature	172.3768 °C
Cp	1.016342
Temperature	173.3379 °C
Cp	1.016195
Temperature	174.299 °C
Cp	1.016065
Temperature	175.2601 °C
Cp	1.015927
Temperature	176.2212 °C
Cp	1.015838
Temperature	177.1822 °C
Cp	1.015746
Temperature	178.1433 °C
Cp	1.015651
Temperature	179.1044 °C
Cp	1.015555
Temperature	180.0655 °C
Cp	1.015459
Temperature	181.0266 °C
Cp	1.015401
Temperature	181.9876 °C
Cp	1.015288
Temperature	182.9487 °C
Cp	1.015195
Temperature	183.9098 °C
Cp	1.015117
Temperature	184.8709 °C
Cp	1.01505
Temperature	185.832 °C
Cp	1.014988
Temperature	186.793 °C
Cp	1.014927
Temperature	187.7541 °C
Cp	1.014849
Temperature	188.7152 °C
Cp	1.014789
Temperature	189.6763 °C
Cp	1.01471
Temperature	190.6374 °C
Cp	1.014614
Temperature	191.5984 °C
Cp	1.014503
Temperature	192.5595 °C
Cp	1.014381
Temperature	193.5206 °C
Cp	1.014268
Temperature	194.4817 °C
Cp	1.014122
Temperature	195.4428 °C
Cp	1.013984
Temperature	196.4038 °C
Cp	1.013853
Temperature	197.3649 °C
Cp	1.013726
Temperature	198.326 °C
Cp	1.013603
Temperature	199.2871 °C
Cp	1.013467
Temperature	200.2482 °C
Cp	1.013359
Temperature	201.2092 °C
Cp	1.013243
Temperature	202.1703 °C
Cp	1.013123
Temperature	203.1314 °C
Cp	1.013002
Temperature	204.0925 °C
Cp	1.012884
Temperature	205.0536 °C
Cp	1.012788
Temperature	206.0146 °C
Cp	1.012674
Temperature	206.9757 °C
Cp	1.012579
Temperature	207.9368 °C
Cp	1.012501
Temperature	208.8979 °C
Cp	1.012439
Temperature	209.859 °C
Cp	1.012389
Temperature	210.82 °C
Cp	1.012351
Temperature	211.7811 °C
Cp	1.012312
Temperature	212.7422 °C
Cp	1.01229
Temperature	213.7033 °C
Cp	1.012262
Temperature	214.6644 °C
Cp	1.012227
Temperature	215.6254 °C
Cp	1.012183
Temperature	216.5865 °C
Cp	1.012129
Temperature	217.5476 °C
Cp	1.012077
Temperature	218.5087 °C
Cp	1.01199
Temperature	219.4698 °C
Cp	1.011897
Temperature	220.4308 °C
Cp	1.011793
Temperature	221.3919 °C
Cp	1.011674
Temperature	222.353 °C
Cp	1.011537
Temperature	223.3141 °C
Cp	1.011362
Temperature	224.2752 °C
Cp	1.011194
Temperature	225.2362 °C
Cp	1.010993
Temperature	226.1973 °C
Cp	1.010766
Temperature	227.1584 °C
Cp	1.010517
Temperature	228.1195 °C
Cp	1.010251
Temperature	229.0806 °C
Cp	1.009998
Temperature	230.0416 °C
Cp	1.009703
Temperature	231.0027 °C
Cp	1.009422
Temperature	231.9638 °C
Cp	1.009156
Temperature	232.9249 °C
Cp	1.008906
Temperature	233.886 °C
Cp	1.008675
Temperature	234.847 °C
Cp	1.008462
Temperature	235.8081 °C
Cp	1.008258
Temperature	236.7692 °C
Cp	1.00809
Temperature	237.7303 °C
Cp	1.007934
Temperature	238.6914 °C
Cp	1.007793
Temperature	239.6524 °C
Cp	1.007668
Temperature	240.6135 °C
Cp	1.007562
Temperature	241.5746 °C
Cp	1.007487
Temperature	242.5357 °C
Cp	1.00741
Temperature	243.4967 °C
Cp	1.00736
Temperature	244.4578 °C
Cp	1.007332
Temperature	245.4189 °C
Cp	1.007321
Temperature	246.38 °C
Cp	1.007321
Temperature	247.3411 °C
Cp	1.007312
Temperature	248.3022 °C
Cp	1.007331
Temperature	249.2632 °C
Cp	1.007338
Temperature	250.2243 °C
Cp	1.007335
Temperature	251.1854 °C
Cp	1.00732
Temperature	252.1465 °C
Cp	1.007295
Temperature	253.1076 °C
Cp	1.007277
Temperature	254.0686 °C
Cp	1.007227
Temperature	255.0297 °C
Cp	1.007179
Temperature	255.9908 °C
Cp	1.007133
Temperature	256.9519 °C
Cp	1.00709
Temperature	257.913 °C
Cp	1.007049
Temperature	258.874 °C
Cp	1.007012
Temperature	259.8351 °C
Cp	1.006978
Temperature	260.7962 °C
Cp	1.006956
Temperature	261.7573 °C
Cp	1.00694
Temperature	262.7184 °C
Cp	1.006934
Temperature	263.6794 °C
Cp	1.006939
Temperature	264.6405 °C
Cp	1.00696
Temperature	265.6016 °C
Cp	1.006999
Temperature	266.5627 °C
Cp	1.007054
Temperature	267.5237 °C
Cp	1.007131
Temperature	268.4848 °C
Cp	1.00723
Temperature	269.4459 °C
Cp	1.00735
Temperature	270.407 °C
Cp	1.007493
Temperature	271.3681 °C
Cp	1.007656
Temperature	272.3292 °C
Cp	1.007839
Temperature	273.2902 °C
Cp	1.008039
Temperature	274.2513 °C
Cp	1.008257
Temperature	275.2124 °C
Cp	1.008488
Temperature	276.1735 °C
Cp	1.008731
Temperature	277.1346 °C
Cp	1.008977
Temperature	278.0956 °C
Cp	1.009237
Temperature	279.0567 °C
Cp	1.009498
Temperature	280.0178 °C
Cp	1.009757
Temperature	280.9789 °C
Cp	1.010014
Temperature	281.9399 °C
Cp	1.010267
Temperature	282.901 °C
Cp	1.010515
Temperature	283.8621 °C
Cp	1.01076
Temperature	284.8232 °C
Cp	1.010993
Temperature	285.7843 °C
Cp	1.011222
Temperature	286.7454 °C
Cp	1.011447
Temperature	287.7064 °C
Cp	1.011665
Temperature	288.6675 °C
Cp	1.011876
Temperature	289.6286 °C
Cp	1.012079
Temperature	290.5897 °C
Cp	1.01228
Temperature	291.5508 °C
Cp	1.012474
Temperature	292.5118 °C
Cp	1.012662
Temperature	293.4729 °C
Cp	1.012846
Temperature	294.434 °C
Cp	1.013028
Temperature	295.3951 °C
Cp	1.013211
Temperature	296.3561 °C
Cp	1.013391
Temperature	297.3172 °C
Cp	1.013574
Temperature	298.2783 °C
Cp	1.013759
Temperature	299.2394 °C
Cp	1.013947
Temperature	300.2005 °C
Cp	1.014136
Temperature	301.1616 °C
Cp	1.01432
Temperature	302.1226 °C
Cp	1.014511
Temperature	303.0837 °C
Cp	1.014695
Temperature	304.0448 °C
Cp	1.014872
Temperature	305.0059 °C
Cp	1.01504
Temperature	305.9669 °C
Cp	1.015198
Temperature	306.928 °C
Cp	1.015343
Temperature	307.8891 °C
Cp	1.015479
Temperature	308.8502 °C
Cp	1.015595
Temperature	309.8113 °C
Cp	1.015699
Temperature	310.7724 °C
Cp	1.015789
Temperature	311.7334 °C
Cp	1.015865
Temperature	312.6945 °C
Cp	1.015925
Temperature	313.6556 °C
Cp	1.015964
Temperature	314.6167 °C
Cp	1.015999
Temperature	315.5778 °C
Cp	1.016018
Temperature	316.5388 °C
Cp	1.016025
Temperature	317.4999 °C
Cp	1.016024
Temperature	318.461 °C
Cp	1.01602
Temperature	319.4221 °C
Cp	1.016029
Temperature	320.3831 °C
Cp	1.016025
Temperature	321.3442 °C
Cp	1.016037
Temperature	322.3053 °C
Cp	1.016066
Temperature	323.2664 °C
Cp	1.01611
Temperature	324.2275 °C
Cp	1.016169
Temperature	325.1886 °C
Cp	1.016225
Temperature	326.1496 °C
Cp	1.016318
Temperature	327.1107 °C
Cp	1.016411
Temperature	328.0718 °C
Cp	1.016504
Temperature	329.0329 °C
Cp	1.016596
Temperature	329.994 °C
Cp	1.016687
Temperature	330.955 °C
Cp	1.016775
Temperature	331.9161 °C
Cp	1.016864
Temperature	332.8772 °C
Cp	1.016942
Temperature	333.8383 °C
Cp	1.017019
Temperature	334.7993 °C
Cp	1.017093
Temperature	335.7604 °C
Cp	1.017163
Temperature	336.7215 °C
Cp	1.01723
Temperature	337.6826 °C
Cp	1.017295
Temperature	338.6437 °C
Cp	1.017358
Temperature	339.6048 °C
Cp	1.017423
Temperature	340.5658 °C
Cp	1.017491
Temperature	341.5269 °C
Cp	1.017567
[...]
151.6000	111.1025	0.3730
151.6083	111.0185	0.3730
151.6167	110.9365	0.3730
151.6250	110.8533	0.3729
151.6333	110.7702	0.3729
151.6417	110.6866	0.3729
151.6500	110.6040	0.3728
151.6583	110.5217	0.3728
151.6667	110.4365	0.3728
151.6750	110.3539	0.3728
151.6833	110.2714	0.3727
151.6917	110.1875	0.3727
151.7000	110.1047	0.3727
151.7083	110.0213	0.3726
151.7167	109.9373	0.3726
151.7250	109.8545	0.3725
151.7333	109.7710	0.3725
151.7417	109.6883	0.3725
151.7500	109.6046	0.3724
151.7583	109.5213	0.3724
151.7667	109.4386	0.3724
151.7750	109.3558	0.3723
151.7833	109.2731	0.3723
151.7917	109.1895	0.3723
151.8000	109.1058	0.3723
151.8083	109.0230	0.3722
151.8167	108.9411	0.3722
151.8250	108.8571	0.3722
151.8333	108.7745	0.3721
151.8417	108.6912	0.3721
151.8500	108.6087	0.3720
151.8583	108.5243	0.3720
151.8667	108.4413	0.3718
151.8750	108.3587	0.3717
151.8833	108.2758	0.3717
151.8917	108.1927	0.3717
151.9000	108.1083	0.3717
151.9083	108.0264	0.3716
151.9167	107.9421	0.3716
151.9250	107.8596	0.3716
151.9333	107.7757	0.3715
151.9417	107.6939	0.3715
151.9500	107.6094	0.3714
151.9583	107.5274	0.3714
151.9667	107.4445	0.3714
151.9750	107.3606	0.3714
151.9833	107.2768	0.3713
151.9917	107.1951	0.3713
152.0000	107.1114	0.3712
152.0083	107.0289	0.3712
152.0167	106.9441	0.3712
152.0250	106.8601	0.3712
152.0333	106.7786	0.3711
152.0417	106.6953	0.3711
152.0500	106.6117	0.3711
152.0583	106.5275	0.3711
152.0667	106.4458	0.3710
152.0750	106.3632	0.3710
152.0833	106.2802	0.3709
152.0917	106.1962	0.3709
152.1000	106.1134	0.3708
152.1083	106.0301	0.3708
152.1167	105.9474	0.3707
152.1250	105.8644	0.3707
152.1333	105.7810	0.3707
152.1417	105.6978	0.3706
152.1500	105.6153	0.3706
152.1583	105.5311	0.3706
152.1667	105.4481	0.3705
152.1750	105.3655	0.3705
152.1833	105.2826	0.3705
152.1917	105.1995	0.3705
152.2000	105.1160	0.3704
152.2083	105.0333	0.3704
152.2167	104.9488	0.3704
152.2250	104.8657	0.3703
152.2333	104.7827	0.3703
152.2417	104.6999	0.3703
152.2500	104.6159	0.3702
152.2583	104.5342	0.3702
152.2667	104.4504	0.3702
152.2750	104.3668	0.3702
152.2833	104.2837	0.3701
152.2917	104.2015	0.3701
152.3000	104.1185	0.3700
152.3083	104.0350	0.3700
152.3167	103.9526	0.3700
152.3250	103.8692	0.3700
152.3333	103.7855	0.3700
152.3417	103.7040	0.3699
152.3500	103.6195	0.3699
152.3583	103.5360	0.3699
152.3667	103.4524	0.3698
152.3750	103.3697	0.3698
152.3833	103.2865	0.3698
152.3917	103.2036	0.3698
152.4000	103.1211	0.3698
152.4083	103.0367	0.3697
152.4167	102.9541	0.3697
152.4250	102.8702	0.3697
152.4333	102.7880	0.3696
152.4417	102.7059	0.3696
152.4500	102.6205	0.3696
152.4583	102.5389	0.3696
152.4667	102.4554	0.3695
152.4750	102.3720	0.3695
152.4833	102.2888	0.3695
152.4917	102.2069	0.3694
152.5000	102.1235	0.3694
152.5083	102.0397	0.3694
152.5167	101.9572	0.3693
152.5250	101.8741	0.3693
152.5333	101.7912	0.3693
152.5417	101.7081	0.3692
152.5500	101.6247	0.3692
152.5583	101.5403	0.3692
152.5667	101.4588	0.3691
152.5750	101.3751	0.3691
152.5833	101.2915	0.3691
152.5917	101.2092	0.3691
152.6000	101.1264	0.3690
152.6083	101.0436	0.3690
152.6167	100.9603	0.3690
152.6250	100.8768	0.3689
152.6333	100.7940	0.3689
152.6417	100.7106	0.3689
152.6500	100.6276	0.3689
152.6583	100.5442	0.3688
152.6667	100.4609	0.3688
152.6750	100.3785	0.3688
152.6833	100.2952	0.3688
152.6917	100.2121	0.3688
152.7000	100.1280	0.3687
152.7083	100.0448	0.3687
152.7167	99.9623	0.3687
152.7250	99.8802	0.3687
152.7333	99.7958	0.3687
152.7417	99.7129	0.3686
152.7500	99.6284	0.3686
152.7583	99.5469	0.3686
152.7667	99.4634	0.3686
152.7750	99.3800	0.3685
152.7833	99.2982	0.3685
152.7917	99.2139	0.3685
152.8000	99.1311	0.3685
152.8083	99.0490	0.3684
152.8167	98.9648	0.3684
152.8250	98.8818	0.3684
152.8333	98.7988	0.3683
152.8417	98.7150	0.3683
152.8500	98.6317	0.3683
152.8583	98.5485	0.3683
152.8667	98.4660	0.3682
152.8750	98.3820	0.3682
152.8833	98.2998	0.3682
152.8917	98.2156	0.3681
152.9000	98.1335	0.3681
152.9083	98.0487	0.3681
152.9167	97.9665	0.3680
152.9250	97.8840	0.3680
152.9333	97.8004	0.3680
152.9417	97.7167	0.3679
152.9500	97.6340	0.3679
152.9583	97.5500	0.3679
152.9667	97.4677	0.3678
152.9750	97.3862	0.3677
152.9833	97.3020	0.3677
152.9917	97.2183	0.3676
153.0000	97.1353	0.3675
153.0083	97.0528	0.3675
153.0167	96.9690	0.3673
153.0250	96.8867	0.3673
153.0333	96.8023	0.3673
153.0417	96.7200	0.3673
153.0500	96.6372	0.3672
153.0583	96.5541	0.3672
153.0667	96.4704	0.3672
153.0750	96.3882	0.3671
153.0833	96.3052	0.3671
153.0917	96.2207	0.3671
153.1000	96.1388	0.3671
153.1083	96.0551	0.3670
153.1167	95.9724	0.3670
153.1250	95.8884	0.3670
153.1333	95.8058	0.3669
153.1417	95.7222	0.3669
153.1500	95.6392	0.3669
153.1583	95.5563	0.3668
153.1667	95.4731	0.3668
153.1750	95.3905	0.3668
153.1833	95.3064	0.3668
153.1917	95.2236	0.3667
153.2000	95.1398	0.3667
153.2083	95.0576	0.3667
153.2167	94.9740	0.3667
153.2250	94.8905	0.3666
153.2333	94.8078	0.3666
153.2417	94.7247	0.3666
153.2500	94.6412	0.3665
153.2583	94.5583	0.3665
153.2667	94.4750	0.3665
153.2750	94.3912	0.3664
153.2833	94.3089	0.3664
153.2917	94.2263	0.3664
153.3000	94.1431	0.3664
153.3083	94.0600	0.3663
153.3167	93.9769	0.3663
153.3250	93.8942	0.3663
153.3333	93.8109	0.3662
153.3417	93.7279	0.3662
153.3500	93.6450	0.3662
153.3583	93.5610	0.3661
153.3667	93.4770	0.3661
153.3750	93.3943	0.3660
153.3833	93.3121	0.3660
153.3917	93.2284	0.3660
153.4000	93.1445	0.3660
153.4083	93.0623	0.3659
153.4167	92.9797	0.3658
153.4250	92.8960	0.3658
153.4333	92.8126	0.3658
153.4417	92.7293	0.3658
153.4500	92.6460	0.3657
153.4583	92.5634	0.3657
153.4667	92.4804	0.3657
153.4750	92.3973	0.3656
153.4833	92.3135	0.3656
153.4917	92.2315	0.3656
153.5000	92.1473	0.3655
153.5083	92.0653	0.3655
153.5167	91.9817	0.3655
153.5250	91.8983	0.3655
153.5333	91.8149	0.3654
153.5417	91.7319	0.3654
153.5500	91.6498	0.3654
153.5583	91.5660	0.3653
153.5667	91.4820	0.3653
153.5750	91.3992	0.3653
153.5833	91.3163	0.3653
153.5917	91.2337	0.3652
153.6000	91.1498	0.3652
153.6083	91.0660	0.3652
153.6167	90.9833	0.3651
153.6250	90.9003	0.3651
153.6333	90.8174	0.3651
153.6417	90.7345	0.3650
153.6500	90.6515	0.3650
153.6583	90.5672	0.3650
153.6667	90.4854	0.3650
153.6750	90.4020	0.3649
153.6833	90.3190	0.3649
153.6917	90.2365	0.3649
153.7000	90.1535	0.3648
153.7083	90.0701	0.3648
153.7167	89.9872	0.3648
153.7250	89.9032	0.3647
153.7333	89.8204	0.3647
153.7417	89.7369	0.3647
153.7500	89.6533	0.3647
153.7583	89.5710	0.3646
153.7667	89.4868	0.3646
153.7750	89.4051	0.3646
153.7833	89.3212	0.3645
153.7917	89.2386	0.3645
153.8000	89.1542	0.3645
153.8083	89.0719	0.3644
153.8167	88.9880	0.3644
153.8250	88.9053	0.3644
153.8333	88.8225	0.3644
153.8417	88.7395	0.3643
153.8500	88.6553	0.3642
153.8583	88.5724	0.3642
153.8667	88.4905	0.3642
153.8750	88.4064	0.3642
153.8833	88.3233	0.3640
153.8917	88.2401	0.3640
153.9000	88.1575	0.3640
153.9083	88.0745	0.3639
153.9167	87.9909	0.3639
153.9250	87.9070	0.3639
153.9333	87.8244	0.3639
153.9417	87.7419	0.3639
153.9500	87.6588	0.3638
153.9583	87.5760	0.3638
153.9667	87.4917	0.3638
153.9750	87.4091	0.3637
153.9833	87.3257	0.3637
153.9917	87.2420	0.3637
154.0000	87.1591	0.3637
154.0083	87.0767	0.3636
154.0167	86.9927	0.3636
154.0250	86.9108	0.3635
154.0333	86.8268	0.3635
154.0417	86.7437	0.3635
154.0500	86.6609	0.3634
154.0583	86.5771	0.3634
154.0667	86.4943	0.3634
154.0750	86.4105	0.3633
154.0833	86.3271	0.3633
154.0917	86.2446	0.3633
154.1000	86.1613	0.3632
154.1083	86.0784	0.3632
154.1167	85.9962	0.3632
154.1250	85.9121	0.3632
154.1333	85.8285	0.3631
154.1417	85.7447	0.3631
154.1500	85.6624	0.3631
154.1583	85.5794	0.3630
154.1667	85.4970	0.3630
154.1750	85.4127	0.3630
154.1833	85.3293	0.3629
154.1917	85.2480	0.3629
154.2000	85.1641	0.3628
154.2083	85.0816	0.3628
154.2167	84.9975	0.3627
154.2250	84.9148	0.3627
154.2333	84.8302	0.3627
154.2417	84.7493	0.3626
154.2500	84.6649	0.3626
154.2583	84.5818	0.3626
154.2667	84.4989	0.3625
154.2750	84.4141	0.3625
154.2833	84.3318	0.3625
154.2917	84.2482	0.3624
154.3000	84.1657	0.3624
154.3083	84.0843	0.3623
154.3167	84.0005	0.3622
154.3250	83.9165	0.3622
154.3333	83.8334	0.3622
154.3417	83.7510	0.3622
154.3500	83.6675	0.3621
154.3583	83.5836	0.3621
154.3667	83.5007	0.3620
154.3750	83.4173	0.3620
154.3833	83.3347	0.3620
154.3917	83.2518	0.3619
154.4000	83.1683	0.3619
154.4083	83.0850	0.3618
154.4167	83.0030	0.3618
154.4250	82.9205	0.3617
154.4333	82.8372	0.3617
154.4417	82.7536	0.3617
154.4500	82.6708	0.3616
154.4583	82.5873	0.3615
154.4667	82.5032	0.3615
154.4750	82.4204	0.3614
154.4833	82.3384	0.3614
154.4917	82.2544	0.3614
154.5000	82.1719	0.3613
154.5083	82.0873	0.3613
154.5167	82.0045	0.3613
154.5250	81.9214	0.3613
154.5333	81.8385	0.3612
154.5417	81.7558	0.3612
154.5500	81.6711	0.3612
154.5583	81.5889	0.3612
154.5667	81.5059	0.3611
154.5750	81.4225	0.3611
154.5833	81.3396	0.3611
154.5917	81.2562	0.3610
154.6000	81.1730	0.3610
154.6083	81.0909	0.3609
154.6167	81.0073	0.3609
154.6250	80.9237	0.3609
154.6333	80.8412	0.3608
154.6417	80.7574	0.3608
154.6500	80.6745	0.3607
154.6583	80.5904	0.3607
154.6667	80.5072	0.3607
154.6750	80.4240	0.3606
154.6833	80.3415	0.3606
154.6917	80.2587	0.3606
154.7000	80.1754	0.3606
154.7083	80.0921	0.3605
154.7167	80.0085	0.3604
154.7250	79.9261	0.3604
154.7333	79.8414	0.3604
154.7417	79.7586	0.3603
154.7500	79.6756	0.3603
154.7583	79.5924	0.3602
154.7667	79.5100	0.3602
154.7750	79.4256	0.3602
154.7833	79.3426	0.3601
154.7917	79.2590	0.3601
154.8000	79.1780	0.3600
154.8083	79.0936	0.3600
154.8167	79.0105	0.3600
154.8250	78.9284	0.3599
154.8333	78.8445	0.3599
154.8417	78.7614	0.3598
154.8500	78.6782	0.3598
154.8583	78.5946	0.3598
154.8667	78.5131	0.3597
154.8750	78.4284	0.3597
154.8833	78.3455	0.3596
154.8917	78.2631	0.3596
154.9000	78.1792	0.3595
154.9083	78.0962	0.3595
154.9167	78.0138	0.3595
154.9250	77.9304	0.3594
154.9333	77.8460	0.3594
154.9417	77.7637	0.3593
154.9500	77.6809	0.3593
154.9583	77.5973	0.3592
154.9667	77.5148	0.3592
154.9750	77.4304	0.3591
154.9833	77.3487	0.3591
154.9917	77.2645	0.3591
155.0000	77.1806	0.3590
155.0083	77.0984	0.3590
155.0167	77.0140	0.3589
155.0250	76.9322	0.3589
155.0333	76.8480	0.3589
155.0417	76.7658	0.3588
155.0500	76.6829	0.3588
155.0583	76.5984	0.3588
155.0667	76.5162	0.3587
155.0750	76.4324	0.3586
155.0833	76.3504	0.3586
155.0917	76.2665	0.3585
155.1000	76.1831	0.3585
155.1083	76.1007	0.3584
155.1167	76.0169	0.3584
155.1250	75.9338	0.3584
155.1333	75.8512	0.3583
155.1417	75.7698	0.3583
155.1500	75.6847	0.3582
155.1583	75.6027	0.3582
155.1667	75.5180	0.3582
155.1750	75.4359	0.3581
155.1833	75.3525	0.3580
155.1917	75.2696	0.3580
155.2000	75.1857	0.3579
155.2083	75.1026	0.3579
155.2167	75.0195	0.3579
155.2250	74.9363	0.3578
155.2333	74.8524	0.3578
155.2417	74.7706	0.3578
155.2500	74.6873	0.3577
155.2583	74.6050	0.3577
155.2667	74.5208	0.3577
155.2750	74.4378	0.3573
155.2833	74.3537	0.3572
155.2917	74.2718	0.3572
155.3000	74.1881	0.3571
155.3083	74.1048	0.3571
155.3167	74.0225	0.3571
155.3250	73.9389	0.3570
155.3333	73.8560	0.3570
155.3417	73.7721	0.3570
155.3500	73.6890	0.3570
155.3583	73.6073	0.3569
155.3667	73.5222	0.3569
155.3750	73.4410	0.3569
155.3833	73.3578	0.3569
155.3917	73.2737	0.3568
155.4000	73.1906	0.3568
155.4083	73.1086	0.3568
155.4167	73.0252	0.3568
155.4250	72.9432	0.3566
155.4333	72.8602	0.3566
155.4417	72.7768	0.3566
155.4500	72.6939	0.3565
155.4583	72.6109	0.3564
155.4667	72.5276	0.3564
155.4750	72.4450	0.3564
155.4833	72.3624	0.3563
155.4917	72.2790	0.3563
155.5000	72.1963	0.3563
155.5083	72.1127	0.3563
155.5167	72.0306	0.3562
155.5250	71.9477	0.3562
155.5333	71.8639	0.3561
155.5417	71.7804	0.3561
155.5500	71.6984	0.3561
155.5583	71.6140	0.3560
155.5667	71.5319	0.3560
155.5750	71.4486	0.3560
155.5833	71.3658	0.3560
155.5917	71.2821	0.3559
155.6000	71.1991	0.3559
155.6083	71.1163	0.3559
155.6167	71.0330	0.3558
155.6250	70.9493	0.3558
155.6333	70.8673	0.3558
155.6417	70.7840	0.3558
155.6500	70.7009	0.3557
155.6583	70.6178	0.3557
155.6667	70.5342	0.3556
155.6750	70.4513	0.3556
155.6833	70.3691	0.3556
155.6917	70.2847	0.3555
155.7000	70.2016	0.3555
155.7083	70.1187	0.3555
155.7167	70.0354	0.3555
155.7250	69.9518	0.3555
155.7333	69.8693	0.3554
155.7417	69.7852	0.3554
155.7500	69.7019	0.3554
155.7583	69.6190	0.3554
155.7667	69.5364	0.3553
155.7750	69.4530	0.3553
155.7833	69.3701	0.3553
155.7917	69.2869	0.3552
155.8000	69.2034	0.3552
155.8083	69.1196	0.3552
155.8167	69.0370	0.3552
155.8250	68.9548	0.3552
155.8333	68.8705	0.3551
155.8417	68.7883	0.3551
155.8500	68.7042	0.3551
155.8583	68.6205	0.3551
155.8667	68.5388	0.3551
155.8750	68.4549	0.3550
155.8833	68.3717	0.3550
155.8917	68.2890	0.3550
155.9000	68.2054	0.3550
155.9083	68.1222	0.3550
155.9167	68.0372	0.3550
155.9250	67.9548	0.3549
155.9333	67.8726	0.3549
155.9417	67.7898	0.3548
155.9500	67.7063	0.3548
155.9583	67.6220	0.3548
155.9667	67.5391	0.3548
155.9750	67.4562	0.3547
155.9833	67.3733	0.3547
155.9917	67.2911	0.3547
156.0000	67.2063	0.3547
156.0083	67.1228	0.3546
156.0167	67.0409	0.3546
156.0250	66.9577	0.3546
156.0333	66.8745	0.3545
156.0417	66.7906	0.3545
156.0500	66.7070	0.3545
156.0583	66.6250	0.3545
156.0667	66.5410	0.3545
156.0750	66.4589	0.3544
156.0833	66.3749	0.3544
156.0917	66.2914	0.3544
156.1000	66.2086	0.3543
156.1083	66.1256	0.3543
156.1167	66.0428	0.3543
156.1250	65.9592	0.3543
156.1333	65.8754	0.3543
156.1417	65.7930	0.3542
156.1500	65.7091	0.3542
156.1583	65.6252	0.3543
156.1667	65.5436	0.3543
156.1750	65.4605	0.3543
156.1833	65.3772	0.3543
156.1917	65.2937	0.3544
156.2000	65.2104	0.3544
156.2083	65.1283	0.3552
156.2167	65.0451	0.3558
156.2250	64.9624	0.3572
156.2333	64.8805	0.3598
156.2417	64.7981	0.3620
156.2500	64.7163	0.3660
156.2583	64.6337	0.3696
156.2667	64.5518	0.3748
156.2750	64.4714	0.3816
156.2833	64.3901	0.3908
156.2917	64.3109	0.4030
156.3000	64.2313	0.4174
156.3083	64.1554	0.4381
156.3167	64.0796	0.4644
156.3250	64.0058	0.4968
156.3333	63.9365	0.5384
156.3417	63.8702	0.5902
156.3500	63.8069	0.6520
156.3583	63.7510	0.7257
156.3667	63.6995	0.8115
156.3750	63.6537	0.9069
156.3833	63.6150	1.0099
156.3917	63.5832	1.1193
156.4000	63.5567	1.2308
156.4083	63.5361	1.3416
156.4167	63.5207	1.4488
156.4250	63.5073	1.5519
156.4333	63.4980	1.6477
156.4417	63.4891	1.7344
156.4500	63.4823	1.8161
156.4583	63.4737	1.8902
156.4667	63.4673	1.9568
156.4750	63.4578	2.0191
156.4833	63.4461	2.0762
156.4917	63.4333	2.1288
156.5000	63.4181	2.1787
156.5083	63.4007	2.2254
156.5167	63.3815	2.2693
156.5250	63.3603	2.3121
156.5333	63.3357	2.3534
156.5417	63.3100	2.3931
156.5500	63.2830	2.4309
156.5583	63.2520	2.4686
156.5667	63.2221	2.5055
156.5750	63.1890	2.5403
156.5833	63.1544	2.5750
156.5917	63.1187	2.6097
156.6000	63.0817	2.6433
156.6083	63.0438	2.6763
156.6167	63.0034	2.7077
156.6250	62.9615	2.7383
156.6333	62.9199	2.7692
156.6417	62.8761	2.7982
156.6500	62.8330	2.8269
156.6583	62.7874	2.8543
156.6667	62.7406	2.8815
156.6750	62.6929	2.9068
156.6833	62.6441	2.9313
156.6917	62.5945	2.9552
156.7000	62.5439	2.9771
156.7083	62.4923	2.9985
156.7167	62.4393	3.0180
156.7250	62.3848	3.0370
156.7333	62.3302	3.0546
156.7417	62.2736	3.0708
156.7500	62.2170	3.0856
156.7583	62.1572	3.0988
156.7667	62.0981	3.1116
156.7750	62.0367	3.1226
156.7833	61.9755	3.1314
156.7917	61.9112	3.1395
156.8000	61.8467	3.1461
156.8083	61.7814	3.1521
156.8167	61.7128	3.1560
156.8250	61.6455	3.1574
156.8333	61.5768	3.1592
156.8417	61.5049	3.1563
156.8500	61.4326	3.1470
156.8583	61.3574	3.1387
156.8667	61.2818	3.1328
156.8750	61.2045	3.1243
156.8833	61.1240	3.1153
156.8917	61.0441	3.1038
156.9000	60.9624	3.0924
156.9083	60.8795	3.0784
156.9167	60.7946	3.0641
156.9250	60.7096	3.0474
156.9333	60.6221	3.0303
156.9417	60.5324	3.0105
156.9500	60.4426	2.9887
156.9583	60.3505	2.9662
156.9667	60.2577	2.9417
156.9750	60.1629	2.9167
156.9833	60.0672	2.8890
156.9917	59.9704	2.8595
157.0000	59.8704	2.8150
157.0083	59.7660	2.7602
157.0167	59.6603	2.7355
157.0250	59.5571	2.7128
157.0333	59.4513	2.6844
157.0417	59.3463	2.6543
157.0500	59.2380	2.6229
157.0583	59.1315	2.5899
157.0667	59.0230	2.5569
157.0750	58.9144	2.5241
157.0833	58.8042	2.4910
157.0917	58.6941	2.4580
157.1000	58.5834	2.4310
157.1083	58.4729	2.4091
157.1167	58.3633	2.3859
157.1250	58.2540	2.3509
157.1333	58.1428	2.3155
157.1417	58.0308	2.2828
157.1500	57.9187	2.2487
157.1583	57.8057	2.2133
157.1667	57.6943	2.1764
157.1750	57.5789	2.1404
157.1833	57.4641	2.1026
157.1917	57.3504	2.0678
157.2000	57.2355	2.0333
157.2083	57.1198	1.9995
157.2167	57.0050	1.9655
157.2250	56.8885	1.9329
157.2333	56.7728	1.8998
157.2417	56.6572	1.8660
157.2500	56.5401	1.8313
157.2583	56.4250	1.7972
157.2667	56.3089	1.7657
157.2750	56.1934	1.7365
157.2833	56.0776	1.7083
157.2917	55.9621	1.6784
157.3000	55.8491	1.6489
157.3083	55.7338	1.6215
157.3167	55.6191	1.5939
157.3250	55.5066	1.5671
157.3333	55.3932	1.5420
157.3417	55.2806	1.5173
157.3500	55.1685	1.4939
157.3583	55.0551	1.4694
157.3667	54.9442	1.4464
157.3750	54.8337	1.4221
157.3833	54.7241	1.4002
157.3917	54.6137	1.3787
157.4000	54.5040	1.3576
157.4083	54.3965	1.3373
157.4167	54.2865	1.3166
157.4250	54.1793	1.2977
157.4333	54.0724	1.2795
157.4417	53.9657	1.2601
157.4500	53.8606	1.2418
157.4583	53.7541	1.2236
157.4667	53.6491	1.2063
157.4750	53.5447	1.1894
157.4833	53.4409	1.1723
157.4917	53.3366	1.1561
157.5000	53.2331	1.1412
157.5083	53.1285	1.1245
157.5167	53.0274	1.1101
157.5250	52.9258	1.0959
157.5333	52.8245	1.0818
157.5417	52.7236	1.0676
157.5500	52.6224	1.0550
157.5583	52.5213	1.0415
157.5667	52.4225	1.0280
157.5750	52.3230	1.0154
157.5833	52.2237	1.0031
157.5917	52.1246	0.9922
157.6000	52.0267	0.9799
157.6083	51.9287	0.9685
157.6167	51.8309	0.9573
157.6250	51.7333	0.9459
157.6333	51.6380	0.9361
157.6417	51.5408	0.9253
157.6500	51.4440	0.9153
157.6583	51.3486	0.9051
157.6667	51.2524	0.8952
157.6750	51.1570	0.8849
157.6833	51.0628	0.8764
157.6917	50.9653	0.8673
157.7000	50.8706	0.8577
157.7083	50.7785	0.8493
157.7167	50.6838	0.8414
157.7250	50.5901	0.8335
157.7333	50.4969	0.8269
157.7417	50.4024	0.8200
157.7500	50.3095	0.8104
157.7583	50.2169	0.8027
157.7667	50.1234	0.7946
157.7750	50.0315	0.7872
157.7833	49.9404	0.7801
157.7917	49.8479	0.7739
157.8000	49.7565	0.7670
157.8083	49.6636	0.7598
157.8167	49.5726	0.7536
157.8250	49.4819	0.7476
157.8333	49.3902	0.7402
157.8417	49.3000	0.7350
157.8500	49.2095	0.7300
157.8583	49.1193	0.7238
157.8667	49.0278	0.7176
157.8750	48.9382	0.7116
157.8833	48.8479	0.7072
157.8917	48.7577	0.7013
157.9000	48.6685	0.6958
157.9083	48.5796	0.6908
157.9167	48.4880	0.6858
157.9250	48.4003	0.6809
157.9333	48.3110	0.6765
157.9417	48.2208	0.6714
157.9500	48.1327	0.6675
157.9583	48.0427	0.6618
157.9667	47.9545	0.6571
157.9750	47.8656	0.6535
157.9833	47.7763	0.6487
157.9917	47.6896	0.6440
158.0000	47.6008	0.6401
158.0083	47.5114	0.6357
158.0167	47.4243	0.6323
158.0250	47.3360	0.6284
158.0333	47.2483	0.6247
158.0417	47.1590	0.6206
158.0500	47.0726	0.6172
158.0583	46.9850	0.6133
158.0667	46.8969	0.6093
158.0750	46.8094	0.6062
158.0833	46.7228	0.6024
158.0917	46.6349	0.5987
158.1000	46.5467	0.5965
158.1083	46.4602	0.5929
158.1167	46.3733	0.5893
158.1250	46.2867	0.5863
158.1333	46.2000	0.5828
158.1417	46.1126	0.5806
158.1500	46.0256	0.5770
158.1583	45.9395	0.5741
158.1667	45.8516	0.5709
158.1750	45.7639	0.5680
158.1833	45.6785	0.5658
158.1917	45.5920	0.5626
158.2000	45.5066	0.5598
158.2083	45.4206	0.5570
158.2167	45.3334	0.5545
158.2250	45.2474	0.5514
158.2333	45.1614	0.5496
158.2417	45.0748	0.5463
158.2500	44.9893	0.5432
158.2583	44.9030	0.5426
158.2667	44.8178	0.5389
158.2750	44.7310	0.5373
158.2833	44.6444	0.5347
158.2917	44.5592	0.5320
158.3000	44.4728	0.5299
158.3083	44.3871	0.5273
158.3167	44.3018	0.5259
158.3250	44.2156	0.5230
158.3333	44.1304	0.5209
158.3417	44.0439	0.5194
158.3500	43.9579	0.5165
158.3583	43.8729	0.5150
158.3667	43.7883	0.5123
158.3750	43.7022	0.5111
158.3833	43.6176	0.5090
158.3917	43.5312	0.5071
158.4000	43.4454	0.5055
158.4083	43.3608	0.5030
158.4167	43.2750	0.5011
158.4250	43.1900	0.5000
158.4333	43.1039	0.4975
158.4417	43.0181	0.4958
158.4500	42.9334	0.4933
158.4583	42.8481
158.4667	42.7631
158.4750	42.6781
158.4833	42.5929
158.4917	42.5086
158.5000	42.4213
158.5083