File: Example Date/My Sample/DSC/test01/DSC TA/YN045.txt
Filename	YN045
Instrument name	DSC2A-01799 (192.168.1.250)
Operator
rundate	05/12/2024
Sample name	YN045
proceduresegments	Ramp 10.00 °C/min to 150.0000 °C; Isothermal 3.0 min; Ramp 10.00 °C/min to -100.0000 °C; Isothermal 3.0 min; Ramp 10.00 °C/min to 150.0000 °C; Isothermal 3.0 min; Ramp 10.00 °C/min to -100.0000 °C; Isothermal 3.0 min; Ramp 10.00 °C/min to 150.0000 °C; Isothermal 3.0 min; Ramp 10.00 °C/min to 40.0000 °C
[File Parameters]
Run Date	05/12/2024 22:13:07
Trios version	5.7.0.56
Original File Name
Current File Name	C:\Users\TA Instruments DSC\Desktop\Data\Yutong Niu\YN045.tri
User at run start	DESKTOP-CFGN8IT\TA Instruments DSC
[Procedure]
Procedure Name	polyether
Sample Name	YN045
Sample Mass	9.4 mg
Reference Sample Mass	0 mg
Pan Mass	60.98 mg
Pan Number	25
Reference Pan Mass	60.81 mg
Reference Pan Number	45
Pan Type	Tzero Aluminum Pin Hole Hermetic
Comments
Project Name
Operator
Test	Custom
Unload Max Temperature	25
Unload Min Temperature	25
FillCooler	Do not fill
Load Max Temperature	25
Load Min Temperature	25
Discard pan in waste bin at end of test	Yes
Stop on Gas Flow Error	No
[Signal List]
Signal #1	Time (min)
Signal #2	Temperature (°C)
Signal #3	Heat Flow (mW)
Signal #4	Delta T (µV)
Signal #5	Delta Tzero (µV)
Signal #6	Tzero Temperature (°C)
Signal #7	Cell Purge (mL/min)
Signal #8	Heater Temp (°C)
Signal #9	Power Delivered (W)
Signal #10	Reference Junction Temperature (°C)
Signal #11	Flange Temperature (°C)
Signal #12	Heat Flow Phase (rad)
Signal #13	Total Heat Capacity (J/°C)
Signal #14	Heat Capacity (J/°C)
Signal #15	LN Pump Tank level (%)
[Configuration]
Company Name	Warwick University
Instrument Name	DSC2A-01799
Instrument Type	DSC2500
Serial Number	DSC2A-01799
IP	192.168.1.250
Location of Instrument	Polymer RTP
DisplayType	TianmaV2andV3
Sample Interval 	0.1 s/pt
Selected Heat Flow	T4P
Exotherm Direction	Up
Cell Serial	DRC2-03788
Lid Type	High Temperature
Cooler	LN Pump
Leave Cooler on at End of Sequence	Off
Gas 2	Air
Gas Selected	Channel 1: Nitrogen
Flow Rate	50 mL/min
Secondary Purge	On
Licensed Heat Flow	Heat Flow T4P
Modulation Licensed	Yes
[Versions]
Common IDD Version	1
Cortex Version	VER 2.11.0.729
Driver	5.0.0.6
GDM Version	1.0.3.3
TouchscreenVersion	1.0.3.1841
FEP Version	1.2.1.21
FEP Bootloader	2.0.0.5
AutoSampler Version	2.1.2.1
Auto Sampler Bootloader	2.0.0.5
FCM Version	1.1.0.3
FCM Bootloader	2.0.0.5
LN Pump Version	10.17.0.0
LN Pump Bootloader	2.0.0.5
[Experiment Logs]
Experiment Log Entry # 1	Ramp Segment 10 C/min to 150 Started
Experiment Log Entry # 3	Air Cool is off.
Experiment Log Entry # 5	Isothermal Segment 3 min started
Experiment Log Entry # 7	Ramp Segment 10 C/min to -100 Started
Experiment Log Entry # 9	Isothermal Segment 3 min started
Experiment Log Entry # 11	Ramp Segment 10 C/min to 150 Started
Experiment Log Entry # 13	Isothermal Segment 3 min started
Experiment Log Entry # 15	Ramp Segment 10 C/min to -100 Started
Experiment Log Entry # 17	Isothermal Segment 3 min started
Experiment Log Entry # 19	Ramp Segment 10 C/min to 150 Started
Experiment Log Entry # 21	Isothermal Segment 3 min started
Experiment Log Entry # 23	Ramp Segment 10 C/min to 40 Started
[Method Log]
Method Log Entry # 1	(Ramp 246542) Ramp 10 °C/minute to 150 °C
Method Log Entry # 2	Isothermal 3 minutes
Method Log Entry # 3	(Ramp 246544) Ramp 10 °C/minute to -100 °C
Method Log Entry # 4	Isothermal 3 minutes
Method Log Entry # 5	(Ramp 246546) Ramp 10 °C/minute to 150 °C
Method Log Entry # 6	Isothermal 3 minutes
Method Log Entry # 7	(Ramp 246548) Ramp 10 °C/minute to -100 °C
Method Log Entry # 8	Isothermal 3 minutes
Method Log Entry # 9	(Ramp 246550) Ramp 10 °C/minute to 150 °C
Method Log Entry # 10	Isothermal 3 minutes
Method Log Entry # 11	(Ramp 246552) Ramp 10 °C/minute to 40 °C
Cell Serial	DRC2-03788
[T1 Calibration]
Date Applied	04/03/2021 14:58:04
Description
Gas Type	Nitrogen
Pan Type	None
Slope	-0.001800291
Offset	-0.1301359
Initial Temperature	-100.6228
GUID	a1d5a6be-decd-4ae4-b22f-d560f3a78a92
[TZero Calibration]
Date Applied	21/08/2024 09:53:38
Description	From -180.022 °C to 395.167 °C at 20.000°C/min
Gas Type	Nitrogen
Pan Type	None
Source Files 1	C:\ProgramData\TA Instruments\TRIOS\Data\TAService\PMV 20Aug2024\Tzero Cal.tri
Source Files 2	C:\ProgramData\TA Instruments\TRIOS\Data\TAService\PMV 20Aug2024\Tzero Cal sapphire.tri
Delta T Offset	1.787969
Delta T Slope	-0.003527276
Delta T0 Offset	0.06831977
Delta T0 Slope	0.02007191
[Temperature Calibration]
Date Applied	21/08/2024 11:06:35
Description	From 106.660 °C to 186.660 °C at 10.000°C/min
Gas Type	Nitrogen
Pan Type	Tzero Aluminum
Source Files 1	C:\ProgramData\TA Instruments\TRIOS\Data\TAService\PMV 20Aug2024\TA Indium cal.tri
Measured 1	157.9141
Known 1	156.66
[Cell Constant Calibration]
Date Applied	21/08/2024 11:06:35
Description	From 106.660 °C to 186.660 °C at 10.000°C/min
Gas Type	Nitrogen
Pan Type	Tzero Aluminum
Source Files 1	C:\ProgramData\TA Instruments\TRIOS\Data\TAService\PMV 20Aug2024\TA Indium cal.tri
T4P KCell	1.038055
Onset Slope	-66.72884 mW/°C
[Direct Cp Calibration]
Date Applied	19/11/2024 16:37:27
Description	From -89.996 °C to 396.697 °C at 20.000°C/min
Gas Type	Nitrogen
Pan Type	Tzero Aluminum
Source Files 1	C:\ProgramData\TA Instruments\TRIOS\Data\Sapphire Direct Heat Capacity(8).tri
GUID	544f8371-fe9b-4f4f-81ca-7980c172113e
Temperature	-89.99625 °C
Cp	1.464367
Temperature	-89.02287 °C
Cp	1.460558
Temperature	-88.04948 °C
Cp	1.456263
Temperature	-87.0761 °C
Cp	1.451626
Temperature	-86.10271 °C
Cp	1.446737
Temperature	-85.12933 °C
Cp	1.441723
Temperature	-84.15594 °C
Cp	1.436654
Temperature	-83.18256 °C
Cp	1.431684
Temperature	-82.20917 °C
Cp	1.426935
Temperature	-81.23578 °C
Cp	1.422396
Temperature	-80.2624 °C
Cp	1.418192
Temperature	-79.28901 °C
Cp	1.414363
Temperature	-78.31562 °C
Cp	1.410925
Temperature	-77.34224 °C
Cp	1.407865
Temperature	-76.36885 °C
Cp	1.405143
Temperature	-75.39546 °C
Cp	1.402789
Temperature	-74.42208 °C
Cp	1.400703
Temperature	-73.44869 °C
Cp	1.398837
Temperature	-72.4753 °C
Cp	1.397142
Temperature	-71.50192 °C
Cp	1.395565
Temperature	-70.52853 °C
Cp	1.394053
Temperature	-69.55515 °C
Cp	1.392558
Temperature	-68.58176 °C
Cp	1.391036
Temperature	-67.60838 °C
Cp	1.389483
Temperature	-66.63499 °C
Cp	1.387847
Temperature	-65.66161 °C
Cp	1.38616
Temperature	-64.68822 °C
Cp	1.384397
Temperature	-63.71483 °C
Cp	1.382535
Temperature	-62.74145 °C
Cp	1.380598
Temperature	-61.76806 °C
Cp	1.37865
Temperature	-60.79467 °C
Cp	1.376673
Temperature	-59.82129 °C
Cp	1.374677
Temperature	-58.8479 °C
Cp	1.372642
Temperature	-57.87452 °C
Cp	1.370686
Temperature	-56.90113 °C
Cp	1.368741
Temperature	-55.92775 °C
Cp	1.366786
Temperature	-54.95436 °C
Cp	1.364863
Temperature	-53.98097 °C
Cp	1.362959
Temperature	-53.00759 °C
Cp	1.361116
Temperature	-52.0342 °C
Cp	1.359247
Temperature	-51.06082 °C
Cp	1.357393
Temperature	-50.08743 °C
Cp	1.355593
Temperature	-49.11404 °C
Cp	1.353796
Temperature	-48.14066 °C
Cp	1.352008
Temperature	-47.16727 °C
Cp	1.350215
Temperature	-46.19389 °C
Cp	1.348396
Temperature	-45.2205 °C
Cp	1.346593
Temperature	-44.24712 °C
Cp	1.344755
Temperature	-43.27373 °C
Cp	1.342891
Temperature	-42.30034 °C
Cp	1.341008
Temperature	-41.32696 °C
Cp	1.339126
Temperature	-40.35357 °C
Cp	1.337236
Temperature	-39.38018 °C
Cp	1.335367
Temperature	-38.4068 °C
Cp	1.333522
Temperature	-37.43341 °C
Cp	1.331708
Temperature	-36.46003 °C
Cp	1.32991
Temperature	-35.48664 °C
Cp	1.328145
Temperature	-34.51326 °C
Cp	1.326414
Temperature	-33.53987 °C
Cp	1.32471
Temperature	-32.56648 °C
Cp	1.323012
Temperature	-31.5931 °C
Cp	1.321323
Temperature	-30.61971 °C
Cp	1.319657
Temperature	-29.64633 °C
Cp	1.317968
Temperature	-28.67294 °C
Cp	1.316286
Temperature	-27.69955 °C
Cp	1.314585
Temperature	-26.72617 °C
Cp	1.312857
Temperature	-25.75278 °C
Cp	1.31111
Temperature	-24.7794 °C
Cp	1.309333
Temperature	-23.80601 °C
Cp	1.307544
Temperature	-22.83262 °C
Cp	1.30575
Temperature	-21.85924 °C
Cp	1.303941
Temperature	-20.88585 °C
Cp	1.302132
Temperature	-19.91247 °C
Cp	1.300313
Temperature	-18.93908 °C
Cp	1.298512
Temperature	-17.96569 °C
Cp	1.296728
Temperature	-16.99231 °C
Cp	1.294939
Temperature	-16.01892 °C
Cp	1.293198
Temperature	-15.04554 °C
Cp	1.291453
Temperature	-14.07215 °C
Cp	1.289723
Temperature	-13.09876 °C
Cp	1.288007
Temperature	-12.12538 °C
Cp	1.286283
Temperature	-11.15199 °C
Cp	1.284578
Temperature	-10.17861 °C
Cp	1.282885
Temperature	-9.205221 °C
Cp	1.281173
Temperature	-8.231835 °C
Cp	1.279472
Temperature	-7.258449 °C
Cp	1.277766
Temperature	-6.285063 °C
Cp	1.276053
Temperature	-5.311677 °C
Cp	1.274341
Temperature	-4.338291 °C
Cp	1.272592
Temperature	-3.364905 °C
Cp	1.270844
Temperature	-2.391519 °C
Cp	1.269062
Temperature	-1.418133 °C
Cp	1.267264
Temperature	-0.4447474 °C
Cp	1.265435
Temperature	0.5286385 °C
Cp	1.263575
Temperature	1.502024 °C
Cp	1.261727
Temperature	2.47541 °C
Cp	1.259854
Temperature	3.448796 °C
Cp	1.257978
Temperature	4.422182 °C
Cp	1.256109
Temperature	5.395568 °C
Cp	1.254244
Temperature	6.368954 °C
Cp	1.252392
Temperature	7.34234 °C
Cp	1.250552
Temperature	8.315726 °C
Cp	1.248704
Temperature	9.289112 °C
Cp	1.246884
Temperature	10.2625 °C
Cp	1.245078
Temperature	11.23588 °C
Cp	1.243287
Temperature	12.20927 °C
Cp	1.241522
Temperature	13.18266 °C
Cp	1.239778
Temperature	14.15604 °C
Cp	1.238068
Temperature	15.12943 °C
Cp	1.236393
Temperature	16.10281 °C
Cp	1.234762
Temperature	17.0762 °C
Cp	1.233176
Temperature	18.04959 °C
Cp	1.231629
Temperature	19.02297 °C
Cp	1.230129
Temperature	19.99636 °C
Cp	1.228694
Temperature	20.96974 °C
Cp	1.22731
Temperature	21.94313 °C
Cp	1.225968
Temperature	22.91652 °C
Cp	1.224676
Temperature	23.8899 °C
Cp	1.223431
Temperature	24.86329 °C
Cp	1.222217
Temperature	25.83667 °C
Cp	1.221065
Temperature	26.81006 °C
Cp	1.219919
Temperature	27.78345 °C
Cp	1.218811
Temperature	28.75683 °C
Cp	1.21773
Temperature	29.73022 °C
Cp	1.216663
Temperature	30.7036 °C
Cp	1.2156
Temperature	31.67699 °C
Cp	1.214515
Temperature	32.65038 °C
Cp	1.213439
Temperature	33.62376 °C
Cp	1.21234
Temperature	34.59715 °C
Cp	1.211209
Temperature	35.57053 °C
Cp	1.210051
Temperature	36.54392 °C
Cp	1.208868
Temperature	37.5173 °C
Cp	1.207666
Temperature	38.49069 °C
Cp	1.206439
Temperature	39.46408 °C
Cp	1.205199
Temperature	40.43746 °C
Cp	1.203959
Temperature	41.41085 °C
Cp	1.202712
Temperature	42.38424 °C
Cp	1.20147
Temperature	43.35762 °C
Cp	1.200231
Temperature	44.33101 °C
Cp	1.199
Temperature	45.30439 °C
Cp	1.197777
Temperature	46.27778 °C
Cp	1.19657
Temperature	47.25116 °C
Cp	1.195367
Temperature	48.22455 °C
Cp	1.194179
Temperature	49.19794 °C
Cp	1.19301
Temperature	50.17132 °C
Cp	1.191849
Temperature	51.14471 °C
Cp	1.190694
Temperature	52.11809 °C
Cp	1.189555
Temperature	53.09148 °C
Cp	1.18843
Temperature	54.06487 °C
Cp	1.187311
Temperature	55.03825 °C
Cp	1.186195
Temperature	56.01164 °C
Cp	1.185095
Temperature	56.98502 °C
Cp	1.183997
Temperature	57.95841 °C
Cp	1.182894
Temperature	58.93179 °C
Cp	1.181793
Temperature	59.90518 °C
Cp	1.180693
Temperature	60.87857 °C
Cp	1.179595
Temperature	61.85195 °C
Cp	1.178501
Temperature	62.82534 °C
Cp	1.177406
Temperature	63.79873 °C
Cp	1.176313
Temperature	64.77211 °C
Cp	1.175239
Temperature	65.7455 °C
Cp	1.17417
Temperature	66.71888 °C
Cp	1.173105
Temperature	67.69227 °C
Cp	1.172037
Temperature	68.66566 °C
Cp	1.170989
Temperature	69.63904 °C
Cp	1.169948
Temperature	70.61243 °C
Cp	1.168905
Temperature	71.58582 °C
Cp	1.167872
Temperature	72.5592 °C
Cp	1.166849
Temperature	73.53259 °C
Cp	1.165851
Temperature	74.50597 °C
Cp	1.164848
Temperature	75.47935 °C
Cp	1.163876
Temperature	76.45274 °C
Cp	1.162926
Temperature	77.42612 °C
Cp	1.162008
Temperature	78.39951 °C
Cp	1.161113
Temperature	79.3729 °C
Cp	1.160219
Temperature	80.34628 °C
Cp	1.159377
Temperature	81.31967 °C
Cp	1.158546
Temperature	82.29306 °C
Cp	1.157726
Temperature	83.26644 °C
Cp	1.15692
Temperature	84.23983 °C
Cp	1.156126
Temperature	85.21322 °C
Cp	1.155375
Temperature	86.1866 °C
Cp	1.154604
Temperature	87.15999 °C
Cp	1.153869
Temperature	88.13337 °C
Cp	1.153158
Temperature	89.10676 °C
Cp	1.152474
Temperature	90.08015 °C
Cp	1.15181
Temperature	91.05353 °C
Cp	1.151134
Temperature	92.02692 °C
Cp	1.150513
Temperature	93.00031 °C
Cp	1.149892
Temperature	93.97369 °C
Cp	1.149266
Temperature	94.94707 °C
Cp	1.148642
Temperature	95.92046 °C
Cp	1.148019
Temperature	96.89384 °C
Cp	1.147402
Temperature	97.86723 °C
Cp	1.146799
Temperature	98.84062 °C
Cp	1.146191
Temperature	99.814 °C
Cp	1.145602
Temperature	100.7874 °C
Cp	1.14503
Temperature	101.7608 °C
Cp	1.144469
Temperature	102.7342 °C
Cp	1.143921
Temperature	103.7076 °C
Cp	1.143383
Temperature	104.6809 °C
Cp	1.142861
Temperature	105.6543 °C
Cp	1.142345
Temperature	106.6277 °C
Cp	1.141835
Temperature	107.6011 °C
Cp	1.141335
Temperature	108.5745 °C
Cp	1.140846
Temperature	109.5479 °C
Cp	1.140365
Temperature	110.5212 °C
Cp	1.139891
Temperature	111.4946 °C
Cp	1.139429
Temperature	112.468 °C
Cp	1.138976
Temperature	113.4414 °C
Cp	1.13853
Temperature	114.4148 °C
Cp	1.138092
Temperature	115.3882 °C
Cp	1.137654
Temperature	116.3616 °C
Cp	1.137223
Temperature	117.335 °C
Cp	1.136785
Temperature	118.3083 °C
Cp	1.136338
Temperature	119.2817 °C
Cp	1.13588
Temperature	120.2551 °C
Cp	1.13541
Temperature	121.2285 °C
Cp	1.134927
Temperature	122.2019 °C
Cp	1.134417
Temperature	123.1753 °C
Cp	1.133892
Temperature	124.1487 °C
Cp	1.133347
Temperature	125.122 °C
Cp	1.132786
Temperature	126.0954 °C
Cp	1.132206
Temperature	127.0688 °C
Cp	1.131606
Temperature	128.0422 °C
Cp	1.130999
Temperature	129.0156 °C
Cp	1.130384
Temperature	129.989 °C
Cp	1.129765
Temperature	130.9624 °C
Cp	1.129147
Temperature	131.9357 °C
Cp	1.12854
Temperature	132.9091 °C
Cp	1.127949
Temperature	133.8825 °C
Cp	1.127383
Temperature	134.8559 °C
Cp	1.126841
Temperature	135.8293 °C
Cp	1.126334
Temperature	136.8027 °C
Cp	1.125871
Temperature	137.7761 °C
Cp	1.125443
Temperature	138.7494 °C
Cp	1.125058
Temperature	139.7228 °C
Cp	1.124701
Temperature	140.6962 °C
Cp	1.124397
Temperature	141.6696 °C
Cp	1.124114
Temperature	142.643 °C
Cp	1.123854
Temperature	143.6164 °C
Cp	1.123612
Temperature	144.5898 °C
Cp	1.123385
Temperature	145.5631 °C
Cp	1.123182
Temperature	146.5365 °C
Cp	1.12296
Temperature	147.5099 °C
Cp	1.12275
Temperature	148.4833 °C
Cp	1.122543
Temperature	149.4567 °C
Cp	1.122327
Temperature	150.4301 °C
Cp	1.122099
Temperature	151.4035 °C
Cp	1.121837
Temperature	152.3768 °C
Cp	1.121582
Temperature	153.3502 °C
Cp	1.121289
Temperature	154.3236 °C
Cp	1.120967
Temperature	155.297 °C
Cp	1.120616
Temperature	156.2704 °C
Cp	1.120238
Temperature	157.2438 °C
Cp	1.119862
Temperature	158.2172 °C
Cp	1.119444
Temperature	159.1906 °C
Cp	1.119028
Temperature	160.1639 °C
Cp	1.118613
Temperature	161.1373 °C
Cp	1.118202
Temperature	162.1107 °C
Cp	1.117795
Temperature	163.0841 °C
Cp	1.117374
Temperature	164.0575 °C
Cp	1.116987
Temperature	165.0309 °C
Cp	1.116595
Temperature	166.0042 °C
Cp	1.116198
Temperature	166.9776 °C
Cp	1.1158
Temperature	167.951 °C
Cp	1.115402
Temperature	168.9244 °C
Cp	1.115006
Temperature	169.8978 °C
Cp	1.11462
Temperature	170.8712 °C
Cp	1.114223
Temperature	171.8446 °C
Cp	1.113836
Temperature	172.8179 °C
Cp	1.113458
Temperature	173.7913 °C
Cp	1.113085
Temperature	174.7647 °C
Cp	1.112712
Temperature	175.7381 °C
Cp	1.112323
Temperature	176.7115 °C
Cp	1.111957
Temperature	177.6849 °C
Cp	1.111578
Temperature	178.6583 °C
Cp	1.111185
Temperature	179.6317 °C
Cp	1.110789
Temperature	180.605 °C
Cp	1.110391
Temperature	181.5784 °C
Cp	1.110016
Temperature	182.5518 °C
Cp	1.109611
Temperature	183.5252 °C
Cp	1.109232
Temperature	184.4986 °C
Cp	1.108873
Temperature	185.472 °C
Cp	1.108531
Temperature	186.4454 °C
Cp	1.108199
Temperature	187.4187 °C
Cp	1.107851
Temperature	188.3921 °C
Cp	1.107551
Temperature	189.3655 °C
Cp	1.107238
Temperature	190.3389 °C
Cp	1.106917
Temperature	191.3123 °C
Cp	1.106589
Temperature	192.2857 °C
Cp	1.106259
Temperature	193.259 °C
Cp	1.105958
Temperature	194.2324 °C
Cp	1.105619
Temperature	195.2058 °C
Cp	1.105301
Temperature	196.1792 °C
Cp	1.105002
Temperature	197.1526 °C
Cp	1.104718
Temperature	198.126 °C
Cp	1.104445
Temperature	199.0994 °C
Cp	1.104161
Temperature	200.0728 °C
Cp	1.103914
Temperature	201.0461 °C
Cp	1.103657
Temperature	202.0195 °C
Cp	1.103395
Temperature	202.9929 °C
Cp	1.103125
Temperature	203.9663 °C
Cp	1.102847
Temperature	204.9397 °C
Cp	1.102563
Temperature	205.9131 °C
Cp	1.102283
Temperature	206.8865 °C
Cp	1.101985
Temperature	207.8598 °C
Cp	1.10169
Temperature	208.8332 °C
Cp	1.101394
Temperature	209.8066 °C
Cp	1.101099
Temperature	210.78 °C
Cp	1.1008
Temperature	211.7534 °C
Cp	1.10049
Temperature	212.7268 °C
Cp	1.100193
Temperature	213.7002 °C
Cp	1.099886
Temperature	214.6735 °C
Cp	1.099577
Temperature	215.6469 °C
Cp	1.099268
Temperature	216.6203 °C
Cp	1.098965
Temperature	217.5937 °C
Cp	1.098685
Temperature	218.5671 °C
Cp	1.098396
Temperature	219.5405 °C
Cp	1.098134
Temperature	220.5139 °C
Cp	1.097895
Temperature	221.4872 °C
Cp	1.09768
Temperature	222.4606 °C
Cp	1.097485
Temperature	223.434 °C
Cp	1.097292
Temperature	224.4074 °C
Cp	1.09714
Temperature	225.3808 °C
Cp	1.096991
Temperature	226.3542 °C
Cp	1.096844
Temperature	227.3276 °C
Cp	1.096699
Temperature	228.3009 °C
Cp	1.096559
Temperature	229.2743 °C
Cp	1.096442
Temperature	230.2477 °C
Cp	1.096296
Temperature	231.2211 °C
Cp	1.096164
Temperature	232.1945 °C
Cp	1.09604
Temperature	233.1679 °C
Cp	1.095924
Temperature	234.1413 °C
Cp	1.095807
Temperature	235.1147 °C
Cp	1.095665
Temperature	236.088 °C
Cp	1.095557
Temperature	237.0614 °C
Cp	1.095433
Temperature	238.0348 °C
Cp	1.095296
Temperature	239.0082 °C
Cp	1.095147
Temperature	239.9816 °C
Cp	1.094995
Temperature	240.955 °C
Cp	1.094843
Temperature	241.9283 °C
Cp	1.094705
Temperature	242.9017 °C
Cp	1.094562
Temperature	243.8751 °C
Cp	1.094442
Temperature	244.8485 °C
Cp	1.094344
Temperature	245.8219 °C
Cp	1.094266
Temperature	246.7953 °C
Cp	1.094209
Temperature	247.7687 °C
Cp	1.094161
Temperature	248.7421 °C
Cp	1.094144
Temperature	249.7154 °C
Cp	1.094133
Temperature	250.6888 °C
Cp	1.094127
Temperature	251.6622 °C
Cp	1.094126
Temperature	252.6356 °C
Cp	1.094127
Temperature	253.609 °C
Cp	1.094138
Temperature	254.5824 °C
Cp	1.09413
Temperature	255.5558 °C
Cp	1.094123
Temperature	256.5291 °C
Cp	1.094111
Temperature	257.5025 °C
Cp	1.094087
Temperature	258.4759 °C
Cp	1.094046
Temperature	259.4493 °C
Cp	1.093978
Temperature	260.4227 °C
Cp	1.093895
Temperature	261.3961 °C
Cp	1.093783
Temperature	262.3694 °C
Cp	1.093645
Temperature	263.3428 °C
Cp	1.093483
Temperature	264.3162 °C
Cp	1.093302
Temperature	265.2896 °C
Cp	1.093109
Temperature	266.263 °C
Cp	1.092906
Temperature	267.2364 °C
Cp	1.092704
Temperature	268.2098 °C
Cp	1.092511
Temperature	269.1832 °C
Cp	1.092331
Temperature	270.1566 °C
Cp	1.092174
Temperature	271.1299 °C
Cp	1.092046
Temperature	272.1033 °C
Cp	1.091947
Temperature	273.0767 °C
Cp	1.091882
Temperature	274.0501 °C
Cp	1.091853
Temperature	275.0235 °C
Cp	1.091859
Temperature	275.9969 °C
Cp	1.091895
Temperature	276.9702 °C
Cp	1.091957
Temperature	277.9436 °C
Cp	1.092036
Temperature	278.917 °C
Cp	1.092132
Temperature	279.8904 °C
Cp	1.09223
Temperature	280.8638 °C
Cp	1.092323
Temperature	281.8372 °C
Cp	1.092405
Temperature	282.8105 °C
Cp	1.092468
Temperature	283.7839 °C
Cp	1.092513
Temperature	284.7573 °C
Cp	1.092525
Temperature	285.7307 °C
Cp	1.092512
Temperature	286.7041 °C
Cp	1.092472
Temperature	287.6775 °C
Cp	1.092405
Temperature	288.6509 °C
Cp	1.092313
Temperature	289.6243 °C
Cp	1.092197
Temperature	290.5977 °C
Cp	1.09207
Temperature	291.571 °C
Cp	1.091931
Temperature	292.5444 °C
Cp	1.091785
Temperature	293.5178 °C
Cp	1.091641
Temperature	294.4912 °C
Cp	1.091506
Temperature	295.4646 °C
Cp	1.091387
Temperature	296.438 °C
Cp	1.091282
Temperature	297.4113 °C
Cp	1.091201
Temperature	298.3847 °C
Cp	1.091145
Temperature	299.3581 °C
Cp	1.091112
Temperature	300.3315 °C
Cp	1.091102
Temperature	301.3049 °C
Cp	1.091107
Temperature	302.2783 °C
Cp	1.091137
Temperature	303.2517 °C
Cp	1.091177
Temperature	304.2251 °C
Cp	1.091226
Temperature	305.1984 °C
Cp	1.09128
Temperature	306.1718 °C
Cp	1.091336
Temperature	307.1452 °C
Cp	1.091403
Temperature	308.1186 °C
Cp	1.091453
Temperature	309.092 °C
Cp	1.091506
Temperature	310.0654 °C
Cp	1.091561
Temperature	311.0388 °C
Cp	1.091617
Temperature	312.0121 °C
Cp	1.09167
Temperature	312.9855 °C
Cp	1.091716
Temperature	313.9589 °C
Cp	1.091762
Temperature	314.9323 °C
Cp	1.091805
Temperature	315.9057 °C
Cp	1.091838
Temperature	316.8791 °C
Cp	1.09186
Temperature	317.8524 °C
Cp	1.091871
Temperature	318.8258 °C
Cp	1.091872
Temperature	319.7992 °C
Cp	1.091867
Temperature	320.7726 °C
Cp	1.091838
Temperature	321.746 °C
Cp	1.0918
Temperature	322.7194 °C
Cp	1.091752
Temperature	323.6928 °C
Cp	1.091689
Temperature	324.6662 °C
Cp	1.091611
Temperature	325.6396 °C
Cp	1.091508
Temperature	326.6129 °C
Cp	1.091406
Temperature	327.5863 °C
Cp	1.091285
Temperature	328.5597 °C
Cp	1.09115
Temperature	329.5331 °C
Cp	1.091009
Temperature	330.5065 °C
Cp	1.09087
Temperature	331.4799 °C
Cp	1.090747
Temperature	332.4532 °C
Cp	1.090628
Temperature	333.4266 °C
Cp	1.090536
Temperature	334.4 °C
Cp	1.090472
Temperature	335.3734 °C
Cp	1.090437
Temperature	336.3468 °C
Cp	1.090431
Temperature	337.3202 °C
Cp	1.090455
Temperature	338.2935 °C
Cp	1.090503
Temperature	339.2669 °C
Cp	1.090573
Temperature	340.2403 °C
Cp	1.090658
Temperature	341.2137 °C
Cp	1.090753
Temperature	342.1871 °C
Cp	1.090853
Temperature	343.1605 °C
Cp	1.090952
Temperature	344.1339 °C
Cp	1.09105
Temperature	345.1073 °C
Cp	1.091141
Temperature	346.0807 °C
Cp	1.091225
Temperature	347.054 °C
Cp	1.091303
Temperature	348.0274 °C
Cp	1.091379
Temperature	349.0008 °C
Cp	1.091453
Temperature	349.9742 °C
Cp	1.091537
Temperature	350.9476 °C
Cp	1.091633
Temperature	351.921 °C
Cp	1.091743
Temperature	352.8943 °C
Cp	1.091874
Temperature	353.8677 °C
Cp	1.092028
Temperature	354.8411 °C
Cp	1.092206
Temperature	355.8145 °C
Cp	1.092411
Temperature	356.7879 °C
Cp	1.092628
Temperature	357.7613 °C
Cp	1.092862
Temperature	358.7346 °C
Cp	1.093102
Temperature	359.708 °C
Cp	1.093338
Temperature	360.6814 °C
Cp	1.093559
Temperature	361.6548 °C
Cp	1.093752
Temperature	362.6282 °C
Cp	1.093915
Temperature	363.6016 °C
Cp	1.094036
Temperature	364.575 °C
Cp	1.094117
Temperature	365.5484 °C
Cp	1.094159
Temperature	366.5218 °C
Cp	1.094172
Temperature	367.4951 °C
Cp	1.094165
Temperature	368.4685 °C
Cp	1.094163
Temperature	369.4419 °C
Cp	1.094182
Temperature	370.4153 °C
Cp	1.094244
Temperature	371.3887 °C
Cp	1.094375
Temperature	372.3621 °C
Cp	1.094598
Temperature	373.3354 °C
Cp	1.094937
Temperature	374.3088 °C
Cp	1.095389
Temperature	375.2822 °C
Cp	1.095973
Temperature	376.2556 °C
Cp	1.096685
Temperature	377.229 °C
Cp	1.097506
Temperature	378.2024 °C
Cp	1.098406
Temperature	379.1758 °C
Cp	1.099338
Temperature	380.1492 °C
Cp	1.10027
Temperature	381.1225 °C
Cp	1.10112
Temperature	382.0959 °C
Cp	1.101818
Temperature	383.0693 °C
Cp	1.10229
Temperature	384.0427 °C
Cp	1.102459
Temperature	385.0161 °C
Cp	1.102253
Temperature	385.9895 °C
Cp	1.101596
Temperature	386.9629 °C
Cp	1.100438
Temperature	387.9362 °C
Cp	1.098736
Temperature	388.9096 °C
Cp	1.096461
Temperature	389.883 °C
Cp	1.093614
Temperature	390.8564 °C
Cp	1.090208
Temperature	391.8298 °C
Cp	1.086278
Temperature	392.8032 °C
Cp	1.081887
Temperature	393.7766 °C
Cp	1.077096
Temperature	394.7499 °C
Cp	1.072007
Temperature	395.7233 °C
Cp	1.066707
[Rev Cp Calibration]
Date Applied	24/10/2024 12:37:31
Description	From -89.998 °C to 390.542 °C at 2.000°C/min
Gas Type	Nitrogen
Pan Type	Tzero Aluminum
Source Files 1	C:\ProgramData\TA Instruments\TRIOS\Data\Reverse Heat Capacity Calibration(6).tri
GUID	ba867d72-cfbb-486e-971e-e86aa544cc02
Temperature	-89.99799 °C
Cp	1.070076
Temperature	-89.03691 °C
Cp	1.072008
Temperature	-88.07584 °C
Cp	1.073556
Temperature	-87.11475 °C
Cp	1.074743
Temperature	-86.15367 °C
Cp	1.075597
Temperature	-85.1926 °C
Cp	1.076163
Temperature	-84.23151 °C
Cp	1.076477
Temperature	-83.27043 °C
Cp	1.076579
Temperature	-82.30936 °C
Cp	1.076527
Temperature	-81.34827 °C
Cp	1.076322
Temperature	-80.38719 °C
Cp	1.076039
Temperature	-79.42612 °C
Cp	1.07571
Temperature	-78.46503 °C
Cp	1.075361
Temperature	-77.50395 °C
Cp	1.075011
Temperature	-76.54288 °C
Cp	1.074656
Temperature	-75.58179 °C
Cp	1.074359
Temperature	-74.62071 °C
Cp	1.074086
Temperature	-73.65964 °C
Cp	1.073842
Temperature	-72.69855 °C
Cp	1.073627
Temperature	-71.73747 °C
Cp	1.073442
Temperature	-70.7764 °C
Cp	1.07329
Temperature	-69.81532 °C
Cp	1.073148
Temperature	-68.85423 °C
Cp	1.073021
Temperature	-67.89315 °C
Cp	1.072902
Temperature	-66.93208 °C
Cp	1.072782
Temperature	-65.97099 °C
Cp	1.072656
Temperature	-65.00991 °C
Cp	1.072518
Temperature	-64.04884 °C
Cp	1.072374
Temperature	-63.08775 °C
Cp	1.072201
Temperature	-62.12667 °C
Cp	1.072019
Temperature	-61.1656 °C
Cp	1.071827
Temperature	-60.20451 °C
Cp	1.071624
Temperature	-59.24343 °C
Cp	1.071411
Temperature	-58.28236 °C
Cp	1.071167
Temperature	-57.32127 °C
Cp	1.070956
Temperature	-56.3602 °C
Cp	1.070724
Temperature	-55.39911 °C
Cp	1.070483
Temperature	-54.43803 °C
Cp	1.070242
Temperature	-53.47696 °C
Cp	1.070009
Temperature	-52.51587 °C
Cp	1.069825
Temperature	-51.55479 °C
Cp	1.069601
Temperature	-50.59372 °C
Cp	1.069418
Temperature	-49.63263 °C
Cp	1.069267
Temperature	-48.67155 °C
Cp	1.069138
Temperature	-47.71048 °C
Cp	1.069021
Temperature	-46.74939 °C
Cp	1.068875
Temperature	-45.78831 °C
Cp	1.068771
Temperature	-44.82724 °C
Cp	1.068634
Temperature	-43.86615 °C
Cp	1.068462
Temperature	-42.90508 °C
Cp	1.068255
Temperature	-41.944 °C
Cp	1.068012
Temperature	-40.98291 °C
Cp	1.067742
Temperature	-40.02184 °C
Cp	1.067427
Temperature	-39.06076 °C
Cp	1.067088
Temperature	-38.09967 °C
Cp	1.066727
Temperature	-37.1386 °C
Cp	1.066349
Temperature	-36.17752 °C
Cp	1.065958
Temperature	-35.21643 °C
Cp	1.065559
Temperature	-34.25536 °C
Cp	1.065162
Temperature	-33.29427 °C
Cp	1.06476
Temperature	-32.33319 °C
Cp	1.064368
Temperature	-31.37212 °C
Cp	1.06399
Temperature	-30.41104 °C
Cp	1.063628
Temperature	-29.44995 °C
Cp	1.063283
Temperature	-28.48887 °C
Cp	1.06295
Temperature	-27.5278 °C
Cp	1.062645
Temperature	-26.56672 °C
Cp	1.062355
Temperature	-25.60563 °C
Cp	1.06208
Temperature	-24.64456 °C
Cp	1.061819
Temperature	-23.68348 °C
Cp	1.061573
Temperature	-22.72239 °C
Cp	1.061345
Temperature	-21.76132 °C
Cp	1.061123
Temperature	-20.80024 °C
Cp	1.060915
Temperature	-19.83916 °C
Cp	1.060719
Temperature	-18.87807 °C
Cp	1.060531
Temperature	-17.917 °C
Cp	1.06035
Temperature	-16.95592 °C
Cp	1.060161
Temperature	-15.99484 °C
Cp	1.059992
Temperature	-15.03376 °C
Cp	1.059817
Temperature	-14.07268 °C
Cp	1.059634
Temperature	-13.1116 °C
Cp	1.059445
Temperature	-12.15052 °C
Cp	1.059248
Temperature	-11.18944 °C
Cp	1.059043
Temperature	-10.22836 °C
Cp	1.058842
Temperature	-9.267276 °C
Cp	1.058615
Temperature	-8.306196 °C
Cp	1.058388
Temperature	-7.345116 °C
Cp	1.058155
Temperature	-6.384036 °C
Cp	1.057911
Temperature	-5.422956 °C
Cp	1.057652
Temperature	-4.461876 °C
Cp	1.057356
Temperature	-3.500796 °C
Cp	1.057063
Temperature	-2.539716 °C
Cp	1.056732
Temperature	-1.578636 °C
Cp	1.056364
Temperature	-0.6175562 °C
Cp	1.05596
Temperature	0.3435238 °C
Cp	1.055523
Temperature	1.304604 °C
Cp	1.055066
Temperature	2.265684 °C
Cp	1.054561
Temperature	3.226764 °C
Cp	1.054035
Temperature	4.187844 °C
Cp	1.053488
Temperature	5.148924 °C
Cp	1.052922
Temperature	6.110003 °C
Cp	1.052337
Temperature	7.071084 °C
Cp	1.051736
Temperature	8.032164 °C
Cp	1.051118
Temperature	8.993243 °C
Cp	1.050488
Temperature	9.954324 °C
Cp	1.049848
Temperature	10.9154 °C
Cp	1.049202
Temperature	11.87648 °C
Cp	1.048552
Temperature	12.83756 °C
Cp	1.047902
Temperature	13.79864 °C
Cp	1.047255
Temperature	14.75972 °C
Cp	1.046615
Temperature	15.7208 °C
Cp	1.045983
Temperature	16.68188 °C
Cp	1.045362
Temperature	17.64296 °C
Cp	1.044756
Temperature	18.60404 °C
Cp	1.044164
Temperature	19.56512 °C
Cp	1.04358
Temperature	20.5262 °C
Cp	1.043027
Temperature	21.48728 °C
Cp	1.042485
Temperature	22.44836 °C
Cp	1.041958
Temperature	23.40944 °C
Cp	1.041446
Temperature	24.37052 °C
Cp	1.040952
Temperature	25.3316 °C
Cp	1.040493
Temperature	26.29268 °C
Cp	1.040022
Temperature	27.25376 °C
Cp	1.039578
Temperature	28.21484 °C
Cp	1.039158
Temperature	29.17592 °C
Cp	1.038758
Temperature	30.137 °C
Cp	1.038373
Temperature	31.09808 °C
Cp	1.037981
Temperature	32.05916 °C
Cp	1.03763
Temperature	33.02024 °C
Cp	1.037276
Temperature	33.98132 °C
Cp	1.03692
Temperature	34.9424 °C
Cp	1.036565
Temperature	35.90348 °C
Cp	1.036213
Temperature	36.86456 °C
Cp	1.035866
Temperature	37.82564 °C
Cp	1.035529
Temperature	38.78672 °C
Cp	1.035195
Temperature	39.7478 °C
Cp	1.034875
Temperature	40.70888 °C
Cp	1.034568
Temperature	41.66996 °C
Cp	1.034276
Temperature	42.63104 °C
Cp	1.033996
Temperature	43.59212 °C
Cp	1.033726
Temperature	44.5532 °C
Cp	1.033469
Temperature	45.51428 °C
Cp	1.033221
Temperature	46.47536 °C
Cp	1.03298
Temperature	47.43644 °C
Cp	1.032744
Temperature	48.39752 °C
Cp	1.032514
Temperature	49.3586 °C
Cp	1.032289
Temperature	50.31968 °C
Cp	1.032065
Temperature	51.28076 °C
Cp	1.031844
Temperature	52.24184 °C
Cp	1.031627
Temperature	53.20292 °C
Cp	1.031413
Temperature	54.164 °C
Cp	1.031203
Temperature	55.12508 °C
Cp	1.030989
Temperature	56.08616 °C
Cp	1.030791
Temperature	57.04724 °C
Cp	1.030595
Temperature	58.00832 °C
Cp	1.030403
Temperature	58.9694 °C
Cp	1.030217
Temperature	59.93048 °C
Cp	1.03004
Temperature	60.89156 °C
Cp	1.029871
Temperature	61.85264 °C
Cp	1.029718
Temperature	62.81372 °C
Cp	1.029567
Temperature	63.7748 °C
Cp	1.02943
Temperature	64.73589 °C
Cp	1.029304
Temperature	65.69696 °C
Cp	1.029185
Temperature	66.65804 °C
Cp	1.02907
Temperature	67.61913 °C
Cp	1.028946
Temperature	68.5802 °C
Cp	1.028831
Temperature	69.54128 °C
Cp	1.028703
Temperature	70.50237 °C
Cp	1.028561
Temperature	71.46344 °C
Cp	1.028404
Temperature	72.42452 °C
Cp	1.028234
Temperature	73.3856 °C
Cp	1.028063
Temperature	74.34668 °C
Cp	1.027861
Temperature	75.30776 °C
Cp	1.027657
Temperature	76.26884 °C
Cp	1.027451
Temperature	77.22992 °C
Cp	1.027243
Temperature	78.191 °C
Cp	1.027036
Temperature	79.15208 °C
Cp	1.026812
Temperature	80.11316 °C
Cp	1.026623
Temperature	81.07424 °C
Cp	1.026431
Temperature	82.03532 °C
Cp	1.026241
Temperature	82.9964 °C
Cp	1.02606
Temperature	83.95748 °C
Cp	1.025891
Temperature	84.91856 °C
Cp	1.025739
Temperature	85.87964 °C
Cp	1.025614
Temperature	86.84072 °C
Cp	1.025493
Temperature	87.8018 °C
Cp	1.0254
Temperature	88.76288 °C
Cp	1.025329
Temperature	89.72396 °C
Cp	1.025274
Temperature	90.68504 °C
Cp	1.025229
Temperature	91.64612 °C
Cp	1.025174
Temperature	92.6072 °C
Cp	1.025138
Temperature	93.56828 °C
Cp	1.025083
Temperature	94.52936 °C
Cp	1.025008
Temperature	95.49044 °C
Cp	1.024912
Temperature	96.45152 °C
Cp	1.024796
Temperature	97.4126 °C
Cp	1.024671
Temperature	98.37368 °C
Cp	1.024506
Temperature	99.33476 °C
Cp	1.02433
Temperature	100.2958 °C
Cp	1.024144
Temperature	101.2569 °C
Cp	1.023948
Temperature	102.218 °C
Cp	1.023743
Temperature	103.1791 °C
Cp	1.023522
Temperature	104.1402 °C
Cp	1.023309
Temperature	105.1012 °C
Cp	1.023089
Temperature	106.0623 °C
Cp	1.022866
Temperature	107.0234 °C
Cp	1.022644
Temperature	107.9845 °C
Cp	1.022427
Temperature	108.9456 °C
Cp	1.022218
Temperature	109.9066 °C
Cp	1.022022
Temperature	110.8677 °C
Cp	1.021836
Temperature	111.8288 °C
Cp	1.021666
Temperature	112.7899 °C
Cp	1.021512
Temperature	113.751 °C
Cp	1.021374
Temperature	114.712 °C
Cp	1.02125
Temperature	115.6731 °C
Cp	1.021137
Temperature	116.6342 °C
Cp	1.021041
Temperature	117.5953 °C
Cp	1.020953
Temperature	118.5564 °C
Cp	1.020872
Temperature	119.5174 °C
Cp	1.020796
Temperature	120.4785 °C
Cp	1.020725
Temperature	121.4396 °C
Cp	1.020659
Temperature	122.4007 °C
Cp	1.020587
Temperature	123.3618 °C
Cp	1.020515
Temperature	124.3228 °C
Cp	1.02044
Temperature	125.2839 °C
Cp	1.020359
Temperature	126.245 °C
Cp	1.02027
Temperature	127.2061 °C
Cp	1.020167
Temperature	128.1672 °C
Cp	1.020057
Temperature	129.1282 °C
Cp	1.019933
Temperature	130.0893 °C
Cp	1.019793
Temperature	131.0504 °C
Cp	1.019638
Temperature	132.0115 °C
Cp	1.019471
Temperature	132.9726 °C
Cp	1.019292
Temperature	133.9336 °C
Cp	1.019107
Temperature	134.8947 °C
Cp	1.018912
Temperature	135.8558 °C
Cp	1.018717
Temperature	136.8169 °C
Cp	1.018527
Temperature	137.778 °C
Cp	1.018344
Temperature	138.739 °C
Cp	1.018171
Temperature	139.7001 °C
Cp	1.018004
Temperature	140.6612 °C
Cp	1.01787
Temperature	141.6223 °C
Cp	1.01775
Temperature	142.5834 °C
Cp	1.017652
Temperature	143.5444 °C
Cp	1.017578
Temperature	144.5055 °C
Cp	1.017534
Temperature	145.4666 °C
Cp	1.017536
Temperature	146.4277 °C
Cp	1.017545
Temperature	147.3888 °C
Cp	1.017595
Temperature	148.3498 °C
Cp	1.017679
Temperature	149.3109 °C
Cp	1.01779
Temperature	150.272 °C
Cp	1.01792
Temperature	151.2331 °C
Cp	1.018043
Temperature	152.1942 °C
Cp	1.018199
Temperature	153.1552 °C
Cp	1.018339
Temperature	154.1163 °C
Cp	1.018458
Temperature	155.0774 °C
Cp	1.018552
Temperature	156.0385 °C
Cp	1.018618
Temperature	156.9996 °C
Cp	1.018662
Temperature	157.9606 °C
Cp	1.018664
Temperature	158.9217 °C
Cp	1.018632
Temperature	159.8828 °C
Cp	1.018575
Temperature	160.8439 °C
Cp	1.018492
Temperature	161.805 °C
Cp	1.018383
Temperature	162.766 °C
Cp	1.01825
Temperature	163.7271 °C
Cp	1.018087
Temperature	164.6882 °C
Cp	1.017917
Temperature	165.6493 °C
Cp	1.017726
Temperature	166.6104 °C
Cp	1.017522
Temperature	167.5714 °C
Cp	1.01731
Temperature	168.5325 °C
Cp	1.017098
Temperature	169.4936 °C
Cp	1.016902
Temperature	170.4547 °C
Cp	1.016695
Temperature	171.4158 °C
Cp	1.016508
Temperature	172.3768 °C
Cp	1.016342
Temperature	173.3379 °C
Cp	1.016195
Temperature	174.299 °C
Cp	1.016065
Temperature	175.2601 °C
Cp	1.015927
Temperature	176.2212 °C
Cp	1.015838
Temperature	177.1822 °C
Cp	1.015746
Temperature	178.1433 °C
Cp	1.015651
Temperature	179.1044 °C
Cp	1.015555
Temperature	180.0655 °C
Cp	1.015459
Temperature	181.0266 °C
Cp	1.015401
Temperature	181.9876 °C
Cp	1.015288
Temperature	182.9487 °C
Cp	1.015195
Temperature	183.9098 °C
Cp	1.015117
Temperature	184.8709 °C
Cp	1.01505
Temperature	185.832 °C
Cp	1.014988
Temperature	186.793 °C
Cp	1.014927
Temperature	187.7541 °C
Cp	1.014849
Temperature	188.7152 °C
Cp	1.014789
Temperature	189.6763 °C
Cp	1.01471
Temperature	190.6374 °C
Cp	1.014614
Temperature	191.5984 °C
Cp	1.014503
Temperature	192.5595 °C
Cp	1.014381
Temperature	193.5206 °C
Cp	1.014268
Temperature	194.4817 °C
Cp	1.014122
Temperature	195.4428 °C
Cp	1.013984
Temperature	196.4038 °C
Cp	1.013853
Temperature	197.3649 °C
Cp	1.013726
Temperature	198.326 °C
Cp	1.013603
Temperature	199.2871 °C
Cp	1.013467
Temperature	200.2482 °C
Cp	1.013359
Temperature	201.2092 °C
Cp	1.013243
Temperature	202.1703 °C
Cp	1.013123
Temperature	203.1314 °C
Cp	1.013002
Temperature	204.0925 °C
Cp	1.012884
Temperature	205.0536 °C
Cp	1.012788
Temperature	206.0146 °C
Cp	1.012674
Temperature	206.9757 °C
Cp	1.012579
Temperature	207.9368 °C
Cp	1.012501
Temperature	208.8979 °C
Cp	1.012439
Temperature	209.859 °C
Cp	1.012389
Temperature	210.82 °C
Cp	1.012351
Temperature	211.7811 °C
Cp	1.012312
Temperature	212.7422 °C
Cp	1.01229
Temperature	213.7033 °C
Cp	1.012262
Temperature	214.6644 °C
Cp	1.012227
Temperature	215.6254 °C
Cp	1.012183
Temperature	216.5865 °C
Cp	1.012129
Temperature	217.5476 °C
Cp	1.012077
Temperature	218.5087 °C
Cp	1.01199
Temperature	219.4698 °C
Cp	1.011897
Temperature	220.4308 °C
Cp	1.011793
Temperature	221.3919 °C
Cp	1.011674
Temperature	222.353 °C
Cp	1.011537
Temperature	223.3141 °C
Cp	1.011362
Temperature	224.2752 °C
Cp	1.011194
Temperature	225.2362 °C
Cp	1.010993
Temperature	226.1973 °C
Cp	1.010766
Temperature	227.1584 °C
Cp	1.010517
Temperature	228.1195 °C
Cp	1.010251
Temperature	229.0806 °C
Cp	1.009998
Temperature	230.0416 °C
Cp	1.009703
Temperature	231.0027 °C
Cp	1.009422
Temperature	231.9638 °C
Cp	1.009156
Temperature	232.9249 °C
Cp	1.008906
Temperature	233.886 °C
Cp	1.008675
Temperature	234.847 °C
Cp	1.008462
Temperature	235.8081 °C
Cp	1.008258
Temperature	236.7692 °C
Cp	1.00809
Temperature	237.7303 °C
Cp	1.007934
Temperature	238.6914 °C
Cp	1.007793
Temperature	239.6524 °C
Cp	1.007668
Temperature	240.6135 °C
Cp	1.007562
Temperature	241.5746 °C
Cp	1.007487
Temperature	242.5357 °C
Cp	1.00741
Temperature	243.4967 °C
Cp	1.00736
Temperature	244.4578 °C
Cp	1.007332
Temperature	245.4189 °C
Cp	1.007321
Temperature	246.38 °C
Cp	1.007321
Temperature	247.3411 °C
Cp	1.007312
Temperature	248.3022 °C
Cp	1.007331
Temperature	249.2632 °C
Cp	1.007338
Temperature	250.2243 °C
Cp	1.007335
Temperature	251.1854 °C
Cp	1.00732
Temperature	252.1465 °C
Cp	1.007295
Temperature	253.1076 °C
Cp	1.007277
Temperature	254.0686 °C
Cp	1.007227
Temperature	255.0297 °C
Cp	1.007179
Temperature	255.9908 °C
Cp	1.007133
Temperature	256.9519 °C
Cp	1.00709
Temperature	257.913 °C
Cp	1.007049
Temperature	258.874 °C
Cp	1.007012
Temperature	259.8351 °C
Cp	1.006978
Temperature	260.7962 °C
Cp	1.006956
Temperature	261.7573 °C
Cp	1.00694
Temperature	262.7184 °C
Cp	1.006934
Temperature	263.6794 °C
Cp	1.006939
Temperature	264.6405 °C
Cp	1.00696
Temperature	265.6016 °C
Cp	1.006999
Temperature	266.5627 °C
Cp	1.007054
Temperature	267.5237 °C
Cp	1.007131
Temperature	268.4848 °C
Cp	1.00723
Temperature	269.4459 °C
Cp	1.00735
Temperature	270.407 °C
Cp	1.007493
Temperature	271.3681 °C
Cp	1.007656
Temperature	272.3292 °C
Cp	1.007839
Temperature	273.2902 °C
Cp	1.008039
Temperature	274.2513 °C
Cp	1.008257
Temperature	275.2124 °C
Cp	1.008488
Temperature	276.1735 °C
Cp	1.008731
Temperature	277.1346 °C
Cp	1.008977
Temperature	278.0956 °C
Cp	1.009237
Temperature	279.0567 °C
Cp	1.009498
Temperature	280.0178 °C
Cp	1.009757
Temperature	280.9789 °C
Cp	1.010014
Temperature	281.9399 °C
Cp	1.010267
Temperature	282.901 °C
Cp	1.010515
Temperature	283.8621 °C
Cp	1.01076
Temperature	284.8232 °C
Cp	1.010993
Temperature	285.7843 °C
Cp	1.011222
Temperature	286.7454 °C
Cp	1.011447
Temperature	287.7064 °C
Cp	1.011665
Temperature	288.6675 °C
Cp	1.011876
Temperature	289.6286 °C
Cp	1.012079
Temperature	290.5897 °C
Cp	1.01228
Temperature	291.5508 °C
Cp	1.012474
Temperature	292.5118 °C
Cp	1.012662
Temperature	293.4729 °C
Cp	1.012846
Temperature	294.434 °C
Cp	1.013028
Temperature	295.3951 °C
Cp	1.013211
Temperature	296.3561 °C
Cp	1.013391
Temperature	297.3172 °C
Cp	1.013574
Temperature	298.2783 °C
Cp	1.013759
Temperature	299.2394 °C
Cp	1.013947
Temperature	300.2005 °C
Cp	1.014136
Temperature	301.1616 °C
Cp	1.01432
Temperature	302.1226 °C
Cp	1.014511
Temperature	303.0837 °C
Cp	1.014695
Temperature	304.0448 °C
Cp	1.014872
Temperature	305.0059 °C
Cp	1.01504
Temperature	305.9669 °C
Cp	1.015198
Temperature	306.928 °C
Cp	1.015343
Temperature	307.8891 °C
Cp	1.015479
Temperature	308.8502 °C
Cp	1.015595
Temperature	309.8113 °C
Cp	1.015699
Temperature	310.7724 °C
Cp	1.015789
Temperature	311.7334 °C
Cp	1.015865
Temperature	312.6945 °C
Cp	1.015925
Temperature	313.6556 °C
Cp	1.015964
Temperature	314.6167 °C
Cp	1.015999
Temperature	315.5778 °C
Cp	1.016018
Temperature	316.5388 °C
Cp	1.016025
Temperature	317.4999 °C
Cp	1.016024
Temperature	318.461 °C
Cp	1.01602
Temperature	319.4221 °C
Cp	1.016029
Temperature	320.3831 °C
Cp	1.016025
Temperature	321.3442 °C
Cp	1.016037
Temperature	322.3053 °C
Cp	1.016066
Temperature	323.2664 °C
Cp	1.01611
Temperature	324.2275 °C
Cp	1.016169
Temperature	325.1886 °C
Cp	1.016225
Temperature	326.1496 °C
Cp	1.016318
Temperature	327.1107 °C
Cp	1.016411
Temperature	328.0718 °C
Cp	1.016504
Temperature	329.0329 °C
Cp	1.016596
Temperature	329.994 °C
Cp	1.016687
Temperature	330.955 °C
Cp	1.016775
Temperature	331.9161 °C
Cp	1.016864
Temperature	332.8772 °C
Cp	1.016942
Temperature	333.8383 °C
Cp	1.017019
Temperature	334.7993 °C
Cp	1.017093
Temperature	335.7604 °C
Cp	1.017163
Temperature	336.7215 °C
Cp	1.01723
Temperature	337.6826 °C
Cp	1.017295
Temperature	338.6437 °C
Cp	1.017358
Temperature	339.6048 °C
Cp	1.017423
Temperature	340.5658 °C
Cp	1.017491
Temperature	341.5269 °C
Cp	1.017567
Temperature	342.488 °C
Cp	1.017651
Temperature	343.4491 °C
Cp	1.017747
Temperature	344.4102 °C
Cp	1.017859
Temperature	345.3712 °C
Cp	1.017987
Temperature	346.3323 °C
Cp	1.018133
Temperature	347.2934 °C
[...]
131.5900	110.9905	0.3782
131.5983	110.9072	0.3782
131.6067	110.8230	0.3782
131.6150	110.7408	0.3782
131.6233	110.6574	0.3781
131.6317	110.5741	0.3781
131.6400	110.4913	0.3781
131.6483	110.4081	0.3780
131.6567	110.3239	0.3780
131.6650	110.2429	0.3780
131.6733	110.1588	0.3780
131.6817	110.0761	0.3779
131.6900	109.9928	0.3779
131.6983	109.9110	0.3779
131.7067	109.8267	0.3778
131.7150	109.7419	0.3778
131.7233	109.6599	0.3779
131.7317	109.5765	0.3778
131.7400	109.4924	0.3778
131.7483	109.4108	0.3778
131.7567	109.3268	0.3777
131.7650	109.2440	0.3777
131.7733	109.1610	0.3777
131.7817	109.0774	0.3776
131.7900	108.9945	0.3775
131.7983	108.9116	0.3775
131.8067	108.8291	0.3775
131.8150	108.7454	0.3775
131.8233	108.6619	0.3774
131.8317	108.5792	0.3774
131.8400	108.4960	0.3774
131.8483	108.4132	0.3774
131.8567	108.3302	0.3774
131.8650	108.2461	0.3773
131.8733	108.1628	0.3773
131.8817	108.0812	0.3773
131.8900	107.9981	0.3772
131.8983	107.9136	0.3772
131.9067	107.8302	0.3772
131.9150	107.7470	0.3772
131.9233	107.6653	0.3771
131.9317	107.5816	0.3771
131.9400	107.4983	0.3771
131.9483	107.4134	0.3771
131.9567	107.3311	0.3771
131.9650	107.2492	0.3770
131.9733	107.1653	0.3770
131.9817	107.0815	0.3770
131.9900	106.9993	0.3770
131.9983	106.9159	0.3769
132.0067	106.8311	0.3769
132.0150	106.7488	0.3769
132.0233	106.6652	0.3769
132.0317	106.5820	0.3769
132.0400	106.5005	0.3768
132.0483	106.4170	0.3768
132.0567	106.3338	0.3768
132.0650	106.2514	0.3767
132.0733	106.1674	0.3767
132.0817	106.0845	0.3767
132.0900	106.0016	0.3766
132.0983	105.9178	0.3766
132.1067	105.8358	0.3766
132.1150	105.7516	0.3766
132.1233	105.6693	0.3765
132.1317	105.5860	0.3765
132.1400	105.5032	0.3765
132.1483	105.4195	0.3764
132.1567	105.3366	0.3764
132.1650	105.2534	0.3764
132.1733	105.1695	0.3764
132.1817	105.0872	0.3764
132.1900	105.0039	0.3763
132.1983	104.9210	0.3763
132.2067	104.8373	0.3763
132.2150	104.7550	0.3762
132.2233	104.6708	0.3762
132.2317	104.5872	0.3762
132.2400	104.5042	0.3762
132.2483	104.4215	0.3761
132.2567	104.3383	0.3761
132.2650	104.2548	0.3760
132.2733	104.1716	0.3760
132.2817	104.0890	0.3760
132.2900	104.0060	0.3759
132.2983	103.9229	0.3759
132.3067	103.8388	0.3759
132.3150	103.7555	0.3758
132.3233	103.6729	0.3758
132.3317	103.5897	0.3758
132.3400	103.5071	0.3758
132.3483	103.4242	0.3758
132.3567	103.3408	0.3757
132.3650	103.2568	0.3757
132.3733	103.1739	0.3757
132.3817	103.0912	0.3756
132.3900	103.0083	0.3756
132.3983	102.9248	0.3756
132.4067	102.8410	0.3756
132.4150	102.7584	0.3756
132.4233	102.6754	0.3755
132.4317	102.5927	0.3755
132.4400	102.5099	0.3755
132.4483	102.4265	0.3754
132.4567	102.3431	0.3754
132.4650	102.2604	0.3754
132.4733	102.1772	0.3753
132.4817	102.0940	0.3753
132.4900	102.0102	0.3752
132.4983	101.9276	0.3752
132.5067	101.8437	0.3752
132.5150	101.7609	0.3752
132.5233	101.6768	0.3751
132.5317	101.5959	0.3751
132.5400	101.5118	0.3751
132.5483	101.4289	0.3751
132.5567	101.3451	0.3751
132.5650	101.2618	0.3750
132.5733	101.1800	0.3750
132.5817	101.0965	0.3749
132.5900	101.0136	0.3749
132.5983	100.9295	0.3749
132.6067	100.8476	0.3749
132.6150	100.7625	0.3749
132.6233	100.6796	0.3748
132.6317	100.5982	0.3748
132.6400	100.5139	0.3747
132.6483	100.4313	0.3747
132.6567	100.3482	0.3747
132.6650	100.2646	0.3746
132.6733	100.1814	0.3746
132.6817	100.0973	0.3746
132.6900	100.0137	0.3745
132.6983	99.9318	0.3745
132.7067	99.8478	0.3745
132.7150	99.7646	0.3745
132.7233	99.6824	0.3745
132.7317	99.5989	0.3745
132.7400	99.5157	0.3744
132.7483	99.4327	0.3742
132.7567	99.3496	0.3742
132.7650	99.2662	0.3742
132.7733	99.1830	0.3741
132.7817	99.1008	0.3741
132.7900	99.0175	0.3740
132.7983	98.9341	0.3740
132.8067	98.8512	0.3740
132.8150	98.7678	0.3739
132.8233	98.6846	0.3739
132.8317	98.6005	0.3739
132.8400	98.5172	0.3739
132.8483	98.4350	0.3738
132.8567	98.3521	0.3738
132.8650	98.2688	0.3738
132.8733	98.1847	0.3737
132.8817	98.1023	0.3737
132.8900	98.0198	0.3737
132.8983	97.9364	0.3737
132.9067	97.8530	0.3737
132.9150	97.7703	0.3736
132.9233	97.6870	0.3736
132.9317	97.6033	0.3735
132.9400	97.5209	0.3735
132.9483	97.4382	0.3735
132.9567	97.3540	0.3735
132.9650	97.2720	0.3734
132.9733	97.1876	0.3734
132.9817	97.1057	0.3734
132.9900	97.0217	0.3733
132.9983	96.9403	0.3733
133.0067	96.8551	0.3733
133.0150	96.7723	0.3732
133.0233	96.6892	0.3732
133.0317	96.6054	0.3732
133.0400	96.5233	0.3731
133.0483	96.4398	0.3731
133.0567	96.3560	0.3731
133.0650	96.2741	0.3730
133.0733	96.1907	0.3730
133.0817	96.1076	0.3730
133.0900	96.0248	0.3730
133.0983	95.9408	0.3729
133.1067	95.8569	0.3729
133.1150	95.7753	0.3729
133.1233	95.6920	0.3728
133.1317	95.6077	0.3728
133.1400	95.5253	0.3728
133.1483	95.4427	0.3727
133.1567	95.3584	0.3727
133.1650	95.2753	0.3727
133.1733	95.1926	0.3726
133.1817	95.1095	0.3726
133.1900	95.0265	0.3725
133.1983	94.9434	0.3725
133.2067	94.8596	0.3725
133.2150	94.7771	0.3724
133.2233	94.6946	0.3723
133.2317	94.6102	0.3723
133.2400	94.5274	0.3723
133.2483	94.4441	0.3723
133.2567	94.3610	0.3722
133.2650	94.2778	0.3722
133.2733	94.1954	0.3721
133.2817	94.1115	0.3721
133.2900	94.0268	0.3720
133.2983	93.9457	0.3720
133.3067	93.8628	0.3720
133.3150	93.7794	0.3720
133.3233	93.6963	0.3719
133.3317	93.6123	0.3719
133.3400	93.5297	0.3718
133.3483	93.4459	0.3718
133.3567	93.3635	0.3717
133.3650	93.2794	0.3717
133.3733	93.1976	0.3717
133.3817	93.1147	0.3716
133.3900	93.0301	0.3716
133.3983	92.9465	0.3716
133.4067	92.8647	0.3716
133.4150	92.7830	0.3715
133.4233	92.6987	0.3715
133.4317	92.6163	0.3715
133.4400	92.5315	0.3714
133.4483	92.4485	0.3714
133.4567	92.3648	0.3714
133.4650	92.2819	0.3713
133.4733	92.1995	0.3713
133.4817	92.1158	0.3713
133.4900	92.0333	0.3713
133.4983	91.9494	0.3712
133.5067	91.8666	0.3712
133.5150	91.7816	0.3712
133.5233	91.7006	0.3712
133.5317	91.6170	0.3711
133.5400	91.5329	0.3711
133.5483	91.4506	0.3711
133.5567	91.3677	0.3710
133.5650	91.2837	0.3709
133.5733	91.2017	0.3709
133.5817	91.1184	0.3709
133.5900	91.0348	0.3708
133.5983	90.9515	0.3708
133.6067	90.8690	0.3708
133.6150	90.7854	0.3708
133.6233	90.7022	0.3707
133.6317	90.6202	0.3706
133.6400	90.5369	0.3706
133.6483	90.4536	0.3706
133.6567	90.3699	0.3705
133.6650	90.2874	0.3705
133.6733	90.2029	0.3705
133.6817	90.1204	0.3705
133.6900	90.0375	0.3704
133.6983	89.9539	0.3704
133.7067	89.8711	0.3704
133.7150	89.7878	0.3704
133.7233	89.7054	0.3703
133.7317	89.6223	0.3703
133.7400	89.5388	0.3703
133.7483	89.4550	0.3702
133.7567	89.3729	0.3701
133.7650	89.2884	0.3701
133.7733	89.2062	0.3701
133.7817	89.1226	0.3701
133.7900	89.0399	0.3701
133.7983	88.9557	0.3701
133.8067	88.8720	0.3700
133.8150	88.7895	0.3700
133.8233	88.7059	0.3700
133.8317	88.6227	0.3699
133.8400	88.5393	0.3699
133.8483	88.4565	0.3699
133.8567	88.3744	0.3699
133.8650	88.2916	0.3699
133.8733	88.2084	0.3698
133.8817	88.1245	0.3699
133.8900	88.0417	0.3698
133.8983	87.9589	0.3697
133.9067	87.8760	0.3696
133.9150	87.7920	0.3696
133.9233	87.7086	0.3696
133.9317	87.6252	0.3696
133.9400	87.5423	0.3696
133.9483	87.4592	0.3696
133.9567	87.3754	0.3695
133.9650	87.2932	0.3695
133.9733	87.2113	0.3695
133.9817	87.1273	0.3694
133.9900	87.0432	0.3694
133.9983	86.9604	0.3694
134.0067	86.8778	0.3693
134.0150	86.7944	0.3693
134.0233	86.7113	0.3693
134.0317	86.6283	0.3693
134.0400	86.5448	0.3692
134.0483	86.4616	0.3692
134.0567	86.3788	0.3692
134.0650	86.2949	0.3692
134.0733	86.2123	0.3691
134.0817	86.1281	0.3691
134.0900	86.0453	0.3691
134.0983	85.9622	0.3691
134.1067	85.8794	0.3690
134.1150	85.7961	0.3690
134.1233	85.7127	0.3689
134.1317	85.6288	0.3689
134.1400	85.5477	0.3689
134.1483	85.4636	0.3689
134.1567	85.3805	0.3689
134.1650	85.2977	0.3688
134.1733	85.2151	0.3688
134.1817	85.1308	0.3688
134.1900	85.0481	0.3688
134.1983	84.9653	0.3687
134.2067	84.8822	0.3687
134.2150	84.7991	0.3687
134.2233	84.7147	0.3687
134.2317	84.6329	0.3686
134.2400	84.5492	0.3686
134.2483	84.4655	0.3685
134.2567	84.3826	0.3685
134.2650	84.2993	0.3684
134.2733	84.2172	0.3684
134.2817	84.1337	0.3684
134.2900	84.0500	0.3684
134.2983	83.9671	0.3684
134.3067	83.8836	0.3684
134.3150	83.8005	0.3684
134.3233	83.7173	0.3683
134.3317	83.6346	0.3682
134.3400	83.5514	0.3682
134.3483	83.4686	0.3682
134.3567	83.3850	0.3681
134.3650	83.3027	0.3681
134.3733	83.2199	0.3681
134.3817	83.1355	0.3681
134.3900	83.0518	0.3680
134.3983	82.9694	0.3680
134.4067	82.8865	0.3680
134.4150	82.8031	0.3679
134.4233	82.7210	0.3679
134.4317	82.6360	0.3679
134.4400	82.5535	0.3678
134.4483	82.4706	0.3678
134.4567	82.3877	0.3678
134.4650	82.3037	0.3677
134.4733	82.2203	0.3677
134.4817	82.1378	0.3677
134.4900	82.0549	0.3677
134.4983	81.9712	0.3676
134.5067	81.8892	0.3676
134.5150	81.8059	0.3675
134.5233	81.7220	0.3675
134.5317	81.6393	0.3675
134.5400	81.5565	0.3674
134.5483	81.4732	0.3674
134.5567	81.3901	0.3674
134.5650	81.3074	0.3673
134.5733	81.2230	0.3673
134.5817	81.1402	0.3673
134.5900	81.0578	0.3672
134.5983	80.9743	0.3672
134.6067	80.8913	0.3672
134.6150	80.8084	0.3671
134.6233	80.7242	0.3671
134.6317	80.6406	0.3671
134.6400	80.5586	0.3671
134.6483	80.4759	0.3670
134.6567	80.3918	0.3670
134.6650	80.3095	0.3670
134.6733	80.2260	0.3670
134.6817	80.1411	0.3670
134.6900	80.0603	0.3669
134.6983	79.9759	0.3669
134.7067	79.8925	0.3669
134.7150	79.8100	0.3668
134.7233	79.7274	0.3668
134.7317	79.6425	0.3668
134.7400	79.5608	0.3667
134.7483	79.4775	0.3667
134.7567	79.3944	0.3667
134.7650	79.3118	0.3666
134.7733	79.2276	0.3666
134.7817	79.1447	0.3666
134.7900	79.0622	0.3665
134.7983	78.9788	0.3665
134.8067	78.8938	0.3665
134.8150	78.8123	0.3664
134.8233	78.7293	0.3664
134.8317	78.6466	0.3663
134.8400	78.5631	0.3663
134.8483	78.4790	0.3663
134.8567	78.3965	0.3663
134.8650	78.3141	0.3663
134.8733	78.2296	0.3662
134.8817	78.1468	0.3662
134.8900	78.0630	0.3661
134.8983	77.9797	0.3661
134.9067	77.8970	0.3660
134.9150	77.8145	0.3660
134.9233	77.7306	0.3660
134.9317	77.6475	0.3660
134.9400	77.5655	0.3659
134.9483	77.4809	0.3659
134.9567	77.3995	0.3659
134.9650	77.3147	0.3658
134.9733	77.2313	0.3658
134.9817	77.1480	0.3657
134.9900	77.0668	0.3657
134.9983	76.9827	0.3657
135.0067	76.8980	0.3656
135.0150	76.8162	0.3656
135.0233	76.7325	0.3656
135.0317	76.6500	0.3655
135.0400	76.5670	0.3654
135.0483	76.4834	0.3654
135.0567	76.4007	0.3653
135.0650	76.3172	0.3653
135.0733	76.2337	0.3653
135.0817	76.1496	0.3652
135.0900	76.0678	0.3652
135.0983	75.9838	0.3652
135.1067	75.9013	0.3651
135.1150	75.8189	0.3651
135.1233	75.7347	0.3650
135.1317	75.6519	0.3650
135.1400	75.5696	0.3650
135.1483	75.4859	0.3650
135.1567	75.4017	0.3649
135.1650	75.3194	0.3646
135.1733	75.2359	0.3646
135.1817	75.1516	0.3646
135.1900	75.0695	0.3646
135.1983	74.9863	0.3645
135.2067	74.9033	0.3645
135.2150	74.8197	0.3645
135.2233	74.7360	0.3643
135.2317	74.6537	0.3643
135.2400	74.5701	0.3643
135.2483	74.4875	0.3642
135.2567	74.4048	0.3642
135.2650	74.3206	0.3642
135.2733	74.2378	0.3641
135.2817	74.1550	0.3639
135.2900	74.0726	0.3639
135.2983	73.9883	0.3637
135.3067	73.9055	0.3636
135.3150	73.8233	0.3636
135.3233	73.7398	0.3635
135.3317	73.6568	0.3635
135.3400	73.5730	0.3635
135.3483	73.4902	0.3635
135.3567	73.4072	0.3635
135.3650	73.3239	0.3635
135.3733	73.2409	0.3635
135.3817	73.1581	0.3635
135.3900	73.0739	0.3634
135.3983	72.9909	0.3634
135.4067	72.9086	0.3633
135.4150	72.8238	0.3633
135.4233	72.7423	0.3633
135.4317	72.6583	0.3633
135.4400	72.5753	0.3633
135.4483	72.4917	0.3632
135.4567	72.4090	0.3632
135.4650	72.3254	0.3632
135.4733	72.2437	0.3631
135.4817	72.1599	0.3631
135.4900	72.0755	0.3631
135.4983	71.9930	0.3631
135.5067	71.9107	0.3630
135.5150	71.8269	0.3630
135.5233	71.7439	0.3630
135.5317	71.6601	0.3630
135.5400	71.5770	0.3629
135.5483	71.4941	0.3629
135.5567	71.4116	0.3629
135.5650	71.3276	0.3628
135.5733	71.2449	0.3628
135.5817	71.1618	0.3627
135.5900	71.0784	0.3627
135.5983	70.9955	0.3627
135.6067	70.9114	0.3626
135.6150	70.8295	0.3626
135.6233	70.7472	0.3625
135.6317	70.6625	0.3625
135.6400	70.5800	0.3625
135.6483	70.4974	0.3624
135.6567	70.4147	0.3624
135.6650	70.3315	0.3624
135.6733	70.2480	0.3624
135.6817	70.1648	0.3624
135.6900	70.0825	0.3624
135.6983	70.0000	0.3623
135.7067	69.9162	0.3623
135.7150	69.8321	0.3623
135.7233	69.7498	0.3621
135.7317	69.6657	0.3621
135.7400	69.5835	0.3621
135.7483	69.4996	0.3619
135.7567	69.4162	0.3619
135.7650	69.3331	0.3620
135.7733	69.2504	0.3619
135.7817	69.1673	0.3619
135.7900	69.0836	0.3619
135.7983	69.0002	0.3619
135.8067	68.9170	0.3618
135.8150	68.8349	0.3618
135.8233	68.7524	0.3618
135.8317	68.6689	0.3618
135.8400	68.5856	0.3618
135.8483	68.5021	0.3616
135.8567	68.4190	0.3614
135.8650	68.3360	0.3615
135.8733	68.2534	0.3615
135.8817	68.1700	0.3615
135.8900	68.0872	0.3615
135.8983	68.0039	0.3614
135.9067	67.9206	0.3614
135.9150	67.8370	0.3613
135.9233	67.7546	0.3613
135.9317	67.6714	0.3613
135.9400	67.5877	0.3613
135.9483	67.5044	0.3613
135.9567	67.4206	0.3613
135.9650	67.3383	0.3612
135.9733	67.2552	0.3612
135.9817	67.1723	0.3612
135.9900	67.0897	0.3611
135.9983	67.0069	0.3611
136.0067	66.9204	0.3611
136.0150	66.8400	0.3611
136.0233	66.7568	0.3611
136.0317	66.6726	0.3610
136.0400	66.5907	0.3610
136.0483	66.5062	0.3610
136.0567	66.4229	0.3610
136.0650	66.3403	0.3609
136.0733	66.2577	0.3609
136.0817	66.1744	0.3609
136.0900	66.0909	0.3608
136.0983	66.0089	0.3608
136.1067	65.9238	0.3608
136.1150	65.8410	0.3608
136.1233	65.7590	0.3607
136.1317	65.6749	0.3607
136.1400	65.5925	0.3607
136.1483	65.5100	0.3607
136.1567	65.4264	0.3607
136.1650	65.3434	0.3608
136.1733	65.2597	0.3608
136.1817	65.1767	0.3608
136.1900	65.0941	0.3613
136.1983	65.0120	0.3621
136.2067	64.9301	0.3634
136.2150	64.8464	0.3675
136.2233	64.7625	0.3711
136.2317	64.6816	0.3751
136.2400	64.5996	0.3807
136.2483	64.5176	0.3870
136.2567	64.4358	0.3959
136.2650	64.3536	0.4088
136.2733	64.2745	0.4237
136.2817	64.1970	0.4451
136.2900	64.1176	0.4730
136.2983	64.0405	0.5104
136.3067	63.9672	0.5571
136.3150	63.8958	0.6175
136.3233	63.8272	0.6928
136.3317	63.7644	0.7848
136.3400	63.7074	0.8947
136.3483	63.6539	1.0225
136.3567	63.6084	1.1687
136.3650	63.5672	1.3249
136.3733	63.5354	1.4923
136.3817	63.5089	1.6614
136.3900	63.4877	1.8316
136.3983	63.4715	1.9946
136.4067	63.4584	2.1484
136.4150	63.4477	2.2905
136.4233	63.4399	2.4232
136.4317	63.4314	2.5428
136.4400	63.4223	2.6510
136.4483	63.4122	2.7494
136.4567	63.4025	2.8377
136.4650	63.3899	2.9198
136.4733	63.3744	2.9934
136.4817	63.3566	3.0624
136.4900	63.3377	3.1268
136.4983	63.3167	3.1876
136.5067	63.2918	3.2427
136.5150	63.2655	3.2979
136.5233	63.2361	3.3479
136.5317	63.2058	3.3963
136.5400	63.1707	3.4426
136.5483	63.1360	3.4865
136.5567	63.0978	3.5295
136.5650	63.0583	3.5685
136.5733	63.0180	3.6053
136.5817	62.9736	3.6429
136.5900	62.9287	3.6750
136.5983	62.8819	3.7066
136.6067	62.8347	3.7342
136.6150	62.7844	3.7614
136.6233	62.7313	3.7857
136.6317	62.6779	3.8048
136.6400	62.6224	3.8225
136.6483	62.5659	3.8374
136.6567	62.5062	3.8486
136.6650	62.4469	3.8579
136.6733	62.3829	3.8624
136.6817	62.3194	3.8651
136.6900	62.2539	3.8642
136.6983	62.1860	3.8600
136.7067	62.1152	3.8526
136.7150	62.0433	3.8428
136.7233	61.9702	3.8278
136.7317	61.8942	3.8117
136.7400	61.8164	3.7917
136.7483	61.7363	3.7674
136.7567	61.6550	3.7422
136.7650	61.5705	3.7117
136.7733	61.4859	3.6793
136.7817	61.3974	3.6447
136.7900	61.3086	3.6039
136.7983	61.2174	3.5627
136.8067	61.1221	3.5162
136.8150	61.0273	3.4668
136.8233	60.9303	3.4154
136.8317	60.8293	3.3614
136.8400	60.7278	3.3036
136.8483	60.6247	3.2454
136.8567	60.5185	3.1851
136.8650	60.4118	3.1209
136.8733	60.3025	3.0606
136.8817	60.1917	2.9979
136.8900	60.0802	2.9362
136.8983	59.9663	2.8738
136.9067	59.8537	2.8155
136.9150	59.7386	2.7586
136.9233	59.6241	2.7034
136.9317	59.5093	2.6486
136.9400	59.3930	2.5950
136.9483	59.2768	2.5451
136.9567	59.1615	2.4939
136.9650	59.0454	2.4442
136.9733	58.9306	2.3977
136.9817	58.8134	2.3517
136.9900	58.6991	2.3039
136.9983	58.5839	2.2621
137.0067	58.4684	2.2194
137.0150	58.3556	2.1741
137.0233	58.2411	2.1310
137.0317	58.1282	2.0902
137.0400	58.0136	2.0503
137.0483	57.9012	2.0102
137.0567	57.7891	1.9718
137.0650	57.6781	1.9355
137.0733	57.5657	1.8968
137.0817	57.4561	1.8610
137.0900	57.3445	1.8272
137.0983	57.2332	1.7931
137.1067	57.1238	1.7581
137.1150	57.0144	1.7214
137.1233	56.9045	1.6849
137.1317	56.7962	1.6515
137.1400	56.6884	1.6219
137.1483	56.5808	1.5904
137.1567	56.4728	1.5587
137.1650	56.3664	1.5297
137.1733	56.2596	1.5021
137.1817	56.1525	1.4738
137.1900	56.0477	1.4471
137.1983	55.9439	1.4221
137.2067	55.8386	1.3987
137.2150	55.7351	1.3729
137.2233	55.6311	1.3496
137.2317	55.5287	1.3266
137.2400	55.4257	1.3034
137.2483	55.3247	1.2830
137.2567	55.2227	1.2636
137.2650	55.1211	1.2429
137.2733	55.0215	1.2224
137.2817	54.9208	1.2034
137.2900	54.8222	1.1862
137.2983	54.7228	1.1675
137.3067	54.6249	1.1488
137.3150	54.5266	1.1335
137.3233	54.4298	1.1174
137.3317	54.3316	1.1007
137.3400	54.2344	1.0857
137.3483	54.1376	1.0713
137.3567	54.0419	1.0560
137.3650	53.9458	1.0415
137.3733	53.8504	1.0283
137.3817	53.7550	1.0150
137.3900	53.6608	1.0033
137.3983	53.5660	0.9920
137.4067	53.4708	0.9774
137.4150	53.3781	0.9674
137.4233	53.2835	0.9563
137.4317	53.1908	0.9436
137.4400	53.0980	0.9344
137.4483	53.0059	0.9224
137.4567	52.9129	0.9127
137.4650	52.8203	0.9022
137.4733	52.7284	0.8931
137.4817	52.6367	0.8842
137.4900	52.5443	0.8739
137.4983	52.4541	0.8646
137.5067	52.3635	0.8573
137.5150	52.2722	0.8483
137.5233	52.1832	0.8404
137.5317	52.0917	0.8309
137.5400	52.0018	0.8238
137.5483	51.9125	0.8164
137.5567	51.8231	0.8095
137.5650	51.7346	0.8020
137.5733	51.6429	0.7946
137.5817	51.5527	0.7885
137.5900	51.4647	0.7827
137.5983	51.3762	0.7741
137.6067	51.2876	0.7685
137.6150	51.1985	0.7623
137.6233	51.1105	0.7554
137.6317	51.0220	0.7499
137.6400	50.9345	0.7441
137.6483	50.8467	0.7392
137.6567	50.7587	0.7337
137.6650	50.6704	0.7269
137.6733	50.5832	0.7225
137.6817	50.4958	0.7186
137.6900	50.4069	0.7128
137.6983	50.3195	0.7069
137.7067	50.2329	0.7022
137.7150	50.1462	0.6976
137.7233	50.0579	0.6948
137.7317	49.9710	0.6877
137.7400	49.8841	0.6846
137.7483	49.7964	0.6797
137.7567	49.7104	0.6747
137.7650	49.6234	0.6709
137.7733	49.5381	0.6668
137.7817	49.4502	0.6631
137.7900	49.3655	0.6583
137.7983	49.2777	0.6555
137.8067	49.1920	0.6507
137.8150	49.1063	0.6477
137.8233	49.0207	0.6435
137.8317	48.9346	0.6400
137.8400	48.8492	0.6374
137.8483	48.7630	0.6328
137.8567	48.6760	0.6296
137.8650	48.5891	0.6274
137.8733	48.5036	0.6220
137.8817	48.4185	0.6199
137.8900	48.3329	0.6174
137.8983	48.2475	0.6136
137.9067	48.1613	0.6102
137.9150	48.0757	0.6076
137.9233	47.9905	0.6054
137.9317	47.9051	0.6017
137.9400	47.8193	0.5999
137.9483	47.7331	0.5968
137.9567	47.6498	0.5940
137.9650	47.5637	0.5911
137.9733	47.4785	0.5875
137.9817	47.3931	0.5855
137.9900	47.3085	0.5827
137.9983	47.2240	0.5802
138.0067	47.1373	0.5770
138.0150	47.0535	0.5751
138.0233	46.9683	0.5721
138.0317	46.8823	0.5693
138.0400	46.7974	0.5678
138.0483	46.7124	0.5645
138.0567	46.6276	0.5623
138.0650	46.5428	0.5607
138.0733	46.4579	0.5581
138.0817	46.3723	0.5550
138.0900	46.2875	0.5539
138.0983	46.2028	0.5515
138.1067	46.1177	0.5477
138.1150	46.0339	0.5471
138.1233	45.9489	0.5451
138.1317	45.8640	0.5429
138.1400	45.7778	0.5412
138.1483	45.6939	0.5386
138.1567	45.6086	0.5354
138.1650	45.5243	0.5340
138.1733	45.4410	0.5327
138.1817	45.3554	0.5315
138.1900	45.2705	0.5291
138.1983	45.1862	0.5264
138.2067	45.1014	0.5255
138.2150	45.0162	0.5222
138.2233	44.9327	0.5207
138.2317	44.8479	0.5190
138.2400	44.7637	0.5178
138.2483	44.6787	0.5151
138.2567	44.5947	0.5138
138.2650	44.5099	0.5124
138.2733	44.4257	0.5114
138.2817	44.3411	0.5087
138.2900	44.2569	0.5082
138.2983	44.1726	0.5043
138.3067	44.0887	0.5034
138.3150	44.0031	0.5026
138.3233	43.9192	0.5003
138.3317	43.8342	0.4986
138.3400	43.7512	0.4972
138.3483	43.6663	0.4961
138.3567	43.5816	0.4942
138.3650	43.4985	0.4927
138.3733	43.4143	0.4916
138.3817	43.3282	0.4898
138.3900	43.2445	0.4886
138.3983	43.1605	0.4868
138.4067	43.0763	0.4848
138.4150	42.9919	0.4847
138.4233	42.9086	0.4831
138.4317	42.8243	0.4818
138.4400	42.7393
138.4483	42.6559
138.4567	42.5714
138.4650	42.4863
138.4733	42.4024
138.4817	42.3191
138.4900
138.4967