File: Example Date/My Sample/DSC/test01/DSC TA/YN046(1).txt
Filename	YN046(1)
Instrument name	DSC2A-01799 (192.168.1.250)
Operator
rundate	05/12/2024
Sample name	YN046
proceduresegments	Ramp 10.00 °C/min to 150.0000 °C; Isothermal 3.0 min; Ramp 10.00 °C/min to -100.0000 °C; Isothermal 3.0 min; Ramp 10.00 °C/min to 150.0000 °C; Isothermal 3.0 min; Ramp 10.00 °C/min to -100.0000 °C; Isothermal 3.0 min; Ramp 10.00 °C/min to 150.0000 °C; Isothermal 3.0 min; Ramp 10.00 °C/min to 40.0000 °C
[File Parameters]
Run Date	05/12/2024 19:51:33
Trios version	5.7.0.56
Original File Name
Current File Name	C:\Users\TA Instruments DSC\Desktop\Data\Yutong Niu\YN046(1).tri
User at run start	DESKTOP-CFGN8IT\TA Instruments DSC
[Procedure]
Procedure Name	polyether
Sample Name	YN046
Sample Mass	15.08 mg
Reference Sample Mass	0 mg
Pan Mass	61.72 mg
Pan Number	24
Reference Pan Mass	60.81 mg
Reference Pan Number	45
Pan Type	Tzero Aluminum Pin Hole Hermetic
Comments
Project Name
Operator
Test	Custom
Unload Max Temperature	25
Unload Min Temperature	25
FillCooler	Do not fill
Load Max Temperature	25
Load Min Temperature	25
Discard pan in waste bin at end of test	Yes
Stop on Gas Flow Error	No
[Signal List]
Signal #1	Time (min)
Signal #2	Temperature (°C)
Signal #3	Heat Flow (mW)
Signal #4	Delta T (µV)
Signal #5	Delta Tzero (µV)
Signal #6	Tzero Temperature (°C)
Signal #7	Cell Purge (mL/min)
Signal #8	Heater Temp (°C)
Signal #9	Power Delivered (W)
Signal #10	Reference Junction Temperature (°C)
Signal #11	Flange Temperature (°C)
Signal #12	Heat Flow Phase (rad)
Signal #13	Total Heat Capacity (J/°C)
Signal #14	Heat Capacity (J/°C)
Signal #15	LN Pump Tank level (%)
[Configuration]
Company Name	Warwick University
Instrument Name	DSC2A-01799
Instrument Type	DSC2500
Serial Number	DSC2A-01799
IP	192.168.1.250
Location of Instrument	Polymer RTP
DisplayType	TianmaV2andV3
Sample Interval 	0.1 s/pt
Selected Heat Flow	T4P
Exotherm Direction	Up
Cell Serial	DRC2-03788
Lid Type	High Temperature
Cooler	LN Pump
Leave Cooler on at End of Sequence	Off
Gas 2	Air
Gas Selected	Channel 1: Nitrogen
Flow Rate	50 mL/min
Secondary Purge	On
Licensed Heat Flow	Heat Flow T4P
Modulation Licensed	Yes
[Versions]
Common IDD Version	1
Cortex Version	VER 2.11.0.729
Driver	5.0.0.6
GDM Version	1.0.3.3
TouchscreenVersion	1.0.3.1841
FEP Version	1.2.1.21
FEP Bootloader	2.0.0.5
AutoSampler Version	2.1.2.1
Auto Sampler Bootloader	2.0.0.5
FCM Version	1.1.0.3
FCM Bootloader	2.0.0.5
LN Pump Version	10.17.0.0
LN Pump Bootloader	2.0.0.5
[Experiment Logs]
Experiment Log Entry # 1	Ramp Segment 10 C/min to 150 Started
Experiment Log Entry # 3	Air Cool is off.
Experiment Log Entry # 5	Isothermal Segment 3 min started
Experiment Log Entry # 7	Ramp Segment 10 C/min to -100 Started
Experiment Log Entry # 9	Isothermal Segment 3 min started
Experiment Log Entry # 11	Ramp Segment 10 C/min to 150 Started
Experiment Log Entry # 13	Isothermal Segment 3 min started
Experiment Log Entry # 15	Ramp Segment 10 C/min to -100 Started
Experiment Log Entry # 17	Isothermal Segment 3 min started
Experiment Log Entry # 19	Ramp Segment 10 C/min to 150 Started
Experiment Log Entry # 21	Isothermal Segment 3 min started
Experiment Log Entry # 23	Ramp Segment 10 C/min to 40 Started
[Method Log]
Method Log Entry # 1	(Ramp 223382) Ramp 10 °C/minute to 150 °C
Method Log Entry # 2	Isothermal 3 minutes
Method Log Entry # 3	(Ramp 223384) Ramp 10 °C/minute to -100 °C
Method Log Entry # 4	Isothermal 3 minutes
Method Log Entry # 5	(Ramp 223386) Ramp 10 °C/minute to 150 °C
Method Log Entry # 6	Isothermal 3 minutes
Method Log Entry # 7	(Ramp 223388) Ramp 10 °C/minute to -100 °C
Method Log Entry # 8	Isothermal 3 minutes
Method Log Entry # 9	(Ramp 223390) Ramp 10 °C/minute to 150 °C
Method Log Entry # 10	Isothermal 3 minutes
Method Log Entry # 11	(Ramp 223392) Ramp 10 °C/minute to 40 °C
Cell Serial	DRC2-03788
[T1 Calibration]
Date Applied	04/03/2021 14:58:04
Description
Gas Type	Nitrogen
Pan Type	None
Slope	-0.001800291
Offset	-0.1301359
Initial Temperature	-100.6228
GUID	a1d5a6be-decd-4ae4-b22f-d560f3a78a92
[TZero Calibration]
Date Applied	21/08/2024 09:53:38
Description	From -180.022 °C to 395.167 °C at 20.000°C/min
Gas Type	Nitrogen
Pan Type	None
Source Files 1	C:\ProgramData\TA Instruments\TRIOS\Data\TAService\PMV 20Aug2024\Tzero Cal.tri
Source Files 2	C:\ProgramData\TA Instruments\TRIOS\Data\TAService\PMV 20Aug2024\Tzero Cal sapphire.tri
Delta T Offset	1.787969
Delta T Slope	-0.003527276
Delta T0 Offset	0.06831977
Delta T0 Slope	0.02007191
[Temperature Calibration]
Date Applied	21/08/2024 11:06:35
Description	From 106.660 °C to 186.660 °C at 10.000°C/min
Gas Type	Nitrogen
Pan Type	Tzero Aluminum
Source Files 1	C:\ProgramData\TA Instruments\TRIOS\Data\TAService\PMV 20Aug2024\TA Indium cal.tri
Measured 1	157.9141
Known 1	156.66
[Cell Constant Calibration]
Date Applied	21/08/2024 11:06:35
Description	From 106.660 °C to 186.660 °C at 10.000°C/min
Gas Type	Nitrogen
Pan Type	Tzero Aluminum
Source Files 1	C:\ProgramData\TA Instruments\TRIOS\Data\TAService\PMV 20Aug2024\TA Indium cal.tri
T4P KCell	1.038055
Onset Slope	-66.72884 mW/°C
[Direct Cp Calibration]
Date Applied	19/11/2024 16:37:27
Description	From -89.996 °C to 396.697 °C at 20.000°C/min
Gas Type	Nitrogen
Pan Type	Tzero Aluminum
Source Files 1	C:\ProgramData\TA Instruments\TRIOS\Data\Sapphire Direct Heat Capacity(8).tri
GUID	544f8371-fe9b-4f4f-81ca-7980c172113e
Temperature	-89.99625 °C
Cp	1.464367
Temperature	-89.02287 °C
Cp	1.460558
Temperature	-88.04948 °C
Cp	1.456263
Temperature	-87.0761 °C
Cp	1.451626
Temperature	-86.10271 °C
Cp	1.446737
Temperature	-85.12933 °C
Cp	1.441723
Temperature	-84.15594 °C
Cp	1.436654
Temperature	-83.18256 °C
Cp	1.431684
Temperature	-82.20917 °C
Cp	1.426935
Temperature	-81.23578 °C
Cp	1.422396
Temperature	-80.2624 °C
Cp	1.418192
Temperature	-79.28901 °C
Cp	1.414363
Temperature	-78.31562 °C
Cp	1.410925
Temperature	-77.34224 °C
Cp	1.407865
Temperature	-76.36885 °C
Cp	1.405143
Temperature	-75.39546 °C
Cp	1.402789
Temperature	-74.42208 °C
Cp	1.400703
Temperature	-73.44869 °C
Cp	1.398837
Temperature	-72.4753 °C
Cp	1.397142
Temperature	-71.50192 °C
Cp	1.395565
Temperature	-70.52853 °C
Cp	1.394053
Temperature	-69.55515 °C
Cp	1.392558
Temperature	-68.58176 °C
Cp	1.391036
Temperature	-67.60838 °C
Cp	1.389483
Temperature	-66.63499 °C
Cp	1.387847
Temperature	-65.66161 °C
Cp	1.38616
Temperature	-64.68822 °C
Cp	1.384397
Temperature	-63.71483 °C
Cp	1.382535
Temperature	-62.74145 °C
Cp	1.380598
Temperature	-61.76806 °C
Cp	1.37865
Temperature	-60.79467 °C
Cp	1.376673
Temperature	-59.82129 °C
Cp	1.374677
Temperature	-58.8479 °C
Cp	1.372642
Temperature	-57.87452 °C
Cp	1.370686
Temperature	-56.90113 °C
Cp	1.368741
Temperature	-55.92775 °C
Cp	1.366786
Temperature	-54.95436 °C
Cp	1.364863
Temperature	-53.98097 °C
Cp	1.362959
Temperature	-53.00759 °C
Cp	1.361116
Temperature	-52.0342 °C
Cp	1.359247
Temperature	-51.06082 °C
Cp	1.357393
Temperature	-50.08743 °C
Cp	1.355593
Temperature	-49.11404 °C
Cp	1.353796
Temperature	-48.14066 °C
Cp	1.352008
Temperature	-47.16727 °C
Cp	1.350215
Temperature	-46.19389 °C
Cp	1.348396
Temperature	-45.2205 °C
Cp	1.346593
Temperature	-44.24712 °C
Cp	1.344755
Temperature	-43.27373 °C
Cp	1.342891
Temperature	-42.30034 °C
Cp	1.341008
Temperature	-41.32696 °C
Cp	1.339126
Temperature	-40.35357 °C
Cp	1.337236
Temperature	-39.38018 °C
Cp	1.335367
Temperature	-38.4068 °C
Cp	1.333522
Temperature	-37.43341 °C
Cp	1.331708
Temperature	-36.46003 °C
Cp	1.32991
Temperature	-35.48664 °C
Cp	1.328145
Temperature	-34.51326 °C
Cp	1.326414
Temperature	-33.53987 °C
Cp	1.32471
Temperature	-32.56648 °C
Cp	1.323012
Temperature	-31.5931 °C
Cp	1.321323
Temperature	-30.61971 °C
Cp	1.319657
Temperature	-29.64633 °C
Cp	1.317968
Temperature	-28.67294 °C
Cp	1.316286
Temperature	-27.69955 °C
Cp	1.314585
Temperature	-26.72617 °C
Cp	1.312857
Temperature	-25.75278 °C
Cp	1.31111
Temperature	-24.7794 °C
Cp	1.309333
Temperature	-23.80601 °C
Cp	1.307544
Temperature	-22.83262 °C
Cp	1.30575
Temperature	-21.85924 °C
Cp	1.303941
Temperature	-20.88585 °C
Cp	1.302132
Temperature	-19.91247 °C
Cp	1.300313
Temperature	-18.93908 °C
Cp	1.298512
Temperature	-17.96569 °C
Cp	1.296728
Temperature	-16.99231 °C
Cp	1.294939
Temperature	-16.01892 °C
Cp	1.293198
Temperature	-15.04554 °C
Cp	1.291453
Temperature	-14.07215 °C
Cp	1.289723
Temperature	-13.09876 °C
Cp	1.288007
Temperature	-12.12538 °C
Cp	1.286283
Temperature	-11.15199 °C
Cp	1.284578
Temperature	-10.17861 °C
Cp	1.282885
Temperature	-9.205221 °C
Cp	1.281173
Temperature	-8.231835 °C
Cp	1.279472
Temperature	-7.258449 °C
Cp	1.277766
Temperature	-6.285063 °C
Cp	1.276053
Temperature	-5.311677 °C
Cp	1.274341
Temperature	-4.338291 °C
Cp	1.272592
Temperature	-3.364905 °C
Cp	1.270844
Temperature	-2.391519 °C
Cp	1.269062
Temperature	-1.418133 °C
Cp	1.267264
Temperature	-0.4447474 °C
Cp	1.265435
Temperature	0.5286385 °C
Cp	1.263575
Temperature	1.502024 °C
Cp	1.261727
Temperature	2.47541 °C
Cp	1.259854
Temperature	3.448796 °C
Cp	1.257978
Temperature	4.422182 °C
Cp	1.256109
Temperature	5.395568 °C
Cp	1.254244
Temperature	6.368954 °C
Cp	1.252392
Temperature	7.34234 °C
Cp	1.250552
Temperature	8.315726 °C
Cp	1.248704
Temperature	9.289112 °C
Cp	1.246884
Temperature	10.2625 °C
Cp	1.245078
Temperature	11.23588 °C
Cp	1.243287
Temperature	12.20927 °C
Cp	1.241522
Temperature	13.18266 °C
Cp	1.239778
Temperature	14.15604 °C
Cp	1.238068
Temperature	15.12943 °C
Cp	1.236393
Temperature	16.10281 °C
Cp	1.234762
Temperature	17.0762 °C
Cp	1.233176
Temperature	18.04959 °C
Cp	1.231629
Temperature	19.02297 °C
Cp	1.230129
Temperature	19.99636 °C
Cp	1.228694
Temperature	20.96974 °C
Cp	1.22731
Temperature	21.94313 °C
Cp	1.225968
Temperature	22.91652 °C
Cp	1.224676
Temperature	23.8899 °C
Cp	1.223431
Temperature	24.86329 °C
Cp	1.222217
Temperature	25.83667 °C
Cp	1.221065
Temperature	26.81006 °C
Cp	1.219919
Temperature	27.78345 °C
Cp	1.218811
Temperature	28.75683 °C
Cp	1.21773
Temperature	29.73022 °C
Cp	1.216663
Temperature	30.7036 °C
Cp	1.2156
Temperature	31.67699 °C
Cp	1.214515
Temperature	32.65038 °C
Cp	1.213439
Temperature	33.62376 °C
Cp	1.21234
Temperature	34.59715 °C
Cp	1.211209
Temperature	35.57053 °C
Cp	1.210051
Temperature	36.54392 °C
Cp	1.208868
Temperature	37.5173 °C
Cp	1.207666
Temperature	38.49069 °C
Cp	1.206439
Temperature	39.46408 °C
Cp	1.205199
Temperature	40.43746 °C
Cp	1.203959
Temperature	41.41085 °C
Cp	1.202712
Temperature	42.38424 °C
Cp	1.20147
Temperature	43.35762 °C
Cp	1.200231
Temperature	44.33101 °C
Cp	1.199
Temperature	45.30439 °C
Cp	1.197777
Temperature	46.27778 °C
Cp	1.19657
Temperature	47.25116 °C
Cp	1.195367
Temperature	48.22455 °C
Cp	1.194179
Temperature	49.19794 °C
Cp	1.19301
Temperature	50.17132 °C
Cp	1.191849
Temperature	51.14471 °C
Cp	1.190694
Temperature	52.11809 °C
Cp	1.189555
Temperature	53.09148 °C
Cp	1.18843
Temperature	54.06487 °C
Cp	1.187311
Temperature	55.03825 °C
Cp	1.186195
Temperature	56.01164 °C
Cp	1.185095
Temperature	56.98502 °C
Cp	1.183997
Temperature	57.95841 °C
Cp	1.182894
Temperature	58.93179 °C
Cp	1.181793
Temperature	59.90518 °C
Cp	1.180693
Temperature	60.87857 °C
Cp	1.179595
Temperature	61.85195 °C
Cp	1.178501
Temperature	62.82534 °C
Cp	1.177406
Temperature	63.79873 °C
Cp	1.176313
Temperature	64.77211 °C
Cp	1.175239
Temperature	65.7455 °C
Cp	1.17417
Temperature	66.71888 °C
Cp	1.173105
Temperature	67.69227 °C
Cp	1.172037
Temperature	68.66566 °C
Cp	1.170989
Temperature	69.63904 °C
Cp	1.169948
Temperature	70.61243 °C
Cp	1.168905
Temperature	71.58582 °C
Cp	1.167872
Temperature	72.5592 °C
Cp	1.166849
Temperature	73.53259 °C
Cp	1.165851
Temperature	74.50597 °C
Cp	1.164848
Temperature	75.47935 °C
Cp	1.163876
Temperature	76.45274 °C
Cp	1.162926
Temperature	77.42612 °C
Cp	1.162008
Temperature	78.39951 °C
Cp	1.161113
Temperature	79.3729 °C
Cp	1.160219
Temperature	80.34628 °C
Cp	1.159377
Temperature	81.31967 °C
Cp	1.158546
Temperature	82.29306 °C
Cp	1.157726
Temperature	83.26644 °C
Cp	1.15692
Temperature	84.23983 °C
Cp	1.156126
Temperature	85.21322 °C
Cp	1.155375
Temperature	86.1866 °C
Cp	1.154604
Temperature	87.15999 °C
Cp	1.153869
Temperature	88.13337 °C
Cp	1.153158
Temperature	89.10676 °C
Cp	1.152474
Temperature	90.08015 °C
Cp	1.15181
Temperature	91.05353 °C
Cp	1.151134
Temperature	92.02692 °C
Cp	1.150513
Temperature	93.00031 °C
Cp	1.149892
Temperature	93.97369 °C
Cp	1.149266
Temperature	94.94707 °C
Cp	1.148642
Temperature	95.92046 °C
Cp	1.148019
Temperature	96.89384 °C
Cp	1.147402
Temperature	97.86723 °C
Cp	1.146799
Temperature	98.84062 °C
Cp	1.146191
Temperature	99.814 °C
Cp	1.145602
Temperature	100.7874 °C
Cp	1.14503
Temperature	101.7608 °C
Cp	1.144469
Temperature	102.7342 °C
Cp	1.143921
Temperature	103.7076 °C
Cp	1.143383
Temperature	104.6809 °C
Cp	1.142861
Temperature	105.6543 °C
Cp	1.142345
Temperature	106.6277 °C
Cp	1.141835
Temperature	107.6011 °C
Cp	1.141335
Temperature	108.5745 °C
Cp	1.140846
Temperature	109.5479 °C
Cp	1.140365
Temperature	110.5212 °C
Cp	1.139891
Temperature	111.4946 °C
Cp	1.139429
Temperature	112.468 °C
Cp	1.138976
Temperature	113.4414 °C
Cp	1.13853
Temperature	114.4148 °C
Cp	1.138092
Temperature	115.3882 °C
Cp	1.137654
Temperature	116.3616 °C
Cp	1.137223
Temperature	117.335 °C
Cp	1.136785
Temperature	118.3083 °C
Cp	1.136338
Temperature	119.2817 °C
Cp	1.13588
Temperature	120.2551 °C
Cp	1.13541
Temperature	121.2285 °C
Cp	1.134927
Temperature	122.2019 °C
Cp	1.134417
Temperature	123.1753 °C
Cp	1.133892
Temperature	124.1487 °C
Cp	1.133347
Temperature	125.122 °C
Cp	1.132786
Temperature	126.0954 °C
Cp	1.132206
Temperature	127.0688 °C
Cp	1.131606
Temperature	128.0422 °C
Cp	1.130999
Temperature	129.0156 °C
Cp	1.130384
Temperature	129.989 °C
Cp	1.129765
Temperature	130.9624 °C
Cp	1.129147
Temperature	131.9357 °C
Cp	1.12854
Temperature	132.9091 °C
Cp	1.127949
Temperature	133.8825 °C
Cp	1.127383
Temperature	134.8559 °C
Cp	1.126841
Temperature	135.8293 °C
Cp	1.126334
Temperature	136.8027 °C
Cp	1.125871
Temperature	137.7761 °C
Cp	1.125443
Temperature	138.7494 °C
Cp	1.125058
Temperature	139.7228 °C
Cp	1.124701
Temperature	140.6962 °C
Cp	1.124397
Temperature	141.6696 °C
Cp	1.124114
Temperature	142.643 °C
Cp	1.123854
Temperature	143.6164 °C
Cp	1.123612
Temperature	144.5898 °C
Cp	1.123385
Temperature	145.5631 °C
Cp	1.123182
Temperature	146.5365 °C
Cp	1.12296
Temperature	147.5099 °C
Cp	1.12275
Temperature	148.4833 °C
Cp	1.122543
Temperature	149.4567 °C
Cp	1.122327
Temperature	150.4301 °C
Cp	1.122099
Temperature	151.4035 °C
Cp	1.121837
Temperature	152.3768 °C
Cp	1.121582
Temperature	153.3502 °C
Cp	1.121289
Temperature	154.3236 °C
Cp	1.120967
Temperature	155.297 °C
Cp	1.120616
Temperature	156.2704 °C
Cp	1.120238
Temperature	157.2438 °C
Cp	1.119862
Temperature	158.2172 °C
Cp	1.119444
Temperature	159.1906 °C
Cp	1.119028
Temperature	160.1639 °C
Cp	1.118613
Temperature	161.1373 °C
Cp	1.118202
Temperature	162.1107 °C
Cp	1.117795
Temperature	163.0841 °C
Cp	1.117374
Temperature	164.0575 °C
Cp	1.116987
Temperature	165.0309 °C
Cp	1.116595
Temperature	166.0042 °C
Cp	1.116198
Temperature	166.9776 °C
Cp	1.1158
Temperature	167.951 °C
Cp	1.115402
Temperature	168.9244 °C
Cp	1.115006
Temperature	169.8978 °C
Cp	1.11462
Temperature	170.8712 °C
Cp	1.114223
Temperature	171.8446 °C
Cp	1.113836
Temperature	172.8179 °C
Cp	1.113458
Temperature	173.7913 °C
Cp	1.113085
Temperature	174.7647 °C
Cp	1.112712
Temperature	175.7381 °C
Cp	1.112323
Temperature	176.7115 °C
Cp	1.111957
Temperature	177.6849 °C
Cp	1.111578
Temperature	178.6583 °C
Cp	1.111185
Temperature	179.6317 °C
Cp	1.110789
Temperature	180.605 °C
Cp	1.110391
Temperature	181.5784 °C
Cp	1.110016
Temperature	182.5518 °C
Cp	1.109611
Temperature	183.5252 °C
Cp	1.109232
Temperature	184.4986 °C
Cp	1.108873
Temperature	185.472 °C
Cp	1.108531
Temperature	186.4454 °C
Cp	1.108199
Temperature	187.4187 °C
Cp	1.107851
Temperature	188.3921 °C
Cp	1.107551
Temperature	189.3655 °C
Cp	1.107238
Temperature	190.3389 °C
Cp	1.106917
Temperature	191.3123 °C
Cp	1.106589
Temperature	192.2857 °C
Cp	1.106259
Temperature	193.259 °C
Cp	1.105958
Temperature	194.2324 °C
Cp	1.105619
Temperature	195.2058 °C
Cp	1.105301
Temperature	196.1792 °C
Cp	1.105002
Temperature	197.1526 °C
Cp	1.104718
Temperature	198.126 °C
Cp	1.104445
Temperature	199.0994 °C
Cp	1.104161
Temperature	200.0728 °C
Cp	1.103914
Temperature	201.0461 °C
Cp	1.103657
Temperature	202.0195 °C
Cp	1.103395
Temperature	202.9929 °C
Cp	1.103125
Temperature	203.9663 °C
Cp	1.102847
Temperature	204.9397 °C
Cp	1.102563
Temperature	205.9131 °C
Cp	1.102283
Temperature	206.8865 °C
Cp	1.101985
Temperature	207.8598 °C
Cp	1.10169
Temperature	208.8332 °C
Cp	1.101394
Temperature	209.8066 °C
Cp	1.101099
Temperature	210.78 °C
Cp	1.1008
Temperature	211.7534 °C
Cp	1.10049
Temperature	212.7268 °C
Cp	1.100193
Temperature	213.7002 °C
Cp	1.099886
Temperature	214.6735 °C
Cp	1.099577
Temperature	215.6469 °C
Cp	1.099268
Temperature	216.6203 °C
Cp	1.098965
Temperature	217.5937 °C
Cp	1.098685
Temperature	218.5671 °C
Cp	1.098396
Temperature	219.5405 °C
Cp	1.098134
Temperature	220.5139 °C
Cp	1.097895
Temperature	221.4872 °C
Cp	1.09768
Temperature	222.4606 °C
Cp	1.097485
Temperature	223.434 °C
Cp	1.097292
Temperature	224.4074 °C
Cp	1.09714
Temperature	225.3808 °C
Cp	1.096991
Temperature	226.3542 °C
Cp	1.096844
Temperature	227.3276 °C
Cp	1.096699
Temperature	228.3009 °C
Cp	1.096559
Temperature	229.2743 °C
Cp	1.096442
Temperature	230.2477 °C
Cp	1.096296
Temperature	231.2211 °C
Cp	1.096164
Temperature	232.1945 °C
Cp	1.09604
Temperature	233.1679 °C
Cp	1.095924
Temperature	234.1413 °C
Cp	1.095807
Temperature	235.1147 °C
Cp	1.095665
Temperature	236.088 °C
Cp	1.095557
Temperature	237.0614 °C
Cp	1.095433
Temperature	238.0348 °C
Cp	1.095296
Temperature	239.0082 °C
Cp	1.095147
Temperature	239.9816 °C
Cp	1.094995
Temperature	240.955 °C
Cp	1.094843
Temperature	241.9283 °C
Cp	1.094705
Temperature	242.9017 °C
Cp	1.094562
Temperature	243.8751 °C
Cp	1.094442
Temperature	244.8485 °C
Cp	1.094344
Temperature	245.8219 °C
Cp	1.094266
Temperature	246.7953 °C
Cp	1.094209
Temperature	247.7687 °C
Cp	1.094161
Temperature	248.7421 °C
Cp	1.094144
Temperature	249.7154 °C
Cp	1.094133
Temperature	250.6888 °C
Cp	1.094127
Temperature	251.6622 °C
Cp	1.094126
Temperature	252.6356 °C
Cp	1.094127
Temperature	253.609 °C
Cp	1.094138
Temperature	254.5824 °C
Cp	1.09413
Temperature	255.5558 °C
Cp	1.094123
Temperature	256.5291 °C
Cp	1.094111
Temperature	257.5025 °C
Cp	1.094087
Temperature	258.4759 °C
Cp	1.094046
Temperature	259.4493 °C
Cp	1.093978
Temperature	260.4227 °C
Cp	1.093895
Temperature	261.3961 °C
Cp	1.093783
Temperature	262.3694 °C
Cp	1.093645
Temperature	263.3428 °C
Cp	1.093483
Temperature	264.3162 °C
Cp	1.093302
Temperature	265.2896 °C
Cp	1.093109
Temperature	266.263 °C
Cp	1.092906
Temperature	267.2364 °C
Cp	1.092704
Temperature	268.2098 °C
Cp	1.092511
Temperature	269.1832 °C
Cp	1.092331
Temperature	270.1566 °C
Cp	1.092174
Temperature	271.1299 °C
Cp	1.092046
Temperature	272.1033 °C
Cp	1.091947
Temperature	273.0767 °C
Cp	1.091882
Temperature	274.0501 °C
Cp	1.091853
Temperature	275.0235 °C
Cp	1.091859
Temperature	275.9969 °C
Cp	1.091895
Temperature	276.9702 °C
Cp	1.091957
Temperature	277.9436 °C
Cp	1.092036
Temperature	278.917 °C
Cp	1.092132
Temperature	279.8904 °C
Cp	1.09223
Temperature	280.8638 °C
Cp	1.092323
Temperature	281.8372 °C
Cp	1.092405
Temperature	282.8105 °C
Cp	1.092468
Temperature	283.7839 °C
Cp	1.092513
Temperature	284.7573 °C
Cp	1.092525
Temperature	285.7307 °C
Cp	1.092512
Temperature	286.7041 °C
Cp	1.092472
Temperature	287.6775 °C
Cp	1.092405
Temperature	288.6509 °C
Cp	1.092313
Temperature	289.6243 °C
Cp	1.092197
Temperature	290.5977 °C
Cp	1.09207
Temperature	291.571 °C
Cp	1.091931
Temperature	292.5444 °C
Cp	1.091785
Temperature	293.5178 °C
Cp	1.091641
Temperature	294.4912 °C
Cp	1.091506
Temperature	295.4646 °C
Cp	1.091387
Temperature	296.438 °C
Cp	1.091282
Temperature	297.4113 °C
Cp	1.091201
Temperature	298.3847 °C
Cp	1.091145
Temperature	299.3581 °C
Cp	1.091112
Temperature	300.3315 °C
Cp	1.091102
Temperature	301.3049 °C
Cp	1.091107
Temperature	302.2783 °C
Cp	1.091137
Temperature	303.2517 °C
Cp	1.091177
Temperature	304.2251 °C
Cp	1.091226
Temperature	305.1984 °C
Cp	1.09128
Temperature	306.1718 °C
Cp	1.091336
Temperature	307.1452 °C
Cp	1.091403
Temperature	308.1186 °C
Cp	1.091453
Temperature	309.092 °C
Cp	1.091506
Temperature	310.0654 °C
Cp	1.091561
Temperature	311.0388 °C
Cp	1.091617
Temperature	312.0121 °C
Cp	1.09167
Temperature	312.9855 °C
Cp	1.091716
Temperature	313.9589 °C
Cp	1.091762
Temperature	314.9323 °C
Cp	1.091805
Temperature	315.9057 °C
Cp	1.091838
Temperature	316.8791 °C
Cp	1.09186
Temperature	317.8524 °C
Cp	1.091871
Temperature	318.8258 °C
Cp	1.091872
Temperature	319.7992 °C
Cp	1.091867
Temperature	320.7726 °C
Cp	1.091838
Temperature	321.746 °C
Cp	1.0918
Temperature	322.7194 °C
Cp	1.091752
Temperature	323.6928 °C
Cp	1.091689
Temperature	324.6662 °C
Cp	1.091611
Temperature	325.6396 °C
Cp	1.091508
Temperature	326.6129 °C
Cp	1.091406
Temperature	327.5863 °C
Cp	1.091285
Temperature	328.5597 °C
Cp	1.09115
Temperature	329.5331 °C
Cp	1.091009
Temperature	330.5065 °C
Cp	1.09087
Temperature	331.4799 °C
Cp	1.090747
Temperature	332.4532 °C
Cp	1.090628
Temperature	333.4266 °C
Cp	1.090536
Temperature	334.4 °C
Cp	1.090472
Temperature	335.3734 °C
Cp	1.090437
Temperature	336.3468 °C
Cp	1.090431
Temperature	337.3202 °C
Cp	1.090455
Temperature	338.2935 °C
Cp	1.090503
Temperature	339.2669 °C
Cp	1.090573
Temperature	340.2403 °C
Cp	1.090658
Temperature	341.2137 °C
Cp	1.090753
Temperature	342.1871 °C
Cp	1.090853
Temperature	343.1605 °C
Cp	1.090952
Temperature	344.1339 °C
Cp	1.09105
Temperature	345.1073 °C
Cp	1.091141
Temperature	346.0807 °C
Cp	1.091225
Temperature	347.054 °C
Cp	1.091303
Temperature	348.0274 °C
Cp	1.091379
Temperature	349.0008 °C
Cp	1.091453
Temperature	349.9742 °C
Cp	1.091537
Temperature	350.9476 °C
Cp	1.091633
Temperature	351.921 °C
Cp	1.091743
Temperature	352.8943 °C
Cp	1.091874
Temperature	353.8677 °C
Cp	1.092028
Temperature	354.8411 °C
Cp	1.092206
Temperature	355.8145 °C
Cp	1.092411
Temperature	356.7879 °C
Cp	1.092628
Temperature	357.7613 °C
Cp	1.092862
Temperature	358.7346 °C
Cp	1.093102
Temperature	359.708 °C
Cp	1.093338
Temperature	360.6814 °C
Cp	1.093559
Temperature	361.6548 °C
Cp	1.093752
Temperature	362.6282 °C
Cp	1.093915
Temperature	363.6016 °C
Cp	1.094036
Temperature	364.575 °C
Cp	1.094117
Temperature	365.5484 °C
Cp	1.094159
Temperature	366.5218 °C
Cp	1.094172
Temperature	367.4951 °C
Cp	1.094165
Temperature	368.4685 °C
Cp	1.094163
Temperature	369.4419 °C
Cp	1.094182
Temperature	370.4153 °C
Cp	1.094244
Temperature	371.3887 °C
Cp	1.094375
Temperature	372.3621 °C
Cp	1.094598
Temperature	373.3354 °C
Cp	1.094937
Temperature	374.3088 °C
Cp	1.095389
Temperature	375.2822 °C
Cp	1.095973
Temperature	376.2556 °C
Cp	1.096685
Temperature	377.229 °C
Cp	1.097506
Temperature	378.2024 °C
Cp	1.098406
Temperature	379.1758 °C
Cp	1.099338
Temperature	380.1492 °C
Cp	1.10027
Temperature	381.1225 °C
Cp	1.10112
Temperature	382.0959 °C
Cp	1.101818
Temperature	383.0693 °C
Cp	1.10229
Temperature	384.0427 °C
Cp	1.102459
Temperature	385.0161 °C
Cp	1.102253
Temperature	385.9895 °C
Cp	1.101596
Temperature	386.9629 °C
Cp	1.100438
Temperature	387.9362 °C
Cp	1.098736
Temperature	388.9096 °C
Cp	1.096461
Temperature	389.883 °C
Cp	1.093614
Temperature	390.8564 °C
Cp	1.090208
Temperature	391.8298 °C
Cp	1.086278
Temperature	392.8032 °C
Cp	1.081887
Temperature	393.7766 °C
Cp	1.077096
Temperature	394.7499 °C
Cp	1.072007
Temperature	395.7233 °C
Cp	1.066707
[Rev Cp Calibration]
Date Applied	24/10/2024 12:37:31
Description	From -89.998 °C to 390.542 °C at 2.000°C/min
Gas Type	Nitrogen
Pan Type	Tzero Aluminum
Source Files 1	C:\ProgramData\TA Instruments\TRIOS\Data\Reverse Heat Capacity Calibration(6).tri
GUID	ba867d72-cfbb-486e-971e-e86aa544cc02
Temperature	-89.99799 °C
Cp	1.070076
Temperature	-89.03691 °C
Cp	1.072008
Temperature	-88.07584 °C
Cp	1.073556
Temperature	-87.11475 °C
Cp	1.074743
Temperature	-86.15367 °C
Cp	1.075597
Temperature	-85.1926 °C
Cp	1.076163
Temperature	-84.23151 °C
Cp	1.076477
Temperature	-83.27043 °C
Cp	1.076579
Temperature	-82.30936 °C
Cp	1.076527
Temperature	-81.34827 °C
Cp	1.076322
Temperature	-80.38719 °C
Cp	1.076039
Temperature	-79.42612 °C
Cp	1.07571
Temperature	-78.46503 °C
Cp	1.075361
Temperature	-77.50395 °C
Cp	1.075011
Temperature	-76.54288 °C
Cp	1.074656
Temperature	-75.58179 °C
Cp	1.074359
Temperature	-74.62071 °C
Cp	1.074086
Temperature	-73.65964 °C
Cp	1.073842
Temperature	-72.69855 °C
Cp	1.073627
Temperature	-71.73747 °C
Cp	1.073442
Temperature	-70.7764 °C
Cp	1.07329
Temperature	-69.81532 °C
Cp	1.073148
Temperature	-68.85423 °C
Cp	1.073021
Temperature	-67.89315 °C
Cp	1.072902
Temperature	-66.93208 °C
Cp	1.072782
Temperature	-65.97099 °C
Cp	1.072656
Temperature	-65.00991 °C
Cp	1.072518
Temperature	-64.04884 °C
Cp	1.072374
Temperature	-63.08775 °C
Cp	1.072201
Temperature	-62.12667 °C
Cp	1.072019
Temperature	-61.1656 °C
Cp	1.071827
Temperature	-60.20451 °C
Cp	1.071624
Temperature	-59.24343 °C
Cp	1.071411
Temperature	-58.28236 °C
Cp	1.071167
Temperature	-57.32127 °C
Cp	1.070956
Temperature	-56.3602 °C
Cp	1.070724
Temperature	-55.39911 °C
Cp	1.070483
Temperature	-54.43803 °C
Cp	1.070242
Temperature	-53.47696 °C
Cp	1.070009
Temperature	-52.51587 °C
Cp	1.069825
Temperature	-51.55479 °C
Cp	1.069601
Temperature	-50.59372 °C
Cp	1.069418
Temperature	-49.63263 °C
Cp	1.069267
Temperature	-48.67155 °C
Cp	1.069138
Temperature	-47.71048 °C
Cp	1.069021
Temperature	-46.74939 °C
Cp	1.068875
Temperature	-45.78831 °C
Cp	1.068771
Temperature	-44.82724 °C
Cp	1.068634
Temperature	-43.86615 °C
Cp	1.068462
Temperature	-42.90508 °C
Cp	1.068255
Temperature	-41.944 °C
Cp	1.068012
Temperature	-40.98291 °C
Cp	1.067742
Temperature	-40.02184 °C
Cp	1.067427
Temperature	-39.06076 °C
Cp	1.067088
Temperature	-38.09967 °C
Cp	1.066727
Temperature	-37.1386 °C
Cp	1.066349
Temperature	-36.17752 °C
Cp	1.065958
Temperature	-35.21643 °C
Cp	1.065559
Temperature	-34.25536 °C
Cp	1.065162
Temperature	-33.29427 °C
Cp	1.06476
Temperature	-32.33319 °C
Cp	1.064368
Temperature	-31.37212 °C
Cp	1.06399
Temperature	-30.41104 °C
Cp	1.063628
Temperature	-29.44995 °C
Cp	1.063283
Temperature	-28.48887 °C
Cp	1.06295
Temperature	-27.5278 °C
Cp	1.062645
Temperature	-26.56672 °C
Cp	1.062355
Temperature	-25.60563 °C
Cp	1.06208
Temperature	-24.64456 °C
Cp	1.061819
Temperature	-23.68348 °C
Cp	1.061573
Temperature	-22.72239 °C
Cp	1.061345
Temperature	-21.76132 °C
Cp	1.061123
Temperature	-20.80024 °C
Cp	1.060915
Temperature	-19.83916 °C
Cp	1.060719
Temperature	-18.87807 °C
Cp	1.060531
Temperature	-17.917 °C
Cp	1.06035
Temperature	-16.95592 °C
Cp	1.060161
Temperature	-15.99484 °C
Cp	1.059992
Temperature	-15.03376 °C
Cp	1.059817
Temperature	-14.07268 °C
Cp	1.059634
Temperature	-13.1116 °C
Cp	1.059445
Temperature	-12.15052 °C
Cp	1.059248
Temperature	-11.18944 °C
Cp	1.059043
Temperature	-10.22836 °C
Cp	1.058842
Temperature	-9.267276 °C
Cp	1.058615
Temperature	-8.306196 °C
Cp	1.058388
Temperature	-7.345116 °C
Cp	1.058155
Temperature	-6.384036 °C
Cp	1.057911
Temperature	-5.422956 °C
Cp	1.057652
Temperature	-4.461876 °C
Cp	1.057356
Temperature	-3.500796 °C
Cp	1.057063
Temperature	-2.539716 °C
Cp	1.056732
Temperature	-1.578636 °C
Cp	1.056364
Temperature	-0.6175562 °C
Cp	1.05596
Temperature	0.3435238 °C
Cp	1.055523
Temperature	1.304604 °C
Cp	1.055066
Temperature	2.265684 °C
Cp	1.054561
Temperature	3.226764 °C
Cp	1.054035
Temperature	4.187844 °C
Cp	1.053488
Temperature	5.148924 °C
Cp	1.052922
Temperature	6.110003 °C
Cp	1.052337
Temperature	7.071084 °C
Cp	1.051736
Temperature	8.032164 °C
Cp	1.051118
Temperature	8.993243 °C
Cp	1.050488
Temperature	9.954324 °C
Cp	1.049848
Temperature	10.9154 °C
Cp	1.049202
Temperature	11.87648 °C
Cp	1.048552
Temperature	12.83756 °C
Cp	1.047902
Temperature	13.79864 °C
Cp	1.047255
Temperature	14.75972 °C
Cp	1.046615
Temperature	15.7208 °C
Cp	1.045983
Temperature	16.68188 °C
Cp	1.045362
Temperature	17.64296 °C
Cp	1.044756
Temperature	18.60404 °C
Cp	1.044164
Temperature	19.56512 °C
Cp	1.04358
Temperature	20.5262 °C
Cp	1.043027
Temperature	21.48728 °C
Cp	1.042485
Temperature	22.44836 °C
Cp	1.041958
Temperature	23.40944 °C
Cp	1.041446
Temperature	24.37052 °C
Cp	1.040952
Temperature	25.3316 °C
Cp	1.040493
Temperature	26.29268 °C
Cp	1.040022
Temperature	27.25376 °C
Cp	1.039578
Temperature	28.21484 °C
Cp	1.039158
Temperature	29.17592 °C
Cp	1.038758
Temperature	30.137 °C
Cp	1.038373
Temperature	31.09808 °C
Cp	1.037981
Temperature	32.05916 °C
Cp	1.03763
Temperature	33.02024 °C
Cp	1.037276
Temperature	33.98132 °C
Cp	1.03692
Temperature	34.9424 °C
Cp	1.036565
Temperature	35.90348 °C
Cp	1.036213
Temperature	36.86456 °C
Cp	1.035866
Temperature	37.82564 °C
Cp	1.035529
Temperature	38.78672 °C
Cp	1.035195
Temperature	39.7478 °C
Cp	1.034875
Temperature	40.70888 °C
Cp	1.034568
Temperature	41.66996 °C
Cp	1.034276
Temperature	42.63104 °C
Cp	1.033996
Temperature	43.59212 °C
Cp	1.033726
Temperature	44.5532 °C
Cp	1.033469
Temperature	45.51428 °C
Cp	1.033221
Temperature	46.47536 °C
Cp	1.03298
Temperature	47.43644 °C
Cp	1.032744
Temperature	48.39752 °C
Cp	1.032514
Temperature	49.3586 °C
Cp	1.032289
Temperature	50.31968 °C
Cp	1.032065
Temperature	51.28076 °C
Cp	1.031844
Temperature	52.24184 °C
Cp	1.031627
Temperature	53.20292 °C
Cp	1.031413
Temperature	54.164 °C
Cp	1.031203
Temperature	55.12508 °C
Cp	1.030989
Temperature	56.08616 °C
Cp	1.030791
Temperature	57.04724 °C
Cp	1.030595
Temperature	58.00832 °C
Cp	1.030403
Temperature	58.9694 °C
Cp	1.030217
Temperature	59.93048 °C
Cp	1.03004
Temperature	60.89156 °C
Cp	1.029871
Temperature	61.85264 °C
Cp	1.029718
Temperature	62.81372 °C
Cp	1.029567
Temperature	63.7748 °C
Cp	1.02943
Temperature	64.73589 °C
Cp	1.029304
Temperature	65.69696 °C
Cp	1.029185
Temperature	66.65804 °C
Cp	1.02907
Temperature	67.61913 °C
Cp	1.028946
Temperature	68.5802 °C
Cp	1.028831
Temperature	69.54128 °C
Cp	1.028703
Temperature	70.50237 °C
Cp	1.028561
Temperature	71.46344 °C
Cp	1.028404
Temperature	72.42452 °C
Cp	1.028234
Temperature	73.3856 °C
Cp	1.028063
Temperature	74.34668 °C
Cp	1.027861
Temperature	75.30776 °C
Cp	1.027657
Temperature	76.26884 °C
Cp	1.027451
Temperature	77.22992 °C
Cp	1.027243
Temperature	78.191 °C
Cp	1.027036
Temperature	79.15208 °C
Cp	1.026812
Temperature	80.11316 °C
Cp	1.026623
Temperature	81.07424 °C
Cp	1.026431
Temperature	82.03532 °C
Cp	1.026241
Temperature	82.9964 °C
Cp	1.02606
Temperature	83.95748 °C
Cp	1.025891
Temperature	84.91856 °C
Cp	1.025739
Temperature	85.87964 °C
Cp	1.025614
Temperature	86.84072 °C
Cp	1.025493
Temperature	87.8018 °C
Cp	1.0254
Temperature	88.76288 °C
Cp	1.025329
Temperature	89.72396 °C
Cp	1.025274
Temperature	90.68504 °C
Cp	1.025229
Temperature	91.64612 °C
Cp	1.025174
Temperature	92.6072 °C
Cp	1.025138
Temperature	93.56828 °C
Cp	1.025083
Temperature	94.52936 °C
Cp	1.025008
Temperature	95.49044 °C
Cp	1.024912
Temperature	96.45152 °C
Cp	1.024796
Temperature	97.4126 °C
Cp	1.024671
Temperature	98.37368 °C
Cp	1.024506
Temperature	99.33476 °C
Cp	1.02433
Temperature	100.2958 °C
Cp	1.024144
Temperature	101.2569 °C
Cp	1.023948
Temperature	102.218 °C
Cp	1.023743
Temperature	103.1791 °C
Cp	1.023522
Temperature	104.1402 °C
Cp	1.023309
Temperature	105.1012 °C
Cp	1.023089
Temperature	106.0623 °C
Cp	1.022866
Temperature	107.0234 °C
Cp	1.022644
Temperature	107.9845 °C
Cp	1.022427
Temperature	108.9456 °C
Cp	1.022218
Temperature	109.9066 °C
Cp	1.022022
Temperature	110.8677 °C
Cp	1.021836
Temperature	111.8288 °C
Cp	1.021666
Temperature	112.7899 °C
Cp	1.021512
Temperature	113.751 °C
Cp	1.021374
Temperature	114.712 °C
Cp	1.02125
Temperature	115.6731 °C
Cp	1.021137
Temperature	116.6342 °C
Cp	1.021041
Temperature	117.5953 °C
Cp	1.020953
Temperature	118.5564 °C
Cp	1.020872
Temperature	119.5174 °C
Cp	1.020796
Temperature	120.4785 °C
Cp	1.020725
Temperature	121.4396 °C
Cp	1.020659
Temperature	122.4007 °C
Cp	1.020587
Temperature	123.3618 °C
Cp	1.020515
Temperature	124.3228 °C
Cp	1.02044
Temperature	125.2839 °C
Cp	1.020359
Temperature	126.245 °C
Cp	1.02027
Temperature	127.2061 °C
Cp	1.020167
Temperature	128.1672 °C
Cp	1.020057
Temperature	129.1282 °C
Cp	1.019933
Temperature	130.0893 °C
Cp	1.019793
Temperature	131.0504 °C
Cp	1.019638
Temperature	132.0115 °C
Cp	1.019471
Temperature	132.9726 °C
Cp	1.019292
Temperature	133.9336 °C
Cp	1.019107
Temperature	134.8947 °C
Cp	1.018912
Temperature	135.8558 °C
Cp	1.018717
Temperature	136.8169 °C
Cp	1.018527
Temperature	137.778 °C
Cp	1.018344
Temperature	138.739 °C
Cp	1.018171
Temperature	139.7001 °C
Cp	1.018004
Temperature	140.6612 °C
Cp	1.01787
Temperature	141.6223 °C
Cp	1.01775
Temperature	142.5834 °C
Cp	1.017652
Temperature	143.5444 °C
Cp	1.017578
Temperature	144.5055 °C
Cp	1.017534
Temperature	145.4666 °C
Cp	1.017536
Temperature	146.4277 °C
Cp	1.017545
Temperature	147.3888 °C
Cp	1.017595
Temperature	148.3498 °C
Cp	1.017679
Temperature	149.3109 °C
Cp	1.01779
Temperature	150.272 °C
Cp	1.01792
Temperature	151.2331 °C
Cp	1.018043
Temperature	152.1942 °C
Cp	1.018199
Temperature	153.1552 °C
Cp	1.018339
Temperature	154.1163 °C
Cp	1.018458
Temperature	155.0774 °C
Cp	1.018552
Temperature	156.0385 °C
Cp	1.018618
Temperature	156.9996 °C
Cp	1.018662
Temperature	157.9606 °C
Cp	1.018664
Temperature	158.9217 °C
Cp	1.018632
Temperature	159.8828 °C
Cp	1.018575
Temperature	160.8439 °C
Cp	1.018492
Temperature	161.805 °C
Cp	1.018383
Temperature	162.766 °C
Cp	1.01825
Temperature	163.7271 °C
Cp	1.018087
Temperature	164.6882 °C
Cp	1.017917
Temperature	165.6493 °C
Cp	1.017726
Temperature	166.6104 °C
Cp	1.017522
Temperature	167.5714 °C
Cp	1.01731
Temperature	168.5325 °C
Cp	1.017098
Temperature	169.4936 °C
Cp	1.016902
Temperature	170.4547 °C
Cp	1.016695
Temperature	171.4158 °C
Cp	1.016508
Temperature	172.3768 °C
Cp	1.016342
Temperature	173.3379 °C
Cp	1.016195
Temperature	174.299 °C
Cp	1.016065
Temperature	175.2601 °C
Cp	1.015927
Temperature	176.2212 °C
Cp	1.015838
Temperature	177.1822 °C
Cp	1.015746
Temperature	178.1433 °C
Cp	1.015651
Temperature	179.1044 °C
Cp	1.015555
Temperature	180.0655 °C
Cp	1.015459
Temperature	181.0266 °C
Cp	1.015401
Temperature	181.9876 °C
Cp	1.015288
Temperature	182.9487 °C
Cp	1.015195
Temperature	183.9098 °C
Cp	1.015117
Temperature	184.8709 °C
Cp	1.01505
Temperature	185.832 °C
Cp	1.014988
Temperature	186.793 °C
Cp	1.014927
Temperature	187.7541 °C
Cp	1.014849
Temperature	188.7152 °C
Cp	1.014789
Temperature	189.6763 °C
Cp	1.01471
Temperature	190.6374 °C
Cp	1.014614
Temperature	191.5984 °C
Cp	1.014503
Temperature	192.5595 °C
Cp	1.014381
Temperature	193.5206 °C
Cp	1.014268
Temperature	194.4817 °C
Cp	1.014122
Temperature	195.4428 °C
Cp	1.013984
Temperature	196.4038 °C
Cp	1.013853
Temperature	197.3649 °C
Cp	1.013726
Temperature	198.326 °C
Cp	1.013603
Temperature	199.2871 °C
Cp	1.013467
Temperature	200.2482 °C
Cp	1.013359
Temperature	201.2092 °C
Cp	1.013243
Temperature	202.1703 °C
Cp	1.013123
Temperature	203.1314 °C
Cp	1.013002
Temperature	204.0925 °C
Cp	1.012884
Temperature	205.0536 °C
Cp	1.012788
Temperature	206.0146 °C
Cp	1.012674
Temperature	206.9757 °C
Cp	1.012579
Temperature	207.9368 °C
Cp	1.012501
Temperature	208.8979 °C
Cp	1.012439
Temperature	209.859 °C
Cp	1.012389
Temperature	210.82 °C
Cp	1.012351
Temperature	211.7811 °C
Cp	1.012312
Temperature	212.7422 °C
Cp	1.01229
Temperature	213.7033 °C
Cp	1.012262
Temperature	214.6644 °C
Cp	1.012227
Temperature	215.6254 °C
Cp	1.012183
Temperature	216.5865 °C
Cp	1.012129
Temperature	217.5476 °C
Cp	1.012077
Temperature	218.5087 °C
Cp	1.01199
Temperature	219.4698 °C
Cp	1.011897
Temperature	220.4308 °C
Cp	1.011793
Temperature	221.3919 °C
Cp	1.011674
Temperature	222.353 °C
Cp	1.011537
Temperature	223.3141 °C
Cp	1.011362
Temperature	224.2752 °C
Cp	1.011194
Temperature	225.2362 °C
Cp	1.010993
Temperature	226.1973 °C
Cp	1.010766
Temperature	227.1584 °C
Cp	1.010517
Temperature	228.1195 °C
Cp	1.010251
Temperature	229.0806 °C
Cp	1.009998
Temperature	230.0416 °C
Cp	1.009703
Temperature	231.0027 °C
Cp	1.009422
Temperature	231.9638 °C
Cp	1.009156
Temperature	232.9249 °C
Cp	1.008906
Temperature	233.886 °C
Cp	1.008675
Temperature	234.847 °C
Cp	1.008462
Temperature	235.8081 °C
Cp	1.008258
Temperature	236.7692 °C
Cp	1.00809
Temperature	237.7303 °C
Cp	1.007934
Temperature	238.6914 °C
Cp	1.007793
Temperature	239.6524 °C
Cp	1.007668
Temperature	240.6135 °C
Cp	1.007562
Temperature	241.5746 °C
Cp	1.007487
Temperature	242.5357 °C
Cp	1.00741
Temperature	243.4967 °C
Cp	1.00736
Temperature	244.4578 °C
Cp	1.007332
Temperature	245.4189 °C
Cp	1.007321
Temperature	246.38 °C
Cp	1.007321
Temperature	247.3411 °C
Cp	1.007312
Temperature	248.3022 °C
Cp	1.007331
Temperature	249.2632 °C
Cp	1.007338
Temperature	250.2243 °C
Cp	1.007335
Temperature	251.1854 °C
Cp	1.00732
Temperature	252.1465 °C
Cp	1.007295
Temperature	253.1076 °C
Cp	1.007277
Temperature	254.0686 °C
Cp	1.007227
Temperature	255.0297 °C
Cp	1.007179
Temperature	255.9908 °C
Cp	1.007133
Temperature	256.9519 °C
Cp	1.00709
Temperature	257.913 °C
Cp	1.007049
Temperature	258.874 °C
Cp	1.007012
Temperature	259.8351 °C
Cp	1.006978
Temperature	260.7962 °C
Cp	1.006956
Temperature	261.7573 °C
Cp	1.00694
Temperature	262.7184 °C
Cp	1.006934
Temperature	263.6794 °C
Cp	1.006939
Temperature	264.6405 °C
Cp	1.00696
Temperature	265.6016 °C
Cp	1.006999
Temperature	266.5627 °C
Cp	1.007054
Temperature	267.5237 °C
Cp	1.007131
Temperature	268.4848 °C
Cp	1.00723
Temperature	269.4459 °C
Cp	1.00735
Temperature	270.407 °C
Cp	1.007493
Temperature	271.3681 °C
Cp	1.007656
Temperature	272.3292 °C
Cp	1.007839
Temperature	273.2902 °C
Cp	1.008039
Temperature	274.2513 °C
Cp	1.008257
Temperature	275.2124 °C
Cp	1.008488
Temperature	276.1735 °C
Cp	1.008731
Temperature	277.1346 °C
Cp	1.008977
Temperature	278.0956 °C
Cp	1.009237
Temperature	279.0567 °C
Cp	1.009498
Temperature	280.0178 °C
Cp	1.009757
Temperature	280.9789 °C
Cp	1.010014
Temperature	281.9399 °C
Cp	1.010267
Temperature	282.901 °C
Cp	1.010515
Temperature	283.8621 °C
Cp	1.01076
Temperature	284.8232 °C
Cp	1.010993
Temperature	285.7843 °C
Cp	1.011222
Temperature	286.7454 °C
Cp	1.011447
Temperature	287.7064 °C
Cp	1.011665
Temperature	288.6675 °C
Cp	1.011876
Temperature	289.6286 °C
Cp	1.012079
Temperature	290.5897 °C
Cp	1.01228
Temperature	291.5508 °C
Cp	1.012474
Temperature	292.5118 °C
Cp	1.012662
Temperature	293.4729 °C
Cp	1.012846
Temperature	294.434 °C
Cp	1.013028
Temperature	295.3951 °C
Cp	1.013211
Temperature	296.3561 °C
Cp	1.013391
Temperature	297.3172 °C
Cp	1.013574
Temperature	298.2783 °C
Cp	1.013759
Temperature	299.2394 °C
Cp	1.013947
Temperature	300.2005 °C
Cp	1.014136
Temperature	301.1616 °C
Cp	1.01432
Temperature	302.1226 °C
Cp	1.014511
Temperature	303.0837 °C
Cp	1.014695
Temperature	304.0448 °C
Cp	1.014872
Temperature	305.0059 °C
Cp	1.01504
Temperature	305.9669 °C
Cp	1.015198
Temperature	306.928 °C
Cp	1.015343
Temperature	307.8891 °C
Cp	1.015479
Temperature	308.8502 °C
Cp	1.015595
Temperature	309.8113 °C
Cp	1.015699
Temperature	310.7724 °C
Cp	1.015789
Temperature	311.7334 °C
Cp	1.015865
Temperature	312.6945 °C
Cp	1.015925
Temperature	313.6556 °C
Cp	1.015964
Temperature	314.6167 °C
Cp	1.015999
Temperature	315.5778 °C
Cp	1.016018
Temperature	316.5388 °C
Cp	1.016025
Temperature	317.4999 °C
Cp	1.016024
Temperature	318.461 °C
Cp	1.01602
Temperature	319.4221 °C
Cp	1.016029
Temperature	320.3831 °C
Cp	1.016025
Temperature	321.3442 °C
Cp	1.016037
Temperature	322.3053 °C
Cp	1.016066
Temperature	323.2664 °C
Cp	1.01611
Temperature	324.2275 °C
Cp	1.016169
Temperature	325.1886 °C
Cp	1.016225
Temperature	326.1496 °C
Cp	1.016318
Temperature	327.1107 °C
Cp	1.016411
Temperature	328.0718 °C
Cp	1.016504
Temperature	329.0329 °C
Cp	1.016596
Temperature	329.994 °C
Cp	1.016687
Temperature	330.955 °C
Cp	1.016775
Temperature	331.9161 °C
Cp	1.016864
Temperature	332.8772 °C
Cp	1.016942
Temperature	333.8383 °C
Cp	1.017019
Temperature	334.7993 °C
Cp	1.017093
Temperature	335.7604 °C
Cp	1.017163
Temperature	336.7215 °C
Cp	1.01723
Temperature	337.6826 °C
Cp	1.017295
Temperature	338.6437 °C
Cp	1.017358
Temperature	339.6048 °C
Cp	1.017423
Temperature	340.5658 °C
Cp	1.017491
Temperature	341.5269 °C
Cp	1.017567
Temperature	342.488 °C
Cp	1.017651
Temperature	343.4491 °C
Cp	1.017747
Temperature	344.4102 °C
Cp	1.017859
Temperature	345.3712 °C
Cp	1.017987
Temperature	346.3323 °C
Cp	1.018133
[...]
131.6083	111.1482	0.3763
131.6167	111.0658	0.3763
131.6250	110.9822	0.3763
131.6333	110.8983	0.3763
131.6417	110.8164	0.3762
131.6500	110.7322	0.3762
131.6583	110.6492	0.3762
131.6667	110.5679	0.3762
131.6750	110.4848	0.3761
131.6833	110.4013	0.3761
131.6917	110.3182	0.3761
131.7000	110.2341	0.3760
131.7083	110.1509	0.3760
131.7167	110.0692	0.3760
131.7250	109.9851	0.3760
131.7333	109.9016	0.3760
131.7417	109.8198	0.3760
131.7500	109.7363	0.3759
131.7583	109.6527	0.3759
131.7667	109.5701	0.3759
131.7750	109.4870	0.3759
131.7833	109.4042	0.3759
131.7917	109.3203	0.3759
131.8000	109.2367	0.3758
131.8083	109.1545	0.3758
131.8167	109.0713	0.3757
131.8250	108.9874	0.3757
131.8333	108.9043	0.3757
131.8417	108.8209	0.3757
131.8500	108.7384	0.3757
131.8583	108.6553	0.3756
131.8667	108.5718	0.3756
131.8750	108.4896	0.3756
131.8833	108.4059	0.3756
131.8917	108.3225	0.3755
131.9000	108.2384	0.3755
131.9083	108.1562	0.3755
131.9167	108.0728	0.3755
131.9250	107.9900	0.3754
131.9333	107.9060	0.3754
131.9417	107.8239	0.3754
131.9500	107.7407	0.3754
131.9583	107.6566	0.3753
131.9667	107.5744	0.3753
131.9750	107.4915	0.3753
131.9833	107.4072	0.3752
131.9917	107.3258	0.3752
132.0000	107.2418	0.3752
132.0083	107.1585	0.3751
132.0167	107.0755	0.3751
132.0250	106.9927	0.3751
132.0333	106.9085	0.3751
132.0417	106.8255	0.3751
132.0500	106.7426	0.3750
132.0583	106.6593	0.3750
132.0667	106.5759	0.3749
132.0750	106.4932	0.3749
132.0833	106.4099	0.3749
132.0917	106.3270	0.3748
132.1000	106.2429	0.3748
132.1083	106.1610	0.3748
132.1167	106.0781	0.3747
132.1250	105.9951	0.3747
132.1333	105.9117	0.3747
132.1417	105.8292	0.3746
132.1500	105.7463	0.3746
132.1583	105.6621	0.3745
132.1667	105.5784	0.3745
132.1750	105.4957	0.3745
132.1833	105.4128	0.3745
132.1917	105.3297	0.3744
132.2000	105.2462	0.3744
132.2083	105.1631	0.3744
132.2167	105.0809	0.3744
132.2250	104.9972	0.3744
132.2333	104.9143	0.3743
132.2417	104.8310	0.3743
132.2500	104.7472	0.3743
132.2583	104.6644	0.3743
132.2667	104.5807	0.3742
132.2750	104.4977	0.3742
132.2833	104.4155	0.3742
132.2917	104.3323	0.3741
132.3000	104.2496	0.3741
132.3083	104.1656	0.3741
132.3167	104.0830	0.3740
132.3250	104.0008	0.3740
132.3333	103.9168	0.3740
132.3417	103.8338	0.3740
132.3500	103.7505	0.3739
132.3583	103.6674	0.3739
132.3667	103.5844	0.3738
132.3750	103.5015	0.3738
132.3833	103.4188	0.3738
132.3917	103.3343	0.3738
132.4000	103.2528	0.3737
132.4083	103.1690	0.3737
132.4167	103.0857	0.3737
132.4250	103.0026	0.3737
132.4333	102.9196	0.3736
132.4417	102.8373	0.3736
132.4500	102.7535	0.3735
132.4583	102.6708	0.3735
132.4667	102.5874	0.3735
132.4750	102.5036	0.3735
132.4833	102.4219	0.3733
132.4917	102.3378	0.3733
132.5000	102.2539	0.3733
132.5083	102.1725	0.3732
132.5167	102.0877	0.3732
132.5250	102.0059	0.3732
132.5333	101.9218	0.3732
132.5417	101.8390	0.3732
132.5500	101.7567	0.3731
132.5583	101.6723	0.3732
132.5667	101.5900	0.3731
132.5750	101.5058	0.3731
132.5833	101.4227	0.3731
132.5917	101.3389	0.3730
132.6000	101.2544	0.3729
132.6083	101.1749	0.3724
132.6167	101.0902	0.3725
132.6250	101.0064	0.3725
132.6333	100.9249	0.3725
132.6417	100.8409	0.3725
132.6500	100.7577	0.3725
132.6583	100.6738	0.3725
132.6667	100.5918	0.3725
132.6750	100.5092	0.3725
132.6833	100.4245	0.3724
132.6917	100.3432	0.3724
132.7000	100.2595	0.3724
132.7083	100.1765	0.3724
132.7167	100.0933	0.3724
132.7250	100.0095	0.3723
132.7333	99.9266	0.3723
132.7417	99.8435	0.3723
132.7500	99.7607	0.3723
132.7583	99.6774	0.3723
132.7667	99.5949	0.3723
132.7750	99.5100	0.3723
132.7833	99.4273	0.3722
132.7917	99.3451	0.3722
132.8000	99.2620	0.3722
132.8083	99.1790	0.3721
132.8167	99.0948	0.3721
132.8250	99.0128	0.3721
132.8333	98.9284	0.3721
132.8417	98.8469	0.3721
132.8500	98.7617	0.3720
132.8583	98.6788	0.3720
132.8667	98.5962	0.3720
132.8750	98.5124	0.3720
132.8833	98.4293	0.3720
132.8917	98.3461	0.3719
132.9000	98.2642	0.3719
132.9083	98.1818	0.3719
132.9167	98.0977	0.3719
132.9250	98.0147	0.3719
132.9333	97.9317	0.3718
132.9417	97.8487	0.3718
132.9500	97.7645	0.3718
132.9583	97.6834	0.3718
132.9667	97.5991	0.3717
132.9750	97.5166	0.3717
132.9833	97.4336	0.3717
132.9917	97.3495	0.3716
133.0000	97.2673	0.3716
133.0083	97.1840	0.3716
133.0167	97.1008	0.3716
133.0250	97.0177	0.3715
133.0333	96.9344	0.3715
133.0417	96.8517	0.3715
133.0500	96.7687	0.3714
133.0583	96.6860	0.3714
133.0667	96.6015	0.3714
133.0750	96.5188	0.3713
133.0833	96.4354	0.3713
133.0917	96.3524	0.3711
133.1000	96.2700	0.3711
133.1083	96.1863	0.3711
133.1167	96.1034	0.3711
133.1250	96.0200	0.3711
133.1333	95.9370	0.3710
133.1417	95.8542	0.3710
133.1500	95.7705	0.3710
133.1583	95.6871	0.3709
133.1667	95.6045	0.3709
133.1750	95.5203	0.3709
133.1833	95.4374	0.3709
133.1917	95.3550	0.3708
133.2000	95.2715	0.3708
133.2083	95.1890	0.3708
133.2167	95.1051	0.3707
133.2250	95.0222	0.3707
133.2333	94.9389	0.3706
133.2417	94.8560	0.3706
133.2500	94.7728	0.3706
133.2583	94.6897	0.3705
133.2667	94.6064	0.3705
133.2750	94.5231	0.3705
133.2833	94.4403	0.3704
133.2917	94.3572	0.3704
133.3000	94.2741	0.3704
133.3083	94.1908	0.3704
133.3167	94.1091	0.3703
133.3250	94.0252	0.3703
133.3333	93.9426	0.3702
133.3417	93.8595	0.3701
133.3500	93.7755	0.3701
133.3583	93.6924	0.3701
133.3667	93.6093	0.3701
133.3750	93.5268	0.3700
133.3833	93.4429	0.3700
133.3917	93.3596	0.3700
133.4000	93.2771	0.3700
133.4083	93.1940	0.3699
133.4167	93.1111	0.3699
133.4250	93.0276	0.3699
133.4333	92.9443	0.3698
133.4417	92.8616	0.3698
133.4500	92.7788	0.3698
133.4583	92.6954	0.3697
133.4667	92.6116	0.3697
133.4750	92.5290	0.3697
133.4833	92.4458	0.3697
133.4917	92.3625	0.3696
133.5000	92.2784	0.3696
133.5083	92.1947	0.3696
133.5167	92.1127	0.3696
133.5250	92.0299	0.3695
133.5333	91.9466	0.3695
133.5417	91.8638	0.3695
133.5500	91.7806	0.3695
133.5583	91.6978	0.3694
133.5667	91.6139	0.3694
133.5750	91.5318	0.3693
133.5833	91.4483	0.3693
133.5917	91.3653	0.3693
133.6000	91.2825	0.3693
133.6083	91.1990	0.3691
133.6167	91.1165	0.3690
133.6250	91.0324	0.3691
133.6333	90.9489	0.3691
133.6417	90.8667	0.3690
133.6500	90.7832	0.3690
133.6583	90.7008	0.3690
133.6667	90.6168	0.3689
133.6750	90.5340	0.3689
133.6833	90.4517	0.3689
133.6917	90.3681	0.3689
133.7000	90.2853	0.3689
133.7083	90.2020	0.3689
133.7167	90.1184	0.3688
133.7250	90.0353	0.3688
133.7333	89.9528	0.3687
133.7417	89.8689	0.3687
133.7500	89.7857	0.3687
133.7583	89.7026	0.3687
133.7667	89.6200	0.3687
133.7750	89.5358	0.3687
133.7833	89.4536	0.3686
133.7917	89.3702	0.3686
133.8000	89.2859	0.3686
133.8083	89.2034	0.3686
133.8167	89.1204	0.3685
133.8250	89.0364	0.3685
133.8333	88.9533	0.3685
133.8417	88.8696	0.3684
133.8500	88.7870	0.3684
133.8583	88.7027	0.3684
133.8667	88.6208	0.3683
133.8750	88.5394	0.3682
133.8833	88.4542	0.3682
133.8917	88.3720	0.3682
133.9000	88.2881	0.3681
133.9083	88.2061	0.3679
133.9167	88.1214	0.3679
133.9250	88.0396	0.3679
133.9333	87.9564	0.3679
133.9417	87.8741	0.3679
133.9500	87.7898	0.3679
133.9583	87.7069	0.3678
133.9667	87.6238	0.3678
133.9750	87.5403	0.3678
133.9833	87.4575	0.3678
133.9917	87.3753	0.3677
134.0000	87.2919	0.3677
134.0083	87.2086	0.3677
134.0167	87.1254	0.3677
134.0250	87.0427	0.3676
134.0333	86.9586	0.3676
134.0417	86.8758	0.3676
134.0500	86.7933	0.3675
134.0583	86.7101	0.3675
134.0667	86.6267	0.3675
134.0750	86.5432	0.3675
134.0833	86.4607	0.3675
134.0917	86.3772	0.3674
134.1000	86.2940	0.3674
134.1083	86.2102	0.3674
134.1167	86.1286	0.3674
134.1250	86.0446	0.3674
134.1333	85.9618	0.3673
134.1417	85.8786	0.3673
134.1500	85.7954	0.3673
134.1583	85.7118	0.3673
134.1667	85.6296	0.3672
134.1750	85.5449	0.3672
134.1833	85.4621	0.3672
134.1917	85.3808	0.3672
134.2000	85.2959	0.3671
134.2083	85.2128	0.3671
134.2167	85.1304	0.3671
134.2250	85.0471	0.3671
134.2333	84.9641	0.3670
134.2417	84.8799	0.3670
134.2500	84.7971	0.3670
134.2583	84.7148	0.3669
134.2667	84.6311	0.3669
134.2750	84.5477	0.3669
134.2833	84.4654	0.3669
134.2917	84.3813	0.3668
134.3000	84.2983	0.3668
134.3083	84.2155	0.3668
134.3167	84.1322	0.3668
134.3250	84.0483	0.3668
134.3333	83.9664	0.3667
134.3417	83.8827	0.3667
134.3500	83.7990	0.3667
134.3583	83.7164	0.3667
134.3667	83.6339	0.3666
134.3750	83.5504	0.3666
134.3833	83.4668	0.3665
134.3917	83.3836	0.3665
134.4000	83.3009	0.3665
134.4083	83.2180	0.3665
134.4167	83.1345	0.3664
134.4250	83.0523	0.3664
134.4333	82.9683	0.3664
134.4417	82.8856	0.3663
134.4500	82.8019	0.3663
134.4583	82.7202	0.3662
134.4667	82.6373	0.3662
134.4750	82.5532	0.3662
134.4833	82.4696	0.3662
134.4917	82.3868	0.3662
134.5000	82.3034	0.3661
134.5083	82.2216	0.3661
134.5167	82.1368	0.3661
134.5250	82.0539	0.3660
134.5333	81.9715	0.3660
134.5417	81.8882	0.3659
134.5500	81.8052	0.3659
134.5583	81.7213	0.3659
134.5667	81.6397	0.3659
134.5750	81.5544	0.3658
134.5833	81.4735	0.3657
134.5917	81.3889	0.3657
134.6000	81.3048	0.3657
134.6083	81.2222	0.3657
134.6167	81.1389	0.3656
134.6250	81.0559	0.3656
134.6333	80.9725	0.3656
134.6417	80.8894	0.3656
134.6500	80.8073	0.3655
134.6583	80.7235	0.3655
134.6667	80.6401	0.3655
134.6750	80.5577	0.3654
134.6833	80.4744	0.3653
134.6917	80.3918	0.3653
134.7000	80.3085	0.3653
134.7083	80.2257	0.3652
134.7167	80.1426	0.3652
134.7250	80.0591	0.3652
134.7333	79.9758	0.3652
134.7417	79.8933	0.3651
134.7500	79.8102	0.3651
134.7583	79.7271	0.3650
134.7667	79.6427	0.3650
134.7750	79.5597	0.3650
134.7833	79.4780	0.3649
134.7917	79.3938	0.3649
134.8000	79.3094	0.3649
134.8083	79.2284	0.3649
134.8167	79.1451	0.3648
134.8250	79.0610	0.3648
134.8333	78.9780	0.3647
134.8417	78.8952	0.3647
134.8500	78.8117	0.3647
134.8583	78.7279	0.3647
134.8667	78.6457	0.3646
134.8750	78.5629	0.3646
134.8833	78.4790	0.3646
134.8917	78.3957	0.3645
134.9000	78.3134	0.3645
134.9083	78.2305	0.3644
134.9167	78.1471	0.3644
134.9250	78.0646	0.3643
134.9333	77.9818	0.3643
134.9417	77.8985	0.3643
134.9500	77.8152	0.3643
134.9583	77.7328	0.3642
134.9667	77.6491	0.3642
134.9750	77.5650	0.3642
134.9833	77.4816	0.3641
134.9917	77.3985	0.3641
135.0000	77.3161	0.3641
135.0083	77.2337	0.3639
135.0167	77.1503	0.3639
135.0250	77.0652	0.3639
135.0333	76.9838	0.3639
135.0417	76.9003	0.3639
135.0500	76.8167	0.3638
135.0583	76.7337	0.3638
135.0667	76.6492	0.3638
135.0750	76.5674	0.3637
135.0833	76.4844	0.3637
135.0917	76.4020	0.3637
135.1000	76.3183	0.3637
135.1083	76.2355	0.3636
135.1167	76.1520	0.3636
135.1250	76.0687	0.3636
135.1333	75.9849	0.3636
135.1417	75.9014	0.3635
135.1500	75.8191	0.3635
135.1583	75.7355	0.3634
135.1667	75.6529	0.3634
135.1750	75.5699	0.3633
135.1833	75.4856	0.3633
135.1917	75.4026	0.3633
135.2000	75.3204	0.3632
135.2083	75.2375	0.3632
135.2167	75.1546	0.3632
135.2250	75.0722	0.3631
135.2333	74.9884	0.3631
135.2417	74.9047	0.3631
135.2500	74.8218	0.3630
135.2583	74.7389	0.3630
135.2667	74.6547	0.3629
135.2750	74.5722	0.3629
135.2833	74.4883	0.3629
135.2917	74.4064	0.3629
135.3000	74.3216	0.3629
135.3083	74.2391	0.3628
135.3167	74.1560	0.3627
135.3250	74.0726	0.3627
135.3333	73.9918	0.3627
135.3417	73.9064	0.3626
135.3500	73.8237	0.3626
135.3583	73.7402	0.3626
135.3667	73.6562	0.3625
135.3750	73.5746	0.3624
135.3833	73.4917	0.3624
135.3917	73.4082	0.3623
135.4000	73.3256	0.3623
135.4083	73.2424	0.3622
135.4167	73.1589	0.3622
135.4250	73.0758	0.3622
135.4333	72.9927	0.3622
135.4417	72.9098	0.3621
135.4500	72.8258	0.3621
135.4583	72.7434	0.3621
135.4667	72.6595	0.3620
135.4750	72.5775	0.3620
135.4833	72.4936	0.3620
135.4917	72.4101	0.3619
135.5000	72.3275	0.3619
135.5083	72.2451	0.3619
135.5167	72.1615	0.3619
135.5250	72.0787	0.3618
135.5333	71.9945	0.3618
135.5417	71.9115	0.3618
135.5500	71.8290	0.3618
135.5583	71.7451	0.3617
135.5667	71.6624	0.3617
135.5750	71.5782	0.3616
135.5833	71.4961	0.3615
135.5917	71.4134	0.3615
135.6000	71.3307	0.3615
135.6083	71.2473	0.3614
135.6167	71.1646	0.3614
135.6250	71.0804	0.3614
135.6333	70.9983	0.3613
135.6417	70.9144	0.3613
135.6500	70.8321	0.3612
135.6583	70.7480	0.3612
135.6667	70.6652	0.3612
135.6750	70.5827	0.3611
135.6833	70.4996	0.3611
135.6917	70.4158	0.3611
135.7000	70.3327	0.3611
135.7083	70.2502	0.3610
135.7167	70.1665	0.3610
135.7250	70.0826	0.3609
135.7333	70.0004	0.3609
135.7417	69.9168	0.3609
135.7500	69.8346	0.3609
135.7583	69.7508	0.3608
135.7667	69.6666	0.3608
135.7750	69.5847	0.3608
135.7833	69.4997	0.3608
135.7917	69.4184	0.3607
135.8000	69.3344	0.3607
135.8083	69.2516	0.3607
135.8167	69.1689	0.3606
135.8250	69.0839	0.3606
135.8333	69.0028	0.3605
135.8417	68.9194	0.3605
135.8500	68.8366	0.3605
135.8583	68.7525	0.3605
135.8667	68.6698	0.3604
135.8750	68.5864	0.3604
135.8833	68.5034	0.3603
135.8917	68.4216	0.3603
135.9000	68.3372	0.3602
135.9083	68.2536	0.3602
135.9167	68.1706	0.3602
135.9250	68.0875	0.3601
135.9333	68.0048	0.3601
135.9417	67.9219	0.3601
135.9500	67.8385	0.3601
135.9583	67.7548	0.3600
135.9667	67.6737	0.3600
135.9750	67.5894	0.3599
135.9833	67.5059	0.3599
135.9917	67.4231	0.3599
136.0000	67.3404	0.3598
136.0083	67.2581	0.3598
136.0167	67.1732	0.3598
136.0250	67.0910	0.3597
136.0333	67.0088	0.3597
136.0417	66.9244	0.3597
136.0500	66.8411	0.3596
136.0583	66.7576	0.3596
136.0667	66.6740	0.3595
136.0750	66.5924	0.3595
136.0833	66.5087	0.3595
136.0917	66.4250	0.3594
136.1000	66.3425	0.3594
136.1083	66.2577	0.3594
136.1167	66.1758	0.3594
136.1250	66.0925	0.3593
136.1333	66.0091	0.3593
136.1417	65.9256	0.3592
136.1500	65.8432	0.3592
136.1583	65.7602	0.3592
136.1667	65.6772	0.3591
136.1750	65.5937	0.3591
136.1833	65.5098	0.3591
136.1917	65.4280	0.3591
136.2000	65.3448	0.3590
136.2083	65.2615	0.3590
136.2167	65.1781	0.3590
136.2250	65.0963	0.3590
136.2333	65.0121	0.3589
136.2417	64.9283	0.3590
136.2500	64.8454	0.3590
136.2583	64.7635	0.3591
136.2667	64.6802	0.3597
136.2750	64.5963	0.3599
136.2833	64.5134	0.3608
136.2917	64.4313	0.3629
136.3000	64.3490	0.3672
136.3083	64.2666	0.3703
136.3167	64.1852	0.3738
136.3250	64.1046	0.3804
136.3333	64.0234	0.3892
136.3417	63.9428	0.3992
136.3500	63.8637	0.4130
136.3583	63.7859	0.4324
136.3667	63.7103	0.4575
136.3750	63.6360	0.4891
136.3833	63.5659	0.5304
136.3917	63.5000	0.5838
136.4000	63.4397	0.6492
136.4083	63.3828	0.7288
136.4167	63.3341	0.8226
136.4250	63.2936	0.9319
136.4333	63.2594	1.0531
136.4417	63.2355	1.1836
136.4500	63.2193	1.3173
136.4583	63.2103	1.4521
136.4667	63.2077	1.5807
136.4750	63.2101	1.6995
136.4833	63.2158	1.8090
136.4917	63.2238	1.9061
136.5000	63.2303	1.9921
136.5083	63.2367	2.0679
136.5167	63.2422	2.1347
136.5250	63.2450	2.1947
136.5333	63.2429	2.2489
136.5417	63.2415	2.2983
136.5500	63.2351	2.3454
136.5583	63.2250	2.3903
136.5667	63.2129	2.4325
136.5750	63.1981	2.4740
136.5833	63.1797	2.5140
136.5917	63.1604	2.5543
136.6000	63.1389	2.5927
136.6083	63.1143	2.6315
136.6167	63.0895	2.6696
136.6250	63.0611	2.7066
136.6333	63.0318	2.7450
136.6417	63.0018	2.7825
136.6500	62.9690	2.8184
136.6583	62.9353	2.8552
136.6667	62.9019	2.8908
136.6750	62.8661	2.9259
136.6833	62.8292	2.9609
136.6917	62.7903	2.9942
136.7000	62.7520	3.0266
136.7083	62.7121	3.0590
136.7167	62.6711	3.0900
136.7250	62.6309	3.1205
136.7333	62.5869	3.1500
136.7417	62.5444	3.1781
136.7500	62.4992	3.2050
136.7583	62.4529	3.2307
136.7667	62.4062	3.2549
136.7750	62.3583	3.2780
136.7833	62.3093	3.2991
136.7917	62.2581	3.3193
136.8000	62.2073	3.3375
136.8083	62.1550	3.3551
136.8167	62.1013	3.3709
136.8250	62.0446	3.3835
136.8333	61.9893	3.3947
136.8417	61.9293	3.4057
136.8500	61.8696	3.4137
136.8583	61.8093	3.4191
136.8667	61.7459	3.4252
136.8750	61.6826	3.4290
136.8833	61.6164	3.4304
136.8917	61.5490	3.4277
136.9000	61.4788	3.4245
136.9083	61.4090	3.4185
136.9167	61.3356	3.4104
136.9250	61.2603	3.4001
136.9333	61.1827	3.3889
136.9417	61.1050	3.3751
136.9500	61.0250	3.3586
136.9583	60.9411	3.3416
136.9667	60.8573	3.3225
136.9750	60.7721	3.3022
136.9833	60.6838	3.2803
136.9917	60.5932	3.2576
137.0000	60.5026	3.2331
137.0083	60.4088	3.2070
137.0167	60.3146	3.1816
137.0250	60.2174	3.1530
137.0333	60.1189	3.1230
137.0417	60.0188	3.0920
137.0500	59.9182	3.0603
137.0583	59.8155	3.0264
137.0667	59.7102	2.9925
137.0750	59.6037	2.9584
137.0833	59.4976	2.9215
137.0917	59.3901	2.8860
137.1000	59.2802	2.8493
137.1083	59.1691	2.8111
137.1167	59.0566	2.7717
137.1250	58.9423	2.7336
137.1333	58.8293	2.6935
137.1417	58.7142	2.6538
137.1500	58.5983	2.6130
137.1583	58.4807	2.5729
137.1667	58.3635	2.5322
137.1750	58.2434	2.4915
137.1833	58.1236	2.4509
137.1917	58.0033	2.4106
137.2000	57.8826	2.3685
137.2083	57.7623	2.3278
137.2167	57.6400	2.2877
137.2250	57.5182	2.2469
137.2333	57.3961	2.2077
137.2417	57.2734	2.1687
137.2500	57.1514	2.1323
137.2583	57.0288	2.0944
137.2667	56.9056	2.0562
137.2750	56.7837	2.0194
137.2833	56.6595	1.9819
137.2917	56.5382	1.9461
137.3000	56.4146	1.9107
137.3083	56.2943	1.8768
137.3167	56.1727	1.8434
137.3250	56.0515	1.8105
137.3333	55.9299	1.7784
137.3417	55.8083	1.7466
137.3500	55.6882	1.7163
137.3583	55.5683	1.6852
137.3667	55.4499	1.6562
137.3750	55.3300	1.6280
137.3833	55.2124	1.5991
137.3917	55.0937	1.5715
137.4000	54.9770	1.5452
137.4083	54.8610	1.5193
137.4167	54.7445	1.4943
137.4250	54.6286	1.4686
137.4333	54.5156	1.4447
137.4417	54.3998	1.4208
137.4500	54.2878	1.3971
137.4583	54.1744	1.3751
137.4667	54.0621	1.3525
137.4750	53.9500	1.3314
137.4833	53.8380	1.3101
137.4917	53.7277	1.2894
137.5000	53.6175	1.2693
137.5083	53.5081	1.2504
137.5167	53.3989	1.2304
137.5250	53.2904	1.2123
137.5333	53.1828	1.1947
137.5417	53.0752	1.1768
137.5500	52.9680	1.1595
137.5583	52.8630	1.1426
137.5667	52.7572	1.1269
137.5750	52.6523	1.1100
137.5833	52.5481	1.0940
137.5917	52.4436	1.0804
137.6000	52.3413	1.0660
137.6083	52.2380	1.0509
137.6167	52.1349	1.0370
137.6250	52.0328	1.0234
137.6333	51.9304	1.0099
137.6417	51.8306	0.9977
137.6500	51.7290	0.9848
137.6583	51.6286	0.9718
137.6667	51.5284	0.9605
137.6750	51.4290	0.9491
137.6833	51.3293	0.9376
137.6917	51.2323	0.9263
137.7000	51.1313	0.9159
137.7083	51.0352	0.9048
137.7167	50.9380	0.8953
137.7250	50.8411	0.8862
137.7333	50.7430	0.8765
137.7417	50.6472	0.8669
137.7500	50.5515	0.8575
137.7583	50.4543	0.8482
137.7667	50.3580	0.8394
137.7750	50.2637	0.8308
137.7833	50.1689	0.8228
137.7917	50.0760	0.8143
137.8000	49.9815	0.8065
137.8083	49.8859	0.7992
137.8167	49.7936	0.7911
137.8250	49.6987	0.7836
137.8333	49.6061	0.7768
137.8417	49.5129	0.7698
137.8500	49.4206	0.7624
137.8583	49.3289	0.7565
137.8667	49.2361	0.7504
137.8750	49.1439	0.7433
137.8833	49.0527	0.7366
137.8917	48.9614	0.7318
137.9000	48.8691	0.7254
137.9083	48.7791	0.7190
137.9167	48.6873	0.7146
137.9250	48.5965	0.7093
137.9333	48.5050	0.7034
137.9417	48.4160	0.6985
137.9500	48.3250	0.6931
137.9583	48.2354	0.6884
137.9667	48.1447	0.6833
137.9750	48.0556	0.6793
137.9833	47.9644	0.6738
137.9917	47.8767	0.6689
138.0000	47.7873	0.6653
138.0083	47.6973	0.6608
138.0167	47.6086	0.6560
138.0250	47.5198	0.6517
138.0333	47.4306	0.6468
138.0417	47.3415	0.6430
138.0500	47.2534	0.6396
138.0583	47.1651	0.6355
138.0667	47.0765	0.6317
138.0750	46.9883	0.6277
138.0833	46.9007	0.6234
138.0917	46.8123	0.6202
138.1000	46.7244	0.6165
138.1083	46.6369	0.6135
138.1167	46.5478	0.6096
138.1250	46.4613	0.6064
138.1333	46.3742	0.6034
138.1417	46.2868	0.6001
138.1500	46.1988	0.5963
138.1583	46.1127	0.5935
138.1667	46.0243	0.5913
138.1750	45.9370	0.5873
138.1833	45.8511	0.5839
138.1917	45.7634	0.5823
138.2000	45.6761	0.5787
138.2083	45.5891	0.5755
138.2167	45.5028	0.5729
138.2250	45.4165	0.5708
138.2333	45.3298	0.5681
138.2417	45.2436	0.5647
138.2500	45.1563	0.5621
138.2583	45.0712	0.5602
138.2667	44.9836	0.5577
138.2750	44.8979	0.5551
138.2833	44.8114	0.5531
138.2917	44.7249	0.5506
138.3000	44.6398	0.5482
138.3083	44.5523	0.5452
138.3167	44.4679	0.5425
138.3250	44.3807	0.5411
138.3333	44.2956	0.5385
138.3417	44.2084	0.5365
138.3500	44.1227	0.5345
138.3583	44.0381	0.5314
138.3667	43.9519	0.5300
138.3750	43.8652	0.5275
138.3833	43.7807	0.5250
138.3917	43.6943	0.5243
138.4000	43.6080	0.5222
138.4083	43.5226	0.5193
138.4167	43.4379	0.5182
138.4250	43.3530	0.5166
138.4333	43.2663	0.5138
138.4417	43.1806	0.5125
138.4500	43.0953	0.5106
138.4583	43.0101	0.5091
138.4667	42.9249
138.4750	42.8393
138.4833	42.7537
138.4917	42.6694
138.5000	42.5851
138.5083	42.4987
138.5167