File: Example Date/My Sample/DSC/test01/DSC TA/YN041.txt
Filename	YN041
Instrument name	DSC2A-01799 (192.168.1.250)
Operator
rundate	02/12/2024
Sample name	YN041
proceduresegments	Ramp 10.00 °C/min to 150.0000 °C; Isothermal 3.0 min; Ramp 10.00 °C/min to -100.0000 °C; Isothermal 3.0 min; Ramp 10.00 °C/min to 150.0000 °C; Isothermal 3.0 min; Ramp 10.00 °C/min to -100.0000 °C; Isothermal 3.0 min; Ramp 10.00 °C/min to 150.0000 °C; Isothermal 3.0 min; Ramp 10.00 °C/min to -100.0000 °C; Isothermal 3.0 min; Ramp 10.00 °C/min to 150.0000 °C; Isothermal 3.0 min; Ramp 10.00 °C/min to 40.0000 °C
[File Parameters]
Run Date	02/12/2024 16:31:07
Trios version	5.7.0.56
Original File Name
Current File Name	C:\Users\TA Instruments DSC\Desktop\Data\Yutong Niu\2024-1126\YN041.tri
User at run start	DESKTOP-CFGN8IT\TA Instruments DSC
[Procedure]
Procedure Name	polyether
Sample Name	YN041
Sample Mass	6.42 mg
Reference Sample Mass	0 mg
Pan Mass	60.46 mg
Pan Number	35
Reference Pan Mass	60.81 mg
Reference Pan Number	45
Pan Type	Tzero Aluminum Pin Hole Hermetic
Comments
Project Name
Operator
Test	Custom
Unload Max Temperature	25
Unload Min Temperature	25
FillCooler	Do not fill
Load Max Temperature	25
Load Min Temperature	25
Discard pan in waste bin at end of test	Yes
Stop on Gas Flow Error	No
[Signal List]
Signal #1	Time (min)
Signal #2	Temperature (°C)
Signal #3	Heat Flow (mW)
Signal #4	Delta T (µV)
Signal #5	Delta Tzero (µV)
Signal #6	Tzero Temperature (°C)
Signal #7	Cell Purge (mL/min)
Signal #8	Heater Temp (°C)
Signal #9	Power Delivered (W)
Signal #10	Reference Junction Temperature (°C)
Signal #11	Flange Temperature (°C)
Signal #12	Heat Flow Phase (rad)
Signal #13	Total Heat Capacity (J/°C)
Signal #14	Heat Capacity (J/°C)
Signal #15	LN Pump Tank level (%)
[Configuration]
Company Name	Warwick University
Instrument Name	DSC2A-01799
Instrument Type	DSC2500
Serial Number	DSC2A-01799
IP	192.168.1.250
Location of Instrument	Polymer RTP
DisplayType	TianmaV2andV3
Sample Interval 	0.1 s/pt
Selected Heat Flow	T4P
Exotherm Direction	Up
Cell Serial	DRC2-03788
Lid Type	High Temperature
Cooler	LN Pump
Leave Cooler on at End of Sequence	Off
Gas 2	Air
Gas Selected	Channel 1: Nitrogen
Flow Rate	50 mL/min
Secondary Purge	On
Licensed Heat Flow	Heat Flow T4P
Modulation Licensed	Yes
[Versions]
Common IDD Version	1
Cortex Version	VER 2.11.0.729
Driver	5.0.0.6
GDM Version	1.0.3.3
TouchscreenVersion	1.0.3.1841
FEP Version	1.2.1.21
FEP Bootloader	2.0.0.5
AutoSampler Version	2.1.2.1
Auto Sampler Bootloader	2.0.0.5
FCM Version	1.1.0.3
FCM Bootloader	2.0.0.5
LN Pump Version	10.17.0.0
LN Pump Bootloader	2.0.0.5
[Experiment Logs]
Experiment Log Entry # 1	Ramp Segment 10 C/min to 150 Started
Experiment Log Entry # 3	Air Cool is off.
Experiment Log Entry # 5	Isothermal Segment 3 min started
Experiment Log Entry # 7	Ramp Segment 10 C/min to -100 Started
Experiment Log Entry # 9	Isothermal Segment 3 min started
Experiment Log Entry # 11	Ramp Segment 10 C/min to 150 Started
Experiment Log Entry # 13	Isothermal Segment 3 min started
Experiment Log Entry # 15	Ramp Segment 10 C/min to -100 Started
Experiment Log Entry # 17	FEP has detected that LNP has gone offline
Experiment Log Entry # 19	Isothermal Segment 3 min started
Experiment Log Entry # 21	Ramp Segment 10 C/min to 150 Started
Experiment Log Entry # 23	Isothermal Segment 3 min started
Experiment Log Entry # 25	Ramp Segment 10 C/min to -100 Started
Experiment Log Entry # 27	Isothermal Segment 3 min started
Experiment Log Entry # 29	Ramp Segment 10 C/min to 150 Started
Experiment Log Entry # 31	Isothermal Segment 3 min started
Experiment Log Entry # 33	Ramp Segment 10 C/min to 40 Started
[Method Log]
Method Log Entry # 1	(Ramp 2036964) Ramp 10 °C/minute to 150 °C
Method Log Entry # 2	Isothermal 3 minutes
Method Log Entry # 3	(Ramp 2036966) Ramp 10 °C/minute to -100 °C
Method Log Entry # 4	Isothermal 3 minutes
Method Log Entry # 5	(Ramp 2036968) Ramp 10 °C/minute to 150 °C
Method Log Entry # 6	Isothermal 3 minutes
Method Log Entry # 7	(Ramp 2036970) Ramp 10 °C/minute to -100 °C
Method Log Entry # 8	Isothermal 3 minutes
Method Log Entry # 9	(Ramp 2036972) Ramp 10 °C/minute to 150 °C
Method Log Entry # 10	Isothermal 3 minutes
Method Log Entry # 11	(Ramp 2036974) Ramp 10 °C/minute to -100 °C
Method Log Entry # 12	Isothermal 3 minutes
Method Log Entry # 13	(Ramp 2036976) Ramp 10 °C/minute to 150 °C
Method Log Entry # 14	Isothermal 3 minutes
Method Log Entry # 15	(Ramp 2036978) Ramp 10 °C/minute to 40 °C
Cell Serial	DRC2-03788
[T1 Calibration]
Date Applied	04/03/2021 14:58:04
Description
Gas Type	Nitrogen
Pan Type	None
Slope	-0.001800291
Offset	-0.1301359
Initial Temperature	-100.6228
GUID	a1d5a6be-decd-4ae4-b22f-d560f3a78a92
[TZero Calibration]
Date Applied	21/08/2024 09:53:38
Description	From -180.022 °C to 395.167 °C at 20.000°C/min
Gas Type	Nitrogen
Pan Type	None
Source Files 1	C:\ProgramData\TA Instruments\TRIOS\Data\TAService\PMV 20Aug2024\Tzero Cal.tri
Source Files 2	C:\ProgramData\TA Instruments\TRIOS\Data\TAService\PMV 20Aug2024\Tzero Cal sapphire.tri
Delta T Offset	1.787969
Delta T Slope	-0.003527276
Delta T0 Offset	0.06831977
Delta T0 Slope	0.02007191
[Temperature Calibration]
Date Applied	21/08/2024 11:06:35
Description	From 106.660 °C to 186.660 °C at 10.000°C/min
Gas Type	Nitrogen
Pan Type	Tzero Aluminum
Source Files 1	C:\ProgramData\TA Instruments\TRIOS\Data\TAService\PMV 20Aug2024\TA Indium cal.tri
Measured 1	157.9141
Known 1	156.66
[Cell Constant Calibration]
Date Applied	21/08/2024 11:06:35
Description	From 106.660 °C to 186.660 °C at 10.000°C/min
Gas Type	Nitrogen
Pan Type	Tzero Aluminum
Source Files 1	C:\ProgramData\TA Instruments\TRIOS\Data\TAService\PMV 20Aug2024\TA Indium cal.tri
T4P KCell	1.038055
Onset Slope	-66.72884 mW/°C
[Direct Cp Calibration]
Date Applied	19/11/2024 16:37:27
Description	From -89.996 °C to 396.697 °C at 20.000°C/min
Gas Type	Nitrogen
Pan Type	Tzero Aluminum
Source Files 1	C:\ProgramData\TA Instruments\TRIOS\Data\Sapphire Direct Heat Capacity(8).tri
GUID	544f8371-fe9b-4f4f-81ca-7980c172113e
Temperature	-89.99625 °C
Cp	1.464367
Temperature	-89.02287 °C
Cp	1.460558
Temperature	-88.04948 °C
Cp	1.456263
Temperature	-87.0761 °C
Cp	1.451626
Temperature	-86.10271 °C
Cp	1.446737
Temperature	-85.12933 °C
Cp	1.441723
Temperature	-84.15594 °C
Cp	1.436654
Temperature	-83.18256 °C
Cp	1.431684
Temperature	-82.20917 °C
Cp	1.426935
Temperature	-81.23578 °C
Cp	1.422396
Temperature	-80.2624 °C
Cp	1.418192
Temperature	-79.28901 °C
Cp	1.414363
Temperature	-78.31562 °C
Cp	1.410925
Temperature	-77.34224 °C
Cp	1.407865
Temperature	-76.36885 °C
Cp	1.405143
Temperature	-75.39546 °C
Cp	1.402789
Temperature	-74.42208 °C
Cp	1.400703
Temperature	-73.44869 °C
Cp	1.398837
Temperature	-72.4753 °C
Cp	1.397142
Temperature	-71.50192 °C
Cp	1.395565
Temperature	-70.52853 °C
Cp	1.394053
Temperature	-69.55515 °C
Cp	1.392558
Temperature	-68.58176 °C
Cp	1.391036
Temperature	-67.60838 °C
Cp	1.389483
Temperature	-66.63499 °C
Cp	1.387847
Temperature	-65.66161 °C
Cp	1.38616
Temperature	-64.68822 °C
Cp	1.384397
Temperature	-63.71483 °C
Cp	1.382535
Temperature	-62.74145 °C
Cp	1.380598
Temperature	-61.76806 °C
Cp	1.37865
Temperature	-60.79467 °C
Cp	1.376673
Temperature	-59.82129 °C
Cp	1.374677
Temperature	-58.8479 °C
Cp	1.372642
Temperature	-57.87452 °C
Cp	1.370686
Temperature	-56.90113 °C
Cp	1.368741
Temperature	-55.92775 °C
Cp	1.366786
Temperature	-54.95436 °C
Cp	1.364863
Temperature	-53.98097 °C
Cp	1.362959
Temperature	-53.00759 °C
Cp	1.361116
Temperature	-52.0342 °C
Cp	1.359247
Temperature	-51.06082 °C
Cp	1.357393
Temperature	-50.08743 °C
Cp	1.355593
Temperature	-49.11404 °C
Cp	1.353796
Temperature	-48.14066 °C
Cp	1.352008
Temperature	-47.16727 °C
Cp	1.350215
Temperature	-46.19389 °C
Cp	1.348396
Temperature	-45.2205 °C
Cp	1.346593
Temperature	-44.24712 °C
Cp	1.344755
Temperature	-43.27373 °C
Cp	1.342891
Temperature	-42.30034 °C
Cp	1.341008
Temperature	-41.32696 °C
Cp	1.339126
Temperature	-40.35357 °C
Cp	1.337236
Temperature	-39.38018 °C
Cp	1.335367
Temperature	-38.4068 °C
Cp	1.333522
Temperature	-37.43341 °C
Cp	1.331708
Temperature	-36.46003 °C
Cp	1.32991
Temperature	-35.48664 °C
Cp	1.328145
Temperature	-34.51326 °C
Cp	1.326414
Temperature	-33.53987 °C
Cp	1.32471
Temperature	-32.56648 °C
Cp	1.323012
Temperature	-31.5931 °C
Cp	1.321323
Temperature	-30.61971 °C
Cp	1.319657
Temperature	-29.64633 °C
Cp	1.317968
Temperature	-28.67294 °C
Cp	1.316286
Temperature	-27.69955 °C
Cp	1.314585
Temperature	-26.72617 °C
Cp	1.312857
Temperature	-25.75278 °C
Cp	1.31111
Temperature	-24.7794 °C
Cp	1.309333
Temperature	-23.80601 °C
Cp	1.307544
Temperature	-22.83262 °C
Cp	1.30575
Temperature	-21.85924 °C
Cp	1.303941
Temperature	-20.88585 °C
Cp	1.302132
Temperature	-19.91247 °C
Cp	1.300313
Temperature	-18.93908 °C
Cp	1.298512
Temperature	-17.96569 °C
Cp	1.296728
Temperature	-16.99231 °C
Cp	1.294939
Temperature	-16.01892 °C
Cp	1.293198
Temperature	-15.04554 °C
Cp	1.291453
Temperature	-14.07215 °C
Cp	1.289723
Temperature	-13.09876 °C
Cp	1.288007
Temperature	-12.12538 °C
Cp	1.286283
Temperature	-11.15199 °C
Cp	1.284578
Temperature	-10.17861 °C
Cp	1.282885
Temperature	-9.205221 °C
Cp	1.281173
Temperature	-8.231835 °C
Cp	1.279472
Temperature	-7.258449 °C
Cp	1.277766
Temperature	-6.285063 °C
Cp	1.276053
Temperature	-5.311677 °C
Cp	1.274341
Temperature	-4.338291 °C
Cp	1.272592
Temperature	-3.364905 °C
Cp	1.270844
Temperature	-2.391519 °C
Cp	1.269062
Temperature	-1.418133 °C
Cp	1.267264
Temperature	-0.4447474 °C
Cp	1.265435
Temperature	0.5286385 °C
Cp	1.263575
Temperature	1.502024 °C
Cp	1.261727
Temperature	2.47541 °C
Cp	1.259854
Temperature	3.448796 °C
Cp	1.257978
Temperature	4.422182 °C
Cp	1.256109
Temperature	5.395568 °C
Cp	1.254244
Temperature	6.368954 °C
Cp	1.252392
Temperature	7.34234 °C
Cp	1.250552
Temperature	8.315726 °C
Cp	1.248704
Temperature	9.289112 °C
Cp	1.246884
Temperature	10.2625 °C
Cp	1.245078
Temperature	11.23588 °C
Cp	1.243287
Temperature	12.20927 °C
Cp	1.241522
Temperature	13.18266 °C
Cp	1.239778
Temperature	14.15604 °C
Cp	1.238068
Temperature	15.12943 °C
Cp	1.236393
Temperature	16.10281 °C
Cp	1.234762
Temperature	17.0762 °C
Cp	1.233176
Temperature	18.04959 °C
Cp	1.231629
Temperature	19.02297 °C
Cp	1.230129
Temperature	19.99636 °C
Cp	1.228694
Temperature	20.96974 °C
Cp	1.22731
Temperature	21.94313 °C
Cp	1.225968
Temperature	22.91652 °C
Cp	1.224676
Temperature	23.8899 °C
Cp	1.223431
Temperature	24.86329 °C
Cp	1.222217
Temperature	25.83667 °C
Cp	1.221065
Temperature	26.81006 °C
Cp	1.219919
Temperature	27.78345 °C
Cp	1.218811
Temperature	28.75683 °C
Cp	1.21773
Temperature	29.73022 °C
Cp	1.216663
Temperature	30.7036 °C
Cp	1.2156
Temperature	31.67699 °C
Cp	1.214515
Temperature	32.65038 °C
Cp	1.213439
Temperature	33.62376 °C
Cp	1.21234
Temperature	34.59715 °C
Cp	1.211209
Temperature	35.57053 °C
Cp	1.210051
Temperature	36.54392 °C
Cp	1.208868
Temperature	37.5173 °C
Cp	1.207666
Temperature	38.49069 °C
Cp	1.206439
Temperature	39.46408 °C
Cp	1.205199
Temperature	40.43746 °C
Cp	1.203959
Temperature	41.41085 °C
Cp	1.202712
Temperature	42.38424 °C
Cp	1.20147
Temperature	43.35762 °C
Cp	1.200231
Temperature	44.33101 °C
Cp	1.199
Temperature	45.30439 °C
Cp	1.197777
Temperature	46.27778 °C
Cp	1.19657
Temperature	47.25116 °C
Cp	1.195367
Temperature	48.22455 °C
Cp	1.194179
Temperature	49.19794 °C
Cp	1.19301
Temperature	50.17132 °C
Cp	1.191849
Temperature	51.14471 °C
Cp	1.190694
Temperature	52.11809 °C
Cp	1.189555
Temperature	53.09148 °C
Cp	1.18843
Temperature	54.06487 °C
Cp	1.187311
Temperature	55.03825 °C
Cp	1.186195
Temperature	56.01164 °C
Cp	1.185095
Temperature	56.98502 °C
Cp	1.183997
Temperature	57.95841 °C
Cp	1.182894
Temperature	58.93179 °C
Cp	1.181793
Temperature	59.90518 °C
Cp	1.180693
Temperature	60.87857 °C
Cp	1.179595
Temperature	61.85195 °C
Cp	1.178501
Temperature	62.82534 °C
Cp	1.177406
Temperature	63.79873 °C
Cp	1.176313
Temperature	64.77211 °C
Cp	1.175239
Temperature	65.7455 °C
Cp	1.17417
Temperature	66.71888 °C
Cp	1.173105
Temperature	67.69227 °C
Cp	1.172037
Temperature	68.66566 °C
Cp	1.170989
Temperature	69.63904 °C
Cp	1.169948
Temperature	70.61243 °C
Cp	1.168905
Temperature	71.58582 °C
Cp	1.167872
Temperature	72.5592 °C
Cp	1.166849
Temperature	73.53259 °C
Cp	1.165851
Temperature	74.50597 °C
Cp	1.164848
Temperature	75.47935 °C
Cp	1.163876
Temperature	76.45274 °C
Cp	1.162926
Temperature	77.42612 °C
Cp	1.162008
Temperature	78.39951 °C
Cp	1.161113
Temperature	79.3729 °C
Cp	1.160219
Temperature	80.34628 °C
Cp	1.159377
Temperature	81.31967 °C
Cp	1.158546
Temperature	82.29306 °C
Cp	1.157726
Temperature	83.26644 °C
Cp	1.15692
Temperature	84.23983 °C
Cp	1.156126
Temperature	85.21322 °C
Cp	1.155375
Temperature	86.1866 °C
Cp	1.154604
Temperature	87.15999 °C
Cp	1.153869
Temperature	88.13337 °C
Cp	1.153158
Temperature	89.10676 °C
Cp	1.152474
Temperature	90.08015 °C
Cp	1.15181
Temperature	91.05353 °C
Cp	1.151134
Temperature	92.02692 °C
Cp	1.150513
Temperature	93.00031 °C
Cp	1.149892
Temperature	93.97369 °C
Cp	1.149266
Temperature	94.94707 °C
Cp	1.148642
Temperature	95.92046 °C
Cp	1.148019
Temperature	96.89384 °C
Cp	1.147402
Temperature	97.86723 °C
Cp	1.146799
Temperature	98.84062 °C
Cp	1.146191
Temperature	99.814 °C
Cp	1.145602
Temperature	100.7874 °C
Cp	1.14503
Temperature	101.7608 °C
Cp	1.144469
Temperature	102.7342 °C
Cp	1.143921
Temperature	103.7076 °C
Cp	1.143383
Temperature	104.6809 °C
Cp	1.142861
Temperature	105.6543 °C
Cp	1.142345
Temperature	106.6277 °C
Cp	1.141835
Temperature	107.6011 °C
Cp	1.141335
Temperature	108.5745 °C
Cp	1.140846
Temperature	109.5479 °C
Cp	1.140365
Temperature	110.5212 °C
Cp	1.139891
Temperature	111.4946 °C
Cp	1.139429
Temperature	112.468 °C
Cp	1.138976
Temperature	113.4414 °C
Cp	1.13853
Temperature	114.4148 °C
Cp	1.138092
Temperature	115.3882 °C
Cp	1.137654
Temperature	116.3616 °C
Cp	1.137223
Temperature	117.335 °C
Cp	1.136785
Temperature	118.3083 °C
Cp	1.136338
Temperature	119.2817 °C
Cp	1.13588
Temperature	120.2551 °C
Cp	1.13541
Temperature	121.2285 °C
Cp	1.134927
Temperature	122.2019 °C
Cp	1.134417
Temperature	123.1753 °C
Cp	1.133892
Temperature	124.1487 °C
Cp	1.133347
Temperature	125.122 °C
Cp	1.132786
Temperature	126.0954 °C
Cp	1.132206
Temperature	127.0688 °C
Cp	1.131606
Temperature	128.0422 °C
Cp	1.130999
Temperature	129.0156 °C
Cp	1.130384
Temperature	129.989 °C
Cp	1.129765
Temperature	130.9624 °C
Cp	1.129147
Temperature	131.9357 °C
Cp	1.12854
Temperature	132.9091 °C
Cp	1.127949
Temperature	133.8825 °C
Cp	1.127383
Temperature	134.8559 °C
Cp	1.126841
Temperature	135.8293 °C
Cp	1.126334
Temperature	136.8027 °C
Cp	1.125871
Temperature	137.7761 °C
Cp	1.125443
Temperature	138.7494 °C
Cp	1.125058
Temperature	139.7228 °C
Cp	1.124701
Temperature	140.6962 °C
Cp	1.124397
Temperature	141.6696 °C
Cp	1.124114
Temperature	142.643 °C
Cp	1.123854
Temperature	143.6164 °C
Cp	1.123612
Temperature	144.5898 °C
Cp	1.123385
Temperature	145.5631 °C
Cp	1.123182
Temperature	146.5365 °C
Cp	1.12296
Temperature	147.5099 °C
Cp	1.12275
Temperature	148.4833 °C
Cp	1.122543
Temperature	149.4567 °C
Cp	1.122327
Temperature	150.4301 °C
Cp	1.122099
Temperature	151.4035 °C
Cp	1.121837
Temperature	152.3768 °C
Cp	1.121582
Temperature	153.3502 °C
Cp	1.121289
Temperature	154.3236 °C
Cp	1.120967
Temperature	155.297 °C
Cp	1.120616
Temperature	156.2704 °C
Cp	1.120238
Temperature	157.2438 °C
Cp	1.119862
Temperature	158.2172 °C
Cp	1.119444
Temperature	159.1906 °C
Cp	1.119028
Temperature	160.1639 °C
Cp	1.118613
Temperature	161.1373 °C
Cp	1.118202
Temperature	162.1107 °C
Cp	1.117795
Temperature	163.0841 °C
Cp	1.117374
Temperature	164.0575 °C
Cp	1.116987
Temperature	165.0309 °C
Cp	1.116595
Temperature	166.0042 °C
Cp	1.116198
Temperature	166.9776 °C
Cp	1.1158
Temperature	167.951 °C
Cp	1.115402
Temperature	168.9244 °C
Cp	1.115006
Temperature	169.8978 °C
Cp	1.11462
Temperature	170.8712 °C
Cp	1.114223
Temperature	171.8446 °C
Cp	1.113836
Temperature	172.8179 °C
Cp	1.113458
Temperature	173.7913 °C
Cp	1.113085
Temperature	174.7647 °C
Cp	1.112712
Temperature	175.7381 °C
Cp	1.112323
Temperature	176.7115 °C
Cp	1.111957
Temperature	177.6849 °C
Cp	1.111578
Temperature	178.6583 °C
Cp	1.111185
Temperature	179.6317 °C
Cp	1.110789
Temperature	180.605 °C
Cp	1.110391
Temperature	181.5784 °C
Cp	1.110016
Temperature	182.5518 °C
Cp	1.109611
Temperature	183.5252 °C
Cp	1.109232
Temperature	184.4986 °C
Cp	1.108873
Temperature	185.472 °C
Cp	1.108531
Temperature	186.4454 °C
Cp	1.108199
Temperature	187.4187 °C
Cp	1.107851
Temperature	188.3921 °C
Cp	1.107551
Temperature	189.3655 °C
Cp	1.107238
Temperature	190.3389 °C
Cp	1.106917
Temperature	191.3123 °C
Cp	1.106589
Temperature	192.2857 °C
Cp	1.106259
Temperature	193.259 °C
Cp	1.105958
Temperature	194.2324 °C
Cp	1.105619
Temperature	195.2058 °C
Cp	1.105301
Temperature	196.1792 °C
Cp	1.105002
Temperature	197.1526 °C
Cp	1.104718
Temperature	198.126 °C
Cp	1.104445
Temperature	199.0994 °C
Cp	1.104161
Temperature	200.0728 °C
Cp	1.103914
Temperature	201.0461 °C
Cp	1.103657
Temperature	202.0195 °C
Cp	1.103395
Temperature	202.9929 °C
Cp	1.103125
Temperature	203.9663 °C
Cp	1.102847
Temperature	204.9397 °C
Cp	1.102563
Temperature	205.9131 °C
Cp	1.102283
Temperature	206.8865 °C
Cp	1.101985
Temperature	207.8598 °C
Cp	1.10169
Temperature	208.8332 °C
Cp	1.101394
Temperature	209.8066 °C
Cp	1.101099
Temperature	210.78 °C
Cp	1.1008
Temperature	211.7534 °C
Cp	1.10049
Temperature	212.7268 °C
Cp	1.100193
Temperature	213.7002 °C
Cp	1.099886
Temperature	214.6735 °C
Cp	1.099577
Temperature	215.6469 °C
Cp	1.099268
Temperature	216.6203 °C
Cp	1.098965
Temperature	217.5937 °C
Cp	1.098685
Temperature	218.5671 °C
Cp	1.098396
Temperature	219.5405 °C
Cp	1.098134
Temperature	220.5139 °C
Cp	1.097895
Temperature	221.4872 °C
Cp	1.09768
Temperature	222.4606 °C
Cp	1.097485
Temperature	223.434 °C
Cp	1.097292
Temperature	224.4074 °C
Cp	1.09714
Temperature	225.3808 °C
Cp	1.096991
Temperature	226.3542 °C
Cp	1.096844
Temperature	227.3276 °C
Cp	1.096699
Temperature	228.3009 °C
Cp	1.096559
Temperature	229.2743 °C
Cp	1.096442
Temperature	230.2477 °C
Cp	1.096296
Temperature	231.2211 °C
Cp	1.096164
Temperature	232.1945 °C
Cp	1.09604
Temperature	233.1679 °C
Cp	1.095924
Temperature	234.1413 °C
Cp	1.095807
Temperature	235.1147 °C
Cp	1.095665
Temperature	236.088 °C
Cp	1.095557
Temperature	237.0614 °C
Cp	1.095433
Temperature	238.0348 °C
Cp	1.095296
Temperature	239.0082 °C
Cp	1.095147
Temperature	239.9816 °C
Cp	1.094995
Temperature	240.955 °C
Cp	1.094843
Temperature	241.9283 °C
Cp	1.094705
Temperature	242.9017 °C
Cp	1.094562
Temperature	243.8751 °C
Cp	1.094442
Temperature	244.8485 °C
Cp	1.094344
Temperature	245.8219 °C
Cp	1.094266
Temperature	246.7953 °C
Cp	1.094209
Temperature	247.7687 °C
Cp	1.094161
Temperature	248.7421 °C
Cp	1.094144
Temperature	249.7154 °C
Cp	1.094133
Temperature	250.6888 °C
Cp	1.094127
Temperature	251.6622 °C
Cp	1.094126
Temperature	252.6356 °C
Cp	1.094127
Temperature	253.609 °C
Cp	1.094138
Temperature	254.5824 °C
Cp	1.09413
Temperature	255.5558 °C
Cp	1.094123
Temperature	256.5291 °C
Cp	1.094111
Temperature	257.5025 °C
Cp	1.094087
Temperature	258.4759 °C
Cp	1.094046
Temperature	259.4493 °C
Cp	1.093978
Temperature	260.4227 °C
Cp	1.093895
Temperature	261.3961 °C
Cp	1.093783
Temperature	262.3694 °C
Cp	1.093645
Temperature	263.3428 °C
Cp	1.093483
Temperature	264.3162 °C
Cp	1.093302
Temperature	265.2896 °C
Cp	1.093109
Temperature	266.263 °C
Cp	1.092906
Temperature	267.2364 °C
Cp	1.092704
Temperature	268.2098 °C
Cp	1.092511
Temperature	269.1832 °C
Cp	1.092331
Temperature	270.1566 °C
Cp	1.092174
Temperature	271.1299 °C
Cp	1.092046
Temperature	272.1033 °C
Cp	1.091947
Temperature	273.0767 °C
Cp	1.091882
Temperature	274.0501 °C
Cp	1.091853
Temperature	275.0235 °C
Cp	1.091859
Temperature	275.9969 °C
Cp	1.091895
Temperature	276.9702 °C
Cp	1.091957
Temperature	277.9436 °C
Cp	1.092036
Temperature	278.917 °C
Cp	1.092132
Temperature	279.8904 °C
Cp	1.09223
Temperature	280.8638 °C
Cp	1.092323
Temperature	281.8372 °C
Cp	1.092405
Temperature	282.8105 °C
Cp	1.092468
Temperature	283.7839 °C
Cp	1.092513
Temperature	284.7573 °C
Cp	1.092525
Temperature	285.7307 °C
Cp	1.092512
Temperature	286.7041 °C
Cp	1.092472
Temperature	287.6775 °C
Cp	1.092405
Temperature	288.6509 °C
Cp	1.092313
Temperature	289.6243 °C
Cp	1.092197
Temperature	290.5977 °C
Cp	1.09207
Temperature	291.571 °C
Cp	1.091931
Temperature	292.5444 °C
Cp	1.091785
Temperature	293.5178 °C
Cp	1.091641
Temperature	294.4912 °C
Cp	1.091506
Temperature	295.4646 °C
Cp	1.091387
Temperature	296.438 °C
Cp	1.091282
Temperature	297.4113 °C
Cp	1.091201
Temperature	298.3847 °C
Cp	1.091145
Temperature	299.3581 °C
Cp	1.091112
Temperature	300.3315 °C
Cp	1.091102
Temperature	301.3049 °C
Cp	1.091107
Temperature	302.2783 °C
Cp	1.091137
Temperature	303.2517 °C
Cp	1.091177
Temperature	304.2251 °C
Cp	1.091226
Temperature	305.1984 °C
Cp	1.09128
Temperature	306.1718 °C
Cp	1.091336
Temperature	307.1452 °C
Cp	1.091403
Temperature	308.1186 °C
Cp	1.091453
Temperature	309.092 °C
Cp	1.091506
Temperature	310.0654 °C
Cp	1.091561
Temperature	311.0388 °C
Cp	1.091617
Temperature	312.0121 °C
Cp	1.09167
Temperature	312.9855 °C
Cp	1.091716
Temperature	313.9589 °C
Cp	1.091762
Temperature	314.9323 °C
Cp	1.091805
Temperature	315.9057 °C
Cp	1.091838
Temperature	316.8791 °C
Cp	1.09186
Temperature	317.8524 °C
Cp	1.091871
Temperature	318.8258 °C
Cp	1.091872
Temperature	319.7992 °C
Cp	1.091867
Temperature	320.7726 °C
Cp	1.091838
Temperature	321.746 °C
Cp	1.0918
Temperature	322.7194 °C
Cp	1.091752
Temperature	323.6928 °C
Cp	1.091689
Temperature	324.6662 °C
Cp	1.091611
Temperature	325.6396 °C
Cp	1.091508
Temperature	326.6129 °C
Cp	1.091406
Temperature	327.5863 °C
Cp	1.091285
Temperature	328.5597 °C
Cp	1.09115
Temperature	329.5331 °C
Cp	1.091009
Temperature	330.5065 °C
Cp	1.09087
Temperature	331.4799 °C
Cp	1.090747
Temperature	332.4532 °C
Cp	1.090628
Temperature	333.4266 °C
Cp	1.090536
Temperature	334.4 °C
Cp	1.090472
Temperature	335.3734 °C
Cp	1.090437
Temperature	336.3468 °C
Cp	1.090431
Temperature	337.3202 °C
Cp	1.090455
Temperature	338.2935 °C
Cp	1.090503
Temperature	339.2669 °C
Cp	1.090573
Temperature	340.2403 °C
Cp	1.090658
Temperature	341.2137 °C
Cp	1.090753
Temperature	342.1871 °C
Cp	1.090853
Temperature	343.1605 °C
Cp	1.090952
Temperature	344.1339 °C
Cp	1.09105
Temperature	345.1073 °C
Cp	1.091141
Temperature	346.0807 °C
Cp	1.091225
Temperature	347.054 °C
Cp	1.091303
Temperature	348.0274 °C
Cp	1.091379
Temperature	349.0008 °C
Cp	1.091453
Temperature	349.9742 °C
Cp	1.091537
Temperature	350.9476 °C
Cp	1.091633
Temperature	351.921 °C
Cp	1.091743
Temperature	352.8943 °C
Cp	1.091874
Temperature	353.8677 °C
Cp	1.092028
Temperature	354.8411 °C
Cp	1.092206
Temperature	355.8145 °C
Cp	1.092411
Temperature	356.7879 °C
Cp	1.092628
Temperature	357.7613 °C
Cp	1.092862
Temperature	358.7346 °C
Cp	1.093102
Temperature	359.708 °C
Cp	1.093338
Temperature	360.6814 °C
Cp	1.093559
Temperature	361.6548 °C
Cp	1.093752
Temperature	362.6282 °C
Cp	1.093915
Temperature	363.6016 °C
Cp	1.094036
Temperature	364.575 °C
Cp	1.094117
Temperature	365.5484 °C
Cp	1.094159
Temperature	366.5218 °C
Cp	1.094172
Temperature	367.4951 °C
Cp	1.094165
Temperature	368.4685 °C
Cp	1.094163
Temperature	369.4419 °C
Cp	1.094182
Temperature	370.4153 °C
Cp	1.094244
Temperature	371.3887 °C
Cp	1.094375
Temperature	372.3621 °C
Cp	1.094598
Temperature	373.3354 °C
Cp	1.094937
Temperature	374.3088 °C
Cp	1.095389
Temperature	375.2822 °C
Cp	1.095973
Temperature	376.2556 °C
Cp	1.096685
Temperature	377.229 °C
Cp	1.097506
Temperature	378.2024 °C
Cp	1.098406
Temperature	379.1758 °C
Cp	1.099338
Temperature	380.1492 °C
Cp	1.10027
Temperature	381.1225 °C
Cp	1.10112
Temperature	382.0959 °C
Cp	1.101818
Temperature	383.0693 °C
Cp	1.10229
Temperature	384.0427 °C
Cp	1.102459
Temperature	385.0161 °C
Cp	1.102253
Temperature	385.9895 °C
Cp	1.101596
Temperature	386.9629 °C
Cp	1.100438
Temperature	387.9362 °C
Cp	1.098736
Temperature	388.9096 °C
Cp	1.096461
Temperature	389.883 °C
Cp	1.093614
Temperature	390.8564 °C
Cp	1.090208
Temperature	391.8298 °C
Cp	1.086278
Temperature	392.8032 °C
Cp	1.081887
Temperature	393.7766 °C
Cp	1.077096
Temperature	394.7499 °C
Cp	1.072007
Temperature	395.7233 °C
Cp	1.066707
[Rev Cp Calibration]
Date Applied	24/10/2024 12:37:31
Description	From -89.998 °C to 390.542 °C at 2.000°C/min
Gas Type	Nitrogen
Pan Type	Tzero Aluminum
Source Files 1	C:\ProgramData\TA Instruments\TRIOS\Data\Reverse Heat Capacity Calibration(6).tri
GUID	ba867d72-cfbb-486e-971e-e86aa544cc02
Temperature	-89.99799 °C
Cp	1.070076
Temperature	-89.03691 °C
Cp	1.072008
Temperature	-88.07584 °C
Cp	1.073556
Temperature	-87.11475 °C
Cp	1.074743
Temperature	-86.15367 °C
Cp	1.075597
Temperature	-85.1926 °C
Cp	1.076163
Temperature	-84.23151 °C
Cp	1.076477
Temperature	-83.27043 °C
Cp	1.076579
Temperature	-82.30936 °C
Cp	1.076527
Temperature	-81.34827 °C
Cp	1.076322
Temperature	-80.38719 °C
Cp	1.076039
Temperature	-79.42612 °C
Cp	1.07571
Temperature	-78.46503 °C
Cp	1.075361
Temperature	-77.50395 °C
Cp	1.075011
Temperature	-76.54288 °C
Cp	1.074656
Temperature	-75.58179 °C
Cp	1.074359
Temperature	-74.62071 °C
Cp	1.074086
Temperature	-73.65964 °C
Cp	1.073842
Temperature	-72.69855 °C
Cp	1.073627
Temperature	-71.73747 °C
Cp	1.073442
Temperature	-70.7764 °C
Cp	1.07329
Temperature	-69.81532 °C
Cp	1.073148
Temperature	-68.85423 °C
Cp	1.073021
Temperature	-67.89315 °C
Cp	1.072902
Temperature	-66.93208 °C
Cp	1.072782
Temperature	-65.97099 °C
Cp	1.072656
Temperature	-65.00991 °C
Cp	1.072518
Temperature	-64.04884 °C
Cp	1.072374
Temperature	-63.08775 °C
Cp	1.072201
Temperature	-62.12667 °C
Cp	1.072019
Temperature	-61.1656 °C
Cp	1.071827
Temperature	-60.20451 °C
Cp	1.071624
Temperature	-59.24343 °C
Cp	1.071411
Temperature	-58.28236 °C
Cp	1.071167
Temperature	-57.32127 °C
Cp	1.070956
Temperature	-56.3602 °C
Cp	1.070724
Temperature	-55.39911 °C
Cp	1.070483
Temperature	-54.43803 °C
Cp	1.070242
Temperature	-53.47696 °C
Cp	1.070009
Temperature	-52.51587 °C
Cp	1.069825
Temperature	-51.55479 °C
Cp	1.069601
Temperature	-50.59372 °C
Cp	1.069418
Temperature	-49.63263 °C
Cp	1.069267
Temperature	-48.67155 °C
Cp	1.069138
Temperature	-47.71048 °C
Cp	1.069021
Temperature	-46.74939 °C
Cp	1.068875
Temperature	-45.78831 °C
Cp	1.068771
Temperature	-44.82724 °C
Cp	1.068634
Temperature	-43.86615 °C
Cp	1.068462
Temperature	-42.90508 °C
Cp	1.068255
Temperature	-41.944 °C
Cp	1.068012
Temperature	-40.98291 °C
Cp	1.067742
Temperature	-40.02184 °C
Cp	1.067427
Temperature	-39.06076 °C
Cp	1.067088
Temperature	-38.09967 °C
Cp	1.066727
Temperature	-37.1386 °C
Cp	1.066349
Temperature	-36.17752 °C
Cp	1.065958
Temperature	-35.21643 °C
Cp	1.065559
Temperature	-34.25536 °C
Cp	1.065162
Temperature	-33.29427 °C
Cp	1.06476
Temperature	-32.33319 °C
Cp	1.064368
Temperature	-31.37212 °C
Cp	1.06399
Temperature	-30.41104 °C
Cp	1.063628
Temperature	-29.44995 °C
Cp	1.063283
Temperature	-28.48887 °C
Cp	1.06295
Temperature	-27.5278 °C
Cp	1.062645
Temperature	-26.56672 °C
Cp	1.062355
Temperature	-25.60563 °C
Cp	1.06208
Temperature	-24.64456 °C
Cp	1.061819
Temperature	-23.68348 °C
Cp	1.061573
Temperature	-22.72239 °C
Cp	1.061345
Temperature	-21.76132 °C
Cp	1.061123
Temperature	-20.80024 °C
Cp	1.060915
Temperature	-19.83916 °C
Cp	1.060719
Temperature	-18.87807 °C
Cp	1.060531
Temperature	-17.917 °C
Cp	1.06035
Temperature	-16.95592 °C
Cp	1.060161
Temperature	-15.99484 °C
Cp	1.059992
Temperature	-15.03376 °C
Cp	1.059817
Temperature	-14.07268 °C
Cp	1.059634
Temperature	-13.1116 °C
Cp	1.059445
Temperature	-12.15052 °C
Cp	1.059248
Temperature	-11.18944 °C
Cp	1.059043
Temperature	-10.22836 °C
Cp	1.058842
Temperature	-9.267276 °C
Cp	1.058615
Temperature	-8.306196 °C
Cp	1.058388
Temperature	-7.345116 °C
Cp	1.058155
Temperature	-6.384036 °C
Cp	1.057911
Temperature	-5.422956 °C
Cp	1.057652
Temperature	-4.461876 °C
Cp	1.057356
Temperature	-3.500796 °C
Cp	1.057063
Temperature	-2.539716 °C
Cp	1.056732
Temperature	-1.578636 °C
Cp	1.056364
Temperature	-0.6175562 °C
Cp	1.05596
Temperature	0.3435238 °C
Cp	1.055523
Temperature	1.304604 °C
Cp	1.055066
Temperature	2.265684 °C
Cp	1.054561
Temperature	3.226764 °C
Cp	1.054035
Temperature	4.187844 °C
Cp	1.053488
Temperature	5.148924 °C
Cp	1.052922
Temperature	6.110003 °C
Cp	1.052337
Temperature	7.071084 °C
Cp	1.051736
Temperature	8.032164 °C
Cp	1.051118
Temperature	8.993243 °C
Cp	1.050488
Temperature	9.954324 °C
Cp	1.049848
Temperature	10.9154 °C
Cp	1.049202
Temperature	11.87648 °C
Cp	1.048552
Temperature	12.83756 °C
Cp	1.047902
Temperature	13.79864 °C
Cp	1.047255
Temperature	14.75972 °C
Cp	1.046615
Temperature	15.7208 °C
Cp	1.045983
Temperature	16.68188 °C
Cp	1.045362
Temperature	17.64296 °C
Cp	1.044756
Temperature	18.60404 °C
Cp	1.044164
Temperature	19.56512 °C
Cp	1.04358
Temperature	20.5262 °C
Cp	1.043027
Temperature	21.48728 °C
Cp	1.042485
Temperature	22.44836 °C
Cp	1.041958
Temperature	23.40944 °C
Cp	1.041446
Temperature	24.37052 °C
Cp	1.040952
Temperature	25.3316 °C
Cp	1.040493
Temperature	26.29268 °C
Cp	1.040022
Temperature	27.25376 °C
Cp	1.039578
Temperature	28.21484 °C
Cp	1.039158
Temperature	29.17592 °C
Cp	1.038758
Temperature	30.137 °C
Cp	1.038373
Temperature	31.09808 °C
Cp	1.037981
Temperature	32.05916 °C
Cp	1.03763
Temperature	33.02024 °C
Cp	1.037276
Temperature	33.98132 °C
Cp	1.03692
Temperature	34.9424 °C
Cp	1.036565
Temperature	35.90348 °C
Cp	1.036213
Temperature	36.86456 °C
Cp	1.035866
Temperature	37.82564 °C
Cp	1.035529
Temperature	38.78672 °C
Cp	1.035195
Temperature	39.7478 °C
Cp	1.034875
Temperature	40.70888 °C
Cp	1.034568
Temperature	41.66996 °C
Cp	1.034276
Temperature	42.63104 °C
Cp	1.033996
Temperature	43.59212 °C
Cp	1.033726
Temperature	44.5532 °C
Cp	1.033469
Temperature	45.51428 °C
Cp	1.033221
Temperature	46.47536 °C
Cp	1.03298
Temperature	47.43644 °C
Cp	1.032744
Temperature	48.39752 °C
Cp	1.032514
Temperature	49.3586 °C
Cp	1.032289
Temperature	50.31968 °C
Cp	1.032065
Temperature	51.28076 °C
Cp	1.031844
Temperature	52.24184 °C
Cp	1.031627
Temperature	53.20292 °C
Cp	1.031413
Temperature	54.164 °C
Cp	1.031203
Temperature	55.12508 °C
Cp	1.030989
Temperature	56.08616 °C
Cp	1.030791
Temperature	57.04724 °C
Cp	1.030595
Temperature	58.00832 °C
Cp	1.030403
Temperature	58.9694 °C
Cp	1.030217
Temperature	59.93048 °C
Cp	1.03004
Temperature	60.89156 °C
Cp	1.029871
Temperature	61.85264 °C
Cp	1.029718
Temperature	62.81372 °C
Cp	1.029567
Temperature	63.7748 °C
Cp	1.02943
Temperature	64.73589 °C
Cp	1.029304
Temperature	65.69696 °C
Cp	1.029185
Temperature	66.65804 °C
Cp	1.02907
Temperature	67.61913 °C
Cp	1.028946
Temperature	68.5802 °C
Cp	1.028831
Temperature	69.54128 °C
Cp	1.028703
Temperature	70.50237 °C
Cp	1.028561
Temperature	71.46344 °C
Cp	1.028404
Temperature	72.42452 °C
Cp	1.028234
Temperature	73.3856 °C
Cp	1.028063
Temperature	74.34668 °C
Cp	1.027861
Temperature	75.30776 °C
Cp	1.027657
Temperature	76.26884 °C
Cp	1.027451
Temperature	77.22992 °C
Cp	1.027243
Temperature	78.191 °C
Cp	1.027036
Temperature	79.15208 °C
Cp	1.026812
Temperature	80.11316 °C
Cp	1.026623
Temperature	81.07424 °C
Cp	1.026431
Temperature	82.03532 °C
Cp	1.026241
Temperature	82.9964 °C
Cp	1.02606
Temperature	83.95748 °C
Cp	1.025891
Temperature	84.91856 °C
Cp	1.025739
Temperature	85.87964 °C
Cp	1.025614
Temperature	86.84072 °C
Cp	1.025493
Temperature	87.8018 °C
Cp	1.0254
Temperature	88.76288 °C
Cp	1.025329
Temperature	89.72396 °C
Cp	1.025274
Temperature	90.68504 °C
Cp	1.025229
Temperature	91.64612 °C
Cp	1.025174
Temperature	92.6072 °C
Cp	1.025138
Temperature	93.56828 °C
Cp	1.025083
Temperature	94.52936 °C
Cp	1.025008
Temperature	95.49044 °C
Cp	1.024912
Temperature	96.45152 °C
Cp	1.024796
Temperature	97.4126 °C
Cp	1.024671
Temperature	98.37368 °C
Cp	1.024506
Temperature	99.33476 °C
Cp	1.02433
Temperature	100.2958 °C
Cp	1.024144
Temperature	101.2569 °C
Cp	1.023948
Temperature	102.218 °C
Cp	1.023743
Temperature	103.1791 °C
Cp	1.023522
Temperature	104.1402 °C
Cp	1.023309
Temperature	105.1012 °C
Cp	1.023089
Temperature	106.0623 °C
Cp	1.022866
Temperature	107.0234 °C
Cp	1.022644
Temperature	107.9845 °C
Cp	1.022427
Temperature	108.9456 °C
Cp	1.022218
Temperature	109.9066 °C
Cp	1.022022
Temperature	110.8677 °C
Cp	1.021836
Temperature	111.8288 °C
Cp	1.021666
Temperature	112.7899 °C
Cp	1.021512
Temperature	113.751 °C
Cp	1.021374
Temperature	114.712 °C
Cp	1.02125
Temperature	115.6731 °C
Cp	1.021137
Temperature	116.6342 °C
Cp	1.021041
Temperature	117.5953 °C
Cp	1.020953
Temperature	118.5564 °C
Cp	1.020872
Temperature	119.5174 °C
Cp	1.020796
Temperature	120.4785 °C
Cp	1.020725
Temperature	121.4396 °C
Cp	1.020659
Temperature	122.4007 °C
Cp	1.020587
Temperature	123.3618 °C
Cp	1.020515
Temperature	124.3228 °C
Cp	1.02044
Temperature	125.2839 °C
Cp	1.020359
Temperature	126.245 °C
Cp	1.02027
Temperature	127.2061 °C
Cp	1.020167
Temperature	128.1672 °C
Cp	1.020057
Temperature	129.1282 °C
Cp	1.019933
Temperature	130.0893 °C
Cp	1.019793
Temperature	131.0504 °C
Cp	1.019638
Temperature	132.0115 °C
Cp	1.019471
Temperature	132.9726 °C
Cp	1.019292
Temperature	133.9336 °C
Cp	1.019107
Temperature	134.8947 °C
Cp	1.018912
Temperature	135.8558 °C
Cp	1.018717
Temperature	136.8169 °C
Cp	1.018527
Temperature	137.778 °C
Cp	1.018344
Temperature	138.739 °C
Cp	1.018171
Temperature	139.7001 °C
Cp	1.018004
Temperature	140.6612 °C
Cp	1.01787
Temperature	141.6223 °C
Cp	1.01775
Temperature	142.5834 °C
Cp	1.017652
Temperature	143.5444 °C
Cp	1.017578
Temperature	144.5055 °C
Cp	1.017534
Temperature	145.4666 °C
Cp	1.017536
Temperature	146.4277 °C
Cp	1.017545
Temperature	147.3888 °C
Cp	1.017595
Temperature	148.3498 °C
Cp	1.017679
Temperature	149.3109 °C
Cp	1.01779
Temperature	150.272 °C
Cp	1.01792
Temperature	151.2331 °C
Cp	1.018043
Temperature	152.1942 °C
Cp	1.018199
Temperature	153.1552 °C
Cp	1.018339
Temperature	154.1163 °C
Cp	1.018458
Temperature	155.0774 °C
Cp	1.018552
Temperature	156.0385 °C
Cp	1.018618
Temperature	156.9996 °C
Cp	1.018662
Temperature	157.9606 °C
Cp	1.018664
Temperature	158.9217 °C
Cp	1.018632
Temperature	159.8828 °C
Cp	1.018575
Temperature	160.8439 °C
Cp	1.018492
Temperature	161.805 °C
Cp	1.018383
Temperature	162.766 °C
Cp	1.01825
Temperature	163.7271 °C
Cp	1.018087
Temperature	164.6882 °C
Cp	1.017917
Temperature	165.6493 °C
Cp	1.017726
Temperature	166.6104 °C
Cp	1.017522
Temperature	167.5714 °C
Cp	1.01731
Temperature	168.5325 °C
Cp	1.017098
Temperature	169.4936 °C
Cp	1.016902
Temperature	170.4547 °C
Cp	1.016695
Temperature	171.4158 °C
Cp	1.016508
Temperature	172.3768 °C
Cp	1.016342
Temperature	173.3379 °C
Cp	1.016195
Temperature	174.299 °C
Cp	1.016065
Temperature	175.2601 °C
Cp	1.015927
Temperature	176.2212 °C
Cp	1.015838
Temperature	177.1822 °C
Cp	1.015746
Temperature	178.1433 °C
Cp	1.015651
Temperature	179.1044 °C
Cp	1.015555
Temperature	180.0655 °C
Cp	1.015459
Temperature	181.0266 °C
Cp	1.015401
Temperature	181.9876 °C
Cp	1.015288
Temperature	182.9487 °C
Cp	1.015195
Temperature	183.9098 °C
Cp	1.015117
Temperature	184.8709 °C
Cp	1.01505
Temperature	185.832 °C
Cp	1.014988
Temperature	186.793 °C
Cp	1.014927
Temperature	187.7541 °C
Cp	1.014849
Temperature	188.7152 °C
Cp	1.014789
Temperature	189.6763 °C
Cp	1.01471
Temperature	190.6374 °C
Cp	1.014614
Temperature	191.5984 °C
Cp	1.014503
Temperature	192.5595 °C
Cp	1.014381
Temperature	193.5206 °C
Cp	1.014268
Temperature	194.4817 °C
Cp	1.014122
Temperature	195.4428 °C
Cp	1.013984
Temperature	196.4038 °C
Cp	1.013853
Temperature	197.3649 °C
Cp	1.013726
Temperature	198.326 °C
Cp	1.013603
Temperature	199.2871 °C
Cp	1.013467
Temperature	200.2482 °C
Cp	1.013359
Temperature	201.2092 °C
Cp	1.013243
Temperature	202.1703 °C
Cp	1.013123
Temperature	203.1314 °C
Cp	1.013002
Temperature	204.0925 °C
Cp	1.012884
Temperature	205.0536 °C
Cp	1.012788
Temperature	206.0146 °C
Cp	1.012674
Temperature	206.9757 °C
Cp	1.012579
Temperature	207.9368 °C
Cp	1.012501
Temperature	208.8979 °C
Cp	1.012439
Temperature	209.859 °C
Cp	1.012389
Temperature	210.82 °C
Cp	1.012351
Temperature	211.7811 °C
Cp	1.012312
Temperature	212.7422 °C
Cp	1.01229
Temperature	213.7033 °C
Cp	1.012262
Temperature	214.6644 °C
Cp	1.012227
Temperature	215.6254 °C
Cp	1.012183
Temperature	216.5865 °C
Cp	1.012129
Temperature	217.5476 °C
Cp	1.012077
Temperature	218.5087 °C
Cp	1.01199
Temperature	219.4698 °C
Cp	1.011897
Temperature	220.4308 °C
Cp	1.011793
Temperature	221.3919 °C
Cp	1.011674
Temperature	222.353 °C
Cp	1.011537
Temperature	223.3141 °C
Cp	1.011362
Temperature	224.2752 °C
Cp	1.011194
Temperature	225.2362 °C
Cp	1.010993
Temperature	226.1973 °C
Cp	1.010766
Temperature	227.1584 °C
Cp	1.010517
Temperature	228.1195 °C
Cp	1.010251
Temperature	229.0806 °C
Cp	1.009998
Temperature	230.0416 °C
Cp	1.009703
Temperature	231.0027 °C
Cp	1.009422
Temperature	231.9638 °C
Cp	1.009156
Temperature	232.9249 °C
Cp	1.008906
Temperature	233.886 °C
Cp	1.008675
Temperature	234.847 °C
Cp	1.008462
Temperature	235.8081 °C
Cp	1.008258
Temperature	236.7692 °C
Cp	1.00809
Temperature	237.7303 °C
Cp	1.007934
Temperature	238.6914 °C
Cp	1.007793
Temperature	239.6524 °C
Cp	1.007668
Temperature	240.6135 °C
Cp	1.007562
Temperature	241.5746 °C
Cp	1.007487
Temperature	242.5357 °C
Cp	1.00741
Temperature	243.4967 °C
Cp	1.00736
Temperature	244.4578 °C
Cp	1.007332
Temperature	245.4189 °C
Cp	1.007321
Temperature	246.38 °C
Cp	1.007321
Temperature	247.3411 °C
Cp	1.007312
Temperature	248.3022 °C
Cp	1.007331
Temperature	249.2632 °C
Cp	1.007338
Temperature	250.2243 °C
Cp	1.007335
Temperature	251.1854 °C
Cp	1.00732
Temperature	252.1465 °C
Cp	1.007295
Temperature	253.1076 °C
Cp	1.007277
Temperature	254.0686 °C
Cp	1.007227
Temperature	255.0297 °C
Cp	1.007179
Temperature	255.9908 °C
Cp	1.007133
Temperature	256.9519 °C
Cp	1.00709
Temperature	257.913 °C
Cp	1.007049
Temperature	258.874 °C
Cp	1.007012
Temperature	259.8351 °C
Cp	1.006978
Temperature	260.7962 °C
Cp	1.006956
Temperature	261.7573 °C
Cp	1.00694
Temperature	262.7184 °C
Cp	1.006934
Temperature	263.6794 °C
Cp	1.006939
Temperature	264.6405 °C
Cp	1.00696
Temperature	265.6016 °C
Cp	1.006999
Temperature	266.5627 °C
Cp	1.007054
Temperature	267.5237 °C
Cp	1.007131
Temperature	268.4848 °C
Cp	1.00723
Temperature	269.4459 °C
Cp	1.00735
Temperature	270.407 °C
Cp	1.007493
Temperature	271.3681 °C
Cp	1.007656
Temperature	272.3292 °C
Cp	1.007839
Temperature	273.2902 °C
Cp	1.008039
Temperature	274.2513 °C
Cp	1.008257
Temperature	275.2124 °C
Cp	1.008488
Temperature	276.1735 °C
Cp	1.008731
Temperature	277.1346 °C
Cp	1.008977
Temperature	278.0956 °C
Cp	1.009237
Temperature	279.0567 °C
Cp	1.009498
Temperature	280.0178 °C
Cp	1.009757
Temperature	280.9789 °C
Cp	1.010014
Temperature	281.9399 °C
Cp	1.010267
Temperature	282.901 °C
Cp	1.010515
Temperature	283.8621 °C
Cp	1.01076
Temperature	284.8232 °C
Cp	1.010993
Temperature	285.7843 °C
Cp	1.011222
Temperature	286.7454 °C
Cp	1.011447
Temperature	287.7064 °C
Cp	1.011665
Temperature	288.6675 °C
Cp	1.011876
Temperature	289.6286 °C
Cp	1.012079
Temperature	290.5897 °C
Cp	1.01228
Temperature	291.5508 °C
Cp	1.012474
Temperature	292.5118 °C
Cp	1.012662
Temperature	293.4729 °C
Cp	1.012846
Temperature	294.434 °C
Cp	1.013028
Temperature	295.3951 °C
Cp	1.013211
Temperature	296.3561 °C
Cp	1.013391
Temperature	297.3172 °C
Cp	1.013574
Temperature	298.2783 °C
Cp	1.013759
Temperature	299.2394 °C
Cp	1.013947
Temperature	300.2005 °C
Cp	1.014136
Temperature	301.1616 °C
Cp	1.01432
Temperature	302.1226 °C
Cp	1.014511
Temperature	303.0837 °C
Cp	1.014695
Temperature	304.0448 °C
Cp	1.014872
Temperature	305.0059 °C
Cp	1.01504
Temperature	305.9669 °C
Cp	1.015198
Temperature	306.928 °C
Cp	1.015343
Temperature	307.8891 °C
Cp	1.015479
Temperature	308.8502 °C
Cp	1.015595
Temperature	309.8113 °C
Cp	1.015699
Temperature	310.7724 °C
Cp	1.015789
Temperature	311.7334 °C
Cp	1.015865
Temperature	312.6945 °C
Cp	1.015925
Temperature	313.6556 °C
Cp	1.015964
Temperature	314.6167 °C
Cp	1.015999
Temperature	315.5778 °C
Cp	1.016018
Temperature	316.5388 °C
Cp	1.016025
Temperature	317.4999 °C
Cp	1.016024
Temperature	318.461 °C
Cp	1.01602
Temperature	319.4221 °C
Cp	1.016029
Temperature	320.3831 °C
Cp	1.016025
Temperature	321.3442 °C
Cp	1.016037
Temperature	322.3053 °C
Cp	1.016066
Temperature	323.2664 °C
Cp	1.01611
Temperature	324.2275 °C
Cp	1.016169
Temperature	325.1886 °C
Cp	1.016225
Temperature	326.1496 °C
Cp	1.016318
Temperature	327.1107 °C
Cp	1.016411
Temperature	328.0718 °C
Cp	1.016504
Temperature	329.0329 °C
Cp	1.016596
[...]
187.5917	110.9099	0.3663
187.6000	110.8268	0.3662
187.6083	110.7438	0.3662
187.6167	110.6595	0.3661
187.6250	110.5774	0.3660
187.6333	110.4947	0.3659
187.6417	110.4114	0.3658
187.6500	110.3290	0.3658
187.6583	110.2459	0.3658
187.6667	110.1624	0.3657
187.6750	110.0782	0.3656
187.6833	109.9958	0.3655
187.6917	109.9126	0.3655
187.7000	109.8300	0.3654
187.7083	109.7464	0.3653
187.7167	109.6635	0.3652
187.7250	109.5799	0.3651
187.7333	109.4973	0.3651
187.7417	109.4136	0.3650
187.7500	109.3302	0.3649
187.7583	109.2469	0.3648
187.7667	109.1634	0.3648
187.7750	109.0798	0.3644
187.7833	108.9968	0.3644
187.7917	108.9147	0.3643
187.8000	108.8308	0.3643
187.8083	108.7482	0.3642
187.8167	108.6647	0.3642
187.8250	108.5823	0.3641
187.8333	108.4985	0.3638
187.8417	108.4152	0.3637
187.8500	108.3323	0.3637
187.8583	108.2481	0.3636
187.8667	108.1667	0.3636
187.8750	108.0836	0.3635
187.8833	108.0007	0.3634
187.8917	107.9168	0.3634
187.9000	107.8340	0.3632
187.9083	107.7508	0.3631
187.9167	107.6668	0.3631
187.9250	107.5823	0.3630
187.9333	107.5019	0.3630
187.9417	107.4177	0.3630
187.9500	107.3340	0.3629
187.9583	107.2515	0.3629
187.9667	107.1682	0.3628
187.9750	107.0852	0.3627
187.9833	107.0026	0.3627
187.9917	106.9182	0.3626
188.0000	106.8359	0.3625
188.0083	106.7534	0.3624
188.0167	106.6693	0.3624
188.0250	106.5860	0.3623
188.0333	106.5034	0.3622
188.0417	106.4203	0.3622
188.0500	106.3370	0.3621
188.0583	106.2528	0.3620
188.0667	106.1712	0.3619
188.0750	106.0871	0.3619
188.0833	106.0048	0.3618
188.0917	105.9212	0.3617
188.1000	105.8379	0.3617
188.1083	105.7554	0.3616
188.1167	105.6708	0.3616
188.1250	105.5894	0.3614
188.1333	105.5058	0.3614
188.1417	105.4221	0.3613
188.1500	105.3382	0.3613
188.1583	105.2565	0.3612
188.1667	105.1730	0.3611
188.1750	105.0893	0.3611
188.1833	105.0063	0.3609
188.1917	104.9235	0.3608
188.2000	104.8400	0.3607
188.2083	104.7573	0.3607
188.2167	104.6739	0.3606
188.2250	104.5910	0.3605
188.2333	104.5067	0.3605
188.2417	104.4249	0.3604
188.2500	104.3407	0.3604
188.2583	104.2570	0.3603
188.2667	104.1754	0.3602
188.2750	104.0920	0.3602
188.2833	104.0088	0.3601
188.2917	103.9254	0.3600
188.3000	103.8415	0.3599
188.3083	103.7590	0.3599
188.3167	103.6754	0.3599
188.3250	103.5922	0.3598
188.3333	103.5099	0.3597
188.3417	103.4264	0.3597
188.3500	103.3431	0.3596
188.3583	103.2605	0.3595
188.3667	103.1767	0.3595
188.3750	103.0946	0.3595
188.3833	103.0106	0.3589
188.3917	102.9282	0.3587
188.4000	102.8440	0.3587
188.4083	102.7608	0.3587
188.4167	102.6780	0.3586
188.4250	102.5955	0.3585
188.4333	102.5120	0.3585
188.4417	102.4285	0.3585
188.4500	102.3457	0.3583
188.4583	102.2626	0.3583
188.4667	102.1793	0.3583
188.4750	102.0969	0.3582
188.4833	102.0133	0.3581
188.4917	101.9295	0.3581
188.5000	101.8461	0.3580
188.5083	101.7627	0.3580
188.5167	101.6814	0.3578
188.5250	101.5972	0.3577
188.5333	101.5140	0.3577
188.5417	101.4313	0.3576
188.5500	101.3473	0.3576
188.5583	101.2649	0.3575
188.5667	101.1823	0.3575
188.5750	101.0986	0.3574
188.5833	101.0157	0.3574
188.5917	100.9322	0.3573
188.6000	100.8494	0.3572
188.6083	100.7664	0.3571
188.6167	100.6831	0.3571
188.6250	100.6003	0.3569
188.6333	100.5171	0.3569
188.6417	100.4338	0.3568
188.6500	100.3509	0.3568
188.6583	100.2668	0.3567
188.6667	100.1843	0.3567
188.6750	100.1010	0.3566
188.6833	100.0175	0.3565
188.6917	99.9335	0.3565
188.7000	99.8508	0.3565
188.7083	99.7680	0.3564
188.7167	99.6851	0.3564
188.7250	99.6015	0.3563
188.7333	99.5185	0.3562
188.7417	99.4356	0.3561
188.7500	99.3520	0.3561
188.7583	99.2685	0.3560
188.7667	99.1861	0.3560
188.7750	99.1031	0.3559
188.7833	99.0204	0.3559
188.7917	98.9368	0.3558
188.8000	98.8529	0.3558
188.8083	98.7700	0.3557
188.8167	98.6863	0.3556
188.8250	98.6028	0.3555
188.8333	98.5200	0.3555
188.8417	98.4371	0.3555
188.8500	98.3542	0.3554
188.8583	98.2700	0.3554
188.8667	98.1870	0.3553
188.8750	98.1053	0.3552
188.8833	98.0210	0.3551
188.8917	97.9378	0.3550
188.9000	97.8548	0.3550
188.9083	97.7719	0.3549
188.9167	97.6884	0.3548
188.9250	97.6046	0.3548
188.9333	97.5222	0.3547
188.9417	97.4396	0.3546
188.9500	97.3549	0.3546
188.9583	97.2728	0.3543
188.9667	97.1887	0.3541
188.9750	97.1068	0.3540
188.9833	97.0226	0.3540
188.9917	96.9400	0.3539
189.0000	96.8567	0.3539
189.0083	96.7739	0.3538
189.0167	96.6916	0.3537
189.0250	96.6081	0.3537
189.0333	96.5245	0.3536
189.0417	96.4409	0.3536
189.0500	96.3584	0.3535
189.0583	96.2754	0.3535
189.0667	96.1920	0.3533
189.0750	96.1076	0.3532
189.0833	96.0256	0.3531
189.0917	95.9409	0.3530
189.1000	95.8589	0.3530
189.1083	95.7770	0.3528
189.1167	95.6929	0.3527
189.1250	95.6099	0.3525
189.1333	95.5266	0.3524
189.1417	95.4434	0.3524
189.1500	95.3607	0.3523
189.1583	95.2777	0.3523
189.1667	95.1934	0.3522
189.1750	95.1102	0.3522
189.1833	95.0284	0.3521
189.1917	94.9443	0.3518
189.2000	94.8611	0.3519
189.2083	94.7782	0.3518
189.2167	94.6956	0.3518
189.2250	94.6126	0.3517
189.2333	94.5290	0.3517
189.2417	94.4451	0.3516
189.2500	94.3619	0.3515
189.2583	94.2790	0.3514
189.2667	94.1956	0.3514
189.2750	94.1129	0.3513
189.2833	94.0301	0.3512
189.2917	93.9465	0.3512
189.3000	93.8632	0.3511
189.3083	93.7796	0.3511
189.3167	93.6970	0.3510
189.3250	93.6149	0.3509
189.3333	93.5308	0.3508
189.3417	93.4481	0.3508
189.3500	93.3654	0.3507
189.3583	93.2814	0.3507
189.3667	93.1991	0.3506
189.3750	93.1156	0.3505
189.3833	93.0311	0.3504
189.3917	92.9494	0.3504
189.4000	92.8656	0.3503
189.4083	92.7821	0.3502
189.4167	92.6990	0.3502
189.4250	92.6161	0.3501
189.4333	92.5330	0.3500
189.4417	92.4494	0.3499
189.4500	92.3660	0.3499
189.4583	92.2825	0.3498
189.4667	92.1997	0.3498
189.4750	92.1163	0.3498
189.4833	92.0336	0.3497
189.4917	91.9504	0.3495
189.5000	91.8667	0.3495
189.5083	91.7840	0.3494
189.5167	91.7020	0.3490
189.5250	91.6176	0.3489
189.5333	91.5346	0.3489
189.5417	91.4507	0.3488
189.5500	91.3693	0.3488
189.5583	91.2848	0.3487
189.5667	91.2023	0.3486
189.5750	91.1195	0.3486
189.5833	91.0355	0.3485
189.5917	90.9533	0.3484
189.6000	90.8695	0.3484
189.6083	90.7863	0.3483
189.6167	90.7032	0.3482
189.6250	90.6212	0.3482
189.6333	90.5380	0.3481
189.6417	90.4536	0.3481
189.6500	90.3708	0.3479
189.6583	90.2882	0.3478
189.6667	90.2054	0.3478
189.6750	90.1229	0.3477
189.6833	90.0382	0.3477
189.6917	89.9560	0.3476
189.7000	89.8729	0.3475
189.7083	89.7887	0.3474
189.7167	89.7059	0.3474
189.7250	89.6226	0.3473
189.7333	89.5402	0.3472
189.7417	89.4561	0.3471
189.7500	89.3728	0.3472
189.7583	89.2906	0.3471
189.7667	89.2061	0.3470
189.7750	89.1243	0.3468
189.7833	89.0416	0.3468
189.7917	88.9570	0.3468
189.8000	88.8730	0.3466
189.8083	88.7900	0.3466
189.8167	88.7076	0.3465
189.8250	88.6243	0.3464
189.8333	88.5413	0.3463
189.8417	88.4571	0.3463
189.8500	88.3743	0.3462
189.8583	88.2911	0.3461
189.8667	88.2088	0.3461
189.8750	88.1247	0.3460
189.8833	88.0419	0.3459
189.8917	87.9592	0.3459
189.9000	87.8761	0.3458
189.9083	87.7926	0.3457
189.9167	87.7093	0.3457
189.9250	87.6264	0.3456
189.9333	87.5430	0.3455
189.9417	87.4603	0.3454
189.9500	87.3762	0.3454
189.9583	87.2939	0.3453
189.9667	87.2101	0.3452
189.9750	87.1275	0.3451
189.9833	87.0442	0.3451
189.9917	86.9617	0.3450
190.0000	86.8787	0.3449
190.0083	86.7952	0.3448
190.0167	86.7121	0.3448
190.0250	86.6291	0.3447
190.0333	86.5458	0.3446
190.0417	86.4619	0.3446
190.0500	86.3786	0.3446
190.0583	86.2951	0.3444
190.0667	86.2128	0.3444
190.0750	86.1296	0.3443
190.0833	86.0467	0.3443
190.0917	85.9629	0.3442
190.1000	85.8804	0.3442
190.1083	85.7976	0.3440
190.1167	85.7137	0.3438
190.1250	85.6307	0.3438
190.1333	85.5478	0.3438
190.1417	85.4642	0.3437
190.1500	85.3807	0.3437
190.1583	85.2989	0.3436
190.1667	85.2144	0.3436
190.1750	85.1323	0.3435
190.1833	85.0491	0.3434
190.1917	84.9648	0.3433
190.2000	84.8829	0.3432
190.2083	84.7986	0.3432
190.2167	84.7161	0.3431
190.2250	84.6331	0.3431
190.2333	84.5492	0.3430
190.2417	84.4661	0.3429
190.2500	84.3837	0.3428
190.2583	84.3000	0.3428
190.2667	84.2169	0.3426
190.2750	84.1335	0.3426
190.2833	84.0509	0.3425
190.2917	83.9685	0.3424
190.3000	83.8848	0.3423
190.3083	83.8003	0.3423
190.3167	83.7176	0.3422
190.3250	83.6352	0.3421
190.3333	83.5517	0.3421
190.3417	83.4684	0.3419
190.3500	83.3851	0.3419
190.3583	83.3019	0.3418
190.3667	83.2195	0.3418
190.3750	83.1352	0.3417
190.3833	83.0525	0.3415
190.3917	82.9705	0.3414
190.4000	82.8876	0.3414
190.4083	82.8040	0.3414
190.4167	82.7194	0.3413
190.4250	82.6376	0.3412
190.4333	82.5549	0.3411
190.4417	82.4718	0.3411
190.4500	82.3882	0.3410
190.4583	82.3055	0.3408
190.4667	82.2220	0.3408
190.4750	82.1386	0.3407
190.4833	82.0548	0.3407
190.4917	81.9730	0.3406
190.5000	81.8894	0.3405
190.5083	81.8058	0.3404
190.5167	81.7230	0.3404
190.5250	81.6398	0.3403
190.5333	81.5562	0.3402
190.5417	81.4728	0.3401
190.5500	81.3907	0.3401
190.5583	81.3065	0.3400
190.5667	81.2231	0.3400
190.5750	81.1408	0.3399
190.5833	81.0576	0.3398
190.5917	80.9752	0.3393
190.6000	80.8913	0.3392
190.6083	80.8077	0.3393
190.6167	80.7257	0.3392
190.6250	80.6423	0.3391
190.6333	80.5588	0.3391
190.6417	80.4753	0.3390
190.6500	80.3917	0.3390
190.6583	80.3098	0.3389
190.6667	80.2262	0.3388
190.6750	80.1427	0.3388
190.6833	80.0586	0.3387
190.6917	79.9765	0.3386
190.7000	79.8933	0.3385
190.7083	79.8107	0.3385
190.7167	79.7270	0.3385
190.7250	79.6432	0.3384
190.7333	79.5600	0.3383
190.7417	79.4775	0.3383
190.7500	79.3945	0.3382
190.7583	79.3105	0.3382
190.7667	79.2273	0.3381
190.7750	79.1442	0.3379
190.7833	79.0611	0.3379
190.7917	78.9780	0.3378
190.8000	78.8963	0.3377
190.8083	78.8110	0.3377
190.8167	78.7294	0.3376
190.8250	78.6448	0.3375
190.8333	78.5622	0.3374
190.8417	78.4801	0.3374
190.8500	78.3965	0.3373
190.8583	78.3134	0.3373
190.8667	78.2291	0.3372
190.8750	78.1457	0.3371
190.8833	78.0633	0.3370
190.8917	77.9812	0.3369
190.9000	77.8972	0.3369
190.9083	77.8148	0.3367
190.9167	77.7300	0.3366
190.9250	77.6482	0.3366
190.9333	77.5652	0.3363
190.9417	77.4814	0.3363
190.9500	77.3991	0.3363
190.9583	77.3147	0.3362
190.9667	77.2320	0.3361
190.9750	77.1480	0.3361
190.9833	77.0663	0.3360
190.9917	76.9822	0.3359
191.0000	76.8996	0.3359
191.0083	76.8159	0.3358
191.0167	76.7324	0.3357
191.0250	76.6497	0.3356
191.0333	76.5660	0.3355
191.0417	76.4830	0.3355
191.0500	76.4003	0.3354
191.0583	76.3172	0.3354
191.0667	76.2337	0.3352
191.0750	76.1510	0.3349
191.0833	76.0668	0.3348
191.0917	75.9843	0.3348
191.1000	75.9013	0.3347
191.1083	75.8173	0.3347
191.1167	75.7356	0.3346
191.1250	75.6523	0.3345
191.1333	75.5688	0.3344
191.1417	75.4860	0.3343
191.1500	75.4025	0.3343
191.1583	75.3191	0.3342
191.1667	75.2369	0.3341
191.1750	75.1523	0.3341
191.1833	75.0704	0.3340
191.1917	74.9870	0.3339
191.2000	74.9036	0.3338
191.2083	74.8203	0.3337
191.2167	74.7367	0.3337
191.2250	74.6542	0.3336
191.2333	74.5710	0.3336
191.2417	74.4883	0.3335
191.2500	74.4044	0.3334
191.2583	74.3216	0.3334
191.2667	74.2384	0.3333
191.2750	74.1552	0.3332
191.2833	74.0716	0.3331
191.2917	73.9889	0.3330
191.3000	73.9047	0.3329
191.3083	73.8229	0.3329
191.3167	73.7398	0.3328
191.3250	73.6567	0.3327
191.3333	73.5722	0.3326
191.3417	73.4907	0.3326
191.3500	73.4060	0.3325
191.3583	73.3228	0.3324
191.3667	73.2399	0.3323
191.3750	73.1574	0.3323
191.3833	73.0730	0.3322
191.3917	72.9895	0.3320
191.4000	72.9071	0.3319
191.4083	72.8248	0.3318
191.4167	72.7411	0.3317
191.4250	72.6574	0.3317
191.4333	72.5747	0.3316
191.4417	72.4916	0.3316
191.4500	72.4072	0.3315
191.4583	72.3258	0.3314
191.4667	72.2426	0.3313
191.4750	72.1586	0.3313
191.4833	72.0760	0.3312
191.4917	71.9919	0.3311
191.5000	71.9101	0.3310
191.5083	71.8266	0.3310
191.5167	71.7428	0.3309
191.5250	71.6601	0.3308
191.5333	71.5776	0.3307
191.5417	71.4941	0.3306
191.5500	71.4111	0.3306
191.5583	71.3275	0.3305
191.5667	71.2445	0.3304
191.5750	71.1608	0.3304
191.5833	71.0796	0.3303
191.5917	70.9945	0.3302
191.6000	70.9117	0.3302
191.6083	70.8288	0.3300
191.6167	70.7449	0.3299
191.6250	70.6630	0.3299
191.6333	70.5791	0.3298
191.6417	70.4957	0.3294
191.6500	70.4121	0.3293
191.6583	70.3294	0.3293
191.6667	70.2464	0.3292
191.6750	70.1637	0.3291
191.6833	70.0803	0.3291
191.6917	69.9962	0.3290
191.7000	69.9144	0.3290
191.7083	69.8303	0.3290
191.7167	69.7468	0.3287
191.7250	69.6644	0.3285
191.7333	69.5816	0.3284
191.7417	69.4971	0.3284
191.7500	69.4151	0.3283
191.7583	69.3320	0.3282
191.7667	69.2485	0.3281
191.7750	69.1650	0.3281
191.7833	69.0822	0.3280
191.7917	68.9995	0.3280
191.8000	68.9162	0.3279
191.8083	68.8335	0.3278
191.8167	68.7497	0.3277
191.8250	68.6661	0.3277
191.8333	68.5839	0.3277
191.8417	68.4999	0.3276
191.8500	68.4162	0.3275
191.8583	68.3341	0.3274
191.8667	68.2502	0.3274
191.8750	68.1672	0.3273
191.8833	68.0831	0.3273
191.8917	68.0015	0.3272
191.9000	67.9176	0.3272
191.9083	67.8347	0.3269
191.9167	67.7516	0.3267
191.9250	67.6675	0.3266
191.9333	67.5847	0.3266
191.9417	67.5023	0.3265
191.9500	67.4193	0.3265
191.9583	67.3352	0.3264
191.9667	67.2534	0.3263
191.9750	67.1698	0.3262
191.9833	67.0854	0.3262
191.9917	67.0024	0.3261
192.0000	66.9193	0.3260
192.0083	66.8365	0.3260
192.0167	66.7543	0.3259
192.0250	66.6704	0.3259
192.0333	66.5875	0.3258
192.0417	66.5039	0.3257
192.0500	66.4213	0.3256
192.0583	66.3381	0.3255
192.0667	66.2544	0.3255
192.0750	66.1723	0.3255
192.0833	66.0885	0.3254
192.0917	66.0043	0.3251
192.1000	65.9225	0.3251
192.1083	65.8379	0.3250
192.1167	65.7550	0.3249
192.1250	65.6726	0.3249
192.1333	65.5894	0.3248
192.1417	65.5062	0.3247
192.1500	65.4230	0.3247
192.1583	65.3390	0.3246
192.1667	65.2563	0.3245
192.1750	65.1726	0.3245
192.1833	65.0894	0.3244
192.1917	65.0061	0.3244
192.2000	64.9232	0.3243
192.2083	64.8399	0.3242
192.2167	64.7566	0.3242
192.2250	64.6733	0.3241
192.2333	64.5918	0.3240
192.2417	64.5071	0.3240
192.2500	64.4243	0.3239
192.2583	64.3416	0.3238
192.2667	64.2576	0.3238
192.2750	64.1747	0.3238
192.2833	64.0920	0.3237
192.2917	64.0078	0.3237
192.3000	63.9255	0.3236
192.3083	63.8424	0.3236
192.3167	63.7601	0.3236
192.3250	63.6762	0.3236
192.3333	63.5917	0.3236
192.3417	63.5101	0.3236
192.3500	63.4269	0.3236
192.3583	63.3444	0.3237
192.3667	63.2608	0.3237
192.3750	63.1770	0.3238
192.3833	63.0938	0.3239
192.3917	63.0106	0.3244
192.4000	62.9280	0.3257
192.4083	62.8456	0.3278
192.4167	62.7629	0.3300
192.4250	62.6802	0.3390
192.4333	62.5981	0.3429
192.4417	62.5159	0.3510
192.4500	62.4353	0.3591
192.4583	62.3519	0.3699
192.4667	62.2708	0.3811
192.4750	62.1902	0.3922
192.4833	62.1108	0.4090
192.4917	62.0299	0.4283
192.5000	61.9498	0.4481
192.5083	61.8717	0.4720
192.5167	61.7934	0.5011
192.5250	61.7160	0.5325
192.5333	61.6405	0.5686
192.5417	61.5655	0.6126
192.5500	61.4919	0.6638
192.5583	61.4197	0.7188
192.5667	61.3494	0.7859
192.5750	61.2821	0.8595
192.5833	61.2160	0.9429
192.5917	61.1524	1.0411
192.6000	61.0908	1.1469
192.6083	61.0335	1.2635
192.6167	60.9792	1.3937
192.6250	60.9277	1.5348
192.6333	60.8800	1.6839
192.6417	60.8350	1.8393
192.6500	60.7935	2.0002
192.6583	60.7570	2.1648
192.6667	60.7213	2.3298
192.6750	60.6894	2.4930
192.6833	60.6585	2.6544
192.6917	60.6301	2.8060
192.7000	60.6027	2.9518
192.7083	60.5759	3.0902
192.7167	60.5494	3.2198
192.7250	60.5240	3.3405
192.7333	60.4957	3.4534
192.7417	60.4681	3.5590
192.7500	60.4377	3.6544
192.7583	60.4101	3.7417
192.7667	60.3778	3.8252
192.7750	60.3441	3.9014
192.7833	60.3077	3.9725
192.7917	60.2701	4.0344
192.8000	60.2308	4.0930
192.8083	60.1922	4.1478
192.8167	60.1473	4.1954
192.8250	60.1015	4.2386
192.8333	60.0550	4.2778
192.8417	60.0060	4.3118
192.8500	59.9547	4.3430
192.8583	59.9008	4.3672
192.8667	59.8465	4.3857
192.8750	59.7888	4.4007
192.8833	59.7286	4.4095
192.8917	59.6671	4.4154
192.9000	59.6035	4.4135
192.9083	59.5380	4.4037
192.9167	59.4698	4.3904
192.9250	59.3992	4.3706
192.9333	59.3250	4.3447
192.9417	59.2498	4.3078
192.9500	59.1723	4.2659
192.9583	59.0932	4.2209
192.9667	59.0092	4.1663
192.9750	58.9236	4.1001
192.9833	58.8351	4.0294
192.9917	58.7427	3.9488
193.0000	58.6489	3.8622
193.0083	58.5522	3.7676
193.0167	58.4512	3.6672
193.0250	58.3477	3.5580
193.0333	58.2417	3.4457
193.0417	58.1315	3.3282
193.0500	58.0192	3.2084
193.0583	57.9051	3.0888
193.0667	57.7887	2.9701
193.0750	57.6684	2.8526
193.0833	57.5483	2.7425
193.0917	57.4271	2.6337
193.1000	57.3060	2.5368
193.1083	57.1825	2.4416
193.1167	57.0604	2.3571
193.1250	56.9386	2.2761
193.1333	56.8160	2.1999
193.1417	56.6958	2.1287
193.1500	56.5749	2.0641
193.1583	56.4565	1.9987
193.1667	56.3379	1.9401
193.1750	56.2191	1.8828
193.1833	56.1034	1.8278
193.1917	55.9888	1.7779
193.2000	55.8724	1.7281
193.2083	55.7590	1.6813
193.2167	55.6469	1.6353
193.2250	55.5355	1.5910
193.2333	55.4254	1.5528
193.2417	55.3154	1.5139
193.2500	55.2068	1.4765
193.2583	55.0985	1.4411
193.2667	54.9910	1.4055
193.2750	54.8856	1.3731
193.2833	54.7799	1.3418
193.2917	54.6758	1.3124
193.3000	54.5725	1.2877
193.3083	54.4696	1.2644
193.3167	54.3691	1.2404
193.3250	54.2670	1.2150
193.3333	54.1690	1.1925
193.3417	54.0688	1.1749
193.3500	53.9696	1.1502
193.3583	53.8717	1.1296
193.3667	53.7731	1.1077
193.3750	53.6768	1.0849
193.3833	53.5793	1.0661
193.3917	53.4848	1.0470
193.4000	53.3895	1.0291
193.4083	53.2933	1.0128
193.4167	53.1992	0.9970
193.4250	53.1043	0.9823
193.4333	53.0109	0.9651
193.4417	52.9179	0.9522
193.4500	52.8250	0.9417
193.4583	52.7309	0.9294
193.4667	52.6385	0.9146
193.4750	52.5478	0.9037
193.4833	52.4562	0.8929
193.4917	52.3650	0.8789
193.5000	52.2732	0.8685
193.5083	52.1826	0.8601
193.5167	52.0921	0.8481
193.5250	52.0030	0.8388
193.5333	51.9131	0.8277
193.5417	51.8224	0.8179
193.5500	51.7347	0.8087
193.5583	51.6446	0.8011
193.5667	51.5553	0.7902
193.5750	51.4680	0.7829
193.5833	51.3792	0.7754
193.5917	51.2908	0.7654
193.6000	51.2027	0.7584
193.6083	51.1150	0.7515
193.6167	51.0262	0.7432
193.6250	50.9400	0.7360
193.6333	50.8513	0.7302
193.6417	50.7640	0.7224
193.6500	50.6771	0.7142
193.6583	50.5894	0.7069
193.6667	50.5032	0.7014
193.6750	50.4147	0.6949
193.6833	50.3284	0.6893
193.6917	50.2412	0.6836
193.7000	50.1541	0.6748
193.7083	50.0674	0.6702
193.7167	49.9817	0.6644
193.7250	49.8950	0.6589
193.7333	49.8078	0.6532
193.7417	49.7212	0.6476
193.7500	49.6344	0.6419
193.7583	49.5482	0.6385
193.7667	49.4636	0.6321
193.7750	49.3764	0.6268
193.7833	49.2919	0.6231
193.7917	49.2063	0.6183
193.8000	49.1190	0.6129
193.8083	49.0346	0.6099
193.8167	48.9497	0.6057
193.8250	48.8627	0.6006
193.8333	48.7767	0.5962
193.8417	48.6928	0.5912
193.8500	48.6067	0.5878
193.8583	48.5201	0.5862
193.8667	48.4362	0.5811
193.8750	48.3494	0.5793
193.8833	48.2650	0.5725
193.8917	48.1798	0.5698
193.9000	48.0948	0.5680
193.9083	48.0100	0.5646
193.9167	47.9252	0.5620
193.9250	47.8404	0.5573
193.9333	47.7557	0.5564
193.9417	47.6707	0.5556
193.9500	47.5840	0.5515
193.9583	47.5002	0.5486
193.9667	47.4161	0.5465
193.9750	47.3309	0.5439
193.9833	47.2464	0.5429
193.9917	47.1620	0.5385
194.0000	47.0778	0.5379
194.0083	46.9941	0.5376
194.0167	46.9094	0.5352
194.0250	46.8247	0.5306
194.0333	46.7411	0.5302
194.0417	46.6547	0.5302
194.0500	46.5713	0.5287
194.0583	46.4875	0.5255
194.0667	46.4045	0.5250
194.0750	46.3195	0.5232
194.0833	46.2356	0.5203
194.0917	46.1510	0.5202
194.1000	46.0669	0.5196
194.1083	45.9831	0.5177
194.1167	45.8985	0.5162
194.1250	45.8152	0.5143
194.1333	45.7311	0.5130
194.1417	45.6469	0.5116
194.1500	45.5634	0.5089
194.1583	45.4797	0.5078
194.1667	45.3959	0.5078
194.1750	45.3120	0.5062
194.1833	45.2270	0.5041
194.1917	45.1433	0.5021
194.2000	45.0593	0.5013
194.2083	44.9752	0.5007
194.2167	44.8919	0.4988
194.2250	44.8077	0.4961
194.2333	44.7230	0.4949
194.2417	44.6400	0.4937
194.2500	44.5566	0.4927
194.2583	44.4720	0.4909
194.2667	44.3880	0.4877
194.2750	44.3046	0.4864
194.2833	44.2206	0.4860
194.2917	44.1364	0.4835
194.3000	44.0527	0.4815
194.3083	43.9694	0.4809
194.3167	43.8853	0.4792
194.3250	43.8014	0.4780
194.3333	43.7175	0.4763
194.3417	43.6342	0.4738
194.3500	43.5510	0.4731
194.3583	43.4655	0.4718
194.3667	43.3820	0.4688
194.3750	43.2982	0.4676
194.3833	43.2150	0.4657
194.3917	43.1316	0.4635
194.4000	43.0476	0.4631
194.4083	42.9623	0.4614
194.4167	42.8778	0.4593
194.4250	42.7948	0.4581
194.4333	42.7109	0.4575
194.4417	42.6277
194.4500	42.5442
194.4583	42.4585
194.4667	42.3757
194.4750	42.2915
194.4833	42.2083
194.4917
194.4983