File: Example Date/My Sample/DSC/test01/DSC TA/YN042 -150-150.txt
Filename	YN042 -150-150
Instrument name	DSC2A-01799 (192.168.1.250)
Operator
rundate	09/12/2024
Sample name	YN042 -150-150
proceduresegments	Ramp 10.00 °C/min to 150.0000 °C; Isothermal 3.0 min; Ramp 10.00 °C/min to -150.0000 °C; Isothermal 3.0 min; Ramp 10.00 °C/min to 150.0000 °C; Isothermal 3.0 min; Ramp 10.00 °C/min to -150.0000 °C; Isothermal 3.0 min; Ramp 10.00 °C/min to 150.0000 °C; Isothermal 3.0 min; Ramp 10.00 °C/min to 40.0000 °C
[File Parameters]
Run Date	09/12/2024 22:28:05
Trios version	5.7.0.56
Original File Name	C:\Users\TA Instruments DSC\Desktop\Data\Yutong Niu\YN042 -150-150.tri
Current File Name	C:\Users\TA Instruments DSC\Desktop\Data\Yutong Niu\YN042 -150-150.tri
User at run start	DESKTOP-CFGN8IT\TA Instruments DSC
[Procedure]
Procedure Name	polyether
Sample Name	YN042 -150-150
Sample Mass	11.48 mg
Reference Sample Mass	0 mg
Pan Mass	62.16 mg
Pan Number	2
Reference Pan Mass	60.81 mg
Reference Pan Number	45
Pan Type	Tzero Aluminum Pin Hole Hermetic
Comments
Project Name
Operator
Test	Custom
Unload Max Temperature	25
Unload Min Temperature	25
FillCooler	Do not fill
Load Max Temperature	25
Load Min Temperature	25
Discard pan in waste bin at end of test	Yes
Stop on Gas Flow Error	No
[Signal List]
Signal #1	Time (min)
Signal #2	Temperature (°C)
Signal #3	Heat Flow (mW)
Signal #4	Delta T (µV)
Signal #5	Delta Tzero (µV)
Signal #6	Tzero Temperature (°C)
Signal #7	Cell Purge (mL/min)
Signal #8	Heater Temp (°C)
Signal #9	Power Delivered (W)
Signal #10	Reference Junction Temperature (°C)
Signal #11	Flange Temperature (°C)
Signal #12	Heat Flow Phase (rad)
Signal #13	Total Heat Capacity (J/°C)
Signal #14	Heat Capacity (J/°C)
Signal #15	LN Pump Tank level (%)
[Configuration]
Company Name	Warwick University
Instrument Name	DSC2A-01799
Instrument Type	DSC2500
Serial Number	DSC2A-01799
IP	192.168.1.250
Location of Instrument	Polymer RTP
DisplayType	TianmaV2andV3
Sample Interval 	0.1 s/pt
Selected Heat Flow	T4P
Exotherm Direction	Up
Cell Serial	DRC2-03788
Lid Type	High Temperature
Cooler	LN Pump
Leave Cooler on at End of Sequence	Off
Gas 2	Air
Gas Selected	Channel 1: Nitrogen
Flow Rate	50 mL/min
Secondary Purge	On
Licensed Heat Flow	Heat Flow T4P
Modulation Licensed	Yes
[Versions]
Common IDD Version	1
Cortex Version	VER 2.11.0.729
Driver	5.0.0.6
GDM Version	1.0.3.3
TouchscreenVersion	1.0.3.1841
FEP Version	1.2.1.21
FEP Bootloader	2.0.0.5
AutoSampler Version	2.1.2.1
Auto Sampler Bootloader	2.0.0.5
FCM Version	1.1.0.3
FCM Bootloader	2.0.0.5
LN Pump Version	10.17.0.0
LN Pump Bootloader	2.0.0.5
[Experiment Logs]
Experiment Log Entry # 1	Ramp Segment 10 C/min to 150 Started
Experiment Log Entry # 3	Air Cool is off.
Experiment Log Entry # 5	Isothermal Segment 3 min started
Experiment Log Entry # 7	Ramp Segment 10 C/min to -150 Started
Experiment Log Entry # 9	Isothermal Segment 3 min started
Experiment Log Entry # 11	Ramp Segment 10 C/min to 150 Started
Experiment Log Entry # 13	Isothermal Segment 3 min started
Experiment Log Entry # 15	Ramp Segment 10 C/min to -150 Started
Experiment Log Entry # 17	Isothermal Segment 3 min started
Experiment Log Entry # 19	Ramp Segment 10 C/min to 150 Started
Experiment Log Entry # 21	Isothermal Segment 3 min started
Experiment Log Entry # 23	Ramp Segment 10 C/min to 40 Started
[Method Log]
Method Log Entry # 1	(Ramp 595115) Ramp 10 °C/minute to 150 °C
Method Log Entry # 2	Isothermal 3 minutes
Method Log Entry # 3	(Ramp 595117) Ramp 10 °C/minute to -150 °C
Method Log Entry # 4	Isothermal 3 minutes
Method Log Entry # 5	(Ramp 595119) Ramp 10 °C/minute to 150 °C
Method Log Entry # 6	Isothermal 3 minutes
Method Log Entry # 7	(Ramp 595121) Ramp 10 °C/minute to -150 °C
Method Log Entry # 8	Isothermal 3 minutes
Method Log Entry # 9	(Ramp 595123) Ramp 10 °C/minute to 150 °C
Method Log Entry # 10	Isothermal 3 minutes
Method Log Entry # 11	(Ramp 595125) Ramp 10 °C/minute to 40 °C
Cell Serial	DRC2-03788
[T1 Calibration]
Date Applied	04/03/2021 14:58:04
Description
Gas Type	Nitrogen
Pan Type	None
Slope	-0.001800291
Offset	-0.1301359
Initial Temperature	-100.6228
GUID	a1d5a6be-decd-4ae4-b22f-d560f3a78a92
[TZero Calibration]
Date Applied	21/08/2024 09:53:38
Description	From -180.022 °C to 395.167 °C at 20.000°C/min
Gas Type	Nitrogen
Pan Type	None
Source Files 1	C:\ProgramData\TA Instruments\TRIOS\Data\TAService\PMV 20Aug2024\Tzero Cal.tri
Source Files 2	C:\ProgramData\TA Instruments\TRIOS\Data\TAService\PMV 20Aug2024\Tzero Cal sapphire.tri
Delta T Offset	1.787969
Delta T Slope	-0.003527276
Delta T0 Offset	0.06831977
Delta T0 Slope	0.02007191
[Temperature Calibration]
Date Applied	21/08/2024 11:06:35
Description	From 106.660 °C to 186.660 °C at 10.000°C/min
Gas Type	Nitrogen
Pan Type	Tzero Aluminum
Source Files 1	C:\ProgramData\TA Instruments\TRIOS\Data\TAService\PMV 20Aug2024\TA Indium cal.tri
Measured 1	157.9141
Known 1	156.66
[Cell Constant Calibration]
Date Applied	21/08/2024 11:06:35
Description	From 106.660 °C to 186.660 °C at 10.000°C/min
Gas Type	Nitrogen
Pan Type	Tzero Aluminum
Source Files 1	C:\ProgramData\TA Instruments\TRIOS\Data\TAService\PMV 20Aug2024\TA Indium cal.tri
T4P KCell	1.038055
Onset Slope	-66.72884 mW/°C
[Direct Cp Calibration]
Date Applied	19/11/2024 16:37:27
Description	From -89.996 °C to 396.697 °C at 20.000°C/min
Gas Type	Nitrogen
Pan Type	Tzero Aluminum
Source Files 1	C:\ProgramData\TA Instruments\TRIOS\Data\Sapphire Direct Heat Capacity(8).tri
GUID	544f8371-fe9b-4f4f-81ca-7980c172113e
Temperature	-89.99625 °C
Cp	1.464367
Temperature	-89.02287 °C
Cp	1.460558
Temperature	-88.04948 °C
Cp	1.456263
Temperature	-87.0761 °C
Cp	1.451626
Temperature	-86.10271 °C
Cp	1.446737
Temperature	-85.12933 °C
Cp	1.441723
Temperature	-84.15594 °C
Cp	1.436654
Temperature	-83.18256 °C
Cp	1.431684
Temperature	-82.20917 °C
Cp	1.426935
Temperature	-81.23578 °C
Cp	1.422396
Temperature	-80.2624 °C
Cp	1.418192
Temperature	-79.28901 °C
Cp	1.414363
Temperature	-78.31562 °C
Cp	1.410925
Temperature	-77.34224 °C
Cp	1.407865
Temperature	-76.36885 °C
Cp	1.405143
Temperature	-75.39546 °C
Cp	1.402789
Temperature	-74.42208 °C
Cp	1.400703
Temperature	-73.44869 °C
Cp	1.398837
Temperature	-72.4753 °C
Cp	1.397142
Temperature	-71.50192 °C
Cp	1.395565
Temperature	-70.52853 °C
Cp	1.394053
Temperature	-69.55515 °C
Cp	1.392558
Temperature	-68.58176 °C
Cp	1.391036
Temperature	-67.60838 °C
Cp	1.389483
Temperature	-66.63499 °C
Cp	1.387847
Temperature	-65.66161 °C
Cp	1.38616
Temperature	-64.68822 °C
Cp	1.384397
Temperature	-63.71483 °C
Cp	1.382535
Temperature	-62.74145 °C
Cp	1.380598
Temperature	-61.76806 °C
Cp	1.37865
Temperature	-60.79467 °C
Cp	1.376673
Temperature	-59.82129 °C
Cp	1.374677
Temperature	-58.8479 °C
Cp	1.372642
Temperature	-57.87452 °C
Cp	1.370686
Temperature	-56.90113 °C
Cp	1.368741
Temperature	-55.92775 °C
Cp	1.366786
Temperature	-54.95436 °C
Cp	1.364863
Temperature	-53.98097 °C
Cp	1.362959
Temperature	-53.00759 °C
Cp	1.361116
Temperature	-52.0342 °C
Cp	1.359247
Temperature	-51.06082 °C
Cp	1.357393
Temperature	-50.08743 °C
Cp	1.355593
Temperature	-49.11404 °C
Cp	1.353796
Temperature	-48.14066 °C
Cp	1.352008
Temperature	-47.16727 °C
Cp	1.350215
Temperature	-46.19389 °C
Cp	1.348396
Temperature	-45.2205 °C
Cp	1.346593
Temperature	-44.24712 °C
Cp	1.344755
Temperature	-43.27373 °C
Cp	1.342891
Temperature	-42.30034 °C
Cp	1.341008
Temperature	-41.32696 °C
Cp	1.339126
Temperature	-40.35357 °C
Cp	1.337236
Temperature	-39.38018 °C
Cp	1.335367
Temperature	-38.4068 °C
Cp	1.333522
Temperature	-37.43341 °C
Cp	1.331708
Temperature	-36.46003 °C
Cp	1.32991
Temperature	-35.48664 °C
Cp	1.328145
Temperature	-34.51326 °C
Cp	1.326414
Temperature	-33.53987 °C
Cp	1.32471
Temperature	-32.56648 °C
Cp	1.323012
Temperature	-31.5931 °C
Cp	1.321323
Temperature	-30.61971 °C
Cp	1.319657
Temperature	-29.64633 °C
Cp	1.317968
Temperature	-28.67294 °C
Cp	1.316286
Temperature	-27.69955 °C
Cp	1.314585
Temperature	-26.72617 °C
Cp	1.312857
Temperature	-25.75278 °C
Cp	1.31111
Temperature	-24.7794 °C
Cp	1.309333
Temperature	-23.80601 °C
Cp	1.307544
Temperature	-22.83262 °C
Cp	1.30575
Temperature	-21.85924 °C
Cp	1.303941
Temperature	-20.88585 °C
Cp	1.302132
Temperature	-19.91247 °C
Cp	1.300313
Temperature	-18.93908 °C
Cp	1.298512
Temperature	-17.96569 °C
Cp	1.296728
Temperature	-16.99231 °C
Cp	1.294939
Temperature	-16.01892 °C
Cp	1.293198
Temperature	-15.04554 °C
Cp	1.291453
Temperature	-14.07215 °C
Cp	1.289723
Temperature	-13.09876 °C
Cp	1.288007
Temperature	-12.12538 °C
Cp	1.286283
Temperature	-11.15199 °C
Cp	1.284578
Temperature	-10.17861 °C
Cp	1.282885
Temperature	-9.205221 °C
Cp	1.281173
Temperature	-8.231835 °C
Cp	1.279472
Temperature	-7.258449 °C
Cp	1.277766
Temperature	-6.285063 °C
Cp	1.276053
Temperature	-5.311677 °C
Cp	1.274341
Temperature	-4.338291 °C
Cp	1.272592
Temperature	-3.364905 °C
Cp	1.270844
Temperature	-2.391519 °C
Cp	1.269062
Temperature	-1.418133 °C
Cp	1.267264
Temperature	-0.4447474 °C
Cp	1.265435
Temperature	0.5286385 °C
Cp	1.263575
Temperature	1.502024 °C
Cp	1.261727
Temperature	2.47541 °C
Cp	1.259854
Temperature	3.448796 °C
Cp	1.257978
Temperature	4.422182 °C
Cp	1.256109
Temperature	5.395568 °C
Cp	1.254244
Temperature	6.368954 °C
Cp	1.252392
Temperature	7.34234 °C
Cp	1.250552
Temperature	8.315726 °C
Cp	1.248704
Temperature	9.289112 °C
Cp	1.246884
Temperature	10.2625 °C
Cp	1.245078
Temperature	11.23588 °C
Cp	1.243287
Temperature	12.20927 °C
Cp	1.241522
Temperature	13.18266 °C
Cp	1.239778
Temperature	14.15604 °C
Cp	1.238068
Temperature	15.12943 °C
Cp	1.236393
Temperature	16.10281 °C
Cp	1.234762
Temperature	17.0762 °C
Cp	1.233176
Temperature	18.04959 °C
Cp	1.231629
Temperature	19.02297 °C
Cp	1.230129
Temperature	19.99636 °C
Cp	1.228694
Temperature	20.96974 °C
Cp	1.22731
Temperature	21.94313 °C
Cp	1.225968
Temperature	22.91652 °C
Cp	1.224676
Temperature	23.8899 °C
Cp	1.223431
Temperature	24.86329 °C
Cp	1.222217
Temperature	25.83667 °C
Cp	1.221065
Temperature	26.81006 °C
Cp	1.219919
Temperature	27.78345 °C
Cp	1.218811
Temperature	28.75683 °C
Cp	1.21773
Temperature	29.73022 °C
Cp	1.216663
Temperature	30.7036 °C
Cp	1.2156
Temperature	31.67699 °C
Cp	1.214515
Temperature	32.65038 °C
Cp	1.213439
Temperature	33.62376 °C
Cp	1.21234
Temperature	34.59715 °C
Cp	1.211209
Temperature	35.57053 °C
Cp	1.210051
Temperature	36.54392 °C
Cp	1.208868
Temperature	37.5173 °C
Cp	1.207666
Temperature	38.49069 °C
Cp	1.206439
Temperature	39.46408 °C
Cp	1.205199
Temperature	40.43746 °C
Cp	1.203959
Temperature	41.41085 °C
Cp	1.202712
Temperature	42.38424 °C
Cp	1.20147
Temperature	43.35762 °C
Cp	1.200231
Temperature	44.33101 °C
Cp	1.199
Temperature	45.30439 °C
Cp	1.197777
Temperature	46.27778 °C
Cp	1.19657
Temperature	47.25116 °C
Cp	1.195367
Temperature	48.22455 °C
Cp	1.194179
Temperature	49.19794 °C
Cp	1.19301
Temperature	50.17132 °C
Cp	1.191849
Temperature	51.14471 °C
Cp	1.190694
Temperature	52.11809 °C
Cp	1.189555
Temperature	53.09148 °C
Cp	1.18843
Temperature	54.06487 °C
Cp	1.187311
Temperature	55.03825 °C
Cp	1.186195
Temperature	56.01164 °C
Cp	1.185095
Temperature	56.98502 °C
Cp	1.183997
Temperature	57.95841 °C
Cp	1.182894
Temperature	58.93179 °C
Cp	1.181793
Temperature	59.90518 °C
Cp	1.180693
Temperature	60.87857 °C
Cp	1.179595
Temperature	61.85195 °C
Cp	1.178501
Temperature	62.82534 °C
Cp	1.177406
Temperature	63.79873 °C
Cp	1.176313
Temperature	64.77211 °C
Cp	1.175239
Temperature	65.7455 °C
Cp	1.17417
Temperature	66.71888 °C
Cp	1.173105
Temperature	67.69227 °C
Cp	1.172037
Temperature	68.66566 °C
Cp	1.170989
Temperature	69.63904 °C
Cp	1.169948
Temperature	70.61243 °C
Cp	1.168905
Temperature	71.58582 °C
Cp	1.167872
Temperature	72.5592 °C
Cp	1.166849
Temperature	73.53259 °C
Cp	1.165851
Temperature	74.50597 °C
Cp	1.164848
Temperature	75.47935 °C
Cp	1.163876
Temperature	76.45274 °C
Cp	1.162926
Temperature	77.42612 °C
Cp	1.162008
Temperature	78.39951 °C
Cp	1.161113
Temperature	79.3729 °C
Cp	1.160219
Temperature	80.34628 °C
Cp	1.159377
Temperature	81.31967 °C
Cp	1.158546
Temperature	82.29306 °C
Cp	1.157726
Temperature	83.26644 °C
Cp	1.15692
Temperature	84.23983 °C
Cp	1.156126
Temperature	85.21322 °C
Cp	1.155375
Temperature	86.1866 °C
Cp	1.154604
Temperature	87.15999 °C
Cp	1.153869
Temperature	88.13337 °C
Cp	1.153158
Temperature	89.10676 °C
Cp	1.152474
Temperature	90.08015 °C
Cp	1.15181
Temperature	91.05353 °C
Cp	1.151134
Temperature	92.02692 °C
Cp	1.150513
Temperature	93.00031 °C
Cp	1.149892
Temperature	93.97369 °C
Cp	1.149266
Temperature	94.94707 °C
Cp	1.148642
Temperature	95.92046 °C
Cp	1.148019
Temperature	96.89384 °C
Cp	1.147402
Temperature	97.86723 °C
Cp	1.146799
Temperature	98.84062 °C
Cp	1.146191
Temperature	99.814 °C
Cp	1.145602
Temperature	100.7874 °C
Cp	1.14503
Temperature	101.7608 °C
Cp	1.144469
Temperature	102.7342 °C
Cp	1.143921
Temperature	103.7076 °C
Cp	1.143383
Temperature	104.6809 °C
Cp	1.142861
Temperature	105.6543 °C
Cp	1.142345
Temperature	106.6277 °C
Cp	1.141835
Temperature	107.6011 °C
Cp	1.141335
Temperature	108.5745 °C
Cp	1.140846
Temperature	109.5479 °C
Cp	1.140365
Temperature	110.5212 °C
Cp	1.139891
Temperature	111.4946 °C
Cp	1.139429
Temperature	112.468 °C
Cp	1.138976
Temperature	113.4414 °C
Cp	1.13853
Temperature	114.4148 °C
Cp	1.138092
Temperature	115.3882 °C
Cp	1.137654
Temperature	116.3616 °C
Cp	1.137223
Temperature	117.335 °C
Cp	1.136785
Temperature	118.3083 °C
Cp	1.136338
Temperature	119.2817 °C
Cp	1.13588
Temperature	120.2551 °C
Cp	1.13541
Temperature	121.2285 °C
Cp	1.134927
Temperature	122.2019 °C
Cp	1.134417
Temperature	123.1753 °C
Cp	1.133892
Temperature	124.1487 °C
Cp	1.133347
Temperature	125.122 °C
Cp	1.132786
Temperature	126.0954 °C
Cp	1.132206
Temperature	127.0688 °C
Cp	1.131606
Temperature	128.0422 °C
Cp	1.130999
Temperature	129.0156 °C
Cp	1.130384
Temperature	129.989 °C
Cp	1.129765
Temperature	130.9624 °C
Cp	1.129147
Temperature	131.9357 °C
Cp	1.12854
Temperature	132.9091 °C
Cp	1.127949
Temperature	133.8825 °C
Cp	1.127383
Temperature	134.8559 °C
Cp	1.126841
Temperature	135.8293 °C
Cp	1.126334
Temperature	136.8027 °C
Cp	1.125871
Temperature	137.7761 °C
Cp	1.125443
Temperature	138.7494 °C
Cp	1.125058
Temperature	139.7228 °C
Cp	1.124701
Temperature	140.6962 °C
Cp	1.124397
Temperature	141.6696 °C
Cp	1.124114
Temperature	142.643 °C
Cp	1.123854
Temperature	143.6164 °C
Cp	1.123612
Temperature	144.5898 °C
Cp	1.123385
Temperature	145.5631 °C
Cp	1.123182
Temperature	146.5365 °C
Cp	1.12296
Temperature	147.5099 °C
Cp	1.12275
Temperature	148.4833 °C
Cp	1.122543
Temperature	149.4567 °C
Cp	1.122327
Temperature	150.4301 °C
Cp	1.122099
Temperature	151.4035 °C
Cp	1.121837
Temperature	152.3768 °C
Cp	1.121582
Temperature	153.3502 °C
Cp	1.121289
Temperature	154.3236 °C
Cp	1.120967
Temperature	155.297 °C
Cp	1.120616
Temperature	156.2704 °C
Cp	1.120238
Temperature	157.2438 °C
Cp	1.119862
Temperature	158.2172 °C
Cp	1.119444
Temperature	159.1906 °C
Cp	1.119028
Temperature	160.1639 °C
Cp	1.118613
Temperature	161.1373 °C
Cp	1.118202
Temperature	162.1107 °C
Cp	1.117795
Temperature	163.0841 °C
Cp	1.117374
Temperature	164.0575 °C
Cp	1.116987
Temperature	165.0309 °C
Cp	1.116595
Temperature	166.0042 °C
Cp	1.116198
Temperature	166.9776 °C
Cp	1.1158
Temperature	167.951 °C
Cp	1.115402
Temperature	168.9244 °C
Cp	1.115006
Temperature	169.8978 °C
Cp	1.11462
Temperature	170.8712 °C
Cp	1.114223
Temperature	171.8446 °C
Cp	1.113836
Temperature	172.8179 °C
Cp	1.113458
Temperature	173.7913 °C
Cp	1.113085
Temperature	174.7647 °C
Cp	1.112712
Temperature	175.7381 °C
Cp	1.112323
Temperature	176.7115 °C
Cp	1.111957
Temperature	177.6849 °C
Cp	1.111578
Temperature	178.6583 °C
Cp	1.111185
Temperature	179.6317 °C
Cp	1.110789
Temperature	180.605 °C
Cp	1.110391
Temperature	181.5784 °C
Cp	1.110016
Temperature	182.5518 °C
Cp	1.109611
Temperature	183.5252 °C
Cp	1.109232
Temperature	184.4986 °C
Cp	1.108873
Temperature	185.472 °C
Cp	1.108531
Temperature	186.4454 °C
Cp	1.108199
Temperature	187.4187 °C
Cp	1.107851
Temperature	188.3921 °C
Cp	1.107551
Temperature	189.3655 °C
Cp	1.107238
Temperature	190.3389 °C
Cp	1.106917
Temperature	191.3123 °C
Cp	1.106589
Temperature	192.2857 °C
Cp	1.106259
Temperature	193.259 °C
Cp	1.105958
Temperature	194.2324 °C
Cp	1.105619
Temperature	195.2058 °C
Cp	1.105301
Temperature	196.1792 °C
Cp	1.105002
Temperature	197.1526 °C
Cp	1.104718
Temperature	198.126 °C
Cp	1.104445
Temperature	199.0994 °C
Cp	1.104161
Temperature	200.0728 °C
Cp	1.103914
Temperature	201.0461 °C
Cp	1.103657
Temperature	202.0195 °C
Cp	1.103395
Temperature	202.9929 °C
Cp	1.103125
Temperature	203.9663 °C
Cp	1.102847
Temperature	204.9397 °C
Cp	1.102563
Temperature	205.9131 °C
Cp	1.102283
Temperature	206.8865 °C
Cp	1.101985
Temperature	207.8598 °C
Cp	1.10169
Temperature	208.8332 °C
Cp	1.101394
Temperature	209.8066 °C
Cp	1.101099
Temperature	210.78 °C
Cp	1.1008
Temperature	211.7534 °C
Cp	1.10049
Temperature	212.7268 °C
Cp	1.100193
Temperature	213.7002 °C
Cp	1.099886
Temperature	214.6735 °C
Cp	1.099577
Temperature	215.6469 °C
Cp	1.099268
Temperature	216.6203 °C
Cp	1.098965
Temperature	217.5937 °C
Cp	1.098685
Temperature	218.5671 °C
Cp	1.098396
Temperature	219.5405 °C
Cp	1.098134
Temperature	220.5139 °C
Cp	1.097895
Temperature	221.4872 °C
Cp	1.09768
Temperature	222.4606 °C
Cp	1.097485
Temperature	223.434 °C
Cp	1.097292
Temperature	224.4074 °C
Cp	1.09714
Temperature	225.3808 °C
Cp	1.096991
Temperature	226.3542 °C
Cp	1.096844
Temperature	227.3276 °C
Cp	1.096699
Temperature	228.3009 °C
Cp	1.096559
Temperature	229.2743 °C
Cp	1.096442
Temperature	230.2477 °C
Cp	1.096296
Temperature	231.2211 °C
Cp	1.096164
Temperature	232.1945 °C
Cp	1.09604
Temperature	233.1679 °C
Cp	1.095924
Temperature	234.1413 °C
Cp	1.095807
Temperature	235.1147 °C
Cp	1.095665
Temperature	236.088 °C
Cp	1.095557
Temperature	237.0614 °C
Cp	1.095433
Temperature	238.0348 °C
Cp	1.095296
Temperature	239.0082 °C
Cp	1.095147
Temperature	239.9816 °C
Cp	1.094995
Temperature	240.955 °C
Cp	1.094843
Temperature	241.9283 °C
Cp	1.094705
Temperature	242.9017 °C
Cp	1.094562
Temperature	243.8751 °C
Cp	1.094442
Temperature	244.8485 °C
Cp	1.094344
Temperature	245.8219 °C
Cp	1.094266
Temperature	246.7953 °C
Cp	1.094209
Temperature	247.7687 °C
Cp	1.094161
Temperature	248.7421 °C
Cp	1.094144
Temperature	249.7154 °C
Cp	1.094133
Temperature	250.6888 °C
Cp	1.094127
Temperature	251.6622 °C
Cp	1.094126
Temperature	252.6356 °C
Cp	1.094127
Temperature	253.609 °C
Cp	1.094138
Temperature	254.5824 °C
Cp	1.09413
Temperature	255.5558 °C
Cp	1.094123
Temperature	256.5291 °C
Cp	1.094111
Temperature	257.5025 °C
Cp	1.094087
Temperature	258.4759 °C
Cp	1.094046
Temperature	259.4493 °C
Cp	1.093978
Temperature	260.4227 °C
Cp	1.093895
Temperature	261.3961 °C
Cp	1.093783
Temperature	262.3694 °C
Cp	1.093645
Temperature	263.3428 °C
Cp	1.093483
Temperature	264.3162 °C
Cp	1.093302
Temperature	265.2896 °C
Cp	1.093109
Temperature	266.263 °C
Cp	1.092906
Temperature	267.2364 °C
Cp	1.092704
Temperature	268.2098 °C
Cp	1.092511
Temperature	269.1832 °C
Cp	1.092331
Temperature	270.1566 °C
Cp	1.092174
Temperature	271.1299 °C
Cp	1.092046
Temperature	272.1033 °C
Cp	1.091947
Temperature	273.0767 °C
Cp	1.091882
Temperature	274.0501 °C
Cp	1.091853
Temperature	275.0235 °C
Cp	1.091859
Temperature	275.9969 °C
Cp	1.091895
Temperature	276.9702 °C
Cp	1.091957
Temperature	277.9436 °C
Cp	1.092036
Temperature	278.917 °C
Cp	1.092132
Temperature	279.8904 °C
Cp	1.09223
Temperature	280.8638 °C
Cp	1.092323
Temperature	281.8372 °C
Cp	1.092405
Temperature	282.8105 °C
Cp	1.092468
Temperature	283.7839 °C
Cp	1.092513
Temperature	284.7573 °C
Cp	1.092525
Temperature	285.7307 °C
Cp	1.092512
Temperature	286.7041 °C
Cp	1.092472
Temperature	287.6775 °C
Cp	1.092405
Temperature	288.6509 °C
Cp	1.092313
Temperature	289.6243 °C
Cp	1.092197
Temperature	290.5977 °C
Cp	1.09207
Temperature	291.571 °C
Cp	1.091931
Temperature	292.5444 °C
Cp	1.091785
Temperature	293.5178 °C
Cp	1.091641
Temperature	294.4912 °C
Cp	1.091506
Temperature	295.4646 °C
Cp	1.091387
Temperature	296.438 °C
Cp	1.091282
Temperature	297.4113 °C
Cp	1.091201
Temperature	298.3847 °C
Cp	1.091145
Temperature	299.3581 °C
Cp	1.091112
Temperature	300.3315 °C
Cp	1.091102
Temperature	301.3049 °C
Cp	1.091107
Temperature	302.2783 °C
Cp	1.091137
Temperature	303.2517 °C
Cp	1.091177
Temperature	304.2251 °C
Cp	1.091226
Temperature	305.1984 °C
Cp	1.09128
Temperature	306.1718 °C
Cp	1.091336
Temperature	307.1452 °C
Cp	1.091403
Temperature	308.1186 °C
Cp	1.091453
Temperature	309.092 °C
Cp	1.091506
Temperature	310.0654 °C
Cp	1.091561
Temperature	311.0388 °C
Cp	1.091617
Temperature	312.0121 °C
Cp	1.09167
Temperature	312.9855 °C
Cp	1.091716
Temperature	313.9589 °C
Cp	1.091762
Temperature	314.9323 °C
Cp	1.091805
Temperature	315.9057 °C
Cp	1.091838
Temperature	316.8791 °C
Cp	1.09186
Temperature	317.8524 °C
Cp	1.091871
Temperature	318.8258 °C
Cp	1.091872
Temperature	319.7992 °C
Cp	1.091867
Temperature	320.7726 °C
Cp	1.091838
Temperature	321.746 °C
Cp	1.0918
Temperature	322.7194 °C
Cp	1.091752
Temperature	323.6928 °C
Cp	1.091689
Temperature	324.6662 °C
Cp	1.091611
Temperature	325.6396 °C
Cp	1.091508
Temperature	326.6129 °C
Cp	1.091406
Temperature	327.5863 °C
Cp	1.091285
Temperature	328.5597 °C
Cp	1.09115
Temperature	329.5331 °C
Cp	1.091009
Temperature	330.5065 °C
Cp	1.09087
Temperature	331.4799 °C
Cp	1.090747
Temperature	332.4532 °C
Cp	1.090628
Temperature	333.4266 °C
Cp	1.090536
Temperature	334.4 °C
Cp	1.090472
Temperature	335.3734 °C
Cp	1.090437
Temperature	336.3468 °C
Cp	1.090431
Temperature	337.3202 °C
Cp	1.090455
Temperature	338.2935 °C
Cp	1.090503
Temperature	339.2669 °C
Cp	1.090573
Temperature	340.2403 °C
Cp	1.090658
Temperature	341.2137 °C
Cp	1.090753
Temperature	342.1871 °C
Cp	1.090853
Temperature	343.1605 °C
Cp	1.090952
Temperature	344.1339 °C
Cp	1.09105
Temperature	345.1073 °C
Cp	1.091141
Temperature	346.0807 °C
Cp	1.091225
Temperature	347.054 °C
Cp	1.091303
Temperature	348.0274 °C
Cp	1.091379
Temperature	349.0008 °C
Cp	1.091453
Temperature	349.9742 °C
Cp	1.091537
Temperature	350.9476 °C
Cp	1.091633
Temperature	351.921 °C
Cp	1.091743
Temperature	352.8943 °C
Cp	1.091874
Temperature	353.8677 °C
Cp	1.092028
Temperature	354.8411 °C
Cp	1.092206
Temperature	355.8145 °C
Cp	1.092411
Temperature	356.7879 °C
Cp	1.092628
Temperature	357.7613 °C
Cp	1.092862
Temperature	358.7346 °C
Cp	1.093102
Temperature	359.708 °C
Cp	1.093338
Temperature	360.6814 °C
Cp	1.093559
Temperature	361.6548 °C
Cp	1.093752
Temperature	362.6282 °C
Cp	1.093915
Temperature	363.6016 °C
Cp	1.094036
Temperature	364.575 °C
Cp	1.094117
Temperature	365.5484 °C
Cp	1.094159
Temperature	366.5218 °C
Cp	1.094172
Temperature	367.4951 °C
Cp	1.094165
Temperature	368.4685 °C
Cp	1.094163
Temperature	369.4419 °C
Cp	1.094182
Temperature	370.4153 °C
Cp	1.094244
Temperature	371.3887 °C
Cp	1.094375
Temperature	372.3621 °C
Cp	1.094598
Temperature	373.3354 °C
Cp	1.094937
Temperature	374.3088 °C
Cp	1.095389
Temperature	375.2822 °C
Cp	1.095973
Temperature	376.2556 °C
Cp	1.096685
Temperature	377.229 °C
Cp	1.097506
Temperature	378.2024 °C
Cp	1.098406
Temperature	379.1758 °C
Cp	1.099338
Temperature	380.1492 °C
Cp	1.10027
Temperature	381.1225 °C
Cp	1.10112
Temperature	382.0959 °C
Cp	1.101818
Temperature	383.0693 °C
Cp	1.10229
Temperature	384.0427 °C
Cp	1.102459
Temperature	385.0161 °C
Cp	1.102253
Temperature	385.9895 °C
Cp	1.101596
Temperature	386.9629 °C
Cp	1.100438
Temperature	387.9362 °C
Cp	1.098736
Temperature	388.9096 °C
Cp	1.096461
Temperature	389.883 °C
Cp	1.093614
Temperature	390.8564 °C
Cp	1.090208
Temperature	391.8298 °C
Cp	1.086278
Temperature	392.8032 °C
Cp	1.081887
Temperature	393.7766 °C
Cp	1.077096
Temperature	394.7499 °C
Cp	1.072007
Temperature	395.7233 °C
Cp	1.066707
[Rev Cp Calibration]
Date Applied	24/10/2024 12:37:31
Description	From -89.998 °C to 390.542 °C at 2.000°C/min
Gas Type	Nitrogen
Pan Type	Tzero Aluminum
Source Files 1	C:\ProgramData\TA Instruments\TRIOS\Data\Reverse Heat Capacity Calibration(6).tri
GUID	ba867d72-cfbb-486e-971e-e86aa544cc02
Temperature	-89.99799 °C
Cp	1.070076
Temperature	-89.03691 °C
Cp	1.072008
Temperature	-88.07584 °C
Cp	1.073556
Temperature	-87.11475 °C
Cp	1.074743
Temperature	-86.15367 °C
Cp	1.075597
Temperature	-85.1926 °C
Cp	1.076163
Temperature	-84.23151 °C
Cp	1.076477
Temperature	-83.27043 °C
Cp	1.076579
Temperature	-82.30936 °C
Cp	1.076527
Temperature	-81.34827 °C
Cp	1.076322
Temperature	-80.38719 °C
Cp	1.076039
Temperature	-79.42612 °C
Cp	1.07571
Temperature	-78.46503 °C
Cp	1.075361
Temperature	-77.50395 °C
Cp	1.075011
Temperature	-76.54288 °C
Cp	1.074656
Temperature	-75.58179 °C
Cp	1.074359
Temperature	-74.62071 °C
Cp	1.074086
Temperature	-73.65964 °C
Cp	1.073842
Temperature	-72.69855 °C
Cp	1.073627
Temperature	-71.73747 °C
Cp	1.073442
Temperature	-70.7764 °C
Cp	1.07329
Temperature	-69.81532 °C
Cp	1.073148
Temperature	-68.85423 °C
Cp	1.073021
Temperature	-67.89315 °C
Cp	1.072902
Temperature	-66.93208 °C
Cp	1.072782
Temperature	-65.97099 °C
Cp	1.072656
Temperature	-65.00991 °C
Cp	1.072518
Temperature	-64.04884 °C
Cp	1.072374
Temperature	-63.08775 °C
Cp	1.072201
Temperature	-62.12667 °C
Cp	1.072019
Temperature	-61.1656 °C
Cp	1.071827
Temperature	-60.20451 °C
Cp	1.071624
Temperature	-59.24343 °C
Cp	1.071411
Temperature	-58.28236 °C
Cp	1.071167
Temperature	-57.32127 °C
Cp	1.070956
Temperature	-56.3602 °C
Cp	1.070724
Temperature	-55.39911 °C
Cp	1.070483
Temperature	-54.43803 °C
Cp	1.070242
Temperature	-53.47696 °C
Cp	1.070009
Temperature	-52.51587 °C
Cp	1.069825
Temperature	-51.55479 °C
Cp	1.069601
Temperature	-50.59372 °C
Cp	1.069418
Temperature	-49.63263 °C
Cp	1.069267
Temperature	-48.67155 °C
Cp	1.069138
Temperature	-47.71048 °C
Cp	1.069021
Temperature	-46.74939 °C
Cp	1.068875
Temperature	-45.78831 °C
Cp	1.068771
Temperature	-44.82724 °C
Cp	1.068634
Temperature	-43.86615 °C
Cp	1.068462
Temperature	-42.90508 °C
Cp	1.068255
Temperature	-41.944 °C
Cp	1.068012
Temperature	-40.98291 °C
Cp	1.067742
Temperature	-40.02184 °C
Cp	1.067427
Temperature	-39.06076 °C
Cp	1.067088
Temperature	-38.09967 °C
Cp	1.066727
Temperature	-37.1386 °C
Cp	1.066349
Temperature	-36.17752 °C
Cp	1.065958
Temperature	-35.21643 °C
Cp	1.065559
Temperature	-34.25536 °C
Cp	1.065162
Temperature	-33.29427 °C
Cp	1.06476
Temperature	-32.33319 °C
Cp	1.064368
Temperature	-31.37212 °C
Cp	1.06399
Temperature	-30.41104 °C
Cp	1.063628
Temperature	-29.44995 °C
Cp	1.063283
Temperature	-28.48887 °C
Cp	1.06295
Temperature	-27.5278 °C
Cp	1.062645
Temperature	-26.56672 °C
Cp	1.062355
Temperature	-25.60563 °C
Cp	1.06208
Temperature	-24.64456 °C
Cp	1.061819
Temperature	-23.68348 °C
Cp	1.061573
Temperature	-22.72239 °C
Cp	1.061345
Temperature	-21.76132 °C
Cp	1.061123
Temperature	-20.80024 °C
Cp	1.060915
Temperature	-19.83916 °C
Cp	1.060719
Temperature	-18.87807 °C
Cp	1.060531
Temperature	-17.917 °C
Cp	1.06035
Temperature	-16.95592 °C
Cp	1.060161
Temperature	-15.99484 °C
Cp	1.059992
Temperature	-15.03376 °C
Cp	1.059817
Temperature	-14.07268 °C
Cp	1.059634
Temperature	-13.1116 °C
Cp	1.059445
Temperature	-12.15052 °C
Cp	1.059248
Temperature	-11.18944 °C
Cp	1.059043
Temperature	-10.22836 °C
Cp	1.058842
Temperature	-9.267276 °C
Cp	1.058615
Temperature	-8.306196 °C
Cp	1.058388
Temperature	-7.345116 °C
Cp	1.058155
Temperature	-6.384036 °C
Cp	1.057911
Temperature	-5.422956 °C
Cp	1.057652
Temperature	-4.461876 °C
Cp	1.057356
Temperature	-3.500796 °C
Cp	1.057063
Temperature	-2.539716 °C
Cp	1.056732
Temperature	-1.578636 °C
Cp	1.056364
Temperature	-0.6175562 °C
Cp	1.05596
Temperature	0.3435238 °C
Cp	1.055523
Temperature	1.304604 °C
Cp	1.055066
Temperature	2.265684 °C
Cp	1.054561
Temperature	3.226764 °C
Cp	1.054035
Temperature	4.187844 °C
Cp	1.053488
Temperature	5.148924 °C
Cp	1.052922
Temperature	6.110003 °C
Cp	1.052337
Temperature	7.071084 °C
Cp	1.051736
Temperature	8.032164 °C
Cp	1.051118
Temperature	8.993243 °C
Cp	1.050488
Temperature	9.954324 °C
Cp	1.049848
Temperature	10.9154 °C
Cp	1.049202
Temperature	11.87648 °C
Cp	1.048552
Temperature	12.83756 °C
Cp	1.047902
Temperature	13.79864 °C
Cp	1.047255
Temperature	14.75972 °C
Cp	1.046615
Temperature	15.7208 °C
Cp	1.045983
Temperature	16.68188 °C
Cp	1.045362
Temperature	17.64296 °C
Cp	1.044756
Temperature	18.60404 °C
Cp	1.044164
Temperature	19.56512 °C
Cp	1.04358
Temperature	20.5262 °C
Cp	1.043027
Temperature	21.48728 °C
Cp	1.042485
Temperature	22.44836 °C
Cp	1.041958
Temperature	23.40944 °C
Cp	1.041446
Temperature	24.37052 °C
Cp	1.040952
Temperature	25.3316 °C
Cp	1.040493
Temperature	26.29268 °C
Cp	1.040022
Temperature	27.25376 °C
Cp	1.039578
Temperature	28.21484 °C
Cp	1.039158
Temperature	29.17592 °C
Cp	1.038758
Temperature	30.137 °C
Cp	1.038373
Temperature	31.09808 °C
Cp	1.037981
Temperature	32.05916 °C
Cp	1.03763
Temperature	33.02024 °C
Cp	1.037276
Temperature	33.98132 °C
Cp	1.03692
Temperature	34.9424 °C
Cp	1.036565
Temperature	35.90348 °C
Cp	1.036213
Temperature	36.86456 °C
Cp	1.035866
Temperature	37.82564 °C
Cp	1.035529
Temperature	38.78672 °C
Cp	1.035195
Temperature	39.7478 °C
Cp	1.034875
Temperature	40.70888 °C
Cp	1.034568
Temperature	41.66996 °C
Cp	1.034276
Temperature	42.63104 °C
Cp	1.033996
Temperature	43.59212 °C
Cp	1.033726
Temperature	44.5532 °C
Cp	1.033469
Temperature	45.51428 °C
Cp	1.033221
Temperature	46.47536 °C
Cp	1.03298
Temperature	47.43644 °C
Cp	1.032744
Temperature	48.39752 °C
Cp	1.032514
Temperature	49.3586 °C
Cp	1.032289
Temperature	50.31968 °C
Cp	1.032065
Temperature	51.28076 °C
Cp	1.031844
Temperature	52.24184 °C
Cp	1.031627
Temperature	53.20292 °C
Cp	1.031413
Temperature	54.164 °C
Cp	1.031203
Temperature	55.12508 °C
Cp	1.030989
Temperature	56.08616 °C
Cp	1.030791
Temperature	57.04724 °C
Cp	1.030595
Temperature	58.00832 °C
Cp	1.030403
Temperature	58.9694 °C
Cp	1.030217
Temperature	59.93048 °C
Cp	1.03004
Temperature	60.89156 °C
Cp	1.029871
Temperature	61.85264 °C
Cp	1.029718
Temperature	62.81372 °C
Cp	1.029567
Temperature	63.7748 °C
Cp	1.02943
Temperature	64.73589 °C
Cp	1.029304
Temperature	65.69696 °C
Cp	1.029185
Temperature	66.65804 °C
Cp	1.02907
Temperature	67.61913 °C
Cp	1.028946
Temperature	68.5802 °C
Cp	1.028831
Temperature	69.54128 °C
Cp	1.028703
Temperature	70.50237 °C
Cp	1.028561
Temperature	71.46344 °C
Cp	1.028404
Temperature	72.42452 °C
Cp	1.028234
Temperature	73.3856 °C
Cp	1.028063
Temperature	74.34668 °C
Cp	1.027861
Temperature	75.30776 °C
Cp	1.027657
Temperature	76.26884 °C
Cp	1.027451
Temperature	77.22992 °C
Cp	1.027243
Temperature	78.191 °C
Cp	1.027036
Temperature	79.15208 °C
Cp	1.026812
Temperature	80.11316 °C
Cp	1.026623
Temperature	81.07424 °C
Cp	1.026431
Temperature	82.03532 °C
Cp	1.026241
Temperature	82.9964 °C
Cp	1.02606
Temperature	83.95748 °C
Cp	1.025891
Temperature	84.91856 °C
Cp	1.025739
Temperature	85.87964 °C
Cp	1.025614
Temperature	86.84072 °C
Cp	1.025493
Temperature	87.8018 °C
Cp	1.0254
Temperature	88.76288 °C
Cp	1.025329
Temperature	89.72396 °C
Cp	1.025274
Temperature	90.68504 °C
Cp	1.025229
Temperature	91.64612 °C
Cp	1.025174
Temperature	92.6072 °C
Cp	1.025138
Temperature	93.56828 °C
Cp	1.025083
Temperature	94.52936 °C
Cp	1.025008
Temperature	95.49044 °C
Cp	1.024912
Temperature	96.45152 °C
Cp	1.024796
Temperature	97.4126 °C
Cp	1.024671
Temperature	98.37368 °C
Cp	1.024506
Temperature	99.33476 °C
Cp	1.02433
Temperature	100.2958 °C
Cp	1.024144
Temperature	101.2569 °C
Cp	1.023948
Temperature	102.218 °C
Cp	1.023743
Temperature	103.1791 °C
Cp	1.023522
Temperature	104.1402 °C
Cp	1.023309
Temperature	105.1012 °C
Cp	1.023089
Temperature	106.0623 °C
Cp	1.022866
Temperature	107.0234 °C
Cp	1.022644
Temperature	107.9845 °C
Cp	1.022427
Temperature	108.9456 °C
Cp	1.022218
Temperature	109.9066 °C
Cp	1.022022
Temperature	110.8677 °C
Cp	1.021836
Temperature	111.8288 °C
Cp	1.021666
Temperature	112.7899 °C
Cp	1.021512
Temperature	113.751 °C
Cp	1.021374
Temperature	114.712 °C
Cp	1.02125
Temperature	115.6731 °C
Cp	1.021137
Temperature	116.6342 °C
Cp	1.021041
Temperature	117.5953 °C
Cp	1.020953
Temperature	118.5564 °C
Cp	1.020872
Temperature	119.5174 °C
Cp	1.020796
Temperature	120.4785 °C
Cp	1.020725
Temperature	121.4396 °C
Cp	1.020659
Temperature	122.4007 °C
Cp	1.020587
Temperature	123.3618 °C
Cp	1.020515
Temperature	124.3228 °C
Cp	1.02044
Temperature	125.2839 °C
Cp	1.020359
Temperature	126.245 °C
Cp	1.02027
Temperature	127.2061 °C
Cp	1.020167
Temperature	128.1672 °C
Cp	1.020057
Temperature	129.1282 °C
Cp	1.019933
Temperature	130.0893 °C
Cp	1.019793
Temperature	131.0504 °C
Cp	1.019638
Temperature	132.0115 °C
Cp	1.019471
Temperature	132.9726 °C
Cp	1.019292
Temperature	133.9336 °C
Cp	1.019107
Temperature	134.8947 °C
Cp	1.018912
Temperature	135.8558 °C
Cp	1.018717
Temperature	136.8169 °C
Cp	1.018527
Temperature	137.778 °C
Cp	1.018344
Temperature	138.739 °C
Cp	1.018171
Temperature	139.7001 °C
Cp	1.018004
Temperature	140.6612 °C
Cp	1.01787
Temperature	141.6223 °C
Cp	1.01775
Temperature	142.5834 °C
Cp	1.017652
Temperature	143.5444 °C
Cp	1.017578
Temperature	144.5055 °C
Cp	1.017534
Temperature	145.4666 °C
Cp	1.017536
Temperature	146.4277 °C
Cp	1.017545
Temperature	147.3888 °C
Cp	1.017595
Temperature	148.3498 °C
Cp	1.017679
Temperature	149.3109 °C
Cp	1.01779
Temperature	150.272 °C
Cp	1.01792
Temperature	151.2331 °C
Cp	1.018043
Temperature	152.1942 °C
Cp	1.018199
Temperature	153.1552 °C
Cp	1.018339
Temperature	154.1163 °C
Cp	1.018458
Temperature	155.0774 °C
Cp	1.018552
Temperature	156.0385 °C
Cp	1.018618
Temperature	156.9996 °C
Cp	1.018662
Temperature	157.9606 °C
Cp	1.018664
Temperature	158.9217 °C
Cp	1.018632
Temperature	159.8828 °C
Cp	1.018575
Temperature	160.8439 °C
Cp	1.018492
Temperature	161.805 °C
Cp	1.018383
Temperature	162.766 °C
Cp	1.01825
Temperature	163.7271 °C
Cp	1.018087
Temperature	164.6882 °C
Cp	1.017917
Temperature	165.6493 °C
Cp	1.017726
Temperature	166.6104 °C
Cp	1.017522
Temperature	167.5714 °C
Cp	1.01731
Temperature	168.5325 °C
Cp	1.017098
Temperature	169.4936 °C
Cp	1.016902
Temperature	170.4547 °C
Cp	1.016695
Temperature	171.4158 °C
Cp	1.016508
Temperature	172.3768 °C
Cp	1.016342
Temperature	173.3379 °C
Cp	1.016195
Temperature	174.299 °C
Cp	1.016065
Temperature	175.2601 °C
Cp	1.015927
Temperature	176.2212 °C
Cp	1.015838
Temperature	177.1822 °C
Cp	1.015746
Temperature	178.1433 °C
Cp	1.015651
Temperature	179.1044 °C
Cp	1.015555
Temperature	180.0655 °C
Cp	1.015459
Temperature	181.0266 °C
Cp	1.015401
Temperature	181.9876 °C
Cp	1.015288
Temperature	182.9487 °C
Cp	1.015195
Temperature	183.9098 °C
Cp	1.015117
Temperature	184.8709 °C
Cp	1.01505
Temperature	185.832 °C
Cp	1.014988
Temperature	186.793 °C
Cp	1.014927
Temperature	187.7541 °C
Cp	1.014849
Temperature	188.7152 °C
Cp	1.014789
Temperature	189.6763 °C
Cp	1.01471
Temperature	190.6374 °C
Cp	1.014614
Temperature	191.5984 °C
Cp	1.014503
Temperature	192.5595 °C
Cp	1.014381
Temperature	193.5206 °C
Cp	1.014268
Temperature	194.4817 °C
Cp	1.014122
Temperature	195.4428 °C
Cp	1.013984
Temperature	196.4038 °C
Cp	1.013853
Temperature	197.3649 °C
Cp	1.013726
Temperature	198.326 °C
Cp	1.013603
Temperature	199.2871 °C
Cp	1.013467
Temperature	200.2482 °C
Cp	1.013359
Temperature	201.2092 °C
Cp	1.013243
Temperature	202.1703 °C
Cp	1.013123
Temperature	203.1314 °C
Cp	1.013002
Temperature	204.0925 °C
Cp	1.012884
Temperature	205.0536 °C
Cp	1.012788
Temperature	206.0146 °C
Cp	1.012674
Temperature	206.9757 °C
Cp	1.012579
Temperature	207.9368 °C
Cp	1.012501
Temperature	208.8979 °C
Cp	1.012439
Temperature	209.859 °C
Cp	1.012389
Temperature	210.82 °C
Cp	1.012351
Temperature	211.7811 °C
Cp	1.012312
Temperature	212.7422 °C
Cp	1.01229
Temperature	213.7033 °C
Cp	1.012262
Temperature	214.6644 °C
Cp	1.012227
Temperature	215.6254 °C
Cp	1.012183
Temperature	216.5865 °C
Cp	1.012129
Temperature	217.5476 °C
Cp	1.012077
Temperature	218.5087 °C
Cp	1.01199
Temperature	219.4698 °C
Cp	1.011897
Temperature	220.4308 °C
Cp	1.011793
Temperature	221.3919 °C
Cp	1.011674
Temperature	222.353 °C
Cp	1.011537
Temperature	223.3141 °C
Cp	1.011362
Temperature	224.2752 °C
Cp	1.011194
Temperature	225.2362 °C
Cp	1.010993
Temperature	226.1973 °C
Cp	1.010766
Temperature	227.1584 °C
Cp	1.010517
Temperature	228.1195 °C
Cp	1.010251
Temperature	229.0806 °C
Cp	1.009998
Temperature	230.0416 °C
Cp	1.009703
Temperature	231.0027 °C
Cp	1.009422
Temperature	231.9638 °C
Cp	1.009156
Temperature	232.9249 °C
Cp	1.008906
Temperature	233.886 °C
Cp	1.008675
Temperature	234.847 °C
Cp	1.008462
Temperature	235.8081 °C
Cp	1.008258
Temperature	236.7692 °C
Cp	1.00809
Temperature	237.7303 °C
Cp	1.007934
Temperature	238.6914 °C
Cp	1.007793
Temperature	239.6524 °C
Cp	1.007668
Temperature	240.6135 °C
Cp	1.007562
Temperature	241.5746 °C
Cp	1.007487
Temperature	242.5357 °C
Cp	1.00741
Temperature	243.4967 °C
Cp	1.00736
Temperature	244.4578 °C
Cp	1.007332
Temperature	245.4189 °C
Cp	1.007321
Temperature	246.38 °C
Cp	1.007321
Temperature	247.3411 °C
Cp	1.007312
Temperature	248.3022 °C
Cp	1.007331
Temperature	249.2632 °C
Cp	1.007338
Temperature	250.2243 °C
Cp	1.007335
Temperature	251.1854 °C
Cp	1.00732
Temperature	252.1465 °C
Cp	1.007295
Temperature	253.1076 °C
Cp	1.007277
Temperature	254.0686 °C
Cp	1.007227
Temperature	255.0297 °C
Cp	1.007179
Temperature	255.9908 °C
Cp	1.007133
Temperature	256.9519 °C
Cp	1.00709
Temperature	257.913 °C
Cp	1.007049
Temperature	258.874 °C
Cp	1.007012
Temperature	259.8351 °C
Cp	1.006978
Temperature	260.7962 °C
Cp	1.006956
Temperature	261.7573 °C
Cp	1.00694
Temperature	262.7184 °C
Cp	1.006934
Temperature	263.6794 °C
Cp	1.006939
Temperature	264.6405 °C
Cp	1.00696
Temperature	265.6016 °C
Cp	1.006999
Temperature	266.5627 °C
Cp	1.007054
Temperature	267.5237 °C
Cp	1.007131
Temperature	268.4848 °C
Cp	1.00723
Temperature	269.4459 °C
Cp	1.00735
Temperature	270.407 °C
Cp	1.007493
Temperature	271.3681 °C
Cp	1.007656
Temperature	272.3292 °C
Cp	1.007839
Temperature	273.2902 °C
Cp	1.008039
Temperature	274.2513 °C
Cp	1.008257
Temperature	275.2124 °C
Cp	1.008488
Temperature	276.1735 °C
Cp	1.008731
Temperature	277.1346 °C
Cp	1.008977
Temperature	278.0956 °C
Cp	1.009237
Temperature	279.0567 °C
Cp	1.009498
Temperature	280.0178 °C
Cp	1.009757
Temperature	280.9789 °C
Cp	1.010014
Temperature	281.9399 °C
Cp	1.010267
Temperature	282.901 °C
Cp	1.010515
Temperature	283.8621 °C
Cp	1.01076
Temperature	284.8232 °C
Cp	1.010993
Temperature	285.7843 °C
Cp	1.011222
Temperature	286.7454 °C
Cp	1.011447
Temperature	287.7064 °C
Cp	1.011665
Temperature	288.6675 °C
Cp	1.011876
Temperature	289.6286 °C
Cp	1.012079
Temperature	290.5897 °C
Cp	1.01228
Temperature	291.5508 °C
Cp	1.012474
Temperature	292.5118 °C
Cp	1.012662
Temperature	293.4729 °C
Cp	1.012846
Temperature	294.434 °C
Cp	1.013028
Temperature	295.3951 °C
Cp	1.013211
Temperature	296.3561 °C
Cp	1.013391
Temperature	297.3172 °C
Cp	1.013574
Temperature	298.2783 °C
Cp	1.013759
Temperature	299.2394 °C
Cp	1.013947
Temperature	300.2005 °C
Cp	1.014136
Temperature	301.1616 °C
Cp	1.01432
Temperature	302.1226 °C
Cp	1.014511
Temperature	303.0837 °C
Cp	1.014695
Temperature	304.0448 °C
Cp	1.014872
Temperature	305.0059 °C
Cp	1.01504
Temperature	305.9669 °C
Cp	1.015198
Temperature	306.928 °C
Cp	1.015343
Temperature	307.8891 °C
Cp	1.015479
Temperature	308.8502 °C
Cp	1.015595
Temperature	309.8113 °C
Cp	1.015699
Temperature	310.7724 °C
Cp	1.015789
Temperature	311.7334 °C
Cp	1.015865
Temperature	312.6945 °C
Cp	1.015925
Temperature	313.6556 °C
Cp	1.015964
Temperature	314.6167 °C
Cp	1.015999
Temperature	315.5778 °C
Cp	1.016018
Temperature	316.5388 °C
Cp	1.016025
Temperature	317.4999 °C
Cp	1.016024
Temperature	318.461 °C
Cp	1.01602
Temperature	319.4221 °C
Cp	1.016029
Temperature	320.3831 °C
Cp	1.016025
Temperature	321.3442 °C
Cp	1.016037
Temperature	322.3053 °C
Cp	1.016066
Temperature	323.2664 °C
Cp	1.01611
Temperature	324.2275 °C
Cp	1.016169
Temperature	325.1886 °C
Cp	1.016225
Temperature	326.1496 °C
Cp	1.016318
Temperature	327.1107 °C
Cp	1.016411
Temperature	328.0718 °C
Cp	1.016504
Temperature	329.0329 °C
Cp	1.016596
Temperature	329.994 °C
Cp	1.016687
Temperature	330.955 °C
Cp	1.016775
Temperature	331.9161 °C
Cp	1.016864
Temperature	332.8772 °C
Cp	1.016942
Temperature	333.8383 °C
Cp	1.017019
Temperature	334.7993 °C
Cp	1.017093
Temperature	335.7604 °C
Cp	1.017163
Temperature	336.7215 °C
Cp	1.01723
Temperature	337.6826 °C
Cp	1.017295
Temperature	338.6437 °C
Cp	1.017358
Temperature	339.6048 °C
Cp	1.017423
Temperature	340.5658 °C
Cp	1.017491
Temperature	341.5269 °C
Cp	1.017567
Temperature	342.488 °C
Cp	1.017651
Temperature	343.4491 °C
Cp	1.017747
Temperature	344.4102 °C
[...]
151.5917	110.9944	0.2997
151.6000	110.9112	0.2996
151.6083	110.8289	0.2996
151.6167	110.7444	0.2995
151.6250	110.6622	0.2995
151.6333	110.5799	0.2995
151.6417	110.4951	0.2994
151.6500	110.4114	0.2994
151.6583	110.3288	0.2994
151.6667	110.2467	0.2993
151.6750	110.1635	0.2993
151.6833	110.0790	0.2993
151.6917	109.9963	0.2991
151.7000	109.9135	0.2991
151.7083	109.8301	0.2991
151.7167	109.7463	0.2990
151.7250	109.6648	0.2989
151.7333	109.5815	0.2989
151.7417	109.4969	0.2988
151.7500	109.4146	0.2988
151.7583	109.3310	0.2987
151.7667	109.2479	0.2986
151.7750	109.1652	0.2986
151.7833	109.0809	0.2986
151.7917	108.9978	0.2986
151.8000	108.9153	0.2985
151.8083	108.8320	0.2985
151.8167	108.7495	0.2984
151.8250	108.6667	0.2984
151.8333	108.5825	0.2983
151.8417	108.4996	0.2983
151.8500	108.4164	0.2982
151.8583	108.3335	0.2982
151.8667	108.2497	0.2982
151.8750	108.1673	0.2981
151.8833	108.0838	0.2980
151.8917	108.0003	0.2980
151.9000	107.9174	0.2980
151.9083	107.8342	0.2979
151.9167	107.7513	0.2979
151.9250	107.6674	0.2979
151.9333	107.5840	0.2978
151.9417	107.5023	0.2978
151.9500	107.4177	0.2977
151.9583	107.3355	0.2977
151.9667	107.2523	0.2976
151.9750	107.1683	0.2976
151.9833	107.0854	0.2976
151.9917	107.0028	0.2975
152.0000	106.9201	0.2975
152.0083	106.8363	0.2974
152.0167	106.7525	0.2973
152.0250	106.6702	0.2972
152.0333	106.5876	0.2972
152.0417	106.5042	0.2972
152.0500	106.4210	0.2971
152.0583	106.3375	0.2971
152.0667	106.2537	0.2971
152.0750	106.1711	0.2970
152.0833	106.0883	0.2970
152.0917	106.0054	0.2970
152.1000	105.9223	0.2969
152.1083	105.8390	0.2969
152.1167	105.7550	0.2969
152.1250	105.6722	0.2967
152.1333	105.5895	0.2966
152.1417	105.5071	0.2966
152.1500	105.4239	0.2966
152.1583	105.3394	0.2965
152.1667	105.2559	0.2965
152.1750	105.1736	0.2964
152.1833	105.0906	0.2964
152.1917	105.0063	0.2964
152.2000	104.9236	0.2962
152.2083	104.8404	0.2962
152.2167	104.7578	0.2962
152.2250	104.6739	0.2961
152.2333	104.5914	0.2961
152.2417	104.5086	0.2961
152.2500	104.4252	0.2960
152.2583	104.3424	0.2960
152.2667	104.2587	0.2959
152.2750	104.1752	0.2959
152.2833	104.0921	0.2959
152.2917	104.0096	0.2959
152.3000	103.9257	0.2958
152.3083	103.8426	0.2958
152.3167	103.7604	0.2957
152.3250	103.6758	0.2957
152.3333	103.5926	0.2957
152.3417	103.5094	0.2956
152.3500	103.4266	0.2956
152.3583	103.3434	0.2955
152.3667	103.2611	0.2955
152.3750	103.1778	0.2955
152.3833	103.0932	0.2954
152.3917	103.0105	0.2953
152.4000	102.9276	0.2953
152.4083	102.8453	0.2953
152.4167	102.7629	0.2953
152.4250	102.6778	0.2952
152.4333	102.5945	0.2952
152.4417	102.5127	0.2951
152.4500	102.4287	0.2951
152.4583	102.3459	0.2951
152.4667	102.2630	0.2950
152.4750	102.1800	0.2950
152.4833	102.0967	0.2950
152.4917	102.0144	0.2949
152.5000	101.9297	0.2949
152.5083	101.8466	0.2947
152.5167	101.7640	0.2947
152.5250	101.6797	0.2946
152.5333	101.5976	0.2946
152.5417	101.5140	0.2945
152.5500	101.4303	0.2945
152.5583	101.3480	0.2945
152.5667	101.2646	0.2944
152.5750	101.1815	0.2944
152.5833	101.0972	0.2944
152.5917	101.0149	0.2943
152.6000	100.9324	0.2943
152.6083	100.8486	0.2943
152.6167	100.7653	0.2942
152.6250	100.6810	0.2942
152.6333	100.5995	0.2942
152.6417	100.5169	0.2941
152.6500	100.4326	0.2940
152.6583	100.3498	0.2940
152.6667	100.2659	0.2940
152.6750	100.1830	0.2939
152.6833	100.1000	0.2939
152.6917	100.0164	0.2938
152.7000	99.9330	0.2938
152.7083	99.8500	0.2938
152.7167	99.7669	0.2937
152.7250	99.6850	0.2937
152.7333	99.6011	0.2936
152.7417	99.5169	0.2936
152.7500	99.4348	0.2936
152.7583	99.3517	0.2935
152.7667	99.2677	0.2934
152.7750	99.1861	0.2934
152.7833	99.1017	0.2934
152.7917	99.0190	0.2933
152.8000	98.9356	0.2932
152.8083	98.8529	0.2932
152.8167	98.7697	0.2932
152.8250	98.6870	0.2931
152.8333	98.6033	0.2931
152.8417	98.5202	0.2930
152.8500	98.4374	0.2929
152.8583	98.3537	0.2928
152.8667	98.2702	0.2928
152.8750	98.1878	0.2928
152.8833	98.1035	0.2927
152.8917	98.0206	0.2927
152.9000	97.9379	0.2926
152.9083	97.8546	0.2926
152.9167	97.7711	0.2926
152.9250	97.6880	0.2925
152.9333	97.6051	0.2925
152.9417	97.5216	0.2925
152.9500	97.4391	0.2924
152.9583	97.3567	0.2924
152.9667	97.2733	0.2923
152.9750	97.1899	0.2923
152.9833	97.1069	0.2922
152.9917	97.0244	0.2922
153.0000	96.9419	0.2921
153.0083	96.8564	0.2921
153.0167	96.7740	0.2920
153.0250	96.6920	0.2920
153.0333	96.6081	0.2919
153.0417	96.5250	0.2919
153.0500	96.4413	0.2918
153.0583	96.3583	0.2918
153.0667	96.2762	0.2917
153.0750	96.1928	0.2917
153.0833	96.1095	0.2916
153.0917	96.0254	0.2916
153.1000	95.9425	0.2915
153.1083	95.8596	0.2915
153.1167	95.7766	0.2915
153.1250	95.6927	0.2914
153.1333	95.6108	0.2914
153.1417	95.5265	0.2913
153.1500	95.4440	0.2913
153.1583	95.3605	0.2912
153.1667	95.2769	0.2912
153.1750	95.1939	0.2912
153.1833	95.1109	0.2911
153.1917	95.0273	0.2910
153.2000	94.9430	0.2910
153.2083	94.8613	0.2910
153.2167	94.7788	0.2909
153.2250	94.6949	0.2908
153.2333	94.6117	0.2907
153.2417	94.5286	0.2906
153.2500	94.4462	0.2906
153.2583	94.3620	0.2906
153.2667	94.2798	0.2905
153.2750	94.1961	0.2904
153.2833	94.1136	0.2904
153.2917	94.0299	0.2903
153.3000	93.9468	0.2903
153.3083	93.8637	0.2903
153.3167	93.7799	0.2902
153.3250	93.6972	0.2902
153.3333	93.6139	0.2901
153.3417	93.5318	0.2901
153.3500	93.4471	0.2900
153.3583	93.3641	0.2900
153.3667	93.2808	0.2899
153.3750	93.1981	0.2899
153.3833	93.1154	0.2898
153.3917	93.0318	0.2898
153.4000	92.9479	0.2898
153.4083	92.8649	0.2897
153.4167	92.7816	0.2897
153.4250	92.6989	0.2896
153.4333	92.6162	0.2896
153.4417	92.5329	0.2896
153.4500	92.4494	0.2894
153.4583	92.3668	0.2894
153.4667	92.2823	0.2894
153.4750	92.1995	0.2893
153.4833	92.1161	0.2892
153.4917	92.0333	0.2892
153.5000	91.9506	0.2891
153.5083	91.8667	0.2891
153.5167	91.7843	0.2891
153.5250	91.7010	0.2890
153.5333	91.6173	0.2890
153.5417	91.5332	0.2889
153.5500	91.4509	0.2889
153.5583	91.3683	0.2888
153.5667	91.2851	0.2888
153.5750	91.2018	0.2888
153.5833	91.1188	0.2886
153.5917	91.0360	0.2886
153.6000	90.9527	0.2886
153.6083	90.8695	0.2886
153.6167	90.7862	0.2885
153.6250	90.7033	0.2885
153.6333	90.6200	0.2884
153.6417	90.5366	0.2884
153.6500	90.4544	0.2884
153.6583	90.3703	0.2883
153.6667	90.2869	0.2883
153.6750	90.2046	0.2882
153.6833	90.1205	0.2882
153.6917	90.0390	0.2881
153.7000	89.9548	0.2881
153.7083	89.8731	0.2881
153.7167	89.7886	0.2880
153.7250	89.7048	0.2880
153.7333	89.6228	0.2879
153.7417	89.5397	0.2879
153.7500	89.4561	0.2879
153.7583	89.3720	0.2878
153.7667	89.2900	0.2878
153.7750	89.2066	0.2877
153.7833	89.1233	0.2877
153.7917	89.0395	0.2876
153.8000	88.9546	0.2876
153.8083	88.8729	0.2875
153.8167	88.7892	0.2875
153.8250	88.7072	0.2875
153.8333	88.6232	0.2874
153.8417	88.5408	0.2874
153.8500	88.4573	0.2874
153.8583	88.3745	0.2873
153.8667	88.2909	0.2872
153.8750	88.2084	0.2872
153.8833	88.1251	0.2872
153.8917	88.0419	0.2871
153.9000	87.9589	0.2870
153.9083	87.8751	0.2869
153.9167	87.7930	0.2869
153.9250	87.7097	0.2869
153.9333	87.6261	0.2868
153.9417	87.5435	0.2868
153.9500	87.4606	0.2867
153.9583	87.3775	0.2867
153.9667	87.2926	0.2867
153.9750	87.2111	0.2865
153.9833	87.1270	0.2865
153.9917	87.0441	0.2865
154.0000	86.9608	0.2864
154.0083	86.8768	0.2864
154.0167	86.7940	0.2864
154.0250	86.7109	0.2864
154.0333	86.6290	0.2860
154.0417	86.5461	0.2860
154.0500	86.4626	0.2860
154.0583	86.3789	0.2860
154.0667	86.2957	0.2860
154.0750	86.2131	0.2859
154.0833	86.1294	0.2859
154.0917	86.0466	0.2859
154.1000	85.9638	0.2858
154.1083	85.8799	0.2858
154.1167	85.7975	0.2858
154.1250	85.7143	0.2857
154.1333	85.6312	0.2857
154.1417	85.5480	0.2857
154.1500	85.4649	0.2857
154.1583	85.3818	0.2856
154.1667	85.2994	0.2856
154.1750	85.2155	0.2855
154.1833	85.1321	0.2855
154.1917	85.0503	0.2854
154.2000	84.9661	0.2854
154.2083	84.8828	0.2854
154.2167	84.7999	0.2853
154.2250	84.7172	0.2853
154.2333	84.6321	0.2853
154.2417	84.5501	0.2852
154.2500	84.4674	0.2852
154.2583	84.3831	0.2851
154.2667	84.3009	0.2851
154.2750	84.2177	0.2850
154.2833	84.1352	0.2850
154.2917	84.0505	0.2850
154.3000	83.9681	0.2849
154.3083	83.8849	0.2849
154.3167	83.8021	0.2848
154.3250	83.7200	0.2848
154.3333	83.6365	0.2848
154.3417	83.5534	0.2847
154.3500	83.4694	0.2847
154.3583	83.3862	0.2847
154.3667	83.3016	0.2846
154.3750	83.2191	0.2846
154.3833	83.1364	0.2845
154.3917	83.0532	0.2845
154.4000	82.9710	0.2845
154.4083	82.8870	0.2844
154.4167	82.8037	0.2843
154.4250	82.7220	0.2843
154.4333	82.6378	0.2843
154.4417	82.5552	0.2842
154.4500	82.4718	0.2842
154.4583	82.3882	0.2842
154.4667	82.3055	0.2841
154.4750	82.2222	0.2841
154.4833	82.1396	0.2840
154.4917	82.0550	0.2840
154.5000	81.9722	0.2839
154.5083	81.8893	0.2839
154.5167	81.8063	0.2839
154.5250	81.7220	0.2838
154.5333	81.6397	0.2838
154.5417	81.5565	0.2838
154.5500	81.4737	0.2837
154.5583	81.3911	0.2837
154.5667	81.3060	0.2837
154.5750	81.2234	0.2836
154.5833	81.1396	0.2836
154.5917	81.0575	0.2835
154.6000	80.9732	0.2834
154.6083	80.8908	0.2834
154.6167	80.8076	0.2834
154.6250	80.7252	0.2833
154.6333	80.6415	0.2833
154.6417	80.5586	0.2832
154.6500	80.4750	0.2832
154.6583	80.3917	0.2831
154.6667	80.3090	0.2831
154.6750	80.2257	0.2830
154.6833	80.1424	0.2830
154.6917	80.0598	0.2829
154.7000	79.9769	0.2829
154.7083	79.8915	0.2828
154.7167	79.8106	0.2828
154.7250	79.7259	0.2827
154.7333	79.6432	0.2827
154.7417	79.5594	0.2827
154.7500	79.4766	0.2826
154.7583	79.3937	0.2826
154.7667	79.3109	0.2825
154.7750	79.2272	0.2825
154.7833	79.1446	0.2824
154.7917	79.0620	0.2824
154.8000	78.9781	0.2824
154.8083	78.8955	0.2823
154.8167	78.8122	0.2823
154.8250	78.7286	0.2822
154.8333	78.6466	0.2822
154.8417	78.5617	0.2821
154.8500	78.4792	0.2820
154.8583	78.3964	0.2820
154.8667	78.3126	0.2820
154.8750	78.2295	0.2819
154.8833	78.1463	0.2819
154.8917	78.0630	0.2819
154.9000	77.9801	0.2818
154.9083	77.8968	0.2818
154.9167	77.8138	0.2817
154.9250	77.7310	0.2816
154.9333	77.6480	0.2816
154.9417	77.5655	0.2815
154.9500	77.4809	0.2815
154.9583	77.3977	0.2814
154.9667	77.3153	0.2814
154.9750	77.2312	0.2813
154.9833	77.1487	0.2812
154.9917	77.0644	0.2811
155.0000	76.9819	0.2811
155.0083	76.8975	0.2811
155.0167	76.8144	0.2810
155.0250	76.7307	0.2810
155.0333	76.6488	0.2809
155.0417	76.5651	0.2809
155.0500	76.4822	0.2808
155.0583	76.3988	0.2808
155.0667	76.3157	0.2808
155.0750	76.2325	0.2808
155.0833	76.1496	0.2807
155.0917	76.0660	0.2807
155.1000	75.9836	0.2806
155.1083	75.9000	0.2806
155.1167	75.8171	0.2805
155.1250	75.7332	0.2805
155.1333	75.6509	0.2804
155.1417	75.5686	0.2804
155.1500	75.4841	0.2804
155.1583	75.4017	0.2803
155.1667	75.3198	0.2802
155.1750	75.2361	0.2802
155.1833	75.1525	0.2800
155.1917	75.0684	0.2799
155.2000	74.9854	0.2799
155.2083	74.9029	0.2799
155.2167	74.8203	0.2798
155.2250	74.7361	0.2797
155.2333	74.6534	0.2797
155.2417	74.5690	0.2797
155.2500	74.4862	0.2796
155.2583	74.4041	0.2795
155.2667	74.3207	0.2795
155.2750	74.2368	0.2795
155.2833	74.1538	0.2794
155.2917	74.0715	0.2794
155.3000	73.9888	0.2793
155.3083	73.9046	0.2793
155.3167	73.8217	0.2793
155.3250	73.7381	0.2792
155.3333	73.6558	0.2791
155.3417	73.5723	0.2790
155.3500	73.4880	0.2790
155.3583	73.4048	0.2790
155.3667	73.3222	0.2789
155.3750	73.2388	0.2789
155.3833	73.1555	0.2788
155.3917	73.0726	0.2788
155.4000	72.9880	0.2788
155.4083	72.9048	0.2787
155.4167	72.8224	0.2786
155.4250	72.7379	0.2786
155.4333	72.6557	0.2785
155.4417	72.5725	0.2785
155.4500	72.4892	0.2785
155.4583	72.4060	0.2784
155.4667	72.3225	0.2784
155.4750	72.2402	0.2783
155.4833	72.1559	0.2783
155.4917	72.0720	0.2782
155.5000	71.9899	0.2782
155.5083	71.9071	0.2781
155.5167	71.8238	0.2781
155.5250	71.7404	0.2780
155.5333	71.6585	0.2780
155.5417	71.5737	0.2779
155.5500	71.4910	0.2778
155.5583	71.4071	0.2777
155.5667	71.3247	0.2776
155.5750	71.2404	0.2776
155.5833	71.1585	0.2775
155.5917	71.0746	0.2775
155.6000	70.9918	0.2774
155.6083	70.9088	0.2774
155.6167	70.8253	0.2774
155.6250	70.7421	0.2773
155.6333	70.6589	0.2772
155.6417	70.5770	0.2771
155.6500	70.4938	0.2771
155.6583	70.4101	0.2771
155.6667	70.3268	0.2770
155.6750	70.2437	0.2769
155.6833	70.1603	0.2769
155.6917	70.0770	0.2767
155.7000	69.9930	0.2767
155.7083	69.9100	0.2767
155.7167	69.8269	0.2766
155.7250	69.7436	0.2765
155.7333	69.6599	0.2765
155.7417	69.5768	0.2765
155.7500	69.4936	0.2764
155.7583	69.4113	0.2764
155.7667	69.3279	0.2764
155.7750	69.2443	0.2762
155.7833	69.1612	0.2762
155.7917	69.0773	0.2762
155.8000	68.9952	0.2762
155.8083	68.9115	0.2761
155.8167	68.8288	0.2761
155.8250	68.7450	0.2759
155.8333	68.6628	0.2759
155.8417	68.5788	0.2759
155.8500	68.4961	0.2758
155.8583	68.4139	0.2757
155.8667	68.3291	0.2757
155.8750	68.2462	0.2756
155.8833	68.1635	0.2756
155.8917	68.0791	0.2756
155.9000	67.9972	0.2755
155.9083	67.9136	0.2755
155.9167	67.8308	0.2754
155.9250	67.7470	0.2754
155.9333	67.6642	0.2753
155.9417	67.5803	0.2753
155.9500	67.4982	0.2752
155.9583	67.4139	0.2752
155.9667	67.3306	0.2752
155.9750	67.2477	0.2751
155.9833	67.1646	0.2750
155.9917	67.0823	0.2750
156.0000	66.9986	0.2749
156.0083	66.9159	0.2749
156.0167	66.8330	0.2749
156.0250	66.7495	0.2748
156.0333	66.6673	0.2748
156.0417	66.5829	0.2748
156.0500	66.4995	0.2747
156.0583	66.4176	0.2746
156.0667	66.3346	0.2746
156.0750	66.2504	0.2746
156.0833	66.1670	0.2745
156.0917	66.0833	0.2744
156.1000	66.0009	0.2743
156.1083	65.9173	0.2743
156.1167	65.8340	0.2742
156.1250	65.7526	0.2742
156.1333	65.6684	0.2741
156.1417	65.5856	0.2741
156.1500	65.5019	0.2740
156.1583	65.4185	0.2739
156.1667	65.3365	0.2739
156.1750	65.2519	0.2739
156.1833	65.1693	0.2738
156.1917	65.0856	0.2737
156.2000	65.0026	0.2737
156.2083	64.9196	0.2736
156.2167	64.8372	0.2735
156.2250	64.7528	0.2735
156.2333	64.6709	0.2734
156.2417	64.5876	0.2734
156.2500	64.5038	0.2733
156.2583	64.4216	0.2733
156.2667	64.3369	0.2732
156.2750	64.2541	0.2732
156.2833	64.1721	0.2731
156.2917	64.0881	0.2730
156.3000	64.0051	0.2730
156.3083	63.9218	0.2729
156.3167	63.8376	0.2729
156.3250	63.7541	0.2728
156.3333	63.6707	0.2728
156.3417	63.5890	0.2728
156.3500	63.5056	0.2727
156.3583	63.4219	0.2727
156.3667	63.3397	0.2726
156.3750	63.2562	0.2726
156.3833	63.1726	0.2726
156.3917	63.0902	0.2725
156.4000	63.0065	0.2725
156.4083	62.9230	0.2724
156.4167	62.8406	0.2724
156.4250	62.7573	0.2723
156.4333	62.6747	0.2721
156.4417	62.5913	0.2721
156.4500	62.5071	0.2721
156.4583	62.4243	0.2720
156.4667	62.3415	0.2720
156.4750	62.2582	0.2717
156.4833	62.1750	0.2716
156.4917	62.0925	0.2716
156.5000	62.0083	0.2716
156.5083	61.9255	0.2716
156.5167	61.8414	0.2715
156.5250	61.7593	0.2714
156.5333	61.6766	0.2714
156.5417	61.5928	0.2714
156.5500	61.5099	0.2713
156.5583	61.4273	0.2713
156.5667	61.3438	0.2713
156.5750	61.2593	0.2712
156.5833	61.1769	0.2711
156.5917	61.0935	0.2711
156.6000	61.0112	0.2711
156.6083	60.9277	0.2710
156.6167	60.8444	0.2710
156.6250	60.7616	0.2710
156.6333	60.6781	0.2709
156.6417	60.5953	0.2708
156.6500	60.5114	0.2707
156.6583	60.4284	0.2707
156.6667	60.3457	0.2707
156.6750	60.2618	0.2706
156.6833	60.1786	0.2706
156.6917	60.0953	0.2704
156.7000	60.0129	0.2703
156.7083	59.9303	0.2703
156.7167	59.8462	0.2703
156.7250	59.7628	0.2702
156.7333	59.6795	0.2702
156.7417	59.5963	0.2702
156.7500	59.5140	0.2701
156.7583	59.4300	0.2701
156.7667	59.3471	0.2701
156.7750	59.2648	0.2700
156.7833	59.1804	0.2700
156.7917	59.0976	0.2699
156.8000	59.0146	0.2699
156.8083	58.9298	0.2699
156.8167	58.8488	0.2698
156.8250	58.7658	0.2697
156.8333	58.6818	0.2697
156.8417	58.5987	0.2697
156.8500	58.5158	0.2696
156.8583	58.4324	0.2696
156.8667	58.3503	0.2695
156.8750	58.2670	0.2695
156.8833	58.1830	0.2695
156.8917	58.1002	0.2694
156.9000	58.0157	0.2693
156.9083	57.9337	0.2692
156.9167	57.8499	0.2692
156.9250	57.7669	0.2692
156.9333	57.6834	0.2691
156.9417	57.6002	0.2691
156.9500	57.5185	0.2690
156.9583	57.4345	0.2690
156.9667	57.3507	0.2689
156.9750	57.2687	0.2688
156.9833	57.1856	0.2688
156.9917	57.1014	0.2687
157.0000	57.0195	0.2687
157.0083	56.9343	0.2687
157.0167	56.8521	0.2686
157.0250	56.7689	0.2686
157.0333	56.6856	0.2685
157.0417	56.6029	0.2684
157.0500	56.5188	0.2683
157.0583	56.4355	0.2683
157.0667	56.3532	0.2683
157.0750	56.2703	0.2683
157.0833	56.1858	0.2682
157.0917	56.1043	0.2682
157.1000	56.0196	0.2681
157.1083	55.9380	0.2681
157.1167	55.8541	0.2681
157.1250	55.7706	0.2680
157.1333	55.6873	0.2680
157.1417	55.6038	0.2679
157.1500	55.5213	0.2676
157.1583	55.4388	0.2676
157.1667	55.3545	0.2676
157.1750	55.2720	0.2675
157.1833	55.1890	0.2675
157.1917	55.1053	0.2674
157.2000	55.0222	0.2672
157.2083	54.9399	0.2671
157.2167	54.8569	0.2671
157.2250	54.7724	0.2671
157.2333	54.6896	0.2671
157.2417	54.6059	0.2671
157.2500	54.5234	0.2670
157.2583	54.4405	0.2670
157.2667	54.3566	0.2669
157.2750	54.2738	0.2669
157.2833	54.1909	0.2669
157.2917	54.1075	0.2668
157.3000	54.0232	0.2668
157.3083	53.9421	0.2667
157.3167	53.8584	0.2667
157.3250	53.7743	0.2667
157.3333	53.6917	0.2666
157.3417	53.6087	0.2666
157.3500	53.5262	0.2665
157.3583	53.4431	0.2665
157.3667	53.3587	0.2665
157.3750	53.2768	0.2664
157.3833	53.1932	0.2664
157.3917	53.1093	0.2663
157.4000	53.0264	0.2663
157.4083	52.9439	0.2662
157.4167	52.8597	0.2662
157.4250	52.7772	0.2661
157.4333	52.6932	0.2661
157.4417	52.6105	0.2661
157.4500	52.5279	0.2660
157.4583	52.4438	0.2660
157.4667	52.3609	0.2660
157.4750	52.2776	0.2658
157.4833	52.1934	0.2658
157.4917	52.1105	0.2658
157.5000	52.0272	0.2657
157.5083	51.9431	0.2657
157.5167	51.8617	0.2656
157.5250	51.7776	0.2656
157.5333	51.6944	0.2655
157.5417	51.6133	0.2655
157.5500	51.5276	0.2655
157.5583	51.4447	0.2654
157.5667	51.3633	0.2651
157.5750	51.2794	0.2650
157.5833	51.1964	0.2650
157.5917	51.1131	0.2649
157.6000	51.0299	0.2649
157.6083	50.9460	0.2649
157.6167	50.8640	0.2648
157.6250	50.7797	0.2648
157.6333	50.6981	0.2648
157.6417	50.6148	0.2647
157.6500	50.5306	0.2647
157.6583	50.4468	0.2646
157.6667	50.3642	0.2646
157.6750	50.2810	0.2645
157.6833	50.1979	0.2645
157.6917	50.1159	0.2645
157.7000	50.0315	0.2644
157.7083	49.9485	0.2644
157.7167	49.8668	0.2644
157.7250	49.7823	0.2644
157.7333	49.6987	0.2644
157.7417	49.6147	0.2644
157.7500	49.5317	0.2644
157.7583	49.4486	0.2644
157.7667	49.3668	0.2644
157.7750	49.2831	0.2644
157.7833	49.2016	0.2648
157.7917	49.1179	0.2654
157.8000	49.0349	0.2662
157.8083	48.9524	0.2669
157.8167	48.8699	0.2690
157.8250	48.7873	0.2711
157.8333	48.7039	0.2733
157.8417	48.6224	0.2770
157.8500	48.5398	0.2818
157.8583	48.4574	0.2862
157.8667	48.3755	0.2919
157.8750	48.2948	0.2990
157.8833	48.2147	0.3091
157.8917	48.1340	0.3211
157.9000	48.0544	0.3355
157.9083	47.9781	0.3546
157.9167	47.9010	0.3789
157.9250	47.8255	0.4083
157.9333	47.7510	0.4436
157.9417	47.6806	0.4885
157.9500	47.6124	0.5415
157.9583	47.5494	0.6044
157.9667	47.4893	0.6792
157.9750	47.4322	0.7651
157.9833	47.3806	0.8601
157.9917	47.3339	0.9637
158.0000	47.2940	1.0727
158.0083	47.2588	1.1880
158.0167	47.2281	1.3036
158.0250	47.2002	1.4172
158.0333	47.1771	1.5276
158.0417	47.1550	1.6318
158.0500	47.1377	1.7294
158.0583	47.1212	1.8189
158.0667	47.1041	1.9013
158.0750	47.0860	1.9764
158.0833	47.0683	2.0452
158.0917	47.0490	2.1074
158.1000	47.0271	2.1628
158.1083	47.0042	2.2129
158.1167	46.9801	2.2615
158.1250	46.9520	2.3049
158.1333	46.9225	2.3449
158.1417	46.8916	2.3834
158.1500	46.8588	2.4181
158.1583	46.8216	2.4515
158.1667	46.7843	2.4835
158.1750	46.7444	2.5131
158.1833	46.7036	2.5416
158.1917	46.6586	2.5683
158.2000	46.6128	2.5932
158.2083	46.5666	2.6181
158.2167	46.5179	2.6390
158.2250	46.4668	2.6618
158.2333	46.4167	2.6796
158.2417	46.3623	2.6978
158.2500	46.3078	2.7153
158.2583	46.2516	2.7304
158.2667	46.1929	2.7424
158.2750	46.1333	2.7542
158.2833	46.0725	2.7639
158.2917	46.0106	2.7705
158.3000	45.9462	2.7755
158.3083	45.8811	2.7789
158.3167	45.8139	2.7805
158.3250	45.7455	2.7796
158.3333	45.6748	2.7751
158.3417	45.6039	2.7691
158.3500	45.5296	2.7598
158.3583	45.4555	2.7495
158.3667	45.3791	2.7375
158.3750	45.2990	2.7217
158.3833	45.2180	2.7030
158.3917	45.1374	2.6834
158.4000	45.0525	2.6614
158.4083	44.9682	2.6367
158.4167	44.8795	2.6111
158.4250	44.7900	2.5826
158.4333	44.7002	2.5511
158.4417	44.6073
158.4500	44.5109
158.4583	44.4168
158.4667	44.3191
158.4750	44.2182
158.4833	44.1176
158.4917
158.4983