File: Example Date/My Sample/DSC/test01/DSC TA/YN046 -150-150.txt
Filename	YN046 -150-150
Instrument name	DSC2A-01799 (192.168.1.250)
Operator
rundate	10/12/2024
Sample name	YN046 -150-150
proceduresegments	Ramp 10.00 °C/min to 150.0000 °C; Isothermal 3.0 min; Ramp 10.00 °C/min to -150.0000 °C; Isothermal 3.0 min; Ramp 10.00 °C/min to 150.0000 °C; Isothermal 3.0 min; Ramp 10.00 °C/min to -150.0000 °C; Isothermal 3.0 min; Ramp 10.00 °C/min to 150.0000 °C; Isothermal 3.0 min; Ramp 10.00 °C/min to 40.0000 °C
[File Parameters]
Run Date	10/12/2024 01:09:31
Trios version	5.7.0.56
Original File Name	C:\Users\TA Instruments DSC\Desktop\Data\Yutong Niu\YN046 -150-150.tri
Current File Name	C:\Users\TA Instruments DSC\Desktop\Data\Yutong Niu\YN046 -150-150.tri
User at run start	DESKTOP-CFGN8IT\TA Instruments DSC
[Procedure]
Procedure Name	polyether
Sample Name	YN046 -150-150
Sample Mass	7.18 mg
Reference Sample Mass	0 mg
Pan Mass	61.12 mg
Pan Number	10
Reference Pan Mass	60.81 mg
Reference Pan Number	45
Pan Type	Tzero Aluminum Pin Hole Hermetic
Comments
Project Name
Operator
Test	Custom
Unload Max Temperature	25
Unload Min Temperature	25
FillCooler	Do not fill
Load Max Temperature	25
Load Min Temperature	25
Discard pan in waste bin at end of test	Yes
Stop on Gas Flow Error	No
[Signal List]
Signal #1	Time (min)
Signal #2	Temperature (°C)
Signal #3	Heat Flow (mW)
Signal #4	Delta T (µV)
Signal #5	Delta Tzero (µV)
Signal #6	Tzero Temperature (°C)
Signal #7	Cell Purge (mL/min)
Signal #8	Heater Temp (°C)
Signal #9	Power Delivered (W)
Signal #10	Reference Junction Temperature (°C)
Signal #11	Flange Temperature (°C)
Signal #12	Heat Flow Phase (rad)
Signal #13	Total Heat Capacity (J/°C)
Signal #14	Heat Capacity (J/°C)
Signal #15	LN Pump Tank level (%)
[Configuration]
Company Name	Warwick University
Instrument Name	DSC2A-01799
Instrument Type	DSC2500
Serial Number	DSC2A-01799
IP	192.168.1.250
Location of Instrument	Polymer RTP
DisplayType	TianmaV2andV3
Sample Interval 	0.1 s/pt
Selected Heat Flow	T4P
Exotherm Direction	Up
Cell Serial	DRC2-03788
Lid Type	High Temperature
Cooler	LN Pump
Leave Cooler on at End of Sequence	Off
Gas 2	Air
Gas Selected	Channel 1: Nitrogen
Flow Rate	50 mL/min
Secondary Purge	On
Licensed Heat Flow	Heat Flow T4P
Modulation Licensed	Yes
[Versions]
Common IDD Version	1
Cortex Version	VER 2.11.0.729
Driver	5.0.0.6
GDM Version	1.0.3.3
TouchscreenVersion	1.0.3.1841
FEP Version	1.2.1.21
FEP Bootloader	2.0.0.5
AutoSampler Version	2.1.2.1
Auto Sampler Bootloader	2.0.0.5
FCM Version	1.1.0.3
FCM Bootloader	2.0.0.5
LN Pump Version	10.17.0.0
LN Pump Bootloader	2.0.0.5
[Experiment Logs]
Experiment Log Entry # 1	Ramp Segment 10 C/min to 150 Started
Experiment Log Entry # 3	Air Cool is off.
Experiment Log Entry # 5	Isothermal Segment 3 min started
Experiment Log Entry # 7	Ramp Segment 10 C/min to -150 Started
Experiment Log Entry # 9	Isothermal Segment 3 min started
Experiment Log Entry # 11	Ramp Segment 10 C/min to 150 Started
Experiment Log Entry # 13	Isothermal Segment 3 min started
Experiment Log Entry # 15	Ramp Segment 10 C/min to -150 Started
Experiment Log Entry # 17	Isothermal Segment 3 min started
Experiment Log Entry # 19	Ramp Segment 10 C/min to 150 Started
Experiment Log Entry # 21	Isothermal Segment 3 min started
Experiment Log Entry # 23	Ramp Segment 10 C/min to 40 Started
Experiment Log Entry # 25	LN2P Tank Level Warning - Level of LN2 remaining in the tank is <= 20% of full while pumping.
[Method Log]
Method Log Entry # 1	(Ramp 621203) Ramp 10 °C/minute to 150 °C
Method Log Entry # 2	Isothermal 3 minutes
Method Log Entry # 3	(Ramp 621205) Ramp 10 °C/minute to -150 °C
Method Log Entry # 4	Isothermal 3 minutes
Method Log Entry # 5	(Ramp 621207) Ramp 10 °C/minute to 150 °C
Method Log Entry # 6	Isothermal 3 minutes
Method Log Entry # 7	(Ramp 621209) Ramp 10 °C/minute to -150 °C
Method Log Entry # 8	Isothermal 3 minutes
Method Log Entry # 9	(Ramp 621211) Ramp 10 °C/minute to 150 °C
Method Log Entry # 10	Isothermal 3 minutes
Method Log Entry # 11	(Ramp 621213) Ramp 10 °C/minute to 40 °C
Cell Serial	DRC2-03788
[T1 Calibration]
Date Applied	04/03/2021 14:58:04
Description
Gas Type	Nitrogen
Pan Type	None
Slope	-0.001800291
Offset	-0.1301359
Initial Temperature	-100.6228
GUID	a1d5a6be-decd-4ae4-b22f-d560f3a78a92
[TZero Calibration]
Date Applied	21/08/2024 09:53:38
Description	From -180.022 °C to 395.167 °C at 20.000°C/min
Gas Type	Nitrogen
Pan Type	None
Source Files 1	C:\ProgramData\TA Instruments\TRIOS\Data\TAService\PMV 20Aug2024\Tzero Cal.tri
Source Files 2	C:\ProgramData\TA Instruments\TRIOS\Data\TAService\PMV 20Aug2024\Tzero Cal sapphire.tri
Delta T Offset	1.787969
Delta T Slope	-0.003527276
Delta T0 Offset	0.06831977
Delta T0 Slope	0.02007191
[Temperature Calibration]
Date Applied	21/08/2024 11:06:35
Description	From 106.660 °C to 186.660 °C at 10.000°C/min
Gas Type	Nitrogen
Pan Type	Tzero Aluminum
Source Files 1	C:\ProgramData\TA Instruments\TRIOS\Data\TAService\PMV 20Aug2024\TA Indium cal.tri
Measured 1	157.9141
Known 1	156.66
[Cell Constant Calibration]
Date Applied	21/08/2024 11:06:35
Description	From 106.660 °C to 186.660 °C at 10.000°C/min
Gas Type	Nitrogen
Pan Type	Tzero Aluminum
Source Files 1	C:\ProgramData\TA Instruments\TRIOS\Data\TAService\PMV 20Aug2024\TA Indium cal.tri
T4P KCell	1.038055
Onset Slope	-66.72884 mW/°C
[Direct Cp Calibration]
Date Applied	19/11/2024 16:37:27
Description	From -89.996 °C to 396.697 °C at 20.000°C/min
Gas Type	Nitrogen
Pan Type	Tzero Aluminum
Source Files 1	C:\ProgramData\TA Instruments\TRIOS\Data\Sapphire Direct Heat Capacity(8).tri
GUID	544f8371-fe9b-4f4f-81ca-7980c172113e
Temperature	-89.99625 °C
Cp	1.464367
Temperature	-89.02287 °C
Cp	1.460558
Temperature	-88.04948 °C
Cp	1.456263
Temperature	-87.0761 °C
Cp	1.451626
Temperature	-86.10271 °C
Cp	1.446737
Temperature	-85.12933 °C
Cp	1.441723
Temperature	-84.15594 °C
Cp	1.436654
Temperature	-83.18256 °C
Cp	1.431684
Temperature	-82.20917 °C
Cp	1.426935
Temperature	-81.23578 °C
Cp	1.422396
Temperature	-80.2624 °C
Cp	1.418192
Temperature	-79.28901 °C
Cp	1.414363
Temperature	-78.31562 °C
Cp	1.410925
Temperature	-77.34224 °C
Cp	1.407865
Temperature	-76.36885 °C
Cp	1.405143
Temperature	-75.39546 °C
Cp	1.402789
Temperature	-74.42208 °C
Cp	1.400703
Temperature	-73.44869 °C
Cp	1.398837
Temperature	-72.4753 °C
Cp	1.397142
Temperature	-71.50192 °C
Cp	1.395565
Temperature	-70.52853 °C
Cp	1.394053
Temperature	-69.55515 °C
Cp	1.392558
Temperature	-68.58176 °C
Cp	1.391036
Temperature	-67.60838 °C
Cp	1.389483
Temperature	-66.63499 °C
Cp	1.387847
Temperature	-65.66161 °C
Cp	1.38616
Temperature	-64.68822 °C
Cp	1.384397
Temperature	-63.71483 °C
Cp	1.382535
Temperature	-62.74145 °C
Cp	1.380598
Temperature	-61.76806 °C
Cp	1.37865
Temperature	-60.79467 °C
Cp	1.376673
Temperature	-59.82129 °C
Cp	1.374677
Temperature	-58.8479 °C
Cp	1.372642
Temperature	-57.87452 °C
Cp	1.370686
Temperature	-56.90113 °C
Cp	1.368741
Temperature	-55.92775 °C
Cp	1.366786
Temperature	-54.95436 °C
Cp	1.364863
Temperature	-53.98097 °C
Cp	1.362959
Temperature	-53.00759 °C
Cp	1.361116
Temperature	-52.0342 °C
Cp	1.359247
Temperature	-51.06082 °C
Cp	1.357393
Temperature	-50.08743 °C
Cp	1.355593
Temperature	-49.11404 °C
Cp	1.353796
Temperature	-48.14066 °C
Cp	1.352008
Temperature	-47.16727 °C
Cp	1.350215
Temperature	-46.19389 °C
Cp	1.348396
Temperature	-45.2205 °C
Cp	1.346593
Temperature	-44.24712 °C
Cp	1.344755
Temperature	-43.27373 °C
Cp	1.342891
Temperature	-42.30034 °C
Cp	1.341008
Temperature	-41.32696 °C
Cp	1.339126
Temperature	-40.35357 °C
Cp	1.337236
Temperature	-39.38018 °C
Cp	1.335367
Temperature	-38.4068 °C
Cp	1.333522
Temperature	-37.43341 °C
Cp	1.331708
Temperature	-36.46003 °C
Cp	1.32991
Temperature	-35.48664 °C
Cp	1.328145
Temperature	-34.51326 °C
Cp	1.326414
Temperature	-33.53987 °C
Cp	1.32471
Temperature	-32.56648 °C
Cp	1.323012
Temperature	-31.5931 °C
Cp	1.321323
Temperature	-30.61971 °C
Cp	1.319657
Temperature	-29.64633 °C
Cp	1.317968
Temperature	-28.67294 °C
Cp	1.316286
Temperature	-27.69955 °C
Cp	1.314585
Temperature	-26.72617 °C
Cp	1.312857
Temperature	-25.75278 °C
Cp	1.31111
Temperature	-24.7794 °C
Cp	1.309333
Temperature	-23.80601 °C
Cp	1.307544
Temperature	-22.83262 °C
Cp	1.30575
Temperature	-21.85924 °C
Cp	1.303941
Temperature	-20.88585 °C
Cp	1.302132
Temperature	-19.91247 °C
Cp	1.300313
Temperature	-18.93908 °C
Cp	1.298512
Temperature	-17.96569 °C
Cp	1.296728
Temperature	-16.99231 °C
Cp	1.294939
Temperature	-16.01892 °C
Cp	1.293198
Temperature	-15.04554 °C
Cp	1.291453
Temperature	-14.07215 °C
Cp	1.289723
Temperature	-13.09876 °C
Cp	1.288007
Temperature	-12.12538 °C
Cp	1.286283
Temperature	-11.15199 °C
Cp	1.284578
Temperature	-10.17861 °C
Cp	1.282885
Temperature	-9.205221 °C
Cp	1.281173
Temperature	-8.231835 °C
Cp	1.279472
Temperature	-7.258449 °C
Cp	1.277766
Temperature	-6.285063 °C
Cp	1.276053
Temperature	-5.311677 °C
Cp	1.274341
Temperature	-4.338291 °C
Cp	1.272592
Temperature	-3.364905 °C
Cp	1.270844
Temperature	-2.391519 °C
Cp	1.269062
Temperature	-1.418133 °C
Cp	1.267264
Temperature	-0.4447474 °C
Cp	1.265435
Temperature	0.5286385 °C
Cp	1.263575
Temperature	1.502024 °C
Cp	1.261727
Temperature	2.47541 °C
Cp	1.259854
Temperature	3.448796 °C
Cp	1.257978
Temperature	4.422182 °C
Cp	1.256109
Temperature	5.395568 °C
Cp	1.254244
Temperature	6.368954 °C
Cp	1.252392
Temperature	7.34234 °C
Cp	1.250552
Temperature	8.315726 °C
Cp	1.248704
Temperature	9.289112 °C
Cp	1.246884
Temperature	10.2625 °C
Cp	1.245078
Temperature	11.23588 °C
Cp	1.243287
Temperature	12.20927 °C
Cp	1.241522
Temperature	13.18266 °C
Cp	1.239778
Temperature	14.15604 °C
Cp	1.238068
Temperature	15.12943 °C
Cp	1.236393
Temperature	16.10281 °C
Cp	1.234762
Temperature	17.0762 °C
Cp	1.233176
Temperature	18.04959 °C
Cp	1.231629
Temperature	19.02297 °C
Cp	1.230129
Temperature	19.99636 °C
Cp	1.228694
Temperature	20.96974 °C
Cp	1.22731
Temperature	21.94313 °C
Cp	1.225968
Temperature	22.91652 °C
Cp	1.224676
Temperature	23.8899 °C
Cp	1.223431
Temperature	24.86329 °C
Cp	1.222217
Temperature	25.83667 °C
Cp	1.221065
Temperature	26.81006 °C
Cp	1.219919
Temperature	27.78345 °C
Cp	1.218811
Temperature	28.75683 °C
Cp	1.21773
Temperature	29.73022 °C
Cp	1.216663
Temperature	30.7036 °C
Cp	1.2156
Temperature	31.67699 °C
Cp	1.214515
Temperature	32.65038 °C
Cp	1.213439
Temperature	33.62376 °C
Cp	1.21234
Temperature	34.59715 °C
Cp	1.211209
Temperature	35.57053 °C
Cp	1.210051
Temperature	36.54392 °C
Cp	1.208868
Temperature	37.5173 °C
Cp	1.207666
Temperature	38.49069 °C
Cp	1.206439
Temperature	39.46408 °C
Cp	1.205199
Temperature	40.43746 °C
Cp	1.203959
Temperature	41.41085 °C
Cp	1.202712
Temperature	42.38424 °C
Cp	1.20147
Temperature	43.35762 °C
Cp	1.200231
Temperature	44.33101 °C
Cp	1.199
Temperature	45.30439 °C
Cp	1.197777
Temperature	46.27778 °C
Cp	1.19657
Temperature	47.25116 °C
Cp	1.195367
Temperature	48.22455 °C
Cp	1.194179
Temperature	49.19794 °C
Cp	1.19301
Temperature	50.17132 °C
Cp	1.191849
Temperature	51.14471 °C
Cp	1.190694
Temperature	52.11809 °C
Cp	1.189555
Temperature	53.09148 °C
Cp	1.18843
Temperature	54.06487 °C
Cp	1.187311
Temperature	55.03825 °C
Cp	1.186195
Temperature	56.01164 °C
Cp	1.185095
Temperature	56.98502 °C
Cp	1.183997
Temperature	57.95841 °C
Cp	1.182894
Temperature	58.93179 °C
Cp	1.181793
Temperature	59.90518 °C
Cp	1.180693
Temperature	60.87857 °C
Cp	1.179595
Temperature	61.85195 °C
Cp	1.178501
Temperature	62.82534 °C
Cp	1.177406
Temperature	63.79873 °C
Cp	1.176313
Temperature	64.77211 °C
Cp	1.175239
Temperature	65.7455 °C
Cp	1.17417
Temperature	66.71888 °C
Cp	1.173105
Temperature	67.69227 °C
Cp	1.172037
Temperature	68.66566 °C
Cp	1.170989
Temperature	69.63904 °C
Cp	1.169948
Temperature	70.61243 °C
Cp	1.168905
Temperature	71.58582 °C
Cp	1.167872
Temperature	72.5592 °C
Cp	1.166849
Temperature	73.53259 °C
Cp	1.165851
Temperature	74.50597 °C
Cp	1.164848
Temperature	75.47935 °C
Cp	1.163876
Temperature	76.45274 °C
Cp	1.162926
Temperature	77.42612 °C
Cp	1.162008
Temperature	78.39951 °C
Cp	1.161113
Temperature	79.3729 °C
Cp	1.160219
Temperature	80.34628 °C
Cp	1.159377
Temperature	81.31967 °C
Cp	1.158546
Temperature	82.29306 °C
Cp	1.157726
Temperature	83.26644 °C
Cp	1.15692
Temperature	84.23983 °C
Cp	1.156126
Temperature	85.21322 °C
Cp	1.155375
Temperature	86.1866 °C
Cp	1.154604
Temperature	87.15999 °C
Cp	1.153869
Temperature	88.13337 °C
Cp	1.153158
Temperature	89.10676 °C
Cp	1.152474
Temperature	90.08015 °C
Cp	1.15181
Temperature	91.05353 °C
Cp	1.151134
Temperature	92.02692 °C
Cp	1.150513
Temperature	93.00031 °C
Cp	1.149892
Temperature	93.97369 °C
Cp	1.149266
Temperature	94.94707 °C
Cp	1.148642
Temperature	95.92046 °C
Cp	1.148019
Temperature	96.89384 °C
Cp	1.147402
Temperature	97.86723 °C
Cp	1.146799
Temperature	98.84062 °C
Cp	1.146191
Temperature	99.814 °C
Cp	1.145602
Temperature	100.7874 °C
Cp	1.14503
Temperature	101.7608 °C
Cp	1.144469
Temperature	102.7342 °C
Cp	1.143921
Temperature	103.7076 °C
Cp	1.143383
Temperature	104.6809 °C
Cp	1.142861
Temperature	105.6543 °C
Cp	1.142345
Temperature	106.6277 °C
Cp	1.141835
Temperature	107.6011 °C
Cp	1.141335
Temperature	108.5745 °C
Cp	1.140846
Temperature	109.5479 °C
Cp	1.140365
Temperature	110.5212 °C
Cp	1.139891
Temperature	111.4946 °C
Cp	1.139429
Temperature	112.468 °C
Cp	1.138976
Temperature	113.4414 °C
Cp	1.13853
Temperature	114.4148 °C
Cp	1.138092
Temperature	115.3882 °C
Cp	1.137654
Temperature	116.3616 °C
Cp	1.137223
Temperature	117.335 °C
Cp	1.136785
Temperature	118.3083 °C
Cp	1.136338
Temperature	119.2817 °C
Cp	1.13588
Temperature	120.2551 °C
Cp	1.13541
Temperature	121.2285 °C
Cp	1.134927
Temperature	122.2019 °C
Cp	1.134417
Temperature	123.1753 °C
Cp	1.133892
Temperature	124.1487 °C
Cp	1.133347
Temperature	125.122 °C
Cp	1.132786
Temperature	126.0954 °C
Cp	1.132206
Temperature	127.0688 °C
Cp	1.131606
Temperature	128.0422 °C
Cp	1.130999
Temperature	129.0156 °C
Cp	1.130384
Temperature	129.989 °C
Cp	1.129765
Temperature	130.9624 °C
Cp	1.129147
Temperature	131.9357 °C
Cp	1.12854
Temperature	132.9091 °C
Cp	1.127949
Temperature	133.8825 °C
Cp	1.127383
Temperature	134.8559 °C
Cp	1.126841
Temperature	135.8293 °C
Cp	1.126334
Temperature	136.8027 °C
Cp	1.125871
Temperature	137.7761 °C
Cp	1.125443
Temperature	138.7494 °C
Cp	1.125058
Temperature	139.7228 °C
Cp	1.124701
Temperature	140.6962 °C
Cp	1.124397
Temperature	141.6696 °C
Cp	1.124114
Temperature	142.643 °C
Cp	1.123854
Temperature	143.6164 °C
Cp	1.123612
Temperature	144.5898 °C
Cp	1.123385
Temperature	145.5631 °C
Cp	1.123182
Temperature	146.5365 °C
Cp	1.12296
Temperature	147.5099 °C
Cp	1.12275
Temperature	148.4833 °C
Cp	1.122543
Temperature	149.4567 °C
Cp	1.122327
Temperature	150.4301 °C
Cp	1.122099
Temperature	151.4035 °C
Cp	1.121837
Temperature	152.3768 °C
Cp	1.121582
Temperature	153.3502 °C
Cp	1.121289
Temperature	154.3236 °C
Cp	1.120967
Temperature	155.297 °C
Cp	1.120616
Temperature	156.2704 °C
Cp	1.120238
Temperature	157.2438 °C
Cp	1.119862
Temperature	158.2172 °C
Cp	1.119444
Temperature	159.1906 °C
Cp	1.119028
Temperature	160.1639 °C
Cp	1.118613
Temperature	161.1373 °C
Cp	1.118202
Temperature	162.1107 °C
Cp	1.117795
Temperature	163.0841 °C
Cp	1.117374
Temperature	164.0575 °C
Cp	1.116987
Temperature	165.0309 °C
Cp	1.116595
Temperature	166.0042 °C
Cp	1.116198
Temperature	166.9776 °C
Cp	1.1158
Temperature	167.951 °C
Cp	1.115402
Temperature	168.9244 °C
Cp	1.115006
Temperature	169.8978 °C
Cp	1.11462
Temperature	170.8712 °C
Cp	1.114223
Temperature	171.8446 °C
Cp	1.113836
Temperature	172.8179 °C
Cp	1.113458
Temperature	173.7913 °C
Cp	1.113085
Temperature	174.7647 °C
Cp	1.112712
Temperature	175.7381 °C
Cp	1.112323
Temperature	176.7115 °C
Cp	1.111957
Temperature	177.6849 °C
Cp	1.111578
Temperature	178.6583 °C
Cp	1.111185
Temperature	179.6317 °C
Cp	1.110789
Temperature	180.605 °C
Cp	1.110391
Temperature	181.5784 °C
Cp	1.110016
Temperature	182.5518 °C
Cp	1.109611
Temperature	183.5252 °C
Cp	1.109232
Temperature	184.4986 °C
Cp	1.108873
Temperature	185.472 °C
Cp	1.108531
Temperature	186.4454 °C
Cp	1.108199
Temperature	187.4187 °C
Cp	1.107851
Temperature	188.3921 °C
Cp	1.107551
Temperature	189.3655 °C
Cp	1.107238
Temperature	190.3389 °C
Cp	1.106917
Temperature	191.3123 °C
Cp	1.106589
Temperature	192.2857 °C
Cp	1.106259
Temperature	193.259 °C
Cp	1.105958
Temperature	194.2324 °C
Cp	1.105619
Temperature	195.2058 °C
Cp	1.105301
Temperature	196.1792 °C
Cp	1.105002
Temperature	197.1526 °C
Cp	1.104718
Temperature	198.126 °C
Cp	1.104445
Temperature	199.0994 °C
Cp	1.104161
Temperature	200.0728 °C
Cp	1.103914
Temperature	201.0461 °C
Cp	1.103657
Temperature	202.0195 °C
Cp	1.103395
Temperature	202.9929 °C
Cp	1.103125
Temperature	203.9663 °C
Cp	1.102847
Temperature	204.9397 °C
Cp	1.102563
Temperature	205.9131 °C
Cp	1.102283
Temperature	206.8865 °C
Cp	1.101985
Temperature	207.8598 °C
Cp	1.10169
Temperature	208.8332 °C
Cp	1.101394
Temperature	209.8066 °C
Cp	1.101099
Temperature	210.78 °C
Cp	1.1008
Temperature	211.7534 °C
Cp	1.10049
Temperature	212.7268 °C
Cp	1.100193
Temperature	213.7002 °C
Cp	1.099886
Temperature	214.6735 °C
Cp	1.099577
Temperature	215.6469 °C
Cp	1.099268
Temperature	216.6203 °C
Cp	1.098965
Temperature	217.5937 °C
Cp	1.098685
Temperature	218.5671 °C
Cp	1.098396
Temperature	219.5405 °C
Cp	1.098134
Temperature	220.5139 °C
Cp	1.097895
Temperature	221.4872 °C
Cp	1.09768
Temperature	222.4606 °C
Cp	1.097485
Temperature	223.434 °C
Cp	1.097292
Temperature	224.4074 °C
Cp	1.09714
Temperature	225.3808 °C
Cp	1.096991
Temperature	226.3542 °C
Cp	1.096844
Temperature	227.3276 °C
Cp	1.096699
Temperature	228.3009 °C
Cp	1.096559
Temperature	229.2743 °C
Cp	1.096442
Temperature	230.2477 °C
Cp	1.096296
Temperature	231.2211 °C
Cp	1.096164
Temperature	232.1945 °C
Cp	1.09604
Temperature	233.1679 °C
Cp	1.095924
Temperature	234.1413 °C
Cp	1.095807
Temperature	235.1147 °C
Cp	1.095665
Temperature	236.088 °C
Cp	1.095557
Temperature	237.0614 °C
Cp	1.095433
Temperature	238.0348 °C
Cp	1.095296
Temperature	239.0082 °C
Cp	1.095147
Temperature	239.9816 °C
Cp	1.094995
Temperature	240.955 °C
Cp	1.094843
Temperature	241.9283 °C
Cp	1.094705
Temperature	242.9017 °C
Cp	1.094562
Temperature	243.8751 °C
Cp	1.094442
Temperature	244.8485 °C
Cp	1.094344
Temperature	245.8219 °C
Cp	1.094266
Temperature	246.7953 °C
Cp	1.094209
Temperature	247.7687 °C
Cp	1.094161
Temperature	248.7421 °C
Cp	1.094144
Temperature	249.7154 °C
Cp	1.094133
Temperature	250.6888 °C
Cp	1.094127
Temperature	251.6622 °C
Cp	1.094126
Temperature	252.6356 °C
Cp	1.094127
Temperature	253.609 °C
Cp	1.094138
Temperature	254.5824 °C
Cp	1.09413
Temperature	255.5558 °C
Cp	1.094123
Temperature	256.5291 °C
Cp	1.094111
Temperature	257.5025 °C
Cp	1.094087
Temperature	258.4759 °C
Cp	1.094046
Temperature	259.4493 °C
Cp	1.093978
Temperature	260.4227 °C
Cp	1.093895
Temperature	261.3961 °C
Cp	1.093783
Temperature	262.3694 °C
Cp	1.093645
Temperature	263.3428 °C
Cp	1.093483
Temperature	264.3162 °C
Cp	1.093302
Temperature	265.2896 °C
Cp	1.093109
Temperature	266.263 °C
Cp	1.092906
Temperature	267.2364 °C
Cp	1.092704
Temperature	268.2098 °C
Cp	1.092511
Temperature	269.1832 °C
Cp	1.092331
Temperature	270.1566 °C
Cp	1.092174
Temperature	271.1299 °C
Cp	1.092046
Temperature	272.1033 °C
Cp	1.091947
Temperature	273.0767 °C
Cp	1.091882
Temperature	274.0501 °C
Cp	1.091853
Temperature	275.0235 °C
Cp	1.091859
Temperature	275.9969 °C
Cp	1.091895
Temperature	276.9702 °C
Cp	1.091957
Temperature	277.9436 °C
Cp	1.092036
Temperature	278.917 °C
Cp	1.092132
Temperature	279.8904 °C
Cp	1.09223
Temperature	280.8638 °C
Cp	1.092323
Temperature	281.8372 °C
Cp	1.092405
Temperature	282.8105 °C
Cp	1.092468
Temperature	283.7839 °C
Cp	1.092513
Temperature	284.7573 °C
Cp	1.092525
Temperature	285.7307 °C
Cp	1.092512
Temperature	286.7041 °C
Cp	1.092472
Temperature	287.6775 °C
Cp	1.092405
Temperature	288.6509 °C
Cp	1.092313
Temperature	289.6243 °C
Cp	1.092197
Temperature	290.5977 °C
Cp	1.09207
Temperature	291.571 °C
Cp	1.091931
Temperature	292.5444 °C
Cp	1.091785
Temperature	293.5178 °C
Cp	1.091641
Temperature	294.4912 °C
Cp	1.091506
Temperature	295.4646 °C
Cp	1.091387
Temperature	296.438 °C
Cp	1.091282
Temperature	297.4113 °C
Cp	1.091201
Temperature	298.3847 °C
Cp	1.091145
Temperature	299.3581 °C
Cp	1.091112
Temperature	300.3315 °C
Cp	1.091102
Temperature	301.3049 °C
Cp	1.091107
Temperature	302.2783 °C
Cp	1.091137
Temperature	303.2517 °C
Cp	1.091177
Temperature	304.2251 °C
Cp	1.091226
Temperature	305.1984 °C
Cp	1.09128
Temperature	306.1718 °C
Cp	1.091336
Temperature	307.1452 °C
Cp	1.091403
Temperature	308.1186 °C
Cp	1.091453
Temperature	309.092 °C
Cp	1.091506
Temperature	310.0654 °C
Cp	1.091561
Temperature	311.0388 °C
Cp	1.091617
Temperature	312.0121 °C
Cp	1.09167
Temperature	312.9855 °C
Cp	1.091716
Temperature	313.9589 °C
Cp	1.091762
Temperature	314.9323 °C
Cp	1.091805
Temperature	315.9057 °C
Cp	1.091838
Temperature	316.8791 °C
Cp	1.09186
Temperature	317.8524 °C
Cp	1.091871
Temperature	318.8258 °C
Cp	1.091872
Temperature	319.7992 °C
Cp	1.091867
Temperature	320.7726 °C
Cp	1.091838
Temperature	321.746 °C
Cp	1.0918
Temperature	322.7194 °C
Cp	1.091752
Temperature	323.6928 °C
Cp	1.091689
Temperature	324.6662 °C
Cp	1.091611
Temperature	325.6396 °C
Cp	1.091508
Temperature	326.6129 °C
Cp	1.091406
Temperature	327.5863 °C
Cp	1.091285
Temperature	328.5597 °C
Cp	1.09115
Temperature	329.5331 °C
Cp	1.091009
Temperature	330.5065 °C
Cp	1.09087
Temperature	331.4799 °C
Cp	1.090747
Temperature	332.4532 °C
Cp	1.090628
Temperature	333.4266 °C
Cp	1.090536
Temperature	334.4 °C
Cp	1.090472
Temperature	335.3734 °C
Cp	1.090437
Temperature	336.3468 °C
Cp	1.090431
Temperature	337.3202 °C
Cp	1.090455
Temperature	338.2935 °C
Cp	1.090503
Temperature	339.2669 °C
Cp	1.090573
Temperature	340.2403 °C
Cp	1.090658
Temperature	341.2137 °C
Cp	1.090753
Temperature	342.1871 °C
Cp	1.090853
Temperature	343.1605 °C
Cp	1.090952
Temperature	344.1339 °C
Cp	1.09105
Temperature	345.1073 °C
Cp	1.091141
Temperature	346.0807 °C
Cp	1.091225
Temperature	347.054 °C
Cp	1.091303
Temperature	348.0274 °C
Cp	1.091379
Temperature	349.0008 °C
Cp	1.091453
Temperature	349.9742 °C
Cp	1.091537
Temperature	350.9476 °C
Cp	1.091633
Temperature	351.921 °C
Cp	1.091743
Temperature	352.8943 °C
Cp	1.091874
Temperature	353.8677 °C
Cp	1.092028
Temperature	354.8411 °C
Cp	1.092206
Temperature	355.8145 °C
Cp	1.092411
Temperature	356.7879 °C
Cp	1.092628
Temperature	357.7613 °C
Cp	1.092862
Temperature	358.7346 °C
Cp	1.093102
Temperature	359.708 °C
Cp	1.093338
Temperature	360.6814 °C
Cp	1.093559
Temperature	361.6548 °C
Cp	1.093752
Temperature	362.6282 °C
Cp	1.093915
Temperature	363.6016 °C
Cp	1.094036
Temperature	364.575 °C
Cp	1.094117
Temperature	365.5484 °C
Cp	1.094159
Temperature	366.5218 °C
Cp	1.094172
Temperature	367.4951 °C
Cp	1.094165
Temperature	368.4685 °C
Cp	1.094163
Temperature	369.4419 °C
Cp	1.094182
Temperature	370.4153 °C
Cp	1.094244
Temperature	371.3887 °C
Cp	1.094375
Temperature	372.3621 °C
Cp	1.094598
Temperature	373.3354 °C
Cp	1.094937
Temperature	374.3088 °C
Cp	1.095389
Temperature	375.2822 °C
Cp	1.095973
Temperature	376.2556 °C
Cp	1.096685
Temperature	377.229 °C
Cp	1.097506
Temperature	378.2024 °C
Cp	1.098406
Temperature	379.1758 °C
Cp	1.099338
Temperature	380.1492 °C
Cp	1.10027
Temperature	381.1225 °C
Cp	1.10112
Temperature	382.0959 °C
Cp	1.101818
Temperature	383.0693 °C
Cp	1.10229
Temperature	384.0427 °C
Cp	1.102459
Temperature	385.0161 °C
Cp	1.102253
Temperature	385.9895 °C
Cp	1.101596
Temperature	386.9629 °C
Cp	1.100438
Temperature	387.9362 °C
Cp	1.098736
Temperature	388.9096 °C
Cp	1.096461
Temperature	389.883 °C
Cp	1.093614
Temperature	390.8564 °C
Cp	1.090208
Temperature	391.8298 °C
Cp	1.086278
Temperature	392.8032 °C
Cp	1.081887
Temperature	393.7766 °C
Cp	1.077096
Temperature	394.7499 °C
Cp	1.072007
Temperature	395.7233 °C
Cp	1.066707
[Rev Cp Calibration]
Date Applied	24/10/2024 12:37:31
Description	From -89.998 °C to 390.542 °C at 2.000°C/min
Gas Type	Nitrogen
Pan Type	Tzero Aluminum
Source Files 1	C:\ProgramData\TA Instruments\TRIOS\Data\Reverse Heat Capacity Calibration(6).tri
GUID	ba867d72-cfbb-486e-971e-e86aa544cc02
Temperature	-89.99799 °C
Cp	1.070076
Temperature	-89.03691 °C
Cp	1.072008
Temperature	-88.07584 °C
Cp	1.073556
Temperature	-87.11475 °C
Cp	1.074743
Temperature	-86.15367 °C
Cp	1.075597
Temperature	-85.1926 °C
Cp	1.076163
Temperature	-84.23151 °C
Cp	1.076477
Temperature	-83.27043 °C
Cp	1.076579
Temperature	-82.30936 °C
Cp	1.076527
Temperature	-81.34827 °C
Cp	1.076322
Temperature	-80.38719 °C
Cp	1.076039
Temperature	-79.42612 °C
Cp	1.07571
Temperature	-78.46503 °C
Cp	1.075361
Temperature	-77.50395 °C
Cp	1.075011
Temperature	-76.54288 °C
Cp	1.074656
Temperature	-75.58179 °C
Cp	1.074359
Temperature	-74.62071 °C
Cp	1.074086
Temperature	-73.65964 °C
Cp	1.073842
Temperature	-72.69855 °C
Cp	1.073627
Temperature	-71.73747 °C
Cp	1.073442
Temperature	-70.7764 °C
Cp	1.07329
Temperature	-69.81532 °C
Cp	1.073148
Temperature	-68.85423 °C
Cp	1.073021
Temperature	-67.89315 °C
Cp	1.072902
Temperature	-66.93208 °C
Cp	1.072782
Temperature	-65.97099 °C
Cp	1.072656
Temperature	-65.00991 °C
Cp	1.072518
Temperature	-64.04884 °C
Cp	1.072374
Temperature	-63.08775 °C
Cp	1.072201
Temperature	-62.12667 °C
Cp	1.072019
Temperature	-61.1656 °C
Cp	1.071827
Temperature	-60.20451 °C
Cp	1.071624
Temperature	-59.24343 °C
Cp	1.071411
Temperature	-58.28236 °C
Cp	1.071167
Temperature	-57.32127 °C
Cp	1.070956
Temperature	-56.3602 °C
Cp	1.070724
Temperature	-55.39911 °C
Cp	1.070483
Temperature	-54.43803 °C
Cp	1.070242
Temperature	-53.47696 °C
Cp	1.070009
Temperature	-52.51587 °C
Cp	1.069825
Temperature	-51.55479 °C
Cp	1.069601
Temperature	-50.59372 °C
Cp	1.069418
Temperature	-49.63263 °C
Cp	1.069267
Temperature	-48.67155 °C
Cp	1.069138
Temperature	-47.71048 °C
Cp	1.069021
Temperature	-46.74939 °C
Cp	1.068875
Temperature	-45.78831 °C
Cp	1.068771
Temperature	-44.82724 °C
Cp	1.068634
Temperature	-43.86615 °C
Cp	1.068462
Temperature	-42.90508 °C
Cp	1.068255
Temperature	-41.944 °C
Cp	1.068012
Temperature	-40.98291 °C
Cp	1.067742
Temperature	-40.02184 °C
Cp	1.067427
Temperature	-39.06076 °C
Cp	1.067088
Temperature	-38.09967 °C
Cp	1.066727
Temperature	-37.1386 °C
Cp	1.066349
Temperature	-36.17752 °C
Cp	1.065958
Temperature	-35.21643 °C
Cp	1.065559
Temperature	-34.25536 °C
Cp	1.065162
Temperature	-33.29427 °C
Cp	1.06476
Temperature	-32.33319 °C
Cp	1.064368
Temperature	-31.37212 °C
Cp	1.06399
Temperature	-30.41104 °C
Cp	1.063628
Temperature	-29.44995 °C
Cp	1.063283
Temperature	-28.48887 °C
Cp	1.06295
Temperature	-27.5278 °C
Cp	1.062645
Temperature	-26.56672 °C
Cp	1.062355
Temperature	-25.60563 °C
Cp	1.06208
Temperature	-24.64456 °C
Cp	1.061819
Temperature	-23.68348 °C
Cp	1.061573
Temperature	-22.72239 °C
Cp	1.061345
Temperature	-21.76132 °C
Cp	1.061123
Temperature	-20.80024 °C
Cp	1.060915
Temperature	-19.83916 °C
Cp	1.060719
Temperature	-18.87807 °C
Cp	1.060531
Temperature	-17.917 °C
Cp	1.06035
Temperature	-16.95592 °C
Cp	1.060161
Temperature	-15.99484 °C
Cp	1.059992
Temperature	-15.03376 °C
Cp	1.059817
Temperature	-14.07268 °C
Cp	1.059634
Temperature	-13.1116 °C
Cp	1.059445
Temperature	-12.15052 °C
Cp	1.059248
Temperature	-11.18944 °C
Cp	1.059043
Temperature	-10.22836 °C
Cp	1.058842
Temperature	-9.267276 °C
Cp	1.058615
Temperature	-8.306196 °C
Cp	1.058388
Temperature	-7.345116 °C
Cp	1.058155
Temperature	-6.384036 °C
Cp	1.057911
Temperature	-5.422956 °C
Cp	1.057652
Temperature	-4.461876 °C
Cp	1.057356
Temperature	-3.500796 °C
Cp	1.057063
Temperature	-2.539716 °C
Cp	1.056732
Temperature	-1.578636 °C
Cp	1.056364
Temperature	-0.6175562 °C
Cp	1.05596
Temperature	0.3435238 °C
Cp	1.055523
Temperature	1.304604 °C
Cp	1.055066
Temperature	2.265684 °C
Cp	1.054561
Temperature	3.226764 °C
Cp	1.054035
Temperature	4.187844 °C
Cp	1.053488
Temperature	5.148924 °C
Cp	1.052922
Temperature	6.110003 °C
Cp	1.052337
Temperature	7.071084 °C
Cp	1.051736
Temperature	8.032164 °C
Cp	1.051118
Temperature	8.993243 °C
Cp	1.050488
Temperature	9.954324 °C
Cp	1.049848
Temperature	10.9154 °C
Cp	1.049202
Temperature	11.87648 °C
Cp	1.048552
Temperature	12.83756 °C
Cp	1.047902
Temperature	13.79864 °C
Cp	1.047255
Temperature	14.75972 °C
Cp	1.046615
Temperature	15.7208 °C
Cp	1.045983
Temperature	16.68188 °C
Cp	1.045362
Temperature	17.64296 °C
Cp	1.044756
Temperature	18.60404 °C
Cp	1.044164
Temperature	19.56512 °C
Cp	1.04358
Temperature	20.5262 °C
Cp	1.043027
Temperature	21.48728 °C
Cp	1.042485
Temperature	22.44836 °C
Cp	1.041958
Temperature	23.40944 °C
Cp	1.041446
Temperature	24.37052 °C
Cp	1.040952
Temperature	25.3316 °C
Cp	1.040493
Temperature	26.29268 °C
Cp	1.040022
Temperature	27.25376 °C
Cp	1.039578
Temperature	28.21484 °C
Cp	1.039158
Temperature	29.17592 °C
Cp	1.038758
Temperature	30.137 °C
Cp	1.038373
Temperature	31.09808 °C
Cp	1.037981
Temperature	32.05916 °C
Cp	1.03763
Temperature	33.02024 °C
Cp	1.037276
Temperature	33.98132 °C
Cp	1.03692
Temperature	34.9424 °C
Cp	1.036565
Temperature	35.90348 °C
Cp	1.036213
Temperature	36.86456 °C
Cp	1.035866
Temperature	37.82564 °C
Cp	1.035529
Temperature	38.78672 °C
Cp	1.035195
Temperature	39.7478 °C
Cp	1.034875
Temperature	40.70888 °C
Cp	1.034568
Temperature	41.66996 °C
Cp	1.034276
Temperature	42.63104 °C
Cp	1.033996
Temperature	43.59212 °C
Cp	1.033726
Temperature	44.5532 °C
Cp	1.033469
Temperature	45.51428 °C
Cp	1.033221
Temperature	46.47536 °C
Cp	1.03298
Temperature	47.43644 °C
Cp	1.032744
Temperature	48.39752 °C
Cp	1.032514
Temperature	49.3586 °C
Cp	1.032289
Temperature	50.31968 °C
Cp	1.032065
Temperature	51.28076 °C
Cp	1.031844
Temperature	52.24184 °C
Cp	1.031627
Temperature	53.20292 °C
Cp	1.031413
Temperature	54.164 °C
Cp	1.031203
Temperature	55.12508 °C
Cp	1.030989
Temperature	56.08616 °C
Cp	1.030791
Temperature	57.04724 °C
Cp	1.030595
Temperature	58.00832 °C
Cp	1.030403
Temperature	58.9694 °C
Cp	1.030217
Temperature	59.93048 °C
Cp	1.03004
Temperature	60.89156 °C
Cp	1.029871
Temperature	61.85264 °C
Cp	1.029718
Temperature	62.81372 °C
Cp	1.029567
Temperature	63.7748 °C
Cp	1.02943
Temperature	64.73589 °C
Cp	1.029304
Temperature	65.69696 °C
Cp	1.029185
Temperature	66.65804 °C
Cp	1.02907
Temperature	67.61913 °C
Cp	1.028946
Temperature	68.5802 °C
Cp	1.028831
Temperature	69.54128 °C
Cp	1.028703
Temperature	70.50237 °C
Cp	1.028561
Temperature	71.46344 °C
Cp	1.028404
Temperature	72.42452 °C
Cp	1.028234
Temperature	73.3856 °C
Cp	1.028063
Temperature	74.34668 °C
Cp	1.027861
Temperature	75.30776 °C
Cp	1.027657
Temperature	76.26884 °C
Cp	1.027451
Temperature	77.22992 °C
Cp	1.027243
Temperature	78.191 °C
Cp	1.027036
Temperature	79.15208 °C
Cp	1.026812
Temperature	80.11316 °C
Cp	1.026623
Temperature	81.07424 °C
Cp	1.026431
Temperature	82.03532 °C
Cp	1.026241
Temperature	82.9964 °C
Cp	1.02606
Temperature	83.95748 °C
Cp	1.025891
Temperature	84.91856 °C
Cp	1.025739
Temperature	85.87964 °C
Cp	1.025614
Temperature	86.84072 °C
Cp	1.025493
Temperature	87.8018 °C
Cp	1.0254
Temperature	88.76288 °C
Cp	1.025329
Temperature	89.72396 °C
Cp	1.025274
Temperature	90.68504 °C
Cp	1.025229
Temperature	91.64612 °C
Cp	1.025174
Temperature	92.6072 °C
Cp	1.025138
Temperature	93.56828 °C
Cp	1.025083
Temperature	94.52936 °C
Cp	1.025008
Temperature	95.49044 °C
Cp	1.024912
Temperature	96.45152 °C
Cp	1.024796
Temperature	97.4126 °C
Cp	1.024671
Temperature	98.37368 °C
Cp	1.024506
Temperature	99.33476 °C
Cp	1.02433
Temperature	100.2958 °C
Cp	1.024144
Temperature	101.2569 °C
Cp	1.023948
Temperature	102.218 °C
Cp	1.023743
Temperature	103.1791 °C
Cp	1.023522
Temperature	104.1402 °C
Cp	1.023309
Temperature	105.1012 °C
Cp	1.023089
Temperature	106.0623 °C
Cp	1.022866
Temperature	107.0234 °C
Cp	1.022644
Temperature	107.9845 °C
Cp	1.022427
Temperature	108.9456 °C
Cp	1.022218
Temperature	109.9066 °C
Cp	1.022022
Temperature	110.8677 °C
Cp	1.021836
Temperature	111.8288 °C
Cp	1.021666
Temperature	112.7899 °C
Cp	1.021512
Temperature	113.751 °C
Cp	1.021374
Temperature	114.712 °C
Cp	1.02125
Temperature	115.6731 °C
Cp	1.021137
Temperature	116.6342 °C
Cp	1.021041
Temperature	117.5953 °C
Cp	1.020953
Temperature	118.5564 °C
Cp	1.020872
Temperature	119.5174 °C
Cp	1.020796
Temperature	120.4785 °C
Cp	1.020725
Temperature	121.4396 °C
Cp	1.020659
Temperature	122.4007 °C
Cp	1.020587
Temperature	123.3618 °C
Cp	1.020515
Temperature	124.3228 °C
Cp	1.02044
Temperature	125.2839 °C
Cp	1.020359
Temperature	126.245 °C
Cp	1.02027
Temperature	127.2061 °C
Cp	1.020167
Temperature	128.1672 °C
Cp	1.020057
Temperature	129.1282 °C
Cp	1.019933
Temperature	130.0893 °C
Cp	1.019793
Temperature	131.0504 °C
Cp	1.019638
Temperature	132.0115 °C
Cp	1.019471
Temperature	132.9726 °C
Cp	1.019292
Temperature	133.9336 °C
Cp	1.019107
Temperature	134.8947 °C
Cp	1.018912
Temperature	135.8558 °C
Cp	1.018717
Temperature	136.8169 °C
Cp	1.018527
Temperature	137.778 °C
Cp	1.018344
Temperature	138.739 °C
Cp	1.018171
Temperature	139.7001 °C
Cp	1.018004
Temperature	140.6612 °C
Cp	1.01787
Temperature	141.6223 °C
Cp	1.01775
Temperature	142.5834 °C
Cp	1.017652
Temperature	143.5444 °C
Cp	1.017578
Temperature	144.5055 °C
Cp	1.017534
Temperature	145.4666 °C
Cp	1.017536
Temperature	146.4277 °C
Cp	1.017545
Temperature	147.3888 °C
Cp	1.017595
Temperature	148.3498 °C
Cp	1.017679
Temperature	149.3109 °C
Cp	1.01779
Temperature	150.272 °C
Cp	1.01792
Temperature	151.2331 °C
Cp	1.018043
Temperature	152.1942 °C
Cp	1.018199
Temperature	153.1552 °C
Cp	1.018339
Temperature	154.1163 °C
Cp	1.018458
Temperature	155.0774 °C
Cp	1.018552
Temperature	156.0385 °C
Cp	1.018618
Temperature	156.9996 °C
Cp	1.018662
Temperature	157.9606 °C
Cp	1.018664
Temperature	158.9217 °C
Cp	1.018632
Temperature	159.8828 °C
Cp	1.018575
Temperature	160.8439 °C
Cp	1.018492
Temperature	161.805 °C
Cp	1.018383
Temperature	162.766 °C
Cp	1.01825
Temperature	163.7271 °C
Cp	1.018087
Temperature	164.6882 °C
Cp	1.017917
Temperature	165.6493 °C
Cp	1.017726
Temperature	166.6104 °C
Cp	1.017522
Temperature	167.5714 °C
Cp	1.01731
Temperature	168.5325 °C
Cp	1.017098
Temperature	169.4936 °C
Cp	1.016902
Temperature	170.4547 °C
Cp	1.016695
Temperature	171.4158 °C
Cp	1.016508
Temperature	172.3768 °C
Cp	1.016342
Temperature	173.3379 °C
Cp	1.016195
Temperature	174.299 °C
Cp	1.016065
Temperature	175.2601 °C
Cp	1.015927
Temperature	176.2212 °C
Cp	1.015838
Temperature	177.1822 °C
Cp	1.015746
Temperature	178.1433 °C
Cp	1.015651
Temperature	179.1044 °C
Cp	1.015555
Temperature	180.0655 °C
Cp	1.015459
Temperature	181.0266 °C
Cp	1.015401
Temperature	181.9876 °C
Cp	1.015288
Temperature	182.9487 °C
Cp	1.015195
Temperature	183.9098 °C
Cp	1.015117
Temperature	184.8709 °C
Cp	1.01505
Temperature	185.832 °C
Cp	1.014988
Temperature	186.793 °C
Cp	1.014927
Temperature	187.7541 °C
Cp	1.014849
Temperature	188.7152 °C
Cp	1.014789
Temperature	189.6763 °C
Cp	1.01471
Temperature	190.6374 °C
Cp	1.014614
Temperature	191.5984 °C
Cp	1.014503
Temperature	192.5595 °C
Cp	1.014381
Temperature	193.5206 °C
Cp	1.014268
Temperature	194.4817 °C
Cp	1.014122
Temperature	195.4428 °C
Cp	1.013984
Temperature	196.4038 °C
Cp	1.013853
Temperature	197.3649 °C
Cp	1.013726
Temperature	198.326 °C
Cp	1.013603
Temperature	199.2871 °C
Cp	1.013467
Temperature	200.2482 °C
Cp	1.013359
Temperature	201.2092 °C
Cp	1.013243
Temperature	202.1703 °C
Cp	1.013123
Temperature	203.1314 °C
Cp	1.013002
Temperature	204.0925 °C
Cp	1.012884
Temperature	205.0536 °C
Cp	1.012788
Temperature	206.0146 °C
Cp	1.012674
Temperature	206.9757 °C
Cp	1.012579
Temperature	207.9368 °C
Cp	1.012501
Temperature	208.8979 °C
Cp	1.012439
Temperature	209.859 °C
Cp	1.012389
Temperature	210.82 °C
Cp	1.012351
Temperature	211.7811 °C
Cp	1.012312
Temperature	212.7422 °C
Cp	1.01229
Temperature	213.7033 °C
Cp	1.012262
Temperature	214.6644 °C
Cp	1.012227
Temperature	215.6254 °C
Cp	1.012183
Temperature	216.5865 °C
Cp	1.012129
Temperature	217.5476 °C
Cp	1.012077
Temperature	218.5087 °C
Cp	1.01199
Temperature	219.4698 °C
Cp	1.011897
Temperature	220.4308 °C
Cp	1.011793
Temperature	221.3919 °C
Cp	1.011674
Temperature	222.353 °C
Cp	1.011537
Temperature	223.3141 °C
Cp	1.011362
Temperature	224.2752 °C
Cp	1.011194
Temperature	225.2362 °C
Cp	1.010993
Temperature	226.1973 °C
Cp	1.010766
Temperature	227.1584 °C
Cp	1.010517
Temperature	228.1195 °C
Cp	1.010251
Temperature	229.0806 °C
Cp	1.009998
Temperature	230.0416 °C
Cp	1.009703
Temperature	231.0027 °C
Cp	1.009422
Temperature	231.9638 °C
Cp	1.009156
Temperature	232.9249 °C
Cp	1.008906
Temperature	233.886 °C
Cp	1.008675
Temperature	234.847 °C
Cp	1.008462
Temperature	235.8081 °C
Cp	1.008258
Temperature	236.7692 °C
Cp	1.00809
Temperature	237.7303 °C
Cp	1.007934
Temperature	238.6914 °C
Cp	1.007793
Temperature	239.6524 °C
Cp	1.007668
Temperature	240.6135 °C
Cp	1.007562
Temperature	241.5746 °C
Cp	1.007487
Temperature	242.5357 °C
Cp	1.00741
Temperature	243.4967 °C
Cp	1.00736
Temperature	244.4578 °C
Cp	1.007332
Temperature	245.4189 °C
Cp	1.007321
Temperature	246.38 °C
Cp	1.007321
Temperature	247.3411 °C
Cp	1.007312
Temperature	248.3022 °C
Cp	1.007331
Temperature	249.2632 °C
Cp	1.007338
Temperature	250.2243 °C
Cp	1.007335
Temperature	251.1854 °C
Cp	1.00732
Temperature	252.1465 °C
Cp	1.007295
Temperature	253.1076 °C
Cp	1.007277
Temperature	254.0686 °C
Cp	1.007227
Temperature	255.0297 °C
Cp	1.007179
Temperature	255.9908 °C
Cp	1.007133
Temperature	256.9519 °C
Cp	1.00709
Temperature	257.913 °C
Cp	1.007049
Temperature	258.874 °C
Cp	1.007012
Temperature	259.8351 °C
Cp	1.006978
Temperature	260.7962 °C
Cp	1.006956
Temperature	261.7573 °C
Cp	1.00694
Temperature	262.7184 °C
Cp	1.006934
Temperature	263.6794 °C
Cp	1.006939
Temperature	264.6405 °C
Cp	1.00696
Temperature	265.6016 °C
Cp	1.006999
Temperature	266.5627 °C
Cp	1.007054
Temperature	267.5237 °C
Cp	1.007131
Temperature	268.4848 °C
Cp	1.00723
Temperature	269.4459 °C
Cp	1.00735
Temperature	270.407 °C
Cp	1.007493
Temperature	271.3681 °C
Cp	1.007656
Temperature	272.3292 °C
Cp	1.007839
Temperature	273.2902 °C
Cp	1.008039
Temperature	274.2513 °C
Cp	1.008257
Temperature	275.2124 °C
Cp	1.008488
Temperature	276.1735 °C
Cp	1.008731
Temperature	277.1346 °C
Cp	1.008977
Temperature	278.0956 °C
Cp	1.009237
Temperature	279.0567 °C
Cp	1.009498
Temperature	280.0178 °C
Cp	1.009757
Temperature	280.9789 °C
Cp	1.010014
Temperature	281.9399 °C
Cp	1.010267
Temperature	282.901 °C
Cp	1.010515
Temperature	283.8621 °C
Cp	1.01076
Temperature	284.8232 °C
Cp	1.010993
Temperature	285.7843 °C
Cp	1.011222
Temperature	286.7454 °C
Cp	1.011447
Temperature	287.7064 °C
Cp	1.011665
Temperature	288.6675 °C
Cp	1.011876
Temperature	289.6286 °C
Cp	1.012079
Temperature	290.5897 °C
Cp	1.01228
Temperature	291.5508 °C
Cp	1.012474
Temperature	292.5118 °C
Cp	1.012662
Temperature	293.4729 °C
Cp	1.012846
Temperature	294.434 °C
Cp	1.013028
Temperature	295.3951 °C
Cp	1.013211
Temperature	296.3561 °C
Cp	1.013391
Temperature	297.3172 °C
Cp	1.013574
Temperature	298.2783 °C
Cp	1.013759
Temperature	299.2394 °C
Cp	1.013947
Temperature	300.2005 °C
Cp	1.014136
Temperature	301.1616 °C
Cp	1.01432
Temperature	302.1226 °C
Cp	1.014511
Temperature	303.0837 °C
Cp	1.014695
Temperature	304.0448 °C
Cp	1.014872
Temperature	305.0059 °C
Cp	1.01504
Temperature	305.9669 °C
Cp	1.015198
Temperature	306.928 °C
Cp	1.015343
Temperature	307.8891 °C
Cp	1.015479
Temperature	308.8502 °C
Cp	1.015595
Temperature	309.8113 °C
Cp	1.015699
Temperature	310.7724 °C
Cp	1.015789
Temperature	311.7334 °C
Cp	1.015865
Temperature	312.6945 °C
Cp	1.015925
Temperature	313.6556 °C
Cp	1.015964
Temperature	314.6167 °C
Cp	1.015999
Temperature	315.5778 °C
Cp	1.016018
Temperature	316.5388 °C
Cp	1.016025
Temperature	317.4999 °C
Cp	1.016024
Temperature	318.461 °C
Cp	1.01602
Temperature	319.4221 °C
Cp	1.016029
Temperature	320.3831 °C
Cp	1.016025
Temperature	321.3442 °C
Cp	1.016037
Temperature	322.3053 °C
Cp	1.016066
Temperature	323.2664 °C
Cp	1.01611
Temperature	324.2275 °C
Cp	1.016169
Temperature	325.1886 °C
Cp	1.016225
Temperature	326.1496 °C
Cp	1.016318
Temperature	327.1107 °C
Cp	1.016411
Temperature	328.0718 °C
Cp	1.016504
Temperature	329.0329 °C
Cp	1.016596
Temperature	329.994 °C
Cp	1.016687
Temperature	330.955 °C
Cp	1.016775
Temperature	331.9161 °C
Cp	1.016864
Temperature	332.8772 °C
Cp	1.016942
Temperature	333.8383 °C
Cp	1.017019
Temperature	334.7993 °C
Cp	1.017093
Temperature	335.7604 °C
Cp	1.017163
Temperature	336.7215 °C
Cp	1.01723
Temperature	337.6826 °C
Cp	1.017295
Temperature	338.6437 °C
Cp	1.017358
Temperature	339.6048 °C
Cp	1.017423
Temperature	340.5658 °C
Cp	1.017491
[...]
151.5833	110.9315	0.3705
151.5917	110.8481	0.3704
151.6000	110.7643	0.3704
151.6083	110.6823	0.3704
151.6167	110.5983	0.3704
151.6250	110.5163	0.3703
151.6333	110.4321	0.3702
151.6417	110.3491	0.3702
151.6500	110.2663	0.3701
151.6583	110.1835	0.3701
151.6667	110.0996	0.3701
151.6750	110.0162	0.3701
151.6833	109.9331	0.3700
151.6917	109.8503	0.3700
151.7000	109.7663	0.3699
151.7083	109.6841	0.3699
151.7167	109.6013	0.3699
151.7250	109.5170	0.3698
151.7333	109.4343	0.3698
151.7417	109.3521	0.3697
151.7500	109.2684	0.3696
151.7583	109.1848	0.3696
151.7667	109.1019	0.3695
151.7750	109.0188	0.3695
151.7833	108.9354	0.3694
151.7917	108.8532	0.3694
151.8000	108.7693	0.3694
151.8083	108.6857	0.3693
151.8167	108.6035	0.3693
151.8250	108.5207	0.3693
151.8333	108.4383	0.3692
151.8417	108.3535	0.3692
151.8500	108.2708	0.3691
151.8583	108.1871	0.3691
151.8667	108.1047	0.3691
151.8750	108.0217	0.3690
151.8833	107.9388	0.3690
151.8917	107.8550	0.3689
151.9000	107.7722	0.3689
151.9083	107.6893	0.3689
151.9167	107.6057	0.3689
151.9250	107.5226	0.3688
151.9333	107.4395	0.3688
151.9417	107.3546	0.3688
151.9500	107.2735	0.3687
151.9583	107.1891	0.3687
151.9667	107.1062	0.3686
151.9750	107.0228	0.3686
151.9833	106.9404	0.3685
151.9917	106.8569	0.3685
152.0000	106.7733	0.3685
152.0083	106.6902	0.3684
152.0167	106.6074	0.3684
152.0250	106.5245	0.3683
152.0333	106.4419	0.3683
152.0417	106.3582	0.3683
152.0500	106.2751	0.3682
152.0583	106.1915	0.3681
152.0667	106.1088	0.3680
152.0750	106.0257	0.3680
152.0833	105.9422	0.3679
152.0917	105.8588	0.3679
152.1000	105.7766	0.3679
152.1083	105.6933	0.3678
152.1167	105.6107	0.3677
152.1250	105.5274	0.3677
152.1333	105.4435	0.3677
152.1417	105.3609	0.3677
152.1500	105.2778	0.3677
152.1583	105.1944	0.3676
152.1667	105.1114	0.3675
152.1750	105.0279	0.3675
152.1833	104.9449	0.3675
152.1917	104.8611	0.3675
152.2000	104.7775	0.3675
152.2083	104.6950	0.3674
152.2167	104.6128	0.3674
152.2250	104.5296	0.3673
152.2333	104.4458	0.3673
152.2417	104.3631	0.3673
152.2500	104.2795	0.3671
152.2583	104.1971	0.3671
152.2667	104.1139	0.3671
152.2750	104.0305	0.3670
152.2833	103.9462	0.3670
152.2917	103.8627	0.3669
152.3000	103.7803	0.3669
152.3083	103.6973	0.3669
152.3167	103.6146	0.3669
152.3250	103.5303	0.3668
152.3333	103.4478	0.3668
152.3417	103.3642	0.3667
152.3500	103.2818	0.3667
152.3583	103.1981	0.3667
152.3667	103.1143	0.3667
152.3750	103.0317	0.3667
152.3833	102.9492	0.3665
152.3917	102.8651	0.3664
152.4000	102.7820	0.3664
152.4083	102.6992	0.3663
152.4167	102.6158	0.3663
152.4250	102.5329	0.3663
152.4333	102.4493	0.3662
152.4417	102.3666	0.3662
152.4500	102.2839	0.3661
152.4583	102.2000	0.3661
152.4667	102.1176	0.3660
152.4750	102.0341	0.3660
152.4833	101.9517	0.3660
152.4917	101.8677	0.3660
152.5000	101.7850	0.3659
152.5083	101.7012	0.3659
152.5167	101.6184	0.3658
152.5250	101.5349	0.3658
152.5333	101.4523	0.3658
152.5417	101.3684	0.3658
152.5500	101.2857	0.3657
152.5583	101.2033	0.3655
152.5667	101.1187	0.3655
152.5750	101.0363	0.3655
152.5833	100.9532	0.3655
152.5917	100.8698	0.3654
152.6000	100.7860	0.3654
152.6083	100.7035	0.3653
152.6167	100.6198	0.3653
152.6250	100.5376	0.3653
152.6333	100.4536	0.3653
152.6417	100.3702	0.3652
152.6500	100.2874	0.3652
152.6583	100.2043	0.3652
152.6667	100.1209	0.3651
152.6750	100.0383	0.3650
152.6833	99.9549	0.3650
152.6917	99.8709	0.3650
152.7000	99.7886	0.3647
152.7083	99.7054	0.3646
152.7167	99.6221	0.3646
152.7250	99.5398	0.3646
152.7333	99.4555	0.3645
152.7417	99.3725	0.3645
152.7500	99.2909	0.3645
152.7583	99.2066	0.3644
152.7667	99.1243	0.3644
152.7750	99.0407	0.3644
152.7833	98.9565	0.3643
152.7917	98.8736	0.3643
152.8000	98.7908	0.3643
152.8083	98.7065	0.3642
152.8167	98.6236	0.3642
152.8250	98.5416	0.3641
152.8333	98.4574	0.3641
152.8417	98.3751	0.3640
152.8500	98.2912	0.3640
152.8583	98.2078	0.3639
152.8667	98.1258	0.3639
152.8750	98.0408	0.3638
152.8833	97.9591	0.3638
152.8917	97.8753	0.3638
152.9000	97.7921	0.3638
152.9083	97.7095	0.3637
152.9167	97.6263	0.3636
152.9250	97.5420	0.3636
152.9333	97.4603	0.3636
152.9417	97.3774	0.3635
152.9500	97.2924	0.3633
152.9583	97.2112	0.3632
152.9667	97.1270	0.3632
152.9750	97.0439	0.3632
152.9833	96.9612	0.3631
152.9917	96.8771	0.3631
153.0000	96.7956	0.3630
153.0083	96.7113	0.3630
153.0167	96.6278	0.3630
153.0250	96.5453	0.3629
153.0333	96.4614	0.3628
153.0417	96.3788	0.3628
153.0500	96.2949	0.3628
153.0583	96.2133	0.3627
153.0667	96.1291	0.3627
153.0750	96.0458	0.3626
153.0833	95.9623	0.3626
153.0917	95.8796	0.3624
153.1000	95.7964	0.3624
153.1083	95.7129	0.3624
153.1167	95.6305	0.3623
153.1250	95.5469	0.3623
153.1333	95.4632	0.3623
153.1417	95.3816	0.3622
153.1500	95.2970	0.3622
153.1583	95.2138	0.3621
153.1667	95.1320	0.3621
153.1750	95.0489	0.3620
153.1833	94.9653	0.3620
153.1917	94.8818	0.3620
153.2000	94.7997	0.3619
153.2083	94.7149	0.3618
153.2167	94.6331	0.3618
153.2250	94.5491	0.3618
153.2333	94.4659	0.3616
153.2417	94.3825	0.3616
153.2500	94.2991	0.3616
153.2583	94.2176	0.3615
153.2667	94.1333	0.3615
153.2750	94.0496	0.3615
153.2833	93.9674	0.3614
153.2917	93.8831	0.3613
153.3000	93.8006	0.3613
153.3083	93.7176	0.3613
153.3167	93.6344	0.3612
153.3250	93.5504	0.3612
153.3333	93.4674	0.3611
153.3417	93.3848	0.3610
153.3500	93.3022	0.3610
153.3583	93.2180	0.3610
153.3667	93.1343	0.3609
153.3750	93.0523	0.3608
153.3833	92.9681	0.3608
153.3917	92.8864	0.3608
153.4000	92.8021	0.3607
153.4083	92.7198	0.3608
153.4167	92.6370	0.3608
153.4250	92.5526	0.3607
153.4333	92.4686	0.3606
153.4417	92.3877	0.3606
153.4500	92.3040	0.3604
153.4583	92.2210	0.3604
153.4667	92.1374	0.3604
153.4750	92.0541	0.3603
153.4833	91.9704	0.3603
153.4917	91.8873	0.3603
153.5000	91.8044	0.3602
153.5083	91.7217	0.3602
153.5167	91.6388	0.3601
153.5250	91.5553	0.3601
153.5333	91.4719	0.3601
153.5417	91.3891	0.3600
153.5500	91.3059	0.3599
153.5583	91.2221	0.3598
153.5667	91.1392	0.3599
153.5750	91.0566	0.3598
153.5833	90.9731	0.3598
153.5917	90.8915	0.3598
153.6000	90.8078	0.3597
153.6083	90.7237	0.3596
153.6167	90.6407	0.3596
153.6250	90.5570	0.3596
153.6333	90.4747	0.3595
153.6417	90.3920	0.3595
153.6500	90.3084	0.3594
153.6583	90.2244	0.3594
153.6667	90.1407	0.3593
153.6750	90.0579	0.3593
153.6833	89.9747	0.3592
153.6917	89.8919	0.3592
153.7000	89.8088	0.3592
153.7083	89.7259	0.3591
153.7167	89.6440	0.3591
153.7250	89.5601	0.3590
153.7333	89.4774	0.3590
153.7417	89.3939	0.3589
153.7500	89.3111	0.3589
153.7583	89.2275	0.3588
153.7667	89.1445	0.3588
153.7750	89.0614	0.3587
153.7833	88.9781	0.3587
153.7917	88.8942	0.3587
153.8000	88.8111	0.3586
153.8083	88.7274	0.3586
153.8167	88.6448	0.3586
153.8250	88.5619	0.3586
153.8333	88.4778	0.3585
153.8417	88.3952	0.3585
153.8500	88.3125	0.3584
153.8583	88.2285	0.3584
153.8667	88.1457	0.3583
153.8750	88.0623	0.3583
153.8833	87.9788	0.3582
153.8917	87.8969	0.3582
153.9000	87.8125	0.3582
153.9083	87.7296	0.3582
153.9167	87.6459	0.3581
153.9250	87.5638	0.3580
153.9333	87.4812	0.3579
153.9417	87.3970	0.3580
153.9500	87.3150	0.3579
153.9583	87.2306	0.3579
153.9667	87.1473	0.3578
153.9750	87.0648	0.3577
153.9833	86.9813	0.3577
153.9917	86.8983	0.3577
154.0000	86.8150	0.3577
154.0083	86.7325	0.3576
154.0167	86.6497	0.3574
154.0250	86.5658	0.3574
154.0333	86.4823	0.3573
154.0417	86.3997	0.3573
154.0500	86.3172	0.3573
154.0583	86.2336	0.3572
154.0667	86.1503	0.3572
154.0750	86.0660	0.3572
154.0833	85.9829	0.3571
154.0917	85.8999	0.3571
154.1000	85.8167	0.3571
154.1083	85.7347	0.3570
154.1167	85.6502	0.3570
154.1250	85.5671	0.3570
154.1333	85.4849	0.3569
154.1417	85.4018	0.3569
154.1500	85.3176	0.3569
154.1583	85.2351	0.3568
154.1667	85.1523	0.3568
154.1750	85.0691	0.3567
154.1833	84.9867	0.3567
154.1917	84.9036	0.3566
154.2000	84.8200	0.3566
154.2083	84.7363	0.3565
154.2167	84.6531	0.3565
154.2250	84.5692	0.3565
154.2333	84.4874	0.3564
154.2417	84.4041	0.3563
154.2500	84.3209	0.3563
154.2583	84.2366	0.3562
154.2667	84.1546	0.3562
154.2750	84.0708	0.3562
154.2833	83.9886	0.3561
154.2917	83.9049	0.3561
154.3000	83.8211	0.3561
154.3083	83.7381	0.3560
154.3167	83.6557	0.3560
154.3250	83.5723	0.3560
154.3333	83.4885	0.3560
154.3417	83.4068	0.3558
154.3500	83.3230	0.3557
154.3583	83.2399	0.3557
154.3667	83.1566	0.3556
154.3750	83.0728	0.3556
154.3833	82.9908	0.3555
154.3917	82.9074	0.3555
154.4000	82.8240	0.3555
154.4083	82.7412	0.3554
154.4167	82.6576	0.3553
154.4250	82.5736	0.3553
154.4333	82.4920	0.3553
154.4417	82.4086	0.3552
154.4500	82.3249	0.3552
154.4583	82.2418	0.3551
154.4667	82.1581	0.3551
154.4750	82.0756	0.3551
154.4833	81.9916	0.3550
154.4917	81.9087	0.3549
154.5000	81.8258	0.3549
154.5083	81.7429	0.3549
154.5167	81.6596	0.3548
154.5250	81.5767	0.3548
154.5333	81.4927	0.3548
154.5417	81.4096	0.3547
154.5500	81.3273	0.3547
154.5583	81.2440	0.3545
154.5667	81.1611	0.3545
154.5750	81.0762	0.3544
154.5833	80.9940	0.3543
154.5917	80.9105	0.3543
154.6000	80.8274	0.3542
154.6083	80.7437	0.3542
154.6167	80.6608	0.3542
154.6250	80.5784	0.3541
154.6333	80.4953	0.3541
154.6417	80.4113	0.3541
154.6500	80.3281	0.3540
154.6583	80.2460	0.3540
154.6667	80.1624	0.3539
154.6750	80.0791	0.3538
154.6833	79.9950	0.3538
154.6917	79.9135	0.3537
154.7000	79.8295	0.3534
154.7083	79.7466	0.3534
154.7167	79.6638	0.3534
154.7250	79.5797	0.3533
154.7333	79.4973	0.3533
154.7417	79.4141	0.3533
154.7500	79.3310	0.3533
154.7583	79.2464	0.3533
154.7667	79.1639	0.3532
154.7750	79.0795	0.3532
154.7833	78.9975	0.3532
154.7917	78.9141	0.3531
154.8000	78.8318	0.3531
154.8083	78.7489	0.3531
154.8167	78.6644	0.3530
154.8250	78.5828	0.3528
154.8333	78.4989	0.3527
154.8417	78.4151	0.3527
154.8500	78.3327	0.3527
154.8583	78.2499	0.3526
154.8667	78.1673	0.3526
154.8750	78.0833	0.3525
154.8833	78.0006	0.3525
154.8917	77.9177	0.3524
154.9000	77.8334	0.3524
154.9083	77.7508	0.3524
154.9167	77.6682	0.3523
154.9250	77.5847	0.3523
154.9333	77.5016	0.3522
154.9417	77.4184	0.3522
154.9500	77.3349	0.3522
154.9583	77.2509	0.3522
154.9667	77.1691	0.3521
154.9750	77.0849	0.3521
154.9833	77.0015	0.3520
154.9917	76.9177	0.3519
155.0000	76.8350	0.3519
155.0083	76.7515	0.3518
155.0167	76.6683	0.3518
155.0250	76.5854	0.3518
155.0333	76.5032	0.3517
155.0417	76.4193	0.3517
155.0500	76.3359	0.3516
155.0583	76.2526	0.3515
155.0667	76.1703	0.3515
155.0750	76.0867	0.3515
155.0833	76.0039	0.3514
155.0917	75.9212	0.3514
155.1000	75.8376	0.3513
155.1083	75.7546	0.3513
155.1167	75.6702	0.3512
155.1250	75.5877	0.3512
155.1333	75.5053	0.3511
155.1417	75.4212	0.3511
155.1500	75.3377	0.3511
155.1583	75.2548	0.3510
155.1667	75.1723	0.3510
155.1750	75.0883	0.3509
155.1833	75.0059	0.3509
155.1917	74.9218	0.3509
155.2000	74.8400	0.3506
155.2083	74.7553	0.3505
155.2167	74.6729	0.3505
155.2250	74.5901	0.3504
155.2333	74.5058	0.3503
155.2417	74.4241	0.3504
155.2500	74.3404	0.3504
155.2583	74.2573	0.3503
155.2667	74.1750	0.3503
155.2750	74.0906	0.3503
155.2833	74.0083	0.3503
155.2917	73.9240	0.3500
155.3000	73.8418	0.3498
155.3083	73.7573	0.3498
155.3167	73.6756	0.3497
155.3250	73.5920	0.3496
155.3333	73.5082	0.3496
155.3417	73.4259	0.3495
155.3500	73.3427	0.3495
155.3583	73.2590	0.3494
155.3667	73.1759	0.3495
155.3750	73.0930	0.3494
155.3833	73.0092	0.3494
155.3917	72.9278	0.3493
155.4000	72.8442	0.3493
155.4083	72.7603	0.3492
155.4167	72.6775	0.3492
155.4250	72.5950	0.3491
155.4333	72.5112	0.3491
155.4417	72.4279	0.3491
155.4500	72.3452	0.3490
155.4583	72.2613	0.3489
155.4667	72.1782	0.3489
155.4750	72.0953	0.3488
155.4833	72.0112	0.3488
155.4917	71.9286	0.3487
155.5000	71.8449	0.3487
155.5083	71.7618	0.3487
155.5167	71.6791	0.3486
155.5250	71.5956	0.3486
155.5333	71.5126	0.3485
155.5417	71.4291	0.3486
155.5500	71.3450	0.3485
155.5583	71.2642	0.3482
155.5667	71.1807	0.3481
155.5750	71.0973	0.3481
155.5833	71.0131	0.3481
155.5917	70.9306	0.3480
155.6000	70.8481	0.3480
155.6083	70.7640	0.3480
155.6167	70.6820	0.3479
155.6250	70.5981	0.3479
155.6333	70.5149	0.3479
155.6417	70.4313	0.3479
155.6500	70.3489	0.3478
155.6583	70.2663	0.3477
155.6667	70.1820	0.3477
155.6750	70.0991	0.3477
155.6833	70.0157	0.3476
155.6917	69.9328	0.3476
155.7000	69.8497	0.3476
155.7083	69.7661	0.3475
155.7167	69.6831	0.3473
155.7250	69.5997	0.3473
155.7333	69.5173	0.3472
155.7417	69.4336	0.3472
155.7500	69.3506	0.3472
155.7583	69.2673	0.3471
155.7667	69.1847	0.3471
155.7750	69.1006	0.3470
155.7833	69.0176	0.3470
155.7917	68.9341	0.3470
155.8000	68.8523	0.3468
155.8083	68.7687	0.3468
155.8167	68.6862	0.3468
155.8250	68.6016	0.3468
155.8333	68.5183	0.3467
155.8417	68.4342	0.3467
155.8500	68.3524	0.3467
155.8583	68.2694	0.3466
155.8667	68.1854	0.3466
155.8750	68.1027	0.3466
155.8833	68.0200	0.3465
155.8917	67.9358	0.3465
155.9000	67.8519	0.3465
155.9083	67.7698	0.3464
155.9167	67.6868	0.3463
155.9250	67.6045	0.3463
155.9333	67.5202	0.3463
155.9417	67.4366	0.3463
155.9500	67.3535	0.3461
155.9583	67.2712	0.3460
155.9667	67.1873	0.3460
155.9750	67.1037	0.3460
155.9833	67.0209	0.3460
155.9917	66.9388	0.3459
156.0000	66.8551	0.3459
156.0083	66.7722	0.3458
156.0167	66.6881	0.3456
156.0250	66.6058	0.3456
156.0333	66.5224	0.3456
156.0417	66.4390	0.3455
156.0500	66.3569	0.3452
156.0583	66.2733	0.3452
156.0667	66.1899	0.3452
156.0750	66.1056	0.3452
156.0833	66.0230	0.3452
156.0917	65.9412	0.3451
156.1000	65.8575	0.3450
156.1083	65.7739	0.3450
156.1167	65.6908	0.3449
156.1250	65.6073	0.3449
156.1333	65.5253	0.3448
156.1417	65.4421	0.3448
156.1500	65.3576	0.3447
156.1583	65.2747	0.3447
156.1667	65.1911	0.3447
156.1750	65.1089	0.3447
156.1833	65.0263	0.3447
156.1917	64.9421	0.3447
156.2000	64.8597	0.3447
156.2083	64.7774	0.3448
156.2167	64.6936	0.3448
156.2250	64.6111	0.3448
156.2333	64.5273	0.3457
156.2417	64.4442	0.3464
156.2500	64.3617	0.3473
156.2583	64.2790	0.3510
156.2667	64.1972	0.3569
156.2750	64.1134	0.3627
156.2833	64.0315	0.3699
156.2917	63.9503	0.3808
156.3000	63.8665	0.3911
156.3083	63.7865	0.4088
156.3167	63.7072	0.4345
156.3250	63.6287	0.4675
156.3333	63.5523	0.5179
156.3417	63.4763	0.5870
156.3500	63.4053	0.6794
156.3583	63.3402	0.8039
156.3667	63.2794	0.9707
156.3750	63.2264	1.1739
156.3833	63.1834	1.4163
156.3917	63.1498	1.6928
156.4000	63.1257	1.9826
156.4083	63.1116	2.2740
156.4167	63.1023	2.5486
156.4250	63.1017	2.7980
156.4333	63.1031	3.0156
156.4417	63.1048	3.2041
156.4500	63.1083	3.3639
156.4583	63.1092	3.4980
156.4667	63.1070	3.6125
156.4750	63.1013	3.7100
156.4833	63.0925	3.7947
156.4917	63.0809	3.8709
156.5000	63.0647	3.9392
156.5083	63.0452	4.0014
156.5167	63.0209	4.0599
156.5250	62.9956	4.1149
156.5333	62.9654	4.1661
156.5417	62.9327	4.2149
156.5500	62.8979	4.2606
156.5583	62.8601	4.3042
156.5667	62.8209	4.3453
156.5750	62.7777	4.3826
156.5833	62.7313	4.4195
156.5917	62.6843	4.4514
156.6000	62.6355	4.4783
156.6083	62.5851	4.5054
156.6167	62.5307	4.5259
156.6250	62.4765	4.5442
156.6333	62.4179	4.5592
156.6417	62.3587	4.5682
156.6500	62.2974	4.5762
156.6583	62.2330	4.5771
156.6667	62.1680	4.5729
156.6750	62.1001	4.5679
156.6833	62.0311	4.5560
156.6917	61.9592	4.5415
156.7000	61.8871	4.5213
156.7083	61.8098	4.4970
156.7167	61.7324	4.4669
156.7250	61.6537	4.4344
156.7333	61.5699	4.3945
156.7417	61.4865	4.3492
156.7500	61.3988	4.2984
156.7583	61.3105	4.2442
156.7667	61.2184	4.1823
156.7750	61.1256	4.1135
156.7833	61.0274	4.0412
156.7917	60.9304	3.9632
156.8000	60.8284	3.8797
156.8083	60.7242	3.7922
156.8167	60.6184	3.7023
156.8250	60.5097	3.6079
156.8333	60.3998	3.5151
156.8417	60.2858	3.4214
156.8500	60.1720	3.3273
156.8583	60.0565	3.2367
156.8667	59.9395	3.1486
156.8750	59.8225	3.0638
156.8833	59.7031	2.9829
156.8917	59.5842	2.9012
156.9000	59.4647	2.8237
156.9083	59.3440	2.7481
156.9167	59.2253	2.6752
156.9250	59.1062	2.6044
156.9333	58.9876	2.5391
156.9417	58.8670	2.4738
156.9500	58.7487	2.4122
156.9583	58.6311	2.3492
156.9667	58.5137	2.2910
156.9750	58.3957	2.2347
156.9833	58.2795	2.1790
156.9917	58.1636	2.1236
157.0000	58.0487	2.0742
157.0083	57.9345	2.0240
157.0167	57.8201	1.9744
157.0250	57.7074	1.9270
157.0333	57.5956	1.8818
157.0417	57.4824	1.8375
157.0500	57.3723	1.7934
157.0583	57.2623	1.7514
157.0667	57.1525	1.7132
157.0750	57.0429	1.6771
157.0833	56.9351	1.6413
157.0917	56.8271	1.6092
157.1000	56.7193	1.5755
157.1083	56.6135	1.5414
157.1167	56.5083	1.5078
157.1250	56.4037	1.4762
157.1333	56.3000	1.4452
157.1417	56.1965	1.4181
157.1500	56.0940	1.3911
157.1583	55.9916	1.3629
157.1667	55.8892	1.3382
157.1750	55.7891	1.3125
157.1833	55.6895	1.2893
157.1917	55.5890	1.2662
157.2000	55.4895	1.2445
157.2083	55.3902	1.2199
157.2167	55.2918	1.2000
157.2250	55.1947	1.1792
157.2333	55.0962	1.1582
157.2417	54.9996	1.1394
157.2500	54.9017	1.1214
157.2583	54.8054	1.1036
157.2667	54.7094	1.0851
157.2750	54.6141	1.0684
157.2833	54.5204	1.0527
157.2917	54.4251	1.0365
157.3000	54.3307	1.0224
157.3083	54.2358	1.0069
157.3167	54.1430	0.9933
157.3250	54.0498	0.9778
157.3333	53.9574	0.9647
157.3417	53.8642	0.9515
157.3500	53.7721	0.9386
157.3583	53.6805	0.9275
157.3667	53.5887	0.9161
157.3750	53.4961	0.9044
157.3833	53.4054	0.8934
157.3917	53.3147	0.8821
157.4000	53.2238	0.8722
157.4083	53.1336	0.8618
157.4167	53.0431	0.8504
157.4250	52.9528	0.8415
157.4333	52.8630	0.8337
157.4417	52.7735	0.8230
157.4500	52.6836	0.8140
157.4583	52.5944	0.8072
157.4667	52.5051	0.7979
157.4750	52.4176	0.7895
157.4833	52.3270	0.7811
157.4917	52.2400	0.7743
157.5000	52.1512	0.7666
157.5083	52.0629	0.7596
157.5167	51.9752	0.7528
157.5250	51.8869	0.7459
157.5333	51.7995	0.7385
157.5417	51.7113	0.7333
157.5500	51.6237	0.7274
157.5583	51.5372	0.7196
157.5667	51.4495	0.7159
157.5750	51.3620	0.7094
157.5833	51.2751	0.7038
157.5917	51.1878	0.6986
157.6000	51.1017	0.6917
157.6083	51.0152	0.6871
157.6167	50.9281	0.6841
157.6250	50.8415	0.6773
157.6333	50.7561	0.6726
157.6417	50.6698	0.6686
157.6500	50.5826	0.6633
157.6583	50.4969	0.6588
157.6667	50.4108	0.6528
157.6750	50.3251	0.6489
157.6833	50.2390	0.6445
157.6917	50.1535	0.6429
157.7000	50.0669	0.6377
157.7083	49.9811	0.6332
157.7167	49.8967	0.6303
157.7250	49.8091	0.6263
157.7333	49.7227	0.6222
157.7417	49.6366	0.6185
157.7500	49.5537	0.6148
157.7583	49.4671	0.6111
157.7667	49.3822	0.6069
157.7750	49.2960	0.6063
157.7833	49.2121	0.6009
157.7917	49.1264	0.5986
157.8000	49.0404	0.5954
157.8083	48.9566	0.5904
157.8167	48.8717	0.5874
157.8250	48.7862	0.5868
157.8333	48.7011	0.5832
157.8417	48.6171	0.5814
157.8500	48.5317	0.5761
157.8583	48.4464	0.5746
157.8667	48.3605	0.5735
157.8750	48.2756	0.5694
157.8833	48.1920	0.5674
157.8917	48.1066	0.5644
157.9000	48.0215	0.5603
157.9083	47.9375	0.5593
157.9167	47.8538	0.5587
157.9250	47.7689	0.5530
157.9333	47.6843	0.5528
157.9417	47.5988	0.5520
157.9500	47.5153	0.5466
157.9583	47.4307	0.5458
157.9667	47.3458	0.5441
157.9750	47.2612	0.5417
157.9833	47.1773	0.5373
157.9917	47.0922	0.5375
158.0000	47.0081	0.5349
158.0083	46.9214	0.5335
158.0167	46.8382	0.5311
158.0250	46.7542	0.5293
158.0333	46.6705	0.5259
158.0417	46.5865	0.5252
158.0500	46.5018	0.5228
158.0583	46.4176	0.5209
158.0667	46.3333	0.5194
158.0750	46.2491	0.5177
158.0833	46.1649	0.5161
158.0917	46.0807	0.5145
158.1000	45.9949	0.5129
158.1083	45.9114	0.5103
158.1167	45.8274	0.5080
158.1250	45.7428	0.5069
158.1333	45.6592	0.5053
158.1417	45.5755	0.5044
158.1500	45.4906	0.5030
158.1583	45.4065	0.5010
158.1667	45.3232	0.4996
158.1750	45.2379	0.4971
158.1833	45.1552	0.4956
158.1917	45.0698	0.4937
158.2000	44.9862	0.4919
158.2083	44.9033	0.4907
158.2167	44.8184	0.4886
158.2250	44.7336	0.4878
158.2333	44.6508	0.4867
158.2417	44.5660	0.4845
158.2500	44.4824	0.4835
158.2583	44.3981	0.4819
158.2667	44.3149	0.4796
158.2750	44.2308	0.4782
158.2833	44.1474	0.4778
158.2917	44.0625	0.4766
158.3000	43.9787	0.4749
158.3083	43.8949	0.4728
158.3167	43.8112	0.4706
158.3250	43.7267	0.4692
158.3333	43.6427	0.4687
158.3417	43.5597	0.4684
158.3500	43.4743	0.4670
158.3583	43.3908	0.4634
158.3667	43.3085	0.4627
158.3750	43.2228	0.4623
158.3833	43.1399	0.4598
158.3917	43.0557	0.4594
158.4000	42.9713	0.4590
158.4083	42.8871	0.4577
158.4167	42.8033	0.4568
158.4250	42.7195	0.4552
158.4333	42.6349	0.4546
158.4417	42.5511
158.4500	42.4669
158.4583	42.3835
158.4667	42.3009
158.4750	42.2169
158.4833	42.1325
158.4917