File: Example Date/My Sample/DSC/test01/DSC TA/YN042.txt
Filename	YN042
Instrument name	DSC2A-01799 (192.168.1.250)
Operator
rundate	02/12/2024
Sample name	YN042
proceduresegments	Ramp 10.00 °C/min to 150.0000 °C; Isothermal 3.0 min; Ramp 10.00 °C/min to -100.0000 °C; Isothermal 3.0 min; Ramp 10.00 °C/min to 150.0000 °C; Isothermal 3.0 min; Ramp 10.00 °C/min to -100.0000 °C; Isothermal 3.0 min; Ramp 10.00 °C/min to 150.0000 °C; Isothermal 3.0 min; Ramp 10.00 °C/min to -100.0000 °C; Isothermal 3.0 min; Ramp 10.00 °C/min to 150.0000 °C; Isothermal 3.0 min; Ramp 10.00 °C/min to 40.0000 °C
[File Parameters]
Run Date	02/12/2024 19:48:43
Trios version	5.7.0.56
Original File Name
Current File Name	C:\Users\TA Instruments DSC\Desktop\Data\Yutong Niu\2024-1126\YN042.tri
User at run start	DESKTOP-CFGN8IT\TA Instruments DSC
[Procedure]
Procedure Name	polyether
Sample Name	YN042
Sample Mass	7.52 mg
Reference Sample Mass	0 mg
Pan Mass	61.21 mg
Pan Number	19
Reference Pan Mass	60.81 mg
Reference Pan Number	45
Pan Type	Tzero Aluminum Pin Hole Hermetic
Comments
Project Name
Operator
Test	Custom
Unload Max Temperature	25
Unload Min Temperature	25
FillCooler	Do not fill
Load Max Temperature	25
Load Min Temperature	25
Discard pan in waste bin at end of test	Yes
Stop on Gas Flow Error	No
[Signal List]
Signal #1	Time (min)
Signal #2	Temperature (°C)
Signal #3	Heat Flow (mW)
Signal #4	Delta T (µV)
Signal #5	Delta Tzero (µV)
Signal #6	Tzero Temperature (°C)
Signal #7	Cell Purge (mL/min)
Signal #8	Heater Temp (°C)
Signal #9	Power Delivered (W)
Signal #10	Reference Junction Temperature (°C)
Signal #11	Flange Temperature (°C)
Signal #12	Heat Flow Phase (rad)
Signal #13	Total Heat Capacity (J/°C)
Signal #14	Heat Capacity (J/°C)
Signal #15	LN Pump Tank level (%)
[Configuration]
Company Name	Warwick University
Instrument Name	DSC2A-01799
Instrument Type	DSC2500
Serial Number	DSC2A-01799
IP	192.168.1.250
Location of Instrument	Polymer RTP
DisplayType	TianmaV2andV3
Sample Interval 	0.1 s/pt
Selected Heat Flow	T4P
Exotherm Direction	Up
Cell Serial	DRC2-03788
Lid Type	High Temperature
Cooler	LN Pump
Leave Cooler on at End of Sequence	Off
Gas 2	Air
Gas Selected	Channel 1: Nitrogen
Flow Rate	50 mL/min
Secondary Purge	On
Licensed Heat Flow	Heat Flow T4P
Modulation Licensed	Yes
[Versions]
Common IDD Version	1
Cortex Version	VER 2.11.0.729
Driver	5.0.0.6
GDM Version	1.0.3.3
TouchscreenVersion	1.0.3.1841
FEP Version	1.2.1.21
FEP Bootloader	2.0.0.5
AutoSampler Version	2.1.2.1
Auto Sampler Bootloader	2.0.0.5
FCM Version	1.1.0.3
FCM Bootloader	2.0.0.5
LN Pump Version	10.17.0.0
LN Pump Bootloader	2.0.0.5
[Experiment Logs]
Experiment Log Entry # 1	Ramp Segment 10 C/min to 150 Started
Experiment Log Entry # 3	Air Cool is off.
Experiment Log Entry # 5	Isothermal Segment 3 min started
Experiment Log Entry # 7	Ramp Segment 10 C/min to -100 Started
Experiment Log Entry # 9	Isothermal Segment 3 min started
Experiment Log Entry # 11	Ramp Segment 10 C/min to 150 Started
Experiment Log Entry # 14	LN2P is filling
Experiment Log Entry # 16	LN2P stopped filling
Experiment Log Entry # 17	Isothermal Segment 3 min started
Experiment Log Entry # 19	Ramp Segment 10 C/min to -100 Started
Experiment Log Entry # 21	Isothermal Segment 3 min started
Experiment Log Entry # 23	Ramp Segment 10 C/min to 150 Started
Experiment Log Entry # 25	Isothermal Segment 3 min started
Experiment Log Entry # 27	Ramp Segment 10 C/min to -100 Started
Experiment Log Entry # 29	Isothermal Segment 3 min started
Experiment Log Entry # 31	Ramp Segment 10 C/min to 150 Started
Experiment Log Entry # 33	Isothermal Segment 3 min started
Experiment Log Entry # 35	Ramp Segment 10 C/min to 40 Started
[Method Log]
Method Log Entry # 1	(Ramp 2072881) Ramp 10 °C/minute to 150 °C
Method Log Entry # 2	Isothermal 3 minutes
Method Log Entry # 3	(Ramp 2072883) Ramp 10 °C/minute to -100 °C
Method Log Entry # 4	Isothermal 3 minutes
Method Log Entry # 5	(Ramp 2072885) Ramp 10 °C/minute to 150 °C
Method Log Entry # 6	Isothermal 3 minutes
Method Log Entry # 7	(Ramp 2072887) Ramp 10 °C/minute to -100 °C
Method Log Entry # 8	Isothermal 3 minutes
Method Log Entry # 9	(Ramp 2072889) Ramp 10 °C/minute to 150 °C
Method Log Entry # 10	Isothermal 3 minutes
Method Log Entry # 11	(Ramp 2072891) Ramp 10 °C/minute to -100 °C
Method Log Entry # 12	Isothermal 3 minutes
Method Log Entry # 13	(Ramp 2072893) Ramp 10 °C/minute to 150 °C
Method Log Entry # 14	Isothermal 3 minutes
Method Log Entry # 15	(Ramp 2072895) Ramp 10 °C/minute to 40 °C
Cell Serial	DRC2-03788
[T1 Calibration]
Date Applied	04/03/2021 14:58:04
Description
Gas Type	Nitrogen
Pan Type	None
Slope	-0.001800291
Offset	-0.1301359
Initial Temperature	-100.6228
GUID	a1d5a6be-decd-4ae4-b22f-d560f3a78a92
[TZero Calibration]
Date Applied	21/08/2024 09:53:38
Description	From -180.022 °C to 395.167 °C at 20.000°C/min
Gas Type	Nitrogen
Pan Type	None
Source Files 1	C:\ProgramData\TA Instruments\TRIOS\Data\TAService\PMV 20Aug2024\Tzero Cal.tri
Source Files 2	C:\ProgramData\TA Instruments\TRIOS\Data\TAService\PMV 20Aug2024\Tzero Cal sapphire.tri
Delta T Offset	1.787969
Delta T Slope	-0.003527276
Delta T0 Offset	0.06831977
Delta T0 Slope	0.02007191
[Temperature Calibration]
Date Applied	21/08/2024 11:06:35
Description	From 106.660 °C to 186.660 °C at 10.000°C/min
Gas Type	Nitrogen
Pan Type	Tzero Aluminum
Source Files 1	C:\ProgramData\TA Instruments\TRIOS\Data\TAService\PMV 20Aug2024\TA Indium cal.tri
Measured 1	157.9141
Known 1	156.66
[Cell Constant Calibration]
Date Applied	21/08/2024 11:06:35
Description	From 106.660 °C to 186.660 °C at 10.000°C/min
Gas Type	Nitrogen
Pan Type	Tzero Aluminum
Source Files 1	C:\ProgramData\TA Instruments\TRIOS\Data\TAService\PMV 20Aug2024\TA Indium cal.tri
T4P KCell	1.038055
Onset Slope	-66.72884 mW/°C
[Direct Cp Calibration]
Date Applied	19/11/2024 16:37:27
Description	From -89.996 °C to 396.697 °C at 20.000°C/min
Gas Type	Nitrogen
Pan Type	Tzero Aluminum
Source Files 1	C:\ProgramData\TA Instruments\TRIOS\Data\Sapphire Direct Heat Capacity(8).tri
GUID	544f8371-fe9b-4f4f-81ca-7980c172113e
Temperature	-89.99625 °C
Cp	1.464367
Temperature	-89.02287 °C
Cp	1.460558
Temperature	-88.04948 °C
Cp	1.456263
Temperature	-87.0761 °C
Cp	1.451626
Temperature	-86.10271 °C
Cp	1.446737
Temperature	-85.12933 °C
Cp	1.441723
Temperature	-84.15594 °C
Cp	1.436654
Temperature	-83.18256 °C
Cp	1.431684
Temperature	-82.20917 °C
Cp	1.426935
Temperature	-81.23578 °C
Cp	1.422396
Temperature	-80.2624 °C
Cp	1.418192
Temperature	-79.28901 °C
Cp	1.414363
Temperature	-78.31562 °C
Cp	1.410925
Temperature	-77.34224 °C
Cp	1.407865
Temperature	-76.36885 °C
Cp	1.405143
Temperature	-75.39546 °C
Cp	1.402789
Temperature	-74.42208 °C
Cp	1.400703
Temperature	-73.44869 °C
Cp	1.398837
Temperature	-72.4753 °C
Cp	1.397142
Temperature	-71.50192 °C
Cp	1.395565
Temperature	-70.52853 °C
Cp	1.394053
Temperature	-69.55515 °C
Cp	1.392558
Temperature	-68.58176 °C
Cp	1.391036
Temperature	-67.60838 °C
Cp	1.389483
Temperature	-66.63499 °C
Cp	1.387847
Temperature	-65.66161 °C
Cp	1.38616
Temperature	-64.68822 °C
Cp	1.384397
Temperature	-63.71483 °C
Cp	1.382535
Temperature	-62.74145 °C
Cp	1.380598
Temperature	-61.76806 °C
Cp	1.37865
Temperature	-60.79467 °C
Cp	1.376673
Temperature	-59.82129 °C
Cp	1.374677
Temperature	-58.8479 °C
Cp	1.372642
Temperature	-57.87452 °C
Cp	1.370686
Temperature	-56.90113 °C
Cp	1.368741
Temperature	-55.92775 °C
Cp	1.366786
Temperature	-54.95436 °C
Cp	1.364863
Temperature	-53.98097 °C
Cp	1.362959
Temperature	-53.00759 °C
Cp	1.361116
Temperature	-52.0342 °C
Cp	1.359247
Temperature	-51.06082 °C
Cp	1.357393
Temperature	-50.08743 °C
Cp	1.355593
Temperature	-49.11404 °C
Cp	1.353796
Temperature	-48.14066 °C
Cp	1.352008
Temperature	-47.16727 °C
Cp	1.350215
Temperature	-46.19389 °C
Cp	1.348396
Temperature	-45.2205 °C
Cp	1.346593
Temperature	-44.24712 °C
Cp	1.344755
Temperature	-43.27373 °C
Cp	1.342891
Temperature	-42.30034 °C
Cp	1.341008
Temperature	-41.32696 °C
Cp	1.339126
Temperature	-40.35357 °C
Cp	1.337236
Temperature	-39.38018 °C
Cp	1.335367
Temperature	-38.4068 °C
Cp	1.333522
Temperature	-37.43341 °C
Cp	1.331708
Temperature	-36.46003 °C
Cp	1.32991
Temperature	-35.48664 °C
Cp	1.328145
Temperature	-34.51326 °C
Cp	1.326414
Temperature	-33.53987 °C
Cp	1.32471
Temperature	-32.56648 °C
Cp	1.323012
Temperature	-31.5931 °C
Cp	1.321323
Temperature	-30.61971 °C
Cp	1.319657
Temperature	-29.64633 °C
Cp	1.317968
Temperature	-28.67294 °C
Cp	1.316286
Temperature	-27.69955 °C
Cp	1.314585
Temperature	-26.72617 °C
Cp	1.312857
Temperature	-25.75278 °C
Cp	1.31111
Temperature	-24.7794 °C
Cp	1.309333
Temperature	-23.80601 °C
Cp	1.307544
Temperature	-22.83262 °C
Cp	1.30575
Temperature	-21.85924 °C
Cp	1.303941
Temperature	-20.88585 °C
Cp	1.302132
Temperature	-19.91247 °C
Cp	1.300313
Temperature	-18.93908 °C
Cp	1.298512
Temperature	-17.96569 °C
Cp	1.296728
Temperature	-16.99231 °C
Cp	1.294939
Temperature	-16.01892 °C
Cp	1.293198
Temperature	-15.04554 °C
Cp	1.291453
Temperature	-14.07215 °C
Cp	1.289723
Temperature	-13.09876 °C
Cp	1.288007
Temperature	-12.12538 °C
Cp	1.286283
Temperature	-11.15199 °C
Cp	1.284578
Temperature	-10.17861 °C
Cp	1.282885
Temperature	-9.205221 °C
Cp	1.281173
Temperature	-8.231835 °C
Cp	1.279472
Temperature	-7.258449 °C
Cp	1.277766
Temperature	-6.285063 °C
Cp	1.276053
Temperature	-5.311677 °C
Cp	1.274341
Temperature	-4.338291 °C
Cp	1.272592
Temperature	-3.364905 °C
Cp	1.270844
Temperature	-2.391519 °C
Cp	1.269062
Temperature	-1.418133 °C
Cp	1.267264
Temperature	-0.4447474 °C
Cp	1.265435
Temperature	0.5286385 °C
Cp	1.263575
Temperature	1.502024 °C
Cp	1.261727
Temperature	2.47541 °C
Cp	1.259854
Temperature	3.448796 °C
Cp	1.257978
Temperature	4.422182 °C
Cp	1.256109
Temperature	5.395568 °C
Cp	1.254244
Temperature	6.368954 °C
Cp	1.252392
Temperature	7.34234 °C
Cp	1.250552
Temperature	8.315726 °C
Cp	1.248704
Temperature	9.289112 °C
Cp	1.246884
Temperature	10.2625 °C
Cp	1.245078
Temperature	11.23588 °C
Cp	1.243287
Temperature	12.20927 °C
Cp	1.241522
Temperature	13.18266 °C
Cp	1.239778
Temperature	14.15604 °C
Cp	1.238068
Temperature	15.12943 °C
Cp	1.236393
Temperature	16.10281 °C
Cp	1.234762
Temperature	17.0762 °C
Cp	1.233176
Temperature	18.04959 °C
Cp	1.231629
Temperature	19.02297 °C
Cp	1.230129
Temperature	19.99636 °C
Cp	1.228694
Temperature	20.96974 °C
Cp	1.22731
Temperature	21.94313 °C
Cp	1.225968
Temperature	22.91652 °C
Cp	1.224676
Temperature	23.8899 °C
Cp	1.223431
Temperature	24.86329 °C
Cp	1.222217
Temperature	25.83667 °C
Cp	1.221065
Temperature	26.81006 °C
Cp	1.219919
Temperature	27.78345 °C
Cp	1.218811
Temperature	28.75683 °C
Cp	1.21773
Temperature	29.73022 °C
Cp	1.216663
Temperature	30.7036 °C
Cp	1.2156
Temperature	31.67699 °C
Cp	1.214515
Temperature	32.65038 °C
Cp	1.213439
Temperature	33.62376 °C
Cp	1.21234
Temperature	34.59715 °C
Cp	1.211209
Temperature	35.57053 °C
Cp	1.210051
Temperature	36.54392 °C
Cp	1.208868
Temperature	37.5173 °C
Cp	1.207666
Temperature	38.49069 °C
Cp	1.206439
Temperature	39.46408 °C
Cp	1.205199
Temperature	40.43746 °C
Cp	1.203959
Temperature	41.41085 °C
Cp	1.202712
Temperature	42.38424 °C
Cp	1.20147
Temperature	43.35762 °C
Cp	1.200231
Temperature	44.33101 °C
Cp	1.199
Temperature	45.30439 °C
Cp	1.197777
Temperature	46.27778 °C
Cp	1.19657
Temperature	47.25116 °C
Cp	1.195367
Temperature	48.22455 °C
Cp	1.194179
Temperature	49.19794 °C
Cp	1.19301
Temperature	50.17132 °C
Cp	1.191849
Temperature	51.14471 °C
Cp	1.190694
Temperature	52.11809 °C
Cp	1.189555
Temperature	53.09148 °C
Cp	1.18843
Temperature	54.06487 °C
Cp	1.187311
Temperature	55.03825 °C
Cp	1.186195
Temperature	56.01164 °C
Cp	1.185095
Temperature	56.98502 °C
Cp	1.183997
Temperature	57.95841 °C
Cp	1.182894
Temperature	58.93179 °C
Cp	1.181793
Temperature	59.90518 °C
Cp	1.180693
Temperature	60.87857 °C
Cp	1.179595
Temperature	61.85195 °C
Cp	1.178501
Temperature	62.82534 °C
Cp	1.177406
Temperature	63.79873 °C
Cp	1.176313
Temperature	64.77211 °C
Cp	1.175239
Temperature	65.7455 °C
Cp	1.17417
Temperature	66.71888 °C
Cp	1.173105
Temperature	67.69227 °C
Cp	1.172037
Temperature	68.66566 °C
Cp	1.170989
Temperature	69.63904 °C
Cp	1.169948
Temperature	70.61243 °C
Cp	1.168905
Temperature	71.58582 °C
Cp	1.167872
Temperature	72.5592 °C
Cp	1.166849
Temperature	73.53259 °C
Cp	1.165851
Temperature	74.50597 °C
Cp	1.164848
Temperature	75.47935 °C
Cp	1.163876
Temperature	76.45274 °C
Cp	1.162926
Temperature	77.42612 °C
Cp	1.162008
Temperature	78.39951 °C
Cp	1.161113
Temperature	79.3729 °C
Cp	1.160219
Temperature	80.34628 °C
Cp	1.159377
Temperature	81.31967 °C
Cp	1.158546
Temperature	82.29306 °C
Cp	1.157726
Temperature	83.26644 °C
Cp	1.15692
Temperature	84.23983 °C
Cp	1.156126
Temperature	85.21322 °C
Cp	1.155375
Temperature	86.1866 °C
Cp	1.154604
Temperature	87.15999 °C
Cp	1.153869
Temperature	88.13337 °C
Cp	1.153158
Temperature	89.10676 °C
Cp	1.152474
Temperature	90.08015 °C
Cp	1.15181
Temperature	91.05353 °C
Cp	1.151134
Temperature	92.02692 °C
Cp	1.150513
Temperature	93.00031 °C
Cp	1.149892
Temperature	93.97369 °C
Cp	1.149266
Temperature	94.94707 °C
Cp	1.148642
Temperature	95.92046 °C
Cp	1.148019
Temperature	96.89384 °C
Cp	1.147402
Temperature	97.86723 °C
Cp	1.146799
Temperature	98.84062 °C
Cp	1.146191
Temperature	99.814 °C
Cp	1.145602
Temperature	100.7874 °C
Cp	1.14503
Temperature	101.7608 °C
Cp	1.144469
Temperature	102.7342 °C
Cp	1.143921
Temperature	103.7076 °C
Cp	1.143383
Temperature	104.6809 °C
Cp	1.142861
Temperature	105.6543 °C
Cp	1.142345
Temperature	106.6277 °C
Cp	1.141835
Temperature	107.6011 °C
Cp	1.141335
Temperature	108.5745 °C
Cp	1.140846
Temperature	109.5479 °C
Cp	1.140365
Temperature	110.5212 °C
Cp	1.139891
Temperature	111.4946 °C
Cp	1.139429
Temperature	112.468 °C
Cp	1.138976
Temperature	113.4414 °C
Cp	1.13853
Temperature	114.4148 °C
Cp	1.138092
Temperature	115.3882 °C
Cp	1.137654
Temperature	116.3616 °C
Cp	1.137223
Temperature	117.335 °C
Cp	1.136785
Temperature	118.3083 °C
Cp	1.136338
Temperature	119.2817 °C
Cp	1.13588
Temperature	120.2551 °C
Cp	1.13541
Temperature	121.2285 °C
Cp	1.134927
Temperature	122.2019 °C
Cp	1.134417
Temperature	123.1753 °C
Cp	1.133892
Temperature	124.1487 °C
Cp	1.133347
Temperature	125.122 °C
Cp	1.132786
Temperature	126.0954 °C
Cp	1.132206
Temperature	127.0688 °C
Cp	1.131606
Temperature	128.0422 °C
Cp	1.130999
Temperature	129.0156 °C
Cp	1.130384
Temperature	129.989 °C
Cp	1.129765
Temperature	130.9624 °C
Cp	1.129147
Temperature	131.9357 °C
Cp	1.12854
Temperature	132.9091 °C
Cp	1.127949
Temperature	133.8825 °C
Cp	1.127383
Temperature	134.8559 °C
Cp	1.126841
Temperature	135.8293 °C
Cp	1.126334
Temperature	136.8027 °C
Cp	1.125871
Temperature	137.7761 °C
Cp	1.125443
Temperature	138.7494 °C
Cp	1.125058
Temperature	139.7228 °C
Cp	1.124701
Temperature	140.6962 °C
Cp	1.124397
Temperature	141.6696 °C
Cp	1.124114
Temperature	142.643 °C
Cp	1.123854
Temperature	143.6164 °C
Cp	1.123612
Temperature	144.5898 °C
Cp	1.123385
Temperature	145.5631 °C
Cp	1.123182
Temperature	146.5365 °C
Cp	1.12296
Temperature	147.5099 °C
Cp	1.12275
Temperature	148.4833 °C
Cp	1.122543
Temperature	149.4567 °C
Cp	1.122327
Temperature	150.4301 °C
Cp	1.122099
Temperature	151.4035 °C
Cp	1.121837
Temperature	152.3768 °C
Cp	1.121582
Temperature	153.3502 °C
Cp	1.121289
Temperature	154.3236 °C
Cp	1.120967
Temperature	155.297 °C
Cp	1.120616
Temperature	156.2704 °C
Cp	1.120238
Temperature	157.2438 °C
Cp	1.119862
Temperature	158.2172 °C
Cp	1.119444
Temperature	159.1906 °C
Cp	1.119028
Temperature	160.1639 °C
Cp	1.118613
Temperature	161.1373 °C
Cp	1.118202
Temperature	162.1107 °C
Cp	1.117795
Temperature	163.0841 °C
Cp	1.117374
Temperature	164.0575 °C
Cp	1.116987
Temperature	165.0309 °C
Cp	1.116595
Temperature	166.0042 °C
Cp	1.116198
Temperature	166.9776 °C
Cp	1.1158
Temperature	167.951 °C
Cp	1.115402
Temperature	168.9244 °C
Cp	1.115006
Temperature	169.8978 °C
Cp	1.11462
Temperature	170.8712 °C
Cp	1.114223
Temperature	171.8446 °C
Cp	1.113836
Temperature	172.8179 °C
Cp	1.113458
Temperature	173.7913 °C
Cp	1.113085
Temperature	174.7647 °C
Cp	1.112712
Temperature	175.7381 °C
Cp	1.112323
Temperature	176.7115 °C
Cp	1.111957
Temperature	177.6849 °C
Cp	1.111578
Temperature	178.6583 °C
Cp	1.111185
Temperature	179.6317 °C
Cp	1.110789
Temperature	180.605 °C
Cp	1.110391
Temperature	181.5784 °C
Cp	1.110016
Temperature	182.5518 °C
Cp	1.109611
Temperature	183.5252 °C
Cp	1.109232
Temperature	184.4986 °C
Cp	1.108873
Temperature	185.472 °C
Cp	1.108531
Temperature	186.4454 °C
Cp	1.108199
Temperature	187.4187 °C
Cp	1.107851
Temperature	188.3921 °C
Cp	1.107551
Temperature	189.3655 °C
Cp	1.107238
Temperature	190.3389 °C
Cp	1.106917
Temperature	191.3123 °C
Cp	1.106589
Temperature	192.2857 °C
Cp	1.106259
Temperature	193.259 °C
Cp	1.105958
Temperature	194.2324 °C
Cp	1.105619
Temperature	195.2058 °C
Cp	1.105301
Temperature	196.1792 °C
Cp	1.105002
Temperature	197.1526 °C
Cp	1.104718
Temperature	198.126 °C
Cp	1.104445
Temperature	199.0994 °C
Cp	1.104161
Temperature	200.0728 °C
Cp	1.103914
Temperature	201.0461 °C
Cp	1.103657
Temperature	202.0195 °C
Cp	1.103395
Temperature	202.9929 °C
Cp	1.103125
Temperature	203.9663 °C
Cp	1.102847
Temperature	204.9397 °C
Cp	1.102563
Temperature	205.9131 °C
Cp	1.102283
Temperature	206.8865 °C
Cp	1.101985
Temperature	207.8598 °C
Cp	1.10169
Temperature	208.8332 °C
Cp	1.101394
Temperature	209.8066 °C
Cp	1.101099
Temperature	210.78 °C
Cp	1.1008
Temperature	211.7534 °C
Cp	1.10049
Temperature	212.7268 °C
Cp	1.100193
Temperature	213.7002 °C
Cp	1.099886
Temperature	214.6735 °C
Cp	1.099577
Temperature	215.6469 °C
Cp	1.099268
Temperature	216.6203 °C
Cp	1.098965
Temperature	217.5937 °C
Cp	1.098685
Temperature	218.5671 °C
Cp	1.098396
Temperature	219.5405 °C
Cp	1.098134
Temperature	220.5139 °C
Cp	1.097895
Temperature	221.4872 °C
Cp	1.09768
Temperature	222.4606 °C
Cp	1.097485
Temperature	223.434 °C
Cp	1.097292
Temperature	224.4074 °C
Cp	1.09714
Temperature	225.3808 °C
Cp	1.096991
Temperature	226.3542 °C
Cp	1.096844
Temperature	227.3276 °C
Cp	1.096699
Temperature	228.3009 °C
Cp	1.096559
Temperature	229.2743 °C
Cp	1.096442
Temperature	230.2477 °C
Cp	1.096296
Temperature	231.2211 °C
Cp	1.096164
Temperature	232.1945 °C
Cp	1.09604
Temperature	233.1679 °C
Cp	1.095924
Temperature	234.1413 °C
Cp	1.095807
Temperature	235.1147 °C
Cp	1.095665
Temperature	236.088 °C
Cp	1.095557
Temperature	237.0614 °C
Cp	1.095433
Temperature	238.0348 °C
Cp	1.095296
Temperature	239.0082 °C
Cp	1.095147
Temperature	239.9816 °C
Cp	1.094995
Temperature	240.955 °C
Cp	1.094843
Temperature	241.9283 °C
Cp	1.094705
Temperature	242.9017 °C
Cp	1.094562
Temperature	243.8751 °C
Cp	1.094442
Temperature	244.8485 °C
Cp	1.094344
Temperature	245.8219 °C
Cp	1.094266
Temperature	246.7953 °C
Cp	1.094209
Temperature	247.7687 °C
Cp	1.094161
Temperature	248.7421 °C
Cp	1.094144
Temperature	249.7154 °C
Cp	1.094133
Temperature	250.6888 °C
Cp	1.094127
Temperature	251.6622 °C
Cp	1.094126
Temperature	252.6356 °C
Cp	1.094127
Temperature	253.609 °C
Cp	1.094138
Temperature	254.5824 °C
Cp	1.09413
Temperature	255.5558 °C
Cp	1.094123
Temperature	256.5291 °C
Cp	1.094111
Temperature	257.5025 °C
Cp	1.094087
Temperature	258.4759 °C
Cp	1.094046
Temperature	259.4493 °C
Cp	1.093978
Temperature	260.4227 °C
Cp	1.093895
Temperature	261.3961 °C
Cp	1.093783
Temperature	262.3694 °C
Cp	1.093645
Temperature	263.3428 °C
Cp	1.093483
Temperature	264.3162 °C
Cp	1.093302
Temperature	265.2896 °C
Cp	1.093109
Temperature	266.263 °C
Cp	1.092906
Temperature	267.2364 °C
Cp	1.092704
Temperature	268.2098 °C
Cp	1.092511
Temperature	269.1832 °C
Cp	1.092331
Temperature	270.1566 °C
Cp	1.092174
Temperature	271.1299 °C
Cp	1.092046
Temperature	272.1033 °C
Cp	1.091947
Temperature	273.0767 °C
Cp	1.091882
Temperature	274.0501 °C
Cp	1.091853
Temperature	275.0235 °C
Cp	1.091859
Temperature	275.9969 °C
Cp	1.091895
Temperature	276.9702 °C
Cp	1.091957
Temperature	277.9436 °C
Cp	1.092036
Temperature	278.917 °C
Cp	1.092132
Temperature	279.8904 °C
Cp	1.09223
Temperature	280.8638 °C
Cp	1.092323
Temperature	281.8372 °C
Cp	1.092405
Temperature	282.8105 °C
Cp	1.092468
Temperature	283.7839 °C
Cp	1.092513
Temperature	284.7573 °C
Cp	1.092525
Temperature	285.7307 °C
Cp	1.092512
Temperature	286.7041 °C
Cp	1.092472
Temperature	287.6775 °C
Cp	1.092405
Temperature	288.6509 °C
Cp	1.092313
Temperature	289.6243 °C
Cp	1.092197
Temperature	290.5977 °C
Cp	1.09207
Temperature	291.571 °C
Cp	1.091931
Temperature	292.5444 °C
Cp	1.091785
Temperature	293.5178 °C
Cp	1.091641
Temperature	294.4912 °C
Cp	1.091506
Temperature	295.4646 °C
Cp	1.091387
Temperature	296.438 °C
Cp	1.091282
Temperature	297.4113 °C
Cp	1.091201
Temperature	298.3847 °C
Cp	1.091145
Temperature	299.3581 °C
Cp	1.091112
Temperature	300.3315 °C
Cp	1.091102
Temperature	301.3049 °C
Cp	1.091107
Temperature	302.2783 °C
Cp	1.091137
Temperature	303.2517 °C
Cp	1.091177
Temperature	304.2251 °C
Cp	1.091226
Temperature	305.1984 °C
Cp	1.09128
Temperature	306.1718 °C
Cp	1.091336
Temperature	307.1452 °C
Cp	1.091403
Temperature	308.1186 °C
Cp	1.091453
Temperature	309.092 °C
Cp	1.091506
Temperature	310.0654 °C
Cp	1.091561
Temperature	311.0388 °C
Cp	1.091617
Temperature	312.0121 °C
Cp	1.09167
Temperature	312.9855 °C
Cp	1.091716
Temperature	313.9589 °C
Cp	1.091762
Temperature	314.9323 °C
Cp	1.091805
Temperature	315.9057 °C
Cp	1.091838
Temperature	316.8791 °C
Cp	1.09186
Temperature	317.8524 °C
Cp	1.091871
Temperature	318.8258 °C
Cp	1.091872
Temperature	319.7992 °C
Cp	1.091867
Temperature	320.7726 °C
Cp	1.091838
Temperature	321.746 °C
Cp	1.0918
Temperature	322.7194 °C
Cp	1.091752
Temperature	323.6928 °C
Cp	1.091689
Temperature	324.6662 °C
Cp	1.091611
Temperature	325.6396 °C
Cp	1.091508
Temperature	326.6129 °C
Cp	1.091406
Temperature	327.5863 °C
Cp	1.091285
Temperature	328.5597 °C
Cp	1.09115
Temperature	329.5331 °C
Cp	1.091009
Temperature	330.5065 °C
Cp	1.09087
Temperature	331.4799 °C
Cp	1.090747
Temperature	332.4532 °C
Cp	1.090628
Temperature	333.4266 °C
Cp	1.090536
Temperature	334.4 °C
Cp	1.090472
Temperature	335.3734 °C
Cp	1.090437
Temperature	336.3468 °C
Cp	1.090431
Temperature	337.3202 °C
Cp	1.090455
Temperature	338.2935 °C
Cp	1.090503
Temperature	339.2669 °C
Cp	1.090573
Temperature	340.2403 °C
Cp	1.090658
Temperature	341.2137 °C
Cp	1.090753
Temperature	342.1871 °C
Cp	1.090853
Temperature	343.1605 °C
Cp	1.090952
Temperature	344.1339 °C
Cp	1.09105
Temperature	345.1073 °C
Cp	1.091141
Temperature	346.0807 °C
Cp	1.091225
Temperature	347.054 °C
Cp	1.091303
Temperature	348.0274 °C
Cp	1.091379
Temperature	349.0008 °C
Cp	1.091453
Temperature	349.9742 °C
Cp	1.091537
Temperature	350.9476 °C
Cp	1.091633
Temperature	351.921 °C
Cp	1.091743
Temperature	352.8943 °C
Cp	1.091874
Temperature	353.8677 °C
Cp	1.092028
Temperature	354.8411 °C
Cp	1.092206
Temperature	355.8145 °C
Cp	1.092411
Temperature	356.7879 °C
Cp	1.092628
Temperature	357.7613 °C
Cp	1.092862
Temperature	358.7346 °C
Cp	1.093102
Temperature	359.708 °C
Cp	1.093338
Temperature	360.6814 °C
Cp	1.093559
Temperature	361.6548 °C
Cp	1.093752
Temperature	362.6282 °C
Cp	1.093915
Temperature	363.6016 °C
Cp	1.094036
Temperature	364.575 °C
Cp	1.094117
Temperature	365.5484 °C
Cp	1.094159
Temperature	366.5218 °C
Cp	1.094172
Temperature	367.4951 °C
Cp	1.094165
Temperature	368.4685 °C
Cp	1.094163
Temperature	369.4419 °C
Cp	1.094182
Temperature	370.4153 °C
Cp	1.094244
Temperature	371.3887 °C
Cp	1.094375
Temperature	372.3621 °C
Cp	1.094598
Temperature	373.3354 °C
Cp	1.094937
Temperature	374.3088 °C
Cp	1.095389
Temperature	375.2822 °C
Cp	1.095973
Temperature	376.2556 °C
Cp	1.096685
Temperature	377.229 °C
Cp	1.097506
Temperature	378.2024 °C
Cp	1.098406
Temperature	379.1758 °C
Cp	1.099338
Temperature	380.1492 °C
Cp	1.10027
Temperature	381.1225 °C
Cp	1.10112
Temperature	382.0959 °C
Cp	1.101818
Temperature	383.0693 °C
Cp	1.10229
Temperature	384.0427 °C
Cp	1.102459
Temperature	385.0161 °C
Cp	1.102253
Temperature	385.9895 °C
Cp	1.101596
Temperature	386.9629 °C
Cp	1.100438
Temperature	387.9362 °C
Cp	1.098736
Temperature	388.9096 °C
Cp	1.096461
Temperature	389.883 °C
Cp	1.093614
Temperature	390.8564 °C
Cp	1.090208
Temperature	391.8298 °C
Cp	1.086278
Temperature	392.8032 °C
Cp	1.081887
Temperature	393.7766 °C
Cp	1.077096
Temperature	394.7499 °C
Cp	1.072007
Temperature	395.7233 °C
Cp	1.066707
[Rev Cp Calibration]
Date Applied	24/10/2024 12:37:31
Description	From -89.998 °C to 390.542 °C at 2.000°C/min
Gas Type	Nitrogen
Pan Type	Tzero Aluminum
Source Files 1	C:\ProgramData\TA Instruments\TRIOS\Data\Reverse Heat Capacity Calibration(6).tri
GUID	ba867d72-cfbb-486e-971e-e86aa544cc02
Temperature	-89.99799 °C
Cp	1.070076
Temperature	-89.03691 °C
Cp	1.072008
Temperature	-88.07584 °C
Cp	1.073556
Temperature	-87.11475 °C
Cp	1.074743
Temperature	-86.15367 °C
Cp	1.075597
Temperature	-85.1926 °C
Cp	1.076163
Temperature	-84.23151 °C
Cp	1.076477
Temperature	-83.27043 °C
Cp	1.076579
Temperature	-82.30936 °C
Cp	1.076527
Temperature	-81.34827 °C
Cp	1.076322
Temperature	-80.38719 °C
Cp	1.076039
Temperature	-79.42612 °C
Cp	1.07571
Temperature	-78.46503 °C
Cp	1.075361
Temperature	-77.50395 °C
Cp	1.075011
Temperature	-76.54288 °C
Cp	1.074656
Temperature	-75.58179 °C
Cp	1.074359
Temperature	-74.62071 °C
Cp	1.074086
Temperature	-73.65964 °C
Cp	1.073842
Temperature	-72.69855 °C
Cp	1.073627
Temperature	-71.73747 °C
Cp	1.073442
Temperature	-70.7764 °C
Cp	1.07329
Temperature	-69.81532 °C
Cp	1.073148
Temperature	-68.85423 °C
Cp	1.073021
Temperature	-67.89315 °C
Cp	1.072902
Temperature	-66.93208 °C
Cp	1.072782
Temperature	-65.97099 °C
Cp	1.072656
Temperature	-65.00991 °C
Cp	1.072518
Temperature	-64.04884 °C
Cp	1.072374
Temperature	-63.08775 °C
Cp	1.072201
Temperature	-62.12667 °C
Cp	1.072019
Temperature	-61.1656 °C
Cp	1.071827
Temperature	-60.20451 °C
Cp	1.071624
Temperature	-59.24343 °C
Cp	1.071411
Temperature	-58.28236 °C
Cp	1.071167
Temperature	-57.32127 °C
Cp	1.070956
Temperature	-56.3602 °C
Cp	1.070724
Temperature	-55.39911 °C
Cp	1.070483
Temperature	-54.43803 °C
Cp	1.070242
Temperature	-53.47696 °C
Cp	1.070009
Temperature	-52.51587 °C
Cp	1.069825
Temperature	-51.55479 °C
Cp	1.069601
Temperature	-50.59372 °C
Cp	1.069418
Temperature	-49.63263 °C
Cp	1.069267
Temperature	-48.67155 °C
Cp	1.069138
Temperature	-47.71048 °C
Cp	1.069021
Temperature	-46.74939 °C
Cp	1.068875
Temperature	-45.78831 °C
Cp	1.068771
Temperature	-44.82724 °C
Cp	1.068634
Temperature	-43.86615 °C
Cp	1.068462
Temperature	-42.90508 °C
Cp	1.068255
Temperature	-41.944 °C
Cp	1.068012
Temperature	-40.98291 °C
Cp	1.067742
Temperature	-40.02184 °C
Cp	1.067427
Temperature	-39.06076 °C
Cp	1.067088
Temperature	-38.09967 °C
Cp	1.066727
Temperature	-37.1386 °C
Cp	1.066349
Temperature	-36.17752 °C
Cp	1.065958
Temperature	-35.21643 °C
Cp	1.065559
Temperature	-34.25536 °C
Cp	1.065162
Temperature	-33.29427 °C
Cp	1.06476
Temperature	-32.33319 °C
Cp	1.064368
Temperature	-31.37212 °C
Cp	1.06399
Temperature	-30.41104 °C
Cp	1.063628
Temperature	-29.44995 °C
Cp	1.063283
Temperature	-28.48887 °C
Cp	1.06295
Temperature	-27.5278 °C
Cp	1.062645
Temperature	-26.56672 °C
Cp	1.062355
Temperature	-25.60563 °C
Cp	1.06208
Temperature	-24.64456 °C
Cp	1.061819
Temperature	-23.68348 °C
Cp	1.061573
Temperature	-22.72239 °C
Cp	1.061345
Temperature	-21.76132 °C
Cp	1.061123
Temperature	-20.80024 °C
Cp	1.060915
Temperature	-19.83916 °C
Cp	1.060719
Temperature	-18.87807 °C
Cp	1.060531
Temperature	-17.917 °C
Cp	1.06035
Temperature	-16.95592 °C
Cp	1.060161
Temperature	-15.99484 °C
Cp	1.059992
Temperature	-15.03376 °C
Cp	1.059817
Temperature	-14.07268 °C
Cp	1.059634
Temperature	-13.1116 °C
Cp	1.059445
Temperature	-12.15052 °C
Cp	1.059248
Temperature	-11.18944 °C
Cp	1.059043
Temperature	-10.22836 °C
Cp	1.058842
Temperature	-9.267276 °C
Cp	1.058615
Temperature	-8.306196 °C
Cp	1.058388
Temperature	-7.345116 °C
Cp	1.058155
Temperature	-6.384036 °C
Cp	1.057911
Temperature	-5.422956 °C
Cp	1.057652
Temperature	-4.461876 °C
Cp	1.057356
Temperature	-3.500796 °C
Cp	1.057063
Temperature	-2.539716 °C
Cp	1.056732
Temperature	-1.578636 °C
Cp	1.056364
Temperature	-0.6175562 °C
Cp	1.05596
Temperature	0.3435238 °C
Cp	1.055523
Temperature	1.304604 °C
Cp	1.055066
Temperature	2.265684 °C
Cp	1.054561
Temperature	3.226764 °C
Cp	1.054035
Temperature	4.187844 °C
Cp	1.053488
Temperature	5.148924 °C
Cp	1.052922
Temperature	6.110003 °C
Cp	1.052337
Temperature	7.071084 °C
Cp	1.051736
Temperature	8.032164 °C
Cp	1.051118
Temperature	8.993243 °C
Cp	1.050488
Temperature	9.954324 °C
Cp	1.049848
Temperature	10.9154 °C
Cp	1.049202
Temperature	11.87648 °C
Cp	1.048552
Temperature	12.83756 °C
Cp	1.047902
Temperature	13.79864 °C
Cp	1.047255
Temperature	14.75972 °C
Cp	1.046615
Temperature	15.7208 °C
Cp	1.045983
Temperature	16.68188 °C
Cp	1.045362
Temperature	17.64296 °C
Cp	1.044756
Temperature	18.60404 °C
Cp	1.044164
Temperature	19.56512 °C
Cp	1.04358
Temperature	20.5262 °C
Cp	1.043027
Temperature	21.48728 °C
Cp	1.042485
Temperature	22.44836 °C
Cp	1.041958
Temperature	23.40944 °C
Cp	1.041446
Temperature	24.37052 °C
Cp	1.040952
Temperature	25.3316 °C
Cp	1.040493
Temperature	26.29268 °C
Cp	1.040022
Temperature	27.25376 °C
Cp	1.039578
Temperature	28.21484 °C
Cp	1.039158
Temperature	29.17592 °C
Cp	1.038758
Temperature	30.137 °C
Cp	1.038373
Temperature	31.09808 °C
Cp	1.037981
Temperature	32.05916 °C
Cp	1.03763
Temperature	33.02024 °C
Cp	1.037276
Temperature	33.98132 °C
Cp	1.03692
Temperature	34.9424 °C
Cp	1.036565
Temperature	35.90348 °C
Cp	1.036213
Temperature	36.86456 °C
Cp	1.035866
Temperature	37.82564 °C
Cp	1.035529
Temperature	38.78672 °C
Cp	1.035195
Temperature	39.7478 °C
Cp	1.034875
Temperature	40.70888 °C
Cp	1.034568
Temperature	41.66996 °C
Cp	1.034276
Temperature	42.63104 °C
Cp	1.033996
Temperature	43.59212 °C
Cp	1.033726
Temperature	44.5532 °C
Cp	1.033469
Temperature	45.51428 °C
Cp	1.033221
Temperature	46.47536 °C
Cp	1.03298
Temperature	47.43644 °C
Cp	1.032744
Temperature	48.39752 °C
Cp	1.032514
Temperature	49.3586 °C
Cp	1.032289
Temperature	50.31968 °C
Cp	1.032065
Temperature	51.28076 °C
Cp	1.031844
Temperature	52.24184 °C
Cp	1.031627
Temperature	53.20292 °C
Cp	1.031413
Temperature	54.164 °C
Cp	1.031203
Temperature	55.12508 °C
Cp	1.030989
Temperature	56.08616 °C
Cp	1.030791
Temperature	57.04724 °C
Cp	1.030595
Temperature	58.00832 °C
Cp	1.030403
Temperature	58.9694 °C
Cp	1.030217
Temperature	59.93048 °C
Cp	1.03004
Temperature	60.89156 °C
Cp	1.029871
Temperature	61.85264 °C
Cp	1.029718
Temperature	62.81372 °C
Cp	1.029567
Temperature	63.7748 °C
Cp	1.02943
Temperature	64.73589 °C
Cp	1.029304
Temperature	65.69696 °C
Cp	1.029185
Temperature	66.65804 °C
Cp	1.02907
Temperature	67.61913 °C
Cp	1.028946
Temperature	68.5802 °C
Cp	1.028831
Temperature	69.54128 °C
Cp	1.028703
Temperature	70.50237 °C
Cp	1.028561
Temperature	71.46344 °C
Cp	1.028404
Temperature	72.42452 °C
Cp	1.028234
Temperature	73.3856 °C
Cp	1.028063
Temperature	74.34668 °C
Cp	1.027861
Temperature	75.30776 °C
Cp	1.027657
Temperature	76.26884 °C
Cp	1.027451
Temperature	77.22992 °C
Cp	1.027243
Temperature	78.191 °C
Cp	1.027036
Temperature	79.15208 °C
Cp	1.026812
Temperature	80.11316 °C
Cp	1.026623
Temperature	81.07424 °C
Cp	1.026431
Temperature	82.03532 °C
Cp	1.026241
Temperature	82.9964 °C
Cp	1.02606
Temperature	83.95748 °C
Cp	1.025891
Temperature	84.91856 °C
Cp	1.025739
Temperature	85.87964 °C
Cp	1.025614
Temperature	86.84072 °C
Cp	1.025493
Temperature	87.8018 °C
Cp	1.0254
Temperature	88.76288 °C
Cp	1.025329
Temperature	89.72396 °C
Cp	1.025274
Temperature	90.68504 °C
Cp	1.025229
Temperature	91.64612 °C
Cp	1.025174
Temperature	92.6072 °C
Cp	1.025138
Temperature	93.56828 °C
Cp	1.025083
Temperature	94.52936 °C
Cp	1.025008
Temperature	95.49044 °C
Cp	1.024912
Temperature	96.45152 °C
Cp	1.024796
Temperature	97.4126 °C
Cp	1.024671
Temperature	98.37368 °C
Cp	1.024506
Temperature	99.33476 °C
Cp	1.02433
Temperature	100.2958 °C
Cp	1.024144
Temperature	101.2569 °C
Cp	1.023948
Temperature	102.218 °C
Cp	1.023743
Temperature	103.1791 °C
Cp	1.023522
Temperature	104.1402 °C
Cp	1.023309
Temperature	105.1012 °C
Cp	1.023089
Temperature	106.0623 °C
Cp	1.022866
Temperature	107.0234 °C
Cp	1.022644
Temperature	107.9845 °C
Cp	1.022427
Temperature	108.9456 °C
Cp	1.022218
Temperature	109.9066 °C
Cp	1.022022
Temperature	110.8677 °C
Cp	1.021836
Temperature	111.8288 °C
Cp	1.021666
Temperature	112.7899 °C
Cp	1.021512
Temperature	113.751 °C
Cp	1.021374
Temperature	114.712 °C
Cp	1.02125
Temperature	115.6731 °C
Cp	1.021137
Temperature	116.6342 °C
Cp	1.021041
Temperature	117.5953 °C
Cp	1.020953
Temperature	118.5564 °C
Cp	1.020872
Temperature	119.5174 °C
Cp	1.020796
Temperature	120.4785 °C
Cp	1.020725
Temperature	121.4396 °C
Cp	1.020659
Temperature	122.4007 °C
Cp	1.020587
Temperature	123.3618 °C
Cp	1.020515
Temperature	124.3228 °C
Cp	1.02044
Temperature	125.2839 °C
Cp	1.020359
Temperature	126.245 °C
Cp	1.02027
Temperature	127.2061 °C
Cp	1.020167
Temperature	128.1672 °C
Cp	1.020057
Temperature	129.1282 °C
Cp	1.019933
Temperature	130.0893 °C
Cp	1.019793
Temperature	131.0504 °C
Cp	1.019638
Temperature	132.0115 °C
Cp	1.019471
Temperature	132.9726 °C
Cp	1.019292
Temperature	133.9336 °C
Cp	1.019107
Temperature	134.8947 °C
Cp	1.018912
Temperature	135.8558 °C
Cp	1.018717
Temperature	136.8169 °C
Cp	1.018527
Temperature	137.778 °C
Cp	1.018344
Temperature	138.739 °C
Cp	1.018171
Temperature	139.7001 °C
Cp	1.018004
Temperature	140.6612 °C
Cp	1.01787
Temperature	141.6223 °C
Cp	1.01775
Temperature	142.5834 °C
Cp	1.017652
Temperature	143.5444 °C
Cp	1.017578
Temperature	144.5055 °C
Cp	1.017534
Temperature	145.4666 °C
Cp	1.017536
Temperature	146.4277 °C
Cp	1.017545
Temperature	147.3888 °C
Cp	1.017595
Temperature	148.3498 °C
Cp	1.017679
Temperature	149.3109 °C
Cp	1.01779
Temperature	150.272 °C
Cp	1.01792
Temperature	151.2331 °C
Cp	1.018043
Temperature	152.1942 °C
Cp	1.018199
Temperature	153.1552 °C
Cp	1.018339
Temperature	154.1163 °C
Cp	1.018458
Temperature	155.0774 °C
Cp	1.018552
Temperature	156.0385 °C
Cp	1.018618
Temperature	156.9996 °C
Cp	1.018662
Temperature	157.9606 °C
Cp	1.018664
Temperature	158.9217 °C
Cp	1.018632
Temperature	159.8828 °C
Cp	1.018575
Temperature	160.8439 °C
Cp	1.018492
Temperature	161.805 °C
Cp	1.018383
Temperature	162.766 °C
Cp	1.01825
Temperature	163.7271 °C
Cp	1.018087
Temperature	164.6882 °C
Cp	1.017917
Temperature	165.6493 °C
Cp	1.017726
Temperature	166.6104 °C
Cp	1.017522
Temperature	167.5714 °C
Cp	1.01731
Temperature	168.5325 °C
Cp	1.017098
Temperature	169.4936 °C
Cp	1.016902
Temperature	170.4547 °C
Cp	1.016695
Temperature	171.4158 °C
Cp	1.016508
Temperature	172.3768 °C
Cp	1.016342
Temperature	173.3379 °C
Cp	1.016195
Temperature	174.299 °C
Cp	1.016065
Temperature	175.2601 °C
Cp	1.015927
Temperature	176.2212 °C
Cp	1.015838
Temperature	177.1822 °C
Cp	1.015746
Temperature	178.1433 °C
Cp	1.015651
Temperature	179.1044 °C
Cp	1.015555
Temperature	180.0655 °C
Cp	1.015459
Temperature	181.0266 °C
Cp	1.015401
Temperature	181.9876 °C
Cp	1.015288
Temperature	182.9487 °C
Cp	1.015195
Temperature	183.9098 °C
Cp	1.015117
Temperature	184.8709 °C
Cp	1.01505
Temperature	185.832 °C
Cp	1.014988
Temperature	186.793 °C
Cp	1.014927
Temperature	187.7541 °C
Cp	1.014849
Temperature	188.7152 °C
Cp	1.014789
Temperature	189.6763 °C
Cp	1.01471
Temperature	190.6374 °C
Cp	1.014614
Temperature	191.5984 °C
Cp	1.014503
Temperature	192.5595 °C
Cp	1.014381
Temperature	193.5206 °C
Cp	1.014268
Temperature	194.4817 °C
Cp	1.014122
Temperature	195.4428 °C
Cp	1.013984
Temperature	196.4038 °C
Cp	1.013853
Temperature	197.3649 °C
Cp	1.013726
Temperature	198.326 °C
Cp	1.013603
Temperature	199.2871 °C
Cp	1.013467
Temperature	200.2482 °C
Cp	1.013359
Temperature	201.2092 °C
Cp	1.013243
Temperature	202.1703 °C
Cp	1.013123
Temperature	203.1314 °C
Cp	1.013002
Temperature	204.0925 °C
Cp	1.012884
Temperature	205.0536 °C
Cp	1.012788
Temperature	206.0146 °C
Cp	1.012674
Temperature	206.9757 °C
Cp	1.012579
Temperature	207.9368 °C
Cp	1.012501
Temperature	208.8979 °C
Cp	1.012439
Temperature	209.859 °C
Cp	1.012389
Temperature	210.82 °C
Cp	1.012351
Temperature	211.7811 °C
Cp	1.012312
Temperature	212.7422 °C
Cp	1.01229
Temperature	213.7033 °C
Cp	1.012262
Temperature	214.6644 °C
Cp	1.012227
Temperature	215.6254 °C
Cp	1.012183
Temperature	216.5865 °C
Cp	1.012129
Temperature	217.5476 °C
Cp	1.012077
Temperature	218.5087 °C
Cp	1.01199
Temperature	219.4698 °C
Cp	1.011897
Temperature	220.4308 °C
Cp	1.011793
Temperature	221.3919 °C
Cp	1.011674
Temperature	222.353 °C
Cp	1.011537
Temperature	223.3141 °C
Cp	1.011362
Temperature	224.2752 °C
Cp	1.011194
Temperature	225.2362 °C
Cp	1.010993
Temperature	226.1973 °C
Cp	1.010766
Temperature	227.1584 °C
Cp	1.010517
Temperature	228.1195 °C
Cp	1.010251
Temperature	229.0806 °C
Cp	1.009998
Temperature	230.0416 °C
Cp	1.009703
Temperature	231.0027 °C
Cp	1.009422
Temperature	231.9638 °C
Cp	1.009156
Temperature	232.9249 °C
Cp	1.008906
Temperature	233.886 °C
Cp	1.008675
Temperature	234.847 °C
Cp	1.008462
Temperature	235.8081 °C
Cp	1.008258
Temperature	236.7692 °C
Cp	1.00809
Temperature	237.7303 °C
Cp	1.007934
Temperature	238.6914 °C
Cp	1.007793
Temperature	239.6524 °C
Cp	1.007668
Temperature	240.6135 °C
Cp	1.007562
Temperature	241.5746 °C
Cp	1.007487
Temperature	242.5357 °C
Cp	1.00741
Temperature	243.4967 °C
Cp	1.00736
Temperature	244.4578 °C
Cp	1.007332
Temperature	245.4189 °C
Cp	1.007321
Temperature	246.38 °C
Cp	1.007321
Temperature	247.3411 °C
Cp	1.007312
Temperature	248.3022 °C
Cp	1.007331
Temperature	249.2632 °C
Cp	1.007338
Temperature	250.2243 °C
Cp	1.007335
Temperature	251.1854 °C
Cp	1.00732
Temperature	252.1465 °C
Cp	1.007295
Temperature	253.1076 °C
Cp	1.007277
Temperature	254.0686 °C
Cp	1.007227
Temperature	255.0297 °C
Cp	1.007179
Temperature	255.9908 °C
Cp	1.007133
Temperature	256.9519 °C
Cp	1.00709
Temperature	257.913 °C
Cp	1.007049
Temperature	258.874 °C
Cp	1.007012
Temperature	259.8351 °C
Cp	1.006978
Temperature	260.7962 °C
Cp	1.006956
Temperature	261.7573 °C
Cp	1.00694
Temperature	262.7184 °C
Cp	1.006934
Temperature	263.6794 °C
Cp	1.006939
Temperature	264.6405 °C
Cp	1.00696
Temperature	265.6016 °C
Cp	1.006999
Temperature	266.5627 °C
Cp	1.007054
Temperature	267.5237 °C
Cp	1.007131
Temperature	268.4848 °C
Cp	1.00723
Temperature	269.4459 °C
Cp	1.00735
Temperature	270.407 °C
Cp	1.007493
Temperature	271.3681 °C
Cp	1.007656
Temperature	272.3292 °C
Cp	1.007839
Temperature	273.2902 °C
Cp	1.008039
Temperature	274.2513 °C
Cp	1.008257
Temperature	275.2124 °C
Cp	1.008488
Temperature	276.1735 °C
Cp	1.008731
Temperature	277.1346 °C
Cp	1.008977
Temperature	278.0956 °C
Cp	1.009237
Temperature	279.0567 °C
Cp	1.009498
Temperature	280.0178 °C
Cp	1.009757
Temperature	280.9789 °C
Cp	1.010014
Temperature	281.9399 °C
Cp	1.010267
Temperature	282.901 °C
Cp	1.010515
Temperature	283.8621 °C
Cp	1.01076
Temperature	284.8232 °C
Cp	1.010993
Temperature	285.7843 °C
Cp	1.011222
Temperature	286.7454 °C
Cp	1.011447
Temperature	287.7064 °C
Cp	1.011665
Temperature	288.6675 °C
Cp	1.011876
Temperature	289.6286 °C
Cp	1.012079
Temperature	290.5897 °C
Cp	1.01228
Temperature	291.5508 °C
Cp	1.012474
Temperature	292.5118 °C
Cp	1.012662
Temperature	293.4729 °C
Cp	1.012846
Temperature	294.434 °C
Cp	1.013028
Temperature	295.3951 °C
Cp	1.013211
Temperature	296.3561 °C
Cp	1.013391
Temperature	297.3172 °C
Cp	1.013574
Temperature	298.2783 °C
Cp	1.013759
Temperature	299.2394 °C
Cp	1.013947
Temperature	300.2005 °C
Cp	1.014136
Temperature	301.1616 °C
Cp	1.01432
Temperature	302.1226 °C
Cp	1.014511
Temperature	303.0837 °C
Cp	1.014695
Temperature	304.0448 °C
Cp	1.014872
Temperature	305.0059 °C
Cp	1.01504
Temperature	305.9669 °C
Cp	1.015198
Temperature	306.928 °C
Cp	1.015343
Temperature	307.8891 °C
Cp	1.015479
Temperature	308.8502 °C
Cp	1.015595
Temperature	309.8113 °C
Cp	1.015699
Temperature	310.7724 °C
Cp	1.015789
Temperature	311.7334 °C
Cp	1.015865
Temperature	312.6945 °C
Cp	1.015925
Temperature	313.6556 °C
Cp	1.015964
Temperature	314.6167 °C
Cp	1.015999
Temperature	315.5778 °C
Cp	1.016018
Temperature	316.5388 °C
Cp	1.016025
Temperature	317.4999 °C
Cp	1.016024
Temperature	318.461 °C
Cp	1.01602
Temperature	319.4221 °C
Cp	1.016029
Temperature	320.3831 °C
Cp	1.016025
Temperature	321.3442 °C
Cp	1.016037
Temperature	322.3053 °C
Cp	1.016066
Temperature	323.2664 °C
Cp	1.01611
Temperature	324.2275 °C
Cp	1.016169
Temperature	325.1886 °C
Cp	1.016225
Temperature	326.1496 °C
Cp	1.016318
Temperature	327.1107 °C
Cp	1.016411
Temperature	328.0718 °C
Cp	1.016504
Temperature	329.0329 °C
[...]
187.5883	110.9562	0.3651
187.5967	110.8722	0.3650
187.6050	110.7900	0.3649
187.6133	110.7073	0.3649
187.6217	110.6231	0.3648
187.6300	110.5408	0.3646
187.6383	110.4570	0.3645
187.6467	110.3740	0.3645
187.6550	110.2911	0.3644
187.6633	110.2085	0.3644
187.6717	110.1244	0.3643
187.6800	110.0415	0.3643
187.6883	109.9586	0.3643
187.6967	109.8746	0.3643
187.7050	109.7917	0.3642
187.7133	109.7084	0.3642
187.7217	109.6256	0.3642
187.7300	109.5423	0.3641
187.7383	109.4602	0.3641
187.7467	109.3770	0.3640
187.7550	109.2930	0.3640
187.7633	109.2105	0.3640
187.7717	109.1272	0.3639
187.7800	109.0433	0.3638
187.7883	108.9609	0.3638
187.7967	108.8774	0.3638
187.8050	108.7944	0.3637
187.8133	108.7127	0.3636
187.8217	108.6290	0.3636
187.8300	108.5460	0.3636
187.8383	108.4623	0.3635
187.8467	108.3799	0.3634
187.8550	108.2957	0.3634
187.8633	108.2135	0.3634
187.8717	108.1302	0.3633
187.8800	108.0467	0.3633
187.8883	107.9632	0.3632
187.8967	107.8804	0.3630
187.9050	107.7966	0.3630
187.9133	107.7147	0.3630
187.9217	107.6306	0.3630
187.9300	107.5486	0.3629
187.9383	107.4650	0.3628
187.9467	107.3799	0.3628
187.9550	107.2975	0.3627
187.9633	107.2151	0.3627
187.9717	107.1320	0.3627
187.9800	107.0487	0.3627
187.9883	106.9660	0.3626
187.9967	106.8820	0.3626
188.0050	106.7973	0.3626
188.0133	106.7153	0.3626
188.0217	106.6322	0.3624
188.0300	106.5495	0.3621
188.0383	106.4651	0.3621
188.0467	106.3831	0.3621
188.0550	106.2998	0.3621
188.0633	106.2172	0.3620
188.0717	106.1333	0.3620
188.0800	106.0508	0.3619
188.0883	105.9676	0.3619
188.0967	105.8861	0.3619
188.1050	105.8011	0.3618
188.1133	105.7180	0.3617
188.1217	105.6352	0.3617
188.1300	105.5518	0.3616
188.1383	105.4679	0.3616
188.1467	105.3852	0.3615
188.1550	105.3021	0.3615
188.1633	105.2192	0.3614
188.1717	105.1354	0.3614
188.1800	105.0517	0.3613
188.1883	104.9693	0.3612
188.1967	104.8865	0.3612
188.2050	104.8035	0.3612
188.2133	104.7178	0.3611
188.2217	104.6372	0.3611
188.2300	104.5530	0.3610
188.2383	104.4703	0.3610
188.2467	104.3875	0.3610
188.2550	104.3034	0.3607
188.2633	104.2207	0.3607
188.2717	104.1372	0.3607
188.2800	104.0536	0.3607
188.2883	103.9707	0.3606
188.2967	103.8875	0.3604
188.3050	103.8048	0.3604
188.3133	103.7215	0.3603
188.3217	103.6385	0.3603
188.3300	103.5555	0.3603
188.3383	103.4728	0.3602
188.3467	103.3889	0.3602
188.3550	103.3050	0.3601
188.3633	103.2238	0.3601
188.3717	103.1403	0.3600
188.3800	103.0564	0.3600
188.3883	102.9741	0.3599
188.3967	102.8896	0.3599
188.4050	102.8059	0.3598
188.4133	102.7243	0.3595
188.4217	102.6411	0.3595
188.4300	102.5574	0.3595
188.4383	102.4741	0.3594
188.4467	102.3910	0.3594
188.4550	102.3091	0.3593
188.4633	102.2265	0.3593
188.4717	102.1415	0.3592
188.4800	102.0594	0.3592
188.4883	101.9764	0.3591
188.4967	101.8928	0.3591
188.5050	101.8109	0.3590
188.5133	101.7268	0.3590
188.5217	101.6447	0.3589
188.5300	101.5598	0.3589
188.5383	101.4758	0.3589
188.5467	101.3930	0.3589
188.5550	101.3106	0.3588
188.5633	101.2282	0.3588
188.5717	101.1444	0.3587
188.5800	101.0610	0.3587
188.5883	100.9780	0.3586
188.5967	100.8954	0.3586
188.6050	100.8116	0.3585
188.6133	100.7285	0.3585
188.6217	100.6456	0.3584
188.6300	100.5619	0.3584
188.6383	100.4791	0.3583
188.6467	100.3964	0.3583
188.6550	100.3132	0.3582
188.6633	100.2290	0.3581
188.6717	100.1457	0.3581
188.6800	100.0631	0.3581
188.6883	99.9790	0.3580
188.6967	99.8967	0.3580
188.7050	99.8121	0.3580
188.7133	99.7308	0.3579
188.7217	99.6477	0.3578
188.7300	99.5645	0.3577
188.7383	99.4811	0.3577
188.7467	99.3985	0.3576
188.7550	99.3165	0.3576
188.7633	99.2325	0.3576
188.7717	99.1495	0.3575
188.7800	99.0665	0.3573
188.7883	98.9827	0.3572
188.7967	98.9001	0.3572
188.8050	98.8161	0.3571
188.8133	98.7336	0.3571
188.8217	98.6508	0.3570
188.8300	98.5662	0.3570
188.8383	98.4837	0.3569
188.8467	98.4018	0.3569
188.8550	98.3182	0.3568
188.8633	98.2337	0.3568
188.8717	98.1517	0.3567
188.8800	98.0685	0.3567
188.8883	97.9852	0.3566
188.8967	97.9023	0.3566
188.9050	97.8186	0.3565
188.9133	97.7359	0.3565
188.9217	97.6520	0.3564
188.9300	97.5694	0.3564
188.9383	97.4873	0.3563
188.9467	97.4035	0.3563
188.9550	97.3214	0.3562
188.9633	97.2366	0.3562
188.9717	97.1537	0.3561
188.9800	97.0709	0.3560
188.9883	96.9887	0.3559
188.9967	96.9049	0.3559
189.0050	96.8215	0.3558
189.0133	96.7390	0.3558
189.0217	96.6543	0.3557
189.0300	96.5714	0.3556
189.0383	96.4894	0.3556
189.0467	96.4059	0.3555
189.0550	96.3219	0.3555
189.0633	96.2392	0.3554
189.0717	96.1558	0.3554
189.0800	96.0734	0.3553
189.0883	95.9893	0.3552
189.0967	95.9068	0.3552
189.1050	95.8234	0.3551
189.1133	95.7405	0.3551
189.1217	95.6571	0.3551
189.1300	95.5736	0.3550
189.1383	95.4912	0.3550
189.1467	95.4085	0.3549
189.1550	95.3250	0.3548
189.1633	95.2421	0.3548
189.1717	95.1588	0.3547
189.1800	95.0765	0.3545
189.1883	94.9938	0.3544
189.1967	94.9092	0.3544
189.2050	94.8261	0.3543
189.2133	94.7439	0.3543
189.2217	94.6597	0.3542
189.2300	94.5768	0.3542
189.2383	94.4931	0.3541
189.2467	94.4101	0.3541
189.2550	94.3272	0.3540
189.2633	94.2438	0.3540
189.2717	94.1614	0.3539
189.2800	94.0778	0.3539
189.2883	93.9941	0.3538
189.2967	93.9106	0.3538
189.3050	93.8285	0.3537
189.3133	93.7450	0.3537
189.3217	93.6622	0.3536
189.3300	93.5783	0.3536
189.3383	93.4955	0.3535
189.3467	93.4123	0.3534
189.3550	93.3288	0.3534
189.3633	93.2462	0.3533
189.3717	93.1628	0.3533
189.3800	93.0804	0.3532
189.3883	92.9973	0.3532
189.3967	92.9151	0.3531
189.4050	92.8317	0.3531
189.4133	92.7484	0.3530
189.4217	92.6628	0.3530
189.4300	92.5807	0.3529
189.4383	92.4977	0.3529
189.4467	92.4142	0.3528
189.4550	92.3306	0.3528
189.4633	92.2491	0.3527
189.4717	92.1654	0.3527
189.4800	92.0822	0.3526
189.4883	91.9977	0.3526
189.4967	91.9164	0.3525
189.5050	91.8333	0.3524
189.5133	91.7500	0.3523
189.5217	91.6671	0.3523
189.5300	91.5840	0.3523
189.5383	91.5007	0.3522
189.5467	91.4174	0.3522
189.5550	91.3345	0.3521
189.5633	91.2515	0.3521
189.5717	91.1669	0.3520
189.5800	91.0844	0.3520
189.5883	91.0015	0.3519
189.5967	90.9174	0.3518
189.6050	90.8347	0.3518
189.6133	90.7519	0.3517
189.6217	90.6691	0.3517
189.6300	90.5861	0.3515
189.6383	90.5023	0.3515
189.6467	90.4186	0.3515
189.6550	90.3368	0.3514
189.6633	90.2523	0.3513
189.6717	90.1692	0.3512
189.6800	90.0872	0.3512
189.6883	90.0030	0.3512
189.6967	89.9196	0.3511
189.7050	89.8367	0.3510
189.7133	89.7540	0.3509
189.7217	89.6711	0.3509
189.7300	89.5876	0.3508
189.7383	89.5048	0.3508
189.7467	89.4213	0.3508
189.7550	89.3373	0.3507
189.7633	89.2552	0.3507
189.7717	89.1709	0.3506
189.7800	89.0884	0.3505
189.7883	89.0046	0.3505
189.7967	88.9211	0.3505
189.8050	88.8387	0.3504
189.8133	88.7542	0.3504
189.8217	88.6717	0.3503
189.8300	88.5892	0.3502
189.8383	88.5063	0.3502
189.8467	88.4223	0.3501
189.8550	88.3403	0.3500
189.8633	88.2564	0.3500
189.8717	88.1737	0.3500
189.8800	88.0894	0.3500
189.8883	88.0072	0.3498
189.8967	87.9233	0.3497
189.9050	87.8406	0.3496
189.9133	87.7583	0.3496
189.9217	87.6742	0.3495
189.9300	87.5922	0.3493
189.9383	87.5086	0.3493
189.9467	87.4253	0.3493
189.9550	87.3417	0.3492
189.9633	87.2591	0.3492
189.9717	87.1758	0.3491
189.9800	87.0924	0.3491
189.9883	87.0095	0.3490
189.9967	86.9261	0.3490
190.0050	86.8430	0.3489
190.0133	86.7600	0.3489
190.0217	86.6771	0.3489
190.0300	86.5940	0.3486
190.0383	86.5096	0.3486
190.0467	86.4272	0.3485
190.0550	86.3450	0.3485
190.0633	86.2611	0.3484
190.0717	86.1775	0.3483
190.0800	86.0953	0.3483
190.0883	86.0117	0.3482
190.0967	85.9282	0.3482
190.1050	85.8453	0.3481
190.1133	85.7623	0.3481
190.1217	85.6786	0.3481
190.1300	85.5972	0.3480
190.1383	85.5125	0.3480
190.1467	85.4290	0.3479
190.1550	85.3468	0.3479
190.1633	85.2638	0.3478
190.1717	85.1808	0.3477
190.1800	85.0970	0.3477
190.1883	85.0137	0.3477
190.1967	84.9312	0.3476
190.2050	84.8473	0.3475
190.2133	84.7639	0.3475
190.2217	84.6810	0.3473
190.2300	84.5979	0.3473
190.2383	84.5163	0.3472
190.2467	84.4326	0.3472
190.2550	84.3485	0.3471
190.2633	84.2645	0.3470
190.2717	84.1825	0.3470
190.2800	84.0986	0.3469
190.2883	84.0161	0.3469
190.2967	83.9340	0.3469
190.3050	83.8509	0.3467
190.3133	83.7666	0.3466
190.3217	83.6835	0.3466
190.3300	83.6003	0.3466
190.3383	83.5171	0.3465
190.3467	83.4341	0.3465
190.3550	83.3501	0.3464
190.3633	83.2681	0.3463
190.3717	83.1843	0.3463
190.3800	83.1009	0.3462
190.3883	83.0193	0.3462
190.3967	82.9357	0.3461
190.4050	82.8518	0.3460
190.4133	82.7695	0.3460
190.4217	82.6872	0.3460
190.4300	82.6040	0.3459
190.4383	82.5198	0.3459
190.4467	82.4363	0.3457
190.4550	82.3533	0.3457
190.4633	82.2706	0.3457
190.4717	82.1875	0.3455
190.4800	82.1049	0.3454
190.4883	82.0216	0.3454
190.4967	81.9387	0.3453
190.5050	81.8557	0.3453
190.5133	81.7714	0.3452
190.5217	81.6897	0.3452
190.5300	81.6068	0.3451
190.5383	81.5233	0.3450
190.5467	81.4384	0.3450
190.5550	81.3567	0.3450
190.5633	81.2734	0.3449
190.5717	81.1898	0.3449
190.5800	81.1084	0.3448
190.5883	81.0245	0.3447
190.5967	80.9413	0.3447
190.6050	80.8582	0.3446
190.6133	80.7740	0.3446
190.6217	80.6912	0.3445
190.6300	80.6096	0.3445
190.6383	80.5250	0.3445
190.6467	80.4415	0.3443
190.6550	80.3595	0.3442
190.6633	80.2763	0.3441
190.6717	80.1934	0.3441
190.6800	80.1099	0.3440
190.6883	80.0270	0.3439
190.6967	79.9437	0.3438
190.7050	79.8603	0.3438
190.7133	79.7773	0.3438
190.7217	79.6940	0.3438
190.7300	79.6105	0.3437
190.7383	79.5263	0.3437
190.7467	79.4450	0.3436
190.7550	79.3613	0.3435
190.7633	79.2770	0.3435
190.7717	79.1947	0.3434
190.7800	79.1122	0.3434
190.7883	79.0287	0.3433
190.7967	78.9466	0.3433
190.8050	78.8624	0.3433
190.8133	78.7781	0.3433
190.8217	78.6968	0.3432
190.8300	78.6126	0.3431
190.8383	78.5299	0.3430
190.8467	78.4470	0.3430
190.8550	78.3647	0.3429
190.8633	78.2805	0.3428
190.8717	78.1973	0.3428
190.8800	78.1139	0.3427
190.8883	78.0307	0.3427
190.8967	77.9479	0.3426
190.9050	77.8648	0.3426
190.9133	77.7815	0.3425
190.9217	77.6985	0.3424
190.9300	77.6151	0.3424
190.9383	77.5315	0.3424
190.9467	77.4486	0.3423
190.9550	77.3652	0.3422
190.9633	77.2816	0.3422
190.9717	77.1994	0.3421
190.9800	77.1159	0.3421
190.9883	77.0323	0.3421
190.9967	76.9489	0.3420
191.0050	76.8664	0.3419
191.0133	76.7821	0.3419
191.0217	76.6992	0.3418
191.0300	76.6164	0.3417
191.0383	76.5324	0.3416
191.0467	76.4493	0.3416
191.0550	76.3674	0.3415
191.0633	76.2841	0.3415
191.0717	76.2006	0.3415
191.0800	76.1176	0.3413
191.0883	76.0355	0.3409
191.0967	75.9519	0.3408
191.1050	75.8686	0.3408
191.1133	75.7857	0.3407
191.1217	75.7023	0.3407
191.1300	75.6188	0.3406
191.1383	75.5364	0.3406
191.1467	75.4529	0.3406
191.1550	75.3697	0.3404
191.1633	75.2866	0.3404
191.1717	75.2035	0.3403
191.1800	75.1207	0.3402
191.1883	75.0366	0.3402
191.1967	74.9539	0.3401
191.2050	74.8700	0.3401
191.2133	74.7885	0.3401
191.2217	74.7051	0.3400
191.2300	74.6209	0.3400
191.2383	74.5380	0.3400
191.2467	74.4554	0.3398
191.2550	74.3729	0.3398
191.2633	74.2896	0.3397
191.2717	74.2053	0.3397
191.2800	74.1226	0.3396
191.2883	74.0393	0.3396
191.2967	73.9561	0.3395
191.3050	73.8731	0.3394
191.3133	73.7892	0.3394
191.3217	73.7070	0.3393
191.3300	73.6239	0.3393
191.3383	73.5406	0.3393
191.3467	73.4574	0.3392
191.3550	73.3738	0.3392
191.3633	73.2918	0.3391
191.3717	73.2075	0.3391
191.3800	73.1246	0.3390
191.3883	73.0427	0.3390
191.3967	72.9594	0.3389
191.4050	72.8755	0.3389
191.4133	72.7920	0.3388
191.4217	72.7086	0.3387
191.4300	72.6257	0.3387
191.4383	72.5431	0.3386
191.4467	72.4598	0.3386
191.4550	72.3769	0.3385
191.4633	72.2934	0.3385
191.4717	72.2113	0.3383
191.4800	72.1268	0.3383
191.4883	72.0439	0.3382
191.4967	71.9611	0.3381
191.5050	71.8779	0.3381
191.5133	71.7954	0.3380
191.5217	71.7109	0.3380
191.5300	71.6287	0.3379
191.5383	71.5453	0.3379
191.5467	71.4627	0.3378
191.5550	71.3783	0.3377
191.5633	71.2957	0.3376
191.5717	71.2123	0.3376
191.5800	71.1292	0.3376
191.5883	71.0462	0.3375
191.5967	70.9634	0.3373
191.6050	70.8795	0.3372
191.6133	70.7967	0.3371
191.6217	70.7137	0.3371
191.6300	70.6310	0.3370
191.6383	70.5475	0.3370
191.6467	70.4648	0.3369
191.6550	70.3821	0.3369
191.6633	70.2977	0.3368
191.6717	70.2148	0.3368
191.6800	70.1318	0.3367
191.6883	70.0490	0.3367
191.6967	69.9655	0.3366
191.7050	69.8819	0.3365
191.7133	69.7989	0.3365
191.7217	69.7157	0.3364
191.7300	69.6332	0.3363
191.7383	69.5500	0.3363
191.7467	69.4666	0.3362
191.7550	69.3834	0.3362
191.7633	69.3013	0.3360
191.7717	69.2161	0.3359
191.7800	69.1333	0.3359
191.7883	69.0497	0.3359
191.7967	68.9668	0.3358
191.8050	68.8839	0.3358
191.8133	68.8009	0.3357
191.8217	68.7179	0.3356
191.8300	68.6342	0.3356
191.8383	68.5507	0.3355
191.8467	68.4669	0.3355
191.8550	68.3848	0.3354
191.8633	68.3013	0.3353
191.8717	68.2182	0.3353
191.8800	68.1353	0.3353
191.8883	68.0516	0.3351
191.8967	67.9698	0.3349
191.9050	67.8857	0.3349
191.9133	67.8029	0.3348
191.9217	67.7198	0.3347
191.9300	67.6370	0.3346
191.9383	67.5540	0.3346
191.9467	67.4691	0.3345
191.9550	67.3870	0.3345
191.9633	67.3039	0.3344
191.9717	67.2209	0.3343
191.9800	67.1377	0.3343
191.9883	67.0541	0.3343
191.9967	66.9711	0.3342
192.0050	66.8880	0.3341
192.0133	66.8053	0.3340
192.0217	66.7215	0.3340
192.0300	66.6383	0.3339
192.0383	66.5558	0.3339
192.0467	66.4739	0.3338
192.0550	66.3885	0.3337
192.0633	66.3064	0.3337
192.0717	66.2237	0.3337
192.0800	66.1394	0.3336
192.0883	66.0562	0.3333
192.0967	65.9747	0.3333
192.1050	65.8899	0.3332
192.1133	65.8064	0.3332
192.1217	65.7237	0.3331
192.1300	65.6412	0.3331
192.1383	65.5581	0.3330
192.1467	65.4753	0.3329
192.1550	65.3911	0.3329
192.1633	65.3092	0.3328
192.1717	65.2250	0.3328
192.1800	65.1416	0.3327
192.1883	65.0581	0.3326
192.1967	64.9757	0.3326
192.2050	64.8916	0.3325
192.2133	64.8096	0.3325
192.2217	64.7245	0.3324
192.2300	64.6432	0.3323
192.2383	64.5605	0.3323
192.2467	64.4764	0.3322
192.2550	64.3932	0.3322
192.2633	64.3090	0.3321
192.2717	64.2266	0.3320
192.2800	64.1434	0.3320
192.2883	64.0606	0.3320
192.2967	63.9770	0.3319
192.3050	63.8941	0.3318
192.3133	63.8100	0.3317
192.3217	63.7271	0.3317
192.3300	63.6448	0.3316
192.3383	63.5610	0.3315
192.3467	63.4777	0.3315
192.3550	63.3956	0.3314
192.3633	63.3125	0.3313
192.3717	63.2278	0.3313
192.3800	63.1455	0.3312
192.3883	63.0625	0.3312
192.3967	62.9788	0.3311
192.4050	62.8970	0.3311
192.4133	62.8130	0.3310
192.4217	62.7290	0.3309
192.4300	62.6463	0.3308
192.4383	62.5630	0.3308
192.4467	62.4797	0.3307
192.4550	62.3962	0.3307
192.4633	62.3129	0.3306
192.4717	62.2303	0.3305
192.4800	62.1465	0.3304
192.4883	62.0635	0.3303
192.4967	61.9798	0.3303
192.5050	61.8971	0.3302
192.5133	61.8144	0.3302
192.5217	61.7310	0.3301
192.5300	61.6472	0.3301
192.5383	61.5636	0.3300
192.5467	61.4812	0.3299
192.5550	61.3972	0.3298
192.5633	61.3150	0.3297
192.5717	61.2325	0.3296
192.5800	61.1483	0.3296
192.5883	61.0662	0.3295
192.5967	60.9812	0.3295
192.6050	60.8980	0.3293
192.6133	60.8158	0.3293
192.6217	60.7320	0.3292
192.6300	60.6494	0.3291
192.6383	60.5668	0.3291
192.6467	60.4833	0.3290
192.6550	60.3985	0.3289
192.6633	60.3153	0.3289
192.6717	60.2327	0.3288
192.6800	60.1499	0.3288
192.6883	60.0671	0.3286
192.6967	59.9845	0.3285
192.7050	59.9014	0.3284
192.7133	59.8172	0.3283
192.7217	59.7351	0.3283
192.7300	59.6515	0.3282
192.7383	59.5676	0.3281
192.7467	59.4848	0.3281
192.7550	59.4023	0.3279
192.7633	59.3192	0.3279
192.7717	59.2354	0.3278
192.7800	59.1525	0.3277
192.7883	59.0707	0.3277
192.7967	58.9860	0.3276
192.8050	58.9025	0.3275
192.8133	58.8206	0.3274
192.8217	58.7362	0.3273
192.8300	58.6529	0.3273
192.8383	58.5695	0.3272
192.8467	58.4874	0.3271
192.8550	58.4030	0.3270
192.8633	58.3210	0.3270
192.8717	58.2373	0.3270
192.8800	58.1542	0.3269
192.8883	58.0712	0.3266
192.8967	57.9879	0.3266
192.9050	57.9039	0.3265
192.9133	57.8211	0.3265
192.9217	57.7387	0.3265
192.9300	57.6549	0.3264
192.9383	57.5723	0.3263
192.9467	57.4887	0.3262
192.9550	57.4058	0.3260
192.9633	57.3219	0.3260
192.9717	57.2396	0.3259
192.9800	57.1554	0.3259
192.9883	57.0717	0.3258
192.9967	56.9883	0.3257
193.0050	56.9064	0.3257
193.0133	56.8228	0.3256
193.0217	56.7401	0.3255
193.0300	56.6572	0.3255
193.0383	56.5730	0.3254
193.0467	56.4900	0.3254
193.0550	56.4070	0.3253
193.0633	56.3243	0.3253
193.0717	56.2410	0.3252
193.0800	56.1577	0.3251
193.0883	56.0744	0.3250
193.0967	55.9923	0.3250
193.1050	55.9089	0.3250
193.1133	55.8253	0.3249
193.1217	55.7421	0.3249
193.1300	55.6588	0.3248
193.1383	55.5763	0.3247
193.1467	55.4928	0.3245
193.1550	55.4100	0.3244
193.1633	55.3271	0.3244
193.1717	55.2431	0.3244
193.1800	55.1599	0.3242
193.1883	55.0766	0.3242
193.1967	54.9931	0.3241
193.2050	54.9118	0.3240
193.2133	54.8277	0.3239
193.2217	54.7445	0.3239
193.2300	54.6605	0.3238
193.2383	54.5777	0.3238
193.2467	54.4941	0.3238
193.2550	54.4106	0.3236
193.2633	54.3285	0.3235
193.2717	54.2454	0.3234
193.2800	54.1608	0.3232
193.2883	54.0794	0.3231
193.2967	53.9951	0.3231
193.3050	53.9132	0.3231
193.3133	53.8293	0.3230
193.3217	53.7452	0.3230
193.3300	53.6623	0.3229
193.3383	53.5790	0.3228
193.3467	53.4954	0.3228
193.3550	53.4127	0.3227
193.3633	53.3298	0.3226
193.3717	53.2469	0.3226
193.3800	53.1644	0.3226
193.3883	53.0803	0.3225
193.3967	52.9978	0.3223
193.4050	52.9138	0.3222
193.4133	52.8310	0.3222
193.4217	52.7477	0.3221
193.4300	52.6657	0.3220
193.4383	52.5812	0.3221
193.4467	52.4982	0.3220
193.4550	52.4156	0.3219
193.4633	52.3322	0.3219
193.4717	52.2487	0.3218
193.4800	52.1646	0.3217
193.4883	52.0818	0.3217
193.4967	51.9992	0.3217
193.5050	51.9154	0.3216
193.5133	51.8316	0.3216
193.5217	51.7501	0.3215
193.5300	51.6663	0.3215
193.5383	51.5838	0.3213
193.5467	51.5005	0.3213
193.5550	51.4166	0.3213
193.5633	51.3333	0.3212
193.5717	51.2505	0.3211
193.5800	51.1677	0.3210
193.5883	51.0845	0.3210
193.5967	51.0014	0.3209
193.6050	50.9177	0.3209
193.6133	50.8347	0.3208
193.6217	50.7518	0.3208
193.6300	50.6681	0.3207
193.6383	50.5865	0.3206
193.6467	50.5025	0.3206
193.6550	50.4186	0.3206
193.6633	50.3357	0.3205
193.6717	50.2523	0.3205
193.6800	50.1703	0.3205
193.6883	50.0879	0.3205
193.6967	50.0047	0.3205
193.7050	49.9212	0.3205
193.7133	49.8370	0.3205
193.7217	49.7543	0.3206
193.7300	49.6699	0.3207
193.7383	49.5876	0.3211
193.7467	49.5041	0.3224
193.7550	49.4225	0.3232
193.7633	49.3398	0.3243
193.7717	49.2582	0.3278
193.7800	49.1750	0.3345
193.7883	49.0932	0.3373
193.7967	49.0110	0.3426
193.8050	48.9277	0.3481
193.8133	48.8468	0.3553
193.8217	48.7655	0.3645
193.8300	48.6840	0.3768
193.8383	48.6041	0.3934
193.8467	48.5243	0.4100
193.8550	48.4448	0.4363
193.8633	48.3667	0.4632
193.8717	48.2899	0.4982
193.8800	48.2152	0.5443
193.8883	48.1422	0.5974
193.8967	48.0706	0.6641
193.9050	48.0021	0.7440
193.9133	47.9386	0.8393
193.9217	47.8781	0.9538
193.9300	47.8215	1.0840
193.9383	47.7690	1.2298
193.9467	47.7228	1.3914
193.9550	47.6822	1.5650
193.9633	47.6470	1.7479
193.9717	47.6173	1.9349
193.9800	47.5915	2.1181
193.9883	47.5694	2.2994
193.9967	47.5518	2.4685
194.0050	47.5341	2.6292
194.0133	47.5198	2.7733
194.0217	47.5061	2.9058
194.0300	47.4905	3.0262
194.0383	47.4744	3.1319
194.0467	47.4581	3.2265
194.0550	47.4378	3.3102
194.0633	47.4162	3.3863
194.0717	47.3925	3.4512
194.0800	47.3665	3.5115
194.0883	47.3372	3.5646
194.0967	47.3055	3.6111
194.1050	47.2703	3.6550
194.1133	47.2334	3.6917
194.1217	47.1939	3.7244
194.1300	47.1511	3.7527
194.1383	47.1060	3.7780
194.1467	47.0592	3.8002
194.1550	47.0081	3.8161
194.1633	46.9557	3.8293
194.1717	46.9007	3.8370
194.1800	46.8432	3.8413
194.1883	46.7832	3.8421
194.1967	46.7217	3.8355
194.2050	46.6555	3.8259
194.2133	46.5891	3.8087
194.2217	46.5196	3.7888
194.2300	46.4454	3.7625
194.2383	46.3727	3.7281
194.2467	46.2950	3.6903
194.2550	46.2137	3.6451
194.2633	46.1311	3.5951
194.2717	46.0448	3.5393
194.2800	45.9555	3.4730
194.2883	45.8652	3.4086
194.2967	45.7704	3.3368
194.3050	45.6724	3.2588
194.3133	45.5731	3.1787
194.3217	45.4696	3.0961
194.3300	45.3653	3.0079
194.3383	45.2575	2.9213
194.3467	45.1470	2.8314
194.3550	45.0352	2.7423
194.3633	44.9209	2.6551
194.3717	44.8071	2.5703
194.3800	44.6910	2.4880
194.3883	44.5720	2.4062
194.3967	44.4544	2.3321
194.4050	44.3366	2.2595
194.4133	44.2175	2.1889
194.4217	44.0994	2.1262
194.4300	43.9808	2.0624
194.4383	43.8626	2.0022
194.4467	43.7443
194.4550	43.6279
194.4633	43.5102
194.4717	43.3937
194.4800	43.2786
194.4883	43.1635
194.4967