File: Example Date/My Sample/DSC/test01/LLM_EP_0402.txt
Filename	LLM_EP_0402
Instrument name	DSC2A-01799 (192.168.1.250)
Operator
rundate	10/02/2025
Sample name	LLM_EP_0402
proceduresegments	Ramp 10.00 °C/min to 25.0000 °C; Ramp 10.00 °C/min to 135.0000 °C; Isothermal 5.0 min; Ramp 10.00 °C/min to -50.0000 °C; Isothermal 5.0 min; Ramp 10.00 °C/min to 200.0000 °C; Isothermal 5.0 min; Ramp 10.00 °C/min to -50.0000 °C; Isothermal 5.0 min; Ramp 10.00 °C/min to 200.0000 °C; Isothermal 5.0 min; Ramp 10.00 °C/min to -50.0000 °C
[File Parameters]
Run Date	10/02/2025 16:55:39
Trios version	5.7.0.56
Original File Name
Current File Name	C:\Users\TA Instruments DSC\Desktop\Data\LLM\LLM_EP_0402.tri
User at run start	DESKTOP-CFGN8IT\TA Instruments DSC
[Procedure]
Procedure Name	LLM_EP_0402
Sample Name	LLM_EP_0402
Sample Mass	14.25 mg
Reference Sample Mass	0 mg
Pan Mass	61.77 mg
Pan Number	21
Reference Pan Mass	43.13 mg
Reference Pan Number	13
Pan Type	Tzero Aluminum Pin Hole Hermetic
Comments
Project Name
Operator
Test	Custom
Unload Max Temperature	25
Unload Min Temperature	25
FillCooler	Do not fill
Load Max Temperature	25
Load Min Temperature	25
Discard pan in waste bin at end of test	No
Stop on Gas Flow Error	No
[Signal List]
Signal #1	Time (min)
Signal #2	Temperature (°C)
Signal #3	Heat Flow (mW)
Signal #4	Delta T (µV)
Signal #5	Delta Tzero (µV)
Signal #6	Tzero Temperature (°C)
Signal #7	Cell Purge (mL/min)
Signal #8	Heater Temp (°C)
Signal #9	Power Delivered (W)
Signal #10	Reference Junction Temperature (°C)
Signal #11	Flange Temperature (°C)
Signal #12	Heat Flow Phase (rad)
Signal #13	Total Heat Capacity (J/°C)
Signal #14	Heat Capacity (J/°C)
Signal #15	LN Pump Tank level (%)
[Configuration]
Company Name	Warwick University
Instrument Name	DSC2A-01799
Instrument Type	DSC2500
Serial Number	DSC2A-01799
IP	192.168.1.250
Location of Instrument	Polymer RTP
DisplayType	TianmaV2andV3
Sample Interval 	0.1 s/pt
Selected Heat Flow	T4P
Exotherm Direction	Up
Cell Serial	DRC2-03788
Lid Type	High Temperature
Cooler	LN Pump
Leave Cooler on at End of Sequence	Off
Gas 2	Air
Gas Selected	Channel 1: Nitrogen
Flow Rate	50 mL/min
Secondary Purge	On
Licensed Heat Flow	Heat Flow T4P
Modulation Licensed	Yes
[Versions]
Common IDD Version	1
Cortex Version	VER 2.11.0.729
Driver	5.0.0.6
GDM Version	1.0.3.3
TouchscreenVersion	1.0.3.1841
FEP Version	1.2.1.21
FEP Bootloader	2.0.0.5
AutoSampler Version	2.1.2.1
Auto Sampler Bootloader	2.0.0.5
FCM Version	1.1.0.3
FCM Bootloader	2.0.0.5
LN Pump Version	10.17.0.0
LN Pump Bootloader	2.0.0.5
[Experiment Logs]
Experiment Log Entry # 1	Ramp Segment 10 C/min to 25 Started
Experiment Log Entry # 3	Air Cool is off.
Experiment Log Entry # 5	Ramp Segment 10 C/min to 135 Started
Experiment Log Entry # 7	Isothermal Segment 5 min started
Experiment Log Entry # 9	Ramp Segment 10 C/min to -50 Started
Experiment Log Entry # 11	Isothermal Segment 5 min started
Experiment Log Entry # 13	Ramp Segment 10 C/min to 200 Started
Experiment Log Entry # 15	Isothermal Segment 5 min started
Experiment Log Entry # 17	Ramp Segment 10 C/min to -50 Started
Experiment Log Entry # 19	Isothermal Segment 5 min started
Experiment Log Entry # 21	Ramp Segment 10 C/min to 200 Started
Experiment Log Entry # 23	Isothermal Segment 5 min started
Experiment Log Entry # 25	Ramp Segment 10 C/min to -50 Started
[Method Log]
Method Log Entry # 1	(Ramp 1165255) Ramp 10 °C/minute to 25 °C
Method Log Entry # 2	(Ramp 1165256) Ramp 10 °C/minute to 135 °C
Method Log Entry # 3	Isothermal 5 minutes
Method Log Entry # 4	(Ramp 1165258) Ramp 10 °C/minute to -50 °C
Method Log Entry # 5	Isothermal 5 minutes
Method Log Entry # 6	(Ramp 1165260) Ramp 10 °C/minute to 200 °C
Method Log Entry # 7	Isothermal 5 minutes
Method Log Entry # 8	(Ramp 1165262) Ramp 10 °C/minute to -50 °C
Method Log Entry # 9	Isothermal 5 minutes
Method Log Entry # 10	(Ramp 1165264) Ramp 10 °C/minute to 200 °C
Method Log Entry # 11	Isothermal 5 minutes
Method Log Entry # 12	(Ramp 1165266) Ramp 10 °C/minute to -50 °C
Cell Serial	DRC2-03788
[T1 Calibration]
Date Applied	04/03/2021 14:58:04
Slope	-0.001800291
Offset	-0.1301359
Initial Temperature	-100.6228
GUID	a1d5a6be-decd-4ae4-b22f-d560f3a78a92
[TZero Calibration]
Date Applied	03/01/2025 12:41:45
Description	From -178.795 °C to 396.200 °C at 20.000°C/min
Gas Type	Nitrogen
Pan Type	None
Source Files 1	C:\ProgramData\TA Instruments\TRIOS\Data\Tzero Cal(23).tri
Source Files 2	C:\ProgramData\TA Instruments\TRIOS\Data\Tzero Cal(24).tri
Delta T Offset	1.869383
Delta T Slope	-0.002827686
Delta T0 Offset	0.6518871
Delta T0 Slope	0.03386689
[Temperature Calibration]
Date Applied	07/01/2025 06:48:00
Description	From 106.598 °C to 186.598 °C at 10.000°C/min
Gas Type	Nitrogen
Pan Type	Aluminum Hermetic
Source Files 1	C:\ProgramData\TA Instruments\TRIOS\Data\Indium(10).tri
Measured 1	158.5387
Known 1	156.598
[Cell Constant Calibration]
Date Applied	07/01/2025 06:21:38
Description	From 106.598 °C to 186.598 °C at 10.000°C/min
Gas Type	Nitrogen
Pan Type	Aluminum Hermetic
Source Files 1	C:\ProgramData\TA Instruments\TRIOS\Data\Indium(8).tri
T4P KCell	1.071186
Onset Slope	-20.76992 mW/°C
[Direct Cp Calibration]
Date Applied	07/01/2025 08:34:40
Description	From -89.983 °C to 397.015 °C at 20.000°C/min
Gas Type	Nitrogen
Pan Type	Aluminum Hermetic
Source Files 1	C:\ProgramData\TA Instruments\TRIOS\Data\Sapphire Direct Heat Capacity(11).tri
GUID	bc2b1dd3-d0d9-41bf-ba72-b5fda717766a
Temperature	-89.98325 °C
Cp	0.9880321
Temperature	-89.00925 °C
Cp	0.9883595
Temperature	-88.03526 °C
Cp	0.9883455
Temperature	-87.06126 °C
Cp	0.9880565
Temperature	-86.08727 °C
Cp	0.9875574
Temperature	-85.11327 °C
Cp	0.9868901
Temperature	-84.13927 °C
Cp	0.9861491
Temperature	-83.16528 °C
Cp	0.9854108
Temperature	-82.19128 °C
Cp	0.9847093
Temperature	-81.21728 °C
Cp	0.984123
Temperature	-80.24328 °C
Cp	0.9836704
Temperature	-79.26929 °C
Cp	0.9834349
Temperature	-78.29529 °C
Cp	0.9833817
Temperature	-77.32129 °C
Cp	0.9835677
Temperature	-76.34729 °C
Cp	0.9839252
Temperature	-75.37329 °C
Cp	0.9844846
Temperature	-74.3993 °C
Cp	0.9852123
Temperature	-73.4253 °C
Cp	0.9860855
Temperature	-72.4513 °C
Cp	0.9870548
Temperature	-71.4773 °C
Cp	0.9881113
Temperature	-70.50331 °C
Cp	0.9892243
Temperature	-69.52931 °C
Cp	0.9903587
Temperature	-68.55531 °C
Cp	0.9915038
Temperature	-67.58131 °C
Cp	0.9926346
Temperature	-66.60732 °C
Cp	0.993748
Temperature	-65.63332 °C
Cp	0.994836
Temperature	-64.65932 °C
Cp	0.9959027
Temperature	-63.68533 °C
Cp	0.9969317
Temperature	-62.71133 °C
Cp	0.997943
Temperature	-61.73733 °C
Cp	0.9989527
Temperature	-60.76334 °C
Cp	0.9999582
Temperature	-59.78934 °C
Cp	1.000969
Temperature	-58.81534 °C
Cp	1.00194
Temperature	-57.84134 °C
Cp	1.002997
Temperature	-56.86735 °C
Cp	1.00403
Temperature	-55.89335 °C
Cp	1.005069
Temperature	-54.91935 °C
Cp	1.006104
Temperature	-53.94535 °C
Cp	1.00713
Temperature	-52.97136 °C
Cp	1.008209
Temperature	-51.99736 °C
Cp	1.009185
Temperature	-51.02336 °C
Cp	1.010177
Temperature	-50.04937 °C
Cp	1.011162
Temperature	-49.07537 °C
Cp	1.012141
Temperature	-48.10137 °C
Cp	1.01308
Temperature	-47.12737 °C
Cp	1.013991
Temperature	-46.15338 °C
Cp	1.014858
Temperature	-45.17938 °C
Cp	1.015703
Temperature	-44.20538 °C
Cp	1.016499
Temperature	-43.23138 °C
Cp	1.017257
Temperature	-42.25739 °C
Cp	1.017991
Temperature	-41.28339 °C
Cp	1.018705
Temperature	-40.30939 °C
Cp	1.019413
Temperature	-39.3354 °C
Cp	1.020126
Temperature	-38.3614 °C
Cp	1.020855
Temperature	-37.3874 °C
Cp	1.021604
Temperature	-36.4134 °C
Cp	1.022382
Temperature	-35.43941 °C
Cp	1.023185
Temperature	-34.46541 °C
Cp	1.024018
Temperature	-33.49141 °C
Cp	1.024865
Temperature	-32.51741 °C
Cp	1.025734
Temperature	-31.54342 °C
Cp	1.026615
Temperature	-30.56942 °C
Cp	1.027499
Temperature	-29.59542 °C
Cp	1.028374
Temperature	-28.62143 °C
Cp	1.029232
Temperature	-27.64743 °C
Cp	1.030081
Temperature	-26.67343 °C
Cp	1.030892
Temperature	-25.69943 °C
Cp	1.031667
Temperature	-24.72544 °C
Cp	1.032406
Temperature	-23.75144 °C
Cp	1.03311
Temperature	-22.77744 °C
Cp	1.033786
Temperature	-21.80344 °C
Cp	1.034412
Temperature	-20.82945 °C
Cp	1.035019
Temperature	-19.85545 °C
Cp	1.035599
Temperature	-18.88145 °C
Cp	1.036155
Temperature	-17.90746 °C
Cp	1.036695
Temperature	-16.93346 °C
Cp	1.037207
Temperature	-15.95946 °C
Cp	1.037712
Temperature	-14.98546 °C
Cp	1.038202
Temperature	-14.01147 °C
Cp	1.038666
Temperature	-13.03747 °C
Cp	1.039103
Temperature	-12.06347 °C
Cp	1.039518
Temperature	-11.08947 °C
Cp	1.039909
Temperature	-10.11548 °C
Cp	1.040284
Temperature	-9.14148 °C
Cp	1.040614
Temperature	-8.167483 °C
Cp	1.040915
Temperature	-7.193486 °C
Cp	1.041192
Temperature	-6.219488 °C
Cp	1.041427
Temperature	-5.245491 °C
Cp	1.041627
Temperature	-4.271494 °C
Cp	1.041773
Temperature	-3.297497 °C
Cp	1.041891
Temperature	-2.323499 °C
Cp	1.041951
Temperature	-1.349502 °C
Cp	1.041963
Temperature	-0.3755048 °C
Cp	1.041932
Temperature	0.5984925 °C
Cp	1.041862
Temperature	1.57249 °C
Cp	1.04176
Temperature	2.546487 °C
Cp	1.04162
Temperature	3.520484 °C
Cp	1.041463
Temperature	4.494482 °C
Cp	1.041297
Temperature	5.468479 °C
Cp	1.041124
Temperature	6.442476 °C
Cp	1.040949
Temperature	7.416473 °C
Cp	1.04077
Temperature	8.390471 °C
Cp	1.040596
Temperature	9.364468 °C
Cp	1.04043
Temperature	10.33846 °C
Cp	1.040276
Temperature	11.31246 °C
Cp	1.040137
Temperature	12.28646 °C
Cp	1.040014
Temperature	13.26046 °C
Cp	1.039915
Temperature	14.23445 °C
Cp	1.03984
Temperature	15.20845 °C
Cp	1.039792
Temperature	16.18245 °C
Cp	1.039777
Temperature	17.15645 °C
Cp	1.03979
Temperature	18.13044 °C
Cp	1.039834
Temperature	19.10444 °C
Cp	1.039903
Temperature	20.07844 °C
Cp	1.040019
Temperature	21.05243 °C
Cp	1.040159
Temperature	22.02643 °C
Cp	1.040318
Temperature	23.00043 °C
Cp	1.040496
Temperature	23.97443 °C
Cp	1.040695
Temperature	24.94842 °C
Cp	1.040908
Temperature	25.92242 °C
Cp	1.041143
Temperature	26.89642 °C
Cp	1.041371
Temperature	27.87042 °C
Cp	1.04161
Temperature	28.84441 °C
Cp	1.041855
Temperature	29.81841 °C
Cp	1.042094
Temperature	30.79241 °C
Cp	1.042325
Temperature	31.76641 °C
Cp	1.042534
Temperature	32.7404 °C
Cp	1.04274
Temperature	33.7144 °C
Cp	1.042917
Temperature	34.6884 °C
Cp	1.043064
Temperature	35.6624 °C
Cp	1.04319
Temperature	36.63639 °C
Cp	1.043295
Temperature	37.61039 °C
Cp	1.043386
Temperature	38.58438 °C
Cp	1.043453
Temperature	39.55838 °C
Cp	1.04351
Temperature	40.53238 °C
Cp	1.043562
Temperature	41.50638 °C
Cp	1.043611
Temperature	42.48037 °C
Cp	1.043655
Temperature	43.45437 °C
Cp	1.043698
Temperature	44.42837 °C
Cp	1.043742
Temperature	45.40237 °C
Cp	1.043786
Temperature	46.37637 °C
Cp	1.04383
Temperature	47.35036 °C
Cp	1.043871
Temperature	48.32436 °C
Cp	1.043918
Temperature	49.29836 °C
Cp	1.043969
Temperature	50.27235 °C
Cp	1.044022
Temperature	51.24635 °C
Cp	1.044086
Temperature	52.22035 °C
Cp	1.044155
Temperature	53.19434 °C
Cp	1.044236
Temperature	54.16834 °C
Cp	1.044331
Temperature	55.14234 °C
Cp	1.04443
Temperature	56.11634 °C
Cp	1.04456
Temperature	57.09034 °C
Cp	1.044703
Temperature	58.06433 °C
Cp	1.044864
Temperature	59.03833 °C
Cp	1.045041
Temperature	60.01233 °C
Cp	1.045232
Temperature	60.98632 °C
Cp	1.045442
Temperature	61.96032 °C
Cp	1.045673
Temperature	62.93432 °C
Cp	1.045911
Temperature	63.90831 °C
Cp	1.046162
Temperature	64.88231 °C
Cp	1.046425
Temperature	65.85631 °C
Cp	1.04669
Temperature	66.83031 °C
Cp	1.046952
Temperature	67.80431 °C
Cp	1.047203
Temperature	68.77831 °C
Cp	1.047453
Temperature	69.7523 °C
Cp	1.047677
Temperature	70.7263 °C
Cp	1.047882
Temperature	71.70029 °C
Cp	1.048065
Temperature	72.67429 °C
Cp	1.048226
Temperature	73.64828 °C
Cp	1.048375
Temperature	74.62228 °C
Cp	1.048498
Temperature	75.59628 °C
Cp	1.04861
Temperature	76.57028 °C
Cp	1.048713
Temperature	77.54427 °C
Cp	1.048811
Temperature	78.51827 °C
Cp	1.048901
Temperature	79.49227 °C
Cp	1.048978
Temperature	80.46627 °C
Cp	1.049068
Temperature	81.44027 °C
Cp	1.049148
Temperature	82.41426 °C
Cp	1.04922
Temperature	83.38826 °C
Cp	1.049288
Temperature	84.36226 °C
Cp	1.049353
Temperature	85.33626 °C
Cp	1.049435
Temperature	86.31025 °C
Cp	1.049486
Temperature	87.28425 °C
Cp	1.049549
Temperature	88.25825 °C
Cp	1.049615
Temperature	89.23225 °C
Cp	1.049683
Temperature	90.20624 °C
Cp	1.049742
Temperature	91.18024 °C
Cp	1.04977
Temperature	92.15424 °C
Cp	1.04982
Temperature	93.12823 °C
Cp	1.049839
Temperature	94.10223 °C
Cp	1.049829
Temperature	95.07623 °C
Cp	1.049792
Temperature	96.05022 °C
Cp	1.049731
Temperature	97.02422 °C
Cp	1.049673
Temperature	97.99822 °C
Cp	1.049564
Temperature	98.97221 °C
Cp	1.049451
Temperature	99.94621 °C
Cp	1.049339
Temperature	100.9202 °C
Cp	1.049223
Temperature	101.8942 °C
Cp	1.049111
Temperature	102.8682 °C
Cp	1.048998
Temperature	103.8422 °C
Cp	1.048886
Temperature	104.8162 °C
Cp	1.048782
Temperature	105.7902 °C
Cp	1.048679
Temperature	106.7642 °C
Cp	1.048577
Temperature	107.7382 °C
Cp	1.048481
Temperature	108.7122 °C
Cp	1.048391
Temperature	109.6862 °C
Cp	1.048309
Temperature	110.6602 °C
Cp	1.048232
Temperature	111.6342 °C
Cp	1.04816
Temperature	112.6082 °C
Cp	1.048096
Temperature	113.5822 °C
Cp	1.048038
Temperature	114.5562 °C
Cp	1.047984
Temperature	115.5302 °C
Cp	1.047932
Temperature	116.5042 °C
Cp	1.047888
Temperature	117.4782 °C
Cp	1.047844
Temperature	118.4522 °C
Cp	1.047801
Temperature	119.4262 °C
Cp	1.047756
Temperature	120.4002 °C
Cp	1.047715
Temperature	121.3742 °C
Cp	1.047678
Temperature	122.3482 °C
Cp	1.047638
Temperature	123.3222 °C
Cp	1.047605
Temperature	124.2961 °C
Cp	1.047578
Temperature	125.2701 °C
Cp	1.047555
Temperature	126.2441 °C
Cp	1.047539
Temperature	127.2181 °C
Cp	1.047525
Temperature	128.1921 °C
Cp	1.047524
Temperature	129.1661 °C
Cp	1.047527
Temperature	130.1401 °C
Cp	1.047536
Temperature	131.1141 °C
Cp	1.047554
Temperature	132.0881 °C
Cp	1.047582
Temperature	133.0621 °C
Cp	1.047624
Temperature	134.0361 °C
Cp	1.047662
Temperature	135.0101 °C
Cp	1.047714
Temperature	135.9841 °C
Cp	1.047779
Temperature	136.9581 °C
Cp	1.047853
Temperature	137.9321 °C
Cp	1.047933
Temperature	138.9061 °C
Cp	1.048018
Temperature	139.8801 °C
Cp	1.048097
Temperature	140.8541 °C
Cp	1.048188
Temperature	141.8281 °C
Cp	1.048267
Temperature	142.8021 °C
Cp	1.048337
Temperature	143.7761 °C
Cp	1.048398
Temperature	144.7501 °C
Cp	1.048449
Temperature	145.7241 °C
Cp	1.048503
Temperature	146.6981 °C
Cp	1.048532
Temperature	147.6721 °C
Cp	1.04856
Temperature	148.6461 °C
Cp	1.048587
Temperature	149.6201 °C
Cp	1.04861
Temperature	150.5941 °C
Cp	1.048628
Temperature	151.5681 °C
Cp	1.048627
Temperature	152.5421 °C
Cp	1.048642
Temperature	153.5161 °C
Cp	1.048646
Temperature	154.4901 °C
Cp	1.048642
Temperature	155.4641 °C
Cp	1.048638
Temperature	156.438 °C
Cp	1.048641
Temperature	157.412 °C
Cp	1.048673
Temperature	158.386 °C
Cp	1.048706
Temperature	159.36 °C
Cp	1.048776
Temperature	160.334 °C
Cp	1.048889
Temperature	161.308 °C
Cp	1.049047
Temperature	162.282 °C
Cp	1.049254
Temperature	163.256 °C
Cp	1.049495
Temperature	164.23 °C
Cp	1.049811
Temperature	165.204 °C
Cp	1.050172
Temperature	166.178 °C
Cp	1.050582
Temperature	167.152 °C
Cp	1.051038
Temperature	168.126 °C
Cp	1.051542
Temperature	169.1 °C
Cp	1.052114
Temperature	170.074 °C
Cp	1.052695
Temperature	171.048 °C
Cp	1.053323
Temperature	172.022 °C
Cp	1.053989
Temperature	172.996 °C
Cp	1.05468
Temperature	173.97 °C
Cp	1.055383
Temperature	174.944 °C
Cp	1.056084
Temperature	175.918 °C
Cp	1.056758
Temperature	176.892 °C
Cp	1.057421
Temperature	177.866 °C
Cp	1.058033
Temperature	178.84 °C
Cp	1.058585
Temperature	179.814 °C
Cp	1.059071
Temperature	180.788 °C
Cp	1.059486
Temperature	181.762 °C
Cp	1.059844
Temperature	182.736 °C
Cp	1.060098
Temperature	183.71 °C
Cp	1.060287
Temperature	184.684 °C
Cp	1.06041
Temperature	185.658 °C
Cp	1.060463
Temperature	186.632 °C
Cp	1.060444
Temperature	187.606 °C
Cp	1.060339
Temperature	188.58 °C
Cp	1.060207
Temperature	189.554 °C
Cp	1.060006
Temperature	190.528 °C
Cp	1.059754
Temperature	191.502 °C
Cp	1.059464
Temperature	192.476 °C
Cp	1.059152
Temperature	193.45 °C
Cp	1.05885
Temperature	194.424 °C
Cp	1.058521
Temperature	195.3979 °C
Cp	1.05822
Temperature	196.3719 °C
Cp	1.057951
Temperature	197.3459 °C
Cp	1.057719
Temperature	198.3199 °C
Cp	1.057524
Temperature	199.2939 °C
Cp	1.057347
Temperature	200.2679 °C
Cp	1.057229
Temperature	201.2419 °C
Cp	1.05713
Temperature	202.2159 °C
Cp	1.05705
Temperature	203.1899 °C
Cp	1.056984
Temperature	204.1639 °C
Cp	1.05693
Temperature	205.1379 °C
Cp	1.0569
Temperature	206.1119 °C
Cp	1.05685
Temperature	207.0859 °C
Cp	1.056808
Temperature	208.0599 °C
Cp	1.05677
Temperature	209.0339 °C
Cp	1.05673
Temperature	210.0079 °C
Cp	1.056685
Temperature	210.9819 °C
Cp	1.056633
Temperature	211.9559 °C
Cp	1.056566
Temperature	212.9299 °C
Cp	1.056501
Temperature	213.9039 °C
Cp	1.056424
Temperature	214.8779 °C
Cp	1.056341
Temperature	215.8519 °C
Cp	1.056252
Temperature	216.8259 °C
Cp	1.056168
Temperature	217.7999 °C
Cp	1.0561
Temperature	218.7739 °C
Cp	1.056026
Temperature	219.7479 °C
Cp	1.055973
Temperature	220.7219 °C
Cp	1.055941
Temperature	221.6959 °C
Cp	1.055926
Temperature	222.6699 °C
Cp	1.055924
Temperature	223.6439 °C
Cp	1.055919
Temperature	224.6179 °C
Cp	1.055941
Temperature	225.5919 °C
Cp	1.055954
Temperature	226.5659 °C
Cp	1.055958
Temperature	227.5399 °C
Cp	1.055954
Temperature	228.5139 °C
Cp	1.055943
Temperature	229.4879 °C
Cp	1.055938
Temperature	230.4619 °C
Cp	1.055901
Temperature	231.4359 °C
Cp	1.055866
Temperature	232.4098 °C
Cp	1.055832
Temperature	233.3838 °C
Cp	1.055797
Temperature	234.3578 °C
Cp	1.055757
Temperature	235.3318 °C
Cp	1.055695
Temperature	236.3058 °C
Cp	1.055658
Temperature	237.2798 °C
Cp	1.055607
Temperature	238.2538 °C
Cp	1.055547
Temperature	239.2278 °C
Cp	1.055481
Temperature	240.2018 °C
Cp	1.055414
Temperature	241.1758 °C
Cp	1.055372
Temperature	242.1498 °C
Cp	1.055303
Temperature	243.1238 °C
Cp	1.055254
Temperature	244.0978 °C
Cp	1.055227
Temperature	245.0718 °C
Cp	1.055215
Temperature	246.0458 °C
Cp	1.055219
Temperature	247.0198 °C
Cp	1.055213
Temperature	247.9938 °C
Cp	1.055252
Temperature	248.9678 °C
Cp	1.055289
Temperature	249.9418 °C
Cp	1.055323
Temperature	250.9158 °C
Cp	1.055358
Temperature	251.8898 °C
Cp	1.055391
Temperature	252.8638 °C
Cp	1.055427
Temperature	253.8378 °C
Cp	1.05547
Temperature	254.8118 °C
Cp	1.055506
Temperature	255.7858 °C
Cp	1.055552
Temperature	256.7598 °C
Cp	1.055605
Temperature	257.7338 °C
Cp	1.055662
Temperature	258.7078 °C
Cp	1.055723
Temperature	259.6818 °C
Cp	1.055782
Temperature	260.6558 °C
Cp	1.055847
Temperature	261.6298 °C
Cp	1.055909
Temperature	262.6038 °C
Cp	1.055965
Temperature	263.5778 °C
Cp	1.05602
Temperature	264.5518 °C
Cp	1.056073
Temperature	265.5258 °C
Cp	1.056125
Temperature	266.4998 °C
Cp	1.056176
Temperature	267.4738 °C
Cp	1.05623
Temperature	268.4478 °C
Cp	1.056288
Temperature	269.4218 °C
Cp	1.056349
Temperature	270.3957 °C
Cp	1.056416
Temperature	271.3697 °C
Cp	1.056491
Temperature	272.3437 °C
Cp	1.056571
Temperature	273.3177 °C
Cp	1.056658
Temperature	274.2917 °C
Cp	1.05675
Temperature	275.2657 °C
Cp	1.056848
Temperature	276.2397 °C
Cp	1.056947
Temperature	277.2137 °C
Cp	1.057042
Temperature	278.1877 °C
Cp	1.057142
Temperature	279.1617 °C
Cp	1.057233
Temperature	280.1357 °C
Cp	1.057313
Temperature	281.1097 °C
Cp	1.057381
Temperature	282.0837 °C
Cp	1.057435
Temperature	283.0577 °C
Cp	1.057481
Temperature	284.0317 °C
Cp	1.057495
Temperature	285.0057 °C
Cp	1.057498
Temperature	285.9797 °C
Cp	1.057486
Temperature	286.9537 °C
Cp	1.057462
Temperature	287.9277 °C
Cp	1.057423
Temperature	288.9017 °C
Cp	1.057373
Temperature	289.8757 °C
Cp	1.05731
Temperature	290.8497 °C
Cp	1.057244
Temperature	291.8237 °C
Cp	1.057169
Temperature	292.7977 °C
Cp	1.057092
Temperature	293.7717 °C
Cp	1.057015
Temperature	294.7457 °C
Cp	1.05694
Temperature	295.7197 °C
Cp	1.056872
Temperature	296.6937 °C
Cp	1.056808
Temperature	297.6677 °C
Cp	1.056752
Temperature	298.6417 °C
Cp	1.056704
Temperature	299.6157 °C
Cp	1.056662
Temperature	300.5897 °C
Cp	1.056626
Temperature	301.5637 °C
Cp	1.05659
Temperature	302.5377 °C
Cp	1.056563
Temperature	303.5117 °C
Cp	1.056535
Temperature	304.4856 °C
Cp	1.056507
Temperature	305.4596 °C
Cp	1.05648
Temperature	306.4336 °C
Cp	1.056456
Temperature	307.4076 °C
Cp	1.056444
Temperature	308.3816 °C
Cp	1.056429
Temperature	309.3556 °C
Cp	1.056431
Temperature	310.3296 °C
Cp	1.056452
Temperature	311.3036 °C
Cp	1.056492
Temperature	312.2776 °C
Cp	1.056555
Temperature	313.2516 °C
Cp	1.056631
Temperature	314.2256 °C
Cp	1.056748
Temperature	315.1996 °C
Cp	1.056883
Temperature	316.1736 °C
Cp	1.057038
Temperature	317.1476 °C
Cp	1.057212
Temperature	318.1216 °C
Cp	1.057405
Temperature	319.0956 °C
Cp	1.057631
Temperature	320.0696 °C
Cp	1.057845
Temperature	321.0436 °C
Cp	1.058079
Temperature	322.0176 °C
Cp	1.058326
Temperature	322.9916 °C
Cp	1.058582
Temperature	323.9656 °C
Cp	1.058841
Temperature	324.9396 °C
Cp	1.059099
Temperature	325.9136 °C
Cp	1.059348
Temperature	326.8876 °C
Cp	1.059604
Temperature	327.8616 °C
Cp	1.05985
Temperature	328.8356 °C
Cp	1.060092
Temperature	329.8096 °C
Cp	1.060333
Temperature	330.7836 °C
Cp	1.060579
Temperature	331.7576 °C
Cp	1.060841
Temperature	332.7316 °C
Cp	1.061109
Temperature	333.7056 °C
Cp	1.061398
Temperature	334.6796 °C
Cp	1.061709
Temperature	335.6536 °C
Cp	1.062038
Temperature	336.6276 °C
Cp	1.062384
Temperature	337.6016 °C
Cp	1.062742
Temperature	338.5755 °C
Cp	1.063104
Temperature	339.5495 °C
Cp	1.063464
Temperature	340.5235 °C
Cp	1.063814
Temperature	341.4975 °C
Cp	1.064146
Temperature	342.4715 °C
Cp	1.064453
Temperature	343.4455 °C
Cp	1.064728
Temperature	344.4195 °C
Cp	1.06497
Temperature	345.3935 °C
Cp	1.065176
Temperature	346.3675 °C
Cp	1.065346
Temperature	347.3415 °C
Cp	1.065484
Temperature	348.3155 °C
Cp	1.065596
Temperature	349.2895 °C
Cp	1.065687
Temperature	350.2635 °C
Cp	1.065775
Temperature	351.2375 °C
Cp	1.065862
Temperature	352.2115 °C
Cp	1.06596
Temperature	353.1855 °C
Cp	1.066075
Temperature	354.1595 °C
Cp	1.066217
Temperature	355.1335 °C
Cp	1.066395
Temperature	356.1075 °C
Cp	1.06659
Temperature	357.0815 °C
Cp	1.066817
Temperature	358.0555 °C
Cp	1.067067
Temperature	359.0295 °C
Cp	1.067329
Temperature	360.0035 °C
Cp	1.067591
Temperature	360.9775 °C
Cp	1.067838
Temperature	361.9515 °C
Cp	1.068055
Temperature	362.9255 °C
Cp	1.068232
Temperature	363.8995 °C
Cp	1.068357
Temperature	364.8735 °C
Cp	1.068423
Temperature	365.8475 °C
Cp	1.068431
Temperature	366.8215 °C
Cp	1.068385
Temperature	367.7955 °C
Cp	1.068293
Temperature	368.7695 °C
Cp	1.068177
Temperature	369.7435 °C
Cp	1.068051
Temperature	370.7175 °C
Cp	1.067937
Temperature	371.6914 °C
Cp	1.067864
Temperature	372.6654 °C
Cp	1.067851
Temperature	373.6394 °C
Cp	1.067924
Temperature	374.6134 °C
Cp	1.068083
Temperature	375.5874 °C
Cp	1.068344
Temperature	376.5614 °C
Cp	1.068699
Temperature	377.5354 °C
Cp	1.069131
Temperature	378.5094 °C
Cp	1.069605
Temperature	379.4834 °C
Cp	1.070071
Temperature	380.4574 °C
Cp	1.070487
Temperature	381.4314 °C
Cp	1.07077
Temperature	382.4054 °C
Cp	1.070846
Temperature	383.3794 °C
Cp	1.070635
Temperature	384.3534 °C
Cp	1.070055
Temperature	385.3274 °C
Cp	1.069033
Temperature	386.3014 °C
Cp	1.067489
Temperature	387.2754 °C
Cp	1.065378
Temperature	388.2494 °C
Cp	1.062665
Temperature	389.2234 °C
Cp	1.059324
Temperature	390.1974 °C
Cp	1.055366
Temperature	391.1714 °C
Cp	1.050821
Temperature	392.1454 °C
Cp	1.045742
Temperature	393.1194 °C
Cp	1.040203
Temperature	394.0934 °C
Cp	1.034295
Temperature	395.0674 °C
Cp	1.028124
Temperature	396.0414 °C
Cp	1.021801
[Rev Cp Calibration]
Date Applied	07/01/2025 13:18:35
Description	From -90.000 °C to 391.202 °C at 2.000°C/min
Gas Type	Nitrogen
Pan Type	Aluminum Hermetic
Source Files 1	C:\ProgramData\TA Instruments\TRIOS\Data\Reverse Heat Capacity Calibration(8).tri
GUID	2f9866b8-ce4e-42f5-95a1-c21443fc3171
Temperature	-89.99985 °C
Cp	1.026385
Temperature	-89.03745 °C
Cp	1.030641
Temperature	-88.07504 °C
Cp	1.034621
Temperature	-87.11264 °C
Cp	1.038235
Temperature	-86.15024 °C
Cp	1.041454
Temperature	-85.18784 °C
Cp	1.044296
Temperature	-84.22543 °C
Cp	1.04679
Temperature	-83.26302 °C
Cp	1.048951
Temperature	-82.30062 °C
Cp	1.050818
Temperature	-81.33822 °C
Cp	1.052404
Temperature	-80.37582 °C
Cp	1.053789
Temperature	-79.41341 °C
Cp	1.055011
Temperature	-78.45101 °C
Cp	1.056107
Temperature	-77.48861 °C
Cp	1.05712
Temperature	-76.52621 °C
Cp	1.058067
Temperature	-75.5638 °C
Cp	1.059033
Temperature	-74.6014 °C
Cp	1.060008
Temperature	-73.639 °C
Cp	1.06102
Temperature	-72.67659 °C
Cp	1.062091
Temperature	-71.71419 °C
Cp	1.06324
Temperature	-70.75179 °C
Cp	1.064487
Temperature	-69.78938 °C
Cp	1.065824
Temperature	-68.82698 °C
Cp	1.067263
Temperature	-67.86458 °C
Cp	1.068802
Temperature	-66.90218 °C
Cp	1.070434
Temperature	-65.93977 °C
Cp	1.07215
Temperature	-64.97737 °C
Cp	1.073961
Temperature	-64.01497 °C
Cp	1.07579
Temperature	-63.05256 °C
Cp	1.077675
Temperature	-62.09016 °C
Cp	1.0796
Temperature	-61.12776 °C
Cp	1.081549
Temperature	-60.16536 °C
Cp	1.083507
Temperature	-59.20295 °C
Cp	1.085459
Temperature	-58.24055 °C
Cp	1.087374
Temperature	-57.27814 °C
Cp	1.089301
Temperature	-56.31574 °C
Cp	1.091179
Temperature	-55.35334 °C
Cp	1.09301
Temperature	-54.39093 °C
Cp	1.094799
Temperature	-53.42853 °C
Cp	1.09655
Temperature	-52.46613 °C
Cp	1.098302
Temperature	-51.50373 °C
Cp	1.099969
Temperature	-50.54132 °C
Cp	1.101634
Temperature	-49.57892 °C
Cp	1.103291
Temperature	-48.61652 °C
Cp	1.104934
Temperature	-47.65411 °C
Cp	1.106558
Temperature	-46.69171 °C
Cp	1.108129
Temperature	-45.72931 °C
Cp	1.109722
Temperature	-44.76691 °C
Cp	1.111267
Temperature	-43.8045 °C
Cp	1.112769
Temperature	-42.8421 °C
Cp	1.11423
Temperature	-41.8797 °C
Cp	1.115656
Temperature	-40.91729 °C
Cp	1.117056
Temperature	-39.95489 °C
Cp	1.118417
Temperature	-38.99249 °C
Cp	1.119757
Temperature	-38.03008 °C
Cp	1.121077
Temperature	-37.06768 °C
Cp	1.12238
Temperature	-36.10528 °C
Cp	1.123667
Temperature	-35.14288 °C
Cp	1.124939
Temperature	-34.18047 °C
Cp	1.126202
Temperature	-33.21807 °C
Cp	1.127441
Temperature	-32.25566 °C
Cp	1.128669
Temperature	-31.29326 °C
Cp	1.129881
Temperature	-30.33086 °C
Cp	1.131073
Temperature	-29.36846 °C
Cp	1.13224
Temperature	-28.40605 °C
Cp	1.133372
Temperature	-27.44365 °C
Cp	1.134479
Temperature	-26.48125 °C
Cp	1.135545
Temperature	-25.51884 °C
Cp	1.136566
Temperature	-24.55644 °C
Cp	1.13754
Temperature	-23.59404 °C
Cp	1.138466
Temperature	-22.63164 °C
Cp	1.139347
Temperature	-21.66923 °C
Cp	1.140172
Temperature	-20.70683 °C
Cp	1.140951
Temperature	-19.74443 °C
Cp	1.141683
Temperature	-18.78202 °C
Cp	1.14237
Temperature	-17.81962 °C
Cp	1.143013
Temperature	-16.85722 °C
Cp	1.143601
Temperature	-15.89482 °C
Cp	1.14417
Temperature	-14.93241 °C
Cp	1.144696
Temperature	-13.97001 °C
Cp	1.145184
Temperature	-13.00761 °C
Cp	1.145641
Temperature	-12.0452 °C
Cp	1.14607
Temperature	-11.0828 °C
Cp	1.146477
Temperature	-10.1204 °C
Cp	1.146876
Temperature	-9.157994 °C
Cp	1.147244
Temperature	-8.195591 °C
Cp	1.147609
Temperature	-7.233188 °C
Cp	1.147968
Temperature	-6.270785 °C
Cp	1.148321
Temperature	-5.308382 °C
Cp	1.148663
Temperature	-4.345979 °C
Cp	1.148978
Temperature	-3.383576 °C
Cp	1.149303
Temperature	-2.421173 °C
Cp	1.1496
Temperature	-1.45877 °C
Cp	1.149872
Temperature	-0.496367 °C
Cp	1.150121
Temperature	0.466036 °C
Cp	1.15035
Temperature	1.428439 °C
Cp	1.150573
Temperature	2.390842 °C
Cp	1.150761
Temperature	3.353245 °C
Cp	1.150942
Temperature	4.315648 °C
Cp	1.151115
Temperature	5.278051 °C
Cp	1.151279
Temperature	6.240454 °C
Cp	1.151435
Temperature	7.202857 °C
Cp	1.151582
Temperature	8.16526 °C
Cp	1.151718
Temperature	9.127664 °C
Cp	1.151844
Temperature	10.09007 °C
Cp	1.151962
Temperature	11.05247 °C
Cp	1.152071
Temperature	12.01487 °C
Cp	1.152174
Temperature	12.97727 °C
Cp	1.15227
Temperature	13.93968 °C
Cp	1.152361
Temperature	14.90208 °C
Cp	1.15245
Temperature	15.86448 °C
Cp	1.152536
Temperature	16.82689 °C
Cp	1.152622
Temperature	17.78929 °C
Cp	1.152709
Temperature	18.75169 °C
Cp	1.152799
Temperature	19.7141 °C
Cp	1.152883
Temperature	20.6765 °C
Cp	1.152982
Temperature	21.6389 °C
Cp	1.15308
Temperature	22.60131 °C
Cp	1.153177
Temperature	23.56371 °C
Cp	1.153276
Temperature	24.52611 °C
Cp	1.153377
Temperature	25.48851 °C
Cp	1.153497
Temperature	26.45092 °C
Cp	1.153591
Temperature	27.41332 °C
Cp	1.153695
Temperature	28.37572 °C
Cp	1.153804
Temperature	29.33813 °C
Cp	1.153913
Temperature	30.30053 °C
Cp	1.154015
Temperature	31.26293 °C
Cp	1.154087
Temperature	32.22533 °C
Cp	1.154174
Temperature	33.18774 °C
Cp	1.154232
Temperature	34.15014 °C
Cp	1.154263
Temperature	35.11255 °C
Cp	1.154269
Temperature	36.07495 °C
Cp	1.154254
Temperature	37.03735 °C
Cp	1.154231
Temperature	37.99975 °C
Cp	1.154176
Temperature	38.96216 °C
Cp	1.154116
Temperature	39.92456 °C
Cp	1.154055
Temperature	40.88696 °C
Cp	1.153996
Temperature	41.84937 °C
Cp	1.153939
Temperature	42.81177 °C
Cp	1.153889
Temperature	43.77417 °C
Cp	1.153844
Temperature	44.73658 °C
Cp	1.153811
Temperature	45.69898 °C
Cp	1.153786
Temperature	46.66138 °C
Cp	1.153769
Temperature	47.62378 °C
Cp	1.153761
Temperature	48.58619 °C
Cp	1.153762
Temperature	49.54859 °C
Cp	1.153771
Temperature	50.51099 °C
Cp	1.153783
Temperature	51.4734 °C
Cp	1.1538
Temperature	52.4358 °C
Cp	1.153821
Temperature	53.3982 °C
Cp	1.153843
Temperature	54.3606 °C
Cp	1.153865
Temperature	55.32301 °C
Cp	1.153879
Temperature	56.28541 °C
Cp	1.153902
Temperature	57.24781 °C
Cp	1.15392
Temperature	58.21022 °C
Cp	1.153935
Temperature	59.17262 °C
Cp	1.15395
Temperature	60.13502 °C
Cp	1.153968
Temperature	61.09743 °C
Cp	1.154004
Temperature	62.05983 °C
Cp	1.154027
Temperature	63.02223 °C
Cp	1.154066
Temperature	63.98463 °C
Cp	1.154123
Temperature	64.94704 °C
Cp	1.154196
Temperature	65.90944 °C
Cp	1.154283
Temperature	66.87184 °C
Cp	1.154383
Temperature	67.83424 °C
Cp	1.154487
Temperature	68.79665 °C
Cp	1.15461
Temperature	69.75906 °C
Cp	1.154733
Temperature	70.72146 °C
Cp	1.154854
Temperature	71.68386 °C
Cp	1.154973
Temperature	72.64626 °C
Cp	1.155089
Temperature	73.60867 °C
Cp	1.15521
Temperature	74.57107 °C
Cp	1.15531
Temperature	75.53347 °C
Cp	1.155409
Temperature	76.49587 °C
Cp	1.155506
Temperature	77.45827 °C
Cp	1.155596
Temperature	78.42068 °C
Cp	1.155678
Temperature	79.38308 °C
Cp	1.155733
Temperature	80.34549 °C
Cp	1.155807
Temperature	81.30789 °C
Cp	1.155861
Temperature	82.27029 °C
Cp	1.155901
Temperature	83.2327 °C
Cp	1.155933
Temperature	84.1951 °C
Cp	1.155961
Temperature	85.1575 °C
Cp	1.156017
Temperature	86.1199 °C
Cp	1.156039
Temperature	87.08231 °C
Cp	1.156086
Temperature	88.04471 °C
Cp	1.156157
Temperature	89.00711 °C
Cp	1.156251
Temperature	89.96951 °C
Cp	1.156367
Temperature	90.93192 °C
Cp	1.156501
Temperature	91.89433 °C
Cp	1.156642
Temperature	92.85673 °C
Cp	1.156814
Temperature	93.81913 °C
Cp	1.156988
Temperature	94.78153 °C
Cp	1.157165
Temperature	95.74393 °C
Cp	1.157348
Temperature	96.70634 °C
Cp	1.157536
Temperature	97.66874 °C
Cp	1.15774
Temperature	98.63114 °C
Cp	1.157933
Temperature	99.59354 °C
Cp	1.158139
Temperature	100.5559 °C
Cp	1.158354
Temperature	101.5184 °C
Cp	1.158574
Temperature	102.4808 °C
Cp	1.158796
Temperature	103.4432 °C
Cp	1.15901
Temperature	104.4056 °C
Cp	1.159229
Temperature	105.368 °C
Cp	1.159435
Temperature	106.3304 °C
Cp	1.159626
Temperature	107.2928 °C
Cp	1.159803
Temperature	108.2552 °C
Cp	1.159964
Temperature	109.2176 °C
Cp	1.160111
Temperature	110.18 °C
Cp	1.160234
Temperature	111.1424 °C
Cp	1.160342
Temperature	112.1048 °C
Cp	1.160432
Temperature	113.0672 °C
Cp	1.160504
Temperature	114.0296 °C
Cp	1.160558
Temperature	114.992 °C
Cp	1.160594
Temperature	115.9544 °C
Cp	1.16061
Temperature	116.9168 °C
Cp	1.160614
Temperature	117.8792 °C
Cp	1.160601
Temperature	118.8416 °C
Cp	1.160574
Temperature	119.804 °C
Cp	1.160534
Temperature	120.7664 °C
Cp	1.160485
Temperature	121.7288 °C
Cp	1.160433
Temperature	122.6912 °C
Cp	1.160372
Temperature	123.6536 °C
Cp	1.160313
Temperature	124.616 °C
Cp	1.160255
Temperature	125.5784 °C
Cp	1.160201
Temperature	126.5408 °C
Cp	1.16015
Temperature	127.5032 °C
Cp	1.160101
Temperature	128.4656 °C
Cp	1.160059
Temperature	129.428 °C
Cp	1.16002
Temperature	130.3904 °C
Cp	1.159983
Temperature	131.3528 °C
Cp	1.159948
Temperature	132.3152 °C
Cp	1.159916
Temperature	133.2776 °C
Cp	1.159893
Temperature	134.2401 °C
Cp	1.15986
Temperature	135.2025 °C
Cp	1.159833
Temperature	136.1649 °C
Cp	1.15981
Temperature	137.1273 °C
Cp	1.159789
Temperature	138.0897 °C
Cp	1.159769
Temperature	139.0521 °C
Cp	1.15973
Temperature	140.0145 °C
Cp	1.159723
Temperature	140.9769 °C
Cp	1.159706
Temperature	141.9393 °C
Cp	1.159682
Temperature	142.9017 °C
Cp	1.159653
Temperature	143.8641 °C
Cp	1.159625
Temperature	144.8265 °C
Cp	1.159599
Temperature	145.7889 °C
Cp	1.15959
Temperature	146.7513 °C
Cp	1.15957
Temperature	147.7137 °C
Cp	1.159569
Temperature	148.6761 °C
Cp	1.159584
Temperature	149.6385 °C
Cp	1.159613
Temperature	150.6009 °C
Cp	1.159654
Temperature	151.5633 °C
Cp	1.15969
Temperature	152.5257 °C
Cp	1.159761
Temperature	153.4881 °C
Cp	1.159829
Temperature	154.4505 °C
Cp	1.159901
Temperature	155.4129 °C
Cp	1.159981
Temperature	156.3753 °C
Cp	1.160076
Temperature	157.3377 °C
Cp	1.160207
Temperature	158.3001 °C
Cp	1.160336
Temperature	159.2625 °C
Cp	1.160508
Temperature	160.2249 °C
Cp	1.160724
Temperature	161.1873 °C
Cp	1.160986
Temperature	162.1497 °C
Cp	1.161296
Temperature	163.1122 °C
Cp	1.161639
Temperature	164.0746 °C
Cp	1.162062
Temperature	165.037 °C
Cp	1.162527
Temperature	165.9994 °C
Cp	1.163037
Temperature	166.9618 °C
Cp	1.163591
Temperature	167.9242 °C
Cp	1.164188
Temperature	168.8866 °C
Cp	1.164826
Temperature	169.849 °C
Cp	1.165508
Temperature	170.8114 °C
Cp	1.166203
Temperature	171.7738 °C
Cp	1.166927
Temperature	172.7362 °C
Cp	1.167664
Temperature	173.6986 °C
Cp	1.168401
Temperature	174.661 °C
Cp	1.169124
Temperature	175.6234 °C
Cp	1.169799
Temperature	176.5858 °C
Cp	1.170462
Temperature	177.5482 °C
Cp	1.171058
Temperature	178.5106 °C
Cp	1.171581
Temperature	179.473 °C
Cp	1.172029
Temperature	180.4354 °C
Cp	1.1724
Temperature	181.3978 °C
Cp	1.172722
Temperature	182.3602 °C
Cp	1.172924
Temperature	183.3226 °C
Cp	1.173072
Temperature	184.285 °C
Cp	1.173165
Temperature	185.2474 °C
Cp	1.173204
Temperature	186.2098 °C
Cp	1.173191
Temperature	187.1722 °C
Cp	1.173098
Temperature	188.1346 °C
Cp	1.173022
Temperature	189.097 °C
Cp	1.172893
Temperature	190.0594 °C
Cp	1.172727
Temperature	191.0218 °C
Cp	1.172536
Temperature	191.9842 °C
Cp	1.172333
Temperature	192.9466 °C
Cp	1.172129
Temperature	193.909 °C
Cp	1.171948
Temperature	194.8714 °C
Cp	1.171764
Temperature	195.8338 °C
Cp	1.171616
Temperature	196.7962 °C
Cp	1.171503
Temperature	197.7587 °C
Cp	1.171422
Temperature	198.7211 °C
Cp	1.171373
Temperature	199.6835 °C
Cp	1.171339
Temperature	200.6459 °C
Cp	1.171347
Temperature	201.6083 °C
Cp	1.171366
Temperature	202.5707 °C
Cp	1.171394
Temperature	203.5331 °C
Cp	1.171431
Temperature	204.4955 °C
Cp	1.171476
Temperature	205.4579 °C
Cp	1.17154
Temperature	206.4203 °C
Cp	1.171593
Temperature	207.3827 °C
Cp	1.171659
Temperature	208.3451 °C
Cp	1.171737
Temperature	209.3075 °C
Cp	1.171824
Temperature	210.2699 °C
Cp	1.171918
Temperature	211.2323 °C
Cp	1.172
Temperature	212.1947 °C
Cp	1.172116
Temperature	213.1571 °C
Cp	1.172226
Temperature	214.1195 °C
Cp	1.172333
Temperature	215.0819 °C
Cp	1.172439
Temperature	216.0443 °C
Cp	1.172549
Temperature	217.0067 °C
Cp	1.172689
Temperature	217.9691 °C
Cp	1.172792
Temperature	218.9315 °C
Cp	1.172914
Temperature	219.8939 °C
Cp	1.173052
Temperature	220.8563 °C
Cp	1.173203
Temperature	221.8187 °C
Cp	1.173361
Temperature	222.7811 °C
Cp	1.173523
Temperature	223.7435 °C
Cp	1.173674
Temperature	224.7059 °C
Cp	1.173842
Temperature	225.6683 °C
Cp	1.173995
Temperature	226.6307 °C
Cp	1.174137
Temperature	227.5932 °C
Cp	1.174268
Temperature	228.5556 °C
Cp	1.174393
Temperature	229.518 °C
Cp	1.174531
Temperature	230.4804 °C
Cp	1.174642
Temperature	231.4428 °C
Cp	1.174766
Temperature	232.4052 °C
Cp	1.174902
Temperature	233.3676 °C
Cp	1.175049
Temperature	234.33 °C
Cp	1.175206
Temperature	235.2924 °C
Cp	1.175351
Temperature	236.2548 °C
Cp	1.175539
Temperature	237.2172 °C
Cp	1.175721
Temperature	238.1796 °C
Cp	1.175902
Temperature	239.142 °C
Cp	1.176085
Temperature	240.1044 °C
Cp	1.176272
Temperature	241.0668 °C
Cp	1.176491
Temperature	242.0292 °C
Cp	1.176676
Temperature	242.9916 °C
Cp	1.176882
Temperature	243.954 °C
Cp	1.177106
Temperature	244.9164 °C
Cp	1.177343
Temperature	245.8788 °C
Cp	1.177589
Temperature	246.8412 °C
Cp	1.17784
Temperature	247.8036 °C
Cp	1.17808
Temperature	248.766 °C
Cp	1.178334
Temperature	249.7284 °C
Cp	1.178575
Temperature	250.6908 °C
Cp	1.178803
Temperature	251.6532 °C
Cp	1.17902
Temperature	252.6156 °C
Cp	1.179227
Temperature	253.578 °C
Cp	1.179435
Temperature	254.5404 °C
Cp	1.17962
Temperature	255.5028 °C
Cp	1.179806
Temperature	256.4652 °C
Cp	1.179992
Temperature	257.4276 °C
Cp	1.180176
Temperature	258.39 °C
Cp	1.180356
Temperature	259.3524 °C
Cp	1.180525
Temperature	260.3148 °C
Cp	1.180699
Temperature	261.2773 °C
Cp	1.18086
Temperature	262.2397 °C
Cp	1.181011
Temperature	263.2021 °C
Cp	1.18115
Temperature	264.1645 °C
Cp	1.181279
Temperature	265.1269 °C
Cp	1.181398
Temperature	266.0893 °C
Cp	1.181504
Temperature	267.0517 °C
Cp	1.1816
Temperature	268.0141 °C
Cp	1.181687
Temperature	268.9765 °C
Cp	1.181765
Temperature	269.9389 °C
Cp	1.181835
Temperature	270.9013 °C
Cp	1.181897
Temperature	271.8637 °C
Cp	1.181952
Temperature	272.8261 °C
Cp	1.182001
Temperature	273.7885 °C
Cp	1.182045
Temperature	274.7509 °C
Cp	1.182086
Temperature	275.7133 °C
Cp	1.182126
Temperature	276.6757 °C
Cp	1.182166
Temperature	277.6381 °C
Cp	1.182204
Temperature	278.6005 °C
Cp	1.182251
Temperature	279.5629 °C
Cp	1.182299
Temperature	280.5253 °C
Cp	1.182353
Temperature	281.4877 °C
Cp	1.182414
Temperature	282.4501 °C
Cp	1.182486
Temperature	283.4125 °C
Cp	1.182577
Temperature	284.3749 °C
Cp	1.182671
Temperature	285.3373 °C
Cp	1.182786
Temperature	286.2997 °C
Cp	1.182921
Temperature	287.2621 °C
Cp	1.183076
Temperature	288.2245 °C
Cp	1.183251
Temperature	289.187 °C
Cp	1.183439
Temperature	290.1494 °C
Cp	1.183654
Temperature	291.1118 °C
Cp	1.183883
Temperature	292.0742 °C
Cp	1.184126
Temperature	293.0366 °C
Cp	1.184383
Temperature	293.999 °C
Cp	1.184651
Temperature	294.9614 °C
Cp	1.184932
Temperature	295.9238 °C
Cp	1.185223
Temperature	296.8862 °C
Cp	1.185522
Temperature	297.8486 °C
Cp	1.185828
Temperature	298.811 °C
Cp	1.18614
Temperature	299.7734 °C
Cp	1.186456
Temperature	300.7358 °C
Cp	1.186773
Temperature	301.6982 °C
Cp	1.187085
Temperature	302.6606 °C
Cp	1.1874
Temperature	303.623 °C
Cp	1.187709
Temperature	304.5854 °C
Cp	1.188011
Temperature	305.5478 °C
Cp	1.188307
Temperature	306.5102 °C
Cp	1.188598
Temperature	307.4726 °C
Cp	1.188893
Temperature	308.435 °C
Cp	1.189173
Temperature	309.3974 °C
Cp	1.189456
Temperature	310.3598 °C
Cp	1.189744
Temperature	311.3222 °C
Cp	1.190034
Temperature	312.2846 °C
Cp	1.190329
Temperature	313.247 °C
Cp	1.190615
Temperature	314.2094 °C
Cp	1.190925
Temperature	315.1718 °C
Cp	1.191232
Temperature	316.1342 °C
Cp	1.191539
Temperature	317.0966 °C
Cp	1.191848
Temperature	318.059 °C
Cp	1.19216
Temperature	319.0214 °C
Cp	1.192496
Temperature	319.9838 °C
Cp	1.192805
Temperature	320.9462 °C
Cp	1.193128
Temperature	321.9086 °C
Cp	1.193462
Temperature	322.871 °C
Cp	1.193803
Temperature	323.8334 °C
Cp	1.194149
Temperature	324.7958 °C
Cp	1.194495
Temperature	325.7583 °C
Cp	1.194832
Temperature	326.7207 °C
Cp	1.195181
Temperature	327.6831 °C
Cp	1.19552
Temperature	328.6455 °C
Cp	1.195853
Temperature	329.6079 °C
Cp	1.196183
Temperature	330.5703 °C
Cp	1.196515
Temperature	331.5327 °C
Cp	1.196862
Temperature	332.4951 °C
Cp	1.197211
Temperature	333.4575 °C
Cp	1.197584
Temperature	334.4199 °C
Cp	1.197985
Temperature	335.3823 °C
Cp	1.198418
Temperature	336.3447 °C
Cp	1.198886
Temperature	337.3071 °C
Cp	1.199394
Temperature	338.2695 °C
Cp	1.199941
Temperature	339.2319 °C
Cp	1.20053
Temperature	340.1943 °C
Cp	1.20116
Temperature	341.1567 °C
Cp	1.201831
Temperature	342.1191 °C
Cp	1.202538
Temperature	343.0815 °C
Cp	1.203274
Temperature	344.0439 °C
Cp	1.20404
Temperature	345.0063 °C
Cp	1.204822
Temperature	345.9687 °C
Cp	1.205612
[...]
140.7633	89.7085	0.5260
140.7800	89.5427	0.5259
140.7967	89.3749	0.5260
140.8133	89.2087	0.5260
140.8300	89.0421	0.5260
140.8467	88.8762	0.5260
140.8633	88.7102	0.5260
140.8800	88.5440	0.5260
140.8967	88.3767	0.5260
140.9133	88.2102	0.5260
140.9300	88.0439	0.5261
140.9467	87.8769	0.5261
140.9633	87.7121	0.5261
140.9800	87.5457	0.5261
140.9967	87.3794	0.5261
141.0133	87.2120	0.5261
141.0300	87.0460	0.5261
141.0467	86.8793	0.5261
141.0633	86.7136	0.5261
141.0800	86.5474	0.5261
141.0967	86.3800	0.5261
141.1133	86.2143	0.5261
141.1300	86.0472	0.5261
141.1467	85.8809	0.5261
141.1633	85.7156	0.5261
141.1800	85.5490	0.5261
141.1967	85.3826	0.5260
141.2133	85.2159	0.5260
141.2300	85.0492	0.5259
141.2467	84.8838	0.5260
141.2633	84.7154	0.5260
141.2800	84.5506	0.5260
141.2967	84.3842	0.5260
141.3133	84.2174	0.5260
141.3300	84.0506	0.5260
141.3467	83.8846	0.5260
141.3633	83.7181	0.5259
141.3800	83.5513	0.5259
141.3967	83.3861	0.5259
141.4133	83.2192	0.5259
141.4300	83.0525	0.5259
141.4467	82.8872	0.5259
141.4633	82.7203	0.5259
141.4800	82.5534	0.5259
141.4967	82.3885	0.5259
141.5133	82.2212	0.5259
141.5300	82.0545	0.5259
141.5467	81.8882	0.5259
141.5633	81.7231	0.5259
141.5800	81.5555	0.5258
141.5967	81.3905	0.5258
141.6133	81.2238	0.5258
141.6300	81.0568	0.5258
141.6467	80.8899	0.5258
141.6633	80.7232	0.5258
141.6800	80.5572	0.5258
141.6967	80.3906	0.5258
141.7133	80.2248	0.5258
141.7300	80.0578	0.5258
141.7467	79.8903	0.5258
141.7633	79.7262	0.5258
141.7800	79.5589	0.5258
141.7967	79.3930	0.5258
141.8133	79.2261	0.5258
141.8300	79.0594	0.5258
141.8467	78.8933	0.5257
141.8633	78.7265	0.5258
141.8800	78.5608	0.5257
141.8967	78.3935	0.5257
141.9133	78.2273	0.5257
141.9300	78.0610	0.5257
141.9467	77.8951	0.5256
141.9633	77.7287	0.5256
141.9800	77.5614	0.5256
141.9967	77.3966	0.5256
142.0133	77.2295	0.5256
142.0300	77.0632	0.5256
142.0467	76.8964	0.5256
142.0633	76.7302	0.5255
142.0800	76.5641	0.5255
142.0967	76.3978	0.5255
142.1133	76.2320	0.5255
142.1300	76.0650	0.5255
142.1467	75.8986	0.5255
142.1633	75.7324	0.5255
142.1800	75.5661	0.5255
142.1967	75.4007	0.5254
142.2133	75.2328	0.5254
142.2300	75.0661	0.5254
142.2467	74.9004	0.5254
142.2633	74.7341	0.5254
142.2800	74.5678	0.5254
142.2967	74.4018	0.5254
142.3133	74.2350	0.5254
142.3300	74.0683	0.5254
142.3467	73.9025	0.5253
142.3633	73.7368	0.5254
142.3800	73.5697	0.5254
142.3967	73.4033	0.5253
142.4133	73.2367	0.5253
142.4300	73.0716	0.5253
142.4467	72.9043	0.5253
142.4633	72.7382	0.5253
142.4800	72.5720	0.5253
142.4967	72.4050	0.5252
142.5133	72.2381	0.5252
142.5300	72.0723	0.5253
142.5467	71.9052	0.5253
142.5633	71.7390	0.5253
142.5800	71.5728	0.5252
142.5967	71.4066	0.5252
142.6133	71.2402	0.5252
142.6300	71.0738	0.5252
142.6467	70.9080	0.5252
142.6633	70.7415	0.5252
142.6800	70.5751	0.5252
142.6967	70.4092	0.5252
142.7133	70.2424	0.5252
142.7300	70.0762	0.5251
142.7467	69.9102	0.5251
142.7633	69.7431	0.5251
142.7800	69.5766	0.5251
142.7967	69.4116	0.5251
142.8133	69.2447	0.5251
142.8300	69.0777	0.5251
142.8467	68.9126	0.5251
142.8633	68.7446	0.5250
142.8800	68.5787	0.5250
142.8967	68.4119	0.5250
142.9133	68.2453	0.5251
142.9300	68.0790	0.5251
142.9467	67.9125	0.5251
142.9633	67.7457	0.5250
142.9800	67.5798	0.5250
142.9967	67.4138	0.5250
143.0133	67.2465	0.5250
143.0300	67.0804	0.5249
143.0467	66.9128	0.5249
143.0633	66.7480	0.5249
143.0800	66.5812	0.5249
143.0967	66.4143	0.5248
143.1133	66.2481	0.5248
143.1300	66.0820	0.5247
143.1467	65.9153	0.5247
143.1633	65.7495	0.5246
143.1800	65.5825	0.5245
143.1967	65.4161	0.5245
143.2133	65.2480	0.5245
143.2300	65.0839	0.5244
143.2467	64.9167	0.5243
143.2633	64.7493	0.5241
143.2800	64.5833	0.5240
143.2967	64.4168	0.5240
143.3133	64.2506	0.5239
143.3300	64.0864	0.5238
143.3467	63.9188	0.5236
143.3633	63.7521	0.5235
143.3800	63.5857	0.5234
143.3967	63.4190	0.5233
143.4133	63.2525	0.5232
143.4300	63.0856	0.5231
143.4467	62.9180	0.5230
143.4633	62.7510	0.5228
143.4800	62.5858	0.5226
143.4967	62.4192	0.5224
143.5133	62.2536	0.5222
143.5300	62.0855	0.5219
143.5467	61.9198	0.5218
143.5633	61.7525	0.5210
143.5800	61.5859	0.5208
143.5967	61.4202	0.5206
143.6133	61.2537	0.5202
143.6300	61.0859	0.5200
143.6467	60.9191	0.5198
143.6633	60.7522	0.5194
143.6800	60.5864	0.5190
143.6967	60.4190	0.5185
143.7133	60.2537	0.5178
143.7300	60.0867	0.5173
143.7467	59.9191	0.5170
143.7633	59.7518	0.5165
143.7800	59.5852	0.5163
143.7967	59.4181	0.5159
143.8133	59.2519	0.5149
143.8300	59.0850	0.5145
143.8467	58.9178	0.5141
143.8633	58.7512	0.5135
143.8800	58.5832	0.5125
143.8967	58.4176	0.5118
143.9133	58.2506	0.5111
143.9300	58.0839	0.5106
143.9467	57.9171	0.5093
143.9633	57.7503	0.5090
143.9800	57.5829	0.5084
143.9967	57.4173	0.5078
144.0133	57.2485	0.5073
144.0300	57.0820	0.5066
144.0467	56.9146	0.5058
144.0633	56.7472	0.5050
144.0800	56.5803	0.5044
144.0967	56.4142	0.5029
144.1133	56.2461	0.5023
144.1300	56.0796	0.5017
144.1467	55.9128	0.5009
144.1633	55.7447	0.5004
144.1800	55.5774	0.4998
144.1967	55.4094	0.4989
144.2133	55.2435	0.4976
144.2300	55.0764	0.4972
144.2467	54.9093	0.4962
144.2633	54.7422	0.4956
144.2800	54.5757	0.4947
144.2967	54.4080	0.4940
144.3133	54.2413	0.4934
144.3300	54.0752	0.4923
144.3467	53.9076	0.4915
144.3633	53.7399	0.4907
144.3800	53.5737	0.4898
144.3967	53.4055	0.4891
144.4133	53.2387	0.4887
144.4300	53.0705	0.4878
144.4467	52.9042	0.4869
144.4633	52.7367	0.4862
144.4800	52.5699	0.4855
144.4967	52.4020	0.4847
144.5133	52.2363	0.4839
144.5300	52.0695	0.4835
144.5467	51.9020	0.4825
144.5633	51.7345	0.4817
144.5800	51.5667	0.4811
144.5967	51.3984	0.4808
144.6133	51.2335	0.4798
144.6300	51.0658	0.4791
144.6467	50.8994	0.4787
144.6633	50.7323	0.4774
144.6800	50.5645	0.4769
144.6967	50.3983	0.4767
144.7133	50.2320	0.4757
144.7300	50.0630	0.4754
144.7467	49.8958	0.4746
144.7633	49.7292	0.4739
144.7800	49.5622	0.4728
144.7967	49.3967	0.4722
144.8133	49.2299	0.4717
144.8300	49.0617	0.4716
144.8467	48.8950	0.4711
144.8633	48.7283	0.4705
144.8800	48.5597	0.4703
144.8967	48.3929	0.4697
144.9133	48.2259	0.4692
144.9300	48.0602	0.4685
144.9467	47.8925	0.4681
144.9633	47.7248	0.4677
144.9800	47.5591	0.4672
144.9967	47.3916	0.4667
145.0133	47.2262	0.4661
145.0300	47.0581	0.4653
145.0467	46.8917	0.4646
145.0633	46.7242	0.4644
145.0800	46.5583	0.4639
145.0967	46.3912	0.4636
145.1133	46.2250	0.4633
145.1300	46.0572	0.4627
145.1467	45.8906	0.4624
145.1633	45.7240	0.4617
145.1800	45.5569	0.4615
145.1967	45.3904	0.4612
145.2133	45.2237	0.4610
145.2300	45.0564	0.4608
145.2467	44.8886	0.4606
145.2633	44.7220	0.4601
145.2800	44.5554	0.4598
145.2967	44.3889	0.4593
145.3133	44.2218	0.4588
145.3300	44.0558	0.4586
145.3467	43.8886	0.4582
145.3633	43.7223	0.4579
145.3800	43.5547	0.4577
145.3967	43.3882	0.4574
145.4133	43.2218	0.4565
145.4300	43.0557	0.4562
145.4467	42.8875	0.4560
145.4633	42.7215	0.4558
145.4800	42.5553	0.4556
145.4967	42.3872	0.4552
145.5133	42.2217	0.4549
145.5300	42.0550	0.4546
145.5467	41.8878	0.4543
145.5633	41.7206	0.4538
145.5800	41.5551	0.4536
145.5967	41.3881	0.4534
145.6133	41.2208	0.4531
145.6300	41.0546	0.4529
145.6467	40.8884	0.4526
145.6633	40.7213	0.4524
145.6800	40.5538	0.4519
145.6967	40.3877	0.4518
145.7133	40.2204	0.4515
145.7300	40.0539	0.4513
145.7467	39.8881	0.4509
145.7633	39.7211	0.4507
145.7800	39.5550	0.4506
145.7967	39.3877	0.4501
145.8133	39.2219	0.4500
145.8300	39.0544	0.4498
145.8467	38.8878	0.4493
145.8633	38.7217	0.4491
145.8800	38.5542	0.4490
145.8967	38.3874	0.4488
145.9133	38.2216	0.4485
145.9300	38.0540	0.4483
145.9467	37.8875	0.4479
145.9633	37.7214	0.4476
145.9800	37.5551	0.4474
145.9967	37.3879	0.4473
146.0133	37.2225	0.4470
146.0300	37.0548	0.4468
146.0467	36.8885	0.4467
146.0633	36.7216	0.4465
146.0800	36.5544	0.4463
146.0967	36.3881	0.4462
146.1133	36.2204	0.4459
146.1300	36.0559	0.4458
146.1467	35.8894	0.4453
146.1633	35.7220	0.4452
146.1800	35.5560	0.4451
146.1967	35.3881	0.4449
146.2133	35.2220	0.4448
146.2300	35.0550	0.4446
146.2467	34.8892	0.4444
146.2633	34.7228	0.4442
146.2800	34.5557	0.4439
146.2967	34.3892	0.4437
146.3133	34.2219	0.4436
146.3300	34.0562	0.4435
146.3467	33.8905	0.4433
146.3633	33.7226	0.4431
146.3800	33.5570	0.4430
146.3967	33.3895	0.4428
146.4133	33.2235	0.4425
146.4300	33.0561	0.4424
146.4467	32.8898	0.4422
146.4633	32.7237	0.4421
146.4800	32.5578	0.4419
146.4967	32.3908	0.4418
146.5133	32.2244	0.4414
146.5300	32.0570	0.4411
146.5467	31.8907	0.4410
146.5633	31.7240	0.4407
146.5800	31.5581	0.4406
146.5967	31.3904	0.4405
146.6133	31.2253	0.4404
146.6300	31.0570	0.4403
146.6467	30.8917	0.4402
146.6633	30.7256	0.4401
146.6800	30.5573	0.4400
146.6967	30.3919	0.4398
146.7133	30.2251	0.4397
146.7300	30.0589	0.4396
146.7467	29.8914	0.4394
146.7633	29.7259	0.4391
146.7800	29.5592	0.4390
146.7967	29.3932	0.4388
146.8133	29.2263	0.4387
146.8300	29.0599	0.4385
146.8467	28.8926	0.4384
146.8633	28.7264	0.4383
146.8800	28.5584	0.4382
146.8967	28.3933	0.4380
146.9133	28.2263	0.4379
146.9300	28.0599	0.4378
146.9467	27.8933	0.4376
146.9633	27.7269	0.4375
146.9800	27.5603	0.4372
146.9967	27.3938	0.4371
147.0133	27.2283	0.4368
147.0300	27.0608	0.4368
147.0467	26.8940	0.4366
147.0633	26.7280	0.4365
147.0800	26.5616	0.4364
147.0967	26.3945	0.4363
147.1133	26.2273	0.4362
147.1300	26.0617	0.4361
147.1467	25.8938	0.4358
147.1633	25.7292	0.4357
147.1800	25.5625	0.4356
147.1967	25.3954	0.4356
147.2133	25.2291	0.4355
147.2300	25.0623	0.4353
147.2467	24.8957	0.4353
147.2633	24.7283	0.4351
147.2800	24.5627	0.4350
147.2967	24.3960	0.4347
147.3133	24.2309	0.4346
147.3300	24.0639	0.4346
147.3467	23.8967	0.4344
147.3633	23.7302	0.4344
147.3800	23.5641	0.4343
147.3967	23.3973	0.4342
147.4133	23.2310	0.4341
147.4300	23.0649	0.4340
147.4467	22.8983	0.4339
147.4633	22.7302	0.4338
147.4800	22.5647	0.4337
147.4967	22.3990	0.4336
147.5133	22.2317	0.4335
147.5300	22.0659	0.4334
147.5467	21.8978	0.4333
147.5633	21.7318	0.4332
147.5800	21.5648	0.4331
147.5967	21.3997	0.4330
147.6133	21.2326	0.4329
147.6300	21.0659	0.4326
147.6467	20.8998	0.4325
147.6633	20.7331	0.4324
147.6800	20.5668	0.4323
147.6967	20.4001	0.4322
147.7133	20.2330	0.4321
147.7300	20.0654	0.4320
147.7467	19.8994	0.4319
147.7633	19.7332	0.4318
147.7800	19.5672	0.4317
147.7967	19.3997	0.4316
147.8133	19.2345	0.4315
147.8300	19.0661	0.4314
147.8467	18.9013	0.4311
147.8633	18.7347	0.4310
147.8800	18.5675	0.4309
147.8967	18.4000	0.4308
147.9133	18.2352	0.4307
147.9300	18.0674	0.4306
147.9467	17.9011	0.4305
147.9633	17.7338	0.4304
147.9800	17.5687	0.4303
147.9967	17.4009	0.4302
148.0133	17.2345	0.4301
148.0300	17.0679	0.4300
148.0467	16.9020	0.4299
148.0633	16.7368	0.4298
148.0800	16.5683	0.4297
148.0967	16.4022	0.4295
148.1133	16.2358	0.4294
148.1300	16.0694	0.4293
148.1467	15.9025	0.4292
148.1633	15.7363	0.4289
148.1800	15.5713	0.4289
148.1967	15.4026	0.4287
148.2133	15.2372	0.4287
148.2300	15.0700	0.4286
148.2467	14.9031	0.4285
148.2633	14.7373	0.4284
148.2800	14.5702	0.4282
148.2967	14.4038	0.4281
148.3133	14.2381	0.4280
148.3300	14.0703	0.4280
148.3467	13.9043	0.4278
148.3633	13.7382	0.4276
148.3800	13.5713	0.4275
148.3967	13.4053	0.4274
148.4133	13.2379	0.4274
148.4300	13.0710	0.4273
148.4467	12.9044	0.4271
148.4633	12.7376	0.4271
148.4800	12.5720	0.4270
148.4967	12.4052	0.4269
148.5133	12.2377	0.4268
148.5300	12.0715	0.4266
148.5467	11.9060	0.4265
148.5633	11.7389	0.4264
148.5800	11.5725	0.4263
148.5967	11.4047	0.4262
148.6133	11.2388	0.4261
148.6300	11.0720	0.4260
148.6467	10.9065	0.4259
148.6633	10.7403	0.4258
148.6800	10.5718	0.4257
148.6967	10.4064	0.4256
148.7133	10.2393	0.4255
148.7300	10.0725	0.4254
148.7467	9.9077	0.4253
148.7633	9.7396	0.4252
148.7800	9.5736	0.4250
148.7967	9.4081	0.4249
148.8133	9.2420	0.4248
148.8300	9.0742	0.4247
148.8467	8.9075	0.4246
148.8633	8.7406	0.4245
148.8800	8.5740	0.4244
148.8967	8.4074	0.4242
148.9133	8.2405	0.4241
148.9300	8.0748	0.4240
148.9467	7.9085	0.4239
148.9633	7.7413	0.4237
148.9800	7.5740	0.4236
148.9967	7.4088	0.4236
149.0133	7.2413	0.4234
149.0300	7.0769	0.4234
149.0467	6.9083	0.4233
149.0633	6.7419	0.4232
149.0800	6.5758	0.4231
149.0967	6.4083	0.4229
149.1133	6.2435	0.4228
149.1300	6.0761	0.4227
149.1467	5.9107	0.4226
149.1633	5.7432	0.4224
149.1800	5.5765	0.4223
149.1967	5.4104	0.4222
149.2133	5.2434	0.4222
149.2300	5.0771	0.4221
149.2467	4.9102	0.4220
149.2633	4.7437	0.4219
149.2800	4.5785	0.4218
149.2967	4.4114	0.4217
149.3133	4.2457	0.4216
149.3300	4.0787	0.4215
149.3467	3.9126	0.4214
149.3633	3.7457	0.4213
149.3800	3.5792	0.4208
149.3967	3.4119	0.4208
149.4133	3.2462	0.4207
149.4300	3.0783	0.4207
149.4467	2.9139	0.4206
149.4633	2.7459	0.4205
149.4800	2.5812	0.4204
149.4967	2.4135	0.4203
149.5133	2.2475	0.4202
149.5300	2.0815	0.4201
149.5467	1.9135	0.4200
149.5633	1.7470	0.4199
149.5800	1.5818	0.4198
149.5967	1.4143	0.4197
149.6133	1.2484	0.4196
149.6300	1.0808	0.4196
149.6467	0.9144	0.4195
149.6633	0.7503	0.4193
149.6800	0.5835	0.4193
149.6967	0.4160	0.4192
149.7133	0.2490	0.4191
149.7300	0.0826	0.4191
149.7467	-0.0832	0.4190
149.7633	-0.2495	0.4189
149.7800	-0.4156	0.4188
149.7967	-0.5825	0.4187
149.8133	-0.7491	0.4187
149.8300	-0.9173	0.4186
149.8467	-1.0831	0.4185
149.8633	-1.2489	0.4184
149.8800	-1.4170	0.4183
149.8967	-1.5823	0.4181
149.9133	-1.7484	0.4181
149.9300	-1.9150	0.4180
149.9467	-2.0817	0.4179
149.9633	-2.2478	0.4178
149.9800	-2.4145	0.4177
149.9967	-2.5803	0.4176
150.0133	-2.7413	0.4722
150.0300	-2.8947	0.4583
150.0467	-3.0593	0.4426
150.0633	-3.2248	0.4350
150.0800	-3.3923	0.4316
150.0967	-3.5601	0.4286
150.1133	-3.7286	0.4277
150.1300	-3.8964	0.4273
150.1467	-4.0642	0.4264
150.1633	-4.2302	0.4254
150.1800	-4.3985	0.4248
150.1967	-4.5646	0.4246
150.2133	-4.7335	0.4242
150.2300	-4.8982	0.4235
150.2467	-5.0664	0.4234
150.2633	-5.2335	0.4229
150.2800	-5.4008	0.4228
150.2967	-5.5676	0.4225
150.3133	-5.7337	0.4224
150.3300	-5.9018	0.4219
150.3467	-6.0684	0.4217
150.3633	-6.2349	0.4214
150.3800	-6.4011	0.4212
150.3967	-6.5674	0.4209
150.4133	-6.7354	0.4209
150.4300	-6.9020	0.4207
150.4467	-7.0687	0.4205
150.4633	-7.2367	0.4204
150.4800	-7.4021	0.4202
150.4967	-7.5694	0.4201
150.5133	-7.7336	0.4197
150.5300	-7.9014	0.4197
150.5467	-8.0692	0.4196
150.5633	-8.2344	0.4195
150.5800	-8.4022	0.4194
150.5967	-8.5687	0.4191
150.6133	-8.7338	0.4190
150.6300	-8.9007	0.4189
150.6467	-9.0686	0.4188
150.6633	-9.2332	0.4187
150.6800	-9.4002	0.4186
150.6967	-9.5672	0.4186
150.7133	-9.7339	0.4184
150.7300	-9.9003	0.4183
150.7467	-10.0671	0.4183
150.7633	-10.2335	0.4182
150.7800	-10.3999	0.4181
150.7967	-10.5667	0.4179
150.8133	-10.7325	0.4179
150.8300	-10.9002	0.4178
150.8467	-11.0660	0.4177
150.8633	-11.2318	0.4176
150.8800	-11.3981	0.4175
150.8967	-11.5644	0.4174
150.9133	-11.7314	0.4174
150.9300	-11.8967	0.4173
150.9467	-12.0641	0.4172
150.9633	-12.2317	0.4171
150.9800	-12.3977	0.4170
150.9967	-12.5640	0.4169
151.0133	-12.7318	0.4168
151.0300	-12.8970	0.4167
151.0467	-13.0640	0.4166
151.0633	-13.2297	0.4166
151.0800	-13.3962	0.4165
151.0967	-13.5621	0.4164
151.1133	-13.7298	0.4164
151.1300	-13.8963	0.4163
151.1467	-14.0631	0.4163
151.1633	-14.2292	0.4162
151.1800	-14.3952	0.4161
151.1967	-14.5611	0.4161
151.2133	-14.7277	0.4160
151.2300	-14.8944	0.4159
151.2467	-15.0614	0.4159
151.2633	-15.2277	0.4158
151.2800	-15.3948	0.4158
151.2967	-15.5600	0.4156
151.3133	-15.7266	0.4155
151.3300	-15.8930	0.4155
151.3467	-16.0587	0.4154
151.3633	-16.2261	0.4154
151.3800	-16.3914	0.4153
151.3967	-16.5598	0.4153
151.4133	-16.7270	0.4152
151.4300	-16.8924	0.4151
151.4467	-17.0581	0.4150
151.4633	-17.2252	0.4149
151.4800	-17.3922	0.4149
151.4967	-17.5580	0.4148
151.5133	-17.7245	0.4148
151.5300	-17.8914	0.4147
151.5467	-18.0579	0.4147
151.5633	-18.2237	0.4146
151.5800	-18.3910	0.4145
151.5967	-18.5583	0.4144
151.6133	-18.7219	0.4144
151.6300	-18.8905	0.4143
151.6467	-19.0572	0.4142
151.6633	-19.2234	0.4141
151.6800	-19.3900	0.4141
151.6967	-19.5577	0.4140
151.7133	-19.7224	0.4139
151.7300	-19.8891	0.4138
151.7467	-20.0549	0.4138
151.7633	-20.2210	0.4137
151.7800	-20.3888	0.4137
151.7967	-20.5571	0.4136
151.8133	-20.7215	0.4135
151.8300	-20.8885	0.4134
151.8467	-21.0533	0.4133
151.8633	-21.2212	0.4132
151.8800	-21.3870	0.4132
151.8967	-21.5536	0.4131
151.9133	-21.7199	0.4130
151.9300	-21.8870	0.4129
151.9467	-22.0538	0.4129
151.9633	-22.2202	0.4128
151.9800	-22.3862	0.4127
151.9967	-22.5541	0.4126
152.0133	-22.7195	0.4125
152.0300	-22.8861	0.4125
152.0467	-23.0520	0.4123
152.0633	-23.2184	0.4123
152.0800	-23.3861	0.4122
152.0967	-23.5519	0.4121
152.1133	-23.7181	0.4121
152.1300	-23.8844	0.4120
152.1467	-24.0510	0.4119
152.1633	-24.2169	0.4119
152.1800	-24.3840	0.4119
152.1967	-24.5502	0.4118
152.2133	-24.7172	0.4117
152.2300	-24.8817	0.4117
152.2467	-25.0504	0.4116
152.2633	-25.2161	0.4115
152.2800	-25.3843	0.4115
152.2967	-25.5504	0.4114
152.3133	-25.7161	0.4114
152.3300	-25.8829	0.4113
152.3467	-26.0486	0.4113
152.3633	-26.2153	0.4111
152.3800	-26.3815	0.4111
152.3967	-26.5492	0.4110
152.4133	-26.7153	0.4110
152.4300	-26.8805	0.4109
152.4467	-27.0490	0.4108
152.4633	-27.2139	0.4107
152.4800	-27.3811	0.4107
152.4967	-27.5471	0.4106
152.5133	-27.7153	0.4105
152.5300	-27.8802	0.4105
152.5467	-28.0472	0.4104
152.5633	-28.2134	0.4103
152.5800	-28.3802	0.4103
152.5967	-28.5475	0.4102
152.6133	-28.7126	0.4101
152.6300	-28.8788	0.4101
152.6467	-29.0449	0.4100
152.6633	-29.2126	0.4100
152.6800	-29.3783	0.4096
152.6967	-29.5443	0.4096
152.7133	-29.7113	0.4096
152.7300	-29.8784	0.4096
152.7467	-30.0440	0.4094
152.7633	-30.2114	0.4094
152.7800	-30.3769	0.4094
152.7967	-30.5447	0.4094
152.8133	-30.7102	0.4093
152.8300	-30.8770	0.4092
152.8467	-31.0445	0.4092
152.8633	-31.2089	0.4092
152.8800	-31.3769	0.4091
152.8967	-31.5437	0.4090
152.9133	-31.7099	0.4090
152.9300	-31.8753	0.4090
152.9467	-32.0423	0.4089
152.9633	-32.2095	0.4089
152.9800	-32.3749	0.4088
152.9967	-32.5427	0.4088
153.0133	-32.7089	0.4087
153.0300	-32.8749	0.4087
153.0467	-33.0423	0.4086
153.0633	-33.2088	0.4086
153.0800	-33.3773	0.4085
153.0967	-33.5430	0.4085
153.1133	-33.7055	0.4084
153.1300	-33.8747	0.4083
153.1467	-34.0409	0.4082
153.1633	-34.2080	0.4081
153.1800	-34.3736	0.4081
153.1967	-34.5415	0.4080
153.2133	-34.7074	0.4080
153.2300	-34.8736	0.4079
153.2467	-35.0404	0.4079
153.2633	-35.2066	0.4079
153.2800	-35.3729	0.4078
153.2967	-35.5386	0.4077
153.3133	-35.7062	0.4076
153.3300	-35.8727	0.4076
153.3467	-36.0386	0.4076
153.3633	-36.2058	0.4075
153.3800	-36.3707	0.4075
153.3967	-36.5404	0.4074
153.4133	-36.7056	0.4074
153.4300	-36.8712	0.4073
153.4467	-37.0390	0.4072
153.4633	-37.2042	0.4072
153.4800	-37.3683	0.4071
153.4967	-37.5382	0.4070
153.5133	-37.7026	0.4069
153.5300	-37.8691	0.4069
153.5467	-38.0362	0.4069
153.5633	-38.2028	0.4067
153.5800	-38.3698	0.4067
153.5967	-38.5367	0.4066
153.6133	-38.7019	0.4066
153.6300	-38.8701	0.4065
153.6467	-39.0346	0.4065
153.6633	-39.2038	0.4064
153.6800	-39.3686	0.4064
153.6967	-39.5361	0.4063
153.7133	-39.7024	0.4063
153.7300	-39.8690	0.4063
153.7467	-40.0354	0.4062
153.7633	-40.2022	0.4061
153.7800	-40.3684	0.4061
153.7967	-40.5345	0.4060
153.8133	-40.7011	0.4059
153.8300	-40.8682	0.4059
153.8467	-41.0341	0.4058
153.8633	-41.2008	0.4057
153.8800	-41.3669	0.4057
153.8967	-41.5339	0.4056
153.9133	-41.6997	0.4056
153.9300	-41.8668	0.4055
153.9467	-42.0336	0.4055
153.9633	-42.1982	0.4054
153.9800	-42.3658	0.4054
153.9967	-42.5318	0.4053
154.0133	-42.6997	0.4053
154.0300	-42.8647	0.4052
154.0467	-43.0328	0.4051
154.0633	-43.1983	0.4051
154.0800	-43.3654	0.4051
154.0967	-43.5318	0.4049
154.1133	-43.6988	0.4048
154.1300	-43.8654	0.4046
154.1467	-44.0307	0.4045
154.1633	-44.1989	0.4045
154.1800	-44.3634	0.4044
154.1967	-44.5309	0.4044
154.2133	-44.6973	0.4043
154.2300	-44.8651	0.4043
154.2467	-45.0307	0.4043
154.2633	-45.1965	0.4043
154.2800	-45.3628	0.4041
154.2967	-45.5313	0.4041
154.3133	-45.6965	0.4040
154.3300	-45.8629	0.4040
154.3467	-46.0298	0.4040
154.3633	-46.1956	0.4040
154.3800	-46.3635	0.4039
154.3967	-46.5302	0.4039
154.4133	-46.6955	0.4039
154.4300	-46.8624	0.4038
154.4467	-47.0278	0.4037
154.4633	-47.1954	0.4037
154.4800	-47.3628
154.4967	-47.5281
154.5133	-47.6951
154.5283