File: Example Date/My Sample/DSC/test01/LLM_EP_0401.txt
Filename	LLM_EP_0401
Instrument name	DSC2A-01799 (192.168.1.250)
Operator
rundate	10/02/2025
Sample name	LLM_EP_0401
proceduresegments	Ramp 10.00 °C/min to 25.0000 °C; Ramp 10.00 °C/min to 135.0000 °C; Isothermal 5.0 min; Ramp 10.00 °C/min to -50.0000 °C; Isothermal 5.0 min; Ramp 10.00 °C/min to 200.0000 °C; Isothermal 5.0 min; Ramp 10.00 °C/min to -50.0000 °C; Isothermal 5.0 min; Ramp 10.00 °C/min to 200.0000 °C; Isothermal 5.0 min; Ramp 10.00 °C/min to -50.0000 °C
[File Parameters]
Run Date	10/02/2025 14:17:57
Trios version	5.7.0.56
Original File Name
Current File Name	C:\Users\TA Instruments DSC\Desktop\Data\LLM\LLM_EP_0401.tri
User at run start	DESKTOP-CFGN8IT\TA Instruments DSC
[Procedure]
Procedure Name	LLM_EP_0401
Sample Name	LLM_EP_0401
Sample Mass	6.65 mg
Reference Sample Mass	0 mg
Pan Mass	62.19 mg
Pan Number	20
Reference Pan Mass	43.13 mg
Reference Pan Number	13
Pan Type	Tzero Aluminum Pin Hole Hermetic
Comments
Project Name
Operator
Test	Custom
Unload Max Temperature	25
Unload Min Temperature	25
FillCooler	Do not fill
Load Max Temperature	25
Load Min Temperature	25
Discard pan in waste bin at end of test	No
Stop on Gas Flow Error	No
[Signal List]
Signal #1	Time (min)
Signal #2	Temperature (°C)
Signal #3	Heat Flow (mW)
Signal #4	Delta T (µV)
Signal #5	Delta Tzero (µV)
Signal #6	Tzero Temperature (°C)
Signal #7	Cell Purge (mL/min)
Signal #8	Heater Temp (°C)
Signal #9	Power Delivered (W)
Signal #10	Reference Junction Temperature (°C)
Signal #11	Flange Temperature (°C)
Signal #12	Heat Flow Phase (rad)
Signal #13	Total Heat Capacity (J/°C)
Signal #14	Heat Capacity (J/°C)
Signal #15	LN Pump Tank level (%)
[Configuration]
Company Name	Warwick University
Instrument Name	DSC2A-01799
Instrument Type	DSC2500
Serial Number	DSC2A-01799
IP	192.168.1.250
Location of Instrument	Polymer RTP
DisplayType	TianmaV2andV3
Sample Interval 	0.1 s/pt
Selected Heat Flow	T4P
Exotherm Direction	Up
Cell Serial	DRC2-03788
Lid Type	High Temperature
Cooler	LN Pump
Leave Cooler on at End of Sequence	Off
Gas 2	Air
Gas Selected	Channel 1: Nitrogen
Flow Rate	50 mL/min
Secondary Purge	On
Licensed Heat Flow	Heat Flow T4P
Modulation Licensed	Yes
[Versions]
Common IDD Version	1
Cortex Version	VER 2.11.0.729
Driver	5.0.0.6
GDM Version	1.0.3.3
TouchscreenVersion	1.0.3.1841
FEP Version	1.2.1.21
FEP Bootloader	2.0.0.5
AutoSampler Version	2.1.2.1
Auto Sampler Bootloader	2.0.0.5
FCM Version	1.1.0.3
FCM Bootloader	2.0.0.5
LN Pump Version	10.17.0.0
LN Pump Bootloader	2.0.0.5
[Experiment Logs]
Experiment Log Entry # 1	Ramp Segment 10 C/min to 25 Started
Experiment Log Entry # 3	Air Cool is off.
Experiment Log Entry # 5	Ramp Segment 10 C/min to 135 Started
Experiment Log Entry # 7	Isothermal Segment 5 min started
Experiment Log Entry # 9	Ramp Segment 10 C/min to -50 Started
Experiment Log Entry # 11	Isothermal Segment 5 min started
Experiment Log Entry # 13	Ramp Segment 10 C/min to 200 Started
Experiment Log Entry # 16	LN2P is filling
Experiment Log Entry # 18	LN2P stopped filling
Experiment Log Entry # 19	Isothermal Segment 5 min started
Experiment Log Entry # 21	Ramp Segment 10 C/min to -50 Started
Experiment Log Entry # 23	Isothermal Segment 5 min started
Experiment Log Entry # 25	Ramp Segment 10 C/min to 200 Started
Experiment Log Entry # 27	Isothermal Segment 5 min started
Experiment Log Entry # 29	Ramp Segment 10 C/min to -50 Started
[Method Log]
Method Log Entry # 1	(Ramp 1139761) Ramp 10 °C/minute to 25 °C
Method Log Entry # 2	(Ramp 1139762) Ramp 10 °C/minute to 135 °C
Method Log Entry # 3	Isothermal 5 minutes
Method Log Entry # 4	(Ramp 1139764) Ramp 10 °C/minute to -50 °C
Method Log Entry # 5	Isothermal 5 minutes
Method Log Entry # 6	(Ramp 1139766) Ramp 10 °C/minute to 200 °C
Method Log Entry # 7	Isothermal 5 minutes
Method Log Entry # 8	(Ramp 1139768) Ramp 10 °C/minute to -50 °C
Method Log Entry # 9	Isothermal 5 minutes
Method Log Entry # 10	(Ramp 1139770) Ramp 10 °C/minute to 200 °C
Method Log Entry # 11	Isothermal 5 minutes
Method Log Entry # 12	(Ramp 1139772) Ramp 10 °C/minute to -50 °C
Cell Serial	DRC2-03788
[T1 Calibration]
Date Applied	04/03/2021 14:58:04
Slope	-0.001800291
Offset	-0.1301359
Initial Temperature	-100.6228
GUID	a1d5a6be-decd-4ae4-b22f-d560f3a78a92
[TZero Calibration]
Date Applied	03/01/2025 12:41:45
Description	From -178.795 °C to 396.200 °C at 20.000°C/min
Gas Type	Nitrogen
Pan Type	None
Source Files 1	C:\ProgramData\TA Instruments\TRIOS\Data\Tzero Cal(23).tri
Source Files 2	C:\ProgramData\TA Instruments\TRIOS\Data\Tzero Cal(24).tri
Delta T Offset	1.869383
Delta T Slope	-0.002827686
Delta T0 Offset	0.6518871
Delta T0 Slope	0.03386689
[Temperature Calibration]
Date Applied	07/01/2025 06:48:00
Description	From 106.598 °C to 186.598 °C at 10.000°C/min
Gas Type	Nitrogen
Pan Type	Aluminum Hermetic
Source Files 1	C:\ProgramData\TA Instruments\TRIOS\Data\Indium(10).tri
Measured 1	158.5387
Known 1	156.598
[Cell Constant Calibration]
Date Applied	07/01/2025 06:21:38
Description	From 106.598 °C to 186.598 °C at 10.000°C/min
Gas Type	Nitrogen
Pan Type	Aluminum Hermetic
Source Files 1	C:\ProgramData\TA Instruments\TRIOS\Data\Indium(8).tri
T4P KCell	1.071186
Onset Slope	-20.76992 mW/°C
[Direct Cp Calibration]
Date Applied	07/01/2025 08:34:40
Description	From -89.983 °C to 397.015 °C at 20.000°C/min
Gas Type	Nitrogen
Pan Type	Aluminum Hermetic
Source Files 1	C:\ProgramData\TA Instruments\TRIOS\Data\Sapphire Direct Heat Capacity(11).tri
GUID	bc2b1dd3-d0d9-41bf-ba72-b5fda717766a
Temperature	-89.98325 °C
Cp	0.9880321
Temperature	-89.00925 °C
Cp	0.9883595
Temperature	-88.03526 °C
Cp	0.9883455
Temperature	-87.06126 °C
Cp	0.9880565
Temperature	-86.08727 °C
Cp	0.9875574
Temperature	-85.11327 °C
Cp	0.9868901
Temperature	-84.13927 °C
Cp	0.9861491
Temperature	-83.16528 °C
Cp	0.9854108
Temperature	-82.19128 °C
Cp	0.9847093
Temperature	-81.21728 °C
Cp	0.984123
Temperature	-80.24328 °C
Cp	0.9836704
Temperature	-79.26929 °C
Cp	0.9834349
Temperature	-78.29529 °C
Cp	0.9833817
Temperature	-77.32129 °C
Cp	0.9835677
Temperature	-76.34729 °C
Cp	0.9839252
Temperature	-75.37329 °C
Cp	0.9844846
Temperature	-74.3993 °C
Cp	0.9852123
Temperature	-73.4253 °C
Cp	0.9860855
Temperature	-72.4513 °C
Cp	0.9870548
Temperature	-71.4773 °C
Cp	0.9881113
Temperature	-70.50331 °C
Cp	0.9892243
Temperature	-69.52931 °C
Cp	0.9903587
Temperature	-68.55531 °C
Cp	0.9915038
Temperature	-67.58131 °C
Cp	0.9926346
Temperature	-66.60732 °C
Cp	0.993748
Temperature	-65.63332 °C
Cp	0.994836
Temperature	-64.65932 °C
Cp	0.9959027
Temperature	-63.68533 °C
Cp	0.9969317
Temperature	-62.71133 °C
Cp	0.997943
Temperature	-61.73733 °C
Cp	0.9989527
Temperature	-60.76334 °C
Cp	0.9999582
Temperature	-59.78934 °C
Cp	1.000969
Temperature	-58.81534 °C
Cp	1.00194
Temperature	-57.84134 °C
Cp	1.002997
Temperature	-56.86735 °C
Cp	1.00403
Temperature	-55.89335 °C
Cp	1.005069
Temperature	-54.91935 °C
Cp	1.006104
Temperature	-53.94535 °C
Cp	1.00713
Temperature	-52.97136 °C
Cp	1.008209
Temperature	-51.99736 °C
Cp	1.009185
Temperature	-51.02336 °C
Cp	1.010177
Temperature	-50.04937 °C
Cp	1.011162
Temperature	-49.07537 °C
Cp	1.012141
Temperature	-48.10137 °C
Cp	1.01308
Temperature	-47.12737 °C
Cp	1.013991
Temperature	-46.15338 °C
Cp	1.014858
Temperature	-45.17938 °C
Cp	1.015703
Temperature	-44.20538 °C
Cp	1.016499
Temperature	-43.23138 °C
Cp	1.017257
Temperature	-42.25739 °C
Cp	1.017991
Temperature	-41.28339 °C
Cp	1.018705
Temperature	-40.30939 °C
Cp	1.019413
Temperature	-39.3354 °C
Cp	1.020126
Temperature	-38.3614 °C
Cp	1.020855
Temperature	-37.3874 °C
Cp	1.021604
Temperature	-36.4134 °C
Cp	1.022382
Temperature	-35.43941 °C
Cp	1.023185
Temperature	-34.46541 °C
Cp	1.024018
Temperature	-33.49141 °C
Cp	1.024865
Temperature	-32.51741 °C
Cp	1.025734
Temperature	-31.54342 °C
Cp	1.026615
Temperature	-30.56942 °C
Cp	1.027499
Temperature	-29.59542 °C
Cp	1.028374
Temperature	-28.62143 °C
Cp	1.029232
Temperature	-27.64743 °C
Cp	1.030081
Temperature	-26.67343 °C
Cp	1.030892
Temperature	-25.69943 °C
Cp	1.031667
Temperature	-24.72544 °C
Cp	1.032406
Temperature	-23.75144 °C
Cp	1.03311
Temperature	-22.77744 °C
Cp	1.033786
Temperature	-21.80344 °C
Cp	1.034412
Temperature	-20.82945 °C
Cp	1.035019
Temperature	-19.85545 °C
Cp	1.035599
Temperature	-18.88145 °C
Cp	1.036155
Temperature	-17.90746 °C
Cp	1.036695
Temperature	-16.93346 °C
Cp	1.037207
Temperature	-15.95946 °C
Cp	1.037712
Temperature	-14.98546 °C
Cp	1.038202
Temperature	-14.01147 °C
Cp	1.038666
Temperature	-13.03747 °C
Cp	1.039103
Temperature	-12.06347 °C
Cp	1.039518
Temperature	-11.08947 °C
Cp	1.039909
Temperature	-10.11548 °C
Cp	1.040284
Temperature	-9.14148 °C
Cp	1.040614
Temperature	-8.167483 °C
Cp	1.040915
Temperature	-7.193486 °C
Cp	1.041192
Temperature	-6.219488 °C
Cp	1.041427
Temperature	-5.245491 °C
Cp	1.041627
Temperature	-4.271494 °C
Cp	1.041773
Temperature	-3.297497 °C
Cp	1.041891
Temperature	-2.323499 °C
Cp	1.041951
Temperature	-1.349502 °C
Cp	1.041963
Temperature	-0.3755048 °C
Cp	1.041932
Temperature	0.5984925 °C
Cp	1.041862
Temperature	1.57249 °C
Cp	1.04176
Temperature	2.546487 °C
Cp	1.04162
Temperature	3.520484 °C
Cp	1.041463
Temperature	4.494482 °C
Cp	1.041297
Temperature	5.468479 °C
Cp	1.041124
Temperature	6.442476 °C
Cp	1.040949
Temperature	7.416473 °C
Cp	1.04077
Temperature	8.390471 °C
Cp	1.040596
Temperature	9.364468 °C
Cp	1.04043
Temperature	10.33846 °C
Cp	1.040276
Temperature	11.31246 °C
Cp	1.040137
Temperature	12.28646 °C
Cp	1.040014
Temperature	13.26046 °C
Cp	1.039915
Temperature	14.23445 °C
Cp	1.03984
Temperature	15.20845 °C
Cp	1.039792
Temperature	16.18245 °C
Cp	1.039777
Temperature	17.15645 °C
Cp	1.03979
Temperature	18.13044 °C
Cp	1.039834
Temperature	19.10444 °C
Cp	1.039903
Temperature	20.07844 °C
Cp	1.040019
Temperature	21.05243 °C
Cp	1.040159
Temperature	22.02643 °C
Cp	1.040318
Temperature	23.00043 °C
Cp	1.040496
Temperature	23.97443 °C
Cp	1.040695
Temperature	24.94842 °C
Cp	1.040908
Temperature	25.92242 °C
Cp	1.041143
Temperature	26.89642 °C
Cp	1.041371
Temperature	27.87042 °C
Cp	1.04161
Temperature	28.84441 °C
Cp	1.041855
Temperature	29.81841 °C
Cp	1.042094
Temperature	30.79241 °C
Cp	1.042325
Temperature	31.76641 °C
Cp	1.042534
Temperature	32.7404 °C
Cp	1.04274
Temperature	33.7144 °C
Cp	1.042917
Temperature	34.6884 °C
Cp	1.043064
Temperature	35.6624 °C
Cp	1.04319
Temperature	36.63639 °C
Cp	1.043295
Temperature	37.61039 °C
Cp	1.043386
Temperature	38.58438 °C
Cp	1.043453
Temperature	39.55838 °C
Cp	1.04351
Temperature	40.53238 °C
Cp	1.043562
Temperature	41.50638 °C
Cp	1.043611
Temperature	42.48037 °C
Cp	1.043655
Temperature	43.45437 °C
Cp	1.043698
Temperature	44.42837 °C
Cp	1.043742
Temperature	45.40237 °C
Cp	1.043786
Temperature	46.37637 °C
Cp	1.04383
Temperature	47.35036 °C
Cp	1.043871
Temperature	48.32436 °C
Cp	1.043918
Temperature	49.29836 °C
Cp	1.043969
Temperature	50.27235 °C
Cp	1.044022
Temperature	51.24635 °C
Cp	1.044086
Temperature	52.22035 °C
Cp	1.044155
Temperature	53.19434 °C
Cp	1.044236
Temperature	54.16834 °C
Cp	1.044331
Temperature	55.14234 °C
Cp	1.04443
Temperature	56.11634 °C
Cp	1.04456
Temperature	57.09034 °C
Cp	1.044703
Temperature	58.06433 °C
Cp	1.044864
Temperature	59.03833 °C
Cp	1.045041
Temperature	60.01233 °C
Cp	1.045232
Temperature	60.98632 °C
Cp	1.045442
Temperature	61.96032 °C
Cp	1.045673
Temperature	62.93432 °C
Cp	1.045911
Temperature	63.90831 °C
Cp	1.046162
Temperature	64.88231 °C
Cp	1.046425
Temperature	65.85631 °C
Cp	1.04669
Temperature	66.83031 °C
Cp	1.046952
Temperature	67.80431 °C
Cp	1.047203
Temperature	68.77831 °C
Cp	1.047453
Temperature	69.7523 °C
Cp	1.047677
Temperature	70.7263 °C
Cp	1.047882
Temperature	71.70029 °C
Cp	1.048065
Temperature	72.67429 °C
Cp	1.048226
Temperature	73.64828 °C
Cp	1.048375
Temperature	74.62228 °C
Cp	1.048498
Temperature	75.59628 °C
Cp	1.04861
Temperature	76.57028 °C
Cp	1.048713
Temperature	77.54427 °C
Cp	1.048811
Temperature	78.51827 °C
Cp	1.048901
Temperature	79.49227 °C
Cp	1.048978
Temperature	80.46627 °C
Cp	1.049068
Temperature	81.44027 °C
Cp	1.049148
Temperature	82.41426 °C
Cp	1.04922
Temperature	83.38826 °C
Cp	1.049288
Temperature	84.36226 °C
Cp	1.049353
Temperature	85.33626 °C
Cp	1.049435
Temperature	86.31025 °C
Cp	1.049486
Temperature	87.28425 °C
Cp	1.049549
Temperature	88.25825 °C
Cp	1.049615
Temperature	89.23225 °C
Cp	1.049683
Temperature	90.20624 °C
Cp	1.049742
Temperature	91.18024 °C
Cp	1.04977
Temperature	92.15424 °C
Cp	1.04982
Temperature	93.12823 °C
Cp	1.049839
Temperature	94.10223 °C
Cp	1.049829
Temperature	95.07623 °C
Cp	1.049792
Temperature	96.05022 °C
Cp	1.049731
Temperature	97.02422 °C
Cp	1.049673
Temperature	97.99822 °C
Cp	1.049564
Temperature	98.97221 °C
Cp	1.049451
Temperature	99.94621 °C
Cp	1.049339
Temperature	100.9202 °C
Cp	1.049223
Temperature	101.8942 °C
Cp	1.049111
Temperature	102.8682 °C
Cp	1.048998
Temperature	103.8422 °C
Cp	1.048886
Temperature	104.8162 °C
Cp	1.048782
Temperature	105.7902 °C
Cp	1.048679
Temperature	106.7642 °C
Cp	1.048577
Temperature	107.7382 °C
Cp	1.048481
Temperature	108.7122 °C
Cp	1.048391
Temperature	109.6862 °C
Cp	1.048309
Temperature	110.6602 °C
Cp	1.048232
Temperature	111.6342 °C
Cp	1.04816
Temperature	112.6082 °C
Cp	1.048096
Temperature	113.5822 °C
Cp	1.048038
Temperature	114.5562 °C
Cp	1.047984
Temperature	115.5302 °C
Cp	1.047932
Temperature	116.5042 °C
Cp	1.047888
Temperature	117.4782 °C
Cp	1.047844
Temperature	118.4522 °C
Cp	1.047801
Temperature	119.4262 °C
Cp	1.047756
Temperature	120.4002 °C
Cp	1.047715
Temperature	121.3742 °C
Cp	1.047678
Temperature	122.3482 °C
Cp	1.047638
Temperature	123.3222 °C
Cp	1.047605
Temperature	124.2961 °C
Cp	1.047578
Temperature	125.2701 °C
Cp	1.047555
Temperature	126.2441 °C
Cp	1.047539
Temperature	127.2181 °C
Cp	1.047525
Temperature	128.1921 °C
Cp	1.047524
Temperature	129.1661 °C
Cp	1.047527
Temperature	130.1401 °C
Cp	1.047536
Temperature	131.1141 °C
Cp	1.047554
Temperature	132.0881 °C
Cp	1.047582
Temperature	133.0621 °C
Cp	1.047624
Temperature	134.0361 °C
Cp	1.047662
Temperature	135.0101 °C
Cp	1.047714
Temperature	135.9841 °C
Cp	1.047779
Temperature	136.9581 °C
Cp	1.047853
Temperature	137.9321 °C
Cp	1.047933
Temperature	138.9061 °C
Cp	1.048018
Temperature	139.8801 °C
Cp	1.048097
Temperature	140.8541 °C
Cp	1.048188
Temperature	141.8281 °C
Cp	1.048267
Temperature	142.8021 °C
Cp	1.048337
Temperature	143.7761 °C
Cp	1.048398
Temperature	144.7501 °C
Cp	1.048449
Temperature	145.7241 °C
Cp	1.048503
Temperature	146.6981 °C
Cp	1.048532
Temperature	147.6721 °C
Cp	1.04856
Temperature	148.6461 °C
Cp	1.048587
Temperature	149.6201 °C
Cp	1.04861
Temperature	150.5941 °C
Cp	1.048628
Temperature	151.5681 °C
Cp	1.048627
Temperature	152.5421 °C
Cp	1.048642
Temperature	153.5161 °C
Cp	1.048646
Temperature	154.4901 °C
Cp	1.048642
Temperature	155.4641 °C
Cp	1.048638
Temperature	156.438 °C
Cp	1.048641
Temperature	157.412 °C
Cp	1.048673
Temperature	158.386 °C
Cp	1.048706
Temperature	159.36 °C
Cp	1.048776
Temperature	160.334 °C
Cp	1.048889
Temperature	161.308 °C
Cp	1.049047
Temperature	162.282 °C
Cp	1.049254
Temperature	163.256 °C
Cp	1.049495
Temperature	164.23 °C
Cp	1.049811
Temperature	165.204 °C
Cp	1.050172
Temperature	166.178 °C
Cp	1.050582
Temperature	167.152 °C
Cp	1.051038
Temperature	168.126 °C
Cp	1.051542
Temperature	169.1 °C
Cp	1.052114
Temperature	170.074 °C
Cp	1.052695
Temperature	171.048 °C
Cp	1.053323
Temperature	172.022 °C
Cp	1.053989
Temperature	172.996 °C
Cp	1.05468
Temperature	173.97 °C
Cp	1.055383
Temperature	174.944 °C
Cp	1.056084
Temperature	175.918 °C
Cp	1.056758
Temperature	176.892 °C
Cp	1.057421
Temperature	177.866 °C
Cp	1.058033
Temperature	178.84 °C
Cp	1.058585
Temperature	179.814 °C
Cp	1.059071
Temperature	180.788 °C
Cp	1.059486
Temperature	181.762 °C
Cp	1.059844
Temperature	182.736 °C
Cp	1.060098
Temperature	183.71 °C
Cp	1.060287
Temperature	184.684 °C
Cp	1.06041
Temperature	185.658 °C
Cp	1.060463
Temperature	186.632 °C
Cp	1.060444
Temperature	187.606 °C
Cp	1.060339
Temperature	188.58 °C
Cp	1.060207
Temperature	189.554 °C
Cp	1.060006
Temperature	190.528 °C
Cp	1.059754
Temperature	191.502 °C
Cp	1.059464
Temperature	192.476 °C
Cp	1.059152
Temperature	193.45 °C
Cp	1.05885
Temperature	194.424 °C
Cp	1.058521
Temperature	195.3979 °C
Cp	1.05822
Temperature	196.3719 °C
Cp	1.057951
Temperature	197.3459 °C
Cp	1.057719
Temperature	198.3199 °C
Cp	1.057524
Temperature	199.2939 °C
Cp	1.057347
Temperature	200.2679 °C
Cp	1.057229
Temperature	201.2419 °C
Cp	1.05713
Temperature	202.2159 °C
Cp	1.05705
Temperature	203.1899 °C
Cp	1.056984
Temperature	204.1639 °C
Cp	1.05693
Temperature	205.1379 °C
Cp	1.0569
Temperature	206.1119 °C
Cp	1.05685
Temperature	207.0859 °C
Cp	1.056808
Temperature	208.0599 °C
Cp	1.05677
Temperature	209.0339 °C
Cp	1.05673
Temperature	210.0079 °C
Cp	1.056685
Temperature	210.9819 °C
Cp	1.056633
Temperature	211.9559 °C
Cp	1.056566
Temperature	212.9299 °C
Cp	1.056501
Temperature	213.9039 °C
Cp	1.056424
Temperature	214.8779 °C
Cp	1.056341
Temperature	215.8519 °C
Cp	1.056252
Temperature	216.8259 °C
Cp	1.056168
Temperature	217.7999 °C
Cp	1.0561
Temperature	218.7739 °C
Cp	1.056026
Temperature	219.7479 °C
Cp	1.055973
Temperature	220.7219 °C
Cp	1.055941
Temperature	221.6959 °C
Cp	1.055926
Temperature	222.6699 °C
Cp	1.055924
Temperature	223.6439 °C
Cp	1.055919
Temperature	224.6179 °C
Cp	1.055941
Temperature	225.5919 °C
Cp	1.055954
Temperature	226.5659 °C
Cp	1.055958
Temperature	227.5399 °C
Cp	1.055954
Temperature	228.5139 °C
Cp	1.055943
Temperature	229.4879 °C
Cp	1.055938
Temperature	230.4619 °C
Cp	1.055901
Temperature	231.4359 °C
Cp	1.055866
Temperature	232.4098 °C
Cp	1.055832
Temperature	233.3838 °C
Cp	1.055797
Temperature	234.3578 °C
Cp	1.055757
Temperature	235.3318 °C
Cp	1.055695
Temperature	236.3058 °C
Cp	1.055658
Temperature	237.2798 °C
Cp	1.055607
Temperature	238.2538 °C
Cp	1.055547
Temperature	239.2278 °C
Cp	1.055481
Temperature	240.2018 °C
Cp	1.055414
Temperature	241.1758 °C
Cp	1.055372
Temperature	242.1498 °C
Cp	1.055303
Temperature	243.1238 °C
Cp	1.055254
Temperature	244.0978 °C
Cp	1.055227
Temperature	245.0718 °C
Cp	1.055215
Temperature	246.0458 °C
Cp	1.055219
Temperature	247.0198 °C
Cp	1.055213
Temperature	247.9938 °C
Cp	1.055252
Temperature	248.9678 °C
Cp	1.055289
Temperature	249.9418 °C
Cp	1.055323
Temperature	250.9158 °C
Cp	1.055358
Temperature	251.8898 °C
Cp	1.055391
Temperature	252.8638 °C
Cp	1.055427
Temperature	253.8378 °C
Cp	1.05547
Temperature	254.8118 °C
Cp	1.055506
Temperature	255.7858 °C
Cp	1.055552
Temperature	256.7598 °C
Cp	1.055605
Temperature	257.7338 °C
Cp	1.055662
Temperature	258.7078 °C
Cp	1.055723
Temperature	259.6818 °C
Cp	1.055782
Temperature	260.6558 °C
Cp	1.055847
Temperature	261.6298 °C
Cp	1.055909
Temperature	262.6038 °C
Cp	1.055965
Temperature	263.5778 °C
Cp	1.05602
Temperature	264.5518 °C
Cp	1.056073
Temperature	265.5258 °C
Cp	1.056125
Temperature	266.4998 °C
Cp	1.056176
Temperature	267.4738 °C
Cp	1.05623
Temperature	268.4478 °C
Cp	1.056288
Temperature	269.4218 °C
Cp	1.056349
Temperature	270.3957 °C
Cp	1.056416
Temperature	271.3697 °C
Cp	1.056491
Temperature	272.3437 °C
Cp	1.056571
Temperature	273.3177 °C
Cp	1.056658
Temperature	274.2917 °C
Cp	1.05675
Temperature	275.2657 °C
Cp	1.056848
Temperature	276.2397 °C
Cp	1.056947
Temperature	277.2137 °C
Cp	1.057042
Temperature	278.1877 °C
Cp	1.057142
Temperature	279.1617 °C
Cp	1.057233
Temperature	280.1357 °C
Cp	1.057313
Temperature	281.1097 °C
Cp	1.057381
Temperature	282.0837 °C
Cp	1.057435
Temperature	283.0577 °C
Cp	1.057481
Temperature	284.0317 °C
Cp	1.057495
Temperature	285.0057 °C
Cp	1.057498
Temperature	285.9797 °C
Cp	1.057486
Temperature	286.9537 °C
Cp	1.057462
Temperature	287.9277 °C
Cp	1.057423
Temperature	288.9017 °C
Cp	1.057373
Temperature	289.8757 °C
Cp	1.05731
Temperature	290.8497 °C
Cp	1.057244
Temperature	291.8237 °C
Cp	1.057169
Temperature	292.7977 °C
Cp	1.057092
Temperature	293.7717 °C
Cp	1.057015
Temperature	294.7457 °C
Cp	1.05694
Temperature	295.7197 °C
Cp	1.056872
Temperature	296.6937 °C
Cp	1.056808
Temperature	297.6677 °C
Cp	1.056752
Temperature	298.6417 °C
Cp	1.056704
Temperature	299.6157 °C
Cp	1.056662
Temperature	300.5897 °C
Cp	1.056626
Temperature	301.5637 °C
Cp	1.05659
Temperature	302.5377 °C
Cp	1.056563
Temperature	303.5117 °C
Cp	1.056535
Temperature	304.4856 °C
Cp	1.056507
Temperature	305.4596 °C
Cp	1.05648
Temperature	306.4336 °C
Cp	1.056456
Temperature	307.4076 °C
Cp	1.056444
Temperature	308.3816 °C
Cp	1.056429
Temperature	309.3556 °C
Cp	1.056431
Temperature	310.3296 °C
Cp	1.056452
Temperature	311.3036 °C
Cp	1.056492
Temperature	312.2776 °C
Cp	1.056555
Temperature	313.2516 °C
Cp	1.056631
Temperature	314.2256 °C
Cp	1.056748
Temperature	315.1996 °C
Cp	1.056883
Temperature	316.1736 °C
Cp	1.057038
Temperature	317.1476 °C
Cp	1.057212
Temperature	318.1216 °C
Cp	1.057405
Temperature	319.0956 °C
Cp	1.057631
Temperature	320.0696 °C
Cp	1.057845
Temperature	321.0436 °C
Cp	1.058079
Temperature	322.0176 °C
Cp	1.058326
Temperature	322.9916 °C
Cp	1.058582
Temperature	323.9656 °C
Cp	1.058841
Temperature	324.9396 °C
Cp	1.059099
Temperature	325.9136 °C
Cp	1.059348
Temperature	326.8876 °C
Cp	1.059604
Temperature	327.8616 °C
Cp	1.05985
Temperature	328.8356 °C
Cp	1.060092
Temperature	329.8096 °C
Cp	1.060333
Temperature	330.7836 °C
Cp	1.060579
Temperature	331.7576 °C
Cp	1.060841
Temperature	332.7316 °C
Cp	1.061109
Temperature	333.7056 °C
Cp	1.061398
Temperature	334.6796 °C
Cp	1.061709
Temperature	335.6536 °C
Cp	1.062038
Temperature	336.6276 °C
Cp	1.062384
Temperature	337.6016 °C
Cp	1.062742
Temperature	338.5755 °C
Cp	1.063104
Temperature	339.5495 °C
Cp	1.063464
Temperature	340.5235 °C
Cp	1.063814
Temperature	341.4975 °C
Cp	1.064146
Temperature	342.4715 °C
Cp	1.064453
Temperature	343.4455 °C
Cp	1.064728
Temperature	344.4195 °C
Cp	1.06497
Temperature	345.3935 °C
Cp	1.065176
Temperature	346.3675 °C
Cp	1.065346
Temperature	347.3415 °C
Cp	1.065484
Temperature	348.3155 °C
Cp	1.065596
Temperature	349.2895 °C
Cp	1.065687
Temperature	350.2635 °C
Cp	1.065775
Temperature	351.2375 °C
Cp	1.065862
Temperature	352.2115 °C
Cp	1.06596
Temperature	353.1855 °C
Cp	1.066075
Temperature	354.1595 °C
Cp	1.066217
Temperature	355.1335 °C
Cp	1.066395
Temperature	356.1075 °C
Cp	1.06659
Temperature	357.0815 °C
Cp	1.066817
Temperature	358.0555 °C
Cp	1.067067
Temperature	359.0295 °C
Cp	1.067329
Temperature	360.0035 °C
Cp	1.067591
Temperature	360.9775 °C
Cp	1.067838
Temperature	361.9515 °C
Cp	1.068055
Temperature	362.9255 °C
Cp	1.068232
Temperature	363.8995 °C
Cp	1.068357
Temperature	364.8735 °C
Cp	1.068423
Temperature	365.8475 °C
Cp	1.068431
Temperature	366.8215 °C
Cp	1.068385
Temperature	367.7955 °C
Cp	1.068293
Temperature	368.7695 °C
Cp	1.068177
Temperature	369.7435 °C
Cp	1.068051
Temperature	370.7175 °C
Cp	1.067937
Temperature	371.6914 °C
Cp	1.067864
Temperature	372.6654 °C
Cp	1.067851
Temperature	373.6394 °C
Cp	1.067924
Temperature	374.6134 °C
Cp	1.068083
Temperature	375.5874 °C
Cp	1.068344
Temperature	376.5614 °C
Cp	1.068699
Temperature	377.5354 °C
Cp	1.069131
Temperature	378.5094 °C
Cp	1.069605
Temperature	379.4834 °C
Cp	1.070071
Temperature	380.4574 °C
Cp	1.070487
Temperature	381.4314 °C
Cp	1.07077
Temperature	382.4054 °C
Cp	1.070846
Temperature	383.3794 °C
Cp	1.070635
Temperature	384.3534 °C
Cp	1.070055
Temperature	385.3274 °C
Cp	1.069033
Temperature	386.3014 °C
Cp	1.067489
Temperature	387.2754 °C
Cp	1.065378
Temperature	388.2494 °C
Cp	1.062665
Temperature	389.2234 °C
Cp	1.059324
Temperature	390.1974 °C
Cp	1.055366
Temperature	391.1714 °C
Cp	1.050821
Temperature	392.1454 °C
Cp	1.045742
Temperature	393.1194 °C
Cp	1.040203
Temperature	394.0934 °C
Cp	1.034295
Temperature	395.0674 °C
Cp	1.028124
Temperature	396.0414 °C
Cp	1.021801
[Rev Cp Calibration]
Date Applied	07/01/2025 13:18:35
Description	From -90.000 °C to 391.202 °C at 2.000°C/min
Gas Type	Nitrogen
Pan Type	Aluminum Hermetic
Source Files 1	C:\ProgramData\TA Instruments\TRIOS\Data\Reverse Heat Capacity Calibration(8).tri
GUID	2f9866b8-ce4e-42f5-95a1-c21443fc3171
Temperature	-89.99985 °C
Cp	1.026385
Temperature	-89.03745 °C
Cp	1.030641
Temperature	-88.07504 °C
Cp	1.034621
Temperature	-87.11264 °C
Cp	1.038235
Temperature	-86.15024 °C
Cp	1.041454
Temperature	-85.18784 °C
Cp	1.044296
Temperature	-84.22543 °C
Cp	1.04679
Temperature	-83.26302 °C
Cp	1.048951
Temperature	-82.30062 °C
Cp	1.050818
Temperature	-81.33822 °C
Cp	1.052404
Temperature	-80.37582 °C
Cp	1.053789
Temperature	-79.41341 °C
Cp	1.055011
Temperature	-78.45101 °C
Cp	1.056107
Temperature	-77.48861 °C
Cp	1.05712
Temperature	-76.52621 °C
Cp	1.058067
Temperature	-75.5638 °C
Cp	1.059033
Temperature	-74.6014 °C
Cp	1.060008
Temperature	-73.639 °C
Cp	1.06102
Temperature	-72.67659 °C
Cp	1.062091
Temperature	-71.71419 °C
Cp	1.06324
Temperature	-70.75179 °C
Cp	1.064487
Temperature	-69.78938 °C
Cp	1.065824
Temperature	-68.82698 °C
Cp	1.067263
Temperature	-67.86458 °C
Cp	1.068802
Temperature	-66.90218 °C
Cp	1.070434
Temperature	-65.93977 °C
Cp	1.07215
Temperature	-64.97737 °C
Cp	1.073961
Temperature	-64.01497 °C
Cp	1.07579
Temperature	-63.05256 °C
Cp	1.077675
Temperature	-62.09016 °C
Cp	1.0796
Temperature	-61.12776 °C
Cp	1.081549
Temperature	-60.16536 °C
Cp	1.083507
Temperature	-59.20295 °C
Cp	1.085459
Temperature	-58.24055 °C
Cp	1.087374
Temperature	-57.27814 °C
Cp	1.089301
Temperature	-56.31574 °C
Cp	1.091179
Temperature	-55.35334 °C
Cp	1.09301
Temperature	-54.39093 °C
Cp	1.094799
Temperature	-53.42853 °C
Cp	1.09655
Temperature	-52.46613 °C
Cp	1.098302
Temperature	-51.50373 °C
Cp	1.099969
Temperature	-50.54132 °C
Cp	1.101634
Temperature	-49.57892 °C
Cp	1.103291
Temperature	-48.61652 °C
Cp	1.104934
Temperature	-47.65411 °C
Cp	1.106558
Temperature	-46.69171 °C
Cp	1.108129
Temperature	-45.72931 °C
Cp	1.109722
Temperature	-44.76691 °C
Cp	1.111267
Temperature	-43.8045 °C
Cp	1.112769
Temperature	-42.8421 °C
Cp	1.11423
Temperature	-41.8797 °C
Cp	1.115656
Temperature	-40.91729 °C
Cp	1.117056
Temperature	-39.95489 °C
Cp	1.118417
Temperature	-38.99249 °C
Cp	1.119757
Temperature	-38.03008 °C
Cp	1.121077
Temperature	-37.06768 °C
Cp	1.12238
Temperature	-36.10528 °C
Cp	1.123667
Temperature	-35.14288 °C
Cp	1.124939
Temperature	-34.18047 °C
Cp	1.126202
Temperature	-33.21807 °C
Cp	1.127441
Temperature	-32.25566 °C
Cp	1.128669
Temperature	-31.29326 °C
Cp	1.129881
Temperature	-30.33086 °C
Cp	1.131073
Temperature	-29.36846 °C
Cp	1.13224
Temperature	-28.40605 °C
Cp	1.133372
Temperature	-27.44365 °C
Cp	1.134479
Temperature	-26.48125 °C
Cp	1.135545
Temperature	-25.51884 °C
Cp	1.136566
Temperature	-24.55644 °C
Cp	1.13754
Temperature	-23.59404 °C
Cp	1.138466
Temperature	-22.63164 °C
Cp	1.139347
Temperature	-21.66923 °C
Cp	1.140172
Temperature	-20.70683 °C
Cp	1.140951
Temperature	-19.74443 °C
Cp	1.141683
Temperature	-18.78202 °C
Cp	1.14237
Temperature	-17.81962 °C
Cp	1.143013
Temperature	-16.85722 °C
Cp	1.143601
Temperature	-15.89482 °C
Cp	1.14417
Temperature	-14.93241 °C
Cp	1.144696
Temperature	-13.97001 °C
Cp	1.145184
Temperature	-13.00761 °C
Cp	1.145641
Temperature	-12.0452 °C
Cp	1.14607
Temperature	-11.0828 °C
Cp	1.146477
Temperature	-10.1204 °C
Cp	1.146876
Temperature	-9.157994 °C
Cp	1.147244
Temperature	-8.195591 °C
Cp	1.147609
Temperature	-7.233188 °C
Cp	1.147968
Temperature	-6.270785 °C
Cp	1.148321
Temperature	-5.308382 °C
Cp	1.148663
Temperature	-4.345979 °C
Cp	1.148978
Temperature	-3.383576 °C
Cp	1.149303
Temperature	-2.421173 °C
Cp	1.1496
Temperature	-1.45877 °C
Cp	1.149872
Temperature	-0.496367 °C
Cp	1.150121
Temperature	0.466036 °C
Cp	1.15035
Temperature	1.428439 °C
Cp	1.150573
Temperature	2.390842 °C
Cp	1.150761
Temperature	3.353245 °C
Cp	1.150942
Temperature	4.315648 °C
Cp	1.151115
Temperature	5.278051 °C
Cp	1.151279
Temperature	6.240454 °C
Cp	1.151435
Temperature	7.202857 °C
Cp	1.151582
Temperature	8.16526 °C
Cp	1.151718
Temperature	9.127664 °C
Cp	1.151844
Temperature	10.09007 °C
Cp	1.151962
Temperature	11.05247 °C
Cp	1.152071
Temperature	12.01487 °C
Cp	1.152174
Temperature	12.97727 °C
Cp	1.15227
Temperature	13.93968 °C
Cp	1.152361
Temperature	14.90208 °C
Cp	1.15245
Temperature	15.86448 °C
Cp	1.152536
Temperature	16.82689 °C
Cp	1.152622
Temperature	17.78929 °C
Cp	1.152709
Temperature	18.75169 °C
Cp	1.152799
Temperature	19.7141 °C
Cp	1.152883
Temperature	20.6765 °C
Cp	1.152982
Temperature	21.6389 °C
Cp	1.15308
Temperature	22.60131 °C
Cp	1.153177
Temperature	23.56371 °C
Cp	1.153276
Temperature	24.52611 °C
Cp	1.153377
Temperature	25.48851 °C
Cp	1.153497
Temperature	26.45092 °C
Cp	1.153591
Temperature	27.41332 °C
Cp	1.153695
Temperature	28.37572 °C
Cp	1.153804
Temperature	29.33813 °C
Cp	1.153913
Temperature	30.30053 °C
Cp	1.154015
Temperature	31.26293 °C
Cp	1.154087
Temperature	32.22533 °C
Cp	1.154174
Temperature	33.18774 °C
Cp	1.154232
Temperature	34.15014 °C
Cp	1.154263
Temperature	35.11255 °C
Cp	1.154269
Temperature	36.07495 °C
Cp	1.154254
Temperature	37.03735 °C
Cp	1.154231
Temperature	37.99975 °C
Cp	1.154176
Temperature	38.96216 °C
Cp	1.154116
Temperature	39.92456 °C
Cp	1.154055
Temperature	40.88696 °C
Cp	1.153996
Temperature	41.84937 °C
Cp	1.153939
Temperature	42.81177 °C
Cp	1.153889
Temperature	43.77417 °C
Cp	1.153844
Temperature	44.73658 °C
Cp	1.153811
Temperature	45.69898 °C
Cp	1.153786
Temperature	46.66138 °C
Cp	1.153769
Temperature	47.62378 °C
Cp	1.153761
Temperature	48.58619 °C
Cp	1.153762
Temperature	49.54859 °C
Cp	1.153771
Temperature	50.51099 °C
Cp	1.153783
Temperature	51.4734 °C
Cp	1.1538
Temperature	52.4358 °C
Cp	1.153821
Temperature	53.3982 °C
Cp	1.153843
Temperature	54.3606 °C
Cp	1.153865
Temperature	55.32301 °C
Cp	1.153879
Temperature	56.28541 °C
Cp	1.153902
Temperature	57.24781 °C
Cp	1.15392
Temperature	58.21022 °C
Cp	1.153935
Temperature	59.17262 °C
Cp	1.15395
Temperature	60.13502 °C
Cp	1.153968
Temperature	61.09743 °C
Cp	1.154004
Temperature	62.05983 °C
Cp	1.154027
Temperature	63.02223 °C
Cp	1.154066
Temperature	63.98463 °C
Cp	1.154123
Temperature	64.94704 °C
Cp	1.154196
Temperature	65.90944 °C
Cp	1.154283
Temperature	66.87184 °C
Cp	1.154383
Temperature	67.83424 °C
Cp	1.154487
Temperature	68.79665 °C
Cp	1.15461
Temperature	69.75906 °C
Cp	1.154733
Temperature	70.72146 °C
Cp	1.154854
Temperature	71.68386 °C
Cp	1.154973
Temperature	72.64626 °C
Cp	1.155089
Temperature	73.60867 °C
Cp	1.15521
Temperature	74.57107 °C
Cp	1.15531
Temperature	75.53347 °C
Cp	1.155409
Temperature	76.49587 °C
Cp	1.155506
Temperature	77.45827 °C
Cp	1.155596
Temperature	78.42068 °C
Cp	1.155678
Temperature	79.38308 °C
Cp	1.155733
Temperature	80.34549 °C
Cp	1.155807
Temperature	81.30789 °C
Cp	1.155861
Temperature	82.27029 °C
Cp	1.155901
Temperature	83.2327 °C
Cp	1.155933
Temperature	84.1951 °C
Cp	1.155961
Temperature	85.1575 °C
Cp	1.156017
Temperature	86.1199 °C
Cp	1.156039
Temperature	87.08231 °C
Cp	1.156086
Temperature	88.04471 °C
Cp	1.156157
Temperature	89.00711 °C
Cp	1.156251
Temperature	89.96951 °C
Cp	1.156367
Temperature	90.93192 °C
Cp	1.156501
Temperature	91.89433 °C
Cp	1.156642
Temperature	92.85673 °C
Cp	1.156814
Temperature	93.81913 °C
Cp	1.156988
Temperature	94.78153 °C
Cp	1.157165
Temperature	95.74393 °C
Cp	1.157348
Temperature	96.70634 °C
Cp	1.157536
Temperature	97.66874 °C
Cp	1.15774
Temperature	98.63114 °C
Cp	1.157933
Temperature	99.59354 °C
Cp	1.158139
Temperature	100.5559 °C
Cp	1.158354
Temperature	101.5184 °C
Cp	1.158574
Temperature	102.4808 °C
Cp	1.158796
Temperature	103.4432 °C
Cp	1.15901
Temperature	104.4056 °C
Cp	1.159229
Temperature	105.368 °C
Cp	1.159435
Temperature	106.3304 °C
Cp	1.159626
Temperature	107.2928 °C
Cp	1.159803
Temperature	108.2552 °C
Cp	1.159964
Temperature	109.2176 °C
Cp	1.160111
Temperature	110.18 °C
Cp	1.160234
Temperature	111.1424 °C
Cp	1.160342
Temperature	112.1048 °C
Cp	1.160432
Temperature	113.0672 °C
Cp	1.160504
Temperature	114.0296 °C
Cp	1.160558
Temperature	114.992 °C
Cp	1.160594
Temperature	115.9544 °C
Cp	1.16061
Temperature	116.9168 °C
Cp	1.160614
Temperature	117.8792 °C
Cp	1.160601
Temperature	118.8416 °C
Cp	1.160574
Temperature	119.804 °C
Cp	1.160534
Temperature	120.7664 °C
Cp	1.160485
Temperature	121.7288 °C
Cp	1.160433
Temperature	122.6912 °C
Cp	1.160372
Temperature	123.6536 °C
Cp	1.160313
Temperature	124.616 °C
Cp	1.160255
Temperature	125.5784 °C
Cp	1.160201
Temperature	126.5408 °C
Cp	1.16015
Temperature	127.5032 °C
Cp	1.160101
Temperature	128.4656 °C
Cp	1.160059
Temperature	129.428 °C
Cp	1.16002
Temperature	130.3904 °C
Cp	1.159983
Temperature	131.3528 °C
Cp	1.159948
Temperature	132.3152 °C
Cp	1.159916
Temperature	133.2776 °C
Cp	1.159893
Temperature	134.2401 °C
Cp	1.15986
Temperature	135.2025 °C
Cp	1.159833
Temperature	136.1649 °C
Cp	1.15981
Temperature	137.1273 °C
Cp	1.159789
Temperature	138.0897 °C
Cp	1.159769
Temperature	139.0521 °C
Cp	1.15973
Temperature	140.0145 °C
Cp	1.159723
Temperature	140.9769 °C
Cp	1.159706
Temperature	141.9393 °C
Cp	1.159682
Temperature	142.9017 °C
Cp	1.159653
Temperature	143.8641 °C
Cp	1.159625
Temperature	144.8265 °C
Cp	1.159599
Temperature	145.7889 °C
Cp	1.15959
Temperature	146.7513 °C
Cp	1.15957
Temperature	147.7137 °C
Cp	1.159569
Temperature	148.6761 °C
Cp	1.159584
Temperature	149.6385 °C
Cp	1.159613
Temperature	150.6009 °C
Cp	1.159654
Temperature	151.5633 °C
Cp	1.15969
Temperature	152.5257 °C
Cp	1.159761
Temperature	153.4881 °C
Cp	1.159829
Temperature	154.4505 °C
Cp	1.159901
Temperature	155.4129 °C
Cp	1.159981
Temperature	156.3753 °C
Cp	1.160076
Temperature	157.3377 °C
Cp	1.160207
Temperature	158.3001 °C
Cp	1.160336
Temperature	159.2625 °C
Cp	1.160508
Temperature	160.2249 °C
Cp	1.160724
Temperature	161.1873 °C
Cp	1.160986
Temperature	162.1497 °C
Cp	1.161296
Temperature	163.1122 °C
Cp	1.161639
Temperature	164.0746 °C
Cp	1.162062
Temperature	165.037 °C
Cp	1.162527
Temperature	165.9994 °C
Cp	1.163037
Temperature	166.9618 °C
Cp	1.163591
Temperature	167.9242 °C
Cp	1.164188
Temperature	168.8866 °C
Cp	1.164826
Temperature	169.849 °C
Cp	1.165508
Temperature	170.8114 °C
Cp	1.166203
Temperature	171.7738 °C
Cp	1.166927
Temperature	172.7362 °C
Cp	1.167664
Temperature	173.6986 °C
Cp	1.168401
Temperature	174.661 °C
Cp	1.169124
Temperature	175.6234 °C
Cp	1.169799
Temperature	176.5858 °C
Cp	1.170462
Temperature	177.5482 °C
Cp	1.171058
Temperature	178.5106 °C
Cp	1.171581
Temperature	179.473 °C
Cp	1.172029
Temperature	180.4354 °C
Cp	1.1724
Temperature	181.3978 °C
Cp	1.172722
Temperature	182.3602 °C
Cp	1.172924
Temperature	183.3226 °C
Cp	1.173072
Temperature	184.285 °C
Cp	1.173165
Temperature	185.2474 °C
Cp	1.173204
Temperature	186.2098 °C
Cp	1.173191
Temperature	187.1722 °C
Cp	1.173098
Temperature	188.1346 °C
Cp	1.173022
Temperature	189.097 °C
Cp	1.172893
Temperature	190.0594 °C
Cp	1.172727
Temperature	191.0218 °C
Cp	1.172536
Temperature	191.9842 °C
Cp	1.172333
Temperature	192.9466 °C
Cp	1.172129
Temperature	193.909 °C
Cp	1.171948
Temperature	194.8714 °C
Cp	1.171764
Temperature	195.8338 °C
Cp	1.171616
Temperature	196.7962 °C
Cp	1.171503
Temperature	197.7587 °C
Cp	1.171422
Temperature	198.7211 °C
Cp	1.171373
Temperature	199.6835 °C
Cp	1.171339
Temperature	200.6459 °C
Cp	1.171347
Temperature	201.6083 °C
Cp	1.171366
Temperature	202.5707 °C
Cp	1.171394
Temperature	203.5331 °C
Cp	1.171431
Temperature	204.4955 °C
Cp	1.171476
Temperature	205.4579 °C
Cp	1.17154
Temperature	206.4203 °C
Cp	1.171593
Temperature	207.3827 °C
Cp	1.171659
Temperature	208.3451 °C
Cp	1.171737
Temperature	209.3075 °C
Cp	1.171824
Temperature	210.2699 °C
Cp	1.171918
Temperature	211.2323 °C
Cp	1.172
Temperature	212.1947 °C
Cp	1.172116
Temperature	213.1571 °C
Cp	1.172226
Temperature	214.1195 °C
Cp	1.172333
Temperature	215.0819 °C
Cp	1.172439
Temperature	216.0443 °C
Cp	1.172549
Temperature	217.0067 °C
Cp	1.172689
Temperature	217.9691 °C
Cp	1.172792
Temperature	218.9315 °C
Cp	1.172914
Temperature	219.8939 °C
Cp	1.173052
Temperature	220.8563 °C
Cp	1.173203
Temperature	221.8187 °C
Cp	1.173361
Temperature	222.7811 °C
Cp	1.173523
Temperature	223.7435 °C
Cp	1.173674
Temperature	224.7059 °C
Cp	1.173842
Temperature	225.6683 °C
Cp	1.173995
Temperature	226.6307 °C
Cp	1.174137
Temperature	227.5932 °C
Cp	1.174268
Temperature	228.5556 °C
Cp	1.174393
Temperature	229.518 °C
Cp	1.174531
Temperature	230.4804 °C
Cp	1.174642
Temperature	231.4428 °C
Cp	1.174766
Temperature	232.4052 °C
Cp	1.174902
Temperature	233.3676 °C
Cp	1.175049
Temperature	234.33 °C
Cp	1.175206
Temperature	235.2924 °C
Cp	1.175351
Temperature	236.2548 °C
Cp	1.175539
Temperature	237.2172 °C
Cp	1.175721
Temperature	238.1796 °C
Cp	1.175902
Temperature	239.142 °C
Cp	1.176085
Temperature	240.1044 °C
Cp	1.176272
Temperature	241.0668 °C
Cp	1.176491
Temperature	242.0292 °C
Cp	1.176676
Temperature	242.9916 °C
Cp	1.176882
Temperature	243.954 °C
Cp	1.177106
Temperature	244.9164 °C
Cp	1.177343
Temperature	245.8788 °C
Cp	1.177589
Temperature	246.8412 °C
Cp	1.17784
Temperature	247.8036 °C
Cp	1.17808
Temperature	248.766 °C
Cp	1.178334
Temperature	249.7284 °C
Cp	1.178575
Temperature	250.6908 °C
Cp	1.178803
Temperature	251.6532 °C
Cp	1.17902
Temperature	252.6156 °C
Cp	1.179227
Temperature	253.578 °C
Cp	1.179435
Temperature	254.5404 °C
Cp	1.17962
Temperature	255.5028 °C
Cp	1.179806
Temperature	256.4652 °C
Cp	1.179992
Temperature	257.4276 °C
Cp	1.180176
Temperature	258.39 °C
Cp	1.180356
Temperature	259.3524 °C
Cp	1.180525
Temperature	260.3148 °C
Cp	1.180699
Temperature	261.2773 °C
Cp	1.18086
Temperature	262.2397 °C
Cp	1.181011
Temperature	263.2021 °C
Cp	1.18115
Temperature	264.1645 °C
Cp	1.181279
Temperature	265.1269 °C
Cp	1.181398
Temperature	266.0893 °C
Cp	1.181504
Temperature	267.0517 °C
Cp	1.1816
Temperature	268.0141 °C
Cp	1.181687
Temperature	268.9765 °C
Cp	1.181765
Temperature	269.9389 °C
Cp	1.181835
Temperature	270.9013 °C
Cp	1.181897
Temperature	271.8637 °C
Cp	1.181952
Temperature	272.8261 °C
Cp	1.182001
Temperature	273.7885 °C
Cp	1.182045
Temperature	274.7509 °C
Cp	1.182086
Temperature	275.7133 °C
Cp	1.182126
Temperature	276.6757 °C
Cp	1.182166
Temperature	277.6381 °C
Cp	1.182204
Temperature	278.6005 °C
Cp	1.182251
Temperature	279.5629 °C
Cp	1.182299
Temperature	280.5253 °C
Cp	1.182353
Temperature	281.4877 °C
Cp	1.182414
Temperature	282.4501 °C
Cp	1.182486
Temperature	283.4125 °C
Cp	1.182577
Temperature	284.3749 °C
Cp	1.182671
Temperature	285.3373 °C
Cp	1.182786
Temperature	286.2997 °C
Cp	1.182921
Temperature	287.2621 °C
Cp	1.183076
Temperature	288.2245 °C
Cp	1.183251
Temperature	289.187 °C
Cp	1.183439
Temperature	290.1494 °C
Cp	1.183654
Temperature	291.1118 °C
Cp	1.183883
Temperature	292.0742 °C
Cp	1.184126
Temperature	293.0366 °C
Cp	1.184383
Temperature	293.999 °C
Cp	1.184651
Temperature	294.9614 °C
Cp	1.184932
Temperature	295.9238 °C
Cp	1.185223
Temperature	296.8862 °C
Cp	1.185522
Temperature	297.8486 °C
Cp	1.185828
Temperature	298.811 °C
Cp	1.18614
Temperature	299.7734 °C
Cp	1.186456
Temperature	300.7358 °C
Cp	1.186773
Temperature	301.6982 °C
Cp	1.187085
Temperature	302.6606 °C
Cp	1.1874
Temperature	303.623 °C
Cp	1.187709
Temperature	304.5854 °C
Cp	1.188011
Temperature	305.5478 °C
Cp	1.188307
Temperature	306.5102 °C
Cp	1.188598
Temperature	307.4726 °C
Cp	1.188893
Temperature	308.435 °C
Cp	1.189173
Temperature	309.3974 °C
Cp	1.189456
Temperature	310.3598 °C
Cp	1.189744
Temperature	311.3222 °C
Cp	1.190034
Temperature	312.2846 °C
Cp	1.190329
Temperature	313.247 °C
Cp	1.190615
Temperature	314.2094 °C
Cp	1.190925
Temperature	315.1718 °C
Cp	1.191232
Temperature	316.1342 °C
Cp	1.191539
Temperature	317.0966 °C
Cp	1.191848
Temperature	318.059 °C
Cp	1.19216
Temperature	319.0214 °C
Cp	1.192496
Temperature	319.9838 °C
Cp	1.192805
Temperature	320.9462 °C
Cp	1.193128
Temperature	321.9086 °C
Cp	1.193462
Temperature	322.871 °C
Cp	1.193803
Temperature	323.8334 °C
Cp	1.194149
Temperature	324.7958 °C
Cp	1.194495
Temperature	325.7583 °C
Cp	1.194832
Temperature	326.7207 °C
Cp	1.195181
Temperature	327.6831 °C
Cp	1.19552
Temperature	328.6455 °C
Cp	1.195853
Temperature	329.6079 °C
Cp	1.196183
Temperature	330.5703 °C
Cp	1.196515
Temperature	331.5327 °C
Cp	1.196862
Temperature	332.4951 °C
Cp	1.197211
Temperature	333.4575 °C
Cp	1.197584
Temperature	334.4199 °C
Cp	1.197985
Temperature	335.3823 °C
Cp	1.198418
Temperature	336.3447 °C
Cp	1.198886
Temperature	337.3071 °C
Cp	1.199394
Temperature	338.2695 °C
Cp	1.199941
Temperature	339.2319 °C
Cp	1.20053
Temperature	340.1943 °C
Cp	1.20116
Temperature	341.1567 °C
Cp	1.201831
Temperature	342.1191 °C
Cp	1.202538
Temperature	343.0815 °C
Cp	1.203274
Temperature	344.0439 °C
[...]
140.7633	89.5766	0.8086
140.7800	89.4104	0.8087
140.7967	89.2439	0.8088
140.8133	89.0773	0.8089
140.8300	88.9121	0.8090
140.8467	88.7453	0.8091
140.8633	88.5795	0.8092
140.8800	88.4132	0.8094
140.8967	88.2447	0.8095
140.9133	88.0796	0.8096
140.9300	87.9133	0.8096
140.9467	87.7459	0.8097
140.9633	87.5791	0.8099
140.9800	87.4143	0.8099
140.9967	87.2466	0.8100
141.0133	87.0812	0.8101
141.0300	86.9151	0.8102
141.0467	86.7476	0.8103
141.0633	86.5812	0.8105
141.0800	86.4154	0.8106
141.0967	86.2495	0.8107
141.1133	86.0835	0.8107
141.1300	85.9161	0.8108
141.1467	85.7495	0.8108
141.1633	85.5830	0.8109
141.1800	85.4172	0.8110
141.1967	85.2513	0.8111
141.2133	85.0845	0.8112
141.2300	84.9188	0.8113
141.2467	84.7523	0.8114
141.2633	84.5851	0.8115
141.2800	84.4191	0.8116
141.2967	84.2522	0.8116
141.3133	84.0873	0.8118
141.3300	83.9199	0.8119
141.3467	83.7538	0.8120
141.3633	83.5876	0.8121
141.3800	83.4213	0.8122
141.3967	83.2538	0.8123
141.4133	83.0882	0.8124
141.4300	82.9222	0.8125
141.4467	82.7557	0.8126
141.4633	82.5896	0.8127
141.4800	82.4226	0.8128
141.4967	82.2565	0.8129
141.5133	82.0898	0.8130
141.5300	81.9237	0.8131
141.5467	81.7590	0.8131
141.5633	81.5907	0.8132
141.5800	81.4249	0.8133
141.5967	81.2582	0.8134
141.6133	81.0925	0.8135
141.6300	80.9259	0.8136
141.6467	80.7600	0.8137
141.6633	80.5934	0.8138
141.6800	80.4263	0.8139
141.6967	80.2594	0.8141
141.7133	80.0942	0.8142
141.7300	79.9269	0.8143
141.7467	79.7608	0.8144
141.7633	79.5951	0.8144
141.7800	79.4282	0.8145
141.7967	79.2620	0.8146
141.8133	79.0956	0.8146
141.8300	78.9306	0.8147
141.8467	78.7624	0.8148
141.8633	78.5973	0.8149
141.8800	78.4312	0.8150
141.8967	78.2642	0.8151
141.9133	78.0984	0.8151
141.9300	77.9324	0.8155
141.9467	77.7652	0.8156
141.9633	77.6000	0.8157
141.9800	77.4341	0.8158
141.9967	77.2668	0.8159
142.0133	77.1007	0.8159
142.0300	76.9332	0.8159
142.0467	76.7680	0.8160
142.0633	76.6002	0.8161
142.0800	76.4353	0.8162
142.0967	76.2679	0.8163
142.1133	76.1022	0.8164
142.1300	75.9360	0.8164
142.1467	75.7701	0.8165
142.1633	75.6027	0.8166
142.1800	75.4374	0.8167
142.1967	75.2712	0.8168
142.2133	75.1042	0.8168
142.2300	74.9387	0.8169
142.2467	74.7712	0.8170
142.2633	74.6053	0.8171
142.2800	74.4398	0.8172
142.2967	74.2719	0.8173
142.3133	74.1061	0.8173
142.3300	73.9407	0.8174
142.3467	73.7735	0.8175
142.3633	73.6081	0.8176
142.3800	73.4409	0.8177
142.3967	73.2756	0.8178
142.4133	73.1082	0.8179
142.4300	72.9414	0.8180
142.4467	72.7751	0.8181
142.4633	72.6087	0.8182
142.4800	72.4406	0.8183
142.4967	72.2759	0.8185
142.5133	72.1101	0.8186
142.5300	71.9438	0.8187
142.5467	71.7779	0.8188
142.5633	71.6102	0.8189
142.5800	71.4438	0.8191
142.5967	71.2782	0.8191
142.6133	71.1114	0.8192
142.6300	70.9449	0.8193
142.6467	70.7792	0.8194
142.6633	70.6135	0.8194
142.6800	70.4458	0.8195
142.6967	70.2794	0.8196
142.7133	70.1140	0.8196
142.7300	69.9484	0.8197
142.7467	69.7809	0.8198
142.7633	69.6139	0.8199
142.7800	69.4478	0.8200
142.7967	69.2821	0.8201
142.8133	69.1150	0.8202
142.8300	68.9500	0.8203
142.8467	68.7837	0.8203
142.8633	68.6163	0.8204
142.8800	68.4501	0.8204
142.8967	68.2840	0.8205
142.9133	68.1165	0.8206
142.9300	67.9509	0.8207
142.9467	67.7853	0.8208
142.9633	67.6181	0.8209
142.9800	67.4514	0.8210
142.9967	67.2864	0.8210
143.0133	67.1188	0.8211
143.0300	66.9530	0.8212
143.0467	66.7868	0.8212
143.0633	66.6203	0.8213
143.0800	66.4546	0.8213
143.0967	66.2874	0.8215
143.1133	66.1212	0.8215
143.1300	65.9558	0.8216
143.1467	65.7887	0.8216
143.1633	65.6228	0.8216
143.1800	65.4555	0.8217
143.1967	65.2901	0.8218
143.2133	65.1223	0.8218
143.2300	64.9557	0.8219
143.2467	64.7892	0.8219
143.2633	64.6241	0.8219
143.2800	64.4568	0.8219
143.2967	64.2905	0.8219
143.3133	64.1246	0.8218
143.3300	63.9585	0.8219
143.3467	63.7919	0.8218
143.3633	63.6253	0.8219
143.3800	63.4593	0.8218
143.3967	63.2913	0.8218
143.4133	63.1253	0.8218
143.4300	62.9597	0.8218
143.4467	62.7930	0.8217
143.4633	62.6267	0.8216
143.4800	62.4600	0.8215
143.4967	62.2938	0.8214
143.5133	62.1267	0.8213
143.5300	61.9610	0.8211
143.5467	61.7939	0.8209
143.5633	61.6272	0.8208
143.5800	61.4617	0.8207
143.5967	61.2939	0.8205
143.6133	61.1282	0.8203
143.6300	60.9626	0.8200
143.6467	60.7955	0.8196
143.6633	60.6289	0.8194
143.6800	60.4627	0.8192
143.6967	60.2956	0.8190
143.7133	60.1286	0.8186
143.7300	59.9623	0.8183
143.7467	59.7948	0.8181
143.7633	59.6299	0.8177
143.7800	59.4634	0.8174
143.7967	59.2965	0.8169
143.8133	59.1301	0.8167
143.8300	58.9619	0.8157
143.8467	58.7956	0.8153
143.8633	58.6301	0.8150
143.8800	58.4633	0.8143
143.8967	58.2975	0.8137
143.9133	58.1312	0.8133
143.9300	57.9641	0.8128
143.9467	57.7978	0.8123
143.9633	57.6314	0.8120
143.9800	57.4647	0.8116
143.9967	57.2980	0.8111
144.0133	57.1310	0.8105
144.0300	56.9641	0.8096
144.0467	56.7967	0.8093
144.0633	56.6298	0.8088
144.0800	56.4646	0.8083
144.0967	56.2971	0.8077
144.1133	56.1297	0.8071
144.1300	55.9624	0.8063
144.1467	55.7965	0.8059
144.1633	55.6301	0.8047
144.1800	55.4629	0.8041
144.1967	55.2973	0.8030
144.2133	55.1297	0.8025
144.2300	54.9635	0.8020
144.2467	54.7969	0.8013
144.2633	54.6290	0.8005
144.2800	54.4634	0.7997
144.2967	54.2964	0.7993
144.3133	54.1296	0.7971
144.3300	53.9622	0.7968
144.3467	53.7974	0.7958
144.3633	53.6293	0.7952
144.3800	53.4634	0.7945
144.3967	53.2958	0.7940
144.4133	53.1299	0.7930
144.4300	52.9628	0.7928
144.4467	52.7968	0.7918
144.4633	52.6297	0.7914
144.4800	52.4622	0.7906
144.4967	52.2953	0.7901
144.5133	52.1290	0.7897
144.5300	51.9623	0.7890
144.5467	51.7953	0.7882
144.5633	51.6286	0.7876
144.5800	51.4620	0.7873
144.5967	51.2946	0.7870
144.6133	51.1275	0.7867
144.6300	50.9608	0.7862
144.6467	50.7943	0.7851
144.6633	50.6278	0.7845
144.6800	50.4613	0.7839
144.6967	50.2947	0.7830
144.7133	50.1284	0.7825
144.7300	49.9621	0.7815
144.7467	49.7943	0.7809
144.7633	49.6285	0.7806
144.7800	49.4613	0.7800
144.7967	49.2946	0.7797
144.8133	49.1288	0.7792
144.8300	48.9616	0.7789
144.8467	48.7947	0.7785
144.8633	48.6285	0.7781
144.8800	48.4629	0.7777
144.8967	48.2954	0.7773
144.9133	48.1292	0.7769
144.9300	47.9625	0.7765
144.9467	47.7953	0.7760
144.9633	47.6283	0.7756
144.9800	47.4632	0.7754
144.9967	47.2968	0.7746
145.0133	47.1302	0.7739
145.0300	46.9629	0.7736
145.0467	46.7951	0.7734
145.0633	46.6290	0.7731
145.0800	46.4624	0.7727
145.0967	46.2959	0.7721
145.1133	46.1301	0.7715
145.1300	45.9633	0.7713
145.1467	45.7954	0.7710
145.1633	45.6292	0.7706
145.1800	45.4628	0.7701
145.1967	45.2968	0.7699
145.2133	45.1308	0.7694
145.2300	44.9632	0.7692
145.2467	44.7977	0.7690
145.2633	44.6303	0.7687
145.2800	44.4638	0.7685
145.2967	44.2976	0.7683
145.3133	44.1313	0.7679
145.3300	43.9651	0.7676
145.3467	43.7975	0.7674
145.3633	43.6316	0.7670
145.3800	43.4643	0.7667
145.3967	43.2988	0.7664
145.4133	43.1322	0.7661
145.4300	42.9662	0.7659
145.4467	42.7990	0.7657
145.4633	42.6324	0.7653
145.4800	42.4656	0.7649
145.4967	42.2997	0.7647
145.5133	42.1335	0.7643
145.5300	41.9668	0.7641
145.5467	41.8014	0.7640
145.5633	41.6328	0.7636
145.5800	41.4672	0.7635
145.5967	41.2993	0.7630
145.6133	41.1339	0.7629
145.6300	40.9672	0.7623
145.6467	40.8026	0.7621
145.6633	40.6354	0.7619
145.6800	40.4685	0.7618
145.6967	40.3028	0.7616
145.7133	40.1366	0.7614
145.7300	39.9687	0.7612
145.7467	39.8019	0.7611
145.7633	39.6349	0.7608
145.7800	39.4690	0.7606
145.7967	39.3029	0.7604
145.8133	39.1367	0.7603
145.8300	38.9700	0.7601
145.8467	38.8034	0.7600
145.8633	38.6363	0.7599
145.8800	38.4701	0.7597
145.8967	38.3036	0.7595
145.9133	38.1369	0.7591
145.9300	37.9705	0.7590
145.9467	37.8027	0.7588
145.9633	37.6376	0.7587
145.9800	37.4718	0.7585
145.9967	37.3052	0.7584
146.0133	37.1379	0.7583
146.0300	36.9723	0.7581
146.0467	36.8041	0.7580
146.0633	36.6379	0.7578
146.0800	36.4730	0.7577
146.0967	36.3062	0.7575
146.1133	36.1375	0.7573
146.1300	35.9734	0.7572
146.1467	35.8055	0.7571
146.1633	35.6405	0.7569
146.1800	35.4738	0.7568
146.1967	35.3059	0.7567
146.2133	35.1416	0.7566
146.2300	34.9753	0.7563
146.2467	34.8060	0.7561
146.2633	34.6408	0.7560
146.2800	34.4719	0.7560
146.2967	34.3077	0.7557
146.3133	34.1415	0.7556
146.3300	33.9749	0.7555
146.3467	33.8078	0.7554
146.3633	33.6422	0.7552
146.3800	33.4754	0.7551
146.3967	33.3081	0.7549
146.4133	33.1418	0.7547
146.4300	32.9755	0.7546
146.4467	32.8075	0.7545
146.4633	32.6431	0.7543
146.4800	32.4773	0.7541
146.4967	32.3093	0.7540
146.5133	32.1431	0.7539
146.5300	31.9766	0.7539
146.5467	31.8101	0.7537
146.5633	31.6437	0.7536
146.5800	31.4779	0.7535
146.5967	31.3106	0.7534
146.6133	31.1438	0.7533
146.6300	30.9779	0.7532
146.6467	30.8120	0.7530
146.6633	30.6451	0.7530
146.6800	30.4785	0.7529
146.6967	30.3123	0.7528
146.7133	30.1459	0.7527
146.7300	29.9794	0.7526
146.7467	29.8130	0.7526
146.7633	29.6459	0.7525
146.7800	29.4800	0.7523
146.7967	29.3137	0.7522
146.8133	29.1469	0.7521
146.8300	28.9801	0.7519
146.8467	28.8135	0.7519
146.8633	28.6472	0.7518
146.8800	28.4824	0.7517
146.8967	28.3148	0.7513
146.9133	28.1485	0.7513
146.9300	27.9809	0.7510
146.9467	27.8157	0.7510
146.9633	27.6492	0.7510
146.9800	27.4821	0.7510
146.9967	27.3155	0.7509
147.0133	27.1494	0.7508
147.0300	26.9830	0.7507
147.0467	26.8161	0.7506
147.0633	26.6501	0.7506
147.0800	26.4829	0.7505
147.0967	26.3166	0.7504
147.1133	26.1497	0.7503
147.1300	25.9848	0.7503
147.1467	25.8177	0.7503
147.1633	25.6517	0.7502
147.1800	25.4857	0.7498
147.1967	25.3184	0.7498
147.2133	25.1526	0.7496
147.2300	24.9857	0.7497
147.2467	24.8189	0.7495
147.2633	24.6531	0.7496
147.2800	24.4866	0.7495
147.2967	24.3202	0.7494
147.3133	24.1542	0.7494
147.3300	23.9870	0.7494
147.3467	23.8204	0.7493
147.3633	23.6540	0.7493
147.3800	23.4863	0.7493
147.3967	23.3196	0.7491
147.4133	23.1539	0.7492
147.4300	22.9879	0.7491
147.4467	22.8204	0.7490
147.4633	22.6542	0.7490
147.4800	22.4878	0.7487
147.4967	22.3218	0.7487
147.5133	22.1556	0.7487
147.5300	21.9899	0.7486
147.5467	21.8218	0.7486
147.5633	21.6557	0.7485
147.5800	21.4900	0.7484
147.5967	21.3232	0.7484
147.6133	21.1552	0.7483
147.6300	20.9902	0.7483
147.6467	20.8227	0.7482
147.6633	20.6561	0.7481
147.6800	20.4903	0.7478
147.6967	20.3236	0.7478
147.7133	20.1572	0.7478
147.7300	19.9919	0.7477
147.7467	19.8244	0.7476
147.7633	19.6574	0.7476
147.7800	19.4927	0.7475
147.7967	19.3252	0.7475
147.8133	19.1586	0.7474
147.8300	18.9927	0.7474
147.8467	18.8269	0.7473
147.8633	18.6584	0.7473
147.8800	18.4933	0.7471
147.8967	18.3268	0.7470
147.9133	18.1594	0.7470
147.9300	17.9931	0.7469
147.9467	17.8258	0.7469
147.9633	17.6603	0.7468
147.9800	17.4933	0.7468
147.9967	17.3273	0.7466
148.0133	17.1612	0.7467
148.0300	16.9946	0.7464
148.0467	16.8282	0.7464
148.0633	16.6629	0.7463
148.0800	16.4944	0.7462
148.0967	16.3270	0.7462
148.1133	16.1611	0.7462
148.1300	15.9942	0.7461
148.1467	15.8288	0.7460
148.1633	15.6615	0.7460
148.1800	15.4960	0.7459
148.1967	15.3303	0.7458
148.2133	15.1631	0.7457
148.2300	14.9962	0.7457
148.2467	14.8295	0.7456
148.2633	14.6629	0.7456
148.2800	14.4971	0.7456
148.2967	14.3298	0.7455
148.3133	14.1635	0.7453
148.3300	13.9965	0.7453
148.3467	13.8317	0.7451
148.3633	13.6639	0.7450
148.3800	13.4984	0.7450
148.3967	13.3309	0.7449
148.4133	13.1653	0.7447
148.4300	12.9997	0.7447
148.4467	12.8324	0.7447
148.4633	12.6650	0.7444
148.4800	12.4991	0.7444
148.4967	12.3335	0.7443
148.5133	12.1661	0.7442
148.5300	12.0004	0.7442
148.5467	11.8334	0.7441
148.5633	11.6672	0.7440
148.5800	11.5001	0.7439
148.5967	11.3347	0.7438
148.6133	11.1671	0.7438
148.6300	11.0012	0.7437
148.6467	10.8349	0.7436
148.6633	10.6680	0.7436
148.6800	10.5006	0.7435
148.6967	10.3343	0.7434
148.7133	10.1683	0.7432
148.7300	10.0001	0.7432
148.7467	9.8345	0.7432
148.7633	9.6691	0.7431
148.7800	9.5013	0.7430
148.7967	9.3346	0.7429
148.8133	9.1679	0.7428
148.8300	9.0019	0.7427
148.8467	8.8356	0.7426
148.8633	8.6689	0.7425
148.8800	8.5026	0.7423
148.8967	8.3365	0.7422
148.9133	8.1703	0.7420
148.9300	8.0035	0.7420
148.9467	7.8367	0.7419
148.9633	7.6709	0.7419
148.9800	7.5024	0.7418
148.9967	7.3368	0.7417
149.0133	7.1702	0.7414
149.0300	7.0044	0.7414
149.0467	6.8372	0.7414
149.0633	6.6714	0.7410
149.0800	6.5045	0.7410
149.0967	6.3385	0.7409
149.1133	6.1721	0.7408
149.1300	6.0055	0.7408
149.1467	5.8393	0.7407
149.1633	5.6723	0.7407
149.1800	5.5057	0.7405
149.1967	5.3393	0.7404
149.2133	5.1725	0.7403
149.2300	5.0061	0.7403
149.2467	4.8398	0.7402
149.2633	4.6734	0.7400
149.2800	4.5064	0.7402
149.2967	4.3408	0.7399
149.3133	4.1737	0.7398
149.3300	4.0070	0.7397
149.3467	3.8405	0.7396
149.3633	3.6744	0.7396
149.3800	3.5080	0.7395
149.3967	3.3424	0.7394
149.4133	3.1747	0.7395
149.4300	3.0078	0.7389
149.4467	2.8422	0.7388
149.4633	2.6747	0.7391
149.4800	2.5096	0.7389
149.4967	2.3433	0.7388
149.5133	2.1778	0.7386
149.5300	2.0101	0.7386
149.5467	1.8430	0.7384
149.5633	1.6772	0.7383
149.5800	1.5113	0.7383
149.5967	1.3449	0.7383
149.6133	1.1780	0.7382
149.6300	1.0128	0.7382
149.6467	0.8455	0.7381
149.6633	0.6784	0.7380
149.6800	0.5126	0.7380
149.6967	0.3454	0.7379
149.7133	0.1796	0.7378
149.7300	0.0133	0.7378
149.7467	-0.1538	0.7378
149.7633	-0.3194	0.7377
149.7800	-0.4861	0.7377
149.7967	-0.6537	0.7377
149.8133	-0.8190	0.7376
149.8300	-0.9872	0.7375
149.8467	-1.1516	0.7374
149.8633	-1.3191	0.7372
149.8800	-1.4842	0.7372
149.8967	-1.6523	0.7371
149.9133	-1.8174	0.7371
149.9300	-1.9847	0.7371
149.9467	-2.1506	0.7370
149.9633	-2.3173	0.7370
149.9800	-2.4842	0.7370
149.9967	-2.6503	0.7369
150.0133	-2.8164	0.7368
150.0300	-2.9825	0.7366
150.0467	-3.1481	0.7365
150.0633	-3.3162	0.7365
150.0800	-3.4819	0.7363
150.0967	-3.6481	0.7363
150.1133	-3.8141	0.7362
150.1300	-3.9825	0.7361
150.1467	-4.1477	0.7362
150.1633	-4.3138	0.7361
150.1800	-4.4797	0.7361
150.1967	-4.6469	0.7361
150.2133	-4.8129	0.7361
150.2300	-4.9797	0.7360
150.2467	-5.1463	0.7358
150.2633	-5.3116	0.7358
150.2800	-5.4784	0.7358
150.2967	-5.6456	0.7357
150.3133	-5.8116	0.7356
150.3300	-5.9785	0.7356
150.3467	-6.1447	0.7356
150.3633	-6.3109	0.7356
150.3800	-6.4772	0.7356
150.3967	-6.6446	0.7355
150.4133	-6.8110	0.7356
150.4300	-6.9759	0.7355
150.4467	-7.1423	0.7354
150.4633	-7.3088	0.7354
150.4800	-7.4755	0.7361
150.4967	-7.6335	0.8232
150.5133	-7.7958	0.7760
150.5300	-7.9620	0.7609
150.5467	-8.1286	0.7548
150.5633	-8.2973	0.7517
150.5800	-8.4637	0.7504
150.5967	-8.6305	0.7493
150.6133	-8.7976	0.7489
150.6300	-8.9659	0.7482
150.6467	-9.1332	0.7480
150.6633	-9.2984	0.7476
150.6800	-9.4647	0.7462
150.6967	-9.6314	0.7461
150.7133	-9.7986	0.7460
150.7300	-9.9657	0.7459
150.7467	-10.1322	0.7458
150.7633	-10.2988	0.7457
150.7800	-10.4660	0.7456
150.7967	-10.6314	0.7455
150.8133	-10.7993	0.7451
150.8300	-10.9644	0.7449
150.8467	-11.1328	0.7448
150.8633	-11.2973	0.7444
150.8800	-11.4658	0.7443
150.8967	-11.6326	0.7441
150.9133	-11.7974	0.7440
150.9300	-11.9637	0.7439
150.9467	-12.1311	0.7438
150.9633	-12.2992	0.7436
150.9800	-12.4652	0.7436
150.9967	-12.6316	0.7435
151.0133	-12.7986	0.7435
151.0300	-12.9643	0.7433
151.0467	-13.1312	0.7433
151.0633	-13.2964	0.7432
151.0800	-13.4627	0.7431
151.0967	-13.6289	0.7431
151.1133	-13.7954	0.7430
151.1300	-13.9633	0.7429
151.1467	-14.1305	0.7428
151.1633	-14.2947	0.7428
151.1800	-14.4615	0.7426
151.1967	-14.6283	0.7426
151.2133	-14.7957	0.7425
151.2300	-14.9615	0.7425
151.2467	-15.1286	0.7425
151.2633	-15.2952	0.7425
151.2800	-15.4596	0.7424
151.2967	-15.6273	0.7423
151.3133	-15.7930	0.7423
151.3300	-15.9603	0.7423
151.3467	-16.1267	0.7423
151.3633	-16.2941	0.7422
151.3800	-16.4594	0.7422
151.3967	-16.6259	0.7421
151.4133	-16.7910	0.7421
151.4300	-16.9586	0.7421
151.4467	-17.1242	0.7421
151.4633	-17.2897	0.7420
151.4800	-17.4568	0.7420
151.4967	-17.6242	0.7421
151.5133	-17.7898	0.7421
151.5300	-17.9569	0.7421
151.5467	-18.1241	0.7420
151.5633	-18.2884	0.7420
151.5800	-18.4562	0.7421
151.5967	-18.6227	0.7419
151.6133	-18.7892	0.7420
151.6300	-18.9556	0.7419
151.6467	-19.1208	0.7419
151.6633	-19.2879	0.7418
151.6800	-19.4552	0.7418
151.6967	-19.6221	0.7419
151.7133	-19.7863	0.7419
151.7300	-19.9539	0.7419
151.7467	-20.1192	0.7419
151.7633	-20.2882	0.7419
151.7800	-20.4533	0.7418
151.7967	-20.6187	0.7418
151.8133	-20.7862	0.7420
151.8300	-20.9529	0.7420
151.8467	-21.1204	0.7420
151.8633	-21.2858	0.7419
151.8800	-21.4527	0.7418
151.8967	-21.6176	0.7419
151.9133	-21.7836	0.7418
151.9300	-21.9512	0.7418
151.9467	-22.1180	0.7418
151.9633	-22.2855	0.7418
151.9800	-22.4509	0.7418
151.9967	-22.6189	0.7418
152.0133	-22.7832	0.7418
152.0300	-22.9492	0.7417
152.0467	-23.1168	0.7417
152.0633	-23.2823	0.7417
152.0800	-23.4493	0.7417
152.0967	-23.6155	0.7416
152.1133	-23.7816	0.7416
152.1300	-23.9484	0.7416
152.1467	-24.1148	0.7416
152.1633	-24.2813	0.7415
152.1800	-24.4475	0.7415
152.1967	-24.6136	0.7415
152.2133	-24.7798	0.7414
152.2300	-24.9479	0.7414
152.2467	-25.1136	0.7414
152.2633	-25.2793	0.7413
152.2800	-25.4465	0.7413
152.2967	-25.6135	0.7413
152.3133	-25.7792	0.7413
152.3300	-25.9448	0.7413
152.3467	-26.1103	0.7413
152.3633	-26.2782	0.7413
152.3800	-26.4438	0.7413
152.3967	-26.6100	0.7413
152.4133	-26.7772	0.7413
152.4300	-26.9447	0.7414
152.4467	-27.1089	0.7412
152.4633	-27.2754	0.7412
152.4800	-27.4414	0.7412
152.4967	-27.6074	0.7412
152.5133	-27.7757	0.7413
152.5300	-27.9419	0.7413
152.5467	-28.1089	0.7413
152.5633	-28.2750	0.7414
152.5800	-28.4415	0.7413
152.5967	-28.6066	0.7412
152.6133	-28.7750	0.7413
152.6300	-28.9398	0.7413
152.6467	-29.1073	0.7416
152.6633	-29.2733	0.7416
152.6800	-29.4389	0.7416
152.6967	-29.6066	0.7416
152.7133	-29.7715	0.7416
152.7300	-29.9365	0.7416
152.7467	-30.1044	0.7417
152.7633	-30.2700	0.7418
152.7800	-30.4372	0.7418
152.7967	-30.6036	0.7418
152.8133	-30.7686	0.7418
152.8300	-30.9366	0.7419
152.8467	-31.1013	0.7418
152.8633	-31.2686	0.7420
152.8800	-31.4346	0.7421
152.8967	-31.6017	0.7421
152.9133	-31.7671	0.7421
152.9300	-31.9339	0.7422
152.9467	-32.1012	0.7423
152.9633	-32.2660	0.7422
152.9800	-32.4323	0.7423
152.9967	-32.5999	0.7423
153.0133	-32.7660	0.7423
153.0300	-32.9330	0.7425
153.0467	-33.0989	0.7425
153.0633	-33.2655	0.7426
153.0800	-33.4307	0.7426
153.0967	-33.5992	0.7427
153.1133	-33.7638	0.7427
153.1300	-33.9307	0.7427
153.1467	-34.0967	0.7428
153.1633	-34.2634	0.7428
153.1800	-34.4301	0.7430
153.1967	-34.5956	0.7427
153.2133	-34.7629	0.7428
153.2300	-34.9302	0.7428
153.2467	-35.0965	0.7428
153.2633	-35.2630	0.7429
153.2800	-35.4281	0.7430
153.2967	-35.5948	0.7430
153.3133	-35.7631	0.7430
153.3300	-35.9288	0.7431
153.3467	-36.0953	0.7431
153.3633	-36.2621	0.7432
153.3800	-36.4286	0.7432
153.3967	-36.5952	0.7433
153.4133	-36.7611	0.7432
153.4300	-36.9286	0.7432
153.4467	-37.0944	0.7432
153.4633	-37.2618	0.7433
153.4800	-37.4274	0.7432
153.4967	-37.5942	0.7432
153.5133	-37.7602	0.7432
153.5300	-37.9246	0.7430
153.5467	-38.0922	0.7431
153.5633	-38.2584	0.7431
153.5800	-38.4246	0.7430
153.5967	-38.5915	0.7431
153.6133	-38.7580	0.7431
153.6300	-38.9250	0.7431
153.6467	-39.0897	0.7431
153.6633	-39.2577	0.7431
153.6800	-39.4242	0.7433
153.6967	-39.5905	0.7433
153.7133	-39.7568	0.7433
153.7300	-39.9228	0.7433
153.7467	-40.0901	0.7433
153.7633	-40.2554	0.7433
153.7800	-40.4217	0.7433
153.7967	-40.5883	0.7433
153.8133	-40.7549	0.7433
153.8300	-40.9218	0.7434
153.8467	-41.0872	0.7434
153.8633	-41.2543	0.7434
153.8800	-41.4213	0.7434
153.8967	-41.5870	0.7435
153.9133	-41.7549	0.7436
153.9300	-41.9204	0.7436
153.9467	-42.0859	0.7435
153.9633	-42.2551	0.7436
153.9800	-42.4202	0.7436
153.9967	-42.5857	0.7437
154.0133	-42.7545	0.7437
154.0300	-42.9193	0.7437
154.0467	-43.0851	0.7437
154.0633	-43.2521	0.7437
154.0800	-43.4196	0.7437
154.0967	-43.5844	0.7437
154.1133	-43.7519	0.7437
154.1300	-43.9185	0.7438
154.1467	-44.0829	0.7437
154.1633	-44.2511	0.7440
154.1800	-44.4176	0.7440
154.1967	-44.5844	0.7440
154.2133	-44.7509	0.7441
154.2300	-44.9173	0.7441
154.2467	-45.0828	0.7442
154.2633	-45.2491	0.7441
154.2800	-45.4168	0.7441
154.2967	-45.5835	0.7441
154.3133	-45.7502	0.7441
154.3300	-45.9157	0.7441
154.3467	-46.0817	0.7440
154.3633	-46.2488	0.7440
154.3800	-46.4151	0.7440
154.3967	-46.5818	0.7441
154.4133	-46.7489	0.7440
154.4300	-46.9151	0.7441
154.4467	-47.0808	0.7440
154.4633	-47.2469	0.7440
154.4800	-47.4140
154.4967	-47.5817
154.5133	-47.7475
154.5283