File: Example Date/My Sample/DSC/LLM_EP_02_PMMA.txt
Filename	LLM_EP_02_PMMA
Instrument name	DSC2A-01799 (192.168.1.250)
Operator
rundate	06/02/2025
Sample name	LLM_EP_02_PMMA
proceduresegments	Select Gas: Gas 1 ; Ramp 10.00 °C/min to 25.0000 °C; Ramp 10.00 °C/min to 120.0000 °C; Isothermal 5.0 min; Ramp 10.00 °C/min to -50.0000 °C; Isothermal 5.0 min; Ramp 10.00 °C/min to 210.0000 °C; Isothermal 5.0 min; Ramp 10.00 °C/min to -50.0000 °C; Isothermal 5.0 min; Ramp 10.00 °C/min to 210.0000 °C; Isothermal 5.0 min; Ramp 10.00 °C/min to -50.0000 °C
[File Parameters]
Run Date	06/02/2025 09:10:17
Trios version	5.7.0.56
Original File Name
Current File Name	C:\Users\TA Instruments DSC\Desktop\Data\LLM\LLM_EP_02_PMMA.tri
User at run start	DESKTOP-CFGN8IT\TA Instruments DSC
[Procedure]
Procedure Name	LLM_EP_02_PMMA
Sample Name	LLM_EP_02_PMMA
Sample Mass	12.83 mg
Reference Sample Mass	0 mg
Pan Mass	62.65 mg
Pan Number	15
Reference Pan Mass	43.13 mg
Reference Pan Number	13
Pan Type	Tzero Aluminum Pin Hole Hermetic
Comments	Cha/Bif PMMA
Project Name
Operator
Test	Custom
Unload Max Temperature	25
Unload Min Temperature	25
FillCooler	Do not fill
Load Max Temperature	25
Load Min Temperature	25
Discard pan in waste bin at end of test	No
Stop on Gas Flow Error	No
[Signal List]
Signal #1	Time (min)
Signal #2	Temperature (°C)
Signal #3	Heat Flow (mW)
Signal #4	Delta T (µV)
Signal #5	Delta Tzero (µV)
Signal #6	Tzero Temperature (°C)
Signal #7	Cell Purge (mL/min)
Signal #8	Heater Temp (°C)
Signal #9	Power Delivered (W)
Signal #10	Reference Junction Temperature (°C)
Signal #11	Flange Temperature (°C)
Signal #12	Heat Flow Phase (rad)
Signal #13	Total Heat Capacity (J/°C)
Signal #14	Heat Capacity (J/°C)
Signal #15	LN Pump Tank level (%)
[Configuration]
Company Name	Warwick University
Instrument Name	DSC2A-01799
Instrument Type	DSC2500
Serial Number	DSC2A-01799
IP	192.168.1.250
Location of Instrument	Polymer RTP
DisplayType	TianmaV2andV3
Sample Interval 	0.1 s/pt
Selected Heat Flow	T4P
Exotherm Direction	Up
Cell Serial	DRC2-03788
Lid Type	High Temperature
Cooler	LN Pump
Leave Cooler on at End of Sequence	Off
Gas 2	Air
Gas Selected	Channel 1: Nitrogen
Flow Rate	50 mL/min
Secondary Purge	On
Licensed Heat Flow	Heat Flow T4P
Modulation Licensed	Yes
[Versions]
Common IDD Version	1
Cortex Version	VER 2.11.0.729
Driver	5.0.0.6
GDM Version	1.0.3.3
TouchscreenVersion	1.0.3.1841
FEP Version	1.2.1.21
FEP Bootloader	2.0.0.5
AutoSampler Version	2.1.2.1
Auto Sampler Bootloader	2.0.0.5
FCM Version	1.1.0.3
FCM Bootloader	2.0.0.5
LN Pump Version	10.17.0.0
LN Pump Bootloader	2.0.0.5
[Experiment Logs]
Experiment Log Entry # 1	Gas Select Segment is 1
Experiment Log Entry # 3	Ramp Segment 10 C/min to 25 Started
Experiment Log Entry # 5	Air Cool is off.
Experiment Log Entry # 7	Ramp Segment 10 C/min to 120 Started
Experiment Log Entry # 9	Isothermal Segment 5 min started
Experiment Log Entry # 11	Ramp Segment 10 C/min to -50 Started
Experiment Log Entry # 13	Isothermal Segment 5 min started
Experiment Log Entry # 15	Ramp Segment 10 C/min to 210 Started
Experiment Log Entry # 17	Isothermal Segment 5 min started
Experiment Log Entry # 19	Ramp Segment 10 C/min to -50 Started
Experiment Log Entry # 21	Isothermal Segment 5 min started
Experiment Log Entry # 23	Ramp Segment 10 C/min to 210 Started
Experiment Log Entry # 26	LN2P is filling
Experiment Log Entry # 27	Isothermal Segment 5 min started
Experiment Log Entry # 29	Ramp Segment 10 C/min to -50 Started
Experiment Log Entry # 31	Current LN2P tank level (94.61%) not increasing during fill. Bulk tank may be empty.
Experiment Log Entry # 33	LN2P stopped filling
[Method Log]
Method Log Entry # 1	Gas Selected 1
Method Log Entry # 2	(Ramp 985412) Ramp 10 °C/minute to 25 °C
Method Log Entry # 3	(Ramp 985413) Ramp 10 °C/minute to 120 °C
Method Log Entry # 4	Isothermal 5 minutes
Method Log Entry # 5	(Ramp 985415) Ramp 10 °C/minute to -50 °C
Method Log Entry # 6	Isothermal 5 minutes
Method Log Entry # 7	(Ramp 985417) Ramp 10 °C/minute to 210 °C
Method Log Entry # 8	Isothermal 5 minutes
Method Log Entry # 9	(Ramp 985419) Ramp 10 °C/minute to -50 °C
Method Log Entry # 10	Isothermal 5 minutes
Method Log Entry # 11	(Ramp 985421) Ramp 10 °C/minute to 210 °C
Method Log Entry # 12	Isothermal 5 minutes
Method Log Entry # 13	(Ramp 985423) Ramp 10 °C/minute to -50 °C
Cell Serial	DRC2-03788
[T1 Calibration]
Date Applied	04/03/2021 14:58:04
Slope	-0.001800291
Offset	-0.1301359
Initial Temperature	-100.6228
GUID	a1d5a6be-decd-4ae4-b22f-d560f3a78a92
[TZero Calibration]
Date Applied	03/01/2025 12:41:45
Description	From -178.795 °C to 396.200 °C at 20.000°C/min
Gas Type	Nitrogen
Pan Type	None
Source Files 1	C:\ProgramData\TA Instruments\TRIOS\Data\Tzero Cal(23).tri
Source Files 2	C:\ProgramData\TA Instruments\TRIOS\Data\Tzero Cal(24).tri
Delta T Offset	1.869383
Delta T Slope	-0.002827686
Delta T0 Offset	0.6518871
Delta T0 Slope	0.03386689
[Temperature Calibration]
Date Applied	07/01/2025 06:48:00
Description	From 106.598 °C to 186.598 °C at 10.000°C/min
Gas Type	Nitrogen
Pan Type	Aluminum Hermetic
Source Files 1	C:\ProgramData\TA Instruments\TRIOS\Data\Indium(10).tri
Measured 1	158.5387
Known 1	156.598
[Cell Constant Calibration]
Date Applied	07/01/2025 06:21:38
Description	From 106.598 °C to 186.598 °C at 10.000°C/min
Gas Type	Nitrogen
Pan Type	Aluminum Hermetic
Source Files 1	C:\ProgramData\TA Instruments\TRIOS\Data\Indium(8).tri
T4P KCell	1.071186
Onset Slope	-20.76992 mW/°C
[Direct Cp Calibration]
Date Applied	07/01/2025 08:34:40
Description	From -89.983 °C to 397.015 °C at 20.000°C/min
Gas Type	Nitrogen
Pan Type	Aluminum Hermetic
Source Files 1	C:\ProgramData\TA Instruments\TRIOS\Data\Sapphire Direct Heat Capacity(11).tri
GUID	bc2b1dd3-d0d9-41bf-ba72-b5fda717766a
Temperature	-89.98325 °C
Cp	0.9880321
Temperature	-89.00925 °C
Cp	0.9883595
Temperature	-88.03526 °C
Cp	0.9883455
Temperature	-87.06126 °C
Cp	0.9880565
Temperature	-86.08727 °C
Cp	0.9875574
Temperature	-85.11327 °C
Cp	0.9868901
Temperature	-84.13927 °C
Cp	0.9861491
Temperature	-83.16528 °C
Cp	0.9854108
Temperature	-82.19128 °C
Cp	0.9847093
Temperature	-81.21728 °C
Cp	0.984123
Temperature	-80.24328 °C
Cp	0.9836704
Temperature	-79.26929 °C
Cp	0.9834349
Temperature	-78.29529 °C
Cp	0.9833817
Temperature	-77.32129 °C
Cp	0.9835677
Temperature	-76.34729 °C
Cp	0.9839252
Temperature	-75.37329 °C
Cp	0.9844846
Temperature	-74.3993 °C
Cp	0.9852123
Temperature	-73.4253 °C
Cp	0.9860855
Temperature	-72.4513 °C
Cp	0.9870548
Temperature	-71.4773 °C
Cp	0.9881113
Temperature	-70.50331 °C
Cp	0.9892243
Temperature	-69.52931 °C
Cp	0.9903587
Temperature	-68.55531 °C
Cp	0.9915038
Temperature	-67.58131 °C
Cp	0.9926346
Temperature	-66.60732 °C
Cp	0.993748
Temperature	-65.63332 °C
Cp	0.994836
Temperature	-64.65932 °C
Cp	0.9959027
Temperature	-63.68533 °C
Cp	0.9969317
Temperature	-62.71133 °C
Cp	0.997943
Temperature	-61.73733 °C
Cp	0.9989527
Temperature	-60.76334 °C
Cp	0.9999582
Temperature	-59.78934 °C
Cp	1.000969
Temperature	-58.81534 °C
Cp	1.00194
Temperature	-57.84134 °C
Cp	1.002997
Temperature	-56.86735 °C
Cp	1.00403
Temperature	-55.89335 °C
Cp	1.005069
Temperature	-54.91935 °C
Cp	1.006104
Temperature	-53.94535 °C
Cp	1.00713
Temperature	-52.97136 °C
Cp	1.008209
Temperature	-51.99736 °C
Cp	1.009185
Temperature	-51.02336 °C
Cp	1.010177
Temperature	-50.04937 °C
Cp	1.011162
Temperature	-49.07537 °C
Cp	1.012141
Temperature	-48.10137 °C
Cp	1.01308
Temperature	-47.12737 °C
Cp	1.013991
Temperature	-46.15338 °C
Cp	1.014858
Temperature	-45.17938 °C
Cp	1.015703
Temperature	-44.20538 °C
Cp	1.016499
Temperature	-43.23138 °C
Cp	1.017257
Temperature	-42.25739 °C
Cp	1.017991
Temperature	-41.28339 °C
Cp	1.018705
Temperature	-40.30939 °C
Cp	1.019413
Temperature	-39.3354 °C
Cp	1.020126
Temperature	-38.3614 °C
Cp	1.020855
Temperature	-37.3874 °C
Cp	1.021604
Temperature	-36.4134 °C
Cp	1.022382
Temperature	-35.43941 °C
Cp	1.023185
Temperature	-34.46541 °C
Cp	1.024018
Temperature	-33.49141 °C
Cp	1.024865
Temperature	-32.51741 °C
Cp	1.025734
Temperature	-31.54342 °C
Cp	1.026615
Temperature	-30.56942 °C
Cp	1.027499
Temperature	-29.59542 °C
Cp	1.028374
Temperature	-28.62143 °C
Cp	1.029232
Temperature	-27.64743 °C
Cp	1.030081
Temperature	-26.67343 °C
Cp	1.030892
Temperature	-25.69943 °C
Cp	1.031667
Temperature	-24.72544 °C
Cp	1.032406
Temperature	-23.75144 °C
Cp	1.03311
Temperature	-22.77744 °C
Cp	1.033786
Temperature	-21.80344 °C
Cp	1.034412
Temperature	-20.82945 °C
Cp	1.035019
Temperature	-19.85545 °C
Cp	1.035599
Temperature	-18.88145 °C
Cp	1.036155
Temperature	-17.90746 °C
Cp	1.036695
Temperature	-16.93346 °C
Cp	1.037207
Temperature	-15.95946 °C
Cp	1.037712
Temperature	-14.98546 °C
Cp	1.038202
Temperature	-14.01147 °C
Cp	1.038666
Temperature	-13.03747 °C
Cp	1.039103
Temperature	-12.06347 °C
Cp	1.039518
Temperature	-11.08947 °C
Cp	1.039909
Temperature	-10.11548 °C
Cp	1.040284
Temperature	-9.14148 °C
Cp	1.040614
Temperature	-8.167483 °C
Cp	1.040915
Temperature	-7.193486 °C
Cp	1.041192
Temperature	-6.219488 °C
Cp	1.041427
Temperature	-5.245491 °C
Cp	1.041627
Temperature	-4.271494 °C
Cp	1.041773
Temperature	-3.297497 °C
Cp	1.041891
Temperature	-2.323499 °C
Cp	1.041951
Temperature	-1.349502 °C
Cp	1.041963
Temperature	-0.3755048 °C
Cp	1.041932
Temperature	0.5984925 °C
Cp	1.041862
Temperature	1.57249 °C
Cp	1.04176
Temperature	2.546487 °C
Cp	1.04162
Temperature	3.520484 °C
Cp	1.041463
Temperature	4.494482 °C
Cp	1.041297
Temperature	5.468479 °C
Cp	1.041124
Temperature	6.442476 °C
Cp	1.040949
Temperature	7.416473 °C
Cp	1.04077
Temperature	8.390471 °C
Cp	1.040596
Temperature	9.364468 °C
Cp	1.04043
Temperature	10.33846 °C
Cp	1.040276
Temperature	11.31246 °C
Cp	1.040137
Temperature	12.28646 °C
Cp	1.040014
Temperature	13.26046 °C
Cp	1.039915
Temperature	14.23445 °C
Cp	1.03984
Temperature	15.20845 °C
Cp	1.039792
Temperature	16.18245 °C
Cp	1.039777
Temperature	17.15645 °C
Cp	1.03979
Temperature	18.13044 °C
Cp	1.039834
Temperature	19.10444 °C
Cp	1.039903
Temperature	20.07844 °C
Cp	1.040019
Temperature	21.05243 °C
Cp	1.040159
Temperature	22.02643 °C
Cp	1.040318
Temperature	23.00043 °C
Cp	1.040496
Temperature	23.97443 °C
Cp	1.040695
Temperature	24.94842 °C
Cp	1.040908
Temperature	25.92242 °C
Cp	1.041143
Temperature	26.89642 °C
Cp	1.041371
Temperature	27.87042 °C
Cp	1.04161
Temperature	28.84441 °C
Cp	1.041855
Temperature	29.81841 °C
Cp	1.042094
Temperature	30.79241 °C
Cp	1.042325
Temperature	31.76641 °C
Cp	1.042534
Temperature	32.7404 °C
Cp	1.04274
Temperature	33.7144 °C
Cp	1.042917
Temperature	34.6884 °C
Cp	1.043064
Temperature	35.6624 °C
Cp	1.04319
Temperature	36.63639 °C
Cp	1.043295
Temperature	37.61039 °C
Cp	1.043386
Temperature	38.58438 °C
Cp	1.043453
Temperature	39.55838 °C
Cp	1.04351
Temperature	40.53238 °C
Cp	1.043562
Temperature	41.50638 °C
Cp	1.043611
Temperature	42.48037 °C
Cp	1.043655
Temperature	43.45437 °C
Cp	1.043698
Temperature	44.42837 °C
Cp	1.043742
Temperature	45.40237 °C
Cp	1.043786
Temperature	46.37637 °C
Cp	1.04383
Temperature	47.35036 °C
Cp	1.043871
Temperature	48.32436 °C
Cp	1.043918
Temperature	49.29836 °C
Cp	1.043969
Temperature	50.27235 °C
Cp	1.044022
Temperature	51.24635 °C
Cp	1.044086
Temperature	52.22035 °C
Cp	1.044155
Temperature	53.19434 °C
Cp	1.044236
Temperature	54.16834 °C
Cp	1.044331
Temperature	55.14234 °C
Cp	1.04443
Temperature	56.11634 °C
Cp	1.04456
Temperature	57.09034 °C
Cp	1.044703
Temperature	58.06433 °C
Cp	1.044864
Temperature	59.03833 °C
Cp	1.045041
Temperature	60.01233 °C
Cp	1.045232
Temperature	60.98632 °C
Cp	1.045442
Temperature	61.96032 °C
Cp	1.045673
Temperature	62.93432 °C
Cp	1.045911
Temperature	63.90831 °C
Cp	1.046162
Temperature	64.88231 °C
Cp	1.046425
Temperature	65.85631 °C
Cp	1.04669
Temperature	66.83031 °C
Cp	1.046952
Temperature	67.80431 °C
Cp	1.047203
Temperature	68.77831 °C
Cp	1.047453
Temperature	69.7523 °C
Cp	1.047677
Temperature	70.7263 °C
Cp	1.047882
Temperature	71.70029 °C
Cp	1.048065
Temperature	72.67429 °C
Cp	1.048226
Temperature	73.64828 °C
Cp	1.048375
Temperature	74.62228 °C
Cp	1.048498
Temperature	75.59628 °C
Cp	1.04861
Temperature	76.57028 °C
Cp	1.048713
Temperature	77.54427 °C
Cp	1.048811
Temperature	78.51827 °C
Cp	1.048901
Temperature	79.49227 °C
Cp	1.048978
Temperature	80.46627 °C
Cp	1.049068
Temperature	81.44027 °C
Cp	1.049148
Temperature	82.41426 °C
Cp	1.04922
Temperature	83.38826 °C
Cp	1.049288
Temperature	84.36226 °C
Cp	1.049353
Temperature	85.33626 °C
Cp	1.049435
Temperature	86.31025 °C
Cp	1.049486
Temperature	87.28425 °C
Cp	1.049549
Temperature	88.25825 °C
Cp	1.049615
Temperature	89.23225 °C
Cp	1.049683
Temperature	90.20624 °C
Cp	1.049742
Temperature	91.18024 °C
Cp	1.04977
Temperature	92.15424 °C
Cp	1.04982
Temperature	93.12823 °C
Cp	1.049839
Temperature	94.10223 °C
Cp	1.049829
Temperature	95.07623 °C
Cp	1.049792
Temperature	96.05022 °C
Cp	1.049731
Temperature	97.02422 °C
Cp	1.049673
Temperature	97.99822 °C
Cp	1.049564
Temperature	98.97221 °C
Cp	1.049451
Temperature	99.94621 °C
Cp	1.049339
Temperature	100.9202 °C
Cp	1.049223
Temperature	101.8942 °C
Cp	1.049111
Temperature	102.8682 °C
Cp	1.048998
Temperature	103.8422 °C
Cp	1.048886
Temperature	104.8162 °C
Cp	1.048782
Temperature	105.7902 °C
Cp	1.048679
Temperature	106.7642 °C
Cp	1.048577
Temperature	107.7382 °C
Cp	1.048481
Temperature	108.7122 °C
Cp	1.048391
Temperature	109.6862 °C
Cp	1.048309
Temperature	110.6602 °C
Cp	1.048232
Temperature	111.6342 °C
Cp	1.04816
Temperature	112.6082 °C
Cp	1.048096
Temperature	113.5822 °C
Cp	1.048038
Temperature	114.5562 °C
Cp	1.047984
Temperature	115.5302 °C
Cp	1.047932
Temperature	116.5042 °C
Cp	1.047888
Temperature	117.4782 °C
Cp	1.047844
Temperature	118.4522 °C
Cp	1.047801
Temperature	119.4262 °C
Cp	1.047756
Temperature	120.4002 °C
Cp	1.047715
Temperature	121.3742 °C
Cp	1.047678
Temperature	122.3482 °C
Cp	1.047638
Temperature	123.3222 °C
Cp	1.047605
Temperature	124.2961 °C
Cp	1.047578
Temperature	125.2701 °C
Cp	1.047555
Temperature	126.2441 °C
Cp	1.047539
Temperature	127.2181 °C
Cp	1.047525
Temperature	128.1921 °C
Cp	1.047524
Temperature	129.1661 °C
Cp	1.047527
Temperature	130.1401 °C
Cp	1.047536
Temperature	131.1141 °C
Cp	1.047554
Temperature	132.0881 °C
Cp	1.047582
Temperature	133.0621 °C
Cp	1.047624
Temperature	134.0361 °C
Cp	1.047662
Temperature	135.0101 °C
Cp	1.047714
Temperature	135.9841 °C
Cp	1.047779
Temperature	136.9581 °C
Cp	1.047853
Temperature	137.9321 °C
Cp	1.047933
Temperature	138.9061 °C
Cp	1.048018
Temperature	139.8801 °C
Cp	1.048097
Temperature	140.8541 °C
Cp	1.048188
Temperature	141.8281 °C
Cp	1.048267
Temperature	142.8021 °C
Cp	1.048337
Temperature	143.7761 °C
Cp	1.048398
Temperature	144.7501 °C
Cp	1.048449
Temperature	145.7241 °C
Cp	1.048503
Temperature	146.6981 °C
Cp	1.048532
Temperature	147.6721 °C
Cp	1.04856
Temperature	148.6461 °C
Cp	1.048587
Temperature	149.6201 °C
Cp	1.04861
Temperature	150.5941 °C
Cp	1.048628
Temperature	151.5681 °C
Cp	1.048627
Temperature	152.5421 °C
Cp	1.048642
Temperature	153.5161 °C
Cp	1.048646
Temperature	154.4901 °C
Cp	1.048642
Temperature	155.4641 °C
Cp	1.048638
Temperature	156.438 °C
Cp	1.048641
Temperature	157.412 °C
Cp	1.048673
Temperature	158.386 °C
Cp	1.048706
Temperature	159.36 °C
Cp	1.048776
Temperature	160.334 °C
Cp	1.048889
Temperature	161.308 °C
Cp	1.049047
Temperature	162.282 °C
Cp	1.049254
Temperature	163.256 °C
Cp	1.049495
Temperature	164.23 °C
Cp	1.049811
Temperature	165.204 °C
Cp	1.050172
Temperature	166.178 °C
Cp	1.050582
Temperature	167.152 °C
Cp	1.051038
Temperature	168.126 °C
Cp	1.051542
Temperature	169.1 °C
Cp	1.052114
Temperature	170.074 °C
Cp	1.052695
Temperature	171.048 °C
Cp	1.053323
Temperature	172.022 °C
Cp	1.053989
Temperature	172.996 °C
Cp	1.05468
Temperature	173.97 °C
Cp	1.055383
Temperature	174.944 °C
Cp	1.056084
Temperature	175.918 °C
Cp	1.056758
Temperature	176.892 °C
Cp	1.057421
Temperature	177.866 °C
Cp	1.058033
Temperature	178.84 °C
Cp	1.058585
Temperature	179.814 °C
Cp	1.059071
Temperature	180.788 °C
Cp	1.059486
Temperature	181.762 °C
Cp	1.059844
Temperature	182.736 °C
Cp	1.060098
Temperature	183.71 °C
Cp	1.060287
Temperature	184.684 °C
Cp	1.06041
Temperature	185.658 °C
Cp	1.060463
Temperature	186.632 °C
Cp	1.060444
Temperature	187.606 °C
Cp	1.060339
Temperature	188.58 °C
Cp	1.060207
Temperature	189.554 °C
Cp	1.060006
Temperature	190.528 °C
Cp	1.059754
Temperature	191.502 °C
Cp	1.059464
Temperature	192.476 °C
Cp	1.059152
Temperature	193.45 °C
Cp	1.05885
Temperature	194.424 °C
Cp	1.058521
Temperature	195.3979 °C
Cp	1.05822
Temperature	196.3719 °C
Cp	1.057951
Temperature	197.3459 °C
Cp	1.057719
Temperature	198.3199 °C
Cp	1.057524
Temperature	199.2939 °C
Cp	1.057347
Temperature	200.2679 °C
Cp	1.057229
Temperature	201.2419 °C
Cp	1.05713
Temperature	202.2159 °C
Cp	1.05705
Temperature	203.1899 °C
Cp	1.056984
Temperature	204.1639 °C
Cp	1.05693
Temperature	205.1379 °C
Cp	1.0569
Temperature	206.1119 °C
Cp	1.05685
Temperature	207.0859 °C
Cp	1.056808
Temperature	208.0599 °C
Cp	1.05677
Temperature	209.0339 °C
Cp	1.05673
Temperature	210.0079 °C
Cp	1.056685
Temperature	210.9819 °C
Cp	1.056633
Temperature	211.9559 °C
Cp	1.056566
Temperature	212.9299 °C
Cp	1.056501
Temperature	213.9039 °C
Cp	1.056424
Temperature	214.8779 °C
Cp	1.056341
Temperature	215.8519 °C
Cp	1.056252
Temperature	216.8259 °C
Cp	1.056168
Temperature	217.7999 °C
Cp	1.0561
Temperature	218.7739 °C
Cp	1.056026
Temperature	219.7479 °C
Cp	1.055973
Temperature	220.7219 °C
Cp	1.055941
Temperature	221.6959 °C
Cp	1.055926
Temperature	222.6699 °C
Cp	1.055924
Temperature	223.6439 °C
Cp	1.055919
Temperature	224.6179 °C
Cp	1.055941
Temperature	225.5919 °C
Cp	1.055954
Temperature	226.5659 °C
Cp	1.055958
Temperature	227.5399 °C
Cp	1.055954
Temperature	228.5139 °C
Cp	1.055943
Temperature	229.4879 °C
Cp	1.055938
Temperature	230.4619 °C
Cp	1.055901
Temperature	231.4359 °C
Cp	1.055866
Temperature	232.4098 °C
Cp	1.055832
Temperature	233.3838 °C
Cp	1.055797
Temperature	234.3578 °C
Cp	1.055757
Temperature	235.3318 °C
Cp	1.055695
Temperature	236.3058 °C
Cp	1.055658
Temperature	237.2798 °C
Cp	1.055607
Temperature	238.2538 °C
Cp	1.055547
Temperature	239.2278 °C
Cp	1.055481
Temperature	240.2018 °C
Cp	1.055414
Temperature	241.1758 °C
Cp	1.055372
Temperature	242.1498 °C
Cp	1.055303
Temperature	243.1238 °C
Cp	1.055254
Temperature	244.0978 °C
Cp	1.055227
Temperature	245.0718 °C
Cp	1.055215
Temperature	246.0458 °C
Cp	1.055219
Temperature	247.0198 °C
Cp	1.055213
Temperature	247.9938 °C
Cp	1.055252
Temperature	248.9678 °C
Cp	1.055289
Temperature	249.9418 °C
Cp	1.055323
Temperature	250.9158 °C
Cp	1.055358
Temperature	251.8898 °C
Cp	1.055391
Temperature	252.8638 °C
Cp	1.055427
Temperature	253.8378 °C
Cp	1.05547
Temperature	254.8118 °C
Cp	1.055506
Temperature	255.7858 °C
Cp	1.055552
Temperature	256.7598 °C
Cp	1.055605
Temperature	257.7338 °C
Cp	1.055662
Temperature	258.7078 °C
Cp	1.055723
Temperature	259.6818 °C
Cp	1.055782
Temperature	260.6558 °C
Cp	1.055847
Temperature	261.6298 °C
Cp	1.055909
Temperature	262.6038 °C
Cp	1.055965
Temperature	263.5778 °C
Cp	1.05602
Temperature	264.5518 °C
Cp	1.056073
Temperature	265.5258 °C
Cp	1.056125
Temperature	266.4998 °C
Cp	1.056176
Temperature	267.4738 °C
Cp	1.05623
Temperature	268.4478 °C
Cp	1.056288
Temperature	269.4218 °C
Cp	1.056349
Temperature	270.3957 °C
Cp	1.056416
Temperature	271.3697 °C
Cp	1.056491
Temperature	272.3437 °C
Cp	1.056571
Temperature	273.3177 °C
Cp	1.056658
Temperature	274.2917 °C
Cp	1.05675
Temperature	275.2657 °C
Cp	1.056848
Temperature	276.2397 °C
Cp	1.056947
Temperature	277.2137 °C
Cp	1.057042
Temperature	278.1877 °C
Cp	1.057142
Temperature	279.1617 °C
Cp	1.057233
Temperature	280.1357 °C
Cp	1.057313
Temperature	281.1097 °C
Cp	1.057381
Temperature	282.0837 °C
Cp	1.057435
Temperature	283.0577 °C
Cp	1.057481
Temperature	284.0317 °C
Cp	1.057495
Temperature	285.0057 °C
Cp	1.057498
Temperature	285.9797 °C
Cp	1.057486
Temperature	286.9537 °C
Cp	1.057462
Temperature	287.9277 °C
Cp	1.057423
Temperature	288.9017 °C
Cp	1.057373
Temperature	289.8757 °C
Cp	1.05731
Temperature	290.8497 °C
Cp	1.057244
Temperature	291.8237 °C
Cp	1.057169
Temperature	292.7977 °C
Cp	1.057092
Temperature	293.7717 °C
Cp	1.057015
Temperature	294.7457 °C
Cp	1.05694
Temperature	295.7197 °C
Cp	1.056872
Temperature	296.6937 °C
Cp	1.056808
Temperature	297.6677 °C
Cp	1.056752
Temperature	298.6417 °C
Cp	1.056704
Temperature	299.6157 °C
Cp	1.056662
Temperature	300.5897 °C
Cp	1.056626
Temperature	301.5637 °C
Cp	1.05659
Temperature	302.5377 °C
Cp	1.056563
Temperature	303.5117 °C
Cp	1.056535
Temperature	304.4856 °C
Cp	1.056507
Temperature	305.4596 °C
Cp	1.05648
Temperature	306.4336 °C
Cp	1.056456
Temperature	307.4076 °C
Cp	1.056444
Temperature	308.3816 °C
Cp	1.056429
Temperature	309.3556 °C
Cp	1.056431
Temperature	310.3296 °C
Cp	1.056452
Temperature	311.3036 °C
Cp	1.056492
Temperature	312.2776 °C
Cp	1.056555
Temperature	313.2516 °C
Cp	1.056631
Temperature	314.2256 °C
Cp	1.056748
Temperature	315.1996 °C
Cp	1.056883
Temperature	316.1736 °C
Cp	1.057038
Temperature	317.1476 °C
Cp	1.057212
Temperature	318.1216 °C
Cp	1.057405
Temperature	319.0956 °C
Cp	1.057631
Temperature	320.0696 °C
Cp	1.057845
Temperature	321.0436 °C
Cp	1.058079
Temperature	322.0176 °C
Cp	1.058326
Temperature	322.9916 °C
Cp	1.058582
Temperature	323.9656 °C
Cp	1.058841
Temperature	324.9396 °C
Cp	1.059099
Temperature	325.9136 °C
Cp	1.059348
Temperature	326.8876 °C
Cp	1.059604
Temperature	327.8616 °C
Cp	1.05985
Temperature	328.8356 °C
Cp	1.060092
Temperature	329.8096 °C
Cp	1.060333
Temperature	330.7836 °C
Cp	1.060579
Temperature	331.7576 °C
Cp	1.060841
Temperature	332.7316 °C
Cp	1.061109
Temperature	333.7056 °C
Cp	1.061398
Temperature	334.6796 °C
Cp	1.061709
Temperature	335.6536 °C
Cp	1.062038
Temperature	336.6276 °C
Cp	1.062384
Temperature	337.6016 °C
Cp	1.062742
Temperature	338.5755 °C
Cp	1.063104
Temperature	339.5495 °C
Cp	1.063464
Temperature	340.5235 °C
Cp	1.063814
Temperature	341.4975 °C
Cp	1.064146
Temperature	342.4715 °C
Cp	1.064453
Temperature	343.4455 °C
Cp	1.064728
Temperature	344.4195 °C
Cp	1.06497
Temperature	345.3935 °C
Cp	1.065176
Temperature	346.3675 °C
Cp	1.065346
Temperature	347.3415 °C
Cp	1.065484
Temperature	348.3155 °C
Cp	1.065596
Temperature	349.2895 °C
Cp	1.065687
Temperature	350.2635 °C
Cp	1.065775
Temperature	351.2375 °C
Cp	1.065862
Temperature	352.2115 °C
Cp	1.06596
Temperature	353.1855 °C
Cp	1.066075
Temperature	354.1595 °C
Cp	1.066217
Temperature	355.1335 °C
Cp	1.066395
Temperature	356.1075 °C
Cp	1.06659
Temperature	357.0815 °C
Cp	1.066817
Temperature	358.0555 °C
Cp	1.067067
Temperature	359.0295 °C
Cp	1.067329
Temperature	360.0035 °C
Cp	1.067591
Temperature	360.9775 °C
Cp	1.067838
Temperature	361.9515 °C
Cp	1.068055
Temperature	362.9255 °C
Cp	1.068232
Temperature	363.8995 °C
Cp	1.068357
Temperature	364.8735 °C
Cp	1.068423
Temperature	365.8475 °C
Cp	1.068431
Temperature	366.8215 °C
Cp	1.068385
Temperature	367.7955 °C
Cp	1.068293
Temperature	368.7695 °C
Cp	1.068177
Temperature	369.7435 °C
Cp	1.068051
Temperature	370.7175 °C
Cp	1.067937
Temperature	371.6914 °C
Cp	1.067864
Temperature	372.6654 °C
Cp	1.067851
Temperature	373.6394 °C
Cp	1.067924
Temperature	374.6134 °C
Cp	1.068083
Temperature	375.5874 °C
Cp	1.068344
Temperature	376.5614 °C
Cp	1.068699
Temperature	377.5354 °C
Cp	1.069131
Temperature	378.5094 °C
Cp	1.069605
Temperature	379.4834 °C
Cp	1.070071
Temperature	380.4574 °C
Cp	1.070487
Temperature	381.4314 °C
Cp	1.07077
Temperature	382.4054 °C
Cp	1.070846
Temperature	383.3794 °C
Cp	1.070635
Temperature	384.3534 °C
Cp	1.070055
Temperature	385.3274 °C
Cp	1.069033
Temperature	386.3014 °C
Cp	1.067489
Temperature	387.2754 °C
Cp	1.065378
Temperature	388.2494 °C
Cp	1.062665
Temperature	389.2234 °C
Cp	1.059324
Temperature	390.1974 °C
Cp	1.055366
Temperature	391.1714 °C
Cp	1.050821
Temperature	392.1454 °C
Cp	1.045742
Temperature	393.1194 °C
Cp	1.040203
Temperature	394.0934 °C
Cp	1.034295
Temperature	395.0674 °C
Cp	1.028124
Temperature	396.0414 °C
Cp	1.021801
[Rev Cp Calibration]
Date Applied	07/01/2025 13:18:35
Description	From -90.000 °C to 391.202 °C at 2.000°C/min
Gas Type	Nitrogen
Pan Type	Aluminum Hermetic
Source Files 1	C:\ProgramData\TA Instruments\TRIOS\Data\Reverse Heat Capacity Calibration(8).tri
GUID	2f9866b8-ce4e-42f5-95a1-c21443fc3171
Temperature	-89.99985 °C
Cp	1.026385
Temperature	-89.03745 °C
Cp	1.030641
Temperature	-88.07504 °C
Cp	1.034621
Temperature	-87.11264 °C
Cp	1.038235
Temperature	-86.15024 °C
Cp	1.041454
Temperature	-85.18784 °C
Cp	1.044296
Temperature	-84.22543 °C
Cp	1.04679
Temperature	-83.26302 °C
Cp	1.048951
Temperature	-82.30062 °C
Cp	1.050818
Temperature	-81.33822 °C
Cp	1.052404
Temperature	-80.37582 °C
Cp	1.053789
Temperature	-79.41341 °C
Cp	1.055011
Temperature	-78.45101 °C
Cp	1.056107
Temperature	-77.48861 °C
Cp	1.05712
Temperature	-76.52621 °C
Cp	1.058067
Temperature	-75.5638 °C
Cp	1.059033
Temperature	-74.6014 °C
Cp	1.060008
Temperature	-73.639 °C
Cp	1.06102
Temperature	-72.67659 °C
Cp	1.062091
Temperature	-71.71419 °C
Cp	1.06324
Temperature	-70.75179 °C
Cp	1.064487
Temperature	-69.78938 °C
Cp	1.065824
Temperature	-68.82698 °C
Cp	1.067263
Temperature	-67.86458 °C
Cp	1.068802
Temperature	-66.90218 °C
Cp	1.070434
Temperature	-65.93977 °C
Cp	1.07215
Temperature	-64.97737 °C
Cp	1.073961
Temperature	-64.01497 °C
Cp	1.07579
Temperature	-63.05256 °C
Cp	1.077675
Temperature	-62.09016 °C
Cp	1.0796
Temperature	-61.12776 °C
Cp	1.081549
Temperature	-60.16536 °C
Cp	1.083507
Temperature	-59.20295 °C
Cp	1.085459
Temperature	-58.24055 °C
Cp	1.087374
Temperature	-57.27814 °C
Cp	1.089301
Temperature	-56.31574 °C
Cp	1.091179
Temperature	-55.35334 °C
Cp	1.09301
Temperature	-54.39093 °C
Cp	1.094799
Temperature	-53.42853 °C
Cp	1.09655
Temperature	-52.46613 °C
Cp	1.098302
Temperature	-51.50373 °C
Cp	1.099969
Temperature	-50.54132 °C
Cp	1.101634
Temperature	-49.57892 °C
Cp	1.103291
Temperature	-48.61652 °C
Cp	1.104934
Temperature	-47.65411 °C
Cp	1.106558
Temperature	-46.69171 °C
Cp	1.108129
Temperature	-45.72931 °C
Cp	1.109722
Temperature	-44.76691 °C
Cp	1.111267
Temperature	-43.8045 °C
Cp	1.112769
Temperature	-42.8421 °C
Cp	1.11423
Temperature	-41.8797 °C
Cp	1.115656
Temperature	-40.91729 °C
Cp	1.117056
Temperature	-39.95489 °C
Cp	1.118417
Temperature	-38.99249 °C
Cp	1.119757
Temperature	-38.03008 °C
Cp	1.121077
Temperature	-37.06768 °C
Cp	1.12238
Temperature	-36.10528 °C
Cp	1.123667
Temperature	-35.14288 °C
Cp	1.124939
Temperature	-34.18047 °C
Cp	1.126202
Temperature	-33.21807 °C
Cp	1.127441
Temperature	-32.25566 °C
Cp	1.128669
Temperature	-31.29326 °C
Cp	1.129881
Temperature	-30.33086 °C
Cp	1.131073
Temperature	-29.36846 °C
Cp	1.13224
Temperature	-28.40605 °C
Cp	1.133372
Temperature	-27.44365 °C
Cp	1.134479
Temperature	-26.48125 °C
Cp	1.135545
Temperature	-25.51884 °C
Cp	1.136566
Temperature	-24.55644 °C
Cp	1.13754
Temperature	-23.59404 °C
Cp	1.138466
Temperature	-22.63164 °C
Cp	1.139347
Temperature	-21.66923 °C
Cp	1.140172
Temperature	-20.70683 °C
Cp	1.140951
Temperature	-19.74443 °C
Cp	1.141683
Temperature	-18.78202 °C
Cp	1.14237
Temperature	-17.81962 °C
Cp	1.143013
Temperature	-16.85722 °C
Cp	1.143601
Temperature	-15.89482 °C
Cp	1.14417
Temperature	-14.93241 °C
Cp	1.144696
Temperature	-13.97001 °C
Cp	1.145184
Temperature	-13.00761 °C
Cp	1.145641
Temperature	-12.0452 °C
Cp	1.14607
Temperature	-11.0828 °C
Cp	1.146477
Temperature	-10.1204 °C
Cp	1.146876
Temperature	-9.157994 °C
Cp	1.147244
Temperature	-8.195591 °C
Cp	1.147609
Temperature	-7.233188 °C
Cp	1.147968
Temperature	-6.270785 °C
Cp	1.148321
Temperature	-5.308382 °C
Cp	1.148663
Temperature	-4.345979 °C
Cp	1.148978
Temperature	-3.383576 °C
Cp	1.149303
Temperature	-2.421173 °C
Cp	1.1496
Temperature	-1.45877 °C
Cp	1.149872
Temperature	-0.496367 °C
Cp	1.150121
Temperature	0.466036 °C
Cp	1.15035
Temperature	1.428439 °C
Cp	1.150573
Temperature	2.390842 °C
Cp	1.150761
Temperature	3.353245 °C
Cp	1.150942
Temperature	4.315648 °C
Cp	1.151115
Temperature	5.278051 °C
Cp	1.151279
Temperature	6.240454 °C
Cp	1.151435
Temperature	7.202857 °C
Cp	1.151582
Temperature	8.16526 °C
Cp	1.151718
Temperature	9.127664 °C
Cp	1.151844
Temperature	10.09007 °C
Cp	1.151962
Temperature	11.05247 °C
Cp	1.152071
Temperature	12.01487 °C
Cp	1.152174
Temperature	12.97727 °C
Cp	1.15227
Temperature	13.93968 °C
Cp	1.152361
Temperature	14.90208 °C
Cp	1.15245
Temperature	15.86448 °C
Cp	1.152536
Temperature	16.82689 °C
Cp	1.152622
Temperature	17.78929 °C
Cp	1.152709
Temperature	18.75169 °C
Cp	1.152799
Temperature	19.7141 °C
Cp	1.152883
Temperature	20.6765 °C
Cp	1.152982
Temperature	21.6389 °C
Cp	1.15308
Temperature	22.60131 °C
Cp	1.153177
Temperature	23.56371 °C
Cp	1.153276
Temperature	24.52611 °C
Cp	1.153377
Temperature	25.48851 °C
Cp	1.153497
Temperature	26.45092 °C
Cp	1.153591
Temperature	27.41332 °C
Cp	1.153695
Temperature	28.37572 °C
Cp	1.153804
Temperature	29.33813 °C
Cp	1.153913
Temperature	30.30053 °C
Cp	1.154015
Temperature	31.26293 °C
Cp	1.154087
Temperature	32.22533 °C
Cp	1.154174
Temperature	33.18774 °C
Cp	1.154232
Temperature	34.15014 °C
Cp	1.154263
Temperature	35.11255 °C
Cp	1.154269
Temperature	36.07495 °C
Cp	1.154254
Temperature	37.03735 °C
Cp	1.154231
Temperature	37.99975 °C
Cp	1.154176
Temperature	38.96216 °C
Cp	1.154116
Temperature	39.92456 °C
Cp	1.154055
Temperature	40.88696 °C
Cp	1.153996
Temperature	41.84937 °C
Cp	1.153939
Temperature	42.81177 °C
Cp	1.153889
Temperature	43.77417 °C
Cp	1.153844
Temperature	44.73658 °C
Cp	1.153811
Temperature	45.69898 °C
Cp	1.153786
Temperature	46.66138 °C
Cp	1.153769
Temperature	47.62378 °C
Cp	1.153761
Temperature	48.58619 °C
Cp	1.153762
Temperature	49.54859 °C
Cp	1.153771
Temperature	50.51099 °C
Cp	1.153783
Temperature	51.4734 °C
Cp	1.1538
Temperature	52.4358 °C
Cp	1.153821
Temperature	53.3982 °C
Cp	1.153843
Temperature	54.3606 °C
Cp	1.153865
Temperature	55.32301 °C
Cp	1.153879
Temperature	56.28541 °C
Cp	1.153902
Temperature	57.24781 °C
Cp	1.15392
Temperature	58.21022 °C
Cp	1.153935
Temperature	59.17262 °C
Cp	1.15395
Temperature	60.13502 °C
Cp	1.153968
Temperature	61.09743 °C
Cp	1.154004
Temperature	62.05983 °C
Cp	1.154027
Temperature	63.02223 °C
Cp	1.154066
Temperature	63.98463 °C
Cp	1.154123
Temperature	64.94704 °C
Cp	1.154196
Temperature	65.90944 °C
Cp	1.154283
Temperature	66.87184 °C
Cp	1.154383
Temperature	67.83424 °C
Cp	1.154487
Temperature	68.79665 °C
Cp	1.15461
Temperature	69.75906 °C
Cp	1.154733
Temperature	70.72146 °C
Cp	1.154854
Temperature	71.68386 °C
Cp	1.154973
Temperature	72.64626 °C
Cp	1.155089
Temperature	73.60867 °C
Cp	1.15521
Temperature	74.57107 °C
Cp	1.15531
Temperature	75.53347 °C
Cp	1.155409
Temperature	76.49587 °C
Cp	1.155506
Temperature	77.45827 °C
Cp	1.155596
Temperature	78.42068 °C
Cp	1.155678
Temperature	79.38308 °C
Cp	1.155733
Temperature	80.34549 °C
Cp	1.155807
Temperature	81.30789 °C
Cp	1.155861
Temperature	82.27029 °C
Cp	1.155901
Temperature	83.2327 °C
Cp	1.155933
Temperature	84.1951 °C
Cp	1.155961
Temperature	85.1575 °C
Cp	1.156017
Temperature	86.1199 °C
Cp	1.156039
Temperature	87.08231 °C
Cp	1.156086
Temperature	88.04471 °C
Cp	1.156157
Temperature	89.00711 °C
Cp	1.156251
Temperature	89.96951 °C
Cp	1.156367
Temperature	90.93192 °C
Cp	1.156501
Temperature	91.89433 °C
Cp	1.156642
Temperature	92.85673 °C
Cp	1.156814
Temperature	93.81913 °C
Cp	1.156988
Temperature	94.78153 °C
Cp	1.157165
Temperature	95.74393 °C
Cp	1.157348
Temperature	96.70634 °C
Cp	1.157536
Temperature	97.66874 °C
Cp	1.15774
Temperature	98.63114 °C
Cp	1.157933
Temperature	99.59354 °C
Cp	1.158139
Temperature	100.5559 °C
Cp	1.158354
Temperature	101.5184 °C
Cp	1.158574
Temperature	102.4808 °C
Cp	1.158796
Temperature	103.4432 °C
Cp	1.15901
Temperature	104.4056 °C
Cp	1.159229
Temperature	105.368 °C
Cp	1.159435
Temperature	106.3304 °C
Cp	1.159626
Temperature	107.2928 °C
Cp	1.159803
Temperature	108.2552 °C
Cp	1.159964
Temperature	109.2176 °C
Cp	1.160111
Temperature	110.18 °C
Cp	1.160234
Temperature	111.1424 °C
Cp	1.160342
Temperature	112.1048 °C
Cp	1.160432
Temperature	113.0672 °C
Cp	1.160504
Temperature	114.0296 °C
Cp	1.160558
Temperature	114.992 °C
Cp	1.160594
Temperature	115.9544 °C
Cp	1.16061
Temperature	116.9168 °C
Cp	1.160614
Temperature	117.8792 °C
Cp	1.160601
Temperature	118.8416 °C
Cp	1.160574
Temperature	119.804 °C
Cp	1.160534
Temperature	120.7664 °C
Cp	1.160485
Temperature	121.7288 °C
Cp	1.160433
Temperature	122.6912 °C
Cp	1.160372
Temperature	123.6536 °C
Cp	1.160313
Temperature	124.616 °C
Cp	1.160255
Temperature	125.5784 °C
Cp	1.160201
Temperature	126.5408 °C
Cp	1.16015
Temperature	127.5032 °C
Cp	1.160101
Temperature	128.4656 °C
Cp	1.160059
Temperature	129.428 °C
Cp	1.16002
Temperature	130.3904 °C
Cp	1.159983
Temperature	131.3528 °C
Cp	1.159948
Temperature	132.3152 °C
Cp	1.159916
Temperature	133.2776 °C
Cp	1.159893
Temperature	134.2401 °C
Cp	1.15986
Temperature	135.2025 °C
Cp	1.159833
Temperature	136.1649 °C
Cp	1.15981
Temperature	137.1273 °C
Cp	1.159789
Temperature	138.0897 °C
Cp	1.159769
Temperature	139.0521 °C
Cp	1.15973
Temperature	140.0145 °C
Cp	1.159723
Temperature	140.9769 °C
Cp	1.159706
Temperature	141.9393 °C
Cp	1.159682
Temperature	142.9017 °C
Cp	1.159653
Temperature	143.8641 °C
Cp	1.159625
Temperature	144.8265 °C
Cp	1.159599
Temperature	145.7889 °C
Cp	1.15959
Temperature	146.7513 °C
Cp	1.15957
Temperature	147.7137 °C
Cp	1.159569
Temperature	148.6761 °C
Cp	1.159584
Temperature	149.6385 °C
Cp	1.159613
Temperature	150.6009 °C
Cp	1.159654
Temperature	151.5633 °C
Cp	1.15969
Temperature	152.5257 °C
Cp	1.159761
Temperature	153.4881 °C
Cp	1.159829
Temperature	154.4505 °C
Cp	1.159901
Temperature	155.4129 °C
Cp	1.159981
Temperature	156.3753 °C
Cp	1.160076
Temperature	157.3377 °C
Cp	1.160207
Temperature	158.3001 °C
Cp	1.160336
Temperature	159.2625 °C
Cp	1.160508
Temperature	160.2249 °C
Cp	1.160724
Temperature	161.1873 °C
Cp	1.160986
Temperature	162.1497 °C
Cp	1.161296
Temperature	163.1122 °C
Cp	1.161639
Temperature	164.0746 °C
Cp	1.162062
Temperature	165.037 °C
Cp	1.162527
Temperature	165.9994 °C
Cp	1.163037
Temperature	166.9618 °C
Cp	1.163591
Temperature	167.9242 °C
Cp	1.164188
Temperature	168.8866 °C
Cp	1.164826
Temperature	169.849 °C
Cp	1.165508
Temperature	170.8114 °C
Cp	1.166203
Temperature	171.7738 °C
Cp	1.166927
Temperature	172.7362 °C
Cp	1.167664
Temperature	173.6986 °C
Cp	1.168401
Temperature	174.661 °C
Cp	1.169124
Temperature	175.6234 °C
Cp	1.169799
Temperature	176.5858 °C
Cp	1.170462
Temperature	177.5482 °C
Cp	1.171058
Temperature	178.5106 °C
Cp	1.171581
Temperature	179.473 °C
Cp	1.172029
Temperature	180.4354 °C
Cp	1.1724
Temperature	181.3978 °C
Cp	1.172722
Temperature	182.3602 °C
Cp	1.172924
Temperature	183.3226 °C
Cp	1.173072
Temperature	184.285 °C
Cp	1.173165
Temperature	185.2474 °C
Cp	1.173204
Temperature	186.2098 °C
Cp	1.173191
Temperature	187.1722 °C
Cp	1.173098
Temperature	188.1346 °C
Cp	1.173022
Temperature	189.097 °C
Cp	1.172893
Temperature	190.0594 °C
Cp	1.172727
Temperature	191.0218 °C
Cp	1.172536
Temperature	191.9842 °C
Cp	1.172333
Temperature	192.9466 °C
Cp	1.172129
Temperature	193.909 °C
Cp	1.171948
Temperature	194.8714 °C
Cp	1.171764
Temperature	195.8338 °C
Cp	1.171616
Temperature	196.7962 °C
Cp	1.171503
Temperature	197.7587 °C
Cp	1.171422
Temperature	198.7211 °C
Cp	1.171373
Temperature	199.6835 °C
Cp	1.171339
Temperature	200.6459 °C
Cp	1.171347
Temperature	201.6083 °C
Cp	1.171366
Temperature	202.5707 °C
Cp	1.171394
Temperature	203.5331 °C
Cp	1.171431
Temperature	204.4955 °C
Cp	1.171476
Temperature	205.4579 °C
Cp	1.17154
Temperature	206.4203 °C
Cp	1.171593
Temperature	207.3827 °C
Cp	1.171659
Temperature	208.3451 °C
Cp	1.171737
Temperature	209.3075 °C
Cp	1.171824
Temperature	210.2699 °C
Cp	1.171918
Temperature	211.2323 °C
Cp	1.172
Temperature	212.1947 °C
Cp	1.172116
Temperature	213.1571 °C
Cp	1.172226
Temperature	214.1195 °C
Cp	1.172333
Temperature	215.0819 °C
Cp	1.172439
Temperature	216.0443 °C
Cp	1.172549
Temperature	217.0067 °C
Cp	1.172689
Temperature	217.9691 °C
Cp	1.172792
Temperature	218.9315 °C
Cp	1.172914
Temperature	219.8939 °C
Cp	1.173052
Temperature	220.8563 °C
Cp	1.173203
Temperature	221.8187 °C
Cp	1.173361
Temperature	222.7811 °C
Cp	1.173523
Temperature	223.7435 °C
Cp	1.173674
Temperature	224.7059 °C
Cp	1.173842
Temperature	225.6683 °C
Cp	1.173995
Temperature	226.6307 °C
Cp	1.174137
Temperature	227.5932 °C
Cp	1.174268
Temperature	228.5556 °C
Cp	1.174393
Temperature	229.518 °C
Cp	1.174531
Temperature	230.4804 °C
Cp	1.174642
Temperature	231.4428 °C
Cp	1.174766
Temperature	232.4052 °C
Cp	1.174902
Temperature	233.3676 °C
Cp	1.175049
Temperature	234.33 °C
Cp	1.175206
Temperature	235.2924 °C
Cp	1.175351
Temperature	236.2548 °C
Cp	1.175539
Temperature	237.2172 °C
Cp	1.175721
Temperature	238.1796 °C
Cp	1.175902
Temperature	239.142 °C
Cp	1.176085
Temperature	240.1044 °C
Cp	1.176272
Temperature	241.0668 °C
Cp	1.176491
Temperature	242.0292 °C
Cp	1.176676
Temperature	242.9916 °C
Cp	1.176882
Temperature	243.954 °C
Cp	1.177106
Temperature	244.9164 °C
Cp	1.177343
Temperature	245.8788 °C
Cp	1.177589
Temperature	246.8412 °C
Cp	1.17784
Temperature	247.8036 °C
Cp	1.17808
Temperature	248.766 °C
Cp	1.178334
Temperature	249.7284 °C
Cp	1.178575
Temperature	250.6908 °C
Cp	1.178803
Temperature	251.6532 °C
Cp	1.17902
Temperature	252.6156 °C
Cp	1.179227
Temperature	253.578 °C
Cp	1.179435
Temperature	254.5404 °C
Cp	1.17962
Temperature	255.5028 °C
Cp	1.179806
Temperature	256.4652 °C
Cp	1.179992
Temperature	257.4276 °C
Cp	1.180176
Temperature	258.39 °C
Cp	1.180356
Temperature	259.3524 °C
Cp	1.180525
Temperature	260.3148 °C
Cp	1.180699
Temperature	261.2773 °C
Cp	1.18086
Temperature	262.2397 °C
Cp	1.181011
Temperature	263.2021 °C
Cp	1.18115
Temperature	264.1645 °C
Cp	1.181279
Temperature	265.1269 °C
Cp	1.181398
Temperature	266.0893 °C
Cp	1.181504
Temperature	267.0517 °C
Cp	1.1816
Temperature	268.0141 °C
Cp	1.181687
Temperature	268.9765 °C
Cp	1.181765
Temperature	269.9389 °C
Cp	1.181835
Temperature	270.9013 °C
Cp	1.181897
Temperature	271.8637 °C
Cp	1.181952
Temperature	272.8261 °C
Cp	1.182001
Temperature	273.7885 °C
Cp	1.182045
Temperature	274.7509 °C
Cp	1.182086
Temperature	275.7133 °C
Cp	1.182126
Temperature	276.6757 °C
Cp	1.182166
Temperature	277.6381 °C
Cp	1.182204
Temperature	278.6005 °C
Cp	1.182251
Temperature	279.5629 °C
Cp	1.182299
Temperature	280.5253 °C
Cp	1.182353
Temperature	281.4877 °C
Cp	1.182414
Temperature	282.4501 °C
Cp	1.182486
Temperature	283.4125 °C
Cp	1.182577
Temperature	284.3749 °C
Cp	1.182671
Temperature	285.3373 °C
Cp	1.182786
Temperature	286.2997 °C
Cp	1.182921
Temperature	287.2621 °C
Cp	1.183076
Temperature	288.2245 °C
Cp	1.183251
Temperature	289.187 °C
Cp	1.183439
Temperature	290.1494 °C
Cp	1.183654
Temperature	291.1118 °C
Cp	1.183883
Temperature	292.0742 °C
Cp	1.184126
Temperature	293.0366 °C
Cp	1.184383
Temperature	293.999 °C
Cp	1.184651
Temperature	294.9614 °C
Cp	1.184932
Temperature	295.9238 °C
Cp	1.185223
Temperature	296.8862 °C
Cp	1.185522
Temperature	297.8486 °C
Cp	1.185828
Temperature	298.811 °C
Cp	1.18614
Temperature	299.7734 °C
Cp	1.186456
Temperature	300.7358 °C
Cp	1.186773
Temperature	301.6982 °C
Cp	1.187085
Temperature	302.6606 °C
Cp	1.1874
Temperature	303.623 °C
Cp	1.187709
Temperature	304.5854 °C
Cp	1.188011
Temperature	305.5478 °C
Cp	1.188307
Temperature	306.5102 °C
Cp	1.188598
Temperature	307.4726 °C
Cp	1.188893
Temperature	308.435 °C
Cp	1.189173
Temperature	309.3974 °C
Cp	1.189456
Temperature	310.3598 °C
Cp	1.189744
Temperature	311.3222 °C
Cp	1.190034
Temperature	312.2846 °C
Cp	1.190329
Temperature	313.247 °C
Cp	1.190615
Temperature	314.2094 °C
Cp	1.190925
Temperature	315.1718 °C
Cp	1.191232
Temperature	316.1342 °C
Cp	1.191539
Temperature	317.0966 °C
Cp	1.191848
Temperature	318.059 °C
Cp	1.19216
Temperature	319.0214 °C
Cp	1.192496
Temperature	319.9838 °C
Cp	1.192805
Temperature	320.9462 °C
Cp	1.193128
Temperature	321.9086 °C
Cp	1.193462
Temperature	322.871 °C
Cp	1.193803
Temperature	323.8334 °C
Cp	1.194149
Temperature	324.7958 °C
Cp	1.194495
Temperature	325.7583 °C
Cp	1.194832
Temperature	326.7207 °C
Cp	1.195181
Temperature	327.6831 °C
Cp	1.19552
Temperature	328.6455 °C
Cp	1.195853
Temperature	329.6079 °C
Cp	1.196183
Temperature	330.5703 °C
Cp	1.196515
Temperature	331.5327 °C
Cp	1.196862
Temperature	332.4951 °C
Cp	1.197211
Temperature	333.4575 °C
Cp	1.197584
Temperature	334.4199 °C
Cp	1.197985
Temperature	335.3823 °C
Cp	1.198418
Temperature	336.3447 °C
Cp	1.198886
Temperature	337.3071 °C
Cp	1.199394
[...]
140.4350	103.3866	0.4805
140.4533	103.2018	0.4805
140.4717	103.0194	0.4805
140.4900	102.8366	0.4805
140.5083	102.6526	0.4805
140.5267	102.4705	0.4805
140.5450	102.2870	0.4805
140.5633	102.1043	0.4805
140.5817	101.9220	0.4805
140.6000	101.7374	0.4805
140.6183	101.5551	0.4806
140.6367	101.3725	0.4806
140.6550	101.1894	0.4805
140.6733	101.0059	0.4805
140.6917	100.8232	0.4805
140.7100	100.6403	0.4805
140.7283	100.4565	0.4805
140.7467	100.2738	0.4805
140.7650	100.0916	0.4805
140.7833	99.9072	0.4805
140.8017	99.7238	0.4805
140.8200	99.5418	0.4805
140.8383	99.3577	0.4804
140.8567	99.1759	0.4804
140.8750	98.9916	0.4804
140.8933	98.8095	0.4804
140.9117	98.6259	0.4804
140.9300	98.4437	0.4804
140.9483	98.2604	0.4804
140.9667	98.0782	0.4804
140.9850	97.8937	0.4804
141.0033	97.7112	0.4804
141.0217	97.5276	0.4803
141.0400	97.3445	0.4803
141.0583	97.1616	0.4803
141.0767	96.9774	0.4803
141.0950	96.7959	0.4803
141.1133	96.6132	0.4803
141.1317	96.4298	0.4803
141.1500	96.2463	0.4803
141.1683	96.0628	0.4803
141.1867	95.8801	0.4803
141.2050	95.6972	0.4803
141.2233	95.5152	0.4803
141.2417	95.3306	0.4802
141.2600	95.1487	0.4802
141.2783	94.9656	0.4802
141.2967	94.7823	0.4802
141.3150	94.5988	0.4802
141.3333	94.4157	0.4802
141.3517	94.2332	0.4802
141.3700	94.0491	0.4802
141.3883	93.8666	0.4802
141.4067	93.6828	0.4802
141.4250	93.5002	0.4801
141.4433	93.3178	0.4801
141.4617	93.1350	0.4800
141.4800	92.9521	0.4800
141.4983	92.7680	0.4800
141.5167	92.5858	0.4800
141.5350	92.4030	0.4799
141.5533	92.2185	0.4800
141.5717	92.0347	0.4800
141.5900	91.8523	0.4800
141.6083	91.6698	0.4799
141.6267	91.4861	0.4799
141.6450	91.3029	0.4799
141.6633	91.1199	0.4799
141.6817	90.9385	0.4799
141.7000	90.7544	0.4799
141.7183	90.5713	0.4799
141.7367	90.3874	0.4799
141.7550	90.2054	0.4799
141.7733	90.0216	0.4799
141.7917	89.8387	0.4799
141.8100	89.6563	0.4799
141.8283	89.4729	0.4799
141.8467	89.2897	0.4799
141.8650	89.1064	0.4799
141.8833	88.9236	0.4799
141.9017	88.7407	0.4799
141.9200	88.5568	0.4798
141.9383	88.3742	0.4798
141.9567	88.1906	0.4798
141.9750	88.0081	0.4797
141.9933	87.8259	0.4797
142.0117	87.6420	0.4797
142.0300	87.4584	0.4797
142.0483	87.2767	0.4797
142.0667	87.0925	0.4797
142.0850	86.9095	0.4796
142.1033	86.7259	0.4796
142.1217	86.5426	0.4796
142.1400	86.3608	0.4796
142.1583	86.1784	0.4795
142.1767	85.9936	0.4795
142.1950	85.8109	0.4795
142.2133	85.6292	0.4794
142.2317	85.4449	0.4794
142.2500	85.2621	0.4794
142.2683	85.0798	0.4794
142.2867	84.8951	0.4794
142.3050	84.7123	0.4793
142.3233	84.5292	0.4793
142.3417	84.3467	0.4793
142.3600	84.1636	0.4792
142.3783	83.9806	0.4792
142.3967	83.7962	0.4792
142.4150	83.6134	0.4792
142.4333	83.4297	0.4791
142.4517	83.2487	0.4791
142.4700	83.0640	0.4791
142.4883	82.8816	0.4791
142.5067	82.6994	0.4789
142.5250	82.5154	0.4790
142.5433	82.3330	0.4789
142.5617	82.1502	0.4789
142.5800	81.9662	0.4789
142.5983	81.7835	0.4789
142.6167	81.6008	0.4788
142.6350	81.4173	0.4788
142.6533	81.2338	0.4788
142.6717	81.0511	0.4788
142.6900	80.8680	0.4787
142.7083	80.6857	0.4787
142.7267	80.5017	0.4787
142.7450	80.3180	0.4787
142.7633	80.1366	0.4786
142.7817	79.9517	0.4787
142.8000	79.7701	0.4786
142.8183	79.5869	0.4786
142.8367	79.4024	0.4786
142.8550	79.2218	0.4786
142.8733	79.0367	0.4786
142.8917	78.8544	0.4785
142.9100	78.6714	0.4785
142.9283	78.4874	0.4785
142.9467	78.3050	0.4785
142.9650	78.1208	0.4784
142.9833	77.9385	0.4784
143.0017	77.7560	0.4784
143.0200	77.5727	0.4783
143.0383	77.3891	0.4783
143.0567	77.2062	0.4783
143.0750	77.0233	0.4782
143.0933	76.8395	0.4782
143.1117	76.6578	0.4782
143.1300	76.4730	0.4782
143.1483	76.2910	0.4781
143.1667	76.1082	0.4781
143.1850	75.9248	0.4781
143.2033	75.7411	0.4781
143.2217	75.5576	0.4780
143.2400	75.3753	0.4780
143.2583	75.1923	0.4780
143.2767	75.0096	0.4780
143.2950	74.8261	0.4779
143.3133	74.6426	0.4779
143.3317	74.4598	0.4779
143.3500	74.2762	0.4779
143.3683	74.0938	0.4778
143.3867	73.9109	0.4778
143.4050	73.7281	0.4778
143.4233	73.5438	0.4778
143.4417	73.3613	0.4777
143.4600	73.1788	0.4777
143.4783	72.9951	0.4777
143.4967	72.8127	0.4776
143.5150	72.6300	0.4776
143.5333	72.4461	0.4776
143.5517	72.2621	0.4776
143.5700	72.0808	0.4776
143.5883	71.8967	0.4775
143.6067	71.7143	0.4775
143.6250	71.5303	0.4775
143.6433	71.3476	0.4775
143.6617	71.1634	0.4775
143.6800	70.9809	0.4775
143.6983	70.7975	0.4774
143.7167	70.6145	0.4774
143.7350	70.4310	0.4773
143.7533	70.2491	0.4773
143.7717	70.0655	0.4773
143.7900	69.8828	0.4772
143.8083	69.7003	0.4772
143.8267	69.5161	0.4772
143.8450	69.3335	0.4771
143.8633	69.1507	0.4771
143.8817	68.9684	0.4771
143.9000	68.7845	0.4770
143.9183	68.6017	0.4770
143.9367	68.4183	0.4770
143.9550	68.2351	0.4769
143.9733	68.0526	0.4769
143.9917	67.8684	0.4769
144.0100	67.6857	0.4769
144.0283	67.5018	0.4769
144.0467	67.3182	0.4769
144.0650	67.1360	0.4769
144.0833	66.9532	0.4768
144.1017	66.7706	0.4768
144.1200	66.5866	0.4768
144.1383	66.4046	0.4768
144.1567	66.2211	0.4767
144.1750	66.0389	0.4767
144.1933	65.8540	0.4767
144.2117	65.6721	0.4766
144.2300	65.4891	0.4766
144.2483	65.3062	0.4766
144.2667	65.1227	0.4766
144.2850	64.9387	0.4765
144.3033	64.7560	0.4765
144.3217	64.5733	0.4765
144.3400	64.3894	0.4764
144.3583	64.2061	0.4763
144.3767	64.0240	0.4763
144.3950	63.8414	0.4762
144.4133	63.6572	0.4762
144.4317	63.4763	0.4761
144.4500	63.2927	0.4761
144.4683	63.1085	0.4761
144.4867	62.9255	0.4761
144.5050	62.7419	0.4761
144.5233	62.5584	0.4760
144.5417	62.3759	0.4760
144.5600	62.1922	0.4759
144.5783	62.0098	0.4759
144.5967	61.8258	0.4758
144.6150	61.6441	0.4757
144.6333	61.4612	0.4757
144.6517	61.2774	0.4756
144.6700	61.0932	0.4756
144.6883	60.9108	0.4756
144.7067	60.7282	0.4755
144.7250	60.5445	0.4755
144.7433	60.3620	0.4754
144.7617	60.1789	0.4754
144.7800	59.9953	0.4753
144.7983	59.8127	0.4752
144.8167	59.6294	0.4752
144.8350	59.4461	0.4752
144.8533	59.2642	0.4751
144.8717	59.0794	0.4751
144.8900	58.8965	0.4750
144.9083	58.7135	0.4750
144.9267	58.5310	0.4749
144.9450	58.3483	0.4749
144.9633	58.1650	0.4748
144.9817	57.9814	0.4748
145.0000	57.7974	0.4748
145.0183	57.6146	0.4747
145.0367	57.4322	0.4747
145.0550	57.2488	0.4746
145.0733	57.0659	0.4745
145.0917	56.8826	0.4745
145.1100	56.6992	0.4745
145.1283	56.5166	0.4744
145.1467	56.3338	0.4744
145.1650	56.1517	0.4744
145.1833	55.9655	0.4743
145.2017	55.7847	0.4742
145.2200	55.6013	0.4742
145.2383	55.4184	0.4742
145.2567	55.2348	0.4741
145.2750	55.0511	0.4741
145.2933	54.8683	0.4740
145.3117	54.6844	0.4740
145.3300	54.5027	0.4739
145.3483	54.3186	0.4738
145.3667	54.1367	0.4738
145.3850	53.9534	0.4738
145.4033	53.7686	0.4737
145.4217	53.5873	0.4736
145.4400	53.4045	0.4735
145.4583	53.2200	0.4735
145.4767	53.0376	0.4735
145.4950	52.8540	0.4734
145.5133	52.6709	0.4734
145.5317	52.4869	0.4733
145.5500	52.3050	0.4733
145.5683	52.1210	0.4732
145.5867	51.9381	0.4731
145.6050	51.7554	0.4731
145.6233	51.5717	0.4730
145.6417	51.3880	0.4729
145.6600	51.2054	0.4728
145.6783	51.0210	0.4728
145.6967	50.8393	0.4727
145.7150	50.6567	0.4727
145.7333	50.4732	0.4726
145.7517	50.2894	0.4725
145.7700	50.1059	0.4725
145.7883	49.9252	0.4724
145.8067	49.7404	0.4723
145.8250	49.5578	0.4723
145.8433	49.3742	0.4722
145.8617	49.1914	0.4722
145.8800	49.0076	0.4721
145.8983	48.8253	0.4721
145.9167	48.6420	0.4720
145.9350	48.4590	0.4719
145.9533	48.2758	0.4718
145.9717	48.0931	0.4718
145.9900	47.9110	0.4717
146.0083	47.7268	0.4717
146.0267	47.5433	0.4717
146.0450	47.3602	0.4716
146.0633	47.1769	0.4716
146.0817	46.9950	0.4715
146.1000	46.8108	0.4715
146.1183	46.6285	0.4713
146.1367	46.4440	0.4713
146.1550	46.2614	0.4713
146.1733	46.0789	0.4712
146.1917	45.8964	0.4712
146.2100	45.7118	0.4711
146.2283	45.5289	0.4710
146.2467	45.3449	0.4710
146.2650	45.1625	0.4709
146.2833	44.9798	0.4709
146.3017	44.7964	0.4708
146.3200	44.6133	0.4708
146.3383	44.4289	0.4707
146.3567	44.2467	0.4706
146.3750	44.0631	0.4705
146.3933	43.8798	0.4705
146.4117	43.6977	0.4705
146.4300	43.5139	0.4704
146.4483	43.3305	0.4703
146.4667	43.1486	0.4702
146.4850	42.9649	0.4702
146.5033	42.7813	0.4701
146.5217	42.5983	0.4700
146.5400	42.4158	0.4700
146.5583	42.2327	0.4699
146.5767	42.0495	0.4699
146.5950	41.8648	0.4697
146.6133	41.6829	0.4696
146.6317	41.4997	0.4696
146.6500	41.3164	0.4695
146.6683	41.1316	0.4695
146.6867	40.9495	0.4694
146.7050	40.7673	0.4693
146.7233	40.5837	0.4693
146.7417	40.4019	0.4692
146.7600	40.2179	0.4691
146.7783	40.0352	0.4690
146.7967	39.8519	0.4690
146.8150	39.6686	0.4689
146.8333	39.4856	0.4689
146.8517	39.3029	0.4687
146.8700	39.1189	0.4687
146.8883	38.9358	0.4686
146.9067	38.7528	0.4686
146.9250	38.5697	0.4685
146.9433	38.3865	0.4684
146.9617	38.2041	0.4683
146.9800	38.0212	0.4683
146.9983	37.8371	0.4682
147.0167	37.6538	0.4681
147.0350	37.4707	0.4680
147.0533	37.2882	0.4680
147.0717	37.1054	0.4679
147.0900	36.9214	0.4678
147.1083	36.7381	0.4677
147.1267	36.5557	0.4677
147.1450	36.3726	0.4675
147.1633	36.1894	0.4675
147.1817	36.0068	0.4674
147.2000	35.8230	0.4673
147.2183	35.6403	0.4672
147.2367	35.4564	0.4672
147.2550	35.2722	0.4671
147.2733	35.0902	0.4670
147.2917	34.9068	0.4669
147.3100	34.7230	0.4668
147.3283	34.5407	0.4667
147.3467	34.3562	0.4666
147.3650	34.1744	0.4665
147.3833	33.9900	0.4663
147.4017	33.8073	0.4662
147.4200	33.6240	0.4661
147.4383	33.4408	0.4660
147.4567	33.2568	0.4657
147.4750	33.0741	0.4655
147.4933	32.8909	0.4654
147.5117	32.7078	0.4652
147.5300	32.5241	0.4651
147.5483	32.3405	0.4649
147.5667	32.1577	0.4647
147.5850	31.9742	0.4645
147.6033	31.7915	0.4642
147.6217	31.6087	0.4639
147.6400	31.4255	0.4634
147.6583	31.2401	0.4632
147.6767	31.0575	0.4627
147.6950	30.8740	0.4625
147.7133	30.6911	0.4623
147.7317	30.5085	0.4621
147.7500	30.3246	0.4618
147.7683	30.1421	0.4610
147.7867	29.9577	0.4605
147.8050	29.7743	0.4603
147.8233	29.5914	0.4598
147.8417	29.4070	0.4594
147.8600	29.2239	0.4588
147.8783	29.0397	0.4581
147.8967	28.8563	0.4575
147.9150	28.6733	0.4569
147.9333	28.4906	0.4563
147.9517	28.3059	0.4559
147.9700	28.1218	0.4551
147.9883	27.9394	0.4545
148.0067	27.7548	0.4540
148.0250	27.5708	0.4529
148.0433	27.3872	0.4526
148.0617	27.2039	0.4517
148.0800	27.0208	0.4512
148.0983	26.8365	0.4502
148.1167	26.6524	0.4495
148.1350	26.4705	0.4482
148.1533	26.2860	0.4475
148.1717	26.1015	0.4468
148.1900	25.9187	0.4461
148.2083	25.7350	0.4457
148.2267	25.5505	0.4449
148.2450	25.3670	0.4441
148.2633	25.1836	0.4435
148.2817	24.9989	0.4425
148.3000	24.8160	0.4412
148.3183	24.6314	0.4406
148.3367	24.4487	0.4397
148.3550	24.2643	0.4391
148.3733	24.0806	0.4383
148.3917	23.8962	0.4373
148.4100	23.7135	0.4369
148.4283	23.5286	0.4362
148.4467	23.3447	0.4355
148.4650	23.1613	0.4340
148.4833	22.9775	0.4334
148.5017	22.7943	0.4328
148.5200	22.6097	0.4319
148.5383	22.4254	0.4313
148.5567	22.2422	0.4305
148.5750	22.0581	0.4299
148.5933	21.8739	0.4290
148.6117	21.6919	0.4284
148.6300	21.5067	0.4279
148.6483	21.3224	0.4272
148.6667	21.1391	0.4264
148.6850	20.9559	0.4259
148.7033	20.7720	0.4251
148.7217	20.5885	0.4246
148.7400	20.4034	0.4236
148.7583	20.2211	0.4230
148.7767	20.0368	0.4226
148.7950	19.8532	0.4220
148.8133	19.6685	0.4217
148.8317	19.4854	0.4215
148.8500	19.3019	0.4206
148.8683	19.1184	0.4202
148.8867	18.9349	0.4191
148.9050	18.7498	0.4187
148.9233	18.5670	0.4182
148.9417	18.3831	0.4176
148.9600	18.1999	0.4165
148.9783	18.0161	0.4163
148.9967	17.8324	0.4160
149.0150	17.6488	0.4150
149.0333	17.4644	0.4148
149.0517	17.2820	0.4142
149.0700	17.0973	0.4136
149.0883	16.9141	0.4132
149.1067	16.7305	0.4127
149.1250	16.5479	0.4124
149.1433	16.3635	0.4121
149.1617	16.1803	0.4116
149.1800	15.9965	0.4109
149.1983	15.8125	0.4107
149.2167	15.6308	0.4100
149.2350	15.4460	0.4099
149.2533	15.2623	0.4096
149.2717	15.0781	0.4089
149.2900	14.8950	0.4086
149.3083	14.7115	0.4082
149.3267	14.5287	0.4077
149.3450	14.3449	0.4073
149.3633	14.1610	0.4071
149.3817	13.9767	0.4068
149.4000	13.7937	0.4062
149.4183	13.6083	0.4058
149.4367	13.4279	0.4055
149.4550	13.2420	0.4052
149.4733	13.0591	0.4046
149.4917	12.8757	0.4043
149.5100	12.6917	0.4040
149.5283	12.5085	0.4037
149.5467	12.3267	0.4035
149.5650	12.1411	0.4033
149.5833	11.9582	0.4030
149.6017	11.7738	0.4028
149.6200	11.5925	0.4022
149.6383	11.4081	0.4018
149.6567	11.2238	0.4016
149.6750	11.0413	0.4015
149.6933	10.8583	0.4012
149.7117	10.6754	0.4009
149.7300	10.4909	0.4006
149.7483	10.3081	0.4004
149.7667	10.1243	0.4002
149.7850	9.9414	0.4000
149.8033	9.7581	0.3995
149.8217	9.5753	0.3993
149.8400	9.3912	0.3991
149.8583	9.2072	0.3988
149.8767	9.0251	0.3985
149.8950	8.8405	0.3983
149.9133	8.6579	0.3981
149.9317	8.4724	0.3979
149.9500	8.2907	0.3977
149.9683	8.1069	0.3973
149.9867	7.9240	0.3971
150.0050	7.7406	0.3968
150.0233	7.5569	0.3967
150.0417	7.3734	0.3964
150.0600	7.1906	0.3962
150.0783	7.0067	0.3959
150.0967	6.8227	0.3957
150.1150	6.6408	0.3953
150.1333	6.4566	0.3952
150.1517	6.2735	0.3949
150.1700	6.0908	0.3947
150.1883	5.9075	0.3946
150.2067	5.7236	0.3944
150.2250	5.5418	0.3939
150.2433	5.3561	0.3936
150.2617	5.1738	0.3933
150.2800	4.9900	0.3931
150.2983	4.8078	0.3929
150.3167	4.6239	0.3927
150.3350	4.4408	0.3923
150.3533	4.2577	0.3922
150.3717	4.0730	0.3921
150.3900	3.8915	0.3918
150.4083	3.7066	0.3917
150.4267	3.5247	0.3915
150.4450	3.3401	0.3913
150.4633	3.1580	0.3912
150.4817	2.9740	0.3909
150.5000	2.7908	0.3906
150.5183	2.6086	0.3905
150.5367	2.4238	0.3903
150.5550	2.2418	0.3902
150.5733	2.0580	0.3900
150.5917	1.8746	0.3898
150.6100	1.6911	0.3896
150.6283	1.5082	0.3894
150.6467	1.3250	0.3892
150.6650	1.1420	0.3891
150.6833	0.9592	0.3888
150.7017	0.7753	0.3887
150.7200	0.5914	0.3885
150.7383	0.4088	0.3884
150.7567	0.2261	0.3882
150.7750	0.0415	0.3879
150.7933	-0.1408	0.3877
150.8117	-0.3237	0.3876
150.8300	-0.5075	0.3876
150.8483	-0.6891	0.3898
150.8667	-0.8717	0.3896
150.8850	-1.0565	0.3895
150.9033	-1.2380	0.3887
150.9217	-1.4228	0.3885
150.9400	-1.6055	0.3881
150.9583	-1.7880	0.3879
150.9767	-1.9719	0.3873
150.9950	-2.1547	0.3871
151.0133	-2.3382	0.3871
151.0317	-2.5218	0.3867
151.0500	-2.7052	0.3865
151.0683	-2.8893	0.3864
151.0867	-3.0720	0.3862
151.1050	-3.2551	0.3860
151.1233	-3.4370	0.3859
151.1417	-3.6203	0.3856
151.1600	-3.8045	0.3852
151.1783	-3.9881	0.3846
151.1967	-4.1705	0.3845
151.2150	-4.3539	0.3844
151.2333	-4.5384	0.3843
151.2517	-4.7200	0.3842
151.2700	-4.9038	0.3841
151.2883	-5.0878	0.3839
151.3067	-5.2694	0.3838
151.3250	-5.4522	0.3836
151.3433	-5.6358	0.3835
151.3617	-5.8202	0.3834
151.3800	-6.0028	0.3831
151.3983	-6.1852	0.3830
151.4167	-6.3711	0.3829
151.4350	-6.5511	0.3828
151.4533	-6.7366	0.3827
151.4717	-6.9198	0.3824
151.4900	-7.1016	0.3822
151.5083	-7.2852	0.3822
151.5267	-7.4692	0.3820
151.5450	-7.6523	0.3819
151.5633	-7.8351	0.3818
151.5817	-8.0179	0.3817
151.6000	-8.2018	0.3816
151.6183	-8.3852	0.3815
151.6367	-8.5680	0.3814
151.6550	-8.7512	0.3813
151.6733	-8.9355	0.3812
151.6917	-9.1169	0.3810
151.7100	-9.3006	0.3809
151.7283	-9.4841	0.3808
151.7467	-9.6676	0.3807
151.7650	-9.8483	0.3805
151.7833	-10.0333	0.3805
151.8017	-10.2165	0.3804
151.8200	-10.4003	0.3802
151.8383	-10.5829	0.3801
151.8567	-10.7662	0.3800
151.8750	-10.9497	0.3799
151.8933	-11.1329	0.3798
151.9117	-11.3157	0.3797
151.9300	-11.4999	0.3796
151.9483	-11.6819	0.3795
151.9667	-11.8648	0.3794
151.9850	-12.0477	0.3793
152.0033	-12.2324	0.3792
152.0217	-12.4151	0.3791
152.0400	-12.5992	0.3789
152.0583	-12.7807	0.3788
152.0767	-12.9646	0.3787
152.0950	-13.1483	0.3785
152.1133	-13.3318	0.3784
152.1317	-13.5146	0.3784
152.1500	-13.6975	0.3782
152.1683	-13.8814	0.3781
152.1867	-14.0645	0.3780
152.2050	-14.2487	0.3779
152.2233	-14.4306	0.3777
152.2417	-14.6136	0.3776
152.2600	-14.7974	0.3775
152.2783	-14.9794	0.3772
152.2967	-15.1644	0.3771
152.3150	-15.3471	0.3770
152.3333	-15.5303	0.3769
152.3517	-15.7135	0.3768
152.3700	-15.8968	0.3766
152.3883	-16.0807	0.3765
152.4067	-16.2643	0.3763
152.4250	-16.4451	0.3762
152.4433	-16.6293	0.3760
152.4617	-16.8122	0.3759
152.4800	-16.9950	0.3758
152.4983	-17.1791	0.3757
152.5167	-17.3631	0.3756
152.5350	-17.5459	0.3754
152.5533	-17.7292	0.3753
152.5717	-17.9125	0.3752
152.5900	-18.0964	0.3750
152.6083	-18.2792	0.3749
152.6267	-18.4628	0.3747
152.6450	-18.6452	0.3745
152.6633	-18.8288	0.3744
152.6817	-19.0112	0.3743
152.7000	-19.1950	0.3742
152.7183	-19.3777	0.3741
152.7367	-19.5605	0.3740
152.7550	-19.7445	0.3739
152.7733	-19.9282	0.3738
152.7917	-20.1113	0.3736
152.8100	-20.2948	0.3735
152.8283	-20.4782	0.3733
152.8467	-20.6618	0.3732
152.8650	-20.8421	0.3731
152.8833	-21.0260	0.3729
152.9017	-21.2112	0.3725
152.9200	-21.3948	0.3716
152.9383	-21.5772	0.3714
152.9567	-21.7603	0.3713
152.9750	-21.9425	0.3712
152.9933	-22.1273	0.3712
153.0117	-22.3099	0.3712
153.0300	-22.4927	0.3711
153.0483	-22.6771	0.3712
153.0667	-22.8587	0.3713
153.0850	-23.0406	0.3789
153.1033	-23.2242	0.3769
153.1217	-23.4063	0.3762
153.1400	-23.5886	0.3755
153.1583	-23.7730	0.3746
153.1767	-23.9551	0.3744
153.1950	-24.1388	0.3740
153.2133	-24.3215	0.3738
153.2317	-24.5058	0.3736
153.2500	-24.6902	0.3734
153.2683	-24.8721	0.3732
153.2867	-25.0563	0.3730
153.3050	-25.2376	0.3760
153.3233	-25.4202	0.3756
153.3417	-25.6041	0.3753
153.3600	-25.7873	0.3747
153.3783	-25.9699	0.3744
153.3967	-26.1530	0.3737
153.4150	-26.3363	0.3734
153.4333	-26.5210	0.3731
153.4517	-26.7049	0.3729
153.4700	-26.8873	0.3727
153.4883	-27.0704	0.3725
153.5067	-27.2548	0.3724
153.5250	-27.4370	0.3721
153.5433	-27.6213	0.3718
153.5617	-27.8055	0.3717
153.5800	-27.9880	0.3712
153.5983	-28.1708	0.3711
153.6167	-28.3536	0.3709
153.6350	-28.5372	0.3707
153.6533	-28.7220	0.3706
153.6717	-28.9034	0.3705
153.6900	-29.0872	0.3704
153.7083	-29.2704	0.3703
153.7267	-29.4541	0.3701
153.7450	-29.6381	0.3699
153.7633	-29.8197	0.3698
153.7817	-30.0043	0.3697
153.8000	-30.1865	0.3694
153.8183	-30.3698	0.3693
153.8367	-30.5530	0.3692
153.8550	-30.7370	0.3691
153.8733	-30.9210	0.3689
153.8917	-31.1027	0.3688
153.9100	-31.2867	0.3687
153.9283	-31.4697	0.3685
153.9467	-31.6527	0.3684
153.9650	-31.8358	0.3682
153.9833	-32.0198	0.3681
154.0017	-32.2020	0.3680
154.0200	-32.3851	0.3679
154.0383	-32.5691	0.3678
154.0567	-32.7537	0.3677
154.0750	-32.9356	0.3675
154.0933	-33.1192	0.3673
154.1117	-33.3016	0.3671
154.1300	-33.4867	0.3670
154.1483	-33.6698	0.3667
154.1667	-33.8522	0.3666
154.1850	-34.0352	0.3665
154.2033	-34.2183	0.3664
154.2217	-34.4010	0.3663
154.2400	-34.5850	0.3662
154.2583	-34.7684	0.3661
154.2767	-34.9511	0.3659
154.2950	-35.1341	0.3658
154.3133	-35.3186	0.3656
154.3317	-35.5004	0.3655
154.3500	-35.6842	0.3652
154.3683	-35.8672	0.3650
154.3867	-36.0517	0.3650
154.4050	-36.2338	0.3649
154.4233	-36.4179	0.3648
154.4417	-36.6018	0.3647
154.4600	-36.7864	0.3645
154.4783	-36.9671	0.3642
154.4967	-37.1481	0.4156
154.5150	-37.3118	0.4166
154.5333	-37.4918	0.3957
154.5517	-37.6754	0.3866
154.5700	-37.8593	0.3826
154.5883	-38.0432	0.3798
154.6067	-38.2276	0.3791
154.6250	-38.4137	0.3779
154.6433	-38.5985	0.3767
154.6617	-38.7808	0.3755
154.6800	-38.9652	0.3747
154.6983	-39.1504	0.3745
154.7167	-39.3340	0.3739
154.7350	-39.5202	0.3733
154.7533	-39.7028	0.3726
154.7717	-39.8870	0.3723
154.7900	-40.0692	0.3721
154.8083	-40.2541	0.3717
154.8267	-40.4382	0.3715
154.8450	-40.6209	0.3709
154.8633	-40.8048	0.3706
154.8817	-40.9881	0.3703
154.9000	-41.1737	0.3701
154.9183	-41.3556	0.3695
154.9367	-41.5391	0.3694
154.9550	-41.7228	0.3692
154.9733	-41.9074	0.3689
154.9917	-42.0878	0.3686
155.0100	-42.2748	0.3685
155.0283	-42.4560	0.3683
155.0467	-42.6419	0.3679
155.0650	-42.8251	0.3674
155.0833	-43.0065	0.3672
155.1017	-43.1911	0.3671
155.1200	-43.3741	0.3669
155.1383	-43.5578	0.3667
155.1567	-43.7411	0.3666
155.1750	-43.9247	0.3665
155.1933	-44.1070	0.3661
155.2117	-44.2920	0.3660
155.2300	-44.4737	0.3657
155.2483	-44.6578	0.3656
155.2667	-44.8407	0.3656
155.2850	-45.0237	0.3655
155.3033	-45.2069	0.3654
155.3217	-45.3904	0.3652
155.3400	-45.5741	0.3649
155.3583	-45.7573	0.3649
155.3767	-45.9408	0.3648
155.3950	-46.1246	0.3647
155.4133	-46.3058	0.3646
155.4317	-46.4915	0.3645
155.4500	-46.6734	0.3644
155.4683	-46.8567	0.3643
155.4867	-47.0415	0.3642
155.5050	-47.2245	0.3640
155.5233	-47.4076	0.3639
155.5417	-47.5907
155.5600	-47.7743
155.5783
155.5817