File: Example Date/My Sample/DSC/LLM_EP_01_02.txt
Filename	LLM_EP_01_02
Instrument name	DSC2A-01799 (192.168.1.250)
Operator
rundate	10/02/2025
Sample name	LLM_EP_01_02
proceduresegments	Ramp 10.00 °C/min to 25.0000 °C; Ramp 10.00 °C/min to 120.0000 °C; Isothermal 5.0 min; Ramp 10.00 °C/min to -50.0000 °C; Isothermal 5.0 min; Ramp 10.00 °C/min to 210.0000 °C; Isothermal 5.0 min; Ramp 10.00 °C/min to -50.0000 °C; Isothermal 5.0 min; Ramp 10.00 °C/min to 210.0000 °C; Isothermal 5.0 min; Ramp 10.00 °C/min to -50.0000 °C
[File Parameters]
Run Date	10/02/2025 09:20:03
Trios version	5.7.0.56
Original File Name
Current File Name	C:\Users\TA Instruments DSC\Desktop\Data\LLM\LLM_EP_01_02.tri
User at run start	DESKTOP-CFGN8IT\TA Instruments DSC
[Procedure]
Procedure Name	LLM_ChaBif
Sample Name	LLM_EP_01_02
Sample Mass	12.22 mg
Reference Sample Mass	0 mg
Pan Mass	61.72 mg
Pan Number	17
Reference Pan Mass	43.13 mg
Reference Pan Number	13
Pan Type	Tzero Aluminum Pin Hole Hermetic
Comments
Project Name
Operator
Test	Custom
Unload Max Temperature	25
Unload Min Temperature	25
FillCooler	Do not fill
Load Max Temperature	25
Load Min Temperature	25
Discard pan in waste bin at end of test	No
Stop on Gas Flow Error	No
[Signal List]
Signal #1	Time (min)
Signal #2	Temperature (°C)
Signal #3	Heat Flow (mW)
Signal #4	Delta T (µV)
Signal #5	Delta Tzero (µV)
Signal #6	Tzero Temperature (°C)
Signal #7	Cell Purge (mL/min)
Signal #8	Heater Temp (°C)
Signal #9	Power Delivered (W)
Signal #10	Reference Junction Temperature (°C)
Signal #11	Flange Temperature (°C)
Signal #12	Heat Flow Phase (rad)
Signal #13	Total Heat Capacity (J/°C)
Signal #14	Heat Capacity (J/°C)
Signal #15	LN Pump Tank level (%)
[Configuration]
Company Name	Warwick University
Instrument Name	DSC2A-01799
Instrument Type	DSC2500
Serial Number	DSC2A-01799
IP	192.168.1.250
Location of Instrument	Polymer RTP
DisplayType	TianmaV2andV3
Sample Interval 	0.1 s/pt
Selected Heat Flow	T4P
Exotherm Direction	Up
Cell Serial	DRC2-03788
Lid Type	High Temperature
Cooler	LN Pump
Leave Cooler on at End of Sequence	Off
Gas 2	Air
Gas Selected	Channel 1: Nitrogen
Flow Rate	50 mL/min
Secondary Purge	On
Licensed Heat Flow	Heat Flow T4P
Modulation Licensed	Yes
[Versions]
Common IDD Version	1
Cortex Version	VER 2.11.0.729
Driver	5.0.0.6
GDM Version	1.0.3.3
TouchscreenVersion	1.0.3.1841
FEP Version	1.2.1.21
FEP Bootloader	2.0.0.5
AutoSampler Version	2.1.2.1
Auto Sampler Bootloader	2.0.0.5
FCM Version	1.1.0.3
FCM Bootloader	2.0.0.5
LN Pump Version	10.17.0.0
LN Pump Bootloader	2.0.0.5
[Experiment Logs]
Experiment Log Entry # 1	Ramp Segment 10 C/min to 25 Started
Experiment Log Entry # 3	Air Cool is off.
Experiment Log Entry # 5	Ramp Segment 10 C/min to 120 Started
Experiment Log Entry # 7	Isothermal Segment 5 min started
Experiment Log Entry # 9	Ramp Segment 10 C/min to -50 Started
Experiment Log Entry # 11	Isothermal Segment 5 min started
Experiment Log Entry # 13	Ramp Segment 10 C/min to 210 Started
Experiment Log Entry # 15	Isothermal Segment 5 min started
Experiment Log Entry # 17	Ramp Segment 10 C/min to -50 Started
Experiment Log Entry # 19	Isothermal Segment 5 min started
Experiment Log Entry # 21	Ramp Segment 10 C/min to 210 Started
Experiment Log Entry # 23	Isothermal Segment 5 min started
Experiment Log Entry # 25	Ramp Segment 10 C/min to -50 Started
[Method Log]
Method Log Entry # 1	(Ramp 1101230) Ramp 10 °C/minute to 25 °C
Method Log Entry # 2	(Ramp 1101231) Ramp 10 °C/minute to 120 °C
Method Log Entry # 3	Isothermal 5 minutes
Method Log Entry # 4	(Ramp 1101233) Ramp 10 °C/minute to -50 °C
Method Log Entry # 5	Isothermal 5 minutes
Method Log Entry # 6	(Ramp 1101235) Ramp 10 °C/minute to 210 °C
Method Log Entry # 7	Isothermal 5 minutes
Method Log Entry # 8	(Ramp 1101237) Ramp 10 °C/minute to -50 °C
Method Log Entry # 9	Isothermal 5 minutes
Method Log Entry # 10	(Ramp 1101239) Ramp 10 °C/minute to 210 °C
Method Log Entry # 11	Isothermal 5 minutes
Method Log Entry # 12	(Ramp 1101241) Ramp 10 °C/minute to -50 °C
Cell Serial	DRC2-03788
[T1 Calibration]
Date Applied	04/03/2021 14:58:04
Slope	-0.001800291
Offset	-0.1301359
Initial Temperature	-100.6228
GUID	a1d5a6be-decd-4ae4-b22f-d560f3a78a92
[TZero Calibration]
Date Applied	03/01/2025 12:41:45
Description	From -178.795 °C to 396.200 °C at 20.000°C/min
Gas Type	Nitrogen
Pan Type	None
Source Files 1	C:\ProgramData\TA Instruments\TRIOS\Data\Tzero Cal(23).tri
Source Files 2	C:\ProgramData\TA Instruments\TRIOS\Data\Tzero Cal(24).tri
Delta T Offset	1.869383
Delta T Slope	-0.002827686
Delta T0 Offset	0.6518871
Delta T0 Slope	0.03386689
[Temperature Calibration]
Date Applied	07/01/2025 06:48:00
Description	From 106.598 °C to 186.598 °C at 10.000°C/min
Gas Type	Nitrogen
Pan Type	Aluminum Hermetic
Source Files 1	C:\ProgramData\TA Instruments\TRIOS\Data\Indium(10).tri
Measured 1	158.5387
Known 1	156.598
[Cell Constant Calibration]
Date Applied	07/01/2025 06:21:38
Description	From 106.598 °C to 186.598 °C at 10.000°C/min
Gas Type	Nitrogen
Pan Type	Aluminum Hermetic
Source Files 1	C:\ProgramData\TA Instruments\TRIOS\Data\Indium(8).tri
T4P KCell	1.071186
Onset Slope	-20.76992 mW/°C
[Direct Cp Calibration]
Date Applied	07/01/2025 08:34:40
Description	From -89.983 °C to 397.015 °C at 20.000°C/min
Gas Type	Nitrogen
Pan Type	Aluminum Hermetic
Source Files 1	C:\ProgramData\TA Instruments\TRIOS\Data\Sapphire Direct Heat Capacity(11).tri
GUID	bc2b1dd3-d0d9-41bf-ba72-b5fda717766a
Temperature	-89.98325 °C
Cp	0.9880321
Temperature	-89.00925 °C
Cp	0.9883595
Temperature	-88.03526 °C
Cp	0.9883455
Temperature	-87.06126 °C
Cp	0.9880565
Temperature	-86.08727 °C
Cp	0.9875574
Temperature	-85.11327 °C
Cp	0.9868901
Temperature	-84.13927 °C
Cp	0.9861491
Temperature	-83.16528 °C
Cp	0.9854108
Temperature	-82.19128 °C
Cp	0.9847093
Temperature	-81.21728 °C
Cp	0.984123
Temperature	-80.24328 °C
Cp	0.9836704
Temperature	-79.26929 °C
Cp	0.9834349
Temperature	-78.29529 °C
Cp	0.9833817
Temperature	-77.32129 °C
Cp	0.9835677
Temperature	-76.34729 °C
Cp	0.9839252
Temperature	-75.37329 °C
Cp	0.9844846
Temperature	-74.3993 °C
Cp	0.9852123
Temperature	-73.4253 °C
Cp	0.9860855
Temperature	-72.4513 °C
Cp	0.9870548
Temperature	-71.4773 °C
Cp	0.9881113
Temperature	-70.50331 °C
Cp	0.9892243
Temperature	-69.52931 °C
Cp	0.9903587
Temperature	-68.55531 °C
Cp	0.9915038
Temperature	-67.58131 °C
Cp	0.9926346
Temperature	-66.60732 °C
Cp	0.993748
Temperature	-65.63332 °C
Cp	0.994836
Temperature	-64.65932 °C
Cp	0.9959027
Temperature	-63.68533 °C
Cp	0.9969317
Temperature	-62.71133 °C
Cp	0.997943
Temperature	-61.73733 °C
Cp	0.9989527
Temperature	-60.76334 °C
Cp	0.9999582
Temperature	-59.78934 °C
Cp	1.000969
Temperature	-58.81534 °C
Cp	1.00194
Temperature	-57.84134 °C
Cp	1.002997
Temperature	-56.86735 °C
Cp	1.00403
Temperature	-55.89335 °C
Cp	1.005069
Temperature	-54.91935 °C
Cp	1.006104
Temperature	-53.94535 °C
Cp	1.00713
Temperature	-52.97136 °C
Cp	1.008209
Temperature	-51.99736 °C
Cp	1.009185
Temperature	-51.02336 °C
Cp	1.010177
Temperature	-50.04937 °C
Cp	1.011162
Temperature	-49.07537 °C
Cp	1.012141
Temperature	-48.10137 °C
Cp	1.01308
Temperature	-47.12737 °C
Cp	1.013991
Temperature	-46.15338 °C
Cp	1.014858
Temperature	-45.17938 °C
Cp	1.015703
Temperature	-44.20538 °C
Cp	1.016499
Temperature	-43.23138 °C
Cp	1.017257
Temperature	-42.25739 °C
Cp	1.017991
Temperature	-41.28339 °C
Cp	1.018705
Temperature	-40.30939 °C
Cp	1.019413
Temperature	-39.3354 °C
Cp	1.020126
Temperature	-38.3614 °C
Cp	1.020855
Temperature	-37.3874 °C
Cp	1.021604
Temperature	-36.4134 °C
Cp	1.022382
Temperature	-35.43941 °C
Cp	1.023185
Temperature	-34.46541 °C
Cp	1.024018
Temperature	-33.49141 °C
Cp	1.024865
Temperature	-32.51741 °C
Cp	1.025734
Temperature	-31.54342 °C
Cp	1.026615
Temperature	-30.56942 °C
Cp	1.027499
Temperature	-29.59542 °C
Cp	1.028374
Temperature	-28.62143 °C
Cp	1.029232
Temperature	-27.64743 °C
Cp	1.030081
Temperature	-26.67343 °C
Cp	1.030892
Temperature	-25.69943 °C
Cp	1.031667
Temperature	-24.72544 °C
Cp	1.032406
Temperature	-23.75144 °C
Cp	1.03311
Temperature	-22.77744 °C
Cp	1.033786
Temperature	-21.80344 °C
Cp	1.034412
Temperature	-20.82945 °C
Cp	1.035019
Temperature	-19.85545 °C
Cp	1.035599
Temperature	-18.88145 °C
Cp	1.036155
Temperature	-17.90746 °C
Cp	1.036695
Temperature	-16.93346 °C
Cp	1.037207
Temperature	-15.95946 °C
Cp	1.037712
Temperature	-14.98546 °C
Cp	1.038202
Temperature	-14.01147 °C
Cp	1.038666
Temperature	-13.03747 °C
Cp	1.039103
Temperature	-12.06347 °C
Cp	1.039518
Temperature	-11.08947 °C
Cp	1.039909
Temperature	-10.11548 °C
Cp	1.040284
Temperature	-9.14148 °C
Cp	1.040614
Temperature	-8.167483 °C
Cp	1.040915
Temperature	-7.193486 °C
Cp	1.041192
Temperature	-6.219488 °C
Cp	1.041427
Temperature	-5.245491 °C
Cp	1.041627
Temperature	-4.271494 °C
Cp	1.041773
Temperature	-3.297497 °C
Cp	1.041891
Temperature	-2.323499 °C
Cp	1.041951
Temperature	-1.349502 °C
Cp	1.041963
Temperature	-0.3755048 °C
Cp	1.041932
Temperature	0.5984925 °C
Cp	1.041862
Temperature	1.57249 °C
Cp	1.04176
Temperature	2.546487 °C
Cp	1.04162
Temperature	3.520484 °C
Cp	1.041463
Temperature	4.494482 °C
Cp	1.041297
Temperature	5.468479 °C
Cp	1.041124
Temperature	6.442476 °C
Cp	1.040949
Temperature	7.416473 °C
Cp	1.04077
Temperature	8.390471 °C
Cp	1.040596
Temperature	9.364468 °C
Cp	1.04043
Temperature	10.33846 °C
Cp	1.040276
Temperature	11.31246 °C
Cp	1.040137
Temperature	12.28646 °C
Cp	1.040014
Temperature	13.26046 °C
Cp	1.039915
Temperature	14.23445 °C
Cp	1.03984
Temperature	15.20845 °C
Cp	1.039792
Temperature	16.18245 °C
Cp	1.039777
Temperature	17.15645 °C
Cp	1.03979
Temperature	18.13044 °C
Cp	1.039834
Temperature	19.10444 °C
Cp	1.039903
Temperature	20.07844 °C
Cp	1.040019
Temperature	21.05243 °C
Cp	1.040159
Temperature	22.02643 °C
Cp	1.040318
Temperature	23.00043 °C
Cp	1.040496
Temperature	23.97443 °C
Cp	1.040695
Temperature	24.94842 °C
Cp	1.040908
Temperature	25.92242 °C
Cp	1.041143
Temperature	26.89642 °C
Cp	1.041371
Temperature	27.87042 °C
Cp	1.04161
Temperature	28.84441 °C
Cp	1.041855
Temperature	29.81841 °C
Cp	1.042094
Temperature	30.79241 °C
Cp	1.042325
Temperature	31.76641 °C
Cp	1.042534
Temperature	32.7404 °C
Cp	1.04274
Temperature	33.7144 °C
Cp	1.042917
Temperature	34.6884 °C
Cp	1.043064
Temperature	35.6624 °C
Cp	1.04319
Temperature	36.63639 °C
Cp	1.043295
Temperature	37.61039 °C
Cp	1.043386
Temperature	38.58438 °C
Cp	1.043453
Temperature	39.55838 °C
Cp	1.04351
Temperature	40.53238 °C
Cp	1.043562
Temperature	41.50638 °C
Cp	1.043611
Temperature	42.48037 °C
Cp	1.043655
Temperature	43.45437 °C
Cp	1.043698
Temperature	44.42837 °C
Cp	1.043742
Temperature	45.40237 °C
Cp	1.043786
Temperature	46.37637 °C
Cp	1.04383
Temperature	47.35036 °C
Cp	1.043871
Temperature	48.32436 °C
Cp	1.043918
Temperature	49.29836 °C
Cp	1.043969
Temperature	50.27235 °C
Cp	1.044022
Temperature	51.24635 °C
Cp	1.044086
Temperature	52.22035 °C
Cp	1.044155
Temperature	53.19434 °C
Cp	1.044236
Temperature	54.16834 °C
Cp	1.044331
Temperature	55.14234 °C
Cp	1.04443
Temperature	56.11634 °C
Cp	1.04456
Temperature	57.09034 °C
Cp	1.044703
Temperature	58.06433 °C
Cp	1.044864
Temperature	59.03833 °C
Cp	1.045041
Temperature	60.01233 °C
Cp	1.045232
Temperature	60.98632 °C
Cp	1.045442
Temperature	61.96032 °C
Cp	1.045673
Temperature	62.93432 °C
Cp	1.045911
Temperature	63.90831 °C
Cp	1.046162
Temperature	64.88231 °C
Cp	1.046425
Temperature	65.85631 °C
Cp	1.04669
Temperature	66.83031 °C
Cp	1.046952
Temperature	67.80431 °C
Cp	1.047203
Temperature	68.77831 °C
Cp	1.047453
Temperature	69.7523 °C
Cp	1.047677
Temperature	70.7263 °C
Cp	1.047882
Temperature	71.70029 °C
Cp	1.048065
Temperature	72.67429 °C
Cp	1.048226
Temperature	73.64828 °C
Cp	1.048375
Temperature	74.62228 °C
Cp	1.048498
Temperature	75.59628 °C
Cp	1.04861
Temperature	76.57028 °C
Cp	1.048713
Temperature	77.54427 °C
Cp	1.048811
Temperature	78.51827 °C
Cp	1.048901
Temperature	79.49227 °C
Cp	1.048978
Temperature	80.46627 °C
Cp	1.049068
Temperature	81.44027 °C
Cp	1.049148
Temperature	82.41426 °C
Cp	1.04922
Temperature	83.38826 °C
Cp	1.049288
Temperature	84.36226 °C
Cp	1.049353
Temperature	85.33626 °C
Cp	1.049435
Temperature	86.31025 °C
Cp	1.049486
Temperature	87.28425 °C
Cp	1.049549
Temperature	88.25825 °C
Cp	1.049615
Temperature	89.23225 °C
Cp	1.049683
Temperature	90.20624 °C
Cp	1.049742
Temperature	91.18024 °C
Cp	1.04977
Temperature	92.15424 °C
Cp	1.04982
Temperature	93.12823 °C
Cp	1.049839
Temperature	94.10223 °C
Cp	1.049829
Temperature	95.07623 °C
Cp	1.049792
Temperature	96.05022 °C
Cp	1.049731
Temperature	97.02422 °C
Cp	1.049673
Temperature	97.99822 °C
Cp	1.049564
Temperature	98.97221 °C
Cp	1.049451
Temperature	99.94621 °C
Cp	1.049339
Temperature	100.9202 °C
Cp	1.049223
Temperature	101.8942 °C
Cp	1.049111
Temperature	102.8682 °C
Cp	1.048998
Temperature	103.8422 °C
Cp	1.048886
Temperature	104.8162 °C
Cp	1.048782
Temperature	105.7902 °C
Cp	1.048679
Temperature	106.7642 °C
Cp	1.048577
Temperature	107.7382 °C
Cp	1.048481
Temperature	108.7122 °C
Cp	1.048391
Temperature	109.6862 °C
Cp	1.048309
Temperature	110.6602 °C
Cp	1.048232
Temperature	111.6342 °C
Cp	1.04816
Temperature	112.6082 °C
Cp	1.048096
Temperature	113.5822 °C
Cp	1.048038
Temperature	114.5562 °C
Cp	1.047984
Temperature	115.5302 °C
Cp	1.047932
Temperature	116.5042 °C
Cp	1.047888
Temperature	117.4782 °C
Cp	1.047844
Temperature	118.4522 °C
Cp	1.047801
Temperature	119.4262 °C
Cp	1.047756
Temperature	120.4002 °C
Cp	1.047715
Temperature	121.3742 °C
Cp	1.047678
Temperature	122.3482 °C
Cp	1.047638
Temperature	123.3222 °C
Cp	1.047605
Temperature	124.2961 °C
Cp	1.047578
Temperature	125.2701 °C
Cp	1.047555
Temperature	126.2441 °C
Cp	1.047539
Temperature	127.2181 °C
Cp	1.047525
Temperature	128.1921 °C
Cp	1.047524
Temperature	129.1661 °C
Cp	1.047527
Temperature	130.1401 °C
Cp	1.047536
Temperature	131.1141 °C
Cp	1.047554
Temperature	132.0881 °C
Cp	1.047582
Temperature	133.0621 °C
Cp	1.047624
Temperature	134.0361 °C
Cp	1.047662
Temperature	135.0101 °C
Cp	1.047714
Temperature	135.9841 °C
Cp	1.047779
Temperature	136.9581 °C
Cp	1.047853
Temperature	137.9321 °C
Cp	1.047933
Temperature	138.9061 °C
Cp	1.048018
Temperature	139.8801 °C
Cp	1.048097
Temperature	140.8541 °C
Cp	1.048188
Temperature	141.8281 °C
Cp	1.048267
Temperature	142.8021 °C
Cp	1.048337
Temperature	143.7761 °C
Cp	1.048398
Temperature	144.7501 °C
Cp	1.048449
Temperature	145.7241 °C
Cp	1.048503
Temperature	146.6981 °C
Cp	1.048532
Temperature	147.6721 °C
Cp	1.04856
Temperature	148.6461 °C
Cp	1.048587
Temperature	149.6201 °C
Cp	1.04861
Temperature	150.5941 °C
Cp	1.048628
Temperature	151.5681 °C
Cp	1.048627
Temperature	152.5421 °C
Cp	1.048642
Temperature	153.5161 °C
Cp	1.048646
Temperature	154.4901 °C
Cp	1.048642
Temperature	155.4641 °C
Cp	1.048638
Temperature	156.438 °C
Cp	1.048641
Temperature	157.412 °C
Cp	1.048673
Temperature	158.386 °C
Cp	1.048706
Temperature	159.36 °C
Cp	1.048776
Temperature	160.334 °C
Cp	1.048889
Temperature	161.308 °C
Cp	1.049047
Temperature	162.282 °C
Cp	1.049254
Temperature	163.256 °C
Cp	1.049495
Temperature	164.23 °C
Cp	1.049811
Temperature	165.204 °C
Cp	1.050172
Temperature	166.178 °C
Cp	1.050582
Temperature	167.152 °C
Cp	1.051038
Temperature	168.126 °C
Cp	1.051542
Temperature	169.1 °C
Cp	1.052114
Temperature	170.074 °C
Cp	1.052695
Temperature	171.048 °C
Cp	1.053323
Temperature	172.022 °C
Cp	1.053989
Temperature	172.996 °C
Cp	1.05468
Temperature	173.97 °C
Cp	1.055383
Temperature	174.944 °C
Cp	1.056084
Temperature	175.918 °C
Cp	1.056758
Temperature	176.892 °C
Cp	1.057421
Temperature	177.866 °C
Cp	1.058033
Temperature	178.84 °C
Cp	1.058585
Temperature	179.814 °C
Cp	1.059071
Temperature	180.788 °C
Cp	1.059486
Temperature	181.762 °C
Cp	1.059844
Temperature	182.736 °C
Cp	1.060098
Temperature	183.71 °C
Cp	1.060287
Temperature	184.684 °C
Cp	1.06041
Temperature	185.658 °C
Cp	1.060463
Temperature	186.632 °C
Cp	1.060444
Temperature	187.606 °C
Cp	1.060339
Temperature	188.58 °C
Cp	1.060207
Temperature	189.554 °C
Cp	1.060006
Temperature	190.528 °C
Cp	1.059754
Temperature	191.502 °C
Cp	1.059464
Temperature	192.476 °C
Cp	1.059152
Temperature	193.45 °C
Cp	1.05885
Temperature	194.424 °C
Cp	1.058521
Temperature	195.3979 °C
Cp	1.05822
Temperature	196.3719 °C
Cp	1.057951
Temperature	197.3459 °C
Cp	1.057719
Temperature	198.3199 °C
Cp	1.057524
Temperature	199.2939 °C
Cp	1.057347
Temperature	200.2679 °C
Cp	1.057229
Temperature	201.2419 °C
Cp	1.05713
Temperature	202.2159 °C
Cp	1.05705
Temperature	203.1899 °C
Cp	1.056984
Temperature	204.1639 °C
Cp	1.05693
Temperature	205.1379 °C
Cp	1.0569
Temperature	206.1119 °C
Cp	1.05685
Temperature	207.0859 °C
Cp	1.056808
Temperature	208.0599 °C
Cp	1.05677
Temperature	209.0339 °C
Cp	1.05673
Temperature	210.0079 °C
Cp	1.056685
Temperature	210.9819 °C
Cp	1.056633
Temperature	211.9559 °C
Cp	1.056566
Temperature	212.9299 °C
Cp	1.056501
Temperature	213.9039 °C
Cp	1.056424
Temperature	214.8779 °C
Cp	1.056341
Temperature	215.8519 °C
Cp	1.056252
Temperature	216.8259 °C
Cp	1.056168
Temperature	217.7999 °C
Cp	1.0561
Temperature	218.7739 °C
Cp	1.056026
Temperature	219.7479 °C
Cp	1.055973
Temperature	220.7219 °C
Cp	1.055941
Temperature	221.6959 °C
Cp	1.055926
Temperature	222.6699 °C
Cp	1.055924
Temperature	223.6439 °C
Cp	1.055919
Temperature	224.6179 °C
Cp	1.055941
Temperature	225.5919 °C
Cp	1.055954
Temperature	226.5659 °C
Cp	1.055958
Temperature	227.5399 °C
Cp	1.055954
Temperature	228.5139 °C
Cp	1.055943
Temperature	229.4879 °C
Cp	1.055938
Temperature	230.4619 °C
Cp	1.055901
Temperature	231.4359 °C
Cp	1.055866
Temperature	232.4098 °C
Cp	1.055832
Temperature	233.3838 °C
Cp	1.055797
Temperature	234.3578 °C
Cp	1.055757
Temperature	235.3318 °C
Cp	1.055695
Temperature	236.3058 °C
Cp	1.055658
Temperature	237.2798 °C
Cp	1.055607
Temperature	238.2538 °C
Cp	1.055547
Temperature	239.2278 °C
Cp	1.055481
Temperature	240.2018 °C
Cp	1.055414
Temperature	241.1758 °C
Cp	1.055372
Temperature	242.1498 °C
Cp	1.055303
Temperature	243.1238 °C
Cp	1.055254
Temperature	244.0978 °C
Cp	1.055227
Temperature	245.0718 °C
Cp	1.055215
Temperature	246.0458 °C
Cp	1.055219
Temperature	247.0198 °C
Cp	1.055213
Temperature	247.9938 °C
Cp	1.055252
Temperature	248.9678 °C
Cp	1.055289
Temperature	249.9418 °C
Cp	1.055323
Temperature	250.9158 °C
Cp	1.055358
Temperature	251.8898 °C
Cp	1.055391
Temperature	252.8638 °C
Cp	1.055427
Temperature	253.8378 °C
Cp	1.05547
Temperature	254.8118 °C
Cp	1.055506
Temperature	255.7858 °C
Cp	1.055552
Temperature	256.7598 °C
Cp	1.055605
Temperature	257.7338 °C
Cp	1.055662
Temperature	258.7078 °C
Cp	1.055723
Temperature	259.6818 °C
Cp	1.055782
Temperature	260.6558 °C
Cp	1.055847
Temperature	261.6298 °C
Cp	1.055909
Temperature	262.6038 °C
Cp	1.055965
Temperature	263.5778 °C
Cp	1.05602
Temperature	264.5518 °C
Cp	1.056073
Temperature	265.5258 °C
Cp	1.056125
Temperature	266.4998 °C
Cp	1.056176
Temperature	267.4738 °C
Cp	1.05623
Temperature	268.4478 °C
Cp	1.056288
Temperature	269.4218 °C
Cp	1.056349
Temperature	270.3957 °C
Cp	1.056416
Temperature	271.3697 °C
Cp	1.056491
Temperature	272.3437 °C
Cp	1.056571
Temperature	273.3177 °C
Cp	1.056658
Temperature	274.2917 °C
Cp	1.05675
Temperature	275.2657 °C
Cp	1.056848
Temperature	276.2397 °C
Cp	1.056947
Temperature	277.2137 °C
Cp	1.057042
Temperature	278.1877 °C
Cp	1.057142
Temperature	279.1617 °C
Cp	1.057233
Temperature	280.1357 °C
Cp	1.057313
Temperature	281.1097 °C
Cp	1.057381
Temperature	282.0837 °C
Cp	1.057435
Temperature	283.0577 °C
Cp	1.057481
Temperature	284.0317 °C
Cp	1.057495
Temperature	285.0057 °C
Cp	1.057498
Temperature	285.9797 °C
Cp	1.057486
Temperature	286.9537 °C
Cp	1.057462
Temperature	287.9277 °C
Cp	1.057423
Temperature	288.9017 °C
Cp	1.057373
Temperature	289.8757 °C
Cp	1.05731
Temperature	290.8497 °C
Cp	1.057244
Temperature	291.8237 °C
Cp	1.057169
Temperature	292.7977 °C
Cp	1.057092
Temperature	293.7717 °C
Cp	1.057015
Temperature	294.7457 °C
Cp	1.05694
Temperature	295.7197 °C
Cp	1.056872
Temperature	296.6937 °C
Cp	1.056808
Temperature	297.6677 °C
Cp	1.056752
Temperature	298.6417 °C
Cp	1.056704
Temperature	299.6157 °C
Cp	1.056662
Temperature	300.5897 °C
Cp	1.056626
Temperature	301.5637 °C
Cp	1.05659
Temperature	302.5377 °C
Cp	1.056563
Temperature	303.5117 °C
Cp	1.056535
Temperature	304.4856 °C
Cp	1.056507
Temperature	305.4596 °C
Cp	1.05648
Temperature	306.4336 °C
Cp	1.056456
Temperature	307.4076 °C
Cp	1.056444
Temperature	308.3816 °C
Cp	1.056429
Temperature	309.3556 °C
Cp	1.056431
Temperature	310.3296 °C
Cp	1.056452
Temperature	311.3036 °C
Cp	1.056492
Temperature	312.2776 °C
Cp	1.056555
Temperature	313.2516 °C
Cp	1.056631
Temperature	314.2256 °C
Cp	1.056748
Temperature	315.1996 °C
Cp	1.056883
Temperature	316.1736 °C
Cp	1.057038
Temperature	317.1476 °C
Cp	1.057212
Temperature	318.1216 °C
Cp	1.057405
Temperature	319.0956 °C
Cp	1.057631
Temperature	320.0696 °C
Cp	1.057845
Temperature	321.0436 °C
Cp	1.058079
Temperature	322.0176 °C
Cp	1.058326
Temperature	322.9916 °C
Cp	1.058582
Temperature	323.9656 °C
Cp	1.058841
Temperature	324.9396 °C
Cp	1.059099
Temperature	325.9136 °C
Cp	1.059348
Temperature	326.8876 °C
Cp	1.059604
Temperature	327.8616 °C
Cp	1.05985
Temperature	328.8356 °C
Cp	1.060092
Temperature	329.8096 °C
Cp	1.060333
Temperature	330.7836 °C
Cp	1.060579
Temperature	331.7576 °C
Cp	1.060841
Temperature	332.7316 °C
Cp	1.061109
Temperature	333.7056 °C
Cp	1.061398
Temperature	334.6796 °C
Cp	1.061709
Temperature	335.6536 °C
Cp	1.062038
Temperature	336.6276 °C
Cp	1.062384
Temperature	337.6016 °C
Cp	1.062742
Temperature	338.5755 °C
Cp	1.063104
Temperature	339.5495 °C
Cp	1.063464
Temperature	340.5235 °C
Cp	1.063814
Temperature	341.4975 °C
Cp	1.064146
Temperature	342.4715 °C
Cp	1.064453
Temperature	343.4455 °C
Cp	1.064728
Temperature	344.4195 °C
Cp	1.06497
Temperature	345.3935 °C
Cp	1.065176
Temperature	346.3675 °C
Cp	1.065346
Temperature	347.3415 °C
Cp	1.065484
Temperature	348.3155 °C
Cp	1.065596
Temperature	349.2895 °C
Cp	1.065687
Temperature	350.2635 °C
Cp	1.065775
Temperature	351.2375 °C
Cp	1.065862
Temperature	352.2115 °C
Cp	1.06596
Temperature	353.1855 °C
Cp	1.066075
Temperature	354.1595 °C
Cp	1.066217
Temperature	355.1335 °C
Cp	1.066395
Temperature	356.1075 °C
Cp	1.06659
Temperature	357.0815 °C
Cp	1.066817
Temperature	358.0555 °C
Cp	1.067067
Temperature	359.0295 °C
Cp	1.067329
Temperature	360.0035 °C
Cp	1.067591
Temperature	360.9775 °C
Cp	1.067838
Temperature	361.9515 °C
Cp	1.068055
Temperature	362.9255 °C
Cp	1.068232
Temperature	363.8995 °C
Cp	1.068357
Temperature	364.8735 °C
Cp	1.068423
Temperature	365.8475 °C
Cp	1.068431
Temperature	366.8215 °C
Cp	1.068385
Temperature	367.7955 °C
Cp	1.068293
Temperature	368.7695 °C
Cp	1.068177
Temperature	369.7435 °C
Cp	1.068051
Temperature	370.7175 °C
Cp	1.067937
Temperature	371.6914 °C
Cp	1.067864
Temperature	372.6654 °C
Cp	1.067851
Temperature	373.6394 °C
Cp	1.067924
Temperature	374.6134 °C
Cp	1.068083
Temperature	375.5874 °C
Cp	1.068344
Temperature	376.5614 °C
Cp	1.068699
Temperature	377.5354 °C
Cp	1.069131
Temperature	378.5094 °C
Cp	1.069605
Temperature	379.4834 °C
Cp	1.070071
Temperature	380.4574 °C
Cp	1.070487
Temperature	381.4314 °C
Cp	1.07077
Temperature	382.4054 °C
Cp	1.070846
Temperature	383.3794 °C
Cp	1.070635
Temperature	384.3534 °C
Cp	1.070055
Temperature	385.3274 °C
Cp	1.069033
Temperature	386.3014 °C
Cp	1.067489
Temperature	387.2754 °C
Cp	1.065378
Temperature	388.2494 °C
Cp	1.062665
Temperature	389.2234 °C
Cp	1.059324
Temperature	390.1974 °C
Cp	1.055366
Temperature	391.1714 °C
Cp	1.050821
Temperature	392.1454 °C
Cp	1.045742
Temperature	393.1194 °C
Cp	1.040203
Temperature	394.0934 °C
Cp	1.034295
Temperature	395.0674 °C
Cp	1.028124
Temperature	396.0414 °C
Cp	1.021801
[Rev Cp Calibration]
Date Applied	07/01/2025 13:18:35
Description	From -90.000 °C to 391.202 °C at 2.000°C/min
Gas Type	Nitrogen
Pan Type	Aluminum Hermetic
Source Files 1	C:\ProgramData\TA Instruments\TRIOS\Data\Reverse Heat Capacity Calibration(8).tri
GUID	2f9866b8-ce4e-42f5-95a1-c21443fc3171
Temperature	-89.99985 °C
Cp	1.026385
Temperature	-89.03745 °C
Cp	1.030641
Temperature	-88.07504 °C
Cp	1.034621
Temperature	-87.11264 °C
Cp	1.038235
Temperature	-86.15024 °C
Cp	1.041454
Temperature	-85.18784 °C
Cp	1.044296
Temperature	-84.22543 °C
Cp	1.04679
Temperature	-83.26302 °C
Cp	1.048951
Temperature	-82.30062 °C
Cp	1.050818
Temperature	-81.33822 °C
Cp	1.052404
Temperature	-80.37582 °C
Cp	1.053789
Temperature	-79.41341 °C
Cp	1.055011
Temperature	-78.45101 °C
Cp	1.056107
Temperature	-77.48861 °C
Cp	1.05712
Temperature	-76.52621 °C
Cp	1.058067
Temperature	-75.5638 °C
Cp	1.059033
Temperature	-74.6014 °C
Cp	1.060008
Temperature	-73.639 °C
Cp	1.06102
Temperature	-72.67659 °C
Cp	1.062091
Temperature	-71.71419 °C
Cp	1.06324
Temperature	-70.75179 °C
Cp	1.064487
Temperature	-69.78938 °C
Cp	1.065824
Temperature	-68.82698 °C
Cp	1.067263
Temperature	-67.86458 °C
Cp	1.068802
Temperature	-66.90218 °C
Cp	1.070434
Temperature	-65.93977 °C
Cp	1.07215
Temperature	-64.97737 °C
Cp	1.073961
Temperature	-64.01497 °C
Cp	1.07579
Temperature	-63.05256 °C
Cp	1.077675
Temperature	-62.09016 °C
Cp	1.0796
Temperature	-61.12776 °C
Cp	1.081549
Temperature	-60.16536 °C
Cp	1.083507
Temperature	-59.20295 °C
Cp	1.085459
Temperature	-58.24055 °C
Cp	1.087374
Temperature	-57.27814 °C
Cp	1.089301
Temperature	-56.31574 °C
Cp	1.091179
Temperature	-55.35334 °C
Cp	1.09301
Temperature	-54.39093 °C
Cp	1.094799
Temperature	-53.42853 °C
Cp	1.09655
Temperature	-52.46613 °C
Cp	1.098302
Temperature	-51.50373 °C
Cp	1.099969
Temperature	-50.54132 °C
Cp	1.101634
Temperature	-49.57892 °C
Cp	1.103291
Temperature	-48.61652 °C
Cp	1.104934
Temperature	-47.65411 °C
Cp	1.106558
Temperature	-46.69171 °C
Cp	1.108129
Temperature	-45.72931 °C
Cp	1.109722
Temperature	-44.76691 °C
Cp	1.111267
Temperature	-43.8045 °C
Cp	1.112769
Temperature	-42.8421 °C
Cp	1.11423
Temperature	-41.8797 °C
Cp	1.115656
Temperature	-40.91729 °C
Cp	1.117056
Temperature	-39.95489 °C
Cp	1.118417
Temperature	-38.99249 °C
Cp	1.119757
Temperature	-38.03008 °C
Cp	1.121077
Temperature	-37.06768 °C
Cp	1.12238
Temperature	-36.10528 °C
Cp	1.123667
Temperature	-35.14288 °C
Cp	1.124939
Temperature	-34.18047 °C
Cp	1.126202
Temperature	-33.21807 °C
Cp	1.127441
Temperature	-32.25566 °C
Cp	1.128669
Temperature	-31.29326 °C
Cp	1.129881
Temperature	-30.33086 °C
Cp	1.131073
Temperature	-29.36846 °C
Cp	1.13224
Temperature	-28.40605 °C
Cp	1.133372
Temperature	-27.44365 °C
Cp	1.134479
Temperature	-26.48125 °C
Cp	1.135545
Temperature	-25.51884 °C
Cp	1.136566
Temperature	-24.55644 °C
Cp	1.13754
Temperature	-23.59404 °C
Cp	1.138466
Temperature	-22.63164 °C
Cp	1.139347
Temperature	-21.66923 °C
Cp	1.140172
Temperature	-20.70683 °C
Cp	1.140951
Temperature	-19.74443 °C
Cp	1.141683
Temperature	-18.78202 °C
Cp	1.14237
Temperature	-17.81962 °C
Cp	1.143013
Temperature	-16.85722 °C
Cp	1.143601
Temperature	-15.89482 °C
Cp	1.14417
Temperature	-14.93241 °C
Cp	1.144696
Temperature	-13.97001 °C
Cp	1.145184
Temperature	-13.00761 °C
Cp	1.145641
Temperature	-12.0452 °C
Cp	1.14607
Temperature	-11.0828 °C
Cp	1.146477
Temperature	-10.1204 °C
Cp	1.146876
Temperature	-9.157994 °C
Cp	1.147244
Temperature	-8.195591 °C
Cp	1.147609
Temperature	-7.233188 °C
Cp	1.147968
Temperature	-6.270785 °C
Cp	1.148321
Temperature	-5.308382 °C
Cp	1.148663
Temperature	-4.345979 °C
Cp	1.148978
Temperature	-3.383576 °C
Cp	1.149303
Temperature	-2.421173 °C
Cp	1.1496
Temperature	-1.45877 °C
Cp	1.149872
Temperature	-0.496367 °C
Cp	1.150121
Temperature	0.466036 °C
Cp	1.15035
Temperature	1.428439 °C
Cp	1.150573
Temperature	2.390842 °C
Cp	1.150761
Temperature	3.353245 °C
Cp	1.150942
Temperature	4.315648 °C
Cp	1.151115
Temperature	5.278051 °C
Cp	1.151279
Temperature	6.240454 °C
Cp	1.151435
Temperature	7.202857 °C
Cp	1.151582
Temperature	8.16526 °C
Cp	1.151718
Temperature	9.127664 °C
Cp	1.151844
Temperature	10.09007 °C
Cp	1.151962
Temperature	11.05247 °C
Cp	1.152071
Temperature	12.01487 °C
Cp	1.152174
Temperature	12.97727 °C
Cp	1.15227
Temperature	13.93968 °C
Cp	1.152361
Temperature	14.90208 °C
Cp	1.15245
Temperature	15.86448 °C
Cp	1.152536
Temperature	16.82689 °C
Cp	1.152622
Temperature	17.78929 °C
Cp	1.152709
Temperature	18.75169 °C
Cp	1.152799
Temperature	19.7141 °C
Cp	1.152883
Temperature	20.6765 °C
Cp	1.152982
Temperature	21.6389 °C
Cp	1.15308
Temperature	22.60131 °C
Cp	1.153177
Temperature	23.56371 °C
Cp	1.153276
Temperature	24.52611 °C
Cp	1.153377
Temperature	25.48851 °C
Cp	1.153497
Temperature	26.45092 °C
Cp	1.153591
Temperature	27.41332 °C
Cp	1.153695
Temperature	28.37572 °C
Cp	1.153804
Temperature	29.33813 °C
Cp	1.153913
Temperature	30.30053 °C
Cp	1.154015
Temperature	31.26293 °C
Cp	1.154087
Temperature	32.22533 °C
Cp	1.154174
Temperature	33.18774 °C
Cp	1.154232
Temperature	34.15014 °C
Cp	1.154263
Temperature	35.11255 °C
Cp	1.154269
Temperature	36.07495 °C
Cp	1.154254
Temperature	37.03735 °C
Cp	1.154231
Temperature	37.99975 °C
Cp	1.154176
Temperature	38.96216 °C
Cp	1.154116
Temperature	39.92456 °C
Cp	1.154055
Temperature	40.88696 °C
Cp	1.153996
Temperature	41.84937 °C
Cp	1.153939
Temperature	42.81177 °C
Cp	1.153889
Temperature	43.77417 °C
Cp	1.153844
Temperature	44.73658 °C
Cp	1.153811
Temperature	45.69898 °C
Cp	1.153786
Temperature	46.66138 °C
Cp	1.153769
Temperature	47.62378 °C
Cp	1.153761
Temperature	48.58619 °C
Cp	1.153762
Temperature	49.54859 °C
Cp	1.153771
Temperature	50.51099 °C
Cp	1.153783
Temperature	51.4734 °C
Cp	1.1538
Temperature	52.4358 °C
Cp	1.153821
Temperature	53.3982 °C
Cp	1.153843
Temperature	54.3606 °C
Cp	1.153865
Temperature	55.32301 °C
Cp	1.153879
Temperature	56.28541 °C
Cp	1.153902
Temperature	57.24781 °C
Cp	1.15392
Temperature	58.21022 °C
Cp	1.153935
Temperature	59.17262 °C
Cp	1.15395
Temperature	60.13502 °C
Cp	1.153968
Temperature	61.09743 °C
Cp	1.154004
Temperature	62.05983 °C
Cp	1.154027
Temperature	63.02223 °C
Cp	1.154066
Temperature	63.98463 °C
Cp	1.154123
Temperature	64.94704 °C
Cp	1.154196
Temperature	65.90944 °C
Cp	1.154283
Temperature	66.87184 °C
Cp	1.154383
Temperature	67.83424 °C
Cp	1.154487
Temperature	68.79665 °C
Cp	1.15461
Temperature	69.75906 °C
Cp	1.154733
Temperature	70.72146 °C
Cp	1.154854
Temperature	71.68386 °C
Cp	1.154973
Temperature	72.64626 °C
Cp	1.155089
Temperature	73.60867 °C
Cp	1.15521
Temperature	74.57107 °C
Cp	1.15531
Temperature	75.53347 °C
Cp	1.155409
Temperature	76.49587 °C
Cp	1.155506
Temperature	77.45827 °C
Cp	1.155596
Temperature	78.42068 °C
Cp	1.155678
Temperature	79.38308 °C
Cp	1.155733
Temperature	80.34549 °C
Cp	1.155807
Temperature	81.30789 °C
Cp	1.155861
Temperature	82.27029 °C
Cp	1.155901
Temperature	83.2327 °C
Cp	1.155933
Temperature	84.1951 °C
Cp	1.155961
Temperature	85.1575 °C
Cp	1.156017
Temperature	86.1199 °C
Cp	1.156039
Temperature	87.08231 °C
Cp	1.156086
Temperature	88.04471 °C
Cp	1.156157
Temperature	89.00711 °C
Cp	1.156251
Temperature	89.96951 °C
Cp	1.156367
Temperature	90.93192 °C
Cp	1.156501
Temperature	91.89433 °C
Cp	1.156642
Temperature	92.85673 °C
Cp	1.156814
Temperature	93.81913 °C
Cp	1.156988
Temperature	94.78153 °C
Cp	1.157165
Temperature	95.74393 °C
Cp	1.157348
Temperature	96.70634 °C
Cp	1.157536
Temperature	97.66874 °C
Cp	1.15774
Temperature	98.63114 °C
Cp	1.157933
Temperature	99.59354 °C
Cp	1.158139
Temperature	100.5559 °C
Cp	1.158354
Temperature	101.5184 °C
Cp	1.158574
Temperature	102.4808 °C
Cp	1.158796
Temperature	103.4432 °C
Cp	1.15901
Temperature	104.4056 °C
Cp	1.159229
Temperature	105.368 °C
Cp	1.159435
Temperature	106.3304 °C
Cp	1.159626
Temperature	107.2928 °C
Cp	1.159803
Temperature	108.2552 °C
Cp	1.159964
Temperature	109.2176 °C
Cp	1.160111
Temperature	110.18 °C
Cp	1.160234
Temperature	111.1424 °C
Cp	1.160342
Temperature	112.1048 °C
Cp	1.160432
Temperature	113.0672 °C
Cp	1.160504
Temperature	114.0296 °C
Cp	1.160558
Temperature	114.992 °C
Cp	1.160594
Temperature	115.9544 °C
Cp	1.16061
Temperature	116.9168 °C
Cp	1.160614
Temperature	117.8792 °C
Cp	1.160601
Temperature	118.8416 °C
Cp	1.160574
Temperature	119.804 °C
Cp	1.160534
Temperature	120.7664 °C
Cp	1.160485
Temperature	121.7288 °C
Cp	1.160433
Temperature	122.6912 °C
Cp	1.160372
Temperature	123.6536 °C
Cp	1.160313
Temperature	124.616 °C
Cp	1.160255
Temperature	125.5784 °C
Cp	1.160201
Temperature	126.5408 °C
Cp	1.16015
Temperature	127.5032 °C
Cp	1.160101
Temperature	128.4656 °C
Cp	1.160059
Temperature	129.428 °C
Cp	1.16002
Temperature	130.3904 °C
Cp	1.159983
Temperature	131.3528 °C
Cp	1.159948
Temperature	132.3152 °C
Cp	1.159916
Temperature	133.2776 °C
Cp	1.159893
Temperature	134.2401 °C
Cp	1.15986
Temperature	135.2025 °C
Cp	1.159833
Temperature	136.1649 °C
Cp	1.15981
Temperature	137.1273 °C
Cp	1.159789
Temperature	138.0897 °C
Cp	1.159769
Temperature	139.0521 °C
Cp	1.15973
Temperature	140.0145 °C
Cp	1.159723
Temperature	140.9769 °C
Cp	1.159706
Temperature	141.9393 °C
Cp	1.159682
Temperature	142.9017 °C
Cp	1.159653
Temperature	143.8641 °C
Cp	1.159625
Temperature	144.8265 °C
Cp	1.159599
Temperature	145.7889 °C
Cp	1.15959
Temperature	146.7513 °C
Cp	1.15957
Temperature	147.7137 °C
Cp	1.159569
Temperature	148.6761 °C
Cp	1.159584
Temperature	149.6385 °C
Cp	1.159613
Temperature	150.6009 °C
Cp	1.159654
Temperature	151.5633 °C
Cp	1.15969
Temperature	152.5257 °C
Cp	1.159761
Temperature	153.4881 °C
Cp	1.159829
Temperature	154.4505 °C
Cp	1.159901
Temperature	155.4129 °C
Cp	1.159981
Temperature	156.3753 °C
Cp	1.160076
Temperature	157.3377 °C
Cp	1.160207
Temperature	158.3001 °C
Cp	1.160336
Temperature	159.2625 °C
Cp	1.160508
Temperature	160.2249 °C
Cp	1.160724
Temperature	161.1873 °C
Cp	1.160986
Temperature	162.1497 °C
Cp	1.161296
Temperature	163.1122 °C
Cp	1.161639
Temperature	164.0746 °C
Cp	1.162062
Temperature	165.037 °C
Cp	1.162527
Temperature	165.9994 °C
Cp	1.163037
Temperature	166.9618 °C
Cp	1.163591
Temperature	167.9242 °C
Cp	1.164188
Temperature	168.8866 °C
Cp	1.164826
Temperature	169.849 °C
Cp	1.165508
Temperature	170.8114 °C
Cp	1.166203
Temperature	171.7738 °C
Cp	1.166927
Temperature	172.7362 °C
Cp	1.167664
Temperature	173.6986 °C
Cp	1.168401
Temperature	174.661 °C
Cp	1.169124
Temperature	175.6234 °C
Cp	1.169799
Temperature	176.5858 °C
Cp	1.170462
Temperature	177.5482 °C
Cp	1.171058
Temperature	178.5106 °C
Cp	1.171581
Temperature	179.473 °C
Cp	1.172029
Temperature	180.4354 °C
Cp	1.1724
Temperature	181.3978 °C
Cp	1.172722
Temperature	182.3602 °C
Cp	1.172924
Temperature	183.3226 °C
Cp	1.173072
Temperature	184.285 °C
Cp	1.173165
Temperature	185.2474 °C
Cp	1.173204
Temperature	186.2098 °C
Cp	1.173191
Temperature	187.1722 °C
Cp	1.173098
Temperature	188.1346 °C
Cp	1.173022
Temperature	189.097 °C
Cp	1.172893
Temperature	190.0594 °C
Cp	1.172727
Temperature	191.0218 °C
Cp	1.172536
Temperature	191.9842 °C
Cp	1.172333
Temperature	192.9466 °C
Cp	1.172129
Temperature	193.909 °C
Cp	1.171948
Temperature	194.8714 °C
Cp	1.171764
Temperature	195.8338 °C
Cp	1.171616
Temperature	196.7962 °C
Cp	1.171503
Temperature	197.7587 °C
Cp	1.171422
Temperature	198.7211 °C
Cp	1.171373
Temperature	199.6835 °C
Cp	1.171339
Temperature	200.6459 °C
Cp	1.171347
Temperature	201.6083 °C
Cp	1.171366
Temperature	202.5707 °C
Cp	1.171394
Temperature	203.5331 °C
Cp	1.171431
Temperature	204.4955 °C
Cp	1.171476
Temperature	205.4579 °C
Cp	1.17154
Temperature	206.4203 °C
Cp	1.171593
Temperature	207.3827 °C
Cp	1.171659
Temperature	208.3451 °C
Cp	1.171737
Temperature	209.3075 °C
Cp	1.171824
Temperature	210.2699 °C
Cp	1.171918
Temperature	211.2323 °C
Cp	1.172
Temperature	212.1947 °C
Cp	1.172116
Temperature	213.1571 °C
Cp	1.172226
Temperature	214.1195 °C
Cp	1.172333
Temperature	215.0819 °C
Cp	1.172439
Temperature	216.0443 °C
Cp	1.172549
Temperature	217.0067 °C
Cp	1.172689
Temperature	217.9691 °C
Cp	1.172792
Temperature	218.9315 °C
Cp	1.172914
Temperature	219.8939 °C
Cp	1.173052
Temperature	220.8563 °C
Cp	1.173203
Temperature	221.8187 °C
Cp	1.173361
Temperature	222.7811 °C
Cp	1.173523
Temperature	223.7435 °C
Cp	1.173674
Temperature	224.7059 °C
Cp	1.173842
Temperature	225.6683 °C
Cp	1.173995
Temperature	226.6307 °C
Cp	1.174137
Temperature	227.5932 °C
Cp	1.174268
Temperature	228.5556 °C
Cp	1.174393
Temperature	229.518 °C
Cp	1.174531
Temperature	230.4804 °C
Cp	1.174642
Temperature	231.4428 °C
Cp	1.174766
Temperature	232.4052 °C
Cp	1.174902
Temperature	233.3676 °C
Cp	1.175049
Temperature	234.33 °C
Cp	1.175206
Temperature	235.2924 °C
Cp	1.175351
Temperature	236.2548 °C
Cp	1.175539
Temperature	237.2172 °C
Cp	1.175721
Temperature	238.1796 °C
Cp	1.175902
Temperature	239.142 °C
Cp	1.176085
Temperature	240.1044 °C
Cp	1.176272
Temperature	241.0668 °C
Cp	1.176491
Temperature	242.0292 °C
Cp	1.176676
Temperature	242.9916 °C
Cp	1.176882
Temperature	243.954 °C
Cp	1.177106
Temperature	244.9164 °C
Cp	1.177343
Temperature	245.8788 °C
Cp	1.177589
Temperature	246.8412 °C
Cp	1.17784
Temperature	247.8036 °C
Cp	1.17808
Temperature	248.766 °C
Cp	1.178334
Temperature	249.7284 °C
Cp	1.178575
Temperature	250.6908 °C
Cp	1.178803
Temperature	251.6532 °C
Cp	1.17902
Temperature	252.6156 °C
Cp	1.179227
Temperature	253.578 °C
Cp	1.179435
Temperature	254.5404 °C
Cp	1.17962
Temperature	255.5028 °C
Cp	1.179806
Temperature	256.4652 °C
Cp	1.179992
Temperature	257.4276 °C
Cp	1.180176
Temperature	258.39 °C
Cp	1.180356
Temperature	259.3524 °C
Cp	1.180525
Temperature	260.3148 °C
Cp	1.180699
Temperature	261.2773 °C
Cp	1.18086
Temperature	262.2397 °C
Cp	1.181011
Temperature	263.2021 °C
Cp	1.18115
Temperature	264.1645 °C
Cp	1.181279
Temperature	265.1269 °C
Cp	1.181398
Temperature	266.0893 °C
Cp	1.181504
Temperature	267.0517 °C
Cp	1.1816
Temperature	268.0141 °C
Cp	1.181687
Temperature	268.9765 °C
Cp	1.181765
Temperature	269.9389 °C
Cp	1.181835
Temperature	270.9013 °C
Cp	1.181897
Temperature	271.8637 °C
Cp	1.181952
Temperature	272.8261 °C
Cp	1.182001
Temperature	273.7885 °C
Cp	1.182045
Temperature	274.7509 °C
Cp	1.182086
Temperature	275.7133 °C
Cp	1.182126
Temperature	276.6757 °C
Cp	1.182166
Temperature	277.6381 °C
Cp	1.182204
Temperature	278.6005 °C
Cp	1.182251
Temperature	279.5629 °C
Cp	1.182299
Temperature	280.5253 °C
Cp	1.182353
Temperature	281.4877 °C
Cp	1.182414
Temperature	282.4501 °C
Cp	1.182486
Temperature	283.4125 °C
Cp	1.182577
Temperature	284.3749 °C
Cp	1.182671
Temperature	285.3373 °C
Cp	1.182786
Temperature	286.2997 °C
Cp	1.182921
Temperature	287.2621 °C
Cp	1.183076
Temperature	288.2245 °C
Cp	1.183251
Temperature	289.187 °C
Cp	1.183439
Temperature	290.1494 °C
Cp	1.183654
Temperature	291.1118 °C
Cp	1.183883
Temperature	292.0742 °C
Cp	1.184126
Temperature	293.0366 °C
Cp	1.184383
Temperature	293.999 °C
Cp	1.184651
Temperature	294.9614 °C
Cp	1.184932
Temperature	295.9238 °C
Cp	1.185223
Temperature	296.8862 °C
Cp	1.185522
Temperature	297.8486 °C
Cp	1.185828
Temperature	298.811 °C
Cp	1.18614
Temperature	299.7734 °C
Cp	1.186456
Temperature	300.7358 °C
Cp	1.186773
Temperature	301.6982 °C
Cp	1.187085
Temperature	302.6606 °C
Cp	1.1874
Temperature	303.623 °C
Cp	1.187709
Temperature	304.5854 °C
Cp	1.188011
Temperature	305.5478 °C
Cp	1.188307
Temperature	306.5102 °C
Cp	1.188598
Temperature	307.4726 °C
Cp	1.188893
Temperature	308.435 °C
Cp	1.189173
Temperature	309.3974 °C
Cp	1.189456
Temperature	310.3598 °C
Cp	1.189744
Temperature	311.3222 °C
Cp	1.190034
Temperature	312.2846 °C
Cp	1.190329
Temperature	313.247 °C
Cp	1.190615
Temperature	314.2094 °C
Cp	1.190925
Temperature	315.1718 °C
Cp	1.191232
Temperature	316.1342 °C
Cp	1.191539
Temperature	317.0966 °C
Cp	1.191848
Temperature	318.059 °C
Cp	1.19216
Temperature	319.0214 °C
Cp	1.192496
Temperature	319.9838 °C
Cp	1.192805
Temperature	320.9462 °C
Cp	1.193128
Temperature	321.9086 °C
Cp	1.193462
Temperature	322.871 °C
Cp	1.193803
Temperature	323.8334 °C
Cp	1.194149
Temperature	324.7958 °C
Cp	1.194495
Temperature	325.7583 °C
Cp	1.194832
Temperature	326.7207 °C
Cp	1.195181
Temperature	327.6831 °C
Cp	1.19552
Temperature	328.6455 °C
Cp	1.195853
Temperature	329.6079 °C
Cp	1.196183
Temperature	330.5703 °C
Cp	1.196515
Temperature	331.5327 °C
Cp	1.196862
Temperature	332.4951 °C
Cp	1.197211
Temperature	333.4575 °C
Cp	1.197584
Temperature	334.4199 °C
Cp	1.197985
Temperature	335.3823 °C
Cp	1.198418
Temperature	336.3447 °C
Cp	1.198886
Temperature	337.3071 °C
Cp	1.199394
Temperature	338.2695 °C
Cp	1.199941
Temperature	339.2319 °C
Cp	1.20053
Temperature	340.1943 °C
Cp	1.20116
Temperature	341.1567 °C
Cp	1.201831
Temperature	342.1191 °C
Cp	1.202538
Temperature	343.0815 °C
Cp	1.203274
Temperature	344.0439 °C
Cp	1.20404
Temperature	345.0063 °C
Cp	1.204822
Temperature	345.9687 °C
Cp	1.205612
[...]
140.4000	103.3490	0.4579
140.4183	103.1655	0.4579
140.4367	102.9836	0.4579
140.4550	102.7996	0.4579
140.4733	102.6169	0.4579
140.4917	102.4328	0.4578
140.5100	102.2504	0.4578
140.5283	102.0660	0.4578
140.5467	101.8830	0.4579
140.5650	101.6997	0.4578
140.5833	101.5172	0.4578
140.6017	101.3347	0.4578
140.6200	101.1513	0.4578
140.6383	100.9670	0.4578
140.6567	100.7850	0.4578
140.6750	100.6018	0.4578
140.6933	100.4171	0.4578
140.7117	100.2358	0.4578
140.7300	100.0528	0.4577
140.7483	99.8706	0.4577
140.7667	99.6879	0.4577
140.7850	99.5031	0.4577
140.8033	99.3216	0.4577
140.8217	99.1384	0.4577
140.8400	98.9553	0.4577
140.8583	98.7717	0.4577
140.8767	98.5879	0.4577
140.8950	98.4067	0.4576
140.9133	98.2227	0.4576
140.9317	98.0392	0.4576
140.9500	97.8572	0.4576
140.9683	97.6745	0.4576
140.9867	97.4900	0.4576
141.0050	97.3079	0.4576
141.0233	97.1244	0.4576
141.0417	96.9420	0.4576
141.0600	96.7593	0.4575
141.0783	96.5755	0.4576
141.0967	96.3933	0.4576
141.1150	96.2095	0.4576
141.1333	96.0268	0.4576
141.1517	95.8443	0.4575
141.1700	95.6605	0.4575
141.1883	95.4780	0.4575
141.2067	95.2939	0.4575
141.2250	95.1114	0.4575
141.2433	94.9279	0.4575
141.2617	94.7445	0.4575
141.2800	94.5613	0.4575
141.2983	94.3778	0.4575
141.3167	94.1951	0.4575
141.3350	94.0121	0.4575
141.3533	93.8290	0.4574
141.3717	93.6446	0.4574
141.3900	93.4632	0.4574
141.4083	93.2802	0.4574
141.4267	93.0971	0.4574
141.4450	92.9143	0.4573
141.4633	92.7307	0.4573
141.4817	92.5480	0.4573
141.5000	92.3648	0.4573
141.5183	92.1821	0.4573
141.5367	91.9980	0.4573
141.5550	91.8157	0.4573
141.5733	91.6321	0.4573
141.5917	91.4498	0.4573
141.6100	91.2657	0.4573
141.6283	91.0830	0.4572
141.6467	90.9000	0.4572
141.6650	90.7165	0.4572
141.6833	90.5341	0.4572
141.7017	90.3507	0.4572
141.7200	90.1685	0.4571
141.7383	89.9848	0.4571
141.7567	89.8023	0.4571
141.7750	89.6188	0.4571
141.7933	89.4350	0.4571
141.8117	89.2531	0.4571
141.8300	89.0692	0.4571
141.8483	88.8876	0.4571
141.8667	88.7040	0.4570
141.8850	88.5199	0.4570
141.9033	88.3374	0.4570
141.9217	88.1543	0.4569
141.9400	87.9710	0.4569
141.9583	87.7881	0.4569
141.9767	87.6039	0.4569
141.9950	87.4218	0.4569
142.0133	87.2387	0.4569
142.0317	87.0562	0.4569
142.0500	86.8725	0.4569
142.0683	86.6898	0.4568
142.0867	86.5053	0.4568
142.1050	86.3242	0.4568
142.1233	86.1394	0.4568
142.1417	85.9578	0.4568
142.1600	85.7740	0.4568
142.1783	85.5910	0.4567
142.1967	85.4078	0.4567
142.2150	85.2249	0.4567
142.2333	85.0426	0.4566
142.2517	84.8586	0.4566
142.2700	84.6758	0.4566
142.2883	84.4920	0.4566
142.3067	84.3087	0.4566
142.3250	84.1260	0.4566
142.3433	83.9426	0.4566
142.3617	83.7591	0.4565
142.3800	83.5776	0.4565
142.3983	83.3937	0.4565
142.4167	83.2104	0.4565
142.4350	83.0274	0.4564
142.4533	82.8451	0.4564
142.4717	82.6607	0.4564
142.4900	82.4779	0.4564
142.5083	82.2951	0.4564
142.5267	82.1125	0.4564
142.5450	81.9305	0.4563
142.5633	81.7469	0.4563
142.5817	81.5634	0.4563
142.6000	81.3807	0.4563
142.6183	81.1973	0.4562
142.6367	81.0144	0.4562
142.6550	80.8307	0.4562
142.6733	80.6480	0.4561
142.6917	80.4643	0.4562
142.7100	80.2815	0.4561
142.7283	80.0985	0.4561
142.7467	79.9165	0.4561
142.7650	79.7324	0.4561
142.7833	79.5505	0.4561
142.8017	79.3664	0.4560
142.8200	79.1847	0.4560
142.8383	79.0001	0.4560
142.8567	78.8186	0.4560
142.8750	78.6343	0.4560
142.8933	78.4513	0.4559
142.9117	78.2685	0.4559
142.9300	78.0852	0.4559
142.9483	77.9016	0.4559
142.9667	77.7197	0.4559
142.9850	77.5361	0.4559
143.0033	77.3521	0.4559
143.0217	77.1697	0.4559
143.0400	76.9865	0.4558
143.0583	76.8046	0.4558
143.0767	76.6203	0.4558
143.0950	76.4369	0.4558
143.1133	76.2546	0.4557
143.1317	76.0713	0.4557
143.1500	75.8880	0.4557
143.1683	75.7046	0.4557
143.1867	75.5224	0.4557
143.2050	75.3393	0.4556
143.2233	75.1560	0.4556
143.2417	74.9726	0.4556
143.2600	74.7908	0.4556
143.2783	74.6063	0.4556
143.2967	74.4236	0.4555
143.3150	74.2415	0.4555
143.3333	74.0579	0.4555
143.3517	73.8738	0.4555
143.3700	73.6914	0.4554
143.3883	73.5074	0.4554
143.4067	73.3250	0.4553
143.4250	73.1420	0.4552
143.4433	72.9592	0.4552
143.4617	72.7756	0.4552
143.4800	72.5929	0.4552
143.4983	72.4093	0.4552
143.5167	72.2261	0.4552
143.5350	72.0436	0.4552
143.5533	71.8605	0.4552
143.5717	71.6769	0.4551
143.5900	71.4936	0.4551
143.6083	71.3103	0.4551
143.6267	71.1272	0.4551
143.6450	70.9448	0.4550
143.6633	70.7605	0.4550
143.6817	70.5780	0.4550
143.7000	70.3946	0.4549
143.7183	70.2135	0.4549
143.7367	70.0304	0.4549
143.7550	69.8464	0.4548
143.7733	69.6633	0.4548
143.7917	69.4801	0.4548
143.8100	69.2972	0.4547
143.8283	69.1145	0.4547
143.8467	68.9302	0.4547
143.8650	68.7473	0.4547
143.8833	68.5647	0.4546
143.9017	68.3807	0.4546
143.9200	68.1979	0.4546
143.9383	68.0157	0.4546
143.9567	67.8320	0.4546
143.9750	67.6490	0.4546
143.9933	67.4658	0.4545
144.0117	67.2832	0.4545
144.0300	67.0991	0.4545
144.0483	66.9167	0.4545
144.0667	66.7339	0.4545
144.0850	66.5499	0.4545
144.1033	66.3676	0.4544
144.1217	66.1845	0.4544
144.1400	66.0016	0.4544
144.1583	65.8188	0.4544
144.1767	65.6352	0.4543
144.1950	65.4518	0.4543
144.2133	65.2676	0.4543
144.2317	65.0865	0.4542
144.2500	64.9017	0.4542
144.2683	64.7201	0.4542
144.2867	64.5350	0.4541
144.3050	64.3523	0.4541
144.3233	64.1700	0.4541
144.3417	63.9863	0.4540
144.3600	63.8050	0.4540
144.3783	63.6213	0.4540
144.3967	63.4396	0.4539
144.4150	63.2552	0.4539
144.4333	63.0723	0.4538
144.4517	62.8883	0.4538
144.4700	62.7058	0.4538
144.4883	62.5234	0.4538
144.5067	62.3404	0.4537
144.5250	62.1562	0.4537
144.5433	61.9730	0.4536
144.5617	61.7906	0.4536
144.5800	61.6071	0.4535
144.5983	61.4250	0.4535
144.6167	61.2420	0.4535
144.6350	61.0579	0.4534
144.6533	60.8750	0.4534
144.6717	60.6917	0.4533
144.6900	60.5081	0.4533
144.7083	60.3255	0.4532
144.7267	60.1421	0.4532
144.7450	59.9597	0.4531
144.7633	59.7756	0.4531
144.7817	59.5933	0.4531
144.8000	59.4092	0.4530
144.8183	59.2271	0.4530
144.8367	59.0441	0.4530
144.8550	58.8608	0.4529
144.8733	58.6773	0.4529
144.8917	58.4943	0.4528
144.9100	58.3119	0.4528
144.9283	58.1286	0.4527
144.9467	57.9463	0.4527
144.9650	57.7622	0.4526
144.9833	57.5789	0.4526
145.0017	57.3966	0.4526
145.0200	57.2137	0.4525
145.0383	57.0311	0.4525
145.0567	56.8466	0.4524
145.0750	56.6635	0.4524
145.0933	56.4798	0.4523
145.1117	56.2975	0.4523
145.1300	56.1149	0.4522
145.1483	55.9312	0.4522
145.1667	55.7477	0.4521
145.1850	55.5650	0.4521
145.2033	55.3806	0.4520
145.2217	55.1997	0.4520
145.2400	55.0156	0.4519
145.2583	54.8328	0.4519
145.2767	54.6488	0.4518
145.2950	54.4669	0.4518
145.3133	54.2842	0.4517
145.3317	54.1005	0.4517
145.3500	53.9171	0.4516
145.3683	53.7341	0.4516
145.3867	53.5505	0.4515
145.4050	53.3673	0.4514
145.4233	53.1845	0.4514
145.4417	53.0019	0.4513
145.4600	52.8193	0.4513
145.4783	52.6349	0.4512
145.4967	52.4513	0.4512
145.5150	52.2686	0.4511
145.5333	52.0853	0.4511
145.5517	51.9019	0.4511
145.5700	51.7196	0.4510
145.5883	51.5369	0.4510
145.6067	51.3535	0.4509
145.6250	51.1699	0.4509
145.6433	50.9877	0.4508
145.6617	50.8029	0.4507
145.6800	50.6206	0.4506
145.6983	50.4379	0.4506
145.7167	50.2555	0.4505
145.7350	50.0726	0.4505
145.7533	49.8888	0.4504
145.7717	49.7052	0.4504
145.7900	49.5218	0.4503
145.8083	49.3404	0.4503
145.8267	49.1568	0.4502
145.8450	48.9732	0.4503
145.8633	48.7895	0.4502
145.8817	48.6080	0.4502
145.9000	48.4242	0.4501
145.9183	48.2409	0.4501
145.9367	48.0587	0.4500
145.9550	47.8751	0.4500
145.9733	47.6914	0.4499
145.9917	47.5088	0.4499
146.0100	47.3242	0.4498
146.0283	47.1417	0.4498
146.0467	46.9589	0.4497
146.0650	46.7752	0.4497
146.0833	46.5920	0.4497
146.1017	46.4085	0.4496
146.1200	46.2262	0.4496
146.1383	46.0434	0.4495
146.1567	45.8594	0.4495
146.1750	45.6774	0.4494
146.1933	45.4940	0.4494
146.2117	45.3104	0.4493
146.2300	45.1281	0.4493
146.2483	44.9447	0.4492
146.2667	44.7613	0.4491
146.2850	44.5780	0.4490
146.3033	44.3948	0.4490
146.3217	44.2122	0.4490
146.3400	44.0294	0.4489
146.3583	43.8453	0.4489
146.3767	43.6636	0.4488
146.3950	43.4810	0.4488
146.4133	43.2974	0.4487
146.4317	43.1135	0.4487
146.4500	42.9304	0.4486
146.4683	42.7469	0.4486
146.4867	42.5645	0.4485
146.5050	42.3825	0.4484
146.5233	42.1990	0.4484
146.5417	42.0156	0.4483
146.5600	41.8329	0.4483
146.5783	41.6492	0.4483
146.5967	41.4649	0.4482
146.6150	41.2836	0.4482
146.6333	41.0997	0.4481
146.6517	40.9155	0.4480
146.6700	40.7339	0.4480
146.6883	40.5511	0.4479
146.7067	40.3676	0.4478
146.7250	40.1844	0.4478
146.7433	40.0008	0.4477
146.7617	39.8178	0.4476
146.7800	39.6358	0.4476
146.7983	39.4513	0.4476
146.8167	39.2689	0.4475
146.8350	39.0848	0.4474
146.8533	38.9021	0.4474
146.8717	38.7193	0.4474
146.8900	38.5356	0.4473
146.9083	38.3527	0.4472
146.9267	38.1695	0.4472
146.9450	37.9859	0.4471
146.9633	37.8031	0.4470
146.9817	37.6201	0.4470
147.0000	37.4375	0.4469
147.0183	37.2536	0.4469
147.0367	37.0706	0.4468
147.0550	36.8880	0.4467
147.0733	36.7040	0.4466
147.0917	36.5210	0.4465
147.1100	36.3386	0.4465
147.1283	36.1550	0.4464
147.1467	35.9727	0.4463
147.1650	35.7893	0.4462
147.1833	35.6067	0.4462
147.2017	35.4218	0.4461
147.2200	35.2393	0.4460
147.2383	35.0569	0.4459
147.2567	34.8736	0.4458
147.2750	34.6888	0.4457
147.2933	34.5071	0.4456
147.3117	34.3234	0.4456
147.3300	34.1400	0.4455
147.3483	33.9565	0.4454
147.3667	33.7741	0.4452
147.3850	33.5906	0.4452
147.4033	33.4085	0.4448
147.4217	33.2238	0.4448
147.4400	33.0402	0.4447
147.4583	32.8570	0.4445
147.4767	32.6737	0.4444
147.4950	32.4911	0.4442
147.5133	32.3074	0.4440
147.5317	32.1247	0.4437
147.5500	31.9415	0.4436
147.5683	31.7575	0.4433
147.5867	31.5755	0.4432
147.6050	31.3925	0.4430
147.6233	31.2077	0.4429
147.6417	31.0255	0.4424
147.6600	30.8419	0.4422
147.6783	30.6581	0.4421
147.6967	30.4753	0.4420
147.7150	30.2917	0.4417
147.7333	30.1086	0.4412
147.7517	29.9255	0.4410
147.7700	29.7428	0.4404
147.7883	29.5583	0.4401
147.8067	29.3766	0.4397
147.8250	29.1931	0.4395
147.8433	29.0092	0.4391
147.8617	28.8256	0.4388
147.8800	28.6411	0.4382
147.8983	28.4585	0.4379
147.9167	28.2746	0.4372
147.9350	28.0908	0.4362
147.9533	27.9090	0.4358
147.9717	27.7238	0.4351
147.9900	27.5406	0.4344
148.0083	27.3574	0.4336
148.0267	27.1724	0.4326
148.0450	26.9892	0.4321
148.0633	26.8076	0.4308
148.0817	26.6213	0.4302
148.1000	26.4388	0.4298
148.1183	26.2547	0.4294
148.1367	26.0711	0.4282
148.1550	25.8875	0.4273
148.1733	25.7053	0.4270
148.1917	25.5216	0.4263
148.2100	25.3368	0.4256
148.2283	25.1533	0.4249
148.2467	24.9695	0.4239
148.2650	24.7851	0.4231
148.2833	24.6020	0.4221
148.3017	24.4181	0.4208
148.3200	24.2336	0.4203
148.3383	24.0499	0.4198
148.3567	23.8672	0.4194
148.3750	23.6837	0.4180
148.3933	23.4980	0.4174
148.4117	23.3151	0.4167
148.4300	23.1312	0.4158
148.4483	22.9473	0.4150
148.4667	22.7635	0.4145
148.4850	22.5795	0.4137
148.5033	22.3964	0.4126
148.5217	22.2127	0.4120
148.5400	22.0290	0.4112
148.5583	21.8449	0.4108
148.5767	21.6616	0.4103
148.5950	21.4769	0.4088
148.6133	21.2926	0.4083
148.6317	21.1091	0.4076
148.6500	20.9264	0.4068
148.6683	20.7422	0.4066
148.6867	20.5585	0.4058
148.7050	20.3757	0.4050
148.7233	20.1899	0.4046
148.7417	20.0069	0.4038
148.7600	19.8231	0.4035
148.7783	19.6392	0.4025
148.7967	19.4565	0.4019
148.8150	19.2736	0.4013
148.8333	19.0884	0.4007
148.8517	18.9055	0.4000
148.8700	18.7217	0.3995
148.8883	18.5378	0.3988
148.9067	18.3541	0.3984
148.9250	18.1694	0.3978
148.9433	17.9877	0.3973
148.9617	17.8039	0.3968
148.9800	17.6190	0.3966
148.9983	17.4369	0.3957
149.0167	17.2524	0.3952
149.0350	17.0681	0.3947
149.0533	16.8845	0.3942
149.0717	16.7013	0.3939
149.0900	16.5195	0.3931
149.1083	16.3340	0.3929
149.1267	16.1508	0.3923
149.1450	15.9672	0.3921
149.1633	15.7837	0.3911
149.1817	15.6003	0.3908
149.2000	15.4173	0.3906
149.2183	15.2346	0.3899
149.2367	15.0491	0.3895
149.2550	14.8667	0.3889
149.2733	14.6817	0.3887
149.2917	14.4996	0.3885
149.3100	14.3160	0.3880
149.3283	14.1325	0.3875
149.3467	13.9473	0.3873
149.3650	13.7643	0.3870
149.3833	13.5825	0.3869
149.4017	13.3973	0.3864
149.4200	13.2144	0.3860
149.4383	13.0314	0.3856
149.4567	12.8479	0.3853
149.4750	12.6639	0.3850
149.4933	12.4802	0.3849
149.5117	12.2973	0.3844
149.5300	12.1137	0.3841
149.5483	11.9305	0.3838
149.5667	11.7472	0.3836
149.5850	11.5630	0.3834
149.6033	11.3803	0.3827
149.6217	11.1957	0.3825
149.6400	11.0124	0.3820
149.6583	10.8297	0.3818
149.6767	10.6472	0.3815
149.6950	10.4626	0.3813
149.7133	10.2789	0.3811
149.7317	10.0959	0.3806
149.7500	9.9128	0.3804
149.7683	9.7287	0.3800
149.7867	9.5448	0.3798
149.8050	9.3624	0.3797
149.8233	9.1784	0.3794
149.8417	8.9956	0.3792
149.8600	8.8119	0.3790
149.8783	8.6286	0.3787
149.8967	8.4461	0.3785
149.9150	8.2608	0.3783
149.9333	8.0776	0.3781
149.9517	7.8955	0.3778
149.9700	7.7128	0.3776
149.9883	7.5305	0.3774
150.0067	7.3456	0.3771
150.0250	7.1614	0.3769
150.0433	6.9786	0.3766
150.0617	6.7944	0.3765
150.0800	6.6117	0.3762
150.0983	6.4288	0.3760
150.1167	6.2444	0.3758
150.1350	6.0614	0.3756
150.1533	5.8799	0.3753
150.1717	5.6960	0.3751
150.1900	5.5142	0.3749
150.2083	5.3289	0.3747
150.2267	5.1444	0.3745
150.2450	4.9635	0.3743
150.2633	4.7786	0.3738
150.2817	4.5964	0.3736
150.3000	4.4122	0.3735
150.3183	4.2288	0.3733
150.3367	4.0458	0.3731
150.3550	3.8623	0.3729
150.3733	3.6809	0.3727
150.3917	3.4975	0.3725
150.4100	3.3141	0.3723
150.4283	3.1290	0.3721
150.4467	2.9465	0.3720
150.4650	2.7628	0.3719
150.4833	2.5794	0.3717
150.5017	2.3962	0.3715
150.5200	2.2136	0.3712
150.5383	2.0298	0.3711
150.5567	1.8481	0.3709
150.5750	1.6640	0.3707
150.5933	1.4800	0.3705
150.6117	1.2974	0.3704
150.6300	1.1130	0.3703
150.6483	0.9315	0.3699
150.6667	0.7467	0.3698
150.6850	0.5639	0.3696
150.7033	0.3808	0.3694
150.7217	0.1988	0.3690
150.7400	0.0153	0.3689
150.7583	-0.1693	0.3687
150.7767	-0.3509	0.3686
150.7950	-0.5344	0.3684
150.8133	-0.7173	0.3683
150.8317	-0.9012	0.3682
150.8500	-1.0854	0.3680
150.8683	-1.2688	0.3679
150.8867	-1.4510	0.3678
150.9050	-1.6331	0.3677
150.9233	-1.8167	0.3676
150.9417	-2.0006	0.3675
150.9600	-2.1838	0.3673
150.9783	-2.3669	0.3671
150.9967	-2.5493	0.3670
151.0150	-2.7327	0.3669
151.0333	-2.9160	0.3667
151.0517	-3.0991	0.3666
151.0700	-3.2828	0.3664
151.0883	-3.4665	0.3663
151.1067	-3.6493	0.3662
151.1250	-3.8330	0.3661
151.1433	-4.0154	0.3659
151.1617	-4.1982	0.3658
151.1800	-4.3808	0.3657
151.1983	-4.5656	0.3656
151.2167	-4.7481	0.3655
151.2350	-4.9309	0.3654
151.2533	-5.1144	0.3653
151.2717	-5.2975	0.3651
151.2900	-5.4815	0.3650
151.3083	-5.6647	0.3649
151.3267	-5.8468	0.3647
151.3450	-6.0299	0.3646
151.3633	-6.2128	0.3645
151.3817	-6.3967	0.3644
151.4000	-6.5804	0.3643
151.4183	-6.7626	0.3642
151.4367	-6.9474	0.3640
151.4550	-7.1297	0.3639
151.4733	-7.3127	0.3638
151.4917	-7.4945	0.3637
151.5100	-7.6789	0.3635
151.5283	-7.8616	0.3634
151.5467	-8.0445	0.3633
151.5650	-8.2282	0.3630
151.5833	-8.4105	0.3629
151.6017	-8.5942	0.3628
151.6200	-8.7768	0.3627
151.6383	-8.9603	0.3624
151.6567	-9.1447	0.3623
151.6750	-9.3285	0.3623
151.6933	-9.5110	0.3622
151.7117	-9.6931	0.3621
151.7300	-9.8770	0.3619
151.7483	-10.0615	0.3618
151.7667	-10.2439	0.3617
151.7850	-10.4259	0.3617
151.8033	-10.6099	0.3616
151.8217	-10.7944	0.3615
151.8400	-10.9770	0.3614
151.8583	-11.1597	0.3613
151.8767	-11.3430	0.3612
151.8950	-11.5260	0.3611
151.9133	-11.7099	0.3610
151.9317	-11.8938	0.3609
151.9500	-12.0750	0.3608
151.9683	-12.2590	0.3607
151.9867	-12.4421	0.3606
152.0050	-12.6248	0.3606
152.0233	-12.8087	0.3604
152.0417	-12.9922	0.3603
152.0600	-13.1759	0.3602
152.0783	-13.3587	0.3601
152.0967	-13.5416	0.3600
152.1150	-13.7252	0.3599
152.1333	-13.9083	0.3599
152.1517	-14.0898	0.3598
152.1700	-14.2743	0.3597
152.1883	-14.4566	0.3596
152.2067	-14.6397	0.3595
152.2250	-14.8241	0.3594
152.2433	-15.0073	0.3594
152.2617	-15.1900	0.3593
152.2800	-15.3735	0.3591
152.2983	-15.5552	0.3590
152.3167	-15.7400	0.3590
152.3350	-15.9231	0.3589
152.3533	-16.1060	0.3588
152.3717	-16.2892	0.3587
152.3900	-16.4713	0.3586
152.4083	-16.6559	0.3585
152.4267	-16.8393	0.3584
152.4450	-17.0227	0.3583
152.4633	-17.2057	0.3582
152.4817	-17.3886	0.3581
152.5000	-17.5714	0.3580
152.5183	-17.7542	0.3579
152.5367	-17.9378	0.3578
152.5550	-18.1218	0.3577
152.5733	-18.3045	0.3575
152.5917	-18.4894	0.3574
152.6100	-18.6707	0.3573
152.6283	-18.8540	0.3572
152.6467	-19.0378	0.3571
152.6650	-19.2204	0.3570
152.6833	-19.4031	0.3569
152.7017	-19.5872	0.3569
152.7200	-19.7707	0.3568
152.7383	-19.9527	0.3567
152.7567	-20.1361	0.3566
152.7750	-20.3196	0.3564
152.7933	-20.5010	0.3563
152.8117	-20.6866	0.3563
152.8300	-20.8696	0.3561
152.8483	-21.0510	0.3560
152.8667	-21.2358	0.3559
152.8850	-21.4169	0.3558
152.9033	-21.6009	0.3558
152.9217	-21.7854	0.3557
152.9400	-21.9668	0.3556
152.9583	-22.1508	0.3555
152.9767	-22.3354	0.3554
152.9950	-22.5183	0.3554
153.0133	-22.7000	0.3553
153.0317	-22.8847	0.3552
153.0500	-23.0671	0.3551
153.0683	-23.2517	0.3550
153.0867	-23.4345	0.3549
153.1050	-23.6160	0.3549
153.1233	-23.7996	0.3548
153.1417	-23.9819	0.3547
153.1600	-24.1674	0.3546
153.1783	-24.3495	0.3545
153.1967	-24.5331	0.3545
153.2150	-24.7163	0.3544
153.2333	-24.8995	0.3542
153.2517	-25.0837	0.3541
153.2700	-25.2657	0.3540
153.2883	-25.4488	0.3539
153.3067	-25.6319	0.3538
153.3250	-25.8153	0.3537
153.3433	-25.9985	0.3536
153.3617	-26.1812	0.3535
153.3800	-26.3659	0.3535
153.3983	-26.5489	0.3534
153.4167	-26.7316	0.3533
153.4350	-26.9136	0.3532
153.4533	-27.0969	0.3531
153.4717	-27.2803	0.3529
153.4900	-27.4631	0.3529
153.5083	-27.6481	0.3528
153.5267	-27.8315	0.3527
153.5450	-28.0137	0.3526
153.5633	-28.1975	0.3526
153.5817	-28.3806	0.3525
153.6000	-28.5634	0.3523
153.6183	-28.7476	0.3522
153.6367	-28.9295	0.3521
153.6550	-29.1121	0.3521
153.6733	-29.2963	0.3519
153.6917	-29.4788	0.3519
153.7100	-29.6638	0.3518
153.7283	-29.8457	0.3517
153.7467	-30.0299	0.3517
153.7650	-30.2119	0.3516
153.7833	-30.3959	0.3515
153.8017	-30.5782	0.3514
153.8200	-30.7624	0.3512
153.8383	-30.9468	0.3512
153.8567	-31.1279	0.3511
153.8750	-31.3121	0.3510
153.8933	-31.4937	0.3509
153.9117	-31.6782	0.3509
153.9300	-31.8602	0.3508
153.9483	-32.0448	0.3507
153.9667	-32.2265	0.3507
153.9850	-32.4108	0.3506
154.0033	-32.5935	0.3505
154.0217	-32.7750	0.3504
154.0400	-32.9600	0.3503
154.0583	-33.1432	0.3503
154.0767	-33.3269	0.3502
154.0950	-33.5095	0.3502
154.1133	-33.6936	0.3501
154.1317	-33.8766	0.3501
154.1500	-34.0587	0.3499
154.1683	-34.2426	0.3498
154.1867	-34.4244	0.3498
154.2050	-34.6080	0.3496
154.2233	-34.7931	0.3496
154.2417	-34.9752	0.3496
154.2600	-35.1575	0.3495
154.2783	-35.3414	0.3494
154.2967	-35.5244	0.3493
154.3150	-35.7060	0.3493
154.3333	-35.8907	0.3492
154.3517	-36.0744	0.3492
154.3700	-36.2581	0.3491
154.3883	-36.4424	0.3490
154.4067	-36.6238	0.3489
154.4250	-36.8074	0.3489
154.4433	-36.9903	0.3488
154.4617	-37.1732	0.3487
154.4800	-37.3561	0.3486
154.4983	-37.5408	0.3485
154.5167	-37.7243	0.3485
154.5350	-37.9068	0.3484
154.5533	-38.0897	0.3483
154.5717	-38.2730	0.3483
154.5900	-38.4567	0.3482
154.6083	-38.6406	0.3481
154.6267	-38.8228	0.3480
154.6450	-39.0063	0.3480
154.6633	-39.1898	0.3479
154.6817	-39.3730	0.3479
154.7000	-39.5564	0.3477
154.7183	-39.7401	0.3477
154.7367	-39.9223	0.3476
154.7550	-40.1051	0.3475
154.7733	-40.2876	0.3474
154.7917	-40.4728	0.3474
154.8100	-40.6553	0.3473
154.8283	-40.8389	0.3472
154.8467	-41.0227	0.3472
154.8650	-41.2050	0.3471
154.8833	-41.3871	0.3470
154.9017	-41.5709	0.3468
154.9200	-41.7551	0.3467
154.9383	-41.9377	0.3467
154.9567	-42.1216	0.3466
154.9750	-42.3040	0.3465
154.9933	-42.4873	0.3464
155.0117	-42.6708	0.3462
155.0300	-42.8544	0.3462
155.0483	-43.0368	0.3461
155.0667	-43.2205	0.3460
155.0850	-43.4015	0.3459
155.1033	-43.5868	0.3459
155.1217	-43.7693	0.3458
155.1400	-43.9521	0.3457
155.1583	-44.1359	0.3457
155.1767	-44.3189	0.3454
155.1950	-44.5017	0.3454
155.2133	-44.6859	0.3453
155.2317	-44.8699	0.3453
155.2500	-45.0533	0.3452
155.2683	-45.2355	0.3451
155.2867	-45.4184	0.3450
155.3050	-45.6022	0.3450
155.3233	-45.7845	0.3449
155.3417	-45.9691	0.3448
155.3600	-46.1519	0.3448
155.3783	-46.3357	0.3447
155.3967	-46.5193	0.3447
155.4150	-46.7014	0.3446
155.4333	-46.8843	0.3445
155.4517	-47.0677	0.3444
155.4700	-47.2515	0.3443
155.4883	-47.4351	0.3442
155.5067	-47.6175
155.5250	-47.8018
155.5433
155.5467