File: Example Date/My Sample/DSC/LLM_ER_01.txt
Filename	chabif01
Instrument name	DSC2A-01799 (192.168.1.250)
Operator
rundate	30/01/2025
Sample name	chabif01
proceduresegments	Ramp 10.00 °C/min to 120.0000 °C; Isothermal 5.0 min; Ramp 10.00 °C/min to -50.0000 °C; Isothermal 5.0 min; Ramp 10.00 °C/min to 210.0000 °C; Isothermal 5.0 min; Ramp 10.00 °C/min to -50.0000 °C; Isothermal 5.0 min; Ramp 10.00 °C/min to 210.0000 °C; Isothermal 5.0 min; Ramp 10.00 °C/min to -50.0000 °C; Isothermal 5.0 min; Ramp 10.00 °C/min to 25.0000 °C
[File Parameters]
Run Date	30/01/2025 12:27:32
Trios version	5.7.0.56
Original File Name
Current File Name	C:\Users\TA Instruments DSC\Desktop\Data\Mars Poxon\chabif01.tri
User at run start	DESKTOP-CFGN8IT\TA Instruments DSC
[Procedure]
Procedure Name	chabif01
Sample Name	chabif01
Sample Mass	13.54 mg
Reference Sample Mass	0 mg
Pan Mass	61.25 mg
Pan Number	10
Reference Pan Mass	60.81 mg
Reference Pan Number	45
Pan Type	Tzero Aluminum Pin Hole Hermetic
Comments
Project Name
Operator
Test	Custom
Unload Max Temperature	25
Unload Min Temperature	25
FillCooler	Do not fill
Load Max Temperature	25
Load Min Temperature	25
Discard pan in waste bin at end of test	No
Stop on Gas Flow Error	No
[Signal List]
Signal #1	Time (min)
Signal #2	Temperature (°C)
Signal #3	Heat Flow (mW)
Signal #4	Delta T (µV)
Signal #5	Delta Tzero (µV)
Signal #6	Tzero Temperature (°C)
Signal #7	Cell Purge (mL/min)
Signal #8	Heater Temp (°C)
Signal #9	Power Delivered (W)
Signal #10	Reference Junction Temperature (°C)
Signal #11	Flange Temperature (°C)
Signal #12	Heat Flow Phase (rad)
Signal #13	Total Heat Capacity (J/°C)
Signal #14	Heat Capacity (J/°C)
Signal #15	LN Pump Tank level (%)
[Configuration]
Company Name	Warwick University
Instrument Name	DSC2A-01799
Instrument Type	DSC2500
Serial Number	DSC2A-01799
IP	192.168.1.250
Location of Instrument	Polymer RTP
DisplayType	TianmaV2andV3
Sample Interval 	0.1 s/pt
Selected Heat Flow	T4P
Exotherm Direction	Up
Cell Serial	DRC2-03788
Lid Type	High Temperature
Cooler	LN Pump
Leave Cooler on at End of Sequence	Off
Gas 2	Air
Gas Selected	Channel 1: Nitrogen
Flow Rate	50 mL/min
Secondary Purge	On
Licensed Heat Flow	Heat Flow T4P
Modulation Licensed	Yes
[Versions]
Common IDD Version	1
Cortex Version	VER 2.11.0.729
Driver	5.0.0.6
GDM Version	1.0.3.3
TouchscreenVersion	1.0.3.1841
FEP Version	1.2.1.21
FEP Bootloader	2.0.0.5
AutoSampler Version	2.1.2.1
Auto Sampler Bootloader	2.0.0.5
FCM Version	1.1.0.3
FCM Bootloader	2.0.0.5
LN Pump Version	10.17.0.0
LN Pump Bootloader	2.0.0.5
[Experiment Logs]
Experiment Log Entry # 1	Ramp Segment 10 C/min to 120 Started
Experiment Log Entry # 3	Isothermal Segment 5 min started
Experiment Log Entry # 5	Ramp Segment 10 C/min to -50 Started
Experiment Log Entry # 7	LN2P Autofill Enabled
Experiment Log Entry # 9	Isothermal Segment 5 min started
Experiment Log Entry # 11	Ramp Segment 10 C/min to 210 Started
Experiment Log Entry # 13	Isothermal Segment 5 min started
Experiment Log Entry # 15	Ramp Segment 10 C/min to -50 Started
Experiment Log Entry # 17	Isothermal Segment 5 min started
Experiment Log Entry # 19	Ramp Segment 10 C/min to 210 Started
Experiment Log Entry # 21	Isothermal Segment 5 min started
Experiment Log Entry # 23	Ramp Segment 10 C/min to -50 Started
Experiment Log Entry # 26	LN2P is filling
Experiment Log Entry # 27	Current LN2P tank level (39.5%) not increasing during fill. Bulk tank may be empty.
Experiment Log Entry # 29	LN2P stopped filling
Experiment Log Entry # 30	Isothermal Segment 5 min started
Experiment Log Entry # 32	Ramp Segment 10 C/min to 25 Started
[Method Log]
Method Log Entry # 1	(Ramp 824122) Ramp 10 °C/minute to 120 °C
Method Log Entry # 2	Isothermal 5 minutes
Method Log Entry # 3	(Ramp 824124) Ramp 10 °C/minute to -50 °C
Method Log Entry # 4	Isothermal 5 minutes
Method Log Entry # 5	(Ramp 824126) Ramp 10 °C/minute to 210 °C
Method Log Entry # 6	Isothermal 5 minutes
Method Log Entry # 7	(Ramp 824128) Ramp 10 °C/minute to -50 °C
Method Log Entry # 8	Isothermal 5 minutes
Method Log Entry # 9	(Ramp 824130) Ramp 10 °C/minute to 210 °C
Method Log Entry # 10	Isothermal 5 minutes
Method Log Entry # 11	(Ramp 824132) Ramp 10 °C/minute to -50 °C
Method Log Entry # 12	Isothermal 5 minutes
Method Log Entry # 13	(Ramp 824134) Ramp 10 °C/minute to 25 °C
Cell Serial	DRC2-03788
[T1 Calibration]
Date Applied	04/03/2021 14:58:04
Slope	-0.001800291
Offset	-0.1301359
Initial Temperature	-100.6228
GUID	a1d5a6be-decd-4ae4-b22f-d560f3a78a92
[TZero Calibration]
Date Applied	03/01/2025 12:41:45
Description	From -178.795 °C to 396.200 °C at 20.000°C/min
Gas Type	Nitrogen
Pan Type	None
Source Files 1	C:\ProgramData\TA Instruments\TRIOS\Data\Tzero Cal(23).tri
Source Files 2	C:\ProgramData\TA Instruments\TRIOS\Data\Tzero Cal(24).tri
Delta T Offset	1.869383
Delta T Slope	-0.002827686
Delta T0 Offset	0.6518871
Delta T0 Slope	0.03386689
[Temperature Calibration]
Date Applied	07/01/2025 06:48:00
Description	From 106.598 °C to 186.598 °C at 10.000°C/min
Gas Type	Nitrogen
Pan Type	Aluminum Hermetic
Source Files 1	C:\ProgramData\TA Instruments\TRIOS\Data\Indium(10).tri
Measured 1	158.5387
Known 1	156.598
[Cell Constant Calibration]
Date Applied	07/01/2025 06:21:38
Description	From 106.598 °C to 186.598 °C at 10.000°C/min
Gas Type	Nitrogen
Pan Type	Aluminum Hermetic
Source Files 1	C:\ProgramData\TA Instruments\TRIOS\Data\Indium(8).tri
T4P KCell	1.071186
Onset Slope	-20.76992 mW/°C
[Direct Cp Calibration]
Date Applied	07/01/2025 08:34:40
Description	From -89.983 °C to 397.015 °C at 20.000°C/min
Gas Type	Nitrogen
Pan Type	Aluminum Hermetic
Source Files 1	C:\ProgramData\TA Instruments\TRIOS\Data\Sapphire Direct Heat Capacity(11).tri
GUID	bc2b1dd3-d0d9-41bf-ba72-b5fda717766a
Temperature	-89.98325 °C
Cp	0.9880321
Temperature	-89.00925 °C
Cp	0.9883595
Temperature	-88.03526 °C
Cp	0.9883455
Temperature	-87.06126 °C
Cp	0.9880565
Temperature	-86.08727 °C
Cp	0.9875574
Temperature	-85.11327 °C
Cp	0.9868901
Temperature	-84.13927 °C
Cp	0.9861491
Temperature	-83.16528 °C
Cp	0.9854108
Temperature	-82.19128 °C
Cp	0.9847093
Temperature	-81.21728 °C
Cp	0.984123
Temperature	-80.24328 °C
Cp	0.9836704
Temperature	-79.26929 °C
Cp	0.9834349
Temperature	-78.29529 °C
Cp	0.9833817
Temperature	-77.32129 °C
Cp	0.9835677
Temperature	-76.34729 °C
Cp	0.9839252
Temperature	-75.37329 °C
Cp	0.9844846
Temperature	-74.3993 °C
Cp	0.9852123
Temperature	-73.4253 °C
Cp	0.9860855
Temperature	-72.4513 °C
Cp	0.9870548
Temperature	-71.4773 °C
Cp	0.9881113
Temperature	-70.50331 °C
Cp	0.9892243
Temperature	-69.52931 °C
Cp	0.9903587
Temperature	-68.55531 °C
Cp	0.9915038
Temperature	-67.58131 °C
Cp	0.9926346
Temperature	-66.60732 °C
Cp	0.993748
Temperature	-65.63332 °C
Cp	0.994836
Temperature	-64.65932 °C
Cp	0.9959027
Temperature	-63.68533 °C
Cp	0.9969317
Temperature	-62.71133 °C
Cp	0.997943
Temperature	-61.73733 °C
Cp	0.9989527
Temperature	-60.76334 °C
Cp	0.9999582
Temperature	-59.78934 °C
Cp	1.000969
Temperature	-58.81534 °C
Cp	1.00194
Temperature	-57.84134 °C
Cp	1.002997
Temperature	-56.86735 °C
Cp	1.00403
Temperature	-55.89335 °C
Cp	1.005069
Temperature	-54.91935 °C
Cp	1.006104
Temperature	-53.94535 °C
Cp	1.00713
Temperature	-52.97136 °C
Cp	1.008209
Temperature	-51.99736 °C
Cp	1.009185
Temperature	-51.02336 °C
Cp	1.010177
Temperature	-50.04937 °C
Cp	1.011162
Temperature	-49.07537 °C
Cp	1.012141
Temperature	-48.10137 °C
Cp	1.01308
Temperature	-47.12737 °C
Cp	1.013991
Temperature	-46.15338 °C
Cp	1.014858
Temperature	-45.17938 °C
Cp	1.015703
Temperature	-44.20538 °C
Cp	1.016499
Temperature	-43.23138 °C
Cp	1.017257
Temperature	-42.25739 °C
Cp	1.017991
Temperature	-41.28339 °C
Cp	1.018705
Temperature	-40.30939 °C
Cp	1.019413
Temperature	-39.3354 °C
Cp	1.020126
Temperature	-38.3614 °C
Cp	1.020855
Temperature	-37.3874 °C
Cp	1.021604
Temperature	-36.4134 °C
Cp	1.022382
Temperature	-35.43941 °C
Cp	1.023185
Temperature	-34.46541 °C
Cp	1.024018
Temperature	-33.49141 °C
Cp	1.024865
Temperature	-32.51741 °C
Cp	1.025734
Temperature	-31.54342 °C
Cp	1.026615
Temperature	-30.56942 °C
Cp	1.027499
Temperature	-29.59542 °C
Cp	1.028374
Temperature	-28.62143 °C
Cp	1.029232
Temperature	-27.64743 °C
Cp	1.030081
Temperature	-26.67343 °C
Cp	1.030892
Temperature	-25.69943 °C
Cp	1.031667
Temperature	-24.72544 °C
Cp	1.032406
Temperature	-23.75144 °C
Cp	1.03311
Temperature	-22.77744 °C
Cp	1.033786
Temperature	-21.80344 °C
Cp	1.034412
Temperature	-20.82945 °C
Cp	1.035019
Temperature	-19.85545 °C
Cp	1.035599
Temperature	-18.88145 °C
Cp	1.036155
Temperature	-17.90746 °C
Cp	1.036695
Temperature	-16.93346 °C
Cp	1.037207
Temperature	-15.95946 °C
Cp	1.037712
Temperature	-14.98546 °C
Cp	1.038202
Temperature	-14.01147 °C
Cp	1.038666
Temperature	-13.03747 °C
Cp	1.039103
Temperature	-12.06347 °C
Cp	1.039518
Temperature	-11.08947 °C
Cp	1.039909
Temperature	-10.11548 °C
Cp	1.040284
Temperature	-9.14148 °C
Cp	1.040614
Temperature	-8.167483 °C
Cp	1.040915
Temperature	-7.193486 °C
Cp	1.041192
Temperature	-6.219488 °C
Cp	1.041427
Temperature	-5.245491 °C
Cp	1.041627
Temperature	-4.271494 °C
Cp	1.041773
Temperature	-3.297497 °C
Cp	1.041891
Temperature	-2.323499 °C
Cp	1.041951
Temperature	-1.349502 °C
Cp	1.041963
Temperature	-0.3755048 °C
Cp	1.041932
Temperature	0.5984925 °C
Cp	1.041862
Temperature	1.57249 °C
Cp	1.04176
Temperature	2.546487 °C
Cp	1.04162
Temperature	3.520484 °C
Cp	1.041463
Temperature	4.494482 °C
Cp	1.041297
Temperature	5.468479 °C
Cp	1.041124
Temperature	6.442476 °C
Cp	1.040949
Temperature	7.416473 °C
Cp	1.04077
Temperature	8.390471 °C
Cp	1.040596
Temperature	9.364468 °C
Cp	1.04043
Temperature	10.33846 °C
Cp	1.040276
Temperature	11.31246 °C
Cp	1.040137
Temperature	12.28646 °C
Cp	1.040014
Temperature	13.26046 °C
Cp	1.039915
Temperature	14.23445 °C
Cp	1.03984
Temperature	15.20845 °C
Cp	1.039792
Temperature	16.18245 °C
Cp	1.039777
Temperature	17.15645 °C
Cp	1.03979
Temperature	18.13044 °C
Cp	1.039834
Temperature	19.10444 °C
Cp	1.039903
Temperature	20.07844 °C
Cp	1.040019
Temperature	21.05243 °C
Cp	1.040159
Temperature	22.02643 °C
Cp	1.040318
Temperature	23.00043 °C
Cp	1.040496
Temperature	23.97443 °C
Cp	1.040695
Temperature	24.94842 °C
Cp	1.040908
Temperature	25.92242 °C
Cp	1.041143
Temperature	26.89642 °C
Cp	1.041371
Temperature	27.87042 °C
Cp	1.04161
Temperature	28.84441 °C
Cp	1.041855
Temperature	29.81841 °C
Cp	1.042094
Temperature	30.79241 °C
Cp	1.042325
Temperature	31.76641 °C
Cp	1.042534
Temperature	32.7404 °C
Cp	1.04274
Temperature	33.7144 °C
Cp	1.042917
Temperature	34.6884 °C
Cp	1.043064
Temperature	35.6624 °C
Cp	1.04319
Temperature	36.63639 °C
Cp	1.043295
Temperature	37.61039 °C
Cp	1.043386
Temperature	38.58438 °C
Cp	1.043453
Temperature	39.55838 °C
Cp	1.04351
Temperature	40.53238 °C
Cp	1.043562
Temperature	41.50638 °C
Cp	1.043611
Temperature	42.48037 °C
Cp	1.043655
Temperature	43.45437 °C
Cp	1.043698
Temperature	44.42837 °C
Cp	1.043742
Temperature	45.40237 °C
Cp	1.043786
Temperature	46.37637 °C
Cp	1.04383
Temperature	47.35036 °C
Cp	1.043871
Temperature	48.32436 °C
Cp	1.043918
Temperature	49.29836 °C
Cp	1.043969
Temperature	50.27235 °C
Cp	1.044022
Temperature	51.24635 °C
Cp	1.044086
Temperature	52.22035 °C
Cp	1.044155
Temperature	53.19434 °C
Cp	1.044236
Temperature	54.16834 °C
Cp	1.044331
Temperature	55.14234 °C
Cp	1.04443
Temperature	56.11634 °C
Cp	1.04456
Temperature	57.09034 °C
Cp	1.044703
Temperature	58.06433 °C
Cp	1.044864
Temperature	59.03833 °C
Cp	1.045041
Temperature	60.01233 °C
Cp	1.045232
Temperature	60.98632 °C
Cp	1.045442
Temperature	61.96032 °C
Cp	1.045673
Temperature	62.93432 °C
Cp	1.045911
Temperature	63.90831 °C
Cp	1.046162
Temperature	64.88231 °C
Cp	1.046425
Temperature	65.85631 °C
Cp	1.04669
Temperature	66.83031 °C
Cp	1.046952
Temperature	67.80431 °C
Cp	1.047203
Temperature	68.77831 °C
Cp	1.047453
Temperature	69.7523 °C
Cp	1.047677
Temperature	70.7263 °C
Cp	1.047882
Temperature	71.70029 °C
Cp	1.048065
Temperature	72.67429 °C
Cp	1.048226
Temperature	73.64828 °C
Cp	1.048375
Temperature	74.62228 °C
Cp	1.048498
Temperature	75.59628 °C
Cp	1.04861
Temperature	76.57028 °C
Cp	1.048713
Temperature	77.54427 °C
Cp	1.048811
Temperature	78.51827 °C
Cp	1.048901
Temperature	79.49227 °C
Cp	1.048978
Temperature	80.46627 °C
Cp	1.049068
Temperature	81.44027 °C
Cp	1.049148
Temperature	82.41426 °C
Cp	1.04922
Temperature	83.38826 °C
Cp	1.049288
Temperature	84.36226 °C
Cp	1.049353
Temperature	85.33626 °C
Cp	1.049435
Temperature	86.31025 °C
Cp	1.049486
Temperature	87.28425 °C
Cp	1.049549
Temperature	88.25825 °C
Cp	1.049615
Temperature	89.23225 °C
Cp	1.049683
Temperature	90.20624 °C
Cp	1.049742
Temperature	91.18024 °C
Cp	1.04977
Temperature	92.15424 °C
Cp	1.04982
Temperature	93.12823 °C
Cp	1.049839
Temperature	94.10223 °C
Cp	1.049829
Temperature	95.07623 °C
Cp	1.049792
Temperature	96.05022 °C
Cp	1.049731
Temperature	97.02422 °C
Cp	1.049673
Temperature	97.99822 °C
Cp	1.049564
Temperature	98.97221 °C
Cp	1.049451
Temperature	99.94621 °C
Cp	1.049339
Temperature	100.9202 °C
Cp	1.049223
Temperature	101.8942 °C
Cp	1.049111
Temperature	102.8682 °C
Cp	1.048998
Temperature	103.8422 °C
Cp	1.048886
Temperature	104.8162 °C
Cp	1.048782
Temperature	105.7902 °C
Cp	1.048679
Temperature	106.7642 °C
Cp	1.048577
Temperature	107.7382 °C
Cp	1.048481
Temperature	108.7122 °C
Cp	1.048391
Temperature	109.6862 °C
Cp	1.048309
Temperature	110.6602 °C
Cp	1.048232
Temperature	111.6342 °C
Cp	1.04816
Temperature	112.6082 °C
Cp	1.048096
Temperature	113.5822 °C
Cp	1.048038
Temperature	114.5562 °C
Cp	1.047984
Temperature	115.5302 °C
Cp	1.047932
Temperature	116.5042 °C
Cp	1.047888
Temperature	117.4782 °C
Cp	1.047844
Temperature	118.4522 °C
Cp	1.047801
Temperature	119.4262 °C
Cp	1.047756
Temperature	120.4002 °C
Cp	1.047715
Temperature	121.3742 °C
Cp	1.047678
Temperature	122.3482 °C
Cp	1.047638
Temperature	123.3222 °C
Cp	1.047605
Temperature	124.2961 °C
Cp	1.047578
Temperature	125.2701 °C
Cp	1.047555
Temperature	126.2441 °C
Cp	1.047539
Temperature	127.2181 °C
Cp	1.047525
Temperature	128.1921 °C
Cp	1.047524
Temperature	129.1661 °C
Cp	1.047527
Temperature	130.1401 °C
Cp	1.047536
Temperature	131.1141 °C
Cp	1.047554
Temperature	132.0881 °C
Cp	1.047582
Temperature	133.0621 °C
Cp	1.047624
Temperature	134.0361 °C
Cp	1.047662
Temperature	135.0101 °C
Cp	1.047714
Temperature	135.9841 °C
Cp	1.047779
Temperature	136.9581 °C
Cp	1.047853
Temperature	137.9321 °C
Cp	1.047933
Temperature	138.9061 °C
Cp	1.048018
Temperature	139.8801 °C
Cp	1.048097
Temperature	140.8541 °C
Cp	1.048188
Temperature	141.8281 °C
Cp	1.048267
Temperature	142.8021 °C
Cp	1.048337
Temperature	143.7761 °C
Cp	1.048398
Temperature	144.7501 °C
Cp	1.048449
Temperature	145.7241 °C
Cp	1.048503
Temperature	146.6981 °C
Cp	1.048532
Temperature	147.6721 °C
Cp	1.04856
Temperature	148.6461 °C
Cp	1.048587
Temperature	149.6201 °C
Cp	1.04861
Temperature	150.5941 °C
Cp	1.048628
Temperature	151.5681 °C
Cp	1.048627
Temperature	152.5421 °C
Cp	1.048642
Temperature	153.5161 °C
Cp	1.048646
Temperature	154.4901 °C
Cp	1.048642
Temperature	155.4641 °C
Cp	1.048638
Temperature	156.438 °C
Cp	1.048641
Temperature	157.412 °C
Cp	1.048673
Temperature	158.386 °C
Cp	1.048706
Temperature	159.36 °C
Cp	1.048776
Temperature	160.334 °C
Cp	1.048889
Temperature	161.308 °C
Cp	1.049047
Temperature	162.282 °C
Cp	1.049254
Temperature	163.256 °C
Cp	1.049495
Temperature	164.23 °C
Cp	1.049811
Temperature	165.204 °C
Cp	1.050172
Temperature	166.178 °C
Cp	1.050582
Temperature	167.152 °C
Cp	1.051038
Temperature	168.126 °C
Cp	1.051542
Temperature	169.1 °C
Cp	1.052114
Temperature	170.074 °C
Cp	1.052695
Temperature	171.048 °C
Cp	1.053323
Temperature	172.022 °C
Cp	1.053989
Temperature	172.996 °C
Cp	1.05468
Temperature	173.97 °C
Cp	1.055383
Temperature	174.944 °C
Cp	1.056084
Temperature	175.918 °C
Cp	1.056758
Temperature	176.892 °C
Cp	1.057421
Temperature	177.866 °C
Cp	1.058033
Temperature	178.84 °C
Cp	1.058585
Temperature	179.814 °C
Cp	1.059071
Temperature	180.788 °C
Cp	1.059486
Temperature	181.762 °C
Cp	1.059844
Temperature	182.736 °C
Cp	1.060098
Temperature	183.71 °C
Cp	1.060287
Temperature	184.684 °C
Cp	1.06041
Temperature	185.658 °C
Cp	1.060463
Temperature	186.632 °C
Cp	1.060444
Temperature	187.606 °C
Cp	1.060339
Temperature	188.58 °C
Cp	1.060207
Temperature	189.554 °C
Cp	1.060006
Temperature	190.528 °C
Cp	1.059754
Temperature	191.502 °C
Cp	1.059464
Temperature	192.476 °C
Cp	1.059152
Temperature	193.45 °C
Cp	1.05885
Temperature	194.424 °C
Cp	1.058521
Temperature	195.3979 °C
Cp	1.05822
Temperature	196.3719 °C
Cp	1.057951
Temperature	197.3459 °C
Cp	1.057719
Temperature	198.3199 °C
Cp	1.057524
Temperature	199.2939 °C
Cp	1.057347
Temperature	200.2679 °C
Cp	1.057229
Temperature	201.2419 °C
Cp	1.05713
Temperature	202.2159 °C
Cp	1.05705
Temperature	203.1899 °C
Cp	1.056984
Temperature	204.1639 °C
Cp	1.05693
Temperature	205.1379 °C
Cp	1.0569
Temperature	206.1119 °C
Cp	1.05685
Temperature	207.0859 °C
Cp	1.056808
Temperature	208.0599 °C
Cp	1.05677
Temperature	209.0339 °C
Cp	1.05673
Temperature	210.0079 °C
Cp	1.056685
Temperature	210.9819 °C
Cp	1.056633
Temperature	211.9559 °C
Cp	1.056566
Temperature	212.9299 °C
Cp	1.056501
Temperature	213.9039 °C
Cp	1.056424
Temperature	214.8779 °C
Cp	1.056341
Temperature	215.8519 °C
Cp	1.056252
Temperature	216.8259 °C
Cp	1.056168
Temperature	217.7999 °C
Cp	1.0561
Temperature	218.7739 °C
Cp	1.056026
Temperature	219.7479 °C
Cp	1.055973
Temperature	220.7219 °C
Cp	1.055941
Temperature	221.6959 °C
Cp	1.055926
Temperature	222.6699 °C
Cp	1.055924
Temperature	223.6439 °C
Cp	1.055919
Temperature	224.6179 °C
Cp	1.055941
Temperature	225.5919 °C
Cp	1.055954
Temperature	226.5659 °C
Cp	1.055958
Temperature	227.5399 °C
Cp	1.055954
Temperature	228.5139 °C
Cp	1.055943
Temperature	229.4879 °C
Cp	1.055938
Temperature	230.4619 °C
Cp	1.055901
Temperature	231.4359 °C
Cp	1.055866
Temperature	232.4098 °C
Cp	1.055832
Temperature	233.3838 °C
Cp	1.055797
Temperature	234.3578 °C
Cp	1.055757
Temperature	235.3318 °C
Cp	1.055695
Temperature	236.3058 °C
Cp	1.055658
Temperature	237.2798 °C
Cp	1.055607
Temperature	238.2538 °C
Cp	1.055547
Temperature	239.2278 °C
Cp	1.055481
Temperature	240.2018 °C
Cp	1.055414
Temperature	241.1758 °C
Cp	1.055372
Temperature	242.1498 °C
Cp	1.055303
Temperature	243.1238 °C
Cp	1.055254
Temperature	244.0978 °C
Cp	1.055227
Temperature	245.0718 °C
Cp	1.055215
Temperature	246.0458 °C
Cp	1.055219
Temperature	247.0198 °C
Cp	1.055213
Temperature	247.9938 °C
Cp	1.055252
Temperature	248.9678 °C
Cp	1.055289
Temperature	249.9418 °C
Cp	1.055323
Temperature	250.9158 °C
Cp	1.055358
Temperature	251.8898 °C
Cp	1.055391
Temperature	252.8638 °C
Cp	1.055427
Temperature	253.8378 °C
Cp	1.05547
Temperature	254.8118 °C
Cp	1.055506
Temperature	255.7858 °C
Cp	1.055552
Temperature	256.7598 °C
Cp	1.055605
Temperature	257.7338 °C
Cp	1.055662
Temperature	258.7078 °C
Cp	1.055723
Temperature	259.6818 °C
Cp	1.055782
Temperature	260.6558 °C
Cp	1.055847
Temperature	261.6298 °C
Cp	1.055909
Temperature	262.6038 °C
Cp	1.055965
Temperature	263.5778 °C
Cp	1.05602
Temperature	264.5518 °C
Cp	1.056073
Temperature	265.5258 °C
Cp	1.056125
Temperature	266.4998 °C
Cp	1.056176
Temperature	267.4738 °C
Cp	1.05623
Temperature	268.4478 °C
Cp	1.056288
Temperature	269.4218 °C
Cp	1.056349
Temperature	270.3957 °C
Cp	1.056416
Temperature	271.3697 °C
Cp	1.056491
Temperature	272.3437 °C
Cp	1.056571
Temperature	273.3177 °C
Cp	1.056658
Temperature	274.2917 °C
Cp	1.05675
Temperature	275.2657 °C
Cp	1.056848
Temperature	276.2397 °C
Cp	1.056947
Temperature	277.2137 °C
Cp	1.057042
Temperature	278.1877 °C
Cp	1.057142
Temperature	279.1617 °C
Cp	1.057233
Temperature	280.1357 °C
Cp	1.057313
Temperature	281.1097 °C
Cp	1.057381
Temperature	282.0837 °C
Cp	1.057435
Temperature	283.0577 °C
Cp	1.057481
Temperature	284.0317 °C
Cp	1.057495
Temperature	285.0057 °C
Cp	1.057498
Temperature	285.9797 °C
Cp	1.057486
Temperature	286.9537 °C
Cp	1.057462
Temperature	287.9277 °C
Cp	1.057423
Temperature	288.9017 °C
Cp	1.057373
Temperature	289.8757 °C
Cp	1.05731
Temperature	290.8497 °C
Cp	1.057244
Temperature	291.8237 °C
Cp	1.057169
Temperature	292.7977 °C
Cp	1.057092
Temperature	293.7717 °C
Cp	1.057015
Temperature	294.7457 °C
Cp	1.05694
Temperature	295.7197 °C
Cp	1.056872
Temperature	296.6937 °C
Cp	1.056808
Temperature	297.6677 °C
Cp	1.056752
Temperature	298.6417 °C
Cp	1.056704
Temperature	299.6157 °C
Cp	1.056662
Temperature	300.5897 °C
Cp	1.056626
Temperature	301.5637 °C
Cp	1.05659
Temperature	302.5377 °C
Cp	1.056563
Temperature	303.5117 °C
Cp	1.056535
Temperature	304.4856 °C
Cp	1.056507
Temperature	305.4596 °C
Cp	1.05648
Temperature	306.4336 °C
Cp	1.056456
Temperature	307.4076 °C
Cp	1.056444
Temperature	308.3816 °C
Cp	1.056429
Temperature	309.3556 °C
Cp	1.056431
Temperature	310.3296 °C
Cp	1.056452
Temperature	311.3036 °C
Cp	1.056492
Temperature	312.2776 °C
Cp	1.056555
Temperature	313.2516 °C
Cp	1.056631
Temperature	314.2256 °C
Cp	1.056748
Temperature	315.1996 °C
Cp	1.056883
Temperature	316.1736 °C
Cp	1.057038
Temperature	317.1476 °C
Cp	1.057212
Temperature	318.1216 °C
Cp	1.057405
Temperature	319.0956 °C
Cp	1.057631
Temperature	320.0696 °C
Cp	1.057845
Temperature	321.0436 °C
Cp	1.058079
Temperature	322.0176 °C
Cp	1.058326
Temperature	322.9916 °C
Cp	1.058582
Temperature	323.9656 °C
Cp	1.058841
Temperature	324.9396 °C
Cp	1.059099
Temperature	325.9136 °C
Cp	1.059348
Temperature	326.8876 °C
Cp	1.059604
Temperature	327.8616 °C
Cp	1.05985
Temperature	328.8356 °C
Cp	1.060092
Temperature	329.8096 °C
Cp	1.060333
Temperature	330.7836 °C
Cp	1.060579
Temperature	331.7576 °C
Cp	1.060841
Temperature	332.7316 °C
Cp	1.061109
Temperature	333.7056 °C
Cp	1.061398
Temperature	334.6796 °C
Cp	1.061709
Temperature	335.6536 °C
Cp	1.062038
Temperature	336.6276 °C
Cp	1.062384
Temperature	337.6016 °C
Cp	1.062742
Temperature	338.5755 °C
Cp	1.063104
Temperature	339.5495 °C
Cp	1.063464
Temperature	340.5235 °C
Cp	1.063814
Temperature	341.4975 °C
Cp	1.064146
Temperature	342.4715 °C
Cp	1.064453
Temperature	343.4455 °C
Cp	1.064728
Temperature	344.4195 °C
Cp	1.06497
Temperature	345.3935 °C
Cp	1.065176
Temperature	346.3675 °C
Cp	1.065346
Temperature	347.3415 °C
Cp	1.065484
Temperature	348.3155 °C
Cp	1.065596
Temperature	349.2895 °C
Cp	1.065687
Temperature	350.2635 °C
Cp	1.065775
Temperature	351.2375 °C
Cp	1.065862
Temperature	352.2115 °C
Cp	1.06596
Temperature	353.1855 °C
Cp	1.066075
Temperature	354.1595 °C
Cp	1.066217
Temperature	355.1335 °C
Cp	1.066395
Temperature	356.1075 °C
Cp	1.06659
Temperature	357.0815 °C
Cp	1.066817
Temperature	358.0555 °C
Cp	1.067067
Temperature	359.0295 °C
Cp	1.067329
Temperature	360.0035 °C
Cp	1.067591
Temperature	360.9775 °C
Cp	1.067838
Temperature	361.9515 °C
Cp	1.068055
Temperature	362.9255 °C
Cp	1.068232
Temperature	363.8995 °C
Cp	1.068357
Temperature	364.8735 °C
Cp	1.068423
Temperature	365.8475 °C
Cp	1.068431
Temperature	366.8215 °C
Cp	1.068385
Temperature	367.7955 °C
Cp	1.068293
Temperature	368.7695 °C
Cp	1.068177
Temperature	369.7435 °C
Cp	1.068051
Temperature	370.7175 °C
Cp	1.067937
Temperature	371.6914 °C
Cp	1.067864
Temperature	372.6654 °C
Cp	1.067851
Temperature	373.6394 °C
Cp	1.067924
Temperature	374.6134 °C
Cp	1.068083
Temperature	375.5874 °C
Cp	1.068344
Temperature	376.5614 °C
Cp	1.068699
Temperature	377.5354 °C
Cp	1.069131
Temperature	378.5094 °C
Cp	1.069605
Temperature	379.4834 °C
Cp	1.070071
Temperature	380.4574 °C
Cp	1.070487
Temperature	381.4314 °C
Cp	1.07077
Temperature	382.4054 °C
Cp	1.070846
Temperature	383.3794 °C
Cp	1.070635
Temperature	384.3534 °C
Cp	1.070055
Temperature	385.3274 °C
Cp	1.069033
Temperature	386.3014 °C
Cp	1.067489
Temperature	387.2754 °C
Cp	1.065378
Temperature	388.2494 °C
Cp	1.062665
Temperature	389.2234 °C
Cp	1.059324
Temperature	390.1974 °C
Cp	1.055366
Temperature	391.1714 °C
Cp	1.050821
Temperature	392.1454 °C
Cp	1.045742
Temperature	393.1194 °C
Cp	1.040203
Temperature	394.0934 °C
Cp	1.034295
Temperature	395.0674 °C
Cp	1.028124
Temperature	396.0414 °C
Cp	1.021801
[Rev Cp Calibration]
Date Applied	07/01/2025 13:18:35
Description	From -90.000 °C to 391.202 °C at 2.000°C/min
Gas Type	Nitrogen
Pan Type	Aluminum Hermetic
Source Files 1	C:\ProgramData\TA Instruments\TRIOS\Data\Reverse Heat Capacity Calibration(8).tri
GUID	2f9866b8-ce4e-42f5-95a1-c21443fc3171
Temperature	-89.99985 °C
Cp	1.026385
Temperature	-89.03745 °C
Cp	1.030641
Temperature	-88.07504 °C
Cp	1.034621
Temperature	-87.11264 °C
Cp	1.038235
Temperature	-86.15024 °C
Cp	1.041454
Temperature	-85.18784 °C
Cp	1.044296
Temperature	-84.22543 °C
Cp	1.04679
Temperature	-83.26302 °C
Cp	1.048951
Temperature	-82.30062 °C
Cp	1.050818
Temperature	-81.33822 °C
Cp	1.052404
Temperature	-80.37582 °C
Cp	1.053789
Temperature	-79.41341 °C
Cp	1.055011
Temperature	-78.45101 °C
Cp	1.056107
Temperature	-77.48861 °C
Cp	1.05712
Temperature	-76.52621 °C
Cp	1.058067
Temperature	-75.5638 °C
Cp	1.059033
Temperature	-74.6014 °C
Cp	1.060008
Temperature	-73.639 °C
Cp	1.06102
Temperature	-72.67659 °C
Cp	1.062091
Temperature	-71.71419 °C
Cp	1.06324
Temperature	-70.75179 °C
Cp	1.064487
Temperature	-69.78938 °C
Cp	1.065824
Temperature	-68.82698 °C
Cp	1.067263
Temperature	-67.86458 °C
Cp	1.068802
Temperature	-66.90218 °C
Cp	1.070434
Temperature	-65.93977 °C
Cp	1.07215
Temperature	-64.97737 °C
Cp	1.073961
Temperature	-64.01497 °C
Cp	1.07579
Temperature	-63.05256 °C
Cp	1.077675
Temperature	-62.09016 °C
Cp	1.0796
Temperature	-61.12776 °C
Cp	1.081549
Temperature	-60.16536 °C
Cp	1.083507
Temperature	-59.20295 °C
Cp	1.085459
Temperature	-58.24055 °C
Cp	1.087374
Temperature	-57.27814 °C
Cp	1.089301
Temperature	-56.31574 °C
Cp	1.091179
Temperature	-55.35334 °C
Cp	1.09301
Temperature	-54.39093 °C
Cp	1.094799
Temperature	-53.42853 °C
Cp	1.09655
Temperature	-52.46613 °C
Cp	1.098302
Temperature	-51.50373 °C
Cp	1.099969
Temperature	-50.54132 °C
Cp	1.101634
Temperature	-49.57892 °C
Cp	1.103291
Temperature	-48.61652 °C
Cp	1.104934
Temperature	-47.65411 °C
Cp	1.106558
Temperature	-46.69171 °C
Cp	1.108129
Temperature	-45.72931 °C
Cp	1.109722
Temperature	-44.76691 °C
Cp	1.111267
Temperature	-43.8045 °C
Cp	1.112769
Temperature	-42.8421 °C
Cp	1.11423
Temperature	-41.8797 °C
Cp	1.115656
Temperature	-40.91729 °C
Cp	1.117056
Temperature	-39.95489 °C
Cp	1.118417
Temperature	-38.99249 °C
Cp	1.119757
Temperature	-38.03008 °C
Cp	1.121077
Temperature	-37.06768 °C
Cp	1.12238
Temperature	-36.10528 °C
Cp	1.123667
Temperature	-35.14288 °C
Cp	1.124939
Temperature	-34.18047 °C
Cp	1.126202
Temperature	-33.21807 °C
Cp	1.127441
Temperature	-32.25566 °C
Cp	1.128669
Temperature	-31.29326 °C
Cp	1.129881
Temperature	-30.33086 °C
Cp	1.131073
Temperature	-29.36846 °C
Cp	1.13224
Temperature	-28.40605 °C
Cp	1.133372
Temperature	-27.44365 °C
Cp	1.134479
Temperature	-26.48125 °C
Cp	1.135545
Temperature	-25.51884 °C
Cp	1.136566
Temperature	-24.55644 °C
Cp	1.13754
Temperature	-23.59404 °C
Cp	1.138466
Temperature	-22.63164 °C
Cp	1.139347
Temperature	-21.66923 °C
Cp	1.140172
Temperature	-20.70683 °C
Cp	1.140951
Temperature	-19.74443 °C
Cp	1.141683
Temperature	-18.78202 °C
Cp	1.14237
Temperature	-17.81962 °C
Cp	1.143013
Temperature	-16.85722 °C
Cp	1.143601
Temperature	-15.89482 °C
Cp	1.14417
Temperature	-14.93241 °C
Cp	1.144696
Temperature	-13.97001 °C
Cp	1.145184
Temperature	-13.00761 °C
Cp	1.145641
Temperature	-12.0452 °C
Cp	1.14607
Temperature	-11.0828 °C
Cp	1.146477
Temperature	-10.1204 °C
Cp	1.146876
Temperature	-9.157994 °C
Cp	1.147244
Temperature	-8.195591 °C
Cp	1.147609
Temperature	-7.233188 °C
Cp	1.147968
Temperature	-6.270785 °C
Cp	1.148321
Temperature	-5.308382 °C
Cp	1.148663
Temperature	-4.345979 °C
Cp	1.148978
Temperature	-3.383576 °C
Cp	1.149303
Temperature	-2.421173 °C
Cp	1.1496
Temperature	-1.45877 °C
Cp	1.149872
Temperature	-0.496367 °C
Cp	1.150121
Temperature	0.466036 °C
Cp	1.15035
Temperature	1.428439 °C
Cp	1.150573
Temperature	2.390842 °C
Cp	1.150761
Temperature	3.353245 °C
Cp	1.150942
Temperature	4.315648 °C
Cp	1.151115
Temperature	5.278051 °C
Cp	1.151279
Temperature	6.240454 °C
Cp	1.151435
Temperature	7.202857 °C
Cp	1.151582
Temperature	8.16526 °C
Cp	1.151718
Temperature	9.127664 °C
Cp	1.151844
Temperature	10.09007 °C
Cp	1.151962
Temperature	11.05247 °C
Cp	1.152071
Temperature	12.01487 °C
Cp	1.152174
Temperature	12.97727 °C
Cp	1.15227
Temperature	13.93968 °C
Cp	1.152361
Temperature	14.90208 °C
Cp	1.15245
Temperature	15.86448 °C
Cp	1.152536
Temperature	16.82689 °C
Cp	1.152622
Temperature	17.78929 °C
Cp	1.152709
Temperature	18.75169 °C
Cp	1.152799
Temperature	19.7141 °C
Cp	1.152883
Temperature	20.6765 °C
Cp	1.152982
Temperature	21.6389 °C
Cp	1.15308
Temperature	22.60131 °C
Cp	1.153177
Temperature	23.56371 °C
Cp	1.153276
Temperature	24.52611 °C
Cp	1.153377
Temperature	25.48851 °C
Cp	1.153497
Temperature	26.45092 °C
Cp	1.153591
Temperature	27.41332 °C
Cp	1.153695
Temperature	28.37572 °C
Cp	1.153804
Temperature	29.33813 °C
Cp	1.153913
Temperature	30.30053 °C
Cp	1.154015
Temperature	31.26293 °C
Cp	1.154087
Temperature	32.22533 °C
Cp	1.154174
Temperature	33.18774 °C
Cp	1.154232
Temperature	34.15014 °C
Cp	1.154263
Temperature	35.11255 °C
Cp	1.154269
Temperature	36.07495 °C
Cp	1.154254
Temperature	37.03735 °C
Cp	1.154231
Temperature	37.99975 °C
Cp	1.154176
Temperature	38.96216 °C
Cp	1.154116
Temperature	39.92456 °C
Cp	1.154055
Temperature	40.88696 °C
Cp	1.153996
Temperature	41.84937 °C
Cp	1.153939
Temperature	42.81177 °C
Cp	1.153889
Temperature	43.77417 °C
Cp	1.153844
Temperature	44.73658 °C
Cp	1.153811
Temperature	45.69898 °C
Cp	1.153786
Temperature	46.66138 °C
Cp	1.153769
Temperature	47.62378 °C
Cp	1.153761
Temperature	48.58619 °C
Cp	1.153762
Temperature	49.54859 °C
Cp	1.153771
Temperature	50.51099 °C
Cp	1.153783
Temperature	51.4734 °C
Cp	1.1538
Temperature	52.4358 °C
Cp	1.153821
Temperature	53.3982 °C
Cp	1.153843
Temperature	54.3606 °C
Cp	1.153865
Temperature	55.32301 °C
Cp	1.153879
Temperature	56.28541 °C
Cp	1.153902
Temperature	57.24781 °C
Cp	1.15392
Temperature	58.21022 °C
Cp	1.153935
Temperature	59.17262 °C
Cp	1.15395
Temperature	60.13502 °C
Cp	1.153968
Temperature	61.09743 °C
Cp	1.154004
Temperature	62.05983 °C
Cp	1.154027
Temperature	63.02223 °C
Cp	1.154066
Temperature	63.98463 °C
Cp	1.154123
Temperature	64.94704 °C
Cp	1.154196
Temperature	65.90944 °C
Cp	1.154283
Temperature	66.87184 °C
Cp	1.154383
Temperature	67.83424 °C
Cp	1.154487
Temperature	68.79665 °C
Cp	1.15461
Temperature	69.75906 °C
Cp	1.154733
Temperature	70.72146 °C
Cp	1.154854
Temperature	71.68386 °C
Cp	1.154973
Temperature	72.64626 °C
Cp	1.155089
Temperature	73.60867 °C
Cp	1.15521
Temperature	74.57107 °C
Cp	1.15531
Temperature	75.53347 °C
Cp	1.155409
Temperature	76.49587 °C
Cp	1.155506
Temperature	77.45827 °C
Cp	1.155596
Temperature	78.42068 °C
Cp	1.155678
Temperature	79.38308 °C
Cp	1.155733
Temperature	80.34549 °C
Cp	1.155807
Temperature	81.30789 °C
Cp	1.155861
Temperature	82.27029 °C
Cp	1.155901
Temperature	83.2327 °C
Cp	1.155933
Temperature	84.1951 °C
Cp	1.155961
Temperature	85.1575 °C
Cp	1.156017
Temperature	86.1199 °C
Cp	1.156039
Temperature	87.08231 °C
Cp	1.156086
Temperature	88.04471 °C
Cp	1.156157
Temperature	89.00711 °C
Cp	1.156251
Temperature	89.96951 °C
Cp	1.156367
Temperature	90.93192 °C
Cp	1.156501
Temperature	91.89433 °C
Cp	1.156642
Temperature	92.85673 °C
Cp	1.156814
Temperature	93.81913 °C
Cp	1.156988
Temperature	94.78153 °C
Cp	1.157165
Temperature	95.74393 °C
Cp	1.157348
Temperature	96.70634 °C
Cp	1.157536
Temperature	97.66874 °C
Cp	1.15774
Temperature	98.63114 °C
Cp	1.157933
Temperature	99.59354 °C
Cp	1.158139
Temperature	100.5559 °C
Cp	1.158354
Temperature	101.5184 °C
Cp	1.158574
Temperature	102.4808 °C
Cp	1.158796
Temperature	103.4432 °C
Cp	1.15901
Temperature	104.4056 °C
Cp	1.159229
Temperature	105.368 °C
Cp	1.159435
Temperature	106.3304 °C
Cp	1.159626
Temperature	107.2928 °C
Cp	1.159803
Temperature	108.2552 °C
Cp	1.159964
Temperature	109.2176 °C
Cp	1.160111
Temperature	110.18 °C
Cp	1.160234
Temperature	111.1424 °C
Cp	1.160342
Temperature	112.1048 °C
Cp	1.160432
Temperature	113.0672 °C
Cp	1.160504
Temperature	114.0296 °C
Cp	1.160558
Temperature	114.992 °C
Cp	1.160594
Temperature	115.9544 °C
Cp	1.16061
Temperature	116.9168 °C
Cp	1.160614
Temperature	117.8792 °C
Cp	1.160601
Temperature	118.8416 °C
Cp	1.160574
Temperature	119.804 °C
Cp	1.160534
Temperature	120.7664 °C
Cp	1.160485
Temperature	121.7288 °C
Cp	1.160433
Temperature	122.6912 °C
Cp	1.160372
Temperature	123.6536 °C
Cp	1.160313
Temperature	124.616 °C
Cp	1.160255
Temperature	125.5784 °C
Cp	1.160201
Temperature	126.5408 °C
Cp	1.16015
Temperature	127.5032 °C
Cp	1.160101
Temperature	128.4656 °C
Cp	1.160059
Temperature	129.428 °C
Cp	1.16002
Temperature	130.3904 °C
Cp	1.159983
Temperature	131.3528 °C
Cp	1.159948
Temperature	132.3152 °C
Cp	1.159916
Temperature	133.2776 °C
Cp	1.159893
Temperature	134.2401 °C
Cp	1.15986
Temperature	135.2025 °C
Cp	1.159833
Temperature	136.1649 °C
Cp	1.15981
Temperature	137.1273 °C
Cp	1.159789
Temperature	138.0897 °C
Cp	1.159769
Temperature	139.0521 °C
Cp	1.15973
Temperature	140.0145 °C
Cp	1.159723
Temperature	140.9769 °C
Cp	1.159706
Temperature	141.9393 °C
Cp	1.159682
Temperature	142.9017 °C
Cp	1.159653
Temperature	143.8641 °C
Cp	1.159625
Temperature	144.8265 °C
Cp	1.159599
Temperature	145.7889 °C
Cp	1.15959
Temperature	146.7513 °C
Cp	1.15957
Temperature	147.7137 °C
Cp	1.159569
Temperature	148.6761 °C
Cp	1.159584
Temperature	149.6385 °C
Cp	1.159613
Temperature	150.6009 °C
Cp	1.159654
Temperature	151.5633 °C
Cp	1.15969
Temperature	152.5257 °C
Cp	1.159761
Temperature	153.4881 °C
Cp	1.159829
Temperature	154.4505 °C
Cp	1.159901
Temperature	155.4129 °C
Cp	1.159981
Temperature	156.3753 °C
Cp	1.160076
Temperature	157.3377 °C
Cp	1.160207
Temperature	158.3001 °C
Cp	1.160336
Temperature	159.2625 °C
Cp	1.160508
Temperature	160.2249 °C
Cp	1.160724
Temperature	161.1873 °C
Cp	1.160986
Temperature	162.1497 °C
Cp	1.161296
Temperature	163.1122 °C
Cp	1.161639
Temperature	164.0746 °C
Cp	1.162062
Temperature	165.037 °C
Cp	1.162527
Temperature	165.9994 °C
Cp	1.163037
Temperature	166.9618 °C
Cp	1.163591
Temperature	167.9242 °C
Cp	1.164188
Temperature	168.8866 °C
Cp	1.164826
Temperature	169.849 °C
Cp	1.165508
Temperature	170.8114 °C
Cp	1.166203
Temperature	171.7738 °C
Cp	1.166927
Temperature	172.7362 °C
Cp	1.167664
Temperature	173.6986 °C
Cp	1.168401
Temperature	174.661 °C
Cp	1.169124
Temperature	175.6234 °C
Cp	1.169799
Temperature	176.5858 °C
Cp	1.170462
Temperature	177.5482 °C
Cp	1.171058
Temperature	178.5106 °C
Cp	1.171581
Temperature	179.473 °C
Cp	1.172029
Temperature	180.4354 °C
Cp	1.1724
Temperature	181.3978 °C
Cp	1.172722
Temperature	182.3602 °C
Cp	1.172924
Temperature	183.3226 °C
Cp	1.173072
Temperature	184.285 °C
Cp	1.173165
Temperature	185.2474 °C
Cp	1.173204
Temperature	186.2098 °C
Cp	1.173191
Temperature	187.1722 °C
Cp	1.173098
Temperature	188.1346 °C
Cp	1.173022
Temperature	189.097 °C
Cp	1.172893
Temperature	190.0594 °C
Cp	1.172727
Temperature	191.0218 °C
Cp	1.172536
Temperature	191.9842 °C
Cp	1.172333
Temperature	192.9466 °C
Cp	1.172129
Temperature	193.909 °C
Cp	1.171948
Temperature	194.8714 °C
Cp	1.171764
Temperature	195.8338 °C
Cp	1.171616
Temperature	196.7962 °C
Cp	1.171503
Temperature	197.7587 °C
Cp	1.171422
Temperature	198.7211 °C
Cp	1.171373
Temperature	199.6835 °C
Cp	1.171339
Temperature	200.6459 °C
Cp	1.171347
Temperature	201.6083 °C
Cp	1.171366
Temperature	202.5707 °C
Cp	1.171394
Temperature	203.5331 °C
Cp	1.171431
Temperature	204.4955 °C
Cp	1.171476
Temperature	205.4579 °C
Cp	1.17154
Temperature	206.4203 °C
Cp	1.171593
Temperature	207.3827 °C
Cp	1.171659
Temperature	208.3451 °C
Cp	1.171737
Temperature	209.3075 °C
Cp	1.171824
Temperature	210.2699 °C
Cp	1.171918
Temperature	211.2323 °C
Cp	1.172
Temperature	212.1947 °C
Cp	1.172116
Temperature	213.1571 °C
Cp	1.172226
Temperature	214.1195 °C
Cp	1.172333
Temperature	215.0819 °C
Cp	1.172439
Temperature	216.0443 °C
Cp	1.172549
Temperature	217.0067 °C
Cp	1.172689
Temperature	217.9691 °C
Cp	1.172792
Temperature	218.9315 °C
Cp	1.172914
Temperature	219.8939 °C
Cp	1.173052
Temperature	220.8563 °C
Cp	1.173203
Temperature	221.8187 °C
Cp	1.173361
Temperature	222.7811 °C
Cp	1.173523
Temperature	223.7435 °C
Cp	1.173674
Temperature	224.7059 °C
Cp	1.173842
Temperature	225.6683 °C
Cp	1.173995
Temperature	226.6307 °C
Cp	1.174137
Temperature	227.5932 °C
Cp	1.174268
Temperature	228.5556 °C
Cp	1.174393
Temperature	229.518 °C
Cp	1.174531
Temperature	230.4804 °C
Cp	1.174642
Temperature	231.4428 °C
Cp	1.174766
Temperature	232.4052 °C
Cp	1.174902
Temperature	233.3676 °C
Cp	1.175049
Temperature	234.33 °C
Cp	1.175206
Temperature	235.2924 °C
Cp	1.175351
Temperature	236.2548 °C
Cp	1.175539
Temperature	237.2172 °C
Cp	1.175721
Temperature	238.1796 °C
Cp	1.175902
Temperature	239.142 °C
Cp	1.176085
Temperature	240.1044 °C
Cp	1.176272
Temperature	241.0668 °C
Cp	1.176491
Temperature	242.0292 °C
Cp	1.176676
Temperature	242.9916 °C
Cp	1.176882
Temperature	243.954 °C
Cp	1.177106
Temperature	244.9164 °C
Cp	1.177343
Temperature	245.8788 °C
Cp	1.177589
Temperature	246.8412 °C
Cp	1.17784
Temperature	247.8036 °C
Cp	1.17808
Temperature	248.766 °C
Cp	1.178334
Temperature	249.7284 °C
Cp	1.178575
Temperature	250.6908 °C
Cp	1.178803
Temperature	251.6532 °C
Cp	1.17902
Temperature	252.6156 °C
Cp	1.179227
Temperature	253.578 °C
Cp	1.179435
Temperature	254.5404 °C
Cp	1.17962
Temperature	255.5028 °C
Cp	1.179806
Temperature	256.4652 °C
Cp	1.179992
Temperature	257.4276 °C
Cp	1.180176
Temperature	258.39 °C
Cp	1.180356
Temperature	259.3524 °C
Cp	1.180525
Temperature	260.3148 °C
Cp	1.180699
Temperature	261.2773 °C
Cp	1.18086
Temperature	262.2397 °C
Cp	1.181011
Temperature	263.2021 °C
Cp	1.18115
Temperature	264.1645 °C
Cp	1.181279
Temperature	265.1269 °C
Cp	1.181398
Temperature	266.0893 °C
Cp	1.181504
Temperature	267.0517 °C
Cp	1.1816
Temperature	268.0141 °C
Cp	1.181687
Temperature	268.9765 °C
Cp	1.181765
Temperature	269.9389 °C
Cp	1.181835
Temperature	270.9013 °C
Cp	1.181897
Temperature	271.8637 °C
Cp	1.181952
Temperature	272.8261 °C
Cp	1.182001
Temperature	273.7885 °C
Cp	1.182045
Temperature	274.7509 °C
Cp	1.182086
Temperature	275.7133 °C
Cp	1.182126
Temperature	276.6757 °C
Cp	1.182166
Temperature	277.6381 °C
Cp	1.182204
Temperature	278.6005 °C
Cp	1.182251
Temperature	279.5629 °C
Cp	1.182299
Temperature	280.5253 °C
Cp	1.182353
Temperature	281.4877 °C
Cp	1.182414
Temperature	282.4501 °C
Cp	1.182486
Temperature	283.4125 °C
Cp	1.182577
Temperature	284.3749 °C
Cp	1.182671
Temperature	285.3373 °C
Cp	1.182786
Temperature	286.2997 °C
Cp	1.182921
Temperature	287.2621 °C
Cp	1.183076
Temperature	288.2245 °C
Cp	1.183251
Temperature	289.187 °C
Cp	1.183439
Temperature	290.1494 °C
Cp	1.183654
Temperature	291.1118 °C
Cp	1.183883
Temperature	292.0742 °C
Cp	1.184126
Temperature	293.0366 °C
Cp	1.184383
Temperature	293.999 °C
Cp	1.184651
Temperature	294.9614 °C
Cp	1.184932
Temperature	295.9238 °C
Cp	1.185223
Temperature	296.8862 °C
Cp	1.185522
Temperature	297.8486 °C
Cp	1.185828
Temperature	298.811 °C
Cp	1.18614
Temperature	299.7734 °C
Cp	1.186456
Temperature	300.7358 °C
Cp	1.186773
Temperature	301.6982 °C
Cp	1.187085
Temperature	302.6606 °C
Cp	1.1874
Temperature	303.623 °C
Cp	1.187709
Temperature	304.5854 °C
Cp	1.188011
Temperature	305.5478 °C
Cp	1.188307
Temperature	306.5102 °C
Cp	1.188598
Temperature	307.4726 °C
Cp	1.188893
Temperature	308.435 °C
Cp	1.189173
Temperature	309.3974 °C
Cp	1.189456
Temperature	310.3598 °C
Cp	1.189744
Temperature	311.3222 °C
Cp	1.190034
Temperature	312.2846 °C
Cp	1.190329
Temperature	313.247 °C
Cp	1.190615
Temperature	314.2094 °C
Cp	1.190925
Temperature	315.1718 °C
Cp	1.191232
Temperature	316.1342 °C
Cp	1.191539
Temperature	317.0966 °C
Cp	1.191848
Temperature	318.059 °C
Cp	1.19216
Temperature	319.0214 °C
Cp	1.192496
Temperature	319.9838 °C
Cp	1.192805
Temperature	320.9462 °C
Cp	1.193128
Temperature	321.9086 °C
Cp	1.193462
Temperature	322.871 °C
Cp	1.193803
Temperature	323.8334 °C
Cp	1.194149
Temperature	324.7958 °C
Cp	1.194495
Temperature	325.7583 °C
Cp	1.194832
Temperature	326.7207 °C
Cp	1.195181
Temperature	327.6831 °C
Cp	1.19552
Temperature	328.6455 °C
Cp	1.195853
Temperature	329.6079 °C
Cp	1.196183
Temperature	330.5703 °C
Cp	1.196515
Temperature	331.5327 °C
Cp	1.196862
Temperature	332.4951 °C
Cp	1.197211
Temperature	333.4575 °C
Cp	1.197584
Temperature	334.4199 °C
Cp	1.197985
Temperature	335.3823 °C
Cp	1.198418
Temperature	336.3447 °C
Cp	1.198886
Temperature	337.3071 °C
Cp	1.199394
[...]
163.9933	-16.9626	-0.1776
163.9983	-16.9131	-0.1777
164.0033	-16.8612	-0.1777
164.0083	-16.8122	-0.1777
164.0133	-16.7628	-0.1778
164.0183	-16.7136	-0.1778
164.0233	-16.6636	-0.1778
164.0283	-16.6137	-0.1778
164.0333	-16.5636	-0.1779
164.0383	-16.5114	-0.1779
164.0433	-16.4630	-0.1779
164.0483	-16.4138	-0.1780
164.0533	-16.3637	-0.1780
164.0583	-16.3129	-0.1780
164.0633	-16.2636	-0.1781
164.0683	-16.2137	-0.1781
164.0733	-16.1643	-0.1781
164.0783	-16.1132	-0.1781
164.0833	-16.0623	-0.1782
164.0883	-16.0120	-0.1782
164.0933	-15.9648	-0.1783
164.0983	-15.9137	-0.1784
164.1033	-15.8642	-0.1784
164.1083	-15.8128	-0.1785
164.1133	-15.7628	-0.1785
164.1183	-15.7145	-0.1785
164.1233	-15.6637	-0.1786
164.1283	-15.6123	-0.1786
164.1333	-15.5637	-0.1786
164.1383	-15.5140	-0.1786
164.1433	-15.4638	-0.1787
164.1483	-15.4146	-0.1787
164.1533	-15.3641	-0.1787
164.1583	-15.3149	-0.1787
164.1633	-15.2638	-0.1788
164.1683	-15.2144	-0.1788
164.1733	-15.1645	-0.1789
164.1783	-15.1152	-0.1789
164.1833	-15.0632	-0.1789
164.1883	-15.0141	-0.1790
164.1933	-14.9645	-0.1790
164.1983	-14.9152	-0.1791
164.2033	-14.8646	-0.1791
164.2083	-14.8150	-0.1791
164.2133	-14.7655	-0.1792
164.2183	-14.7144	-0.1792
164.2233	-14.6643	-0.1792
164.2283	-14.6151	-0.1792
164.2333	-14.5651	-0.1793
164.2383	-14.5146	-0.1793
164.2433	-14.4648	-0.1793
164.2483	-14.4148	-0.1794
164.2533	-14.3647	-0.1794
164.2583	-14.3142	-0.1795
164.2633	-14.2650	-0.1795
164.2683	-14.2159	-0.1796
164.2733	-14.1657	-0.1796
164.2783	-14.1156	-0.1796
164.2833	-14.0654	-0.1797
164.2883	-14.0151	-0.1797
164.2933	-13.9647	-0.1797
164.2983	-13.9155	-0.1798
164.3033	-13.8654	-0.1798
164.3083	-13.8160	-0.1798
164.3133	-13.7668	-0.1798
164.3183	-13.7158	-0.1799
164.3233	-13.6650	-0.1799
164.3283	-13.6163	-0.1800
164.3333	-13.5665	-0.1800
164.3383	-13.5152	-0.1800
164.3433	-13.4654	-0.1800
164.3483	-13.4159	-0.1801
164.3533	-13.3671	-0.1801
164.3583	-13.3165	-0.1801
164.3633	-13.2653	-0.1802
164.3683	-13.2155	-0.1802
164.3733	-13.1664	-0.1802
164.3783	-13.1166	-0.1803
164.3833	-13.0667	-0.1803
164.3883	-13.0176	-0.1804
164.3933	-12.9668	-0.1804
164.3983	-12.9163	-0.1804
164.4033	-12.8654	-0.1805
164.4083	-12.8169	-0.1805
164.4133	-12.7668	-0.1805
164.4183	-12.7166	-0.1806
164.4233	-12.6666	-0.1806
164.4283	-12.6171	-0.1806
164.4333	-12.5659	-0.1806
164.4383	-12.5173	-0.1807
164.4433	-12.4653	-0.1807
164.4483	-12.4177	-0.1808
164.4533	-12.3650	-0.1808
164.4583	-12.3178	-0.1808
164.4633	-12.2666	-0.1808
164.4683	-12.2159	-0.1809
164.4733	-12.1662	-0.1809
164.4783	-12.1164	-0.1809
164.4833	-12.0661	-0.1810
164.4883	-12.0167	-0.1810
164.4933	-11.9669	-0.1810
164.4983	-11.9169	-0.1810
164.5033	-11.8678	-0.1811
164.5083	-11.8168	-0.1812
164.5133	-11.7657	-0.1814
164.5183	-11.7167	-0.1814
164.5233	-11.6665	-0.1814
164.5283	-11.6172	-0.1815
164.5333	-11.5674	-0.1815
164.5383	-11.5171	-0.1815
164.5433	-11.4663	-0.1816
164.5483	-11.4159	-0.1816
164.5533	-11.3665	-0.1816
164.5583	-11.3174	-0.1816
164.5633	-11.2667	-0.1817
164.5683	-11.2172	-0.1817
164.5733	-11.1664	-0.1818
164.5783	-11.1173	-0.1818
164.5833	-11.0659	-0.1818
164.5883	-11.0175	-0.1819
164.5933	-10.9655	-0.1819
164.5983	-10.9163	-0.1819
164.6033	-10.8673	-0.1819
164.6083	-10.8177	-0.1820
164.6133	-10.7659	-0.1820
164.6183	-10.7169	-0.1821
164.6233	-10.6677	-0.1821
164.6283	-10.6176	-0.1821
164.6333	-10.5667	-0.1822
164.6383	-10.5172	-0.1822
164.6433	-10.4669	-0.1822
164.6483	-10.4169	-0.1822
164.6533	-10.3687	-0.1822
164.6583	-10.3181	-0.1823
164.6633	-10.2689	-0.1824
164.6683	-10.2178	-0.1824
164.6733	-10.1690	-0.1824
164.6783	-10.1182	-0.1824
164.6833	-10.0688	-0.1824
164.6883	-10.0175	-0.1825
164.6933	-9.9679	-0.1825
164.6983	-9.9182	-0.1825
164.7033	-9.8680	-0.1825
164.7083	-9.8174	-0.1826
164.7133	-9.7672	-0.1826
164.7183	-9.7179	-0.1826
164.7233	-9.6678	-0.1826
164.7283	-9.6171	-0.1827
164.7333	-9.5668	-0.1827
164.7383	-9.5179	-0.1828
164.7433	-9.4685	-0.1828
164.7483	-9.4185	-0.1828
164.7533	-9.3677	-0.1828
164.7583	-9.3177	-0.1829
164.7633	-9.2674	-0.1830
164.7683	-9.2189	-0.1830
164.7733	-9.1679	-0.1830
164.7783	-9.1179	-0.1831
164.7833	-9.0674	-0.1831
164.7883	-9.0174	-0.1831
164.7933	-8.9682	-0.1831
164.7983	-8.9182	-0.1832
164.8033	-8.8671	-0.1833
164.8083	-8.8183	-0.1834
164.8133	-8.7675	-0.1834
164.8183	-8.7194	-0.1834
164.8233	-8.6692	-0.1834
164.8283	-8.6184	-0.1834
164.8333	-8.5683	-0.1835
164.8383	-8.5184	-0.1835
164.8433	-8.4690	-0.1835
164.8483	-8.4194	-0.1836
164.8533	-8.3682	-0.1836
164.8583	-8.3177	-0.1836
164.8633	-8.2673	-0.1837
164.8683	-8.2182	-0.1837
164.8733	-8.1676	-0.1837
164.8783	-8.1186	-0.1837
164.8833	-8.0690	-0.1838
164.8883	-8.0179	-0.1838
164.8933	-7.9685	-0.1838
164.8983	-7.9176	-0.1839
164.9033	-7.8695	-0.1839
164.9083	-7.8184	-0.1839
164.9133	-7.7681	-0.1840
164.9183	-7.7184	-0.1840
164.9233	-7.6682	-0.1840
164.9283	-7.6176	-0.1841
164.9333	-7.5687	-0.1841
164.9383	-7.5183	-0.1841
164.9433	-7.4700	-0.1841
164.9483	-7.4199	-0.1842
164.9533	-7.3687	-0.1842
164.9583	-7.3188	-0.1842
164.9633	-7.2687	-0.1842
164.9683	-7.2202	-0.1843
164.9733	-7.1697	-0.1843
164.9783	-7.1173	-0.1843
164.9833	-7.0683	-0.1844
164.9883	-7.0188	-0.1845
164.9933	-6.9690	-0.1845
164.9983	-6.9191	-0.1845
165.0033	-6.8687	-0.1845
165.0083	-6.8196	-0.1846
165.0133	-6.7686	-0.1846
165.0183	-6.7188	-0.1846
165.0233	-6.6703	-0.1847
165.0283	-6.6190	-0.1847
165.0333	-6.5691	-0.1848
165.0383	-6.5201	-0.1848
165.0433	-6.4688	-0.1848
165.0483	-6.4200	-0.1849
165.0533	-6.3691	-0.1849
165.0583	-6.3177	-0.1849
165.0633	-6.2685	-0.1849
165.0683	-6.2203	-0.1850
165.0733	-6.1693	-0.1850
165.0783	-6.1193	-0.1850
165.0833	-6.0698	-0.1851
165.0883	-6.0209	-0.1851
165.0933	-5.9699	-0.1851
165.0983	-5.9191	-0.1851
165.1033	-5.8688	-0.1852
165.1083	-5.8210	-0.1853
165.1133	-5.7701	-0.1854
165.1183	-5.7187	-0.1854
165.1233	-5.6693	-0.1854
165.1283	-5.6194	-0.1854
165.1333	-5.5706	-0.1855
165.1383	-5.5213	-0.1855
165.1433	-5.4701	-0.1856
165.1483	-5.4198	-0.1856
165.1533	-5.3701	-0.1856
165.1583	-5.3188	-0.1857
165.1633	-5.2699	-0.1857
165.1683	-5.2197	-0.1857
165.1733	-5.1708	-0.1857
165.1783	-5.1199	-0.1858
165.1833	-5.0701	-0.1858
165.1883	-5.0197	-0.1858
165.1933	-4.9694	-0.1859
165.1983	-4.9195	-0.1859
165.2033	-4.8702	-0.1859
165.2083	-4.8199	-0.1860
165.2133	-4.7701	-0.1861
165.2183	-4.7195	-0.1861
165.2233	-4.6702	-0.1861
165.2283	-4.6195	-0.1861
165.2333	-4.5701	-0.1862
165.2383	-4.5185	-0.1862
165.2433	-4.4690	-0.1862
165.2483	-4.4197	-0.1863
165.2533	-4.3699	-0.1863
165.2583	-4.3207	-0.1863
165.2633	-4.2696	-0.1864
165.2683	-4.2206	-0.1864
165.2733	-4.1700	-0.1864
165.2783	-4.1216	-0.1865
165.2833	-4.0708	-0.1865
165.2883	-4.0194	-0.1865
165.2933	-3.9699	-0.1866
165.2983	-3.9196	-0.1866
165.3033	-3.8689	-0.1866
165.3083	-3.8198	-0.1867
165.3133	-3.7698	-0.1867
165.3183	-3.7209	-0.1867
165.3233	-3.6710	-0.1868
165.3283	-3.6201	-0.1868
165.3333	-3.5686	-0.1868
165.3383	-3.5198	-0.1869
165.3433	-3.4711	-0.1869
165.3483	-3.4206	-0.1869
165.3533	-3.3703	-0.1870
165.3583	-3.3195	-0.1870
165.3633	-3.2683	-0.1871
165.3683	-3.2193	-0.1871
165.3733	-3.1703	-0.1871
165.3783	-3.1189	-0.1872
165.3833	-3.0703	-0.1872
165.3883	-3.0214	-0.1873
165.3933	-2.9693	-0.1873
165.3983	-2.9204	-0.1873
165.4033	-2.8693	-0.1874
165.4083	-2.8215	-0.1874
165.4133	-2.7711	-0.1874
165.4183	-2.7212	-0.1874
165.4233	-2.6715	-0.1875
165.4283	-2.6216	-0.1875
165.4333	-2.5710	-0.1875
165.4383	-2.5213	-0.1875
165.4433	-2.4717	-0.1876
165.4483	-2.4209	-0.1876
165.4533	-2.3713	-0.1877
165.4583	-2.3210	-0.1877
165.4633	-2.2709	-0.1877
165.4683	-2.2206	-0.1878
165.4733	-2.1717	-0.1879
165.4783	-2.1211	-0.1879
165.4833	-2.0712	-0.1880
165.4883	-2.0224	-0.1880
165.4933	-1.9711	-0.1881
165.4983	-1.9208	-0.1881
165.5033	-1.8709	-0.1881
165.5083	-1.8217	-0.1881
165.5133	-1.7718	-0.1882
165.5183	-1.7213	-0.1882
165.5233	-1.6712	-0.1883
165.5283	-1.6212	-0.1883
165.5333	-1.5725	-0.1883
165.5383	-1.5225	-0.1884
165.5433	-1.4722	-0.1884
165.5483	-1.4221	-0.1884
165.5533	-1.3725	-0.1885
165.5583	-1.3227	-0.1885
165.5633	-1.2724	-0.1885
165.5683	-1.2223	-0.1886
165.5733	-1.1729	-0.1886
165.5783	-1.1232	-0.1886
165.5833	-1.0734	-0.1886
165.5883	-1.0220	-0.1887
165.5933	-0.9720	-0.1888
165.5983	-0.9222	-0.1888
165.6033	-0.8719	-0.1889
165.6083	-0.8235	-0.1889
165.6133	-0.7730	-0.1889
165.6183	-0.7228	-0.1889
165.6233	-0.6743	-0.1890
165.6283	-0.6227	-0.1891
165.6333	-0.5717	-0.1892
165.6383	-0.5222	-0.1893
165.6433	-0.4725	-0.1893
165.6483	-0.4232	-0.1893
165.6533	-0.3725	-0.1894
165.6583	-0.3229	-0.1895
165.6633	-0.2725	-0.1896
165.6683	-0.2235	-0.1896
165.6733	-0.1734	-0.1896
165.6783	-0.1229	-0.1896
165.6833	-0.0733	-0.1897
165.6883	-0.0232	-0.1897
165.6933	0.0268	-0.1898
165.6983	0.0781	-0.1898
165.7033	0.1273	-0.1899
165.7083	0.1769	-0.1899
165.7133	0.2262	-0.1900
165.7183	0.2771	-0.1901
165.7233	0.3276	-0.1901
165.7283	0.3772	-0.1901
165.7333	0.4273	-0.1901
165.7383	0.4773	-0.1902
165.7433	0.5271	-0.1902
165.7483	0.5769	-0.1902
165.7533	0.6265	-0.1903
165.7583	0.6778	-0.1903
165.7633	0.7265	-0.1904
165.7683	0.7775	-0.1904
165.7733	0.8261	-0.1904
165.7783	0.8769	-0.1905
165.7833	0.9265	-0.1905
165.7883	0.9770	-0.1905
165.7933	1.0267	-0.1906
165.7983	1.0767	-0.1907
165.8033	1.1273	-0.1907
165.8083	1.1770	-0.1907
165.8133	1.2250	-0.1908
165.8183	1.2771	-0.1909
165.8233	1.3253	-0.1909
165.8283	1.3767	-0.1909
165.8333	1.4246	-0.1909
165.8383	1.4764	-0.1910
165.8433	1.5274	-0.1911
165.8483	1.5771	-0.1911
165.8533	1.6259	-0.1911
165.8583	1.6768	-0.1912
165.8633	1.7265	-0.1912
165.8683	1.7766	-0.1912
165.8733	1.8256	-0.1913
165.8783	1.8749	-0.1914
165.8833	1.9267	-0.1915
165.8883	1.9766	-0.1915
165.8933	2.0273	-0.1916
165.8983	2.0752	-0.1916
165.9033	2.1256	-0.1916
165.9083	2.1752	-0.1916
165.9133	2.2265	-0.1917
165.9183	2.2762	-0.1917
165.9233	2.3254	-0.1917
165.9283	2.3753	-0.1918
165.9333	2.4267	-0.1918
165.9383	2.4759	-0.1919
165.9433	2.5275	-0.1919
165.9483	2.5755	-0.1920
165.9533	2.6258	-0.1920
165.9583	2.6770	-0.1921
165.9633	2.7267	-0.1921
165.9683	2.7759	-0.1921
165.9733	2.8258	-0.1922
165.9783	2.8752	-0.1922
165.9833	2.9260	-0.1922
165.9883	2.9746	-0.1923
165.9933	3.0254	-0.1923
165.9983	3.0766	-0.1923
166.0033	3.1249	-0.1924
166.0083	3.1745	-0.1924
166.0133	3.2245	-0.1924
166.0183	3.2745	-0.1925
166.0233	3.3250	-0.1925
166.0283	3.3750	-0.1926
166.0333	3.4249	-0.1926
166.0383	3.4752	-0.1926
166.0433	3.5247	-0.1927
166.0483	3.5742	-0.1927
166.0533	3.6240	-0.1927
166.0583	3.6746	-0.1928
166.0633	3.7250	-0.1929
166.0683	3.7746	-0.1929
166.0733	3.8249	-0.1930
166.0783	3.8749	-0.1930
166.0833	3.9261	-0.1931
166.0883	3.9751	-0.1931
166.0933	4.0247	-0.1932
166.0983	4.0742	-0.1932
166.1033	4.1257	-0.1932
166.1083	4.1754	-0.1933
166.1133	4.2262	-0.1934
166.1183	4.2740	-0.1934
166.1233	4.3253	-0.1934
166.1283	4.3741	-0.1935
166.1333	4.4242	-0.1935
166.1383	4.4746	-0.1935
166.1433	4.5247	-0.1936
166.1483	4.5759	-0.1936
166.1533	4.6253	-0.1937
166.1583	4.6760	-0.1937
166.1633	4.7254	-0.1937
166.1683	4.7751	-0.1937
166.1733	4.8253	-0.1938
166.1783	4.8749	-0.1939
166.1833	4.9247	-0.1939
166.1883	4.9750	-0.1940
166.1933	5.0245	-0.1940
166.1983	5.0743	-0.1940
166.2033	5.1252	-0.1942
166.2083	5.1750	-0.1942
166.2133	5.2250	-0.1943
166.2183	5.2746	-0.1943
166.2233	5.3244	-0.1943
166.2283	5.3756	-0.1944
166.2333	5.4246	-0.1944
166.2383	5.4758	-0.1944
166.2433	5.5252	-0.1945
166.2483	5.5732	-0.1945
166.2533	5.6256	-0.1946
166.2583	5.6745	-0.1946
166.2633	5.7245	-0.1947
166.2683	5.7745	-0.1947
166.2733	5.8252	-0.1947
166.2783	5.8748	-0.1947
166.2833	5.9245	-0.1948
166.2883	5.9733	-0.1948
166.2933	6.0237	-0.1948
166.2983	6.0745	-0.1949
166.3033	6.1248	-0.1949
166.3083	6.1746	-0.1949
166.3133	6.2238	-0.1950
166.3183	6.2742	-0.1950
166.3233	6.3237	-0.1950
166.3283	6.3737	-0.1951
166.3333	6.4241	-0.1951
166.3383	6.4733	-0.1952
166.3433	6.5243	-0.1952
166.3483	6.5739	-0.1953
166.3533	6.6236	-0.1953
166.3583	6.6743	-0.1953
166.3633	6.7239	-0.1954
166.3683	6.7733	-0.1956
166.3733	6.8237	-0.1957
166.3783	6.8743	-0.1957
166.3833	6.9238	-0.1957
166.3883	6.9735	-0.1957
166.3933	7.0243	-0.1958
166.3983	7.0744	-0.1958
166.4033	7.1234	-0.1958
166.4083	7.1735	-0.1959
166.4133	7.2225	-0.1959
166.4183	7.2734	-0.1959
166.4233	7.3243	-0.1960
166.4283	7.3740	-0.1960
166.4333	7.4234	-0.1961
166.4383	7.4737	-0.1961
166.4433	7.5231	-0.1961
166.4483	7.5733	-0.1962
166.4533	7.6226	-0.1962
166.4583	7.6735	-0.1962
166.4633	7.7234	-0.1963
166.4683	7.7720	-0.1963
166.4733	7.8233	-0.1963
166.4783	7.8726	-0.1964
166.4833	7.9230	-0.1964
166.4883	7.9732	-0.1965
166.4933	8.0235	-0.1965
166.4983	8.0733	-0.1965
166.5033	8.1222	-0.1965
166.5083	8.1733	-0.1966
166.5133	8.2223	-0.1966
166.5183	8.2721	-0.1967
166.5233	8.3230	-0.1967
166.5283	8.3728	-0.1968
166.5333	8.4227	-0.1968
166.5383	8.4729	-0.1969
166.5433	8.5221	-0.1969
166.5483	8.5730	-0.1969
166.5533	8.6218	-0.1970
166.5583	8.6728	-0.1970
166.5633	8.7216	-0.1970
166.5683	8.7713	-0.1971
166.5733	8.8209	-0.1971
166.5783	8.8716	-0.1971
166.5833	8.9229	-0.1972
166.5883	8.9724	-0.1972
166.5933	9.0213	-0.1973
166.5983	9.0718	-0.1973
166.6033	9.1213	-0.1974
166.6083	9.1723	-0.1975
166.6133	9.2220	-0.1976
166.6183	9.2723	-0.1976
166.6233	9.3212	-0.1976
166.6283	9.3724	-0.1977
166.6333	9.4220	-0.1977
166.6383	9.4728	-0.1977
166.6433	9.5228	-0.1978
166.6483	9.5715	-0.1978
166.6533	9.6213	-0.1979
166.6583	9.6710	-0.1979
166.6633	9.7214	-0.1979
166.6683	9.7705	-0.1980
166.6733	9.8209	-0.1980
166.6783	9.8716	-0.1981
166.6833	9.9220	-0.1981
166.6883	9.9705	-0.1981
166.6933	10.0201	-0.1981
166.6983	10.0696	-0.1982
166.7033	10.1207	-0.1983
166.7083	10.1706	-0.1984
166.7133	10.2208	-0.1985
166.7183	10.2702	-0.1985
166.7233	10.3207	-0.1985
166.7283	10.3707	-0.1986
166.7333	10.4198	-0.1987
166.7383	10.4710	-0.1987
166.7433	10.5197	-0.1988
166.7483	10.5699	-0.1988
166.7533	10.6200	-0.1989
166.7583	10.6695	-0.1989
166.7633	10.7199	-0.1989
166.7683	10.7689	-0.1990
166.7733	10.8205	-0.1990
166.7783	10.8700	-0.1991
166.7833	10.9204	-0.1991
166.7883	10.9690	-0.1991
166.7933	11.0203	-0.1992
166.7983	11.0691	-0.1992
166.8033	11.1197	-0.1993
166.8083	11.1694	-0.1994
166.8133	11.2192	-0.1995
166.8183	11.2703	-0.1995
166.8233	11.3195	-0.1995
166.8283	11.3695	-0.1995
166.8333	11.4198	-0.1996
166.8383	11.4687	-0.1996
166.8433	11.5208	-0.1997
166.8483	11.5685	-0.1997
166.8533	11.6195	-0.1997
166.8583	11.6691	-0.1999
166.8633	11.7200	-0.2000
166.8683	11.7702	-0.2000
166.8733	11.8203	-0.2000
166.8783	11.8699	-0.2001
166.8833	11.9189	-0.2001
166.8883	11.9695	-0.2002
166.8933	12.0206	-0.2002
166.8983	12.0698	-0.2003
166.9033	12.1202	-0.2004
166.9083	12.1700	-0.2005
166.9133	12.2197	-0.2005
166.9183	12.2700	-0.2005
166.9233	12.3202	-0.2006
166.9283	12.3693	-0.2006
166.9333	12.4192	-0.2007
166.9383	12.4684	-0.2007
166.9433	12.5187	-0.2008
166.9483	12.5683	-0.2008
166.9533	12.6180	-0.2008
166.9583	12.6692	-0.2008
166.9633	12.7198	-0.2009
166.9683	12.7687	-0.2010
166.9733	12.8182	-0.2010
166.9783	12.8687	-0.2010
166.9833	12.9185	-0.2011
166.9883	12.9690	-0.2011
166.9933	13.0187	-0.2011
166.9983	13.0680	-0.2012
167.0033	13.1192	-0.2012
167.0083	13.1695	-0.2013
167.0133	13.2190	-0.2013
167.0183	13.2678	-0.2014
167.0233	13.3185	-0.2015
167.0283	13.3676	-0.2015
167.0333	13.4187	-0.2015
167.0383	13.4683	-0.2016
167.0433	13.5186	-0.2017
167.0483	13.5682	-0.2017
167.0533	13.6192	-0.2018
167.0583	13.6676	-0.2018
167.0633	13.7176	-0.2018
167.0683	13.7669	-0.2019
167.0733	13.8177	-0.2020
167.0783	13.8682	-0.2020
167.0833	13.9173	-0.2020
167.0883	13.9686	-0.2021
167.0933	14.0168	-0.2021
167.0983	14.0667	-0.2022
167.1033	14.1180	-0.2022
167.1083	14.1679	-0.2023
167.1133	14.2179	-0.2023
167.1183	14.2679	-0.2023
167.1233	14.3175	-0.2023
167.1283	14.3688	-0.2024
167.1333	14.4184	-0.2024
167.1383	14.4687	-0.2025
167.1433	14.5166	-0.2025
167.1483	14.5674	-0.2025
167.1533	14.6168	-0.2026
167.1583	14.6669	-0.2026
167.1633	14.7165	-0.2027
167.1683	14.7676	-0.2028
167.1733	14.8184	-0.2029
167.1783	14.8665	-0.2029
167.1833	14.9166	-0.2029
167.1883	14.9668	-0.2030
167.1933	15.0166	-0.2030
167.1983	15.0674	-0.2031
167.2033	15.1170	-0.2031
167.2083	15.1665	-0.2032
167.2133	15.2160	-0.2032
167.2183	15.2667	-0.2032
167.2233	15.3169	-0.2033
167.2283	15.3669	-0.2033
167.2333	15.4162	-0.2034
167.2383	15.4662	-0.2035
167.2433	15.5163	-0.2036
167.2483	15.5663	-0.2036
167.2533	15.6161	-0.2036
167.2583	15.6661	-0.2037
167.2633	15.7171	-0.2037
167.2683	15.7672	-0.2037
167.2733	15.8157	-0.2038
167.2783	15.8651	-0.2039
167.2833	15.9163	-0.2042
167.2883	15.9677	-0.2042
167.2933	16.0166	-0.2043
167.2983	16.0661	-0.2043
167.3033	16.1171	-0.2043
167.3083	16.1667	-0.2044
167.3133	16.2167	-0.2044
167.3183	16.2666	-0.2045
167.3233	16.3161	-0.2045
167.3283	16.3657	-0.2046
167.3333	16.4159	-0.2046
167.3383	16.4658	-0.2046
167.3433	16.5158	-0.2047
167.3483	16.5658	-0.2047
167.3533	16.6161	-0.2047
167.3583	16.6664	-0.2048
167.3633	16.7158	-0.2048
167.3683	16.7655	-0.2049
167.3733	16.8155	-0.2049
167.3783	16.8651	-0.2050
167.3833	16.9154	-0.2050
167.3883	16.9651	-0.2051
167.3933	17.0158	-0.2051
167.3983	17.0656	-0.2051
167.4033	17.1162	-0.2052
167.4083	17.1647	-0.2053
167.4133	17.2152	-0.2054
167.4183	17.2651	-0.2054
167.4233	17.3158	-0.2054
167.4283	17.3652	-0.2055
167.4333	17.4152	-0.2055
167.4383	17.4653	-0.2056
167.4433	17.5147	-0.2056
167.4483	17.5646	-0.2058
167.4533	17.6151	-0.2060
167.4583	17.6651	-0.2061
167.4633	17.7148	-0.2061
167.4683	17.7653	-0.2062
167.4733	17.8151	-0.2062
167.4783	17.8650	-0.2063
167.4833	17.9151	-0.2063
167.4883	17.9648	-0.2064
167.4933	18.0153	-0.2064
167.4983	18.0639	-0.2064
167.5033	18.1145	-0.2065
167.5083	18.1641	-0.2065
167.5133	18.2149	-0.2066
167.5183	18.2658	-0.2067
167.5233	18.3149	-0.2067
167.5283	18.3641	-0.2068
167.5333	18.4148	-0.2068
167.5383	18.4644	-0.2068
167.5433	18.5132	-0.2069
167.5483	18.5630	-0.2070
167.5533	18.6137	-0.2072
167.5583	18.6643	-0.2073
167.5633	18.7151	-0.2073
167.5683	18.7642	-0.2074
167.5733	18.8142	-0.2074
167.5783	18.8640	-0.2075
167.5833	18.9128	-0.2075
167.5883	18.9638	-0.2076
167.5933	19.0150	-0.2076
167.5983	19.0643	-0.2077
167.6033	19.1153	-0.2077
167.6083	19.1646	-0.2078
167.6133	19.2144	-0.2078
167.6183	19.2639	-0.2079
167.6233	19.3140	-0.2079
167.6283	19.3638	-0.2080
167.6333	19.4134	-0.2081
167.6383	19.4632	-0.2082
167.6433	19.5133	-0.2083
167.6483	19.5642	-0.2083
167.6533	19.6133	-0.2084
167.6583	19.6638	-0.2084
167.6633	19.7131	-0.2084
167.6683	19.7642	-0.2085
167.6733	19.8130	-0.2087
167.6783	19.8641	-0.2088
167.6833	19.9125	-0.2089
167.6883	19.9632	-0.2089
167.6933	20.0138	-0.2090
167.6983	20.0631	-0.2090
167.7033	20.1134	-0.2091
167.7083	20.1628	-0.2091
167.7133	20.2132	-0.2092
167.7183	20.2618	-0.2093
167.7233	20.3128	-0.2093
167.7283	20.3618	-0.2093
167.7333	20.4121	-0.2094
167.7383	20.4623	-0.2097
167.7433	20.5125	-0.2100
167.7483	20.5623	-0.2100
167.7533	20.6119	-0.2101
167.7583	20.6612	-0.2102
167.7633	20.7119	-0.2103
167.7683	20.7623	-0.2103
167.7733	20.8123	-0.2104
167.7783	20.8622	-0.2104
167.7833	20.9117	-0.2105
167.7883	20.9616	-0.2105
167.7933	21.0113	-0.2106
167.7983	21.0615	-0.2106
167.8033	21.1119	-0.2107
167.8083	21.1611	-0.2109
167.8133	21.2109	-0.2111
167.8183	21.2621	-0.2112
167.8233	21.3117	-0.2112
167.8283	21.3609	-0.2113
167.8333	21.4113	-0.2115
167.8383	21.4620	-0.2116
167.8433	21.5113	-0.2117
167.8483	21.5618	-0.2117
167.8533	21.6103	-0.2118
167.8583	21.6606	-0.2119
167.8633	21.7110	-0.2120
167.8683	21.7614	-0.2121
167.8733	21.8116	-0.2122
167.8783	21.8606	-0.2122
167.8833	21.9110	-0.2123
167.8883	21.9599	-0.2123
167.8933	22.0109	-0.2124
167.8983	22.0604	-0.2124
167.9033	22.1110	-0.2126
167.9083	22.1611	-0.2132
167.9133	22.2106	-0.2135
167.9183	22.2602	-0.2137
167.9233	22.3095	-0.2137
167.9283	22.3598	-0.2138
167.9333	22.4097	-0.2138
167.9383	22.4602	-0.2140
167.9433	22.5095	-0.2142
167.9483	22.5603	-0.2144
167.9533	22.6095	-0.2147
167.9583	22.6604	-0.2148
167.9633	22.7093
167.9683	22.7592
167.9733	22.8103
167.9783	22.8597
167.9833	22.9095
167.9883	22.9595
167.9933	23.0080
167.9983	23.0588
168.0033	23.1086
168.0083	23.1586
168.0133
168.0167